2026/05/06 17:32:00 Starting K8s Sim Control Plane with Fake API Server on port :8080
Using scheduler: default-scheduler
2026/05/06 17:32:00 Serving HTTP API on :8080
2026/05/06 17:32:00 Fake Kubernetes API server ready for kube-scheduler connections
2026/05/06 17:32:00 Start kube-scheduler with: --master http://localhost:8080 --leader-elect=false
2026/05/06 17:32:01 Scheduling round reset
2026/05/06 17:32:01 {"action":"HandleReset","result":"ok","roundId":"-","ts":"2026-05-06T17:32:01.972413684+01:00"}
2026/05/06 17:32:05 Scheduling round reset
2026/05/06 17:32:05 {"action":"HandleReset","result":"ok","roundId":"-","ts":"2026-05-06T17:32:05.105629299+01:00"}
2026/05/06 17:32:05 Scheduling round reset
2026/05/06 17:32:05 {"action":"HandleReset","result":"ok","roundId":"-","ts":"2026-05-06T17:32:05.109017032+01:00"}
2026/05/06 17:32:10 {"action":"HandleNodes","durationMs":0,"nodeCount":3,"result":"ok","roundId":"0","ts":"2026-05-06T17:32:10.425317719+01:00"}
2026/05/06 17:32:10 {"action":"HandleSchedule","completedIds":0,"nodeCount":3,"phase":"start","podCount":12,"roundId":"1","ts":"2026-05-06T17:32:10.452209941+01:00"}
2026/05/06 17:32:10 {"action":"HandleSchedule","phase":"prep_done","podsCreated":12,"prepMs":0,"roundId":"1","staleDeleted":0,"ts":"2026-05-06T17:32:10.452566269+01:00"}
2026/05/06 17:32:10 Scheduling round started: expecting 12 decisions
2026/05/06 17:32:10 Parsed protobuf binding: pod=cspod-4 -> node=csnode-0
2026/05/06 17:32:10 Parsed protobuf binding: pod=cspod-3 -> node=csnode-1
2026/05/06 17:32:10 Parsed protobuf binding: pod=cspod-0 -> node=csnode-1
2026/05/06 17:32:10 Parsed protobuf binding: pod=cspod-2 -> node=csnode-0
2026/05/06 17:32:10 Parsed protobuf binding: pod=cspod-1 -> node=csnode-2
2026/05/06 17:32:10 Parsed protobuf binding: pod=cspod-5 -> node=csnode-2
2026/05/06 17:32:10 Binding: pod=cspod-4 -> node=csnode-0 (1/12 resolved)
2026/05/06 17:32:10 Binding: pod=cspod-0 -> node=csnode-1 (2/12 resolved)
2026/05/06 17:32:10 Binding: pod=cspod-5 -> node=csnode-2 (3/12 resolved)
2026/05/06 17:32:10 Binding: pod=cspod-3 -> node=csnode-1 (4/12 resolved)
2026/05/06 17:32:10 Binding: pod=cspod-2 -> node=csnode-0 (5/12 resolved)
2026/05/06 17:32:10 Binding: pod=cspod-1 -> node=csnode-2 (6/12 resolved)
2026/05/06 17:32:10 Failure: pod=cspod-6 reason="0/3 nodes are available: 3 Insufficient cpu. preemption: 0/3 nodes are available: 3 No preemption victims found for incoming pod." (7/12 resolved)
2026/05/06 17:32:10 Failure: pod=cspod-7 reason="0/3 nodes are available: 3 Insufficient cpu. preemption: 0/3 nodes are available: 3 No preemption victims found for incoming pod." (8/12 resolved)
2026/05/06 17:32:10 Failure: pod=cspod-8 reason="0/3 nodes are available: 3 Insufficient cpu. preemption: 0/3 nodes are available: 3 No preemption victims found for incoming pod." (9/12 resolved)
2026/05/06 17:32:10 Failure: pod=cspod-9 reason="0/3 nodes are available: 3 Insufficient cpu. preemption: 0/3 nodes are available: 3 No preemption victims found for incoming pod." (10/12 resolved)
2026/05/06 17:32:10 Failure: pod=cspod-10 reason="0/3 nodes are available: 3 Insufficient cpu. preemption: 0/3 nodes are available: 3 No preemption victims found for incoming pod." (11/12 resolved)
2026/05/06 17:32:10 Failure: pod=cspod-11 reason="0/3 nodes are available: 3 Insufficient cpu. preemption: 0/3 nodes are available: 3 No preemption victims found for incoming pod." (12/12 resolved)
2026/05/06 17:32:10 Round complete: 6 scheduled, 6 failed in 10.025363ms
2026/05/06 17:32:10 {"action":"HandleSchedule","durationMs":10,"podCount":12,"result":"ok","roundId":"1","scheduled":6,"ts":"2026-05-06T17:32:10.462738864+01:00","unschedulable":6}
2026/05/06 17:32:10 Scheduling round reset
2026/05/06 17:32:10 {"action":"HandleReset","result":"ok","roundId":"1","ts":"2026-05-06T17:32:10.500335164+01:00"}
