2026/05/09 14:10:55 Running command:
Command env: (log-file=, also-stdout=false, redirect-stderr=true)
Run from directory: 
Executable path: /usr/local/bin/kube-scheduler
Args (comma-delimited): kube-scheduler,--config=/etc/kube-scheduler/scheduler-config.yaml,--secure-port=10260,--v=2
2026/05/09 14:10:55 Now listening for interrupts
I0509 14:10:55.339839      12 flags.go:64] FLAG: --allow-metric-labels="[]"
I0509 14:10:55.339896      12 flags.go:64] FLAG: --allow-metric-labels-manifest=""
I0509 14:10:55.339902      12 flags.go:64] FLAG: --authentication-kubeconfig=""
I0509 14:10:55.339903      12 flags.go:64] FLAG: --authentication-skip-lookup="false"
I0509 14:10:55.339905      12 flags.go:64] FLAG: --authentication-token-webhook-cache-ttl="10s"
I0509 14:10:55.339907      12 flags.go:64] FLAG: --authentication-tolerate-lookup-failure="true"
I0509 14:10:55.339908      12 flags.go:64] FLAG: --authorization-always-allow-paths="[/healthz,/readyz,/livez]"
I0509 14:10:55.339931      12 flags.go:64] FLAG: --authorization-kubeconfig=""
I0509 14:10:55.339932      12 flags.go:64] FLAG: --authorization-webhook-cache-authorized-ttl="10s"
I0509 14:10:55.339933      12 flags.go:64] FLAG: --authorization-webhook-cache-unauthorized-ttl="10s"
I0509 14:10:55.339934      12 flags.go:64] FLAG: --bind-address="0.0.0.0"
I0509 14:10:55.339937      12 flags.go:64] FLAG: --cert-dir=""
I0509 14:10:55.339937      12 flags.go:64] FLAG: --client-ca-file=""
I0509 14:10:55.339938      12 flags.go:64] FLAG: --config="/etc/kube-scheduler/scheduler-config.yaml"
I0509 14:10:55.339939      12 flags.go:64] FLAG: --contention-profiling="true"
I0509 14:10:55.339940      12 flags.go:64] FLAG: --disable-http2-serving="false"
I0509 14:10:55.339941      12 flags.go:64] FLAG: --disabled-metrics="[]"
I0509 14:10:55.339944      12 flags.go:64] FLAG: --emulated-version="[]"
I0509 14:10:55.339949      12 flags.go:64] FLAG: --feature-gates=""
I0509 14:10:55.339953      12 flags.go:64] FLAG: --help="false"
I0509 14:10:55.339954      12 flags.go:64] FLAG: --http2-max-streams-per-connection="0"
I0509 14:10:55.339955      12 flags.go:64] FLAG: --kube-api-burst="100"
I0509 14:10:55.339957      12 flags.go:64] FLAG: --kube-api-content-type="application/vnd.kubernetes.protobuf"
I0509 14:10:55.339958      12 flags.go:64] FLAG: --kube-api-qps="50"
I0509 14:10:55.339960      12 flags.go:64] FLAG: --kubeconfig=""
I0509 14:10:55.339961      12 flags.go:64] FLAG: --leader-elect="true"
I0509 14:10:55.339962      12 flags.go:64] FLAG: --leader-elect-lease-duration="15s"
I0509 14:10:55.339962      12 flags.go:64] FLAG: --leader-elect-renew-deadline="10s"
I0509 14:10:55.339963      12 flags.go:64] FLAG: --leader-elect-resource-lock="leases"
I0509 14:10:55.339964      12 flags.go:64] FLAG: --leader-elect-resource-name="kube-scheduler"
I0509 14:10:55.339965      12 flags.go:64] FLAG: --leader-elect-resource-namespace="kube-system"
I0509 14:10:55.339966      12 flags.go:64] FLAG: --leader-elect-retry-period="2s"
I0509 14:10:55.339967      12 flags.go:64] FLAG: --log-flush-frequency="5s"
I0509 14:10:55.339968      12 flags.go:64] FLAG: --log-json-info-buffer-size="0"
I0509 14:10:55.339970      12 flags.go:64] FLAG: --log-json-split-stream="false"
I0509 14:10:55.339971      12 flags.go:64] FLAG: --log-text-info-buffer-size="0"
I0509 14:10:55.339972      12 flags.go:64] FLAG: --log-text-split-stream="false"
I0509 14:10:55.339973      12 flags.go:64] FLAG: --logging-format="text"
I0509 14:10:55.339974      12 flags.go:64] FLAG: --master=""
I0509 14:10:55.339975      12 flags.go:64] FLAG: --permit-address-sharing="false"
I0509 14:10:55.339975      12 flags.go:64] FLAG: --permit-port-sharing="false"
I0509 14:10:55.339976      12 flags.go:64] FLAG: --pod-max-in-unschedulable-pods-duration="5m0s"
I0509 14:10:55.339977      12 flags.go:64] FLAG: --profiling="true"
I0509 14:10:55.339978      12 flags.go:64] FLAG: --requestheader-allowed-names="[]"
I0509 14:10:55.339983      12 flags.go:64] FLAG: --requestheader-client-ca-file=""
I0509 14:10:55.339984      12 flags.go:64] FLAG: --requestheader-extra-headers-prefix="[x-remote-extra-]"
I0509 14:10:55.339985      12 flags.go:64] FLAG: --requestheader-group-headers="[x-remote-group]"
I0509 14:10:55.339989      12 flags.go:64] FLAG: --requestheader-uid-headers="[]"
I0509 14:10:55.339991      12 flags.go:64] FLAG: --requestheader-username-headers="[x-remote-user]"
I0509 14:10:55.339993      12 flags.go:64] FLAG: --secure-port="10260"
I0509 14:10:55.339994      12 flags.go:64] FLAG: --show-hidden-metrics-for-version=""
I0509 14:10:55.339997      12 flags.go:64] FLAG: --tls-cert-file=""
I0509 14:10:55.340020      12 flags.go:64] FLAG: --tls-cipher-suites="[]"
I0509 14:10:55.340032      12 flags.go:64] FLAG: --tls-min-version=""
I0509 14:10:55.340033      12 flags.go:64] FLAG: --tls-private-key-file=""
I0509 14:10:55.340034      12 flags.go:64] FLAG: --tls-sni-cert-key="[]"
I0509 14:10:55.340036      12 flags.go:64] FLAG: --v="2"
I0509 14:10:55.340039      12 flags.go:64] FLAG: --version="false"
I0509 14:10:55.340040      12 flags.go:64] FLAG: --vmodule=""
I0509 14:10:55.340041      12 flags.go:64] FLAG: --write-config-to=""
I0509 14:10:55.503503      12 serving.go:386] Generated self-signed cert in-memory
W0509 14:10:55.779592      12 authentication.go:368] No authentication-kubeconfig provided in order to lookup client-ca-file in configmap/extension-apiserver-authentication in kube-system, so client certificate authentication won't work.
W0509 14:10:55.779631      12 authentication.go:392] No authentication-kubeconfig provided in order to lookup requestheader-client-ca-file in configmap/extension-apiserver-authentication in kube-system, so request-header client certificate authentication won't work.
W0509 14:10:55.779667      12 authorization.go:193] No authorization-kubeconfig provided, so SubjectAccessReview of authorization tokens won't work.
I0509 14:10:55.781638      12 framework.go:399] "the scheduler starts to work with those plugins" Plugins={"PreEnqueue":{"Enabled":[{"Name":"SchedulingGates","Weight":0},{"Name":"DefaultPreemption","Weight":0}],"Disabled":null},"QueueSort":{"Enabled":[{"Name":"PrioritySort","Weight":0}],"Disabled":null},"PreFilter":{"Enabled":[{"Name":"NodeAffinity","Weight":0},{"Name":"NodePorts","Weight":0},{"Name":"NodeResourcesFit","Weight":0},{"Name":"VolumeRestrictions","Weight":0},{"Name":"NodeVolumeLimits","Weight":0},{"Name":"VolumeBinding","Weight":0},{"Name":"VolumeZone","Weight":0},{"Name":"PodTopologySpread","Weight":0},{"Name":"InterPodAffinity","Weight":0}],"Disabled":null},"Filter":{"Enabled":[{"Name":"NodeUnschedulable","Weight":0},{"Name":"NodeName","Weight":0},{"Name":"TaintToleration","Weight":0},{"Name":"NodeAffinity","Weight":0},{"Name":"NodePorts","Weight":0},{"Name":"NodeResourcesFit","Weight":0},{"Name":"VolumeRestrictions","Weight":0},{"Name":"NodeVolumeLimits","Weight":0},{"Name":"VolumeBinding","Weight":0},{"Name":"VolumeZone","Weight":0},{"Name":"PodTopologySpread","Weight":0},{"Name":"InterPodAffinity","Weight":0}],"Disabled":null},"PostFilter":{"Enabled":[{"Name":"DefaultPreemption","Weight":0}],"Disabled":null},"PreScore":{"Enabled":[{"Name":"TaintToleration","Weight":0},{"Name":"NodeAffinity","Weight":0},{"Name":"NodeResourcesFit","Weight":0},{"Name":"VolumeBinding","Weight":0},{"Name":"PodTopologySpread","Weight":0},{"Name":"InterPodAffinity","Weight":0},{"Name":"NodeResourcesBalancedAllocation","Weight":0}],"Disabled":null},"Score":{"Enabled":[{"Name":"NodeResourcesFit","Weight":1}],"Disabled":null},"Reserve":{"Enabled":[{"Name":"VolumeBinding","Weight":0}],"Disabled":null},"Permit":{"Enabled":null,"Disabled":null},"PreBind":{"Enabled":[{"Name":"VolumeBinding","Weight":0}],"Disabled":null},"Bind":{"Enabled":[{"Name":"DefaultBinder","Weight":0}],"Disabled":null},"PostBind":{"Enabled":null,"Disabled":null},"MultiPoint":{"Enabled":null,"Disabled":null}}
I0509 14:10:55.781817      12 framework.go:399] "the scheduler starts to work with those plugins" Plugins={"PreEnqueue":{"Enabled":[{"Name":"SchedulingGates","Weight":0},{"Name":"DefaultPreemption","Weight":0}],"Disabled":null},"QueueSort":{"Enabled":[{"Name":"PrioritySort","Weight":0}],"Disabled":null},"PreFilter":{"Enabled":[{"Name":"NodeAffinity","Weight":0},{"Name":"NodePorts","Weight":0},{"Name":"NodeResourcesFit","Weight":0},{"Name":"VolumeRestrictions","Weight":0},{"Name":"NodeVolumeLimits","Weight":0},{"Name":"VolumeBinding","Weight":0},{"Name":"VolumeZone","Weight":0},{"Name":"PodTopologySpread","Weight":0},{"Name":"InterPodAffinity","Weight":0}],"Disabled":null},"Filter":{"Enabled":[{"Name":"NodeUnschedulable","Weight":0},{"Name":"NodeName","Weight":0},{"Name":"TaintToleration","Weight":0},{"Name":"NodeAffinity","Weight":0},{"Name":"NodePorts","Weight":0},{"Name":"NodeResourcesFit","Weight":0},{"Name":"VolumeRestrictions","Weight":0},{"Name":"NodeVolumeLimits","Weight":0},{"Name":"VolumeBinding","Weight":0},{"Name":"VolumeZone","Weight":0},{"Name":"PodTopologySpread","Weight":0},{"Name":"InterPodAffinity","Weight":0}],"Disabled":null},"PostFilter":{"Enabled":[{"Name":"DefaultPreemption","Weight":0}],"Disabled":null},"PreScore":{"Enabled":[{"Name":"TaintToleration","Weight":0},{"Name":"NodeAffinity","Weight":0},{"Name":"NodeResourcesFit","Weight":0},{"Name":"VolumeBinding","Weight":0},{"Name":"PodTopologySpread","Weight":0},{"Name":"InterPodAffinity","Weight":0},{"Name":"NodeResourcesBalancedAllocation","Weight":0}],"Disabled":null},"Score":{"Enabled":[{"Name":"NodeResourcesFit","Weight":1}],"Disabled":null},"Reserve":{"Enabled":[{"Name":"VolumeBinding","Weight":0}],"Disabled":null},"Permit":{"Enabled":null,"Disabled":null},"PreBind":{"Enabled":[{"Name":"VolumeBinding","Weight":0}],"Disabled":null},"Bind":{"Enabled":[{"Name":"DefaultBinder","Weight":0}],"Disabled":null},"PostBind":{"Enabled":null,"Disabled":null},"MultiPoint":{"Enabled":null,"Disabled":null}}
I0509 14:10:55.783711      12 configfile.go:94] "Using component config" config=<
	apiVersion: kubescheduler.config.k8s.io/v1
	clientConnection:
	  acceptContentTypes: ""
	  burst: 100
	  contentType: application/vnd.kubernetes.protobuf
	  kubeconfig: /etc/kube-scheduler/kubeconfig.yaml
	  qps: 50
	enableContentionProfiling: true
	enableProfiling: true
	kind: KubeSchedulerConfiguration
	leaderElection:
	  leaderElect: false
	  leaseDuration: 15s
	  renewDeadline: 10s
	  resourceLock: leases
	  resourceName: kube-scheduler
	  resourceNamespace: kube-system
	  retryPeriod: 2s
	parallelism: 16
	percentageOfNodesToScore: 0
	podInitialBackoffSeconds: 1
	podMaxBackoffSeconds: 10
	profiles:
	- pluginConfig:
	  - args:
	      apiVersion: kubescheduler.config.k8s.io/v1
	      kind: DefaultPreemptionArgs
	      minCandidateNodesAbsolute: 100
	      minCandidateNodesPercentage: 10
	    name: DefaultPreemption
	  - args:
	      apiVersion: kubescheduler.config.k8s.io/v1
	      hardPodAffinityWeight: 1
	      ignorePreferredTermsOfExistingPods: false
	      kind: InterPodAffinityArgs
	    name: InterPodAffinity
	  - args:
	      apiVersion: kubescheduler.config.k8s.io/v1
	      kind: NodeAffinityArgs
	    name: NodeAffinity
	  - args:
	      apiVersion: kubescheduler.config.k8s.io/v1
	      kind: NodeResourcesBalancedAllocationArgs
	      resources:
	      - name: cpu
	        weight: 1
	      - name: memory
	        weight: 1
	    name: NodeResourcesBalancedAllocation
	  - args:
	      apiVersion: kubescheduler.config.k8s.io/v1
	      kind: NodeResourcesFitArgs
	      scoringStrategy:
	        resources:
	        - name: cpu
	          weight: 1
	        - name: memory
	          weight: 1
	        type: LeastAllocated
	    name: NodeResourcesFit
	  - args:
	      apiVersion: kubescheduler.config.k8s.io/v1
	      defaultingType: System
	      kind: PodTopologySpreadArgs
	    name: PodTopologySpread
	  - args:
	      apiVersion: kubescheduler.config.k8s.io/v1
	      bindTimeoutSeconds: 600
	      kind: VolumeBindingArgs
	    name: VolumeBinding
	  plugins:
	    bind: {}
	    filter: {}
	    multiPoint:
	      enabled:
	      - name: SchedulingGates
	        weight: 0
	      - name: PrioritySort
	        weight: 0
	      - name: NodeUnschedulable
	        weight: 0
	      - name: NodeName
	        weight: 0
	      - name: TaintToleration
	        weight: 3
	      - name: NodeAffinity
	        weight: 2
	      - name: NodePorts
	        weight: 0
	      - name: NodeResourcesFit
	        weight: 1
	      - name: VolumeRestrictions
	        weight: 0
	      - name: NodeVolumeLimits
	        weight: 0
	      - name: VolumeBinding
	        weight: 0
	      - name: VolumeZone
	        weight: 0
	      - name: PodTopologySpread
	        weight: 2
	      - name: InterPodAffinity
	        weight: 2
	      - name: DefaultPreemption
	        weight: 0
	      - name: NodeResourcesBalancedAllocation
	        weight: 1
	      - name: ImageLocality
	        weight: 1
	      - name: DefaultBinder
	        weight: 0
	    permit: {}
	    postBind: {}
	    postFilter: {}
	    preBind: {}
	    preEnqueue: {}
	    preFilter: {}
	    preScore: {}
	    queueSort: {}
	    reserve: {}
	    score:
	      disabled:
	      - name: '*'
	        weight: 0
	      enabled:
	      - name: NodeResourcesFit
	        weight: 0
	  schedulerName: least-allocated
	- pluginConfig:
	  - args:
	      apiVersion: kubescheduler.config.k8s.io/v1
	      kind: DefaultPreemptionArgs
	      minCandidateNodesAbsolute: 100
	      minCandidateNodesPercentage: 10
	    name: DefaultPreemption
	  - args:
	      apiVersion: kubescheduler.config.k8s.io/v1
	      hardPodAffinityWeight: 1
	      ignorePreferredTermsOfExistingPods: false
	      kind: InterPodAffinityArgs
	    name: InterPodAffinity
	  - args:
	      apiVersion: kubescheduler.config.k8s.io/v1
	      kind: NodeAffinityArgs
	    name: NodeAffinity
	  - args:
	      apiVersion: kubescheduler.config.k8s.io/v1
	      kind: NodeResourcesBalancedAllocationArgs
	      resources:
	      - name: cpu
	        weight: 1
	      - name: memory
	        weight: 1
	    name: NodeResourcesBalancedAllocation
	  - args:
	      apiVersion: kubescheduler.config.k8s.io/v1
	      kind: NodeResourcesFitArgs
	      scoringStrategy:
	        resources:
	        - name: cpu
	          weight: 1
	        - name: memory
	          weight: 1
	        type: MostAllocated
	    name: NodeResourcesFit
	  - args:
	      apiVersion: kubescheduler.config.k8s.io/v1
	      defaultingType: System
	      kind: PodTopologySpreadArgs
	    name: PodTopologySpread
	  - args:
	      apiVersion: kubescheduler.config.k8s.io/v1
	      bindTimeoutSeconds: 600
	      kind: VolumeBindingArgs
	    name: VolumeBinding
	  plugins:
	    bind: {}
	    filter: {}
	    multiPoint:
	      enabled:
	      - name: SchedulingGates
	        weight: 0
	      - name: PrioritySort
	        weight: 0
	      - name: NodeUnschedulable
	        weight: 0
	      - name: NodeName
	        weight: 0
	      - name: TaintToleration
	        weight: 3
	      - name: NodeAffinity
	        weight: 2
	      - name: NodePorts
	        weight: 0
	      - name: NodeResourcesFit
	        weight: 1
	      - name: VolumeRestrictions
	        weight: 0
	      - name: NodeVolumeLimits
	        weight: 0
	      - name: VolumeBinding
	        weight: 0
	      - name: VolumeZone
	        weight: 0
	      - name: PodTopologySpread
	        weight: 2
	      - name: InterPodAffinity
	        weight: 2
	      - name: DefaultPreemption
	        weight: 0
	      - name: NodeResourcesBalancedAllocation
	        weight: 1
	      - name: ImageLocality
	        weight: 1
	      - name: DefaultBinder
	        weight: 0
	    permit: {}
	    postBind: {}
	    postFilter: {}
	    preBind: {}
	    preEnqueue: {}
	    preFilter: {}
	    preScore: {}
	    queueSort: {}
	    reserve: {}
	    score:
	      disabled:
	      - name: '*'
	        weight: 0
	      enabled:
	      - name: NodeResourcesFit
	        weight: 0
	  schedulerName: most-allocated
 >
I0509 14:10:55.784396      12 server.go:171] "Starting Kubernetes Scheduler" version="v1.33.0"
I0509 14:10:55.784424      12 server.go:173] "Golang settings" GOGC="" GOMAXPROCS="" GOTRACEBACK=""
I0509 14:10:55.785450      12 tlsconfig.go:203] "Loaded serving cert" certName="Generated self signed cert" certDetail="\"localhost@1778335855\" [serving] validServingFor=[127.0.0.1,localhost,localhost] issuer=\"localhost-ca@1778335855\" (2026-05-09 13:10:55 +0000 UTC to 2027-05-09 13:10:55 +0000 UTC (now=2026-05-09 14:10:55.785438789 +0000 UTC))"
I0509 14:10:55.785549      12 named_certificates.go:53] "Loaded SNI cert" index=0 certName="self-signed loopback" certDetail="\"apiserver-loopback-client@1778335855\" [serving] validServingFor=[apiserver-loopback-client] issuer=\"apiserver-loopback-client-ca@1778335855\" (2026-05-09 13:10:55 +0000 UTC to 2029-05-09 13:10:55 +0000 UTC (now=2026-05-09 14:10:55.785543352 +0000 UTC))"
I0509 14:10:55.785607      12 secure_serving.go:211] Serving securely on [::]:10260
I0509 14:10:55.785683      12 tlsconfig.go:243] "Starting DynamicServingCertificateController"
I0509 14:10:55.786892      12 reflector.go:430] "Caches populated" type="*v1.CSIDriver" reflector="k8s.io/client-go/informers/factory.go:160"
I0509 14:10:55.786917      12 reflector.go:430] "Caches populated" type="*v1.StorageClass" reflector="k8s.io/client-go/informers/factory.go:160"
I0509 14:10:55.786960      12 reflector.go:430] "Caches populated" type="*v1.CSIStorageCapacity" reflector="k8s.io/client-go/informers/factory.go:160"
I0509 14:10:55.786980      12 reflector.go:430] "Caches populated" type="*v1.Node" reflector="k8s.io/client-go/informers/factory.go:160"
I0509 14:10:55.786985      12 reflector.go:430] "Caches populated" type="*v1.CSINode" reflector="k8s.io/client-go/informers/factory.go:160"
I0509 14:10:55.787166      12 reflector.go:430] "Caches populated" type="*v1.VolumeAttachment" reflector="k8s.io/client-go/informers/factory.go:160"
I0509 14:10:55.787479      12 reflector.go:430] "Caches populated" type="*v1.ReplicaSet" reflector="k8s.io/client-go/informers/factory.go:160"
I0509 14:10:55.788084      12 reflector.go:430] "Caches populated" type="*v1.ReplicationController" reflector="k8s.io/client-go/informers/factory.go:160"
I0509 14:10:55.788562      12 reflector.go:430] "Caches populated" type="*v1.PodDisruptionBudget" reflector="k8s.io/client-go/informers/factory.go:160"
I0509 14:10:55.788594      12 reflector.go:430] "Caches populated" type="*v1.StatefulSet" reflector="k8s.io/client-go/informers/factory.go:160"
I0509 14:10:55.788663      12 reflector.go:430] "Caches populated" type="*v1.Namespace" reflector="k8s.io/client-go/informers/factory.go:160"
I0509 14:10:55.788735      12 reflector.go:430] "Caches populated" type="*v1.PersistentVolumeClaim" reflector="k8s.io/client-go/informers/factory.go:160"
I0509 14:10:55.789428      12 reflector.go:430] "Caches populated" type="*v1.Service" reflector="k8s.io/client-go/informers/factory.go:160"
I0509 14:10:55.789663      12 reflector.go:430] "Caches populated" type="*v1.PersistentVolume" reflector="k8s.io/client-go/informers/factory.go:160"
I0509 14:10:55.789896      12 reflector.go:430] "Caches populated" type="*v1.Pod" reflector="k8s.io/client-go/informers/factory.go:160"
I0509 14:11:02.142955      12 node_tree.go:65] "Added node to NodeTree" node="csnode-0" zone=""
I0509 14:11:02.143017      12 node_tree.go:65] "Added node to NodeTree" node="csnode-1" zone=""
I0509 14:11:02.143030      12 node_tree.go:65] "Added node to NodeTree" node="csnode-2" zone=""
I0509 14:11:02.143034      12 node_tree.go:65] "Added node to NodeTree" node="csnode-3" zone=""
I0509 14:11:02.143038      12 node_tree.go:65] "Added node to NodeTree" node="csnode-4" zone=""
I0509 14:11:02.168370      12 preemption.go:264] "No preemption candidate is found; preemption is not helpful for scheduling" pod="default/cspod-10"
I0509 14:11:02.168424      12 schedule_one.go:1044] "Unable to schedule pod; no fit; waiting" pod="default/cspod-10" err="0/5 nodes are available: 5 Insufficient cpu. preemption: 0/5 nodes are available: 5 No preemption victims found for incoming pod."
I0509 14:11:02.169119      12 schedule_one.go:314] "Successfully bound pod to node" pod="default/cspod-0" node="csnode-0" evaluatedNodes=5 feasibleNodes=5
I0509 14:11:02.169206      12 schedule_one.go:314] "Successfully bound pod to node" pod="default/cspod-1" node="csnode-0" evaluatedNodes=5 feasibleNodes=5
I0509 14:11:02.169236      12 schedule_one.go:314] "Successfully bound pod to node" pod="default/cspod-5" node="csnode-1" evaluatedNodes=5 feasibleNodes=3
I0509 14:11:02.169319      12 schedule_one.go:314] "Successfully bound pod to node" pod="default/cspod-8" node="csnode-2" evaluatedNodes=5 feasibleNodes=1
I0509 14:11:02.169334      12 schedule_one.go:314] "Successfully bound pod to node" pod="default/cspod-4" node="csnode-1" evaluatedNodes=5 feasibleNodes=3
I0509 14:11:02.169367      12 schedule_one.go:314] "Successfully bound pod to node" pod="default/cspod-3" node="csnode-3" evaluatedNodes=5 feasibleNodes=4
I0509 14:11:02.169396      12 schedule_one.go:314] "Successfully bound pod to node" pod="default/cspod-7" node="csnode-4" evaluatedNodes=5 feasibleNodes=2
I0509 14:11:02.169485      12 schedule_one.go:314] "Successfully bound pod to node" pod="default/cspod-2" node="csnode-3" evaluatedNodes=5 feasibleNodes=4
I0509 14:11:02.169520      12 schedule_one.go:314] "Successfully bound pod to node" pod="default/cspod-9" node="csnode-2" evaluatedNodes=5 feasibleNodes=1
I0509 14:11:02.169522      12 schedule_one.go:314] "Successfully bound pod to node" pod="default/cspod-6" node="csnode-4" evaluatedNodes=5 feasibleNodes=2
E0509 14:11:02.169580      12 event.go:368] "Unable to write event (may retry after sleeping)" err="0-length response with status code: 201 and content type: application/vnd.kubernetes.protobuf" event="&Event{ObjectMeta:{cspod-10.18adeb0b6be395e6  default    0 0001-01-01 00:00:00 +0000 UTC <nil> <nil> map[] map[] [] [] []},InvolvedObject:ObjectReference{Kind:Pod,Namespace:default,Name:cspod-10,UID:cspod-10-uid,APIVersion:v1,ResourceVersion:16,FieldPath:,},Reason:FailedScheduling,Message:0/5 nodes are available: 5 Insufficient cpu. preemption: 0/5 nodes are available: 5 No preemption victims found for incoming pod.,Source:EventSource{Component:most-allocated,Host:,},FirstTimestamp:2026-05-09 14:11:02.168458726 +0000 UTC m=+6.851560157,LastTimestamp:2026-05-09 14:11:02.168458726 +0000 UTC m=+6.851560157,Count:1,Type:Warning,EventTime:0001-01-01 00:00:00 +0000 UTC,Series:nil,Action:,Related:nil,ReportingController:most-allocated,ReportingInstance:,}"
I0509 14:11:02.169896      12 preemption.go:264] "No preemption candidate is found; preemption is not helpful for scheduling" pod="default/cspod-11"
I0509 14:11:02.169932      12 schedule_one.go:1044] "Unable to schedule pod; no fit; waiting" pod="default/cspod-11" err="0/5 nodes are available: 5 Insufficient cpu. preemption: 0/5 nodes are available: 5 No preemption victims found for incoming pod."
I0509 14:11:02.170539      12 preemption.go:264] "No preemption candidate is found; preemption is not helpful for scheduling" pod="default/cspod-12"
I0509 14:11:02.170574      12 schedule_one.go:1044] "Unable to schedule pod; no fit; waiting" pod="default/cspod-12" err="0/5 nodes are available: 5 Insufficient cpu. preemption: 0/5 nodes are available: 5 No preemption victims found for incoming pod."
I0509 14:11:02.171092      12 preemption.go:264] "No preemption candidate is found; preemption is not helpful for scheduling" pod="default/cspod-13"
I0509 14:11:02.171127      12 schedule_one.go:1044] "Unable to schedule pod; no fit; waiting" pod="default/cspod-13" err="0/5 nodes are available: 5 Insufficient cpu. preemption: 0/5 nodes are available: 5 No preemption victims found for incoming pod."
I0509 14:11:02.171747      12 preemption.go:264] "No preemption candidate is found; preemption is not helpful for scheduling" pod="default/cspod-14"
I0509 14:11:02.171780      12 schedule_one.go:1044] "Unable to schedule pod; no fit; waiting" pod="default/cspod-14" err="0/5 nodes are available: 5 Insufficient cpu. preemption: 0/5 nodes are available: 5 No preemption victims found for incoming pod."
I0509 14:11:02.172339      12 preemption.go:264] "No preemption candidate is found; preemption is not helpful for scheduling" pod="default/cspod-15"
I0509 14:11:02.172371      12 schedule_one.go:1044] "Unable to schedule pod; no fit; waiting" pod="default/cspod-15" err="0/5 nodes are available: 5 Insufficient cpu. preemption: 0/5 nodes are available: 5 No preemption victims found for incoming pod."
I0509 14:11:02.172879      12 preemption.go:264] "No preemption candidate is found; preemption is not helpful for scheduling" pod="default/cspod-16"
I0509 14:11:02.172925      12 schedule_one.go:1044] "Unable to schedule pod; no fit; waiting" pod="default/cspod-16" err="0/5 nodes are available: 5 Insufficient cpu. preemption: 0/5 nodes are available: 5 No preemption victims found for incoming pod."
I0509 14:11:02.173625      12 preemption.go:264] "No preemption candidate is found; preemption is not helpful for scheduling" pod="default/cspod-17"
I0509 14:11:02.173658      12 schedule_one.go:1044] "Unable to schedule pod; no fit; waiting" pod="default/cspod-17" err="0/5 nodes are available: 5 Insufficient cpu. preemption: 0/5 nodes are available: 5 No preemption victims found for incoming pod."
I0509 14:11:02.174147      12 preemption.go:264] "No preemption candidate is found; preemption is not helpful for scheduling" pod="default/cspod-18"
I0509 14:11:02.174180      12 schedule_one.go:1044] "Unable to schedule pod; no fit; waiting" pod="default/cspod-18" err="0/5 nodes are available: 5 Insufficient cpu. preemption: 0/5 nodes are available: 5 No preemption victims found for incoming pod."
I0509 14:11:02.174717      12 preemption.go:264] "No preemption candidate is found; preemption is not helpful for scheduling" pod="default/cspod-19"
I0509 14:11:02.174751      12 schedule_one.go:1044] "Unable to schedule pod; no fit; waiting" pod="default/cspod-19" err="0/5 nodes are available: 5 Insufficient cpu. preemption: 0/5 nodes are available: 5 No preemption victims found for incoming pod."
I0509 14:11:02.175262      12 preemption.go:264] "No preemption candidate is found; preemption is not helpful for scheduling" pod="default/cspod-20"
I0509 14:11:02.175294      12 schedule_one.go:1044] "Unable to schedule pod; no fit; waiting" pod="default/cspod-20" err="0/5 nodes are available: 5 Insufficient cpu. preemption: 0/5 nodes are available: 5 No preemption victims found for incoming pod."
I0509 14:11:02.175800      12 preemption.go:264] "No preemption candidate is found; preemption is not helpful for scheduling" pod="default/cspod-21"
I0509 14:11:02.175831      12 schedule_one.go:1044] "Unable to schedule pod; no fit; waiting" pod="default/cspod-21" err="0/5 nodes are available: 5 Insufficient cpu. preemption: 0/5 nodes are available: 5 No preemption victims found for incoming pod."
I0509 14:11:02.176279      12 preemption.go:264] "No preemption candidate is found; preemption is not helpful for scheduling" pod="default/cspod-22"
I0509 14:11:02.176309      12 schedule_one.go:1044] "Unable to schedule pod; no fit; waiting" pod="default/cspod-22" err="0/5 nodes are available: 5 Insufficient cpu. preemption: 0/5 nodes are available: 5 No preemption victims found for incoming pod."
I0509 14:11:02.176783      12 preemption.go:264] "No preemption candidate is found; preemption is not helpful for scheduling" pod="default/cspod-23"
I0509 14:11:02.176815      12 schedule_one.go:1044] "Unable to schedule pod; no fit; waiting" pod="default/cspod-23" err="0/5 nodes are available: 5 Insufficient cpu. preemption: 0/5 nodes are available: 5 No preemption victims found for incoming pod."
I0509 14:11:02.177281      12 preemption.go:264] "No preemption candidate is found; preemption is not helpful for scheduling" pod="default/cspod-24"
I0509 14:11:02.177317      12 schedule_one.go:1044] "Unable to schedule pod; no fit; waiting" pod="default/cspod-24" err="0/5 nodes are available: 5 Insufficient cpu. preemption: 0/5 nodes are available: 5 No preemption victims found for incoming pod."
I0509 14:11:02.177793      12 preemption.go:264] "No preemption candidate is found; preemption is not helpful for scheduling" pod="default/cspod-25"
I0509 14:11:02.177828      12 schedule_one.go:1044] "Unable to schedule pod; no fit; waiting" pod="default/cspod-25" err="0/5 nodes are available: 5 Insufficient cpu. preemption: 0/5 nodes are available: 5 No preemption victims found for incoming pod."
I0509 14:11:02.178389      12 preemption.go:264] "No preemption candidate is found; preemption is not helpful for scheduling" pod="default/cspod-26"
I0509 14:11:02.178426      12 schedule_one.go:1044] "Unable to schedule pod; no fit; waiting" pod="default/cspod-26" err="0/5 nodes are available: 5 Insufficient cpu. preemption: 0/5 nodes are available: 5 No preemption victims found for incoming pod."
I0509 14:11:02.178993      12 preemption.go:264] "No preemption candidate is found; preemption is not helpful for scheduling" pod="default/cspod-27"
I0509 14:11:02.179026      12 schedule_one.go:1044] "Unable to schedule pod; no fit; waiting" pod="default/cspod-27" err="0/5 nodes are available: 5 Insufficient cpu. preemption: 0/5 nodes are available: 5 No preemption victims found for incoming pod."
I0509 14:11:02.179597      12 preemption.go:264] "No preemption candidate is found; preemption is not helpful for scheduling" pod="default/cspod-28"
I0509 14:11:02.179628      12 schedule_one.go:1044] "Unable to schedule pod; no fit; waiting" pod="default/cspod-28" err="0/5 nodes are available: 5 Insufficient cpu. preemption: 0/5 nodes are available: 5 No preemption victims found for incoming pod."
I0509 14:11:02.180171      12 preemption.go:264] "No preemption candidate is found; preemption is not helpful for scheduling" pod="default/cspod-29"
I0509 14:11:02.180202      12 schedule_one.go:1044] "Unable to schedule pod; no fit; waiting" pod="default/cspod-29" err="0/5 nodes are available: 5 Insufficient cpu. preemption: 0/5 nodes are available: 5 No preemption victims found for incoming pod."
I0509 14:11:02.180708      12 preemption.go:264] "No preemption candidate is found; preemption is not helpful for scheduling" pod="default/cspod-30"
I0509 14:11:02.180742      12 schedule_one.go:1044] "Unable to schedule pod; no fit; waiting" pod="default/cspod-30" err="0/5 nodes are available: 5 Insufficient cpu. preemption: 0/5 nodes are available: 5 No preemption victims found for incoming pod."
I0509 14:11:02.181258      12 preemption.go:264] "No preemption candidate is found; preemption is not helpful for scheduling" pod="default/cspod-31"
I0509 14:11:02.181288      12 schedule_one.go:1044] "Unable to schedule pod; no fit; waiting" pod="default/cspod-31" err="0/5 nodes are available: 5 Insufficient cpu. preemption: 0/5 nodes are available: 5 No preemption victims found for incoming pod."
I0509 14:11:02.181792      12 preemption.go:264] "No preemption candidate is found; preemption is not helpful for scheduling" pod="default/cspod-32"
I0509 14:11:02.181823      12 schedule_one.go:1044] "Unable to schedule pod; no fit; waiting" pod="default/cspod-32" err="0/5 nodes are available: 5 Insufficient cpu. preemption: 0/5 nodes are available: 5 No preemption victims found for incoming pod."
I0509 14:11:02.182309      12 preemption.go:264] "No preemption candidate is found; preemption is not helpful for scheduling" pod="default/cspod-33"
I0509 14:11:02.182342      12 schedule_one.go:1044] "Unable to schedule pod; no fit; waiting" pod="default/cspod-33" err="0/5 nodes are available: 5 Insufficient cpu. preemption: 0/5 nodes are available: 5 No preemption victims found for incoming pod."
I0509 14:11:02.182831      12 preemption.go:264] "No preemption candidate is found; preemption is not helpful for scheduling" pod="default/cspod-34"
I0509 14:11:02.182861      12 schedule_one.go:1044] "Unable to schedule pod; no fit; waiting" pod="default/cspod-34" err="0/5 nodes are available: 5 Insufficient cpu. preemption: 0/5 nodes are available: 5 No preemption victims found for incoming pod."
I0509 14:11:02.183409      12 preemption.go:264] "No preemption candidate is found; preemption is not helpful for scheduling" pod="default/cspod-35"
I0509 14:11:02.183442      12 schedule_one.go:1044] "Unable to schedule pod; no fit; waiting" pod="default/cspod-35" err="0/5 nodes are available: 5 Insufficient cpu. preemption: 0/5 nodes are available: 5 No preemption victims found for incoming pod."
I0509 14:11:02.183901      12 preemption.go:264] "No preemption candidate is found; preemption is not helpful for scheduling" pod="default/cspod-36"
I0509 14:11:02.183931      12 schedule_one.go:1044] "Unable to schedule pod; no fit; waiting" pod="default/cspod-36" err="0/5 nodes are available: 5 Insufficient cpu. preemption: 0/5 nodes are available: 5 No preemption victims found for incoming pod."
I0509 14:11:02.275507      12 preemption.go:264] "No preemption candidate is found; preemption is not helpful for scheduling" pod="default/cspod-37"
I0509 14:11:02.275545      12 schedule_one.go:1044] "Unable to schedule pod; no fit; waiting" pod="default/cspod-37" err="0/5 nodes are available: 5 Insufficient cpu. preemption: 0/5 nodes are available: 5 No preemption victims found for incoming pod."
I0509 14:11:02.276177      12 preemption.go:264] "No preemption candidate is found; preemption is not helpful for scheduling" pod="default/cspod-38"
I0509 14:11:02.276212      12 schedule_one.go:1044] "Unable to schedule pod; no fit; waiting" pod="default/cspod-38" err="0/5 nodes are available: 5 Insufficient cpu. preemption: 0/5 nodes are available: 5 No preemption victims found for incoming pod."
I0509 14:11:02.276733      12 preemption.go:264] "No preemption candidate is found; preemption is not helpful for scheduling" pod="default/cspod-39"
I0509 14:11:02.276764      12 schedule_one.go:1044] "Unable to schedule pod; no fit; waiting" pod="default/cspod-39" err="0/5 nodes are available: 5 Insufficient cpu. preemption: 0/5 nodes are available: 5 No preemption victims found for incoming pod."
I0509 14:11:02.277823      12 preemption.go:264] "No preemption candidate is found; preemption is not helpful for scheduling" pod="default/cspod-40"
I0509 14:11:02.277956      12 schedule_one.go:1044] "Unable to schedule pod; no fit; waiting" pod="default/cspod-40" err="0/5 nodes are available: 5 Insufficient cpu. preemption: 0/5 nodes are available: 5 No preemption victims found for incoming pod."
I0509 14:11:02.278508      12 preemption.go:264] "No preemption candidate is found; preemption is not helpful for scheduling" pod="default/cspod-41"
I0509 14:11:02.278537      12 schedule_one.go:1044] "Unable to schedule pod; no fit; waiting" pod="default/cspod-41" err="0/5 nodes are available: 5 Insufficient cpu. preemption: 0/5 nodes are available: 5 No preemption victims found for incoming pod."
I0509 14:11:02.279009      12 preemption.go:264] "No preemption candidate is found; preemption is not helpful for scheduling" pod="default/cspod-42"
I0509 14:11:02.279025      12 schedule_one.go:1044] "Unable to schedule pod; no fit; waiting" pod="default/cspod-42" err="0/5 nodes are available: 5 Insufficient cpu. preemption: 0/5 nodes are available: 5 No preemption victims found for incoming pod."
I0509 14:11:02.279484      12 preemption.go:264] "No preemption candidate is found; preemption is not helpful for scheduling" pod="default/cspod-43"
I0509 14:11:02.279517      12 schedule_one.go:1044] "Unable to schedule pod; no fit; waiting" pod="default/cspod-43" err="0/5 nodes are available: 5 Insufficient cpu. preemption: 0/5 nodes are available: 5 No preemption victims found for incoming pod."
I0509 14:11:02.279972      12 preemption.go:264] "No preemption candidate is found; preemption is not helpful for scheduling" pod="default/cspod-44"
I0509 14:11:02.280005      12 schedule_one.go:1044] "Unable to schedule pod; no fit; waiting" pod="default/cspod-44" err="0/5 nodes are available: 5 Insufficient cpu. preemption: 0/5 nodes are available: 5 No preemption victims found for incoming pod."
I0509 14:11:02.280480      12 preemption.go:264] "No preemption candidate is found; preemption is not helpful for scheduling" pod="default/cspod-45"
I0509 14:11:02.280511      12 schedule_one.go:1044] "Unable to schedule pod; no fit; waiting" pod="default/cspod-45" err="0/5 nodes are available: 5 Insufficient cpu. preemption: 0/5 nodes are available: 5 No preemption victims found for incoming pod."
I0509 14:11:02.280997      12 preemption.go:264] "No preemption candidate is found; preemption is not helpful for scheduling" pod="default/cspod-46"
I0509 14:11:02.281029      12 schedule_one.go:1044] "Unable to schedule pod; no fit; waiting" pod="default/cspod-46" err="0/5 nodes are available: 5 Insufficient cpu. preemption: 0/5 nodes are available: 5 No preemption victims found for incoming pod."
I0509 14:11:02.281443      12 preemption.go:264] "No preemption candidate is found; preemption is not helpful for scheduling" pod="default/cspod-47"
I0509 14:11:02.281473      12 schedule_one.go:1044] "Unable to schedule pod; no fit; waiting" pod="default/cspod-47" err="0/5 nodes are available: 5 Insufficient cpu. preemption: 0/5 nodes are available: 5 No preemption victims found for incoming pod."
I0509 14:11:02.281925      12 preemption.go:264] "No preemption candidate is found; preemption is not helpful for scheduling" pod="default/cspod-48"
I0509 14:11:02.281955      12 schedule_one.go:1044] "Unable to schedule pod; no fit; waiting" pod="default/cspod-48" err="0/5 nodes are available: 5 Insufficient cpu. preemption: 0/5 nodes are available: 5 No preemption victims found for incoming pod."
I0509 14:11:02.282498      12 preemption.go:264] "No preemption candidate is found; preemption is not helpful for scheduling" pod="default/cspod-49"
I0509 14:11:02.282554      12 schedule_one.go:1044] "Unable to schedule pod; no fit; waiting" pod="default/cspod-49" err="0/5 nodes are available: 5 Insufficient cpu. preemption: 0/5 nodes are available: 5 No preemption victims found for incoming pod."
I0509 14:11:02.283133      12 preemption.go:264] "No preemption candidate is found; preemption is not helpful for scheduling" pod="default/cspod-50"
I0509 14:11:02.283166      12 schedule_one.go:1044] "Unable to schedule pod; no fit; waiting" pod="default/cspod-50" err="0/5 nodes are available: 5 Insufficient cpu. preemption: 0/5 nodes are available: 5 No preemption victims found for incoming pod."
I0509 14:11:02.283670      12 preemption.go:264] "No preemption candidate is found; preemption is not helpful for scheduling" pod="default/cspod-51"
I0509 14:11:02.283707      12 schedule_one.go:1044] "Unable to schedule pod; no fit; waiting" pod="default/cspod-51" err="0/5 nodes are available: 5 Insufficient cpu. preemption: 0/5 nodes are available: 5 No preemption victims found for incoming pod."
I0509 14:11:02.284168      12 preemption.go:264] "No preemption candidate is found; preemption is not helpful for scheduling" pod="default/cspod-52"
I0509 14:11:02.284205      12 schedule_one.go:1044] "Unable to schedule pod; no fit; waiting" pod="default/cspod-52" err="0/5 nodes are available: 5 Insufficient cpu. preemption: 0/5 nodes are available: 5 No preemption victims found for incoming pod."
I0509 14:11:02.284650      12 preemption.go:264] "No preemption candidate is found; preemption is not helpful for scheduling" pod="default/cspod-53"
I0509 14:11:02.284682      12 schedule_one.go:1044] "Unable to schedule pod; no fit; waiting" pod="default/cspod-53" err="0/5 nodes are available: 5 Insufficient cpu. preemption: 0/5 nodes are available: 5 No preemption victims found for incoming pod."
I0509 14:11:02.285129      12 preemption.go:264] "No preemption candidate is found; preemption is not helpful for scheduling" pod="default/cspod-54"
I0509 14:11:02.285160      12 schedule_one.go:1044] "Unable to schedule pod; no fit; waiting" pod="default/cspod-54" err="0/5 nodes are available: 5 Insufficient cpu. preemption: 0/5 nodes are available: 5 No preemption victims found for incoming pod."
I0509 14:11:02.309523      12 schedule_one.go:314] "Successfully bound pod to node" pod="default/cspod-55" node="csnode-1" evaluatedNodes=5 feasibleNodes=5
I0509 14:11:02.309667      12 schedule_one.go:314] "Successfully bound pod to node" pod="default/cspod-56" node="csnode-3" evaluatedNodes=5 feasibleNodes=4
I0509 14:11:02.309852      12 schedule_one.go:314] "Successfully bound pod to node" pod="default/cspod-58" node="csnode-4" evaluatedNodes=5 feasibleNodes=2
I0509 14:11:02.309948      12 preemption.go:264] "No preemption candidate is found; preemption is not helpful for scheduling" pod="default/cspod-60"
I0509 14:11:02.309965      12 schedule_one.go:1044] "Unable to schedule pod; no fit; waiting" pod="default/cspod-60" err="0/5 nodes are available: 5 Insufficient cpu. preemption: 0/5 nodes are available: 5 No preemption victims found for incoming pod."
I0509 14:11:02.309999      12 schedule_one.go:314] "Successfully bound pod to node" pod="default/cspod-57" node="csnode-0" evaluatedNodes=5 feasibleNodes=3
I0509 14:11:02.310149      12 schedule_one.go:314] "Successfully bound pod to node" pod="default/cspod-59" node="csnode-2" evaluatedNodes=5 feasibleNodes=1
I0509 14:11:02.310550      12 preemption.go:264] "No preemption candidate is found; preemption is not helpful for scheduling" pod="default/cspod-61"
I0509 14:11:02.310588      12 schedule_one.go:1044] "Unable to schedule pod; no fit; waiting" pod="default/cspod-61" err="0/5 nodes are available: 5 Insufficient cpu. preemption: 0/5 nodes are available: 5 No preemption victims found for incoming pod."
I0509 14:11:02.311106      12 preemption.go:264] "No preemption candidate is found; preemption is not helpful for scheduling" pod="default/cspod-62"
I0509 14:11:02.311143      12 schedule_one.go:1044] "Unable to schedule pod; no fit; waiting" pod="default/cspod-62" err="0/5 nodes are available: 5 Insufficient cpu. preemption: 0/5 nodes are available: 5 No preemption victims found for incoming pod."
I0509 14:11:02.311637      12 preemption.go:264] "No preemption candidate is found; preemption is not helpful for scheduling" pod="default/cspod-63"
I0509 14:11:02.311669      12 schedule_one.go:1044] "Unable to schedule pod; no fit; waiting" pod="default/cspod-63" err="0/5 nodes are available: 5 Insufficient cpu. preemption: 0/5 nodes are available: 5 No preemption victims found for incoming pod."
I0509 14:11:02.312164      12 preemption.go:264] "No preemption candidate is found; preemption is not helpful for scheduling" pod="default/cspod-64"
I0509 14:11:02.312197      12 schedule_one.go:1044] "Unable to schedule pod; no fit; waiting" pod="default/cspod-64" err="0/5 nodes are available: 5 Insufficient cpu. preemption: 0/5 nodes are available: 5 No preemption victims found for incoming pod."
I0509 14:11:02.312646      12 preemption.go:264] "No preemption candidate is found; preemption is not helpful for scheduling" pod="default/cspod-65"
I0509 14:11:02.312677      12 schedule_one.go:1044] "Unable to schedule pod; no fit; waiting" pod="default/cspod-65" err="0/5 nodes are available: 5 Insufficient cpu. preemption: 0/5 nodes are available: 5 No preemption victims found for incoming pod."
I0509 14:11:02.313113      12 preemption.go:264] "No preemption candidate is found; preemption is not helpful for scheduling" pod="default/cspod-66"
I0509 14:11:02.313144      12 schedule_one.go:1044] "Unable to schedule pod; no fit; waiting" pod="default/cspod-66" err="0/5 nodes are available: 5 Insufficient cpu. preemption: 0/5 nodes are available: 5 No preemption victims found for incoming pod."
I0509 14:11:02.313634      12 preemption.go:264] "No preemption candidate is found; preemption is not helpful for scheduling" pod="default/cspod-67"
I0509 14:11:02.313667      12 schedule_one.go:1044] "Unable to schedule pod; no fit; waiting" pod="default/cspod-67" err="0/5 nodes are available: 5 Insufficient cpu. preemption: 0/5 nodes are available: 5 No preemption victims found for incoming pod."
I0509 14:11:02.314165      12 preemption.go:264] "No preemption candidate is found; preemption is not helpful for scheduling" pod="default/cspod-68"
I0509 14:11:02.314196      12 schedule_one.go:1044] "Unable to schedule pod; no fit; waiting" pod="default/cspod-68" err="0/5 nodes are available: 5 Insufficient cpu. preemption: 0/5 nodes are available: 5 No preemption victims found for incoming pod."
I0509 14:11:02.314736      12 preemption.go:264] "No preemption candidate is found; preemption is not helpful for scheduling" pod="default/cspod-69"
I0509 14:11:02.314766      12 schedule_one.go:1044] "Unable to schedule pod; no fit; waiting" pod="default/cspod-69" err="0/5 nodes are available: 5 Insufficient cpu. preemption: 0/5 nodes are available: 5 No preemption victims found for incoming pod."
I0509 14:11:02.330383      12 schedule_one.go:314] "Successfully bound pod to node" pod="default/cspod-10" node="csnode-1" evaluatedNodes=5 feasibleNodes=3
I0509 14:11:02.330435      12 schedule_one.go:314] "Successfully bound pod to node" pod="default/cspod-16" node="csnode-0" evaluatedNodes=5 feasibleNodes=2
I0509 14:11:02.330453      12 schedule_one.go:314] "Successfully bound pod to node" pod="default/cspod-12" node="csnode-4" evaluatedNodes=5 feasibleNodes=4
I0509 14:11:02.330480      12 schedule_one.go:314] "Successfully bound pod to node" pod="default/cspod-11" node="csnode-1" evaluatedNodes=5 feasibleNodes=5
I0509 14:11:02.330517      12 schedule_one.go:314] "Successfully bound pod to node" pod="default/cspod-15" node="csnode-2" evaluatedNodes=5 feasibleNodes=3
I0509 14:11:02.330548      12 preemption.go:264] "No preemption candidate is found; preemption is not helpful for scheduling" pod="default/cspod-20"
I0509 14:11:02.330566      12 schedule_one.go:314] "Successfully bound pod to node" pod="default/cspod-13" node="csnode-4" evaluatedNodes=5 feasibleNodes=4
I0509 14:11:02.330574      12 schedule_one.go:1044] "Unable to schedule pod; no fit; waiting" pod="default/cspod-20" err="0/5 nodes are available: 5 Insufficient cpu. preemption: 0/5 nodes are available: 5 No preemption victims found for incoming pod."
I0509 14:11:02.330551      12 schedule_one.go:314] "Successfully bound pod to node" pod="default/cspod-14" node="csnode-2" evaluatedNodes=5 feasibleNodes=3
I0509 14:11:02.330631      12 schedule_one.go:314] "Successfully bound pod to node" pod="default/cspod-17" node="csnode-0" evaluatedNodes=5 feasibleNodes=2
I0509 14:11:02.330834      12 schedule_one.go:314] "Successfully bound pod to node" pod="default/cspod-18" node="csnode-3" evaluatedNodes=5 feasibleNodes=1
I0509 14:11:02.331018      12 schedule_one.go:314] "Successfully bound pod to node" pod="default/cspod-19" node="csnode-3" evaluatedNodes=5 feasibleNodes=1
I0509 14:11:02.331096      12 preemption.go:264] "No preemption candidate is found; preemption is not helpful for scheduling" pod="default/cspod-21"
I0509 14:11:02.331118      12 schedule_one.go:1044] "Unable to schedule pod; no fit; waiting" pod="default/cspod-21" err="0/5 nodes are available: 5 Insufficient cpu. preemption: 0/5 nodes are available: 5 No preemption victims found for incoming pod."
I0509 14:11:02.331732      12 preemption.go:264] "No preemption candidate is found; preemption is not helpful for scheduling" pod="default/cspod-22"
I0509 14:11:02.331770      12 schedule_one.go:1044] "Unable to schedule pod; no fit; waiting" pod="default/cspod-22" err="0/5 nodes are available: 5 Insufficient cpu. preemption: 0/5 nodes are available: 5 No preemption victims found for incoming pod."
I0509 14:11:02.332311      12 preemption.go:264] "No preemption candidate is found; preemption is not helpful for scheduling" pod="default/cspod-23"
I0509 14:11:02.332349      12 schedule_one.go:1044] "Unable to schedule pod; no fit; waiting" pod="default/cspod-23" err="0/5 nodes are available: 5 Insufficient cpu. preemption: 0/5 nodes are available: 5 No preemption victims found for incoming pod."
I0509 14:11:02.332956      12 preemption.go:264] "No preemption candidate is found; preemption is not helpful for scheduling" pod="default/cspod-24"
I0509 14:11:02.333039      12 schedule_one.go:1044] "Unable to schedule pod; no fit; waiting" pod="default/cspod-24" err="0/5 nodes are available: 5 Insufficient cpu. preemption: 0/5 nodes are available: 5 No preemption victims found for incoming pod."
I0509 14:11:02.333619      12 preemption.go:264] "No preemption candidate is found; preemption is not helpful for scheduling" pod="default/cspod-25"
I0509 14:11:02.333654      12 schedule_one.go:1044] "Unable to schedule pod; no fit; waiting" pod="default/cspod-25" err="0/5 nodes are available: 5 Insufficient cpu. preemption: 0/5 nodes are available: 5 No preemption victims found for incoming pod."
I0509 14:11:02.334140      12 preemption.go:264] "No preemption candidate is found; preemption is not helpful for scheduling" pod="default/cspod-26"
I0509 14:11:02.334172      12 schedule_one.go:1044] "Unable to schedule pod; no fit; waiting" pod="default/cspod-26" err="0/5 nodes are available: 5 Insufficient cpu. preemption: 0/5 nodes are available: 5 No preemption victims found for incoming pod."
I0509 14:11:02.334738      12 preemption.go:264] "No preemption candidate is found; preemption is not helpful for scheduling" pod="default/cspod-27"
I0509 14:11:02.334773      12 schedule_one.go:1044] "Unable to schedule pod; no fit; waiting" pod="default/cspod-27" err="0/5 nodes are available: 5 Insufficient cpu. preemption: 0/5 nodes are available: 5 No preemption victims found for incoming pod."
I0509 14:11:02.335278      12 preemption.go:264] "No preemption candidate is found; preemption is not helpful for scheduling" pod="default/cspod-28"
I0509 14:11:02.335308      12 schedule_one.go:1044] "Unable to schedule pod; no fit; waiting" pod="default/cspod-28" err="0/5 nodes are available: 5 Insufficient cpu. preemption: 0/5 nodes are available: 5 No preemption victims found for incoming pod."
I0509 14:11:02.335827      12 preemption.go:264] "No preemption candidate is found; preemption is not helpful for scheduling" pod="default/cspod-29"
I0509 14:11:02.335864      12 schedule_one.go:1044] "Unable to schedule pod; no fit; waiting" pod="default/cspod-29" err="0/5 nodes are available: 5 Insufficient cpu. preemption: 0/5 nodes are available: 5 No preemption victims found for incoming pod."
I0509 14:11:02.336354      12 preemption.go:264] "No preemption candidate is found; preemption is not helpful for scheduling" pod="default/cspod-30"
I0509 14:11:02.336385      12 schedule_one.go:1044] "Unable to schedule pod; no fit; waiting" pod="default/cspod-30" err="0/5 nodes are available: 5 Insufficient cpu. preemption: 0/5 nodes are available: 5 No preemption victims found for incoming pod."
I0509 14:11:02.336861      12 preemption.go:264] "No preemption candidate is found; preemption is not helpful for scheduling" pod="default/cspod-31"
I0509 14:11:02.336891      12 schedule_one.go:1044] "Unable to schedule pod; no fit; waiting" pod="default/cspod-31" err="0/5 nodes are available: 5 Insufficient cpu. preemption: 0/5 nodes are available: 5 No preemption victims found for incoming pod."
I0509 14:11:02.337387      12 preemption.go:264] "No preemption candidate is found; preemption is not helpful for scheduling" pod="default/cspod-32"
I0509 14:11:02.337422      12 schedule_one.go:1044] "Unable to schedule pod; no fit; waiting" pod="default/cspod-32" err="0/5 nodes are available: 5 Insufficient cpu. preemption: 0/5 nodes are available: 5 No preemption victims found for incoming pod."
I0509 14:11:02.337898      12 preemption.go:264] "No preemption candidate is found; preemption is not helpful for scheduling" pod="default/cspod-33"
I0509 14:11:02.337929      12 schedule_one.go:1044] "Unable to schedule pod; no fit; waiting" pod="default/cspod-33" err="0/5 nodes are available: 5 Insufficient cpu. preemption: 0/5 nodes are available: 5 No preemption victims found for incoming pod."
I0509 14:11:02.338489      12 preemption.go:264] "No preemption candidate is found; preemption is not helpful for scheduling" pod="default/cspod-34"
I0509 14:11:02.338525      12 schedule_one.go:1044] "Unable to schedule pod; no fit; waiting" pod="default/cspod-34" err="0/5 nodes are available: 5 Insufficient cpu. preemption: 0/5 nodes are available: 5 No preemption victims found for incoming pod."
I0509 14:11:02.338997      12 preemption.go:264] "No preemption candidate is found; preemption is not helpful for scheduling" pod="default/cspod-35"
I0509 14:11:02.339036      12 schedule_one.go:1044] "Unable to schedule pod; no fit; waiting" pod="default/cspod-35" err="0/5 nodes are available: 5 Insufficient cpu. preemption: 0/5 nodes are available: 5 No preemption victims found for incoming pod."
I0509 14:11:02.339575      12 preemption.go:264] "No preemption candidate is found; preemption is not helpful for scheduling" pod="default/cspod-36"
I0509 14:11:02.339608      12 schedule_one.go:1044] "Unable to schedule pod; no fit; waiting" pod="default/cspod-36" err="0/5 nodes are available: 5 Insufficient cpu. preemption: 0/5 nodes are available: 5 No preemption victims found for incoming pod."
I0509 14:11:02.340141      12 preemption.go:264] "No preemption candidate is found; preemption is not helpful for scheduling" pod="default/cspod-37"
I0509 14:11:02.340173      12 schedule_one.go:1044] "Unable to schedule pod; no fit; waiting" pod="default/cspod-37" err="0/5 nodes are available: 5 Insufficient cpu. preemption: 0/5 nodes are available: 5 No preemption victims found for incoming pod."
I0509 14:11:02.340654      12 preemption.go:264] "No preemption candidate is found; preemption is not helpful for scheduling" pod="default/cspod-38"
I0509 14:11:02.340684      12 schedule_one.go:1044] "Unable to schedule pod; no fit; waiting" pod="default/cspod-38" err="0/5 nodes are available: 5 Insufficient cpu. preemption: 0/5 nodes are available: 5 No preemption victims found for incoming pod."
I0509 14:11:02.341193      12 preemption.go:264] "No preemption candidate is found; preemption is not helpful for scheduling" pod="default/cspod-39"
I0509 14:11:02.341224      12 schedule_one.go:1044] "Unable to schedule pod; no fit; waiting" pod="default/cspod-39" err="0/5 nodes are available: 5 Insufficient cpu. preemption: 0/5 nodes are available: 5 No preemption victims found for incoming pod."
I0509 14:11:02.341698      12 preemption.go:264] "No preemption candidate is found; preemption is not helpful for scheduling" pod="default/cspod-40"
I0509 14:11:02.341728      12 schedule_one.go:1044] "Unable to schedule pod; no fit; waiting" pod="default/cspod-40" err="0/5 nodes are available: 5 Insufficient cpu. preemption: 0/5 nodes are available: 5 No preemption victims found for incoming pod."
I0509 14:11:02.342316      12 preemption.go:264] "No preemption candidate is found; preemption is not helpful for scheduling" pod="default/cspod-41"
I0509 14:11:02.342348      12 schedule_one.go:1044] "Unable to schedule pod; no fit; waiting" pod="default/cspod-41" err="0/5 nodes are available: 5 Insufficient cpu. preemption: 0/5 nodes are available: 5 No preemption victims found for incoming pod."
I0509 14:11:02.342933      12 preemption.go:264] "No preemption candidate is found; preemption is not helpful for scheduling" pod="default/cspod-42"
I0509 14:11:02.342976      12 schedule_one.go:1044] "Unable to schedule pod; no fit; waiting" pod="default/cspod-42" err="0/5 nodes are available: 5 Insufficient cpu. preemption: 0/5 nodes are available: 5 No preemption victims found for incoming pod."
I0509 14:11:02.343528      12 preemption.go:264] "No preemption candidate is found; preemption is not helpful for scheduling" pod="default/cspod-43"
I0509 14:11:02.343560      12 schedule_one.go:1044] "Unable to schedule pod; no fit; waiting" pod="default/cspod-43" err="0/5 nodes are available: 5 Insufficient cpu. preemption: 0/5 nodes are available: 5 No preemption victims found for incoming pod."
I0509 14:11:02.344043      12 preemption.go:264] "No preemption candidate is found; preemption is not helpful for scheduling" pod="default/cspod-44"
I0509 14:11:02.344075      12 schedule_one.go:1044] "Unable to schedule pod; no fit; waiting" pod="default/cspod-44" err="0/5 nodes are available: 5 Insufficient cpu. preemption: 0/5 nodes are available: 5 No preemption victims found for incoming pod."
I0509 14:11:02.344582      12 preemption.go:264] "No preemption candidate is found; preemption is not helpful for scheduling" pod="default/cspod-45"
I0509 14:11:02.344615      12 schedule_one.go:1044] "Unable to schedule pod; no fit; waiting" pod="default/cspod-45" err="0/5 nodes are available: 5 Insufficient cpu. preemption: 0/5 nodes are available: 5 No preemption victims found for incoming pod."
I0509 14:11:02.345150      12 preemption.go:264] "No preemption candidate is found; preemption is not helpful for scheduling" pod="default/cspod-46"
I0509 14:11:02.345183      12 schedule_one.go:1044] "Unable to schedule pod; no fit; waiting" pod="default/cspod-46" err="0/5 nodes are available: 5 Insufficient cpu. preemption: 0/5 nodes are available: 5 No preemption victims found for incoming pod."
I0509 14:11:02.345709      12 preemption.go:264] "No preemption candidate is found; preemption is not helpful for scheduling" pod="default/cspod-47"
I0509 14:11:02.345741      12 schedule_one.go:1044] "Unable to schedule pod; no fit; waiting" pod="default/cspod-47" err="0/5 nodes are available: 5 Insufficient cpu. preemption: 0/5 nodes are available: 5 No preemption victims found for incoming pod."
I0509 14:11:02.346247      12 preemption.go:264] "No preemption candidate is found; preemption is not helpful for scheduling" pod="default/cspod-48"
I0509 14:11:02.346301      12 schedule_one.go:1044] "Unable to schedule pod; no fit; waiting" pod="default/cspod-48" err="0/5 nodes are available: 5 Insufficient cpu. preemption: 0/5 nodes are available: 5 No preemption victims found for incoming pod."
I0509 14:11:02.347936      12 preemption.go:264] "No preemption candidate is found; preemption is not helpful for scheduling" pod="default/cspod-49"
I0509 14:11:02.347966      12 schedule_one.go:1044] "Unable to schedule pod; no fit; waiting" pod="default/cspod-49" err="0/5 nodes are available: 5 Insufficient cpu. preemption: 0/5 nodes are available: 5 No preemption victims found for incoming pod."
I0509 14:11:02.367912      12 preemption.go:264] "No preemption candidate is found; preemption is not helpful for scheduling" pod="default/cspod-50"
I0509 14:11:02.367956      12 schedule_one.go:1044] "Unable to schedule pod; no fit; waiting" pod="default/cspod-50" err="0/5 nodes are available: 5 Insufficient cpu. preemption: 0/5 nodes are available: 5 No preemption victims found for incoming pod."
I0509 14:11:02.388160      12 preemption.go:264] "No preemption candidate is found; preemption is not helpful for scheduling" pod="default/cspod-51"
I0509 14:11:02.388210      12 schedule_one.go:1044] "Unable to schedule pod; no fit; waiting" pod="default/cspod-51" err="0/5 nodes are available: 5 Insufficient cpu. preemption: 0/5 nodes are available: 5 No preemption victims found for incoming pod."
I0509 14:11:02.409105      12 preemption.go:264] "No preemption candidate is found; preemption is not helpful for scheduling" pod="default/cspod-52"
I0509 14:11:02.409164      12 schedule_one.go:1044] "Unable to schedule pod; no fit; waiting" pod="default/cspod-52" err="0/5 nodes are available: 5 Insufficient cpu. preemption: 0/5 nodes are available: 5 No preemption victims found for incoming pod."
I0509 14:11:02.428082      12 preemption.go:264] "No preemption candidate is found; preemption is not helpful for scheduling" pod="default/cspod-53"
I0509 14:11:02.428122      12 schedule_one.go:1044] "Unable to schedule pod; no fit; waiting" pod="default/cspod-53" err="0/5 nodes are available: 5 Insufficient cpu. preemption: 0/5 nodes are available: 5 No preemption victims found for incoming pod."
I0509 14:11:02.448606      12 preemption.go:264] "No preemption candidate is found; preemption is not helpful for scheduling" pod="default/cspod-54"
I0509 14:11:02.448689      12 schedule_one.go:1044] "Unable to schedule pod; no fit; waiting" pod="default/cspod-54" err="0/5 nodes are available: 5 Insufficient cpu. preemption: 0/5 nodes are available: 5 No preemption victims found for incoming pod."
I0509 14:11:02.468973      12 preemption.go:264] "No preemption candidate is found; preemption is not helpful for scheduling" pod="default/cspod-60"
I0509 14:11:02.469039      12 schedule_one.go:1044] "Unable to schedule pod; no fit; waiting" pod="default/cspod-60" err="0/5 nodes are available: 5 Insufficient cpu. preemption: 0/5 nodes are available: 5 No preemption victims found for incoming pod."
I0509 14:11:02.488202      12 preemption.go:264] "No preemption candidate is found; preemption is not helpful for scheduling" pod="default/cspod-61"
I0509 14:11:02.488248      12 schedule_one.go:1044] "Unable to schedule pod; no fit; waiting" pod="default/cspod-61" err="0/5 nodes are available: 5 Insufficient cpu. preemption: 0/5 nodes are available: 5 No preemption victims found for incoming pod."
I0509 14:11:02.508534      12 preemption.go:264] "No preemption candidate is found; preemption is not helpful for scheduling" pod="default/cspod-62"
I0509 14:11:02.508581      12 schedule_one.go:1044] "Unable to schedule pod; no fit; waiting" pod="default/cspod-62" err="0/5 nodes are available: 5 Insufficient cpu. preemption: 0/5 nodes are available: 5 No preemption victims found for incoming pod."
I0509 14:11:02.528859      12 preemption.go:264] "No preemption candidate is found; preemption is not helpful for scheduling" pod="default/cspod-63"
I0509 14:11:02.528908      12 schedule_one.go:1044] "Unable to schedule pod; no fit; waiting" pod="default/cspod-63" err="0/5 nodes are available: 5 Insufficient cpu. preemption: 0/5 nodes are available: 5 No preemption victims found for incoming pod."
I0509 14:11:02.549030      12 preemption.go:264] "No preemption candidate is found; preemption is not helpful for scheduling" pod="default/cspod-64"
I0509 14:11:02.549070      12 schedule_one.go:1044] "Unable to schedule pod; no fit; waiting" pod="default/cspod-64" err="0/5 nodes are available: 5 Insufficient cpu. preemption: 0/5 nodes are available: 5 No preemption victims found for incoming pod."
I0509 14:11:02.568306      12 preemption.go:264] "No preemption candidate is found; preemption is not helpful for scheduling" pod="default/cspod-65"
I0509 14:11:02.568383      12 schedule_one.go:1044] "Unable to schedule pod; no fit; waiting" pod="default/cspod-65" err="0/5 nodes are available: 5 Insufficient cpu. preemption: 0/5 nodes are available: 5 No preemption victims found for incoming pod."
I0509 14:11:02.588604      12 preemption.go:264] "No preemption candidate is found; preemption is not helpful for scheduling" pod="default/cspod-66"
I0509 14:11:02.588647      12 schedule_one.go:1044] "Unable to schedule pod; no fit; waiting" pod="default/cspod-66" err="0/5 nodes are available: 5 Insufficient cpu. preemption: 0/5 nodes are available: 5 No preemption victims found for incoming pod."
I0509 14:11:02.608784      12 preemption.go:264] "No preemption candidate is found; preemption is not helpful for scheduling" pod="default/cspod-67"
I0509 14:11:02.608826      12 schedule_one.go:1044] "Unable to schedule pod; no fit; waiting" pod="default/cspod-67" err="0/5 nodes are available: 5 Insufficient cpu. preemption: 0/5 nodes are available: 5 No preemption victims found for incoming pod."
I0509 14:11:02.628923      12 preemption.go:264] "No preemption candidate is found; preemption is not helpful for scheduling" pod="default/cspod-68"
I0509 14:11:02.628962      12 schedule_one.go:1044] "Unable to schedule pod; no fit; waiting" pod="default/cspod-68" err="0/5 nodes are available: 5 Insufficient cpu. preemption: 0/5 nodes are available: 5 No preemption victims found for incoming pod."
I0509 14:11:02.648597      12 preemption.go:264] "No preemption candidate is found; preemption is not helpful for scheduling" pod="default/cspod-69"
I0509 14:11:02.648680      12 schedule_one.go:1044] "Unable to schedule pod; no fit; waiting" pod="default/cspod-69" err="0/5 nodes are available: 5 Insufficient cpu. preemption: 0/5 nodes are available: 5 No preemption victims found for incoming pod."
I0509 14:11:02.682128      12 preemption.go:264] "No preemption candidate is found; preemption is not helpful for scheduling" pod="default/cspod-20"
I0509 14:11:02.682174      12 schedule_one.go:1044] "Unable to schedule pod; no fit; waiting" pod="default/cspod-20" err="0/5 nodes are available: 5 Insufficient cpu. preemption: 0/5 nodes are available: 5 No preemption victims found for incoming pod."
I0509 14:11:02.682305      12 preemption.go:264] "No preemption candidate is found; preemption is not helpful for scheduling" pod="default/cspod-21"
I0509 14:11:02.682344      12 schedule_one.go:1044] "Unable to schedule pod; no fit; waiting" pod="default/cspod-21" err="0/5 nodes are available: 5 Insufficient cpu. preemption: 0/5 nodes are available: 5 No preemption victims found for incoming pod."
I0509 14:11:02.688217      12 preemption.go:264] "No preemption candidate is found; preemption is not helpful for scheduling" pod="default/cspod-22"
I0509 14:11:02.688255      12 schedule_one.go:1044] "Unable to schedule pod; no fit; waiting" pod="default/cspod-22" err="0/5 nodes are available: 5 Insufficient cpu. preemption: 0/5 nodes are available: 5 No preemption victims found for incoming pod."
I0509 14:11:02.708538      12 preemption.go:264] "No preemption candidate is found; preemption is not helpful for scheduling" pod="default/cspod-23"
I0509 14:11:02.708582      12 schedule_one.go:1044] "Unable to schedule pod; no fit; waiting" pod="default/cspod-23" err="0/5 nodes are available: 5 Insufficient cpu. preemption: 0/5 nodes are available: 5 No preemption victims found for incoming pod."
I0509 14:11:02.728772      12 preemption.go:264] "No preemption candidate is found; preemption is not helpful for scheduling" pod="default/cspod-24"
I0509 14:11:02.728812      12 schedule_one.go:1044] "Unable to schedule pod; no fit; waiting" pod="default/cspod-24" err="0/5 nodes are available: 5 Insufficient cpu. preemption: 0/5 nodes are available: 5 No preemption victims found for incoming pod."
I0509 14:11:02.749032      12 preemption.go:264] "No preemption candidate is found; preemption is not helpful for scheduling" pod="default/cspod-25"
I0509 14:11:02.749068      12 schedule_one.go:1044] "Unable to schedule pod; no fit; waiting" pod="default/cspod-25" err="0/5 nodes are available: 5 Insufficient cpu. preemption: 0/5 nodes are available: 5 No preemption victims found for incoming pod."
I0509 14:11:02.768175      12 preemption.go:264] "No preemption candidate is found; preemption is not helpful for scheduling" pod="default/cspod-26"
I0509 14:11:02.768217      12 schedule_one.go:1044] "Unable to schedule pod; no fit; waiting" pod="default/cspod-26" err="0/5 nodes are available: 5 Insufficient cpu. preemption: 0/5 nodes are available: 5 No preemption victims found for incoming pod."
I0509 14:11:02.788103      12 preemption.go:264] "No preemption candidate is found; preemption is not helpful for scheduling" pod="default/cspod-27"
I0509 14:11:02.788139      12 schedule_one.go:1044] "Unable to schedule pod; no fit; waiting" pod="default/cspod-27" err="0/5 nodes are available: 5 Insufficient cpu. preemption: 0/5 nodes are available: 5 No preemption victims found for incoming pod."
I0509 14:11:02.808417      12 preemption.go:264] "No preemption candidate is found; preemption is not helpful for scheduling" pod="default/cspod-28"
I0509 14:11:02.808457      12 schedule_one.go:1044] "Unable to schedule pod; no fit; waiting" pod="default/cspod-28" err="0/5 nodes are available: 5 Insufficient cpu. preemption: 0/5 nodes are available: 5 No preemption victims found for incoming pod."
I0509 14:11:02.828651      12 preemption.go:264] "No preemption candidate is found; preemption is not helpful for scheduling" pod="default/cspod-29"
I0509 14:11:02.828699      12 schedule_one.go:1044] "Unable to schedule pod; no fit; waiting" pod="default/cspod-29" err="0/5 nodes are available: 5 Insufficient cpu. preemption: 0/5 nodes are available: 5 No preemption victims found for incoming pod."
I0509 14:11:02.848976      12 preemption.go:264] "No preemption candidate is found; preemption is not helpful for scheduling" pod="default/cspod-30"
I0509 14:11:02.849018      12 schedule_one.go:1044] "Unable to schedule pod; no fit; waiting" pod="default/cspod-30" err="0/5 nodes are available: 5 Insufficient cpu. preemption: 0/5 nodes are available: 5 No preemption victims found for incoming pod."
I0509 14:11:02.867907      12 preemption.go:264] "No preemption candidate is found; preemption is not helpful for scheduling" pod="default/cspod-31"
I0509 14:11:02.867946      12 schedule_one.go:1044] "Unable to schedule pod; no fit; waiting" pod="default/cspod-31" err="0/5 nodes are available: 5 Insufficient cpu. preemption: 0/5 nodes are available: 5 No preemption victims found for incoming pod."
I0509 14:11:02.889169      12 preemption.go:264] "No preemption candidate is found; preemption is not helpful for scheduling" pod="default/cspod-32"
I0509 14:11:02.889211      12 schedule_one.go:1044] "Unable to schedule pod; no fit; waiting" pod="default/cspod-32" err="0/5 nodes are available: 5 Insufficient cpu. preemption: 0/5 nodes are available: 5 No preemption victims found for incoming pod."
I0509 14:11:02.908533      12 preemption.go:264] "No preemption candidate is found; preemption is not helpful for scheduling" pod="default/cspod-33"
I0509 14:11:02.908581      12 schedule_one.go:1044] "Unable to schedule pod; no fit; waiting" pod="default/cspod-33" err="0/5 nodes are available: 5 Insufficient cpu. preemption: 0/5 nodes are available: 5 No preemption victims found for incoming pod."
I0509 14:11:02.929037      12 preemption.go:264] "No preemption candidate is found; preemption is not helpful for scheduling" pod="default/cspod-34"
I0509 14:11:02.929083      12 schedule_one.go:1044] "Unable to schedule pod; no fit; waiting" pod="default/cspod-34" err="0/5 nodes are available: 5 Insufficient cpu. preemption: 0/5 nodes are available: 5 No preemption victims found for incoming pod."
I0509 14:11:02.948110      12 preemption.go:264] "No preemption candidate is found; preemption is not helpful for scheduling" pod="default/cspod-35"
I0509 14:11:02.948149      12 schedule_one.go:1044] "Unable to schedule pod; no fit; waiting" pod="default/cspod-35" err="0/5 nodes are available: 5 Insufficient cpu. preemption: 0/5 nodes are available: 5 No preemption victims found for incoming pod."
I0509 14:11:02.968364      12 preemption.go:264] "No preemption candidate is found; preemption is not helpful for scheduling" pod="default/cspod-36"
I0509 14:11:02.968408      12 schedule_one.go:1044] "Unable to schedule pod; no fit; waiting" pod="default/cspod-36" err="0/5 nodes are available: 5 Insufficient cpu. preemption: 0/5 nodes are available: 5 No preemption victims found for incoming pod."
I0509 14:11:02.988301      12 preemption.go:264] "No preemption candidate is found; preemption is not helpful for scheduling" pod="default/cspod-37"
I0509 14:11:02.988336      12 schedule_one.go:1044] "Unable to schedule pod; no fit; waiting" pod="default/cspod-37" err="0/5 nodes are available: 5 Insufficient cpu. preemption: 0/5 nodes are available: 5 No preemption victims found for incoming pod."
I0509 14:11:03.008695      12 preemption.go:264] "No preemption candidate is found; preemption is not helpful for scheduling" pod="default/cspod-38"
I0509 14:11:03.008733      12 schedule_one.go:1044] "Unable to schedule pod; no fit; waiting" pod="default/cspod-38" err="0/5 nodes are available: 5 Insufficient cpu. preemption: 0/5 nodes are available: 5 No preemption victims found for incoming pod."
I0509 14:11:03.028876      12 preemption.go:264] "No preemption candidate is found; preemption is not helpful for scheduling" pod="default/cspod-39"
I0509 14:11:03.028913      12 schedule_one.go:1044] "Unable to schedule pod; no fit; waiting" pod="default/cspod-39" err="0/5 nodes are available: 5 Insufficient cpu. preemption: 0/5 nodes are available: 5 No preemption victims found for incoming pod."
I0509 14:11:03.049089      12 preemption.go:264] "No preemption candidate is found; preemption is not helpful for scheduling" pod="default/cspod-40"
I0509 14:11:03.049175      12 schedule_one.go:1044] "Unable to schedule pod; no fit; waiting" pod="default/cspod-40" err="0/5 nodes are available: 5 Insufficient cpu. preemption: 0/5 nodes are available: 5 No preemption victims found for incoming pod."
I0509 14:11:03.068269      12 preemption.go:264] "No preemption candidate is found; preemption is not helpful for scheduling" pod="default/cspod-41"
I0509 14:11:03.068306      12 schedule_one.go:1044] "Unable to schedule pod; no fit; waiting" pod="default/cspod-41" err="0/5 nodes are available: 5 Insufficient cpu. preemption: 0/5 nodes are available: 5 No preemption victims found for incoming pod."
I0509 14:11:03.088642      12 preemption.go:264] "No preemption candidate is found; preemption is not helpful for scheduling" pod="default/cspod-42"
I0509 14:11:03.088687      12 schedule_one.go:1044] "Unable to schedule pod; no fit; waiting" pod="default/cspod-42" err="0/5 nodes are available: 5 Insufficient cpu. preemption: 0/5 nodes are available: 5 No preemption victims found for incoming pod."
I0509 14:11:03.108839      12 preemption.go:264] "No preemption candidate is found; preemption is not helpful for scheduling" pod="default/cspod-43"
I0509 14:11:03.108875      12 schedule_one.go:1044] "Unable to schedule pod; no fit; waiting" pod="default/cspod-43" err="0/5 nodes are available: 5 Insufficient cpu. preemption: 0/5 nodes are available: 5 No preemption victims found for incoming pod."
I0509 14:11:03.129180      12 preemption.go:264] "No preemption candidate is found; preemption is not helpful for scheduling" pod="default/cspod-44"
I0509 14:11:03.129223      12 schedule_one.go:1044] "Unable to schedule pod; no fit; waiting" pod="default/cspod-44" err="0/5 nodes are available: 5 Insufficient cpu. preemption: 0/5 nodes are available: 5 No preemption victims found for incoming pod."
I0509 14:11:03.148531      12 preemption.go:264] "No preemption candidate is found; preemption is not helpful for scheduling" pod="default/cspod-45"
I0509 14:11:03.148604      12 schedule_one.go:1044] "Unable to schedule pod; no fit; waiting" pod="default/cspod-45" err="0/5 nodes are available: 5 Insufficient cpu. preemption: 0/5 nodes are available: 5 No preemption victims found for incoming pod."
I0509 14:11:03.168940      12 preemption.go:264] "No preemption candidate is found; preemption is not helpful for scheduling" pod="default/cspod-46"
I0509 14:11:03.168983      12 schedule_one.go:1044] "Unable to schedule pod; no fit; waiting" pod="default/cspod-46" err="0/5 nodes are available: 5 Insufficient cpu. preemption: 0/5 nodes are available: 5 No preemption victims found for incoming pod."
I0509 14:11:03.188056      12 preemption.go:264] "No preemption candidate is found; preemption is not helpful for scheduling" pod="default/cspod-47"
I0509 14:11:03.188122      12 schedule_one.go:1044] "Unable to schedule pod; no fit; waiting" pod="default/cspod-47" err="0/5 nodes are available: 5 Insufficient cpu. preemption: 0/5 nodes are available: 5 No preemption victims found for incoming pod."
I0509 14:11:03.208543      12 preemption.go:264] "No preemption candidate is found; preemption is not helpful for scheduling" pod="default/cspod-48"
I0509 14:11:03.208587      12 schedule_one.go:1044] "Unable to schedule pod; no fit; waiting" pod="default/cspod-48" err="0/5 nodes are available: 5 Insufficient cpu. preemption: 0/5 nodes are available: 5 No preemption victims found for incoming pod."
I0509 14:11:03.228679      12 preemption.go:264] "No preemption candidate is found; preemption is not helpful for scheduling" pod="default/cspod-49"
I0509 14:11:03.228712      12 schedule_one.go:1044] "Unable to schedule pod; no fit; waiting" pod="default/cspod-49" err="0/5 nodes are available: 5 Insufficient cpu. preemption: 0/5 nodes are available: 5 No preemption victims found for incoming pod."
I0509 14:11:03.248761      12 preemption.go:264] "No preemption candidate is found; preemption is not helpful for scheduling" pod="default/cspod-50"
I0509 14:11:03.248799      12 schedule_one.go:1044] "Unable to schedule pod; no fit; waiting" pod="default/cspod-50" err="0/5 nodes are available: 5 Insufficient cpu. preemption: 0/5 nodes are available: 5 No preemption victims found for incoming pod."
I0509 14:11:03.269163      12 preemption.go:264] "No preemption candidate is found; preemption is not helpful for scheduling" pod="default/cspod-51"
I0509 14:11:03.269238      12 schedule_one.go:1044] "Unable to schedule pod; no fit; waiting" pod="default/cspod-51" err="0/5 nodes are available: 5 Insufficient cpu. preemption: 0/5 nodes are available: 5 No preemption victims found for incoming pod."
I0509 14:11:03.288265      12 preemption.go:264] "No preemption candidate is found; preemption is not helpful for scheduling" pod="default/cspod-52"
I0509 14:11:03.288310      12 schedule_one.go:1044] "Unable to schedule pod; no fit; waiting" pod="default/cspod-52" err="0/5 nodes are available: 5 Insufficient cpu. preemption: 0/5 nodes are available: 5 No preemption victims found for incoming pod."
I0509 14:11:03.308308      12 preemption.go:264] "No preemption candidate is found; preemption is not helpful for scheduling" pod="default/cspod-53"
I0509 14:11:03.308347      12 schedule_one.go:1044] "Unable to schedule pod; no fit; waiting" pod="default/cspod-53" err="0/5 nodes are available: 5 Insufficient cpu. preemption: 0/5 nodes are available: 5 No preemption victims found for incoming pod."
I0509 14:11:03.328324      12 preemption.go:264] "No preemption candidate is found; preemption is not helpful for scheduling" pod="default/cspod-54"
I0509 14:11:03.328366      12 schedule_one.go:1044] "Unable to schedule pod; no fit; waiting" pod="default/cspod-54" err="0/5 nodes are available: 5 Insufficient cpu. preemption: 0/5 nodes are available: 5 No preemption victims found for incoming pod."
I0509 14:11:03.348546      12 preemption.go:264] "No preemption candidate is found; preemption is not helpful for scheduling" pod="default/cspod-60"
I0509 14:11:03.348588      12 schedule_one.go:1044] "Unable to schedule pod; no fit; waiting" pod="default/cspod-60" err="0/5 nodes are available: 5 Insufficient cpu. preemption: 0/5 nodes are available: 5 No preemption victims found for incoming pod."
I0509 14:11:03.368789      12 preemption.go:264] "No preemption candidate is found; preemption is not helpful for scheduling" pod="default/cspod-61"
I0509 14:11:03.368860      12 schedule_one.go:1044] "Unable to schedule pod; no fit; waiting" pod="default/cspod-61" err="0/5 nodes are available: 5 Insufficient cpu. preemption: 0/5 nodes are available: 5 No preemption victims found for incoming pod."
I0509 14:11:03.388991      12 preemption.go:264] "No preemption candidate is found; preemption is not helpful for scheduling" pod="default/cspod-62"
I0509 14:11:03.389035      12 schedule_one.go:1044] "Unable to schedule pod; no fit; waiting" pod="default/cspod-62" err="0/5 nodes are available: 5 Insufficient cpu. preemption: 0/5 nodes are available: 5 No preemption victims found for incoming pod."
I0509 14:11:03.408249      12 preemption.go:264] "No preemption candidate is found; preemption is not helpful for scheduling" pod="default/cspod-63"
I0509 14:11:03.408293      12 schedule_one.go:1044] "Unable to schedule pod; no fit; waiting" pod="default/cspod-63" err="0/5 nodes are available: 5 Insufficient cpu. preemption: 0/5 nodes are available: 5 No preemption victims found for incoming pod."
I0509 14:11:03.428544      12 preemption.go:264] "No preemption candidate is found; preemption is not helpful for scheduling" pod="default/cspod-64"
I0509 14:11:03.428592      12 schedule_one.go:1044] "Unable to schedule pod; no fit; waiting" pod="default/cspod-64" err="0/5 nodes are available: 5 Insufficient cpu. preemption: 0/5 nodes are available: 5 No preemption victims found for incoming pod."
I0509 14:11:03.448642      12 preemption.go:264] "No preemption candidate is found; preemption is not helpful for scheduling" pod="default/cspod-65"
I0509 14:11:03.448718      12 schedule_one.go:1044] "Unable to schedule pod; no fit; waiting" pod="default/cspod-65" err="0/5 nodes are available: 5 Insufficient cpu. preemption: 0/5 nodes are available: 5 No preemption victims found for incoming pod."
I0509 14:11:03.469096      12 preemption.go:264] "No preemption candidate is found; preemption is not helpful for scheduling" pod="default/cspod-66"
I0509 14:11:03.469172      12 schedule_one.go:1044] "Unable to schedule pod; no fit; waiting" pod="default/cspod-66" err="0/5 nodes are available: 5 Insufficient cpu. preemption: 0/5 nodes are available: 5 No preemption victims found for incoming pod."
I0509 14:11:03.488349      12 preemption.go:264] "No preemption candidate is found; preemption is not helpful for scheduling" pod="default/cspod-67"
I0509 14:11:03.488395      12 schedule_one.go:1044] "Unable to schedule pod; no fit; waiting" pod="default/cspod-67" err="0/5 nodes are available: 5 Insufficient cpu. preemption: 0/5 nodes are available: 5 No preemption victims found for incoming pod."
I0509 14:11:03.508669      12 preemption.go:264] "No preemption candidate is found; preemption is not helpful for scheduling" pod="default/cspod-68"
I0509 14:11:03.508715      12 schedule_one.go:1044] "Unable to schedule pod; no fit; waiting" pod="default/cspod-68" err="0/5 nodes are available: 5 Insufficient cpu. preemption: 0/5 nodes are available: 5 No preemption victims found for incoming pod."
I0509 14:11:03.529043      12 preemption.go:264] "No preemption candidate is found; preemption is not helpful for scheduling" pod="default/cspod-69"
I0509 14:11:03.529086      12 schedule_one.go:1044] "Unable to schedule pod; no fit; waiting" pod="default/cspod-69" err="0/5 nodes are available: 5 Insufficient cpu. preemption: 0/5 nodes are available: 5 No preemption victims found for incoming pod."
I0509 14:11:06.708602      12 schedule_one.go:314] "Successfully bound pod to node" pod="default/cspod-20" node="csnode-3" evaluatedNodes=5 feasibleNodes=5
I0509 14:11:06.708615      12 schedule_one.go:314] "Successfully bound pod to node" pod="default/cspod-21" node="csnode-3" evaluatedNodes=5 feasibleNodes=5
I0509 14:11:06.708691      12 schedule_one.go:314] "Successfully bound pod to node" pod="default/cspod-22" node="csnode-1" evaluatedNodes=5 feasibleNodes=4
I0509 14:11:06.708988      12 schedule_one.go:314] "Successfully bound pod to node" pod="default/cspod-23" node="csnode-1" evaluatedNodes=5 feasibleNodes=4
I0509 14:11:06.709111      12 schedule_one.go:314] "Successfully bound pod to node" pod="default/cspod-24" node="csnode-0" evaluatedNodes=5 feasibleNodes=3
I0509 14:11:06.709372      12 schedule_one.go:314] "Successfully bound pod to node" pod="default/cspod-25" node="csnode-0" evaluatedNodes=5 feasibleNodes=3
I0509 14:11:06.709512      12 schedule_one.go:314] "Successfully bound pod to node" pod="default/cspod-26" node="csnode-4" evaluatedNodes=5 feasibleNodes=2
I0509 14:11:06.709570      12 schedule_one.go:314] "Successfully bound pod to node" pod="default/cspod-27" node="csnode-4" evaluatedNodes=5 feasibleNodes=2
I0509 14:11:06.709599      12 preemption.go:264] "No preemption candidate is found; preemption is not helpful for scheduling" pod="default/cspod-30"
I0509 14:11:06.709633      12 schedule_one.go:1044] "Unable to schedule pod; no fit; waiting" pod="default/cspod-30" err="0/5 nodes are available: 5 Insufficient cpu. preemption: 0/5 nodes are available: 5 No preemption victims found for incoming pod."
I0509 14:11:06.709782      12 schedule_one.go:314] "Successfully bound pod to node" pod="default/cspod-29" node="csnode-2" evaluatedNodes=5 feasibleNodes=1
I0509 14:11:06.709781      12 schedule_one.go:314] "Successfully bound pod to node" pod="default/cspod-28" node="csnode-2" evaluatedNodes=5 feasibleNodes=1
I0509 14:11:06.710342      12 preemption.go:264] "No preemption candidate is found; preemption is not helpful for scheduling" pod="default/cspod-31"
I0509 14:11:06.710380      12 schedule_one.go:1044] "Unable to schedule pod; no fit; waiting" pod="default/cspod-31" err="0/5 nodes are available: 5 Insufficient cpu. preemption: 0/5 nodes are available: 5 No preemption victims found for incoming pod."
I0509 14:11:06.710930      12 preemption.go:264] "No preemption candidate is found; preemption is not helpful for scheduling" pod="default/cspod-32"
I0509 14:11:06.710963      12 schedule_one.go:1044] "Unable to schedule pod; no fit; waiting" pod="default/cspod-32" err="0/5 nodes are available: 5 Insufficient cpu. preemption: 0/5 nodes are available: 5 No preemption victims found for incoming pod."
I0509 14:11:06.711482      12 preemption.go:264] "No preemption candidate is found; preemption is not helpful for scheduling" pod="default/cspod-33"
I0509 14:11:06.711518      12 schedule_one.go:1044] "Unable to schedule pod; no fit; waiting" pod="default/cspod-33" err="0/5 nodes are available: 5 Insufficient cpu. preemption: 0/5 nodes are available: 5 No preemption victims found for incoming pod."
I0509 14:11:06.712115      12 preemption.go:264] "No preemption candidate is found; preemption is not helpful for scheduling" pod="default/cspod-34"
I0509 14:11:06.712154      12 schedule_one.go:1044] "Unable to schedule pod; no fit; waiting" pod="default/cspod-34" err="0/5 nodes are available: 5 Insufficient cpu. preemption: 0/5 nodes are available: 5 No preemption victims found for incoming pod."
I0509 14:11:06.712708      12 preemption.go:264] "No preemption candidate is found; preemption is not helpful for scheduling" pod="default/cspod-35"
I0509 14:11:06.712747      12 schedule_one.go:1044] "Unable to schedule pod; no fit; waiting" pod="default/cspod-35" err="0/5 nodes are available: 5 Insufficient cpu. preemption: 0/5 nodes are available: 5 No preemption victims found for incoming pod."
I0509 14:11:06.713319      12 preemption.go:264] "No preemption candidate is found; preemption is not helpful for scheduling" pod="default/cspod-36"
I0509 14:11:06.713356      12 schedule_one.go:1044] "Unable to schedule pod; no fit; waiting" pod="default/cspod-36" err="0/5 nodes are available: 5 Insufficient cpu. preemption: 0/5 nodes are available: 5 No preemption victims found for incoming pod."
I0509 14:11:06.713976      12 preemption.go:264] "No preemption candidate is found; preemption is not helpful for scheduling" pod="default/cspod-37"
I0509 14:11:06.714013      12 schedule_one.go:1044] "Unable to schedule pod; no fit; waiting" pod="default/cspod-37" err="0/5 nodes are available: 5 Insufficient cpu. preemption: 0/5 nodes are available: 5 No preemption victims found for incoming pod."
I0509 14:11:06.714617      12 preemption.go:264] "No preemption candidate is found; preemption is not helpful for scheduling" pod="default/cspod-38"
I0509 14:11:06.714657      12 schedule_one.go:1044] "Unable to schedule pod; no fit; waiting" pod="default/cspod-38" err="0/5 nodes are available: 5 Insufficient cpu. preemption: 0/5 nodes are available: 5 No preemption victims found for incoming pod."
I0509 14:11:06.715199      12 preemption.go:264] "No preemption candidate is found; preemption is not helpful for scheduling" pod="default/cspod-39"
I0509 14:11:06.715233      12 schedule_one.go:1044] "Unable to schedule pod; no fit; waiting" pod="default/cspod-39" err="0/5 nodes are available: 5 Insufficient cpu. preemption: 0/5 nodes are available: 5 No preemption victims found for incoming pod."
I0509 14:11:06.715792      12 preemption.go:264] "No preemption candidate is found; preemption is not helpful for scheduling" pod="default/cspod-40"
I0509 14:11:06.715832      12 schedule_one.go:1044] "Unable to schedule pod; no fit; waiting" pod="default/cspod-40" err="0/5 nodes are available: 5 Insufficient cpu. preemption: 0/5 nodes are available: 5 No preemption victims found for incoming pod."
I0509 14:11:06.717203      12 preemption.go:264] "No preemption candidate is found; preemption is not helpful for scheduling" pod="default/cspod-41"
I0509 14:11:06.717247      12 schedule_one.go:1044] "Unable to schedule pod; no fit; waiting" pod="default/cspod-41" err="0/5 nodes are available: 5 Insufficient cpu. preemption: 0/5 nodes are available: 5 No preemption victims found for incoming pod."
I0509 14:11:06.717780      12 preemption.go:264] "No preemption candidate is found; preemption is not helpful for scheduling" pod="default/cspod-42"
I0509 14:11:06.717813      12 schedule_one.go:1044] "Unable to schedule pod; no fit; waiting" pod="default/cspod-42" err="0/5 nodes are available: 5 Insufficient cpu. preemption: 0/5 nodes are available: 5 No preemption victims found for incoming pod."
I0509 14:11:06.718465      12 preemption.go:264] "No preemption candidate is found; preemption is not helpful for scheduling" pod="default/cspod-43"
I0509 14:11:06.718532      12 schedule_one.go:1044] "Unable to schedule pod; no fit; waiting" pod="default/cspod-43" err="0/5 nodes are available: 5 Insufficient cpu. preemption: 0/5 nodes are available: 5 No preemption victims found for incoming pod."
I0509 14:11:06.719192      12 preemption.go:264] "No preemption candidate is found; preemption is not helpful for scheduling" pod="default/cspod-44"
I0509 14:11:06.719227      12 schedule_one.go:1044] "Unable to schedule pod; no fit; waiting" pod="default/cspod-44" err="0/5 nodes are available: 5 Insufficient cpu. preemption: 0/5 nodes are available: 5 No preemption victims found for incoming pod."
I0509 14:11:06.719731      12 preemption.go:264] "No preemption candidate is found; preemption is not helpful for scheduling" pod="default/cspod-45"
I0509 14:11:06.719763      12 schedule_one.go:1044] "Unable to schedule pod; no fit; waiting" pod="default/cspod-45" err="0/5 nodes are available: 5 Insufficient cpu. preemption: 0/5 nodes are available: 5 No preemption victims found for incoming pod."
I0509 14:11:06.720259      12 preemption.go:264] "No preemption candidate is found; preemption is not helpful for scheduling" pod="default/cspod-46"
I0509 14:11:06.720290      12 schedule_one.go:1044] "Unable to schedule pod; no fit; waiting" pod="default/cspod-46" err="0/5 nodes are available: 5 Insufficient cpu. preemption: 0/5 nodes are available: 5 No preemption victims found for incoming pod."
I0509 14:11:06.720896      12 preemption.go:264] "No preemption candidate is found; preemption is not helpful for scheduling" pod="default/cspod-47"
I0509 14:11:06.720930      12 schedule_one.go:1044] "Unable to schedule pod; no fit; waiting" pod="default/cspod-47" err="0/5 nodes are available: 5 Insufficient cpu. preemption: 0/5 nodes are available: 5 No preemption victims found for incoming pod."
I0509 14:11:06.721428      12 preemption.go:264] "No preemption candidate is found; preemption is not helpful for scheduling" pod="default/cspod-48"
I0509 14:11:06.721463      12 schedule_one.go:1044] "Unable to schedule pod; no fit; waiting" pod="default/cspod-48" err="0/5 nodes are available: 5 Insufficient cpu. preemption: 0/5 nodes are available: 5 No preemption victims found for incoming pod."
I0509 14:11:06.721974      12 preemption.go:264] "No preemption candidate is found; preemption is not helpful for scheduling" pod="default/cspod-49"
I0509 14:11:06.722041      12 schedule_one.go:1044] "Unable to schedule pod; no fit; waiting" pod="default/cspod-49" err="0/5 nodes are available: 5 Insufficient cpu. preemption: 0/5 nodes are available: 5 No preemption victims found for incoming pod."
I0509 14:11:06.722646      12 preemption.go:264] "No preemption candidate is found; preemption is not helpful for scheduling" pod="default/cspod-50"
I0509 14:11:06.722682      12 schedule_one.go:1044] "Unable to schedule pod; no fit; waiting" pod="default/cspod-50" err="0/5 nodes are available: 5 Insufficient cpu. preemption: 0/5 nodes are available: 5 No preemption victims found for incoming pod."
I0509 14:11:06.723158      12 preemption.go:264] "No preemption candidate is found; preemption is not helpful for scheduling" pod="default/cspod-51"
I0509 14:11:06.723191      12 schedule_one.go:1044] "Unable to schedule pod; no fit; waiting" pod="default/cspod-51" err="0/5 nodes are available: 5 Insufficient cpu. preemption: 0/5 nodes are available: 5 No preemption victims found for incoming pod."
I0509 14:11:06.723664      12 preemption.go:264] "No preemption candidate is found; preemption is not helpful for scheduling" pod="default/cspod-52"
I0509 14:11:06.723698      12 schedule_one.go:1044] "Unable to schedule pod; no fit; waiting" pod="default/cspod-52" err="0/5 nodes are available: 5 Insufficient cpu. preemption: 0/5 nodes are available: 5 No preemption victims found for incoming pod."
I0509 14:11:06.724227      12 preemption.go:264] "No preemption candidate is found; preemption is not helpful for scheduling" pod="default/cspod-53"
I0509 14:11:06.724260      12 schedule_one.go:1044] "Unable to schedule pod; no fit; waiting" pod="default/cspod-53" err="0/5 nodes are available: 5 Insufficient cpu. preemption: 0/5 nodes are available: 5 No preemption victims found for incoming pod."
I0509 14:11:06.724769      12 preemption.go:264] "No preemption candidate is found; preemption is not helpful for scheduling" pod="default/cspod-54"
I0509 14:11:06.724800      12 schedule_one.go:1044] "Unable to schedule pod; no fit; waiting" pod="default/cspod-54" err="0/5 nodes are available: 5 Insufficient cpu. preemption: 0/5 nodes are available: 5 No preemption victims found for incoming pod."
I0509 14:11:06.725466      12 preemption.go:264] "No preemption candidate is found; preemption is not helpful for scheduling" pod="default/cspod-60"
I0509 14:11:06.725496      12 schedule_one.go:1044] "Unable to schedule pod; no fit; waiting" pod="default/cspod-60" err="0/5 nodes are available: 5 Insufficient cpu. preemption: 0/5 nodes are available: 5 No preemption victims found for incoming pod."
I0509 14:11:06.725998      12 preemption.go:264] "No preemption candidate is found; preemption is not helpful for scheduling" pod="default/cspod-61"
I0509 14:11:06.726028      12 schedule_one.go:1044] "Unable to schedule pod; no fit; waiting" pod="default/cspod-61" err="0/5 nodes are available: 5 Insufficient cpu. preemption: 0/5 nodes are available: 5 No preemption victims found for incoming pod."
I0509 14:11:06.726497      12 preemption.go:264] "No preemption candidate is found; preemption is not helpful for scheduling" pod="default/cspod-62"
I0509 14:11:06.726528      12 schedule_one.go:1044] "Unable to schedule pod; no fit; waiting" pod="default/cspod-62" err="0/5 nodes are available: 5 Insufficient cpu. preemption: 0/5 nodes are available: 5 No preemption victims found for incoming pod."
I0509 14:11:06.727074      12 preemption.go:264] "No preemption candidate is found; preemption is not helpful for scheduling" pod="default/cspod-63"
I0509 14:11:06.727104      12 schedule_one.go:1044] "Unable to schedule pod; no fit; waiting" pod="default/cspod-63" err="0/5 nodes are available: 5 Insufficient cpu. preemption: 0/5 nodes are available: 5 No preemption victims found for incoming pod."
I0509 14:11:06.727557      12 preemption.go:264] "No preemption candidate is found; preemption is not helpful for scheduling" pod="default/cspod-64"
I0509 14:11:06.727590      12 schedule_one.go:1044] "Unable to schedule pod; no fit; waiting" pod="default/cspod-64" err="0/5 nodes are available: 5 Insufficient cpu. preemption: 0/5 nodes are available: 5 No preemption victims found for incoming pod."
I0509 14:11:06.728059      12 preemption.go:264] "No preemption candidate is found; preemption is not helpful for scheduling" pod="default/cspod-65"
I0509 14:11:06.728091      12 schedule_one.go:1044] "Unable to schedule pod; no fit; waiting" pod="default/cspod-65" err="0/5 nodes are available: 5 Insufficient cpu. preemption: 0/5 nodes are available: 5 No preemption victims found for incoming pod."
I0509 14:11:06.728679      12 preemption.go:264] "No preemption candidate is found; preemption is not helpful for scheduling" pod="default/cspod-66"
I0509 14:11:06.728712      12 schedule_one.go:1044] "Unable to schedule pod; no fit; waiting" pod="default/cspod-66" err="0/5 nodes are available: 5 Insufficient cpu. preemption: 0/5 nodes are available: 5 No preemption victims found for incoming pod."
I0509 14:11:06.729229      12 preemption.go:264] "No preemption candidate is found; preemption is not helpful for scheduling" pod="default/cspod-67"
I0509 14:11:06.729262      12 schedule_one.go:1044] "Unable to schedule pod; no fit; waiting" pod="default/cspod-67" err="0/5 nodes are available: 5 Insufficient cpu. preemption: 0/5 nodes are available: 5 No preemption victims found for incoming pod."
I0509 14:11:06.729741      12 preemption.go:264] "No preemption candidate is found; preemption is not helpful for scheduling" pod="default/cspod-68"
I0509 14:11:06.729773      12 schedule_one.go:1044] "Unable to schedule pod; no fit; waiting" pod="default/cspod-68" err="0/5 nodes are available: 5 Insufficient cpu. preemption: 0/5 nodes are available: 5 No preemption victims found for incoming pod."
I0509 14:11:06.730326      12 preemption.go:264] "No preemption candidate is found; preemption is not helpful for scheduling" pod="default/cspod-69"
I0509 14:11:06.730359      12 schedule_one.go:1044] "Unable to schedule pod; no fit; waiting" pod="default/cspod-69" err="0/5 nodes are available: 5 Insufficient cpu. preemption: 0/5 nodes are available: 5 No preemption victims found for incoming pod."
I0509 14:11:06.769462      12 schedule_one.go:314] "Successfully bound pod to node" pod="default/cspod-30" node="csnode-2" evaluatedNodes=5 feasibleNodes=3
I0509 14:11:06.769600      12 schedule_one.go:314] "Successfully bound pod to node" pod="default/cspod-31" node="csnode-1" evaluatedNodes=5 feasibleNodes=2
I0509 14:11:06.769613      12 schedule_one.go:314] "Successfully bound pod to node" pod="default/cspod-32" node="csnode-1" evaluatedNodes=5 feasibleNodes=5
I0509 14:11:06.769867      12 schedule_one.go:314] "Successfully bound pod to node" pod="default/cspod-33" node="csnode-2" evaluatedNodes=5 feasibleNodes=4
I0509 14:11:06.769882      12 schedule_one.go:314] "Successfully bound pod to node" pod="default/cspod-36" node="csnode-0" evaluatedNodes=5 feasibleNodes=2
I0509 14:11:06.769955      12 schedule_one.go:314] "Successfully bound pod to node" pod="default/cspod-34" node="csnode-3" evaluatedNodes=5 feasibleNodes=3
I0509 14:11:06.769991      12 schedule_one.go:314] "Successfully bound pod to node" pod="default/cspod-35" node="csnode-3" evaluatedNodes=5 feasibleNodes=3
I0509 14:11:06.770125      12 preemption.go:264] "No preemption candidate is found; preemption is not helpful for scheduling" pod="default/cspod-40"
I0509 14:11:06.770164      12 schedule_one.go:1044] "Unable to schedule pod; no fit; waiting" pod="default/cspod-40" err="0/5 nodes are available: 5 Insufficient cpu. preemption: 0/5 nodes are available: 5 No preemption victims found for incoming pod."
I0509 14:11:06.770209      12 schedule_one.go:314] "Successfully bound pod to node" pod="default/cspod-37" node="csnode-0" evaluatedNodes=5 feasibleNodes=2
I0509 14:11:06.770232      12 schedule_one.go:314] "Successfully bound pod to node" pod="default/cspod-38" node="csnode-4" evaluatedNodes=5 feasibleNodes=1
I0509 14:11:06.770431      12 schedule_one.go:314] "Successfully bound pod to node" pod="default/cspod-39" node="csnode-4" evaluatedNodes=5 feasibleNodes=1
I0509 14:11:06.770780      12 preemption.go:264] "No preemption candidate is found; preemption is not helpful for scheduling" pod="default/cspod-41"
I0509 14:11:06.770815      12 schedule_one.go:1044] "Unable to schedule pod; no fit; waiting" pod="default/cspod-41" err="0/5 nodes are available: 5 Insufficient cpu. preemption: 0/5 nodes are available: 5 No preemption victims found for incoming pod."
I0509 14:11:06.771385      12 preemption.go:264] "No preemption candidate is found; preemption is not helpful for scheduling" pod="default/cspod-42"
I0509 14:11:06.771421      12 schedule_one.go:1044] "Unable to schedule pod; no fit; waiting" pod="default/cspod-42" err="0/5 nodes are available: 5 Insufficient cpu. preemption: 0/5 nodes are available: 5 No preemption victims found for incoming pod."
I0509 14:11:06.772010      12 preemption.go:264] "No preemption candidate is found; preemption is not helpful for scheduling" pod="default/cspod-43"
I0509 14:11:06.772049      12 schedule_one.go:1044] "Unable to schedule pod; no fit; waiting" pod="default/cspod-43" err="0/5 nodes are available: 5 Insufficient cpu. preemption: 0/5 nodes are available: 5 No preemption victims found for incoming pod."
I0509 14:11:06.772573      12 preemption.go:264] "No preemption candidate is found; preemption is not helpful for scheduling" pod="default/cspod-44"
I0509 14:11:06.772611      12 schedule_one.go:1044] "Unable to schedule pod; no fit; waiting" pod="default/cspod-44" err="0/5 nodes are available: 5 Insufficient cpu. preemption: 0/5 nodes are available: 5 No preemption victims found for incoming pod."
I0509 14:11:06.773132      12 preemption.go:264] "No preemption candidate is found; preemption is not helpful for scheduling" pod="default/cspod-45"
I0509 14:11:06.773165      12 schedule_one.go:1044] "Unable to schedule pod; no fit; waiting" pod="default/cspod-45" err="0/5 nodes are available: 5 Insufficient cpu. preemption: 0/5 nodes are available: 5 No preemption victims found for incoming pod."
I0509 14:11:06.773654      12 preemption.go:264] "No preemption candidate is found; preemption is not helpful for scheduling" pod="default/cspod-46"
I0509 14:11:06.773689      12 schedule_one.go:1044] "Unable to schedule pod; no fit; waiting" pod="default/cspod-46" err="0/5 nodes are available: 5 Insufficient cpu. preemption: 0/5 nodes are available: 5 No preemption victims found for incoming pod."
I0509 14:11:06.774222      12 preemption.go:264] "No preemption candidate is found; preemption is not helpful for scheduling" pod="default/cspod-47"
I0509 14:11:06.774255      12 schedule_one.go:1044] "Unable to schedule pod; no fit; waiting" pod="default/cspod-47" err="0/5 nodes are available: 5 Insufficient cpu. preemption: 0/5 nodes are available: 5 No preemption victims found for incoming pod."
I0509 14:11:06.774759      12 preemption.go:264] "No preemption candidate is found; preemption is not helpful for scheduling" pod="default/cspod-48"
I0509 14:11:06.774792      12 schedule_one.go:1044] "Unable to schedule pod; no fit; waiting" pod="default/cspod-48" err="0/5 nodes are available: 5 Insufficient cpu. preemption: 0/5 nodes are available: 5 No preemption victims found for incoming pod."
I0509 14:11:06.775280      12 preemption.go:264] "No preemption candidate is found; preemption is not helpful for scheduling" pod="default/cspod-49"
I0509 14:11:06.775311      12 schedule_one.go:1044] "Unable to schedule pod; no fit; waiting" pod="default/cspod-49" err="0/5 nodes are available: 5 Insufficient cpu. preemption: 0/5 nodes are available: 5 No preemption victims found for incoming pod."
I0509 14:11:06.775823      12 preemption.go:264] "No preemption candidate is found; preemption is not helpful for scheduling" pod="default/cspod-50"
I0509 14:11:06.775860      12 schedule_one.go:1044] "Unable to schedule pod; no fit; waiting" pod="default/cspod-50" err="0/5 nodes are available: 5 Insufficient cpu. preemption: 0/5 nodes are available: 5 No preemption victims found for incoming pod."
I0509 14:11:06.776330      12 preemption.go:264] "No preemption candidate is found; preemption is not helpful for scheduling" pod="default/cspod-51"
I0509 14:11:06.776362      12 schedule_one.go:1044] "Unable to schedule pod; no fit; waiting" pod="default/cspod-51" err="0/5 nodes are available: 5 Insufficient cpu. preemption: 0/5 nodes are available: 5 No preemption victims found for incoming pod."
I0509 14:11:06.776851      12 preemption.go:264] "No preemption candidate is found; preemption is not helpful for scheduling" pod="default/cspod-52"
I0509 14:11:06.776885      12 schedule_one.go:1044] "Unable to schedule pod; no fit; waiting" pod="default/cspod-52" err="0/5 nodes are available: 5 Insufficient cpu. preemption: 0/5 nodes are available: 5 No preemption victims found for incoming pod."
I0509 14:11:06.777382      12 preemption.go:264] "No preemption candidate is found; preemption is not helpful for scheduling" pod="default/cspod-53"
I0509 14:11:06.777414      12 schedule_one.go:1044] "Unable to schedule pod; no fit; waiting" pod="default/cspod-53" err="0/5 nodes are available: 5 Insufficient cpu. preemption: 0/5 nodes are available: 5 No preemption victims found for incoming pod."
I0509 14:11:06.777881      12 preemption.go:264] "No preemption candidate is found; preemption is not helpful for scheduling" pod="default/cspod-54"
I0509 14:11:06.777912      12 schedule_one.go:1044] "Unable to schedule pod; no fit; waiting" pod="default/cspod-54" err="0/5 nodes are available: 5 Insufficient cpu. preemption: 0/5 nodes are available: 5 No preemption victims found for incoming pod."
I0509 14:11:06.778401      12 preemption.go:264] "No preemption candidate is found; preemption is not helpful for scheduling" pod="default/cspod-60"
I0509 14:11:06.778432      12 schedule_one.go:1044] "Unable to schedule pod; no fit; waiting" pod="default/cspod-60" err="0/5 nodes are available: 5 Insufficient cpu. preemption: 0/5 nodes are available: 5 No preemption victims found for incoming pod."
I0509 14:11:06.778869      12 preemption.go:264] "No preemption candidate is found; preemption is not helpful for scheduling" pod="default/cspod-61"
I0509 14:11:06.778898      12 schedule_one.go:1044] "Unable to schedule pod; no fit; waiting" pod="default/cspod-61" err="0/5 nodes are available: 5 Insufficient cpu. preemption: 0/5 nodes are available: 5 No preemption victims found for incoming pod."
I0509 14:11:06.779495      12 preemption.go:264] "No preemption candidate is found; preemption is not helpful for scheduling" pod="default/cspod-62"
I0509 14:11:06.779528      12 schedule_one.go:1044] "Unable to schedule pod; no fit; waiting" pod="default/cspod-62" err="0/5 nodes are available: 5 Insufficient cpu. preemption: 0/5 nodes are available: 5 No preemption victims found for incoming pod."
I0509 14:11:06.780005      12 preemption.go:264] "No preemption candidate is found; preemption is not helpful for scheduling" pod="default/cspod-63"
I0509 14:11:06.780035      12 schedule_one.go:1044] "Unable to schedule pod; no fit; waiting" pod="default/cspod-63" err="0/5 nodes are available: 5 Insufficient cpu. preemption: 0/5 nodes are available: 5 No preemption victims found for incoming pod."
I0509 14:11:06.780605      12 preemption.go:264] "No preemption candidate is found; preemption is not helpful for scheduling" pod="default/cspod-64"
I0509 14:11:06.780637      12 schedule_one.go:1044] "Unable to schedule pod; no fit; waiting" pod="default/cspod-64" err="0/5 nodes are available: 5 Insufficient cpu. preemption: 0/5 nodes are available: 5 No preemption victims found for incoming pod."
I0509 14:11:06.781159      12 preemption.go:264] "No preemption candidate is found; preemption is not helpful for scheduling" pod="default/cspod-65"
I0509 14:11:06.781192      12 schedule_one.go:1044] "Unable to schedule pod; no fit; waiting" pod="default/cspod-65" err="0/5 nodes are available: 5 Insufficient cpu. preemption: 0/5 nodes are available: 5 No preemption victims found for incoming pod."
I0509 14:11:06.781689      12 preemption.go:264] "No preemption candidate is found; preemption is not helpful for scheduling" pod="default/cspod-66"
I0509 14:11:06.781724      12 schedule_one.go:1044] "Unable to schedule pod; no fit; waiting" pod="default/cspod-66" err="0/5 nodes are available: 5 Insufficient cpu. preemption: 0/5 nodes are available: 5 No preemption victims found for incoming pod."
I0509 14:11:06.782237      12 preemption.go:264] "No preemption candidate is found; preemption is not helpful for scheduling" pod="default/cspod-67"
I0509 14:11:06.782270      12 schedule_one.go:1044] "Unable to schedule pod; no fit; waiting" pod="default/cspod-67" err="0/5 nodes are available: 5 Insufficient cpu. preemption: 0/5 nodes are available: 5 No preemption victims found for incoming pod."
I0509 14:11:06.782738      12 preemption.go:264] "No preemption candidate is found; preemption is not helpful for scheduling" pod="default/cspod-68"
I0509 14:11:06.782769      12 schedule_one.go:1044] "Unable to schedule pod; no fit; waiting" pod="default/cspod-68" err="0/5 nodes are available: 5 Insufficient cpu. preemption: 0/5 nodes are available: 5 No preemption victims found for incoming pod."
I0509 14:11:06.783203      12 preemption.go:264] "No preemption candidate is found; preemption is not helpful for scheduling" pod="default/cspod-69"
I0509 14:11:06.783233      12 schedule_one.go:1044] "Unable to schedule pod; no fit; waiting" pod="default/cspod-69" err="0/5 nodes are available: 5 Insufficient cpu. preemption: 0/5 nodes are available: 5 No preemption victims found for incoming pod."
I0509 14:11:06.806167      12 preemption.go:264] "No preemption candidate is found; preemption is not helpful for scheduling" pod="default/cspod-43"
I0509 14:11:06.806209      12 schedule_one.go:1044] "Unable to schedule pod; no fit; waiting" pod="default/cspod-43" err="0/5 nodes are available: 5 Insufficient cpu. preemption: 0/5 nodes are available: 5 No preemption victims found for incoming pod."
I0509 14:11:06.806416      12 schedule_one.go:314] "Successfully bound pod to node" pod="default/cspod-41" node="csnode-4" evaluatedNodes=5 feasibleNodes=1
I0509 14:11:06.806487      12 schedule_one.go:314] "Successfully bound pod to node" pod="default/cspod-40" node="csnode-0" evaluatedNodes=5 feasibleNodes=2
I0509 14:11:06.806770      12 schedule_one.go:314] "Successfully bound pod to node" pod="default/cspod-42" node="csnode-4" evaluatedNodes=5 feasibleNodes=1
I0509 14:11:06.806981      12 preemption.go:264] "No preemption candidate is found; preemption is not helpful for scheduling" pod="default/cspod-44"
I0509 14:11:06.807012      12 schedule_one.go:1044] "Unable to schedule pod; no fit; waiting" pod="default/cspod-44" err="0/5 nodes are available: 5 Insufficient cpu. preemption: 0/5 nodes are available: 5 No preemption victims found for incoming pod."
I0509 14:11:06.807507      12 preemption.go:264] "No preemption candidate is found; preemption is not helpful for scheduling" pod="default/cspod-45"
I0509 14:11:06.807541      12 schedule_one.go:1044] "Unable to schedule pod; no fit; waiting" pod="default/cspod-45" err="0/5 nodes are available: 5 Insufficient cpu. preemption: 0/5 nodes are available: 5 No preemption victims found for incoming pod."
I0509 14:11:06.808017      12 preemption.go:264] "No preemption candidate is found; preemption is not helpful for scheduling" pod="default/cspod-46"
I0509 14:11:06.808048      12 schedule_one.go:1044] "Unable to schedule pod; no fit; waiting" pod="default/cspod-46" err="0/5 nodes are available: 5 Insufficient cpu. preemption: 0/5 nodes are available: 5 No preemption victims found for incoming pod."
I0509 14:11:06.808517      12 preemption.go:264] "No preemption candidate is found; preemption is not helpful for scheduling" pod="default/cspod-47"
I0509 14:11:06.808548      12 schedule_one.go:1044] "Unable to schedule pod; no fit; waiting" pod="default/cspod-47" err="0/5 nodes are available: 5 Insufficient cpu. preemption: 0/5 nodes are available: 5 No preemption victims found for incoming pod."
I0509 14:11:06.809000      12 preemption.go:264] "No preemption candidate is found; preemption is not helpful for scheduling" pod="default/cspod-48"
I0509 14:11:06.809031      12 schedule_one.go:1044] "Unable to schedule pod; no fit; waiting" pod="default/cspod-48" err="0/5 nodes are available: 5 Insufficient cpu. preemption: 0/5 nodes are available: 5 No preemption victims found for incoming pod."
I0509 14:11:06.809621      12 preemption.go:264] "No preemption candidate is found; preemption is not helpful for scheduling" pod="default/cspod-49"
I0509 14:11:06.809652      12 schedule_one.go:1044] "Unable to schedule pod; no fit; waiting" pod="default/cspod-49" err="0/5 nodes are available: 5 Insufficient cpu. preemption: 0/5 nodes are available: 5 No preemption victims found for incoming pod."
I0509 14:11:06.810171      12 preemption.go:264] "No preemption candidate is found; preemption is not helpful for scheduling" pod="default/cspod-50"
I0509 14:11:06.810205      12 schedule_one.go:1044] "Unable to schedule pod; no fit; waiting" pod="default/cspod-50" err="0/5 nodes are available: 5 Insufficient cpu. preemption: 0/5 nodes are available: 5 No preemption victims found for incoming pod."
I0509 14:11:06.810788      12 preemption.go:264] "No preemption candidate is found; preemption is not helpful for scheduling" pod="default/cspod-51"
I0509 14:11:06.810821      12 schedule_one.go:1044] "Unable to schedule pod; no fit; waiting" pod="default/cspod-51" err="0/5 nodes are available: 5 Insufficient cpu. preemption: 0/5 nodes are available: 5 No preemption victims found for incoming pod."
I0509 14:11:06.811320      12 preemption.go:264] "No preemption candidate is found; preemption is not helpful for scheduling" pod="default/cspod-52"
I0509 14:11:06.811360      12 schedule_one.go:1044] "Unable to schedule pod; no fit; waiting" pod="default/cspod-52" err="0/5 nodes are available: 5 Insufficient cpu. preemption: 0/5 nodes are available: 5 No preemption victims found for incoming pod."
I0509 14:11:06.811807      12 preemption.go:264] "No preemption candidate is found; preemption is not helpful for scheduling" pod="default/cspod-53"
I0509 14:11:06.811837      12 schedule_one.go:1044] "Unable to schedule pod; no fit; waiting" pod="default/cspod-53" err="0/5 nodes are available: 5 Insufficient cpu. preemption: 0/5 nodes are available: 5 No preemption victims found for incoming pod."
I0509 14:11:06.812295      12 preemption.go:264] "No preemption candidate is found; preemption is not helpful for scheduling" pod="default/cspod-54"
I0509 14:11:06.812326      12 schedule_one.go:1044] "Unable to schedule pod; no fit; waiting" pod="default/cspod-54" err="0/5 nodes are available: 5 Insufficient cpu. preemption: 0/5 nodes are available: 5 No preemption victims found for incoming pod."
I0509 14:11:06.812798      12 preemption.go:264] "No preemption candidate is found; preemption is not helpful for scheduling" pod="default/cspod-60"
I0509 14:11:06.812828      12 schedule_one.go:1044] "Unable to schedule pod; no fit; waiting" pod="default/cspod-60" err="0/5 nodes are available: 5 Insufficient cpu. preemption: 0/5 nodes are available: 5 No preemption victims found for incoming pod."
I0509 14:11:06.813337      12 preemption.go:264] "No preemption candidate is found; preemption is not helpful for scheduling" pod="default/cspod-61"
I0509 14:11:06.813372      12 schedule_one.go:1044] "Unable to schedule pod; no fit; waiting" pod="default/cspod-61" err="0/5 nodes are available: 5 Insufficient cpu. preemption: 0/5 nodes are available: 5 No preemption victims found for incoming pod."
I0509 14:11:06.813907      12 preemption.go:264] "No preemption candidate is found; preemption is not helpful for scheduling" pod="default/cspod-62"
I0509 14:11:06.813942      12 schedule_one.go:1044] "Unable to schedule pod; no fit; waiting" pod="default/cspod-62" err="0/5 nodes are available: 5 Insufficient cpu. preemption: 0/5 nodes are available: 5 No preemption victims found for incoming pod."
I0509 14:11:06.814472      12 preemption.go:264] "No preemption candidate is found; preemption is not helpful for scheduling" pod="default/cspod-63"
I0509 14:11:06.814502      12 schedule_one.go:1044] "Unable to schedule pod; no fit; waiting" pod="default/cspod-63" err="0/5 nodes are available: 5 Insufficient cpu. preemption: 0/5 nodes are available: 5 No preemption victims found for incoming pod."
I0509 14:11:06.815004      12 preemption.go:264] "No preemption candidate is found; preemption is not helpful for scheduling" pod="default/cspod-64"
I0509 14:11:06.815042      12 schedule_one.go:1044] "Unable to schedule pod; no fit; waiting" pod="default/cspod-64" err="0/5 nodes are available: 5 Insufficient cpu. preemption: 0/5 nodes are available: 5 No preemption victims found for incoming pod."
I0509 14:11:06.815609      12 preemption.go:264] "No preemption candidate is found; preemption is not helpful for scheduling" pod="default/cspod-65"
I0509 14:11:06.815643      12 schedule_one.go:1044] "Unable to schedule pod; no fit; waiting" pod="default/cspod-65" err="0/5 nodes are available: 5 Insufficient cpu. preemption: 0/5 nodes are available: 5 No preemption victims found for incoming pod."
I0509 14:11:06.816205      12 preemption.go:264] "No preemption candidate is found; preemption is not helpful for scheduling" pod="default/cspod-66"
I0509 14:11:06.816244      12 schedule_one.go:1044] "Unable to schedule pod; no fit; waiting" pod="default/cspod-66" err="0/5 nodes are available: 5 Insufficient cpu. preemption: 0/5 nodes are available: 5 No preemption victims found for incoming pod."
I0509 14:11:06.816816      12 preemption.go:264] "No preemption candidate is found; preemption is not helpful for scheduling" pod="default/cspod-67"
I0509 14:11:06.816852      12 schedule_one.go:1044] "Unable to schedule pod; no fit; waiting" pod="default/cspod-67" err="0/5 nodes are available: 5 Insufficient cpu. preemption: 0/5 nodes are available: 5 No preemption victims found for incoming pod."
I0509 14:11:06.817429      12 preemption.go:264] "No preemption candidate is found; preemption is not helpful for scheduling" pod="default/cspod-68"
I0509 14:11:06.817464      12 schedule_one.go:1044] "Unable to schedule pod; no fit; waiting" pod="default/cspod-68" err="0/5 nodes are available: 5 Insufficient cpu. preemption: 0/5 nodes are available: 5 No preemption victims found for incoming pod."
I0509 14:11:06.818039      12 preemption.go:264] "No preemption candidate is found; preemption is not helpful for scheduling" pod="default/cspod-69"
I0509 14:11:06.818074      12 schedule_one.go:1044] "Unable to schedule pod; no fit; waiting" pod="default/cspod-69" err="0/5 nodes are available: 5 Insufficient cpu. preemption: 0/5 nodes are available: 5 No preemption victims found for incoming pod."
I0509 14:11:06.830622      12 preemption.go:264] "No preemption candidate is found; preemption is not helpful for scheduling" pod="default/cspod-46"
I0509 14:11:06.830685      12 schedule_one.go:1044] "Unable to schedule pod; no fit; waiting" pod="default/cspod-46" err="0/5 nodes are available: 5 Insufficient cpu. preemption: 0/5 nodes are available: 5 No preemption victims found for incoming pod."
I0509 14:11:06.830625      12 schedule_one.go:314] "Successfully bound pod to node" pod="default/cspod-43" node="csnode-2" evaluatedNodes=5 feasibleNodes=2
I0509 14:11:06.849215      12 schedule_one.go:314] "Successfully bound pod to node" pod="default/cspod-44" node="csnode-1" evaluatedNodes=5 feasibleNodes=1
I0509 14:11:06.868906      12 schedule_one.go:314] "Successfully bound pod to node" pod="default/cspod-45" node="csnode-1" evaluatedNodes=5 feasibleNodes=1
I0509 14:11:06.890189      12 preemption.go:264] "No preemption candidate is found; preemption is not helpful for scheduling" pod="default/cspod-47"
I0509 14:11:06.890236      12 schedule_one.go:1044] "Unable to schedule pod; no fit; waiting" pod="default/cspod-47" err="0/5 nodes are available: 5 Insufficient cpu. preemption: 0/5 nodes are available: 5 No preemption victims found for incoming pod."
I0509 14:11:06.909602      12 preemption.go:264] "No preemption candidate is found; preemption is not helpful for scheduling" pod="default/cspod-48"
I0509 14:11:06.909653      12 schedule_one.go:1044] "Unable to schedule pod; no fit; waiting" pod="default/cspod-48" err="0/5 nodes are available: 5 Insufficient cpu. preemption: 0/5 nodes are available: 5 No preemption victims found for incoming pod."
I0509 14:11:06.929963      12 preemption.go:264] "No preemption candidate is found; preemption is not helpful for scheduling" pod="default/cspod-49"
I0509 14:11:06.930030      12 schedule_one.go:1044] "Unable to schedule pod; no fit; waiting" pod="default/cspod-49" err="0/5 nodes are available: 5 Insufficient cpu. preemption: 0/5 nodes are available: 5 No preemption victims found for incoming pod."
I0509 14:11:06.949446      12 preemption.go:264] "No preemption candidate is found; preemption is not helpful for scheduling" pod="default/cspod-50"
I0509 14:11:06.949497      12 schedule_one.go:1044] "Unable to schedule pod; no fit; waiting" pod="default/cspod-50" err="0/5 nodes are available: 5 Insufficient cpu. preemption: 0/5 nodes are available: 5 No preemption victims found for incoming pod."
I0509 14:11:06.969804      12 preemption.go:264] "No preemption candidate is found; preemption is not helpful for scheduling" pod="default/cspod-51"
I0509 14:11:06.969853      12 schedule_one.go:1044] "Unable to schedule pod; no fit; waiting" pod="default/cspod-51" err="0/5 nodes are available: 5 Insufficient cpu. preemption: 0/5 nodes are available: 5 No preemption victims found for incoming pod."
I0509 14:11:06.990498      12 preemption.go:264] "No preemption candidate is found; preemption is not helpful for scheduling" pod="default/cspod-52"
I0509 14:11:06.990549      12 schedule_one.go:1044] "Unable to schedule pod; no fit; waiting" pod="default/cspod-52" err="0/5 nodes are available: 5 Insufficient cpu. preemption: 0/5 nodes are available: 5 No preemption victims found for incoming pod."
I0509 14:11:07.009422      12 preemption.go:264] "No preemption candidate is found; preemption is not helpful for scheduling" pod="default/cspod-53"
I0509 14:11:07.009492      12 schedule_one.go:1044] "Unable to schedule pod; no fit; waiting" pod="default/cspod-53" err="0/5 nodes are available: 5 Insufficient cpu. preemption: 0/5 nodes are available: 5 No preemption victims found for incoming pod."
I0509 14:11:07.029911      12 preemption.go:264] "No preemption candidate is found; preemption is not helpful for scheduling" pod="default/cspod-54"
I0509 14:11:07.029955      12 schedule_one.go:1044] "Unable to schedule pod; no fit; waiting" pod="default/cspod-54" err="0/5 nodes are available: 5 Insufficient cpu. preemption: 0/5 nodes are available: 5 No preemption victims found for incoming pod."
I0509 14:11:07.049260      12 preemption.go:264] "No preemption candidate is found; preemption is not helpful for scheduling" pod="default/cspod-60"
I0509 14:11:07.049307      12 schedule_one.go:1044] "Unable to schedule pod; no fit; waiting" pod="default/cspod-60" err="0/5 nodes are available: 5 Insufficient cpu. preemption: 0/5 nodes are available: 5 No preemption victims found for incoming pod."
I0509 14:11:07.069504      12 preemption.go:264] "No preemption candidate is found; preemption is not helpful for scheduling" pod="default/cspod-61"
I0509 14:11:07.069581      12 schedule_one.go:1044] "Unable to schedule pod; no fit; waiting" pod="default/cspod-61" err="0/5 nodes are available: 5 Insufficient cpu. preemption: 0/5 nodes are available: 5 No preemption victims found for incoming pod."
I0509 14:11:07.089857      12 preemption.go:264] "No preemption candidate is found; preemption is not helpful for scheduling" pod="default/cspod-62"
I0509 14:11:07.089901      12 schedule_one.go:1044] "Unable to schedule pod; no fit; waiting" pod="default/cspod-62" err="0/5 nodes are available: 5 Insufficient cpu. preemption: 0/5 nodes are available: 5 No preemption victims found for incoming pod."
I0509 14:11:07.108856      12 preemption.go:264] "No preemption candidate is found; preemption is not helpful for scheduling" pod="default/cspod-63"
I0509 14:11:07.108893      12 schedule_one.go:1044] "Unable to schedule pod; no fit; waiting" pod="default/cspod-63" err="0/5 nodes are available: 5 Insufficient cpu. preemption: 0/5 nodes are available: 5 No preemption victims found for incoming pod."
I0509 14:11:07.130162      12 preemption.go:264] "No preemption candidate is found; preemption is not helpful for scheduling" pod="default/cspod-64"
I0509 14:11:07.130208      12 schedule_one.go:1044] "Unable to schedule pod; no fit; waiting" pod="default/cspod-64" err="0/5 nodes are available: 5 Insufficient cpu. preemption: 0/5 nodes are available: 5 No preemption victims found for incoming pod."
I0509 14:11:07.149413      12 preemption.go:264] "No preemption candidate is found; preemption is not helpful for scheduling" pod="default/cspod-65"
I0509 14:11:07.149458      12 schedule_one.go:1044] "Unable to schedule pod; no fit; waiting" pod="default/cspod-65" err="0/5 nodes are available: 5 Insufficient cpu. preemption: 0/5 nodes are available: 5 No preemption victims found for incoming pod."
I0509 14:11:07.169404      12 preemption.go:264] "No preemption candidate is found; preemption is not helpful for scheduling" pod="default/cspod-66"
I0509 14:11:07.169442      12 schedule_one.go:1044] "Unable to schedule pod; no fit; waiting" pod="default/cspod-66" err="0/5 nodes are available: 5 Insufficient cpu. preemption: 0/5 nodes are available: 5 No preemption victims found for incoming pod."
I0509 14:11:07.189560      12 preemption.go:264] "No preemption candidate is found; preemption is not helpful for scheduling" pod="default/cspod-67"
I0509 14:11:07.189601      12 schedule_one.go:1044] "Unable to schedule pod; no fit; waiting" pod="default/cspod-67" err="0/5 nodes are available: 5 Insufficient cpu. preemption: 0/5 nodes are available: 5 No preemption victims found for incoming pod."
I0509 14:11:07.210097      12 preemption.go:264] "No preemption candidate is found; preemption is not helpful for scheduling" pod="default/cspod-68"
I0509 14:11:07.210167      12 schedule_one.go:1044] "Unable to schedule pod; no fit; waiting" pod="default/cspod-68" err="0/5 nodes are available: 5 Insufficient cpu. preemption: 0/5 nodes are available: 5 No preemption victims found for incoming pod."
I0509 14:11:07.229493      12 preemption.go:264] "No preemption candidate is found; preemption is not helpful for scheduling" pod="default/cspod-69"
I0509 14:11:07.229539      12 schedule_one.go:1044] "Unable to schedule pod; no fit; waiting" pod="default/cspod-69" err="0/5 nodes are available: 5 Insufficient cpu. preemption: 0/5 nodes are available: 5 No preemption victims found for incoming pod."
I0509 14:11:07.256112      12 preemption.go:264] "No preemption candidate is found; preemption is not helpful for scheduling" pod="default/cspod-49"
I0509 14:11:07.256152      12 schedule_one.go:1044] "Unable to schedule pod; no fit; waiting" pod="default/cspod-49" err="0/5 nodes are available: 5 Insufficient cpu. preemption: 0/5 nodes are available: 5 No preemption victims found for incoming pod."
I0509 14:11:07.268810      12 schedule_one.go:314] "Successfully bound pod to node" pod="default/cspod-46" node="csnode-0" evaluatedNodes=5 feasibleNodes=2
I0509 14:11:07.289940      12 schedule_one.go:314] "Successfully bound pod to node" pod="default/cspod-47" node="csnode-4" evaluatedNodes=5 feasibleNodes=1
I0509 14:11:07.309591      12 schedule_one.go:314] "Successfully bound pod to node" pod="default/cspod-48" node="csnode-4" evaluatedNodes=5 feasibleNodes=1
I0509 14:11:07.329811      12 preemption.go:264] "No preemption candidate is found; preemption is not helpful for scheduling" pod="default/cspod-50"
I0509 14:11:07.329879      12 schedule_one.go:1044] "Unable to schedule pod; no fit; waiting" pod="default/cspod-50" err="0/5 nodes are available: 5 Insufficient cpu. preemption: 0/5 nodes are available: 5 No preemption victims found for incoming pod."
I0509 14:11:07.349002      12 preemption.go:264] "No preemption candidate is found; preemption is not helpful for scheduling" pod="default/cspod-51"
I0509 14:11:07.349071      12 schedule_one.go:1044] "Unable to schedule pod; no fit; waiting" pod="default/cspod-51" err="0/5 nodes are available: 5 Insufficient cpu. preemption: 0/5 nodes are available: 5 No preemption victims found for incoming pod."
I0509 14:11:07.369422      12 preemption.go:264] "No preemption candidate is found; preemption is not helpful for scheduling" pod="default/cspod-52"
I0509 14:11:07.369470      12 schedule_one.go:1044] "Unable to schedule pod; no fit; waiting" pod="default/cspod-52" err="0/5 nodes are available: 5 Insufficient cpu. preemption: 0/5 nodes are available: 5 No preemption victims found for incoming pod."
I0509 14:11:07.389784      12 preemption.go:264] "No preemption candidate is found; preemption is not helpful for scheduling" pod="default/cspod-53"
I0509 14:11:07.389829      12 schedule_one.go:1044] "Unable to schedule pod; no fit; waiting" pod="default/cspod-53" err="0/5 nodes are available: 5 Insufficient cpu. preemption: 0/5 nodes are available: 5 No preemption victims found for incoming pod."
I0509 14:11:07.410069      12 preemption.go:264] "No preemption candidate is found; preemption is not helpful for scheduling" pod="default/cspod-54"
I0509 14:11:07.410116      12 schedule_one.go:1044] "Unable to schedule pod; no fit; waiting" pod="default/cspod-54" err="0/5 nodes are available: 5 Insufficient cpu. preemption: 0/5 nodes are available: 5 No preemption victims found for incoming pod."
I0509 14:11:07.429360      12 preemption.go:264] "No preemption candidate is found; preemption is not helpful for scheduling" pod="default/cspod-60"
I0509 14:11:07.429427      12 schedule_one.go:1044] "Unable to schedule pod; no fit; waiting" pod="default/cspod-60" err="0/5 nodes are available: 5 Insufficient cpu. preemption: 0/5 nodes are available: 5 No preemption victims found for incoming pod."
I0509 14:11:07.450017      12 preemption.go:264] "No preemption candidate is found; preemption is not helpful for scheduling" pod="default/cspod-61"
I0509 14:11:07.450068      12 schedule_one.go:1044] "Unable to schedule pod; no fit; waiting" pod="default/cspod-61" err="0/5 nodes are available: 5 Insufficient cpu. preemption: 0/5 nodes are available: 5 No preemption victims found for incoming pod."
I0509 14:11:07.469208      12 preemption.go:264] "No preemption candidate is found; preemption is not helpful for scheduling" pod="default/cspod-62"
I0509 14:11:07.469252      12 schedule_one.go:1044] "Unable to schedule pod; no fit; waiting" pod="default/cspod-62" err="0/5 nodes are available: 5 Insufficient cpu. preemption: 0/5 nodes are available: 5 No preemption victims found for incoming pod."
I0509 14:11:07.489371      12 preemption.go:264] "No preemption candidate is found; preemption is not helpful for scheduling" pod="default/cspod-63"
I0509 14:11:07.489415      12 schedule_one.go:1044] "Unable to schedule pod; no fit; waiting" pod="default/cspod-63" err="0/5 nodes are available: 5 Insufficient cpu. preemption: 0/5 nodes are available: 5 No preemption victims found for incoming pod."
I0509 14:11:07.509826      12 preemption.go:264] "No preemption candidate is found; preemption is not helpful for scheduling" pod="default/cspod-64"
I0509 14:11:07.509871      12 schedule_one.go:1044] "Unable to schedule pod; no fit; waiting" pod="default/cspod-64" err="0/5 nodes are available: 5 Insufficient cpu. preemption: 0/5 nodes are available: 5 No preemption victims found for incoming pod."
I0509 14:11:07.530484      12 preemption.go:264] "No preemption candidate is found; preemption is not helpful for scheduling" pod="default/cspod-65"
I0509 14:11:07.530529      12 schedule_one.go:1044] "Unable to schedule pod; no fit; waiting" pod="default/cspod-65" err="0/5 nodes are available: 5 Insufficient cpu. preemption: 0/5 nodes are available: 5 No preemption victims found for incoming pod."
I0509 14:11:07.549696      12 preemption.go:264] "No preemption candidate is found; preemption is not helpful for scheduling" pod="default/cspod-66"
I0509 14:11:07.549733      12 schedule_one.go:1044] "Unable to schedule pod; no fit; waiting" pod="default/cspod-66" err="0/5 nodes are available: 5 Insufficient cpu. preemption: 0/5 nodes are available: 5 No preemption victims found for incoming pod."
I0509 14:11:07.569942      12 preemption.go:264] "No preemption candidate is found; preemption is not helpful for scheduling" pod="default/cspod-67"
I0509 14:11:07.570024      12 schedule_one.go:1044] "Unable to schedule pod; no fit; waiting" pod="default/cspod-67" err="0/5 nodes are available: 5 Insufficient cpu. preemption: 0/5 nodes are available: 5 No preemption victims found for incoming pod."
I0509 14:11:07.589376      12 preemption.go:264] "No preemption candidate is found; preemption is not helpful for scheduling" pod="default/cspod-68"
I0509 14:11:07.589424      12 schedule_one.go:1044] "Unable to schedule pod; no fit; waiting" pod="default/cspod-68" err="0/5 nodes are available: 5 Insufficient cpu. preemption: 0/5 nodes are available: 5 No preemption victims found for incoming pod."
I0509 14:11:07.609527      12 preemption.go:264] "No preemption candidate is found; preemption is not helpful for scheduling" pod="default/cspod-69"
I0509 14:11:07.609567      12 schedule_one.go:1044] "Unable to schedule pod; no fit; waiting" pod="default/cspod-69" err="0/5 nodes are available: 5 Insufficient cpu. preemption: 0/5 nodes are available: 5 No preemption victims found for incoming pod."
I0509 14:11:07.638147      12 preemption.go:264] "No preemption candidate is found; preemption is not helpful for scheduling" pod="default/cspod-51"
I0509 14:11:07.638221      12 schedule_one.go:1044] "Unable to schedule pod; no fit; waiting" pod="default/cspod-51" err="0/5 nodes are available: 5 Insufficient cpu. preemption: 0/5 nodes are available: 5 No preemption victims found for incoming pod."
I0509 14:11:07.648779      12 schedule_one.go:314] "Successfully bound pod to node" pod="default/cspod-49" node="csnode-3" evaluatedNodes=5 feasibleNodes=1
I0509 14:11:07.669704      12 schedule_one.go:314] "Successfully bound pod to node" pod="default/cspod-50" node="csnode-3" evaluatedNodes=5 feasibleNodes=1
I0509 14:11:07.689711      12 preemption.go:264] "No preemption candidate is found; preemption is not helpful for scheduling" pod="default/cspod-52"
I0509 14:11:07.689754      12 schedule_one.go:1044] "Unable to schedule pod; no fit; waiting" pod="default/cspod-52" err="0/5 nodes are available: 5 Insufficient cpu. preemption: 0/5 nodes are available: 5 No preemption victims found for incoming pod."
I0509 14:11:07.709940      12 preemption.go:264] "No preemption candidate is found; preemption is not helpful for scheduling" pod="default/cspod-53"
I0509 14:11:07.709985      12 schedule_one.go:1044] "Unable to schedule pod; no fit; waiting" pod="default/cspod-53" err="0/5 nodes are available: 5 Insufficient cpu. preemption: 0/5 nodes are available: 5 No preemption victims found for incoming pod."
I0509 14:11:07.729030      12 preemption.go:264] "No preemption candidate is found; preemption is not helpful for scheduling" pod="default/cspod-54"
I0509 14:11:07.729071      12 schedule_one.go:1044] "Unable to schedule pod; no fit; waiting" pod="default/cspod-54" err="0/5 nodes are available: 5 Insufficient cpu. preemption: 0/5 nodes are available: 5 No preemption victims found for incoming pod."
I0509 14:11:07.749060      12 preemption.go:264] "No preemption candidate is found; preemption is not helpful for scheduling" pod="default/cspod-60"
I0509 14:11:07.749100      12 schedule_one.go:1044] "Unable to schedule pod; no fit; waiting" pod="default/cspod-60" err="0/5 nodes are available: 5 Insufficient cpu. preemption: 0/5 nodes are available: 5 No preemption victims found for incoming pod."
I0509 14:11:07.769177      12 preemption.go:264] "No preemption candidate is found; preemption is not helpful for scheduling" pod="default/cspod-61"
I0509 14:11:07.769220      12 schedule_one.go:1044] "Unable to schedule pod; no fit; waiting" pod="default/cspod-61" err="0/5 nodes are available: 5 Insufficient cpu. preemption: 0/5 nodes are available: 5 No preemption victims found for incoming pod."
I0509 14:11:07.789253      12 preemption.go:264] "No preemption candidate is found; preemption is not helpful for scheduling" pod="default/cspod-62"
I0509 14:11:07.789296      12 schedule_one.go:1044] "Unable to schedule pod; no fit; waiting" pod="default/cspod-62" err="0/5 nodes are available: 5 Insufficient cpu. preemption: 0/5 nodes are available: 5 No preemption victims found for incoming pod."
I0509 14:11:07.809252      12 preemption.go:264] "No preemption candidate is found; preemption is not helpful for scheduling" pod="default/cspod-63"
I0509 14:11:07.809296      12 schedule_one.go:1044] "Unable to schedule pod; no fit; waiting" pod="default/cspod-63" err="0/5 nodes are available: 5 Insufficient cpu. preemption: 0/5 nodes are available: 5 No preemption victims found for incoming pod."
I0509 14:11:07.829423      12 preemption.go:264] "No preemption candidate is found; preemption is not helpful for scheduling" pod="default/cspod-64"
I0509 14:11:07.829462      12 schedule_one.go:1044] "Unable to schedule pod; no fit; waiting" pod="default/cspod-64" err="0/5 nodes are available: 5 Insufficient cpu. preemption: 0/5 nodes are available: 5 No preemption victims found for incoming pod."
I0509 14:11:07.849505      12 preemption.go:264] "No preemption candidate is found; preemption is not helpful for scheduling" pod="default/cspod-65"
I0509 14:11:07.849552      12 schedule_one.go:1044] "Unable to schedule pod; no fit; waiting" pod="default/cspod-65" err="0/5 nodes are available: 5 Insufficient cpu. preemption: 0/5 nodes are available: 5 No preemption victims found for incoming pod."
I0509 14:11:07.869787      12 preemption.go:264] "No preemption candidate is found; preemption is not helpful for scheduling" pod="default/cspod-66"
I0509 14:11:07.869832      12 schedule_one.go:1044] "Unable to schedule pod; no fit; waiting" pod="default/cspod-66" err="0/5 nodes are available: 5 Insufficient cpu. preemption: 0/5 nodes are available: 5 No preemption victims found for incoming pod."
I0509 14:11:07.890236      12 preemption.go:264] "No preemption candidate is found; preemption is not helpful for scheduling" pod="default/cspod-67"
I0509 14:11:07.890327      12 schedule_one.go:1044] "Unable to schedule pod; no fit; waiting" pod="default/cspod-67" err="0/5 nodes are available: 5 Insufficient cpu. preemption: 0/5 nodes are available: 5 No preemption victims found for incoming pod."
I0509 14:11:07.909250      12 preemption.go:264] "No preemption candidate is found; preemption is not helpful for scheduling" pod="default/cspod-68"
I0509 14:11:07.909287      12 schedule_one.go:1044] "Unable to schedule pod; no fit; waiting" pod="default/cspod-68" err="0/5 nodes are available: 5 Insufficient cpu. preemption: 0/5 nodes are available: 5 No preemption victims found for incoming pod."
I0509 14:11:07.929363      12 preemption.go:264] "No preemption candidate is found; preemption is not helpful for scheduling" pod="default/cspod-69"
I0509 14:11:07.929402      12 schedule_one.go:1044] "Unable to schedule pod; no fit; waiting" pod="default/cspod-69" err="0/5 nodes are available: 5 Insufficient cpu. preemption: 0/5 nodes are available: 5 No preemption victims found for incoming pod."
I0509 14:11:07.955487      12 preemption.go:264] "No preemption candidate is found; preemption is not helpful for scheduling" pod="default/cspod-53"
I0509 14:11:07.955529      12 schedule_one.go:1044] "Unable to schedule pod; no fit; waiting" pod="default/cspod-53" err="0/5 nodes are available: 5 Insufficient cpu. preemption: 0/5 nodes are available: 5 No preemption victims found for incoming pod."
I0509 14:11:07.969175      12 schedule_one.go:314] "Successfully bound pod to node" pod="default/cspod-51" node="csnode-2" evaluatedNodes=5 feasibleNodes=2
I0509 14:11:07.988689      12 schedule_one.go:314] "Successfully bound pod to node" pod="default/cspod-52" node="csnode-0" evaluatedNodes=5 feasibleNodes=1
I0509 14:11:08.009021      12 preemption.go:264] "No preemption candidate is found; preemption is not helpful for scheduling" pod="default/cspod-54"
I0509 14:11:08.009093      12 schedule_one.go:1044] "Unable to schedule pod; no fit; waiting" pod="default/cspod-54" err="0/5 nodes are available: 5 Insufficient cpu. preemption: 0/5 nodes are available: 5 No preemption victims found for incoming pod."
I0509 14:11:08.029369      12 preemption.go:264] "No preemption candidate is found; preemption is not helpful for scheduling" pod="default/cspod-60"
I0509 14:11:08.029414      12 schedule_one.go:1044] "Unable to schedule pod; no fit; waiting" pod="default/cspod-60" err="0/5 nodes are available: 5 Insufficient cpu. preemption: 0/5 nodes are available: 5 No preemption victims found for incoming pod."
I0509 14:11:08.049561      12 preemption.go:264] "No preemption candidate is found; preemption is not helpful for scheduling" pod="default/cspod-61"
I0509 14:11:08.049603      12 schedule_one.go:1044] "Unable to schedule pod; no fit; waiting" pod="default/cspod-61" err="0/5 nodes are available: 5 Insufficient cpu. preemption: 0/5 nodes are available: 5 No preemption victims found for incoming pod."
I0509 14:11:08.069602      12 preemption.go:264] "No preemption candidate is found; preemption is not helpful for scheduling" pod="default/cspod-62"
I0509 14:11:08.069658      12 schedule_one.go:1044] "Unable to schedule pod; no fit; waiting" pod="default/cspod-62" err="0/5 nodes are available: 5 Insufficient cpu. preemption: 0/5 nodes are available: 5 No preemption victims found for incoming pod."
I0509 14:11:08.089903      12 preemption.go:264] "No preemption candidate is found; preemption is not helpful for scheduling" pod="default/cspod-63"
I0509 14:11:08.089980      12 schedule_one.go:1044] "Unable to schedule pod; no fit; waiting" pod="default/cspod-63" err="0/5 nodes are available: 5 Insufficient cpu. preemption: 0/5 nodes are available: 5 No preemption victims found for incoming pod."
I0509 14:11:08.109034      12 preemption.go:264] "No preemption candidate is found; preemption is not helpful for scheduling" pod="default/cspod-64"
I0509 14:11:08.109074      12 schedule_one.go:1044] "Unable to schedule pod; no fit; waiting" pod="default/cspod-64" err="0/5 nodes are available: 5 Insufficient cpu. preemption: 0/5 nodes are available: 5 No preemption victims found for incoming pod."
I0509 14:11:08.129289      12 preemption.go:264] "No preemption candidate is found; preemption is not helpful for scheduling" pod="default/cspod-65"
I0509 14:11:08.129332      12 schedule_one.go:1044] "Unable to schedule pod; no fit; waiting" pod="default/cspod-65" err="0/5 nodes are available: 5 Insufficient cpu. preemption: 0/5 nodes are available: 5 No preemption victims found for incoming pod."
I0509 14:11:08.149584      12 preemption.go:264] "No preemption candidate is found; preemption is not helpful for scheduling" pod="default/cspod-66"
I0509 14:11:08.149626      12 schedule_one.go:1044] "Unable to schedule pod; no fit; waiting" pod="default/cspod-66" err="0/5 nodes are available: 5 Insufficient cpu. preemption: 0/5 nodes are available: 5 No preemption victims found for incoming pod."
I0509 14:11:08.169650      12 preemption.go:264] "No preemption candidate is found; preemption is not helpful for scheduling" pod="default/cspod-67"
I0509 14:11:08.169688      12 schedule_one.go:1044] "Unable to schedule pod; no fit; waiting" pod="default/cspod-67" err="0/5 nodes are available: 5 Insufficient cpu. preemption: 0/5 nodes are available: 5 No preemption victims found for incoming pod."
I0509 14:11:08.189914      12 preemption.go:264] "No preemption candidate is found; preemption is not helpful for scheduling" pod="default/cspod-68"
I0509 14:11:08.189956      12 schedule_one.go:1044] "Unable to schedule pod; no fit; waiting" pod="default/cspod-68" err="0/5 nodes are available: 5 Insufficient cpu. preemption: 0/5 nodes are available: 5 No preemption victims found for incoming pod."
I0509 14:11:08.209284      12 preemption.go:264] "No preemption candidate is found; preemption is not helpful for scheduling" pod="default/cspod-69"
I0509 14:11:08.209328      12 schedule_one.go:1044] "Unable to schedule pod; no fit; waiting" pod="default/cspod-69" err="0/5 nodes are available: 5 Insufficient cpu. preemption: 0/5 nodes are available: 5 No preemption victims found for incoming pod."
I0509 14:11:08.234639      12 preemption.go:264] "No preemption candidate is found; preemption is not helpful for scheduling" pod="default/cspod-61"
I0509 14:11:08.234708      12 schedule_one.go:1044] "Unable to schedule pod; no fit; waiting" pod="default/cspod-61" err="0/5 nodes are available: 5 Insufficient cpu. preemption: 0/5 nodes are available: 5 No preemption victims found for incoming pod."
I0509 14:11:08.249145      12 schedule_one.go:314] "Successfully bound pod to node" pod="default/cspod-53" node="csnode-1" evaluatedNodes=5 feasibleNodes=1
I0509 14:11:08.269161      12 schedule_one.go:314] "Successfully bound pod to node" pod="default/cspod-54" node="csnode-2" evaluatedNodes=5 feasibleNodes=2
I0509 14:11:08.289196      12 schedule_one.go:314] "Successfully bound pod to node" pod="default/cspod-60" node="csnode-1" evaluatedNodes=5 feasibleNodes=1
I0509 14:11:08.309237      12 preemption.go:264] "No preemption candidate is found; preemption is not helpful for scheduling" pod="default/cspod-62"
I0509 14:11:08.309279      12 schedule_one.go:1044] "Unable to schedule pod; no fit; waiting" pod="default/cspod-62" err="0/5 nodes are available: 5 Insufficient cpu. preemption: 0/5 nodes are available: 5 No preemption victims found for incoming pod."
I0509 14:11:08.329531      12 preemption.go:264] "No preemption candidate is found; preemption is not helpful for scheduling" pod="default/cspod-63"
I0509 14:11:08.329600      12 schedule_one.go:1044] "Unable to schedule pod; no fit; waiting" pod="default/cspod-63" err="0/5 nodes are available: 5 Insufficient cpu. preemption: 0/5 nodes are available: 5 No preemption victims found for incoming pod."
I0509 14:11:08.350001      12 preemption.go:264] "No preemption candidate is found; preemption is not helpful for scheduling" pod="default/cspod-64"
I0509 14:11:08.350043      12 schedule_one.go:1044] "Unable to schedule pod; no fit; waiting" pod="default/cspod-64" err="0/5 nodes are available: 5 Insufficient cpu. preemption: 0/5 nodes are available: 5 No preemption victims found for incoming pod."
I0509 14:11:08.369521      12 preemption.go:264] "No preemption candidate is found; preemption is not helpful for scheduling" pod="default/cspod-65"
I0509 14:11:08.369572      12 schedule_one.go:1044] "Unable to schedule pod; no fit; waiting" pod="default/cspod-65" err="0/5 nodes are available: 5 Insufficient cpu. preemption: 0/5 nodes are available: 5 No preemption victims found for incoming pod."
I0509 14:11:08.389720      12 preemption.go:264] "No preemption candidate is found; preemption is not helpful for scheduling" pod="default/cspod-66"
I0509 14:11:08.389770      12 schedule_one.go:1044] "Unable to schedule pod; no fit; waiting" pod="default/cspod-66" err="0/5 nodes are available: 5 Insufficient cpu. preemption: 0/5 nodes are available: 5 No preemption victims found for incoming pod."
I0509 14:11:08.409878      12 preemption.go:264] "No preemption candidate is found; preemption is not helpful for scheduling" pod="default/cspod-67"
I0509 14:11:08.409915      12 schedule_one.go:1044] "Unable to schedule pod; no fit; waiting" pod="default/cspod-67" err="0/5 nodes are available: 5 Insufficient cpu. preemption: 0/5 nodes are available: 5 No preemption victims found for incoming pod."
I0509 14:11:08.428834      12 preemption.go:264] "No preemption candidate is found; preemption is not helpful for scheduling" pod="default/cspod-68"
I0509 14:11:08.428872      12 schedule_one.go:1044] "Unable to schedule pod; no fit; waiting" pod="default/cspod-68" err="0/5 nodes are available: 5 Insufficient cpu. preemption: 0/5 nodes are available: 5 No preemption victims found for incoming pod."
I0509 14:11:08.450214      12 preemption.go:264] "No preemption candidate is found; preemption is not helpful for scheduling" pod="default/cspod-69"
I0509 14:11:08.450268      12 schedule_one.go:1044] "Unable to schedule pod; no fit; waiting" pod="default/cspod-69" err="0/5 nodes are available: 5 Insufficient cpu. preemption: 0/5 nodes are available: 5 No preemption victims found for incoming pod."
I0509 14:11:08.474941      12 preemption.go:264] "No preemption candidate is found; preemption is not helpful for scheduling" pod="default/cspod-64"
I0509 14:11:08.474976      12 schedule_one.go:1044] "Unable to schedule pod; no fit; waiting" pod="default/cspod-64" err="0/5 nodes are available: 5 Insufficient cpu. preemption: 0/5 nodes are available: 5 No preemption victims found for incoming pod."
I0509 14:11:08.489695      12 schedule_one.go:314] "Successfully bound pod to node" pod="default/cspod-61" node="csnode-0" evaluatedNodes=5 feasibleNodes=2
I0509 14:11:08.509363      12 schedule_one.go:314] "Successfully bound pod to node" pod="default/cspod-62" node="csnode-4" evaluatedNodes=5 feasibleNodes=1
I0509 14:11:08.529260      12 schedule_one.go:314] "Successfully bound pod to node" pod="default/cspod-63" node="csnode-4" evaluatedNodes=5 feasibleNodes=1
I0509 14:11:08.549344      12 preemption.go:264] "No preemption candidate is found; preemption is not helpful for scheduling" pod="default/cspod-65"
I0509 14:11:08.549398      12 schedule_one.go:1044] "Unable to schedule pod; no fit; waiting" pod="default/cspod-65" err="0/5 nodes are available: 5 Insufficient cpu. preemption: 0/5 nodes are available: 5 No preemption victims found for incoming pod."
I0509 14:11:08.569373      12 preemption.go:264] "No preemption candidate is found; preemption is not helpful for scheduling" pod="default/cspod-66"
I0509 14:11:08.569440      12 schedule_one.go:1044] "Unable to schedule pod; no fit; waiting" pod="default/cspod-66" err="0/5 nodes are available: 5 Insufficient cpu. preemption: 0/5 nodes are available: 5 No preemption victims found for incoming pod."
I0509 14:11:08.589835      12 preemption.go:264] "No preemption candidate is found; preemption is not helpful for scheduling" pod="default/cspod-67"
I0509 14:11:08.589890      12 schedule_one.go:1044] "Unable to schedule pod; no fit; waiting" pod="default/cspod-67" err="0/5 nodes are available: 5 Insufficient cpu. preemption: 0/5 nodes are available: 5 No preemption victims found for incoming pod."
I0509 14:11:08.608961      12 preemption.go:264] "No preemption candidate is found; preemption is not helpful for scheduling" pod="default/cspod-68"
I0509 14:11:08.608999      12 schedule_one.go:1044] "Unable to schedule pod; no fit; waiting" pod="default/cspod-68" err="0/5 nodes are available: 5 Insufficient cpu. preemption: 0/5 nodes are available: 5 No preemption victims found for incoming pod."
I0509 14:11:08.629318      12 preemption.go:264] "No preemption candidate is found; preemption is not helpful for scheduling" pod="default/cspod-69"
I0509 14:11:08.629368      12 schedule_one.go:1044] "Unable to schedule pod; no fit; waiting" pod="default/cspod-69" err="0/5 nodes are available: 5 Insufficient cpu. preemption: 0/5 nodes are available: 5 No preemption victims found for incoming pod."
I0509 14:11:08.656510      12 preemption.go:264] "No preemption candidate is found; preemption is not helpful for scheduling" pod="default/cspod-66"
I0509 14:11:08.656553      12 schedule_one.go:1044] "Unable to schedule pod; no fit; waiting" pod="default/cspod-66" err="0/5 nodes are available: 5 Insufficient cpu. preemption: 0/5 nodes are available: 5 No preemption victims found for incoming pod."
I0509 14:11:08.669199      12 schedule_one.go:314] "Successfully bound pod to node" pod="default/cspod-64" node="csnode-3" evaluatedNodes=5 feasibleNodes=1
I0509 14:11:08.689359      12 schedule_one.go:314] "Successfully bound pod to node" pod="default/cspod-65" node="csnode-3" evaluatedNodes=5 feasibleNodes=1
I0509 14:11:08.709459      12 preemption.go:264] "No preemption candidate is found; preemption is not helpful for scheduling" pod="default/cspod-67"
I0509 14:11:08.709502      12 schedule_one.go:1044] "Unable to schedule pod; no fit; waiting" pod="default/cspod-67" err="0/5 nodes are available: 5 Insufficient cpu. preemption: 0/5 nodes are available: 5 No preemption victims found for incoming pod."
I0509 14:11:08.729431      12 preemption.go:264] "No preemption candidate is found; preemption is not helpful for scheduling" pod="default/cspod-68"
I0509 14:11:08.729468      12 schedule_one.go:1044] "Unable to schedule pod; no fit; waiting" pod="default/cspod-68" err="0/5 nodes are available: 5 Insufficient cpu. preemption: 0/5 nodes are available: 5 No preemption victims found for incoming pod."
I0509 14:11:08.749680      12 preemption.go:264] "No preemption candidate is found; preemption is not helpful for scheduling" pod="default/cspod-69"
I0509 14:11:08.749716      12 schedule_one.go:1044] "Unable to schedule pod; no fit; waiting" pod="default/cspod-69" err="0/5 nodes are available: 5 Insufficient cpu. preemption: 0/5 nodes are available: 5 No preemption victims found for incoming pod."
I0509 14:11:08.774678      12 preemption.go:264] "No preemption candidate is found; preemption is not helpful for scheduling" pod="default/cspod-67"
I0509 14:11:08.774720      12 schedule_one.go:1044] "Unable to schedule pod; no fit; waiting" pod="default/cspod-67" err="0/5 nodes are available: 5 Insufficient cpu. preemption: 0/5 nodes are available: 5 No preemption victims found for incoming pod."
I0509 14:11:08.789652      12 schedule_one.go:314] "Successfully bound pod to node" pod="default/cspod-66" node="csnode-2" evaluatedNodes=5 feasibleNodes=1
I0509 14:11:08.809112      12 preemption.go:264] "No preemption candidate is found; preemption is not helpful for scheduling" pod="default/cspod-68"
I0509 14:11:08.809155      12 schedule_one.go:1044] "Unable to schedule pod; no fit; waiting" pod="default/cspod-68" err="0/5 nodes are available: 5 Insufficient cpu. preemption: 0/5 nodes are available: 5 No preemption victims found for incoming pod."
I0509 14:11:08.829470      12 preemption.go:264] "No preemption candidate is found; preemption is not helpful for scheduling" pod="default/cspod-69"
I0509 14:11:08.829531      12 schedule_one.go:1044] "Unable to schedule pod; no fit; waiting" pod="default/cspod-69" err="0/5 nodes are available: 5 Insufficient cpu. preemption: 0/5 nodes are available: 5 No preemption victims found for incoming pod."
I0509 14:11:08.869969      12 schedule_one.go:314] "Successfully bound pod to node" pod="default/cspod-67" node="csnode-0" evaluatedNodes=5 feasibleNodes=1
I0509 14:11:08.889791      12 schedule_one.go:314] "Successfully bound pod to node" pod="default/cspod-68" node="csnode-1" evaluatedNodes=5 feasibleNodes=2
I0509 14:11:08.909609      12 schedule_one.go:314] "Successfully bound pod to node" pod="default/cspod-69" node="csnode-2" evaluatedNodes=5 feasibleNodes=1
I0509 14:11:08.924487      12 node_tree.go:79] "Removed node from NodeTree" node="csnode-0" zone=""
I0509 14:11:08.924519      12 node_tree.go:79] "Removed node from NodeTree" node="csnode-1" zone=""
I0509 14:11:08.924527      12 node_tree.go:79] "Removed node from NodeTree" node="csnode-2" zone=""
I0509 14:11:08.924530      12 node_tree.go:79] "Removed node from NodeTree" node="csnode-3" zone=""
I0509 14:11:08.924533      12 node_tree.go:79] "Removed node from NodeTree" node="csnode-4" zone=""
E0509 14:11:11.680565      12 event.go:368] "Unable to write event (may retry after sleeping)" err="0-length response with status code: 201 and content type: application/vnd.kubernetes.protobuf" event="&Event{ObjectMeta:{cspod-10.18adeb0b6be395e6  default    0 0001-01-01 00:00:00 +0000 UTC <nil> <nil> map[] map[] [] [] []},InvolvedObject:ObjectReference{Kind:Pod,Namespace:default,Name:cspod-10,UID:cspod-10-uid,APIVersion:v1,ResourceVersion:16,FieldPath:,},Reason:FailedScheduling,Message:0/5 nodes are available: 5 Insufficient cpu. preemption: 0/5 nodes are available: 5 No preemption victims found for incoming pod.,Source:EventSource{Component:most-allocated,Host:,},FirstTimestamp:2026-05-09 14:11:02.168458726 +0000 UTC m=+6.851560157,LastTimestamp:2026-05-09 14:11:02.168458726 +0000 UTC m=+6.851560157,Count:1,Type:Warning,EventTime:0001-01-01 00:00:00 +0000 UTC,Series:nil,Action:,Related:nil,ReportingController:most-allocated,ReportingInstance:,}"
