2026/05/09 14:10:30 Running command:
Command env: (log-file=, also-stdout=false, redirect-stderr=true)
Run from directory: 
Executable path: /usr/local/bin/kube-scheduler
Args (comma-delimited): kube-scheduler,--config=/etc/kube-scheduler/scheduler-config.yaml,--secure-port=10260,--v=2
2026/05/09 14:10:30 Now listening for interrupts
I0509 14:10:30.332002      12 flags.go:64] FLAG: --allow-metric-labels="[]"
I0509 14:10:30.332054      12 flags.go:64] FLAG: --allow-metric-labels-manifest=""
I0509 14:10:30.332060      12 flags.go:64] FLAG: --authentication-kubeconfig=""
I0509 14:10:30.332062      12 flags.go:64] FLAG: --authentication-skip-lookup="false"
I0509 14:10:30.332064      12 flags.go:64] FLAG: --authentication-token-webhook-cache-ttl="10s"
I0509 14:10:30.332067      12 flags.go:64] FLAG: --authentication-tolerate-lookup-failure="true"
I0509 14:10:30.332068      12 flags.go:64] FLAG: --authorization-always-allow-paths="[/healthz,/readyz,/livez]"
I0509 14:10:30.332072      12 flags.go:64] FLAG: --authorization-kubeconfig=""
I0509 14:10:30.332074      12 flags.go:64] FLAG: --authorization-webhook-cache-authorized-ttl="10s"
I0509 14:10:30.332075      12 flags.go:64] FLAG: --authorization-webhook-cache-unauthorized-ttl="10s"
I0509 14:10:30.332076      12 flags.go:64] FLAG: --bind-address="0.0.0.0"
I0509 14:10:30.332078      12 flags.go:64] FLAG: --cert-dir=""
I0509 14:10:30.332079      12 flags.go:64] FLAG: --client-ca-file=""
I0509 14:10:30.332080      12 flags.go:64] FLAG: --config="/etc/kube-scheduler/scheduler-config.yaml"
I0509 14:10:30.332081      12 flags.go:64] FLAG: --contention-profiling="true"
I0509 14:10:30.332082      12 flags.go:64] FLAG: --disable-http2-serving="false"
I0509 14:10:30.332083      12 flags.go:64] FLAG: --disabled-metrics="[]"
I0509 14:10:30.332087      12 flags.go:64] FLAG: --emulated-version="[]"
I0509 14:10:30.332089      12 flags.go:64] FLAG: --feature-gates=""
I0509 14:10:30.332097      12 flags.go:64] FLAG: --help="false"
I0509 14:10:30.332098      12 flags.go:64] FLAG: --http2-max-streams-per-connection="0"
I0509 14:10:30.332099      12 flags.go:64] FLAG: --kube-api-burst="100"
I0509 14:10:30.332101      12 flags.go:64] FLAG: --kube-api-content-type="application/vnd.kubernetes.protobuf"
I0509 14:10:30.332102      12 flags.go:64] FLAG: --kube-api-qps="50"
I0509 14:10:30.332105      12 flags.go:64] FLAG: --kubeconfig=""
I0509 14:10:30.332106      12 flags.go:64] FLAG: --leader-elect="true"
I0509 14:10:30.332107      12 flags.go:64] FLAG: --leader-elect-lease-duration="15s"
I0509 14:10:30.332108      12 flags.go:64] FLAG: --leader-elect-renew-deadline="10s"
I0509 14:10:30.332109      12 flags.go:64] FLAG: --leader-elect-resource-lock="leases"
I0509 14:10:30.332110      12 flags.go:64] FLAG: --leader-elect-resource-name="kube-scheduler"
I0509 14:10:30.332111      12 flags.go:64] FLAG: --leader-elect-resource-namespace="kube-system"
I0509 14:10:30.332111      12 flags.go:64] FLAG: --leader-elect-retry-period="2s"
I0509 14:10:30.332112      12 flags.go:64] FLAG: --log-flush-frequency="5s"
I0509 14:10:30.332113      12 flags.go:64] FLAG: --log-json-info-buffer-size="0"
I0509 14:10:30.332116      12 flags.go:64] FLAG: --log-json-split-stream="false"
I0509 14:10:30.332117      12 flags.go:64] FLAG: --log-text-info-buffer-size="0"
I0509 14:10:30.332118      12 flags.go:64] FLAG: --log-text-split-stream="false"
I0509 14:10:30.332118      12 flags.go:64] FLAG: --logging-format="text"
I0509 14:10:30.332119      12 flags.go:64] FLAG: --master=""
I0509 14:10:30.332120      12 flags.go:64] FLAG: --permit-address-sharing="false"
I0509 14:10:30.332121      12 flags.go:64] FLAG: --permit-port-sharing="false"
I0509 14:10:30.332122      12 flags.go:64] FLAG: --pod-max-in-unschedulable-pods-duration="5m0s"
I0509 14:10:30.332123      12 flags.go:64] FLAG: --profiling="true"
I0509 14:10:30.332124      12 flags.go:64] FLAG: --requestheader-allowed-names="[]"
I0509 14:10:30.332125      12 flags.go:64] FLAG: --requestheader-client-ca-file=""
I0509 14:10:30.332126      12 flags.go:64] FLAG: --requestheader-extra-headers-prefix="[x-remote-extra-]"
I0509 14:10:30.332129      12 flags.go:64] FLAG: --requestheader-group-headers="[x-remote-group]"
I0509 14:10:30.332131      12 flags.go:64] FLAG: --requestheader-uid-headers="[]"
I0509 14:10:30.332133      12 flags.go:64] FLAG: --requestheader-username-headers="[x-remote-user]"
I0509 14:10:30.332135      12 flags.go:64] FLAG: --secure-port="10260"
I0509 14:10:30.332137      12 flags.go:64] FLAG: --show-hidden-metrics-for-version=""
I0509 14:10:30.332138      12 flags.go:64] FLAG: --tls-cert-file=""
I0509 14:10:30.332139      12 flags.go:64] FLAG: --tls-cipher-suites="[]"
I0509 14:10:30.332144      12 flags.go:64] FLAG: --tls-min-version=""
I0509 14:10:30.332144      12 flags.go:64] FLAG: --tls-private-key-file=""
I0509 14:10:30.332145      12 flags.go:64] FLAG: --tls-sni-cert-key="[]"
I0509 14:10:30.332147      12 flags.go:64] FLAG: --v="2"
I0509 14:10:30.332166      12 flags.go:64] FLAG: --version="false"
I0509 14:10:30.332171      12 flags.go:64] FLAG: --vmodule=""
I0509 14:10:30.332174      12 flags.go:64] FLAG: --write-config-to=""
I0509 14:10:30.417415      12 serving.go:386] Generated self-signed cert in-memory
W0509 14:10:30.737930      12 authentication.go:368] No authentication-kubeconfig provided in order to lookup client-ca-file in configmap/extension-apiserver-authentication in kube-system, so client certificate authentication won't work.
W0509 14:10:30.737965      12 authentication.go:392] No authentication-kubeconfig provided in order to lookup requestheader-client-ca-file in configmap/extension-apiserver-authentication in kube-system, so request-header client certificate authentication won't work.
W0509 14:10:30.737977      12 authorization.go:193] No authorization-kubeconfig provided, so SubjectAccessReview of authorization tokens won't work.
I0509 14:10:30.739891      12 framework.go:399] "the scheduler starts to work with those plugins" Plugins={"PreEnqueue":{"Enabled":[{"Name":"SchedulingGates","Weight":0},{"Name":"DefaultPreemption","Weight":0}],"Disabled":null},"QueueSort":{"Enabled":[{"Name":"PrioritySort","Weight":0}],"Disabled":null},"PreFilter":{"Enabled":[{"Name":"NodeAffinity","Weight":0},{"Name":"NodePorts","Weight":0},{"Name":"NodeResourcesFit","Weight":0},{"Name":"VolumeRestrictions","Weight":0},{"Name":"NodeVolumeLimits","Weight":0},{"Name":"VolumeBinding","Weight":0},{"Name":"VolumeZone","Weight":0},{"Name":"PodTopologySpread","Weight":0},{"Name":"InterPodAffinity","Weight":0}],"Disabled":null},"Filter":{"Enabled":[{"Name":"NodeUnschedulable","Weight":0},{"Name":"NodeName","Weight":0},{"Name":"TaintToleration","Weight":0},{"Name":"NodeAffinity","Weight":0},{"Name":"NodePorts","Weight":0},{"Name":"NodeResourcesFit","Weight":0},{"Name":"VolumeRestrictions","Weight":0},{"Name":"NodeVolumeLimits","Weight":0},{"Name":"VolumeBinding","Weight":0},{"Name":"VolumeZone","Weight":0},{"Name":"PodTopologySpread","Weight":0},{"Name":"InterPodAffinity","Weight":0}],"Disabled":null},"PostFilter":{"Enabled":[{"Name":"DefaultPreemption","Weight":0}],"Disabled":null},"PreScore":{"Enabled":[{"Name":"TaintToleration","Weight":0},{"Name":"NodeAffinity","Weight":0},{"Name":"NodeResourcesFit","Weight":0},{"Name":"VolumeBinding","Weight":0},{"Name":"PodTopologySpread","Weight":0},{"Name":"InterPodAffinity","Weight":0},{"Name":"NodeResourcesBalancedAllocation","Weight":0}],"Disabled":null},"Score":{"Enabled":[{"Name":"NodeResourcesFit","Weight":1}],"Disabled":null},"Reserve":{"Enabled":[{"Name":"VolumeBinding","Weight":0}],"Disabled":null},"Permit":{"Enabled":null,"Disabled":null},"PreBind":{"Enabled":[{"Name":"VolumeBinding","Weight":0}],"Disabled":null},"Bind":{"Enabled":[{"Name":"DefaultBinder","Weight":0}],"Disabled":null},"PostBind":{"Enabled":null,"Disabled":null},"MultiPoint":{"Enabled":null,"Disabled":null}}
I0509 14:10:30.740070      12 framework.go:399] "the scheduler starts to work with those plugins" Plugins={"PreEnqueue":{"Enabled":[{"Name":"SchedulingGates","Weight":0},{"Name":"DefaultPreemption","Weight":0}],"Disabled":null},"QueueSort":{"Enabled":[{"Name":"PrioritySort","Weight":0}],"Disabled":null},"PreFilter":{"Enabled":[{"Name":"NodeAffinity","Weight":0},{"Name":"NodePorts","Weight":0},{"Name":"NodeResourcesFit","Weight":0},{"Name":"VolumeRestrictions","Weight":0},{"Name":"NodeVolumeLimits","Weight":0},{"Name":"VolumeBinding","Weight":0},{"Name":"VolumeZone","Weight":0},{"Name":"PodTopologySpread","Weight":0},{"Name":"InterPodAffinity","Weight":0}],"Disabled":null},"Filter":{"Enabled":[{"Name":"NodeUnschedulable","Weight":0},{"Name":"NodeName","Weight":0},{"Name":"TaintToleration","Weight":0},{"Name":"NodeAffinity","Weight":0},{"Name":"NodePorts","Weight":0},{"Name":"NodeResourcesFit","Weight":0},{"Name":"VolumeRestrictions","Weight":0},{"Name":"NodeVolumeLimits","Weight":0},{"Name":"VolumeBinding","Weight":0},{"Name":"VolumeZone","Weight":0},{"Name":"PodTopologySpread","Weight":0},{"Name":"InterPodAffinity","Weight":0}],"Disabled":null},"PostFilter":{"Enabled":[{"Name":"DefaultPreemption","Weight":0}],"Disabled":null},"PreScore":{"Enabled":[{"Name":"TaintToleration","Weight":0},{"Name":"NodeAffinity","Weight":0},{"Name":"NodeResourcesFit","Weight":0},{"Name":"VolumeBinding","Weight":0},{"Name":"PodTopologySpread","Weight":0},{"Name":"InterPodAffinity","Weight":0},{"Name":"NodeResourcesBalancedAllocation","Weight":0}],"Disabled":null},"Score":{"Enabled":[{"Name":"NodeResourcesFit","Weight":1}],"Disabled":null},"Reserve":{"Enabled":[{"Name":"VolumeBinding","Weight":0}],"Disabled":null},"Permit":{"Enabled":null,"Disabled":null},"PreBind":{"Enabled":[{"Name":"VolumeBinding","Weight":0}],"Disabled":null},"Bind":{"Enabled":[{"Name":"DefaultBinder","Weight":0}],"Disabled":null},"PostBind":{"Enabled":null,"Disabled":null},"MultiPoint":{"Enabled":null,"Disabled":null}}
I0509 14:10:30.741259      12 configfile.go:94] "Using component config" config=<
	apiVersion: kubescheduler.config.k8s.io/v1
	clientConnection:
	  acceptContentTypes: ""
	  burst: 100
	  contentType: application/vnd.kubernetes.protobuf
	  kubeconfig: /etc/kube-scheduler/kubeconfig.yaml
	  qps: 50
	enableContentionProfiling: true
	enableProfiling: true
	kind: KubeSchedulerConfiguration
	leaderElection:
	  leaderElect: false
	  leaseDuration: 15s
	  renewDeadline: 10s
	  resourceLock: leases
	  resourceName: kube-scheduler
	  resourceNamespace: kube-system
	  retryPeriod: 2s
	parallelism: 16
	percentageOfNodesToScore: 0
	podInitialBackoffSeconds: 1
	podMaxBackoffSeconds: 10
	profiles:
	- pluginConfig:
	  - args:
	      apiVersion: kubescheduler.config.k8s.io/v1
	      kind: DefaultPreemptionArgs
	      minCandidateNodesAbsolute: 100
	      minCandidateNodesPercentage: 10
	    name: DefaultPreemption
	  - args:
	      apiVersion: kubescheduler.config.k8s.io/v1
	      hardPodAffinityWeight: 1
	      ignorePreferredTermsOfExistingPods: false
	      kind: InterPodAffinityArgs
	    name: InterPodAffinity
	  - args:
	      apiVersion: kubescheduler.config.k8s.io/v1
	      kind: NodeAffinityArgs
	    name: NodeAffinity
	  - args:
	      apiVersion: kubescheduler.config.k8s.io/v1
	      kind: NodeResourcesBalancedAllocationArgs
	      resources:
	      - name: cpu
	        weight: 1
	      - name: memory
	        weight: 1
	    name: NodeResourcesBalancedAllocation
	  - args:
	      apiVersion: kubescheduler.config.k8s.io/v1
	      kind: NodeResourcesFitArgs
	      scoringStrategy:
	        resources:
	        - name: cpu
	          weight: 1
	        - name: memory
	          weight: 1
	        type: LeastAllocated
	    name: NodeResourcesFit
	  - args:
	      apiVersion: kubescheduler.config.k8s.io/v1
	      defaultingType: System
	      kind: PodTopologySpreadArgs
	    name: PodTopologySpread
	  - args:
	      apiVersion: kubescheduler.config.k8s.io/v1
	      bindTimeoutSeconds: 600
	      kind: VolumeBindingArgs
	    name: VolumeBinding
	  plugins:
	    bind: {}
	    filter: {}
	    multiPoint:
	      enabled:
	      - name: SchedulingGates
	        weight: 0
	      - name: PrioritySort
	        weight: 0
	      - name: NodeUnschedulable
	        weight: 0
	      - name: NodeName
	        weight: 0
	      - name: TaintToleration
	        weight: 3
	      - name: NodeAffinity
	        weight: 2
	      - name: NodePorts
	        weight: 0
	      - name: NodeResourcesFit
	        weight: 1
	      - name: VolumeRestrictions
	        weight: 0
	      - name: NodeVolumeLimits
	        weight: 0
	      - name: VolumeBinding
	        weight: 0
	      - name: VolumeZone
	        weight: 0
	      - name: PodTopologySpread
	        weight: 2
	      - name: InterPodAffinity
	        weight: 2
	      - name: DefaultPreemption
	        weight: 0
	      - name: NodeResourcesBalancedAllocation
	        weight: 1
	      - name: ImageLocality
	        weight: 1
	      - name: DefaultBinder
	        weight: 0
	    permit: {}
	    postBind: {}
	    postFilter: {}
	    preBind: {}
	    preEnqueue: {}
	    preFilter: {}
	    preScore: {}
	    queueSort: {}
	    reserve: {}
	    score:
	      disabled:
	      - name: '*'
	        weight: 0
	      enabled:
	      - name: NodeResourcesFit
	        weight: 0
	  schedulerName: least-allocated
	- pluginConfig:
	  - args:
	      apiVersion: kubescheduler.config.k8s.io/v1
	      kind: DefaultPreemptionArgs
	      minCandidateNodesAbsolute: 100
	      minCandidateNodesPercentage: 10
	    name: DefaultPreemption
	  - args:
	      apiVersion: kubescheduler.config.k8s.io/v1
	      hardPodAffinityWeight: 1
	      ignorePreferredTermsOfExistingPods: false
	      kind: InterPodAffinityArgs
	    name: InterPodAffinity
	  - args:
	      apiVersion: kubescheduler.config.k8s.io/v1
	      kind: NodeAffinityArgs
	    name: NodeAffinity
	  - args:
	      apiVersion: kubescheduler.config.k8s.io/v1
	      kind: NodeResourcesBalancedAllocationArgs
	      resources:
	      - name: cpu
	        weight: 1
	      - name: memory
	        weight: 1
	    name: NodeResourcesBalancedAllocation
	  - args:
	      apiVersion: kubescheduler.config.k8s.io/v1
	      kind: NodeResourcesFitArgs
	      scoringStrategy:
	        resources:
	        - name: cpu
	          weight: 1
	        - name: memory
	          weight: 1
	        type: MostAllocated
	    name: NodeResourcesFit
	  - args:
	      apiVersion: kubescheduler.config.k8s.io/v1
	      defaultingType: System
	      kind: PodTopologySpreadArgs
	    name: PodTopologySpread
	  - args:
	      apiVersion: kubescheduler.config.k8s.io/v1
	      bindTimeoutSeconds: 600
	      kind: VolumeBindingArgs
	    name: VolumeBinding
	  plugins:
	    bind: {}
	    filter: {}
	    multiPoint:
	      enabled:
	      - name: SchedulingGates
	        weight: 0
	      - name: PrioritySort
	        weight: 0
	      - name: NodeUnschedulable
	        weight: 0
	      - name: NodeName
	        weight: 0
	      - name: TaintToleration
	        weight: 3
	      - name: NodeAffinity
	        weight: 2
	      - name: NodePorts
	        weight: 0
	      - name: NodeResourcesFit
	        weight: 1
	      - name: VolumeRestrictions
	        weight: 0
	      - name: NodeVolumeLimits
	        weight: 0
	      - name: VolumeBinding
	        weight: 0
	      - name: VolumeZone
	        weight: 0
	      - name: PodTopologySpread
	        weight: 2
	      - name: InterPodAffinity
	        weight: 2
	      - name: DefaultPreemption
	        weight: 0
	      - name: NodeResourcesBalancedAllocation
	        weight: 1
	      - name: ImageLocality
	        weight: 1
	      - name: DefaultBinder
	        weight: 0
	    permit: {}
	    postBind: {}
	    postFilter: {}
	    preBind: {}
	    preEnqueue: {}
	    preFilter: {}
	    preScore: {}
	    queueSort: {}
	    reserve: {}
	    score:
	      disabled:
	      - name: '*'
	        weight: 0
	      enabled:
	      - name: NodeResourcesFit
	        weight: 0
	  schedulerName: most-allocated
 >
I0509 14:10:30.742625      12 server.go:171] "Starting Kubernetes Scheduler" version="v1.33.0"
I0509 14:10:30.742654      12 server.go:173] "Golang settings" GOGC="" GOMAXPROCS="" GOTRACEBACK=""
I0509 14:10:30.743609      12 tlsconfig.go:203] "Loaded serving cert" certName="Generated self signed cert" certDetail="\"localhost@1778335830\" [serving] validServingFor=[127.0.0.1,localhost,localhost] issuer=\"localhost-ca@1778335830\" (2026-05-09 13:10:30 +0000 UTC to 2027-05-09 13:10:30 +0000 UTC (now=2026-05-09 14:10:30.743598888 +0000 UTC))"
I0509 14:10:30.743731      12 named_certificates.go:53] "Loaded SNI cert" index=0 certName="self-signed loopback" certDetail="\"apiserver-loopback-client@1778335830\" [serving] validServingFor=[apiserver-loopback-client] issuer=\"apiserver-loopback-client-ca@1778335830\" (2026-05-09 13:10:30 +0000 UTC to 2029-05-09 13:10:30 +0000 UTC (now=2026-05-09 14:10:30.743726337 +0000 UTC))"
I0509 14:10:30.743797      12 secure_serving.go:211] Serving securely on [::]:10260
I0509 14:10:30.743862      12 tlsconfig.go:243] "Starting DynamicServingCertificateController"
I0509 14:10:30.744980      12 reflector.go:430] "Caches populated" type="*v1.PodDisruptionBudget" reflector="k8s.io/client-go/informers/factory.go:160"
I0509 14:10:30.745017      12 reflector.go:430] "Caches populated" type="*v1.ReplicationController" reflector="k8s.io/client-go/informers/factory.go:160"
I0509 14:10:30.745033      12 reflector.go:430] "Caches populated" type="*v1.CSIStorageCapacity" reflector="k8s.io/client-go/informers/factory.go:160"
I0509 14:10:30.745057      12 reflector.go:430] "Caches populated" type="*v1.PersistentVolume" reflector="k8s.io/client-go/informers/factory.go:160"
I0509 14:10:30.745269      12 reflector.go:430] "Caches populated" type="*v1.VolumeAttachment" reflector="k8s.io/client-go/informers/factory.go:160"
I0509 14:10:30.746170      12 reflector.go:430] "Caches populated" type="*v1.PersistentVolumeClaim" reflector="k8s.io/client-go/informers/factory.go:160"
I0509 14:10:30.746204      12 reflector.go:430] "Caches populated" type="*v1.StatefulSet" reflector="k8s.io/client-go/informers/factory.go:160"
I0509 14:10:30.746407      12 reflector.go:430] "Caches populated" type="*v1.ReplicaSet" reflector="k8s.io/client-go/informers/factory.go:160"
I0509 14:10:30.746452      12 reflector.go:430] "Caches populated" type="*v1.CSINode" reflector="k8s.io/client-go/informers/factory.go:160"
I0509 14:10:30.746465      12 reflector.go:430] "Caches populated" type="*v1.CSIDriver" reflector="k8s.io/client-go/informers/factory.go:160"
I0509 14:10:30.746501      12 reflector.go:430] "Caches populated" type="*v1.StorageClass" reflector="k8s.io/client-go/informers/factory.go:160"
I0509 14:10:30.746548      12 reflector.go:430] "Caches populated" type="*v1.Namespace" reflector="k8s.io/client-go/informers/factory.go:160"
I0509 14:10:30.746764      12 reflector.go:430] "Caches populated" type="*v1.Service" reflector="k8s.io/client-go/informers/factory.go:160"
I0509 14:10:30.747530      12 reflector.go:430] "Caches populated" type="*v1.Node" reflector="k8s.io/client-go/informers/factory.go:160"
I0509 14:10:30.747626      12 reflector.go:430] "Caches populated" type="*v1.Pod" reflector="k8s.io/client-go/informers/factory.go:160"
I0509 14:10:37.140148      12 node_tree.go:65] "Added node to NodeTree" node="csnode-4" zone=""
I0509 14:10:37.140208      12 node_tree.go:65] "Added node to NodeTree" node="csnode-0" zone=""
I0509 14:10:37.140220      12 node_tree.go:65] "Added node to NodeTree" node="csnode-1" zone=""
I0509 14:10:37.140226      12 node_tree.go:65] "Added node to NodeTree" node="csnode-2" zone=""
I0509 14:10:37.140230      12 node_tree.go:65] "Added node to NodeTree" node="csnode-3" zone=""
I0509 14:10:37.163351      12 schedule_one.go:314] "Successfully bound pod to node" pod="default/cspod-0" node="csnode-4" evaluatedNodes=5 feasibleNodes=5
I0509 14:10:37.163375      12 schedule_one.go:314] "Successfully bound pod to node" pod="default/cspod-1" node="csnode-0" evaluatedNodes=5 feasibleNodes=5
I0509 14:10:37.163428      12 schedule_one.go:314] "Successfully bound pod to node" pod="default/cspod-2" node="csnode-1" evaluatedNodes=5 feasibleNodes=5
I0509 14:10:37.163450      12 schedule_one.go:314] "Successfully bound pod to node" pod="default/cspod-3" node="csnode-2" evaluatedNodes=5 feasibleNodes=5
I0509 14:10:37.163550      12 schedule_one.go:314] "Successfully bound pod to node" pod="default/cspod-4" node="csnode-3" evaluatedNodes=5 feasibleNodes=5
I0509 14:10:37.163580      12 schedule_one.go:314] "Successfully bound pod to node" pod="default/cspod-5" node="csnode-1" evaluatedNodes=5 feasibleNodes=5
E0509 14:10:37.163628      12 event.go:368] "Unable to write event (may retry after sleeping)" err="0-length response with status code: 201 and content type: application/vnd.kubernetes.protobuf" event="&Event{ObjectMeta:{cspod-0.18adeb0599779d03  default    0 0001-01-01 00:00:00 +0000 UTC <nil> <nil> map[] map[] [] [] []},InvolvedObject:ObjectReference{Kind:Pod,Namespace:default,Name:cspod-0,UID:cspod-0-uid,APIVersion:v1,ResourceVersion:6,FieldPath:,},Reason:Scheduled,Message:Successfully assigned default/cspod-0 to csnode-4,Source:EventSource{Component:least-allocated,Host:,},FirstTimestamp:2026-05-09 14:10:37.163330819 +0000 UTC m=+6.856372268,LastTimestamp:2026-05-09 14:10:37.163330819 +0000 UTC m=+6.856372268,Count:1,Type:Normal,EventTime:0001-01-01 00:00:00 +0000 UTC,Series:nil,Action:,Related:nil,ReportingController:least-allocated,ReportingInstance:,}"
I0509 14:10:37.163788      12 schedule_one.go:314] "Successfully bound pod to node" pod="default/cspod-6" node="csnode-2" evaluatedNodes=5 feasibleNodes=4
I0509 14:10:37.164015      12 schedule_one.go:314] "Successfully bound pod to node" pod="default/cspod-7" node="csnode-3" evaluatedNodes=5 feasibleNodes=3
I0509 14:10:37.164064      12 preemption.go:264] "No preemption candidate is found; preemption is not helpful for scheduling" pod="default/cspod-10"
I0509 14:10:37.164082      12 schedule_one.go:1044] "Unable to schedule pod; no fit; waiting" pod="default/cspod-10" err="0/5 nodes are available: 5 Insufficient cpu. preemption: 0/5 nodes are available: 5 No preemption victims found for incoming pod."
I0509 14:10:37.164203      12 schedule_one.go:314] "Successfully bound pod to node" pod="default/cspod-8" node="csnode-4" evaluatedNodes=5 feasibleNodes=2
I0509 14:10:37.164353      12 schedule_one.go:314] "Successfully bound pod to node" pod="default/cspod-9" node="csnode-0" evaluatedNodes=5 feasibleNodes=1
I0509 14:10:37.165362      12 preemption.go:264] "No preemption candidate is found; preemption is not helpful for scheduling" pod="default/cspod-11"
I0509 14:10:37.165399      12 schedule_one.go:1044] "Unable to schedule pod; no fit; waiting" pod="default/cspod-11" err="0/5 nodes are available: 5 Insufficient cpu. preemption: 0/5 nodes are available: 5 No preemption victims found for incoming pod."
I0509 14:10:37.165956      12 preemption.go:264] "No preemption candidate is found; preemption is not helpful for scheduling" pod="default/cspod-12"
I0509 14:10:37.165992      12 schedule_one.go:1044] "Unable to schedule pod; no fit; waiting" pod="default/cspod-12" err="0/5 nodes are available: 5 Insufficient cpu. preemption: 0/5 nodes are available: 5 No preemption victims found for incoming pod."
I0509 14:10:37.166534      12 preemption.go:264] "No preemption candidate is found; preemption is not helpful for scheduling" pod="default/cspod-13"
I0509 14:10:37.166567      12 schedule_one.go:1044] "Unable to schedule pod; no fit; waiting" pod="default/cspod-13" err="0/5 nodes are available: 5 Insufficient cpu. preemption: 0/5 nodes are available: 5 No preemption victims found for incoming pod."
I0509 14:10:37.167116      12 preemption.go:264] "No preemption candidate is found; preemption is not helpful for scheduling" pod="default/cspod-14"
I0509 14:10:37.167150      12 schedule_one.go:1044] "Unable to schedule pod; no fit; waiting" pod="default/cspod-14" err="0/5 nodes are available: 5 Insufficient cpu. preemption: 0/5 nodes are available: 5 No preemption victims found for incoming pod."
I0509 14:10:37.167670      12 preemption.go:264] "No preemption candidate is found; preemption is not helpful for scheduling" pod="default/cspod-15"
I0509 14:10:37.167702      12 schedule_one.go:1044] "Unable to schedule pod; no fit; waiting" pod="default/cspod-15" err="0/5 nodes are available: 5 Insufficient cpu. preemption: 0/5 nodes are available: 5 No preemption victims found for incoming pod."
I0509 14:10:37.168179      12 preemption.go:264] "No preemption candidate is found; preemption is not helpful for scheduling" pod="default/cspod-16"
I0509 14:10:37.168211      12 schedule_one.go:1044] "Unable to schedule pod; no fit; waiting" pod="default/cspod-16" err="0/5 nodes are available: 5 Insufficient cpu. preemption: 0/5 nodes are available: 5 No preemption victims found for incoming pod."
I0509 14:10:37.168753      12 preemption.go:264] "No preemption candidate is found; preemption is not helpful for scheduling" pod="default/cspod-17"
I0509 14:10:37.168790      12 schedule_one.go:1044] "Unable to schedule pod; no fit; waiting" pod="default/cspod-17" err="0/5 nodes are available: 5 Insufficient cpu. preemption: 0/5 nodes are available: 5 No preemption victims found for incoming pod."
I0509 14:10:37.169333      12 preemption.go:264] "No preemption candidate is found; preemption is not helpful for scheduling" pod="default/cspod-18"
I0509 14:10:37.169366      12 schedule_one.go:1044] "Unable to schedule pod; no fit; waiting" pod="default/cspod-18" err="0/5 nodes are available: 5 Insufficient cpu. preemption: 0/5 nodes are available: 5 No preemption victims found for incoming pod."
I0509 14:10:37.173613      12 preemption.go:264] "No preemption candidate is found; preemption is not helpful for scheduling" pod="default/cspod-19"
I0509 14:10:37.173654      12 schedule_one.go:1044] "Unable to schedule pod; no fit; waiting" pod="default/cspod-19" err="0/5 nodes are available: 5 Insufficient cpu. preemption: 0/5 nodes are available: 5 No preemption victims found for incoming pod."
I0509 14:10:37.174349      12 preemption.go:264] "No preemption candidate is found; preemption is not helpful for scheduling" pod="default/cspod-20"
I0509 14:10:37.174383      12 schedule_one.go:1044] "Unable to schedule pod; no fit; waiting" pod="default/cspod-20" err="0/5 nodes are available: 5 Insufficient cpu. preemption: 0/5 nodes are available: 5 No preemption victims found for incoming pod."
I0509 14:10:37.174936      12 preemption.go:264] "No preemption candidate is found; preemption is not helpful for scheduling" pod="default/cspod-21"
I0509 14:10:37.174969      12 schedule_one.go:1044] "Unable to schedule pod; no fit; waiting" pod="default/cspod-21" err="0/5 nodes are available: 5 Insufficient cpu. preemption: 0/5 nodes are available: 5 No preemption victims found for incoming pod."
I0509 14:10:37.175494      12 preemption.go:264] "No preemption candidate is found; preemption is not helpful for scheduling" pod="default/cspod-22"
I0509 14:10:37.175533      12 schedule_one.go:1044] "Unable to schedule pod; no fit; waiting" pod="default/cspod-22" err="0/5 nodes are available: 5 Insufficient cpu. preemption: 0/5 nodes are available: 5 No preemption victims found for incoming pod."
I0509 14:10:37.176028      12 preemption.go:264] "No preemption candidate is found; preemption is not helpful for scheduling" pod="default/cspod-23"
I0509 14:10:37.176063      12 schedule_one.go:1044] "Unable to schedule pod; no fit; waiting" pod="default/cspod-23" err="0/5 nodes are available: 5 Insufficient cpu. preemption: 0/5 nodes are available: 5 No preemption victims found for incoming pod."
I0509 14:10:37.176917      12 preemption.go:264] "No preemption candidate is found; preemption is not helpful for scheduling" pod="default/cspod-24"
I0509 14:10:37.176950      12 schedule_one.go:1044] "Unable to schedule pod; no fit; waiting" pod="default/cspod-24" err="0/5 nodes are available: 5 Insufficient cpu. preemption: 0/5 nodes are available: 5 No preemption victims found for incoming pod."
I0509 14:10:37.177532      12 preemption.go:264] "No preemption candidate is found; preemption is not helpful for scheduling" pod="default/cspod-25"
I0509 14:10:37.177566      12 schedule_one.go:1044] "Unable to schedule pod; no fit; waiting" pod="default/cspod-25" err="0/5 nodes are available: 5 Insufficient cpu. preemption: 0/5 nodes are available: 5 No preemption victims found for incoming pod."
I0509 14:10:37.178073      12 preemption.go:264] "No preemption candidate is found; preemption is not helpful for scheduling" pod="default/cspod-26"
I0509 14:10:37.178104      12 schedule_one.go:1044] "Unable to schedule pod; no fit; waiting" pod="default/cspod-26" err="0/5 nodes are available: 5 Insufficient cpu. preemption: 0/5 nodes are available: 5 No preemption victims found for incoming pod."
I0509 14:10:37.178700      12 preemption.go:264] "No preemption candidate is found; preemption is not helpful for scheduling" pod="default/cspod-27"
I0509 14:10:37.178731      12 schedule_one.go:1044] "Unable to schedule pod; no fit; waiting" pod="default/cspod-27" err="0/5 nodes are available: 5 Insufficient cpu. preemption: 0/5 nodes are available: 5 No preemption victims found for incoming pod."
I0509 14:10:37.179270      12 preemption.go:264] "No preemption candidate is found; preemption is not helpful for scheduling" pod="default/cspod-28"
I0509 14:10:37.179311      12 schedule_one.go:1044] "Unable to schedule pod; no fit; waiting" pod="default/cspod-28" err="0/5 nodes are available: 5 Insufficient cpu. preemption: 0/5 nodes are available: 5 No preemption victims found for incoming pod."
I0509 14:10:37.179835      12 preemption.go:264] "No preemption candidate is found; preemption is not helpful for scheduling" pod="default/cspod-29"
I0509 14:10:37.179868      12 schedule_one.go:1044] "Unable to schedule pod; no fit; waiting" pod="default/cspod-29" err="0/5 nodes are available: 5 Insufficient cpu. preemption: 0/5 nodes are available: 5 No preemption victims found for incoming pod."
I0509 14:10:37.180352      12 preemption.go:264] "No preemption candidate is found; preemption is not helpful for scheduling" pod="default/cspod-30"
I0509 14:10:37.180389      12 schedule_one.go:1044] "Unable to schedule pod; no fit; waiting" pod="default/cspod-30" err="0/5 nodes are available: 5 Insufficient cpu. preemption: 0/5 nodes are available: 5 No preemption victims found for incoming pod."
I0509 14:10:37.180871      12 preemption.go:264] "No preemption candidate is found; preemption is not helpful for scheduling" pod="default/cspod-31"
I0509 14:10:37.180902      12 schedule_one.go:1044] "Unable to schedule pod; no fit; waiting" pod="default/cspod-31" err="0/5 nodes are available: 5 Insufficient cpu. preemption: 0/5 nodes are available: 5 No preemption victims found for incoming pod."
I0509 14:10:37.181395      12 preemption.go:264] "No preemption candidate is found; preemption is not helpful for scheduling" pod="default/cspod-32"
I0509 14:10:37.181427      12 schedule_one.go:1044] "Unable to schedule pod; no fit; waiting" pod="default/cspod-32" err="0/5 nodes are available: 5 Insufficient cpu. preemption: 0/5 nodes are available: 5 No preemption victims found for incoming pod."
I0509 14:10:37.181928      12 preemption.go:264] "No preemption candidate is found; preemption is not helpful for scheduling" pod="default/cspod-33"
I0509 14:10:37.181961      12 schedule_one.go:1044] "Unable to schedule pod; no fit; waiting" pod="default/cspod-33" err="0/5 nodes are available: 5 Insufficient cpu. preemption: 0/5 nodes are available: 5 No preemption victims found for incoming pod."
I0509 14:10:37.182534      12 preemption.go:264] "No preemption candidate is found; preemption is not helpful for scheduling" pod="default/cspod-34"
I0509 14:10:37.182567      12 schedule_one.go:1044] "Unable to schedule pod; no fit; waiting" pod="default/cspod-34" err="0/5 nodes are available: 5 Insufficient cpu. preemption: 0/5 nodes are available: 5 No preemption victims found for incoming pod."
I0509 14:10:37.183116      12 preemption.go:264] "No preemption candidate is found; preemption is not helpful for scheduling" pod="default/cspod-35"
I0509 14:10:37.183167      12 schedule_one.go:1044] "Unable to schedule pod; no fit; waiting" pod="default/cspod-35" err="0/5 nodes are available: 5 Insufficient cpu. preemption: 0/5 nodes are available: 5 No preemption victims found for incoming pod."
I0509 14:10:37.183720      12 preemption.go:264] "No preemption candidate is found; preemption is not helpful for scheduling" pod="default/cspod-36"
I0509 14:10:37.183757      12 schedule_one.go:1044] "Unable to schedule pod; no fit; waiting" pod="default/cspod-36" err="0/5 nodes are available: 5 Insufficient cpu. preemption: 0/5 nodes are available: 5 No preemption victims found for incoming pod."
I0509 14:10:37.270075      12 preemption.go:264] "No preemption candidate is found; preemption is not helpful for scheduling" pod="default/cspod-37"
I0509 14:10:37.270124      12 schedule_one.go:1044] "Unable to schedule pod; no fit; waiting" pod="default/cspod-37" err="0/5 nodes are available: 5 Insufficient cpu. preemption: 0/5 nodes are available: 5 No preemption victims found for incoming pod."
I0509 14:10:37.270943      12 preemption.go:264] "No preemption candidate is found; preemption is not helpful for scheduling" pod="default/cspod-38"
I0509 14:10:37.270981      12 schedule_one.go:1044] "Unable to schedule pod; no fit; waiting" pod="default/cspod-38" err="0/5 nodes are available: 5 Insufficient cpu. preemption: 0/5 nodes are available: 5 No preemption victims found for incoming pod."
I0509 14:10:37.271542      12 preemption.go:264] "No preemption candidate is found; preemption is not helpful for scheduling" pod="default/cspod-39"
I0509 14:10:37.271574      12 schedule_one.go:1044] "Unable to schedule pod; no fit; waiting" pod="default/cspod-39" err="0/5 nodes are available: 5 Insufficient cpu. preemption: 0/5 nodes are available: 5 No preemption victims found for incoming pod."
I0509 14:10:37.272064      12 preemption.go:264] "No preemption candidate is found; preemption is not helpful for scheduling" pod="default/cspod-40"
I0509 14:10:37.272097      12 schedule_one.go:1044] "Unable to schedule pod; no fit; waiting" pod="default/cspod-40" err="0/5 nodes are available: 5 Insufficient cpu. preemption: 0/5 nodes are available: 5 No preemption victims found for incoming pod."
I0509 14:10:37.272567      12 preemption.go:264] "No preemption candidate is found; preemption is not helpful for scheduling" pod="default/cspod-41"
I0509 14:10:37.272600      12 schedule_one.go:1044] "Unable to schedule pod; no fit; waiting" pod="default/cspod-41" err="0/5 nodes are available: 5 Insufficient cpu. preemption: 0/5 nodes are available: 5 No preemption victims found for incoming pod."
I0509 14:10:37.273781      12 preemption.go:264] "No preemption candidate is found; preemption is not helpful for scheduling" pod="default/cspod-42"
I0509 14:10:37.273817      12 schedule_one.go:1044] "Unable to schedule pod; no fit; waiting" pod="default/cspod-42" err="0/5 nodes are available: 5 Insufficient cpu. preemption: 0/5 nodes are available: 5 No preemption victims found for incoming pod."
I0509 14:10:37.274342      12 preemption.go:264] "No preemption candidate is found; preemption is not helpful for scheduling" pod="default/cspod-43"
I0509 14:10:37.274383      12 schedule_one.go:1044] "Unable to schedule pod; no fit; waiting" pod="default/cspod-43" err="0/5 nodes are available: 5 Insufficient cpu. preemption: 0/5 nodes are available: 5 No preemption victims found for incoming pod."
I0509 14:10:37.274922      12 preemption.go:264] "No preemption candidate is found; preemption is not helpful for scheduling" pod="default/cspod-44"
I0509 14:10:37.274955      12 schedule_one.go:1044] "Unable to schedule pod; no fit; waiting" pod="default/cspod-44" err="0/5 nodes are available: 5 Insufficient cpu. preemption: 0/5 nodes are available: 5 No preemption victims found for incoming pod."
I0509 14:10:37.275405      12 preemption.go:264] "No preemption candidate is found; preemption is not helpful for scheduling" pod="default/cspod-45"
I0509 14:10:37.275436      12 schedule_one.go:1044] "Unable to schedule pod; no fit; waiting" pod="default/cspod-45" err="0/5 nodes are available: 5 Insufficient cpu. preemption: 0/5 nodes are available: 5 No preemption victims found for incoming pod."
I0509 14:10:37.275928      12 preemption.go:264] "No preemption candidate is found; preemption is not helpful for scheduling" pod="default/cspod-46"
I0509 14:10:37.275959      12 schedule_one.go:1044] "Unable to schedule pod; no fit; waiting" pod="default/cspod-46" err="0/5 nodes are available: 5 Insufficient cpu. preemption: 0/5 nodes are available: 5 No preemption victims found for incoming pod."
I0509 14:10:37.276537      12 preemption.go:264] "No preemption candidate is found; preemption is not helpful for scheduling" pod="default/cspod-47"
I0509 14:10:37.276570      12 schedule_one.go:1044] "Unable to schedule pod; no fit; waiting" pod="default/cspod-47" err="0/5 nodes are available: 5 Insufficient cpu. preemption: 0/5 nodes are available: 5 No preemption victims found for incoming pod."
I0509 14:10:37.277139      12 preemption.go:264] "No preemption candidate is found; preemption is not helpful for scheduling" pod="default/cspod-48"
I0509 14:10:37.277172      12 schedule_one.go:1044] "Unable to schedule pod; no fit; waiting" pod="default/cspod-48" err="0/5 nodes are available: 5 Insufficient cpu. preemption: 0/5 nodes are available: 5 No preemption victims found for incoming pod."
I0509 14:10:37.277640      12 preemption.go:264] "No preemption candidate is found; preemption is not helpful for scheduling" pod="default/cspod-49"
I0509 14:10:37.277672      12 schedule_one.go:1044] "Unable to schedule pod; no fit; waiting" pod="default/cspod-49" err="0/5 nodes are available: 5 Insufficient cpu. preemption: 0/5 nodes are available: 5 No preemption victims found for incoming pod."
I0509 14:10:37.278112      12 preemption.go:264] "No preemption candidate is found; preemption is not helpful for scheduling" pod="default/cspod-50"
I0509 14:10:37.278142      12 schedule_one.go:1044] "Unable to schedule pod; no fit; waiting" pod="default/cspod-50" err="0/5 nodes are available: 5 Insufficient cpu. preemption: 0/5 nodes are available: 5 No preemption victims found for incoming pod."
I0509 14:10:37.278587      12 preemption.go:264] "No preemption candidate is found; preemption is not helpful for scheduling" pod="default/cspod-51"
I0509 14:10:37.278618      12 schedule_one.go:1044] "Unable to schedule pod; no fit; waiting" pod="default/cspod-51" err="0/5 nodes are available: 5 Insufficient cpu. preemption: 0/5 nodes are available: 5 No preemption victims found for incoming pod."
I0509 14:10:37.279103      12 preemption.go:264] "No preemption candidate is found; preemption is not helpful for scheduling" pod="default/cspod-52"
I0509 14:10:37.279148      12 schedule_one.go:1044] "Unable to schedule pod; no fit; waiting" pod="default/cspod-52" err="0/5 nodes are available: 5 Insufficient cpu. preemption: 0/5 nodes are available: 5 No preemption victims found for incoming pod."
I0509 14:10:37.279637      12 preemption.go:264] "No preemption candidate is found; preemption is not helpful for scheduling" pod="default/cspod-53"
I0509 14:10:37.279668      12 schedule_one.go:1044] "Unable to schedule pod; no fit; waiting" pod="default/cspod-53" err="0/5 nodes are available: 5 Insufficient cpu. preemption: 0/5 nodes are available: 5 No preemption victims found for incoming pod."
I0509 14:10:37.280156      12 preemption.go:264] "No preemption candidate is found; preemption is not helpful for scheduling" pod="default/cspod-54"
I0509 14:10:37.280187      12 schedule_one.go:1044] "Unable to schedule pod; no fit; waiting" pod="default/cspod-54" err="0/5 nodes are available: 5 Insufficient cpu. preemption: 0/5 nodes are available: 5 No preemption victims found for incoming pod."
I0509 14:10:37.301260      12 schedule_one.go:314] "Successfully bound pod to node" pod="default/cspod-56" node="csnode-0" evaluatedNodes=5 feasibleNodes=4
I0509 14:10:37.301299      12 schedule_one.go:314] "Successfully bound pod to node" pod="default/cspod-55" node="csnode-3" evaluatedNodes=5 feasibleNodes=5
I0509 14:10:37.301605      12 schedule_one.go:314] "Successfully bound pod to node" pod="default/cspod-57" node="csnode-2" evaluatedNodes=5 feasibleNodes=3
I0509 14:10:37.301644      12 schedule_one.go:314] "Successfully bound pod to node" pod="default/cspod-58" node="csnode-4" evaluatedNodes=5 feasibleNodes=2
I0509 14:10:37.301661      12 preemption.go:264] "No preemption candidate is found; preemption is not helpful for scheduling" pod="default/cspod-60"
I0509 14:10:37.301687      12 schedule_one.go:1044] "Unable to schedule pod; no fit; waiting" pod="default/cspod-60" err="0/5 nodes are available: 5 Insufficient cpu. preemption: 0/5 nodes are available: 5 No preemption victims found for incoming pod."
I0509 14:10:37.301951      12 schedule_one.go:314] "Successfully bound pod to node" pod="default/cspod-59" node="csnode-1" evaluatedNodes=5 feasibleNodes=1
I0509 14:10:37.302427      12 preemption.go:264] "No preemption candidate is found; preemption is not helpful for scheduling" pod="default/cspod-61"
I0509 14:10:37.302462      12 schedule_one.go:1044] "Unable to schedule pod; no fit; waiting" pod="default/cspod-61" err="0/5 nodes are available: 5 Insufficient cpu. preemption: 0/5 nodes are available: 5 No preemption victims found for incoming pod."
I0509 14:10:37.303056      12 preemption.go:264] "No preemption candidate is found; preemption is not helpful for scheduling" pod="default/cspod-62"
I0509 14:10:37.303094      12 schedule_one.go:1044] "Unable to schedule pod; no fit; waiting" pod="default/cspod-62" err="0/5 nodes are available: 5 Insufficient cpu. preemption: 0/5 nodes are available: 5 No preemption victims found for incoming pod."
I0509 14:10:37.303803      12 preemption.go:264] "No preemption candidate is found; preemption is not helpful for scheduling" pod="default/cspod-63"
I0509 14:10:37.303837      12 schedule_one.go:1044] "Unable to schedule pod; no fit; waiting" pod="default/cspod-63" err="0/5 nodes are available: 5 Insufficient cpu. preemption: 0/5 nodes are available: 5 No preemption victims found for incoming pod."
I0509 14:10:37.304404      12 preemption.go:264] "No preemption candidate is found; preemption is not helpful for scheduling" pod="default/cspod-64"
I0509 14:10:37.304438      12 schedule_one.go:1044] "Unable to schedule pod; no fit; waiting" pod="default/cspod-64" err="0/5 nodes are available: 5 Insufficient cpu. preemption: 0/5 nodes are available: 5 No preemption victims found for incoming pod."
I0509 14:10:37.304948      12 preemption.go:264] "No preemption candidate is found; preemption is not helpful for scheduling" pod="default/cspod-65"
I0509 14:10:37.304979      12 schedule_one.go:1044] "Unable to schedule pod; no fit; waiting" pod="default/cspod-65" err="0/5 nodes are available: 5 Insufficient cpu. preemption: 0/5 nodes are available: 5 No preemption victims found for incoming pod."
I0509 14:10:37.305472      12 preemption.go:264] "No preemption candidate is found; preemption is not helpful for scheduling" pod="default/cspod-66"
I0509 14:10:37.305507      12 schedule_one.go:1044] "Unable to schedule pod; no fit; waiting" pod="default/cspod-66" err="0/5 nodes are available: 5 Insufficient cpu. preemption: 0/5 nodes are available: 5 No preemption victims found for incoming pod."
I0509 14:10:37.306042      12 preemption.go:264] "No preemption candidate is found; preemption is not helpful for scheduling" pod="default/cspod-67"
I0509 14:10:37.306074      12 schedule_one.go:1044] "Unable to schedule pod; no fit; waiting" pod="default/cspod-67" err="0/5 nodes are available: 5 Insufficient cpu. preemption: 0/5 nodes are available: 5 No preemption victims found for incoming pod."
I0509 14:10:37.306540      12 preemption.go:264] "No preemption candidate is found; preemption is not helpful for scheduling" pod="default/cspod-68"
I0509 14:10:37.306572      12 schedule_one.go:1044] "Unable to schedule pod; no fit; waiting" pod="default/cspod-68" err="0/5 nodes are available: 5 Insufficient cpu. preemption: 0/5 nodes are available: 5 No preemption victims found for incoming pod."
I0509 14:10:37.307094      12 preemption.go:264] "No preemption candidate is found; preemption is not helpful for scheduling" pod="default/cspod-69"
I0509 14:10:37.307127      12 schedule_one.go:1044] "Unable to schedule pod; no fit; waiting" pod="default/cspod-69" err="0/5 nodes are available: 5 Insufficient cpu. preemption: 0/5 nodes are available: 5 No preemption victims found for incoming pod."
I0509 14:10:37.321901      12 schedule_one.go:314] "Successfully bound pod to node" pod="default/cspod-10" node="csnode-0" evaluatedNodes=5 feasibleNodes=2
I0509 14:10:37.322037      12 schedule_one.go:314] "Successfully bound pod to node" pod="default/cspod-11" node="csnode-1" evaluatedNodes=5 feasibleNodes=3
I0509 14:10:37.322351      12 schedule_one.go:314] "Successfully bound pod to node" pod="default/cspod-13" node="csnode-3" evaluatedNodes=5 feasibleNodes=5
I0509 14:10:37.322371      12 schedule_one.go:314] "Successfully bound pod to node" pod="default/cspod-12" node="csnode-2" evaluatedNodes=5 feasibleNodes=5
I0509 14:10:37.322661      12 schedule_one.go:314] "Successfully bound pod to node" pod="default/cspod-14" node="csnode-4" evaluatedNodes=5 feasibleNodes=5
I0509 14:10:37.322783      12 schedule_one.go:314] "Successfully bound pod to node" pod="default/cspod-15" node="csnode-0" evaluatedNodes=5 feasibleNodes=5
I0509 14:10:37.322786      12 schedule_one.go:314] "Successfully bound pod to node" pod="default/cspod-16" node="csnode-4" evaluatedNodes=5 feasibleNodes=4
I0509 14:10:37.322882      12 preemption.go:264] "No preemption candidate is found; preemption is not helpful for scheduling" pod="default/cspod-20"
I0509 14:10:37.322917      12 schedule_one.go:1044] "Unable to schedule pod; no fit; waiting" pod="default/cspod-20" err="0/5 nodes are available: 5 Insufficient cpu. preemption: 0/5 nodes are available: 5 No preemption victims found for incoming pod."
I0509 14:10:37.323013      12 schedule_one.go:314] "Successfully bound pod to node" pod="default/cspod-17" node="csnode-1" evaluatedNodes=5 feasibleNodes=3
I0509 14:10:37.323154      12 schedule_one.go:314] "Successfully bound pod to node" pod="default/cspod-18" node="csnode-3" evaluatedNodes=5 feasibleNodes=2
I0509 14:10:37.323212      12 schedule_one.go:314] "Successfully bound pod to node" pod="default/cspod-19" node="csnode-2" evaluatedNodes=5 feasibleNodes=1
I0509 14:10:37.323378      12 preemption.go:264] "No preemption candidate is found; preemption is not helpful for scheduling" pod="default/cspod-21"
I0509 14:10:37.323414      12 schedule_one.go:1044] "Unable to schedule pod; no fit; waiting" pod="default/cspod-21" err="0/5 nodes are available: 5 Insufficient cpu. preemption: 0/5 nodes are available: 5 No preemption victims found for incoming pod."
I0509 14:10:37.323936      12 preemption.go:264] "No preemption candidate is found; preemption is not helpful for scheduling" pod="default/cspod-22"
I0509 14:10:37.323971      12 schedule_one.go:1044] "Unable to schedule pod; no fit; waiting" pod="default/cspod-22" err="0/5 nodes are available: 5 Insufficient cpu. preemption: 0/5 nodes are available: 5 No preemption victims found for incoming pod."
I0509 14:10:37.324485      12 preemption.go:264] "No preemption candidate is found; preemption is not helpful for scheduling" pod="default/cspod-23"
I0509 14:10:37.324518      12 schedule_one.go:1044] "Unable to schedule pod; no fit; waiting" pod="default/cspod-23" err="0/5 nodes are available: 5 Insufficient cpu. preemption: 0/5 nodes are available: 5 No preemption victims found for incoming pod."
I0509 14:10:37.325796      12 preemption.go:264] "No preemption candidate is found; preemption is not helpful for scheduling" pod="default/cspod-24"
I0509 14:10:37.325831      12 schedule_one.go:1044] "Unable to schedule pod; no fit; waiting" pod="default/cspod-24" err="0/5 nodes are available: 5 Insufficient cpu. preemption: 0/5 nodes are available: 5 No preemption victims found for incoming pod."
I0509 14:10:37.326306      12 preemption.go:264] "No preemption candidate is found; preemption is not helpful for scheduling" pod="default/cspod-25"
I0509 14:10:37.326342      12 schedule_one.go:1044] "Unable to schedule pod; no fit; waiting" pod="default/cspod-25" err="0/5 nodes are available: 5 Insufficient cpu. preemption: 0/5 nodes are available: 5 No preemption victims found for incoming pod."
I0509 14:10:37.326887      12 preemption.go:264] "No preemption candidate is found; preemption is not helpful for scheduling" pod="default/cspod-26"
I0509 14:10:37.326920      12 schedule_one.go:1044] "Unable to schedule pod; no fit; waiting" pod="default/cspod-26" err="0/5 nodes are available: 5 Insufficient cpu. preemption: 0/5 nodes are available: 5 No preemption victims found for incoming pod."
I0509 14:10:37.327374      12 preemption.go:264] "No preemption candidate is found; preemption is not helpful for scheduling" pod="default/cspod-27"
I0509 14:10:37.327405      12 schedule_one.go:1044] "Unable to schedule pod; no fit; waiting" pod="default/cspod-27" err="0/5 nodes are available: 5 Insufficient cpu. preemption: 0/5 nodes are available: 5 No preemption victims found for incoming pod."
I0509 14:10:37.327829      12 preemption.go:264] "No preemption candidate is found; preemption is not helpful for scheduling" pod="default/cspod-28"
I0509 14:10:37.327859      12 schedule_one.go:1044] "Unable to schedule pod; no fit; waiting" pod="default/cspod-28" err="0/5 nodes are available: 5 Insufficient cpu. preemption: 0/5 nodes are available: 5 No preemption victims found for incoming pod."
I0509 14:10:37.328378      12 preemption.go:264] "No preemption candidate is found; preemption is not helpful for scheduling" pod="default/cspod-29"
I0509 14:10:37.328411      12 schedule_one.go:1044] "Unable to schedule pod; no fit; waiting" pod="default/cspod-29" err="0/5 nodes are available: 5 Insufficient cpu. preemption: 0/5 nodes are available: 5 No preemption victims found for incoming pod."
I0509 14:10:37.328902      12 preemption.go:264] "No preemption candidate is found; preemption is not helpful for scheduling" pod="default/cspod-30"
I0509 14:10:37.328931      12 schedule_one.go:1044] "Unable to schedule pod; no fit; waiting" pod="default/cspod-30" err="0/5 nodes are available: 5 Insufficient cpu. preemption: 0/5 nodes are available: 5 No preemption victims found for incoming pod."
I0509 14:10:37.329403      12 preemption.go:264] "No preemption candidate is found; preemption is not helpful for scheduling" pod="default/cspod-31"
I0509 14:10:37.329434      12 schedule_one.go:1044] "Unable to schedule pod; no fit; waiting" pod="default/cspod-31" err="0/5 nodes are available: 5 Insufficient cpu. preemption: 0/5 nodes are available: 5 No preemption victims found for incoming pod."
I0509 14:10:37.329916      12 preemption.go:264] "No preemption candidate is found; preemption is not helpful for scheduling" pod="default/cspod-32"
I0509 14:10:37.329946      12 schedule_one.go:1044] "Unable to schedule pod; no fit; waiting" pod="default/cspod-32" err="0/5 nodes are available: 5 Insufficient cpu. preemption: 0/5 nodes are available: 5 No preemption victims found for incoming pod."
I0509 14:10:37.330420      12 preemption.go:264] "No preemption candidate is found; preemption is not helpful for scheduling" pod="default/cspod-33"
I0509 14:10:37.330454      12 schedule_one.go:1044] "Unable to schedule pod; no fit; waiting" pod="default/cspod-33" err="0/5 nodes are available: 5 Insufficient cpu. preemption: 0/5 nodes are available: 5 No preemption victims found for incoming pod."
I0509 14:10:37.331029      12 preemption.go:264] "No preemption candidate is found; preemption is not helpful for scheduling" pod="default/cspod-34"
I0509 14:10:37.331068      12 schedule_one.go:1044] "Unable to schedule pod; no fit; waiting" pod="default/cspod-34" err="0/5 nodes are available: 5 Insufficient cpu. preemption: 0/5 nodes are available: 5 No preemption victims found for incoming pod."
I0509 14:10:37.331882      12 preemption.go:264] "No preemption candidate is found; preemption is not helpful for scheduling" pod="default/cspod-35"
I0509 14:10:37.331917      12 schedule_one.go:1044] "Unable to schedule pod; no fit; waiting" pod="default/cspod-35" err="0/5 nodes are available: 5 Insufficient cpu. preemption: 0/5 nodes are available: 5 No preemption victims found for incoming pod."
I0509 14:10:37.332374      12 preemption.go:264] "No preemption candidate is found; preemption is not helpful for scheduling" pod="default/cspod-36"
I0509 14:10:37.332403      12 schedule_one.go:1044] "Unable to schedule pod; no fit; waiting" pod="default/cspod-36" err="0/5 nodes are available: 5 Insufficient cpu. preemption: 0/5 nodes are available: 5 No preemption victims found for incoming pod."
I0509 14:10:37.332860      12 preemption.go:264] "No preemption candidate is found; preemption is not helpful for scheduling" pod="default/cspod-37"
I0509 14:10:37.332892      12 schedule_one.go:1044] "Unable to schedule pod; no fit; waiting" pod="default/cspod-37" err="0/5 nodes are available: 5 Insufficient cpu. preemption: 0/5 nodes are available: 5 No preemption victims found for incoming pod."
I0509 14:10:37.333594      12 preemption.go:264] "No preemption candidate is found; preemption is not helpful for scheduling" pod="default/cspod-38"
I0509 14:10:37.333634      12 schedule_one.go:1044] "Unable to schedule pod; no fit; waiting" pod="default/cspod-38" err="0/5 nodes are available: 5 Insufficient cpu. preemption: 0/5 nodes are available: 5 No preemption victims found for incoming pod."
I0509 14:10:37.334170      12 preemption.go:264] "No preemption candidate is found; preemption is not helpful for scheduling" pod="default/cspod-39"
I0509 14:10:37.334203      12 schedule_one.go:1044] "Unable to schedule pod; no fit; waiting" pod="default/cspod-39" err="0/5 nodes are available: 5 Insufficient cpu. preemption: 0/5 nodes are available: 5 No preemption victims found for incoming pod."
I0509 14:10:37.334765      12 preemption.go:264] "No preemption candidate is found; preemption is not helpful for scheduling" pod="default/cspod-40"
I0509 14:10:37.334796      12 schedule_one.go:1044] "Unable to schedule pod; no fit; waiting" pod="default/cspod-40" err="0/5 nodes are available: 5 Insufficient cpu. preemption: 0/5 nodes are available: 5 No preemption victims found for incoming pod."
I0509 14:10:37.335315      12 preemption.go:264] "No preemption candidate is found; preemption is not helpful for scheduling" pod="default/cspod-41"
I0509 14:10:37.335347      12 schedule_one.go:1044] "Unable to schedule pod; no fit; waiting" pod="default/cspod-41" err="0/5 nodes are available: 5 Insufficient cpu. preemption: 0/5 nodes are available: 5 No preemption victims found for incoming pod."
I0509 14:10:37.335818      12 preemption.go:264] "No preemption candidate is found; preemption is not helpful for scheduling" pod="default/cspod-42"
I0509 14:10:37.335850      12 schedule_one.go:1044] "Unable to schedule pod; no fit; waiting" pod="default/cspod-42" err="0/5 nodes are available: 5 Insufficient cpu. preemption: 0/5 nodes are available: 5 No preemption victims found for incoming pod."
I0509 14:10:37.336350      12 preemption.go:264] "No preemption candidate is found; preemption is not helpful for scheduling" pod="default/cspod-43"
I0509 14:10:37.336379      12 schedule_one.go:1044] "Unable to schedule pod; no fit; waiting" pod="default/cspod-43" err="0/5 nodes are available: 5 Insufficient cpu. preemption: 0/5 nodes are available: 5 No preemption victims found for incoming pod."
I0509 14:10:37.336901      12 preemption.go:264] "No preemption candidate is found; preemption is not helpful for scheduling" pod="default/cspod-44"
I0509 14:10:37.336932      12 schedule_one.go:1044] "Unable to schedule pod; no fit; waiting" pod="default/cspod-44" err="0/5 nodes are available: 5 Insufficient cpu. preemption: 0/5 nodes are available: 5 No preemption victims found for incoming pod."
I0509 14:10:37.337397      12 preemption.go:264] "No preemption candidate is found; preemption is not helpful for scheduling" pod="default/cspod-45"
I0509 14:10:37.337428      12 schedule_one.go:1044] "Unable to schedule pod; no fit; waiting" pod="default/cspod-45" err="0/5 nodes are available: 5 Insufficient cpu. preemption: 0/5 nodes are available: 5 No preemption victims found for incoming pod."
I0509 14:10:37.337953      12 preemption.go:264] "No preemption candidate is found; preemption is not helpful for scheduling" pod="default/cspod-46"
I0509 14:10:37.337983      12 schedule_one.go:1044] "Unable to schedule pod; no fit; waiting" pod="default/cspod-46" err="0/5 nodes are available: 5 Insufficient cpu. preemption: 0/5 nodes are available: 5 No preemption victims found for incoming pod."
I0509 14:10:37.338500      12 preemption.go:264] "No preemption candidate is found; preemption is not helpful for scheduling" pod="default/cspod-47"
I0509 14:10:37.338530      12 schedule_one.go:1044] "Unable to schedule pod; no fit; waiting" pod="default/cspod-47" err="0/5 nodes are available: 5 Insufficient cpu. preemption: 0/5 nodes are available: 5 No preemption victims found for incoming pod."
I0509 14:10:37.339014      12 preemption.go:264] "No preemption candidate is found; preemption is not helpful for scheduling" pod="default/cspod-48"
I0509 14:10:37.339047      12 schedule_one.go:1044] "Unable to schedule pod; no fit; waiting" pod="default/cspod-48" err="0/5 nodes are available: 5 Insufficient cpu. preemption: 0/5 nodes are available: 5 No preemption victims found for incoming pod."
I0509 14:10:37.343871      12 preemption.go:264] "No preemption candidate is found; preemption is not helpful for scheduling" pod="default/cspod-49"
I0509 14:10:37.343938      12 schedule_one.go:1044] "Unable to schedule pod; no fit; waiting" pod="default/cspod-49" err="0/5 nodes are available: 5 Insufficient cpu. preemption: 0/5 nodes are available: 5 No preemption victims found for incoming pod."
I0509 14:10:37.364182      12 preemption.go:264] "No preemption candidate is found; preemption is not helpful for scheduling" pod="default/cspod-50"
I0509 14:10:37.364226      12 schedule_one.go:1044] "Unable to schedule pod; no fit; waiting" pod="default/cspod-50" err="0/5 nodes are available: 5 Insufficient cpu. preemption: 0/5 nodes are available: 5 No preemption victims found for incoming pod."
I0509 14:10:37.384312      12 preemption.go:264] "No preemption candidate is found; preemption is not helpful for scheduling" pod="default/cspod-51"
I0509 14:10:37.384354      12 schedule_one.go:1044] "Unable to schedule pod; no fit; waiting" pod="default/cspod-51" err="0/5 nodes are available: 5 Insufficient cpu. preemption: 0/5 nodes are available: 5 No preemption victims found for incoming pod."
I0509 14:10:37.403261      12 preemption.go:264] "No preemption candidate is found; preemption is not helpful for scheduling" pod="default/cspod-52"
I0509 14:10:37.403301      12 schedule_one.go:1044] "Unable to schedule pod; no fit; waiting" pod="default/cspod-52" err="0/5 nodes are available: 5 Insufficient cpu. preemption: 0/5 nodes are available: 5 No preemption victims found for incoming pod."
I0509 14:10:37.423362      12 preemption.go:264] "No preemption candidate is found; preemption is not helpful for scheduling" pod="default/cspod-53"
I0509 14:10:37.423403      12 schedule_one.go:1044] "Unable to schedule pod; no fit; waiting" pod="default/cspod-53" err="0/5 nodes are available: 5 Insufficient cpu. preemption: 0/5 nodes are available: 5 No preemption victims found for incoming pod."
I0509 14:10:37.443411      12 preemption.go:264] "No preemption candidate is found; preemption is not helpful for scheduling" pod="default/cspod-54"
I0509 14:10:37.443455      12 schedule_one.go:1044] "Unable to schedule pod; no fit; waiting" pod="default/cspod-54" err="0/5 nodes are available: 5 Insufficient cpu. preemption: 0/5 nodes are available: 5 No preemption victims found for incoming pod."
I0509 14:10:37.463320      12 preemption.go:264] "No preemption candidate is found; preemption is not helpful for scheduling" pod="default/cspod-60"
I0509 14:10:37.463382      12 schedule_one.go:1044] "Unable to schedule pod; no fit; waiting" pod="default/cspod-60" err="0/5 nodes are available: 5 Insufficient cpu. preemption: 0/5 nodes are available: 5 No preemption victims found for incoming pod."
I0509 14:10:37.483440      12 preemption.go:264] "No preemption candidate is found; preemption is not helpful for scheduling" pod="default/cspod-61"
I0509 14:10:37.483515      12 schedule_one.go:1044] "Unable to schedule pod; no fit; waiting" pod="default/cspod-61" err="0/5 nodes are available: 5 Insufficient cpu. preemption: 0/5 nodes are available: 5 No preemption victims found for incoming pod."
I0509 14:10:37.503734      12 preemption.go:264] "No preemption candidate is found; preemption is not helpful for scheduling" pod="default/cspod-62"
I0509 14:10:37.503785      12 schedule_one.go:1044] "Unable to schedule pod; no fit; waiting" pod="default/cspod-62" err="0/5 nodes are available: 5 Insufficient cpu. preemption: 0/5 nodes are available: 5 No preemption victims found for incoming pod."
I0509 14:10:37.523952      12 preemption.go:264] "No preemption candidate is found; preemption is not helpful for scheduling" pod="default/cspod-63"
I0509 14:10:37.524002      12 schedule_one.go:1044] "Unable to schedule pod; no fit; waiting" pod="default/cspod-63" err="0/5 nodes are available: 5 Insufficient cpu. preemption: 0/5 nodes are available: 5 No preemption victims found for incoming pod."
I0509 14:10:37.544060      12 preemption.go:264] "No preemption candidate is found; preemption is not helpful for scheduling" pod="default/cspod-64"
I0509 14:10:37.544098      12 schedule_one.go:1044] "Unable to schedule pod; no fit; waiting" pod="default/cspod-64" err="0/5 nodes are available: 5 Insufficient cpu. preemption: 0/5 nodes are available: 5 No preemption victims found for incoming pod."
I0509 14:10:37.564250      12 preemption.go:264] "No preemption candidate is found; preemption is not helpful for scheduling" pod="default/cspod-65"
I0509 14:10:37.564295      12 schedule_one.go:1044] "Unable to schedule pod; no fit; waiting" pod="default/cspod-65" err="0/5 nodes are available: 5 Insufficient cpu. preemption: 0/5 nodes are available: 5 No preemption victims found for incoming pod."
I0509 14:10:37.584081      12 preemption.go:264] "No preemption candidate is found; preemption is not helpful for scheduling" pod="default/cspod-66"
I0509 14:10:37.584119      12 schedule_one.go:1044] "Unable to schedule pod; no fit; waiting" pod="default/cspod-66" err="0/5 nodes are available: 5 Insufficient cpu. preemption: 0/5 nodes are available: 5 No preemption victims found for incoming pod."
I0509 14:10:37.604183      12 preemption.go:264] "No preemption candidate is found; preemption is not helpful for scheduling" pod="default/cspod-67"
I0509 14:10:37.604225      12 schedule_one.go:1044] "Unable to schedule pod; no fit; waiting" pod="default/cspod-67" err="0/5 nodes are available: 5 Insufficient cpu. preemption: 0/5 nodes are available: 5 No preemption victims found for incoming pod."
I0509 14:10:37.624208      12 preemption.go:264] "No preemption candidate is found; preemption is not helpful for scheduling" pod="default/cspod-68"
I0509 14:10:37.624253      12 schedule_one.go:1044] "Unable to schedule pod; no fit; waiting" pod="default/cspod-68" err="0/5 nodes are available: 5 Insufficient cpu. preemption: 0/5 nodes are available: 5 No preemption victims found for incoming pod."
I0509 14:10:37.644656      12 preemption.go:264] "No preemption candidate is found; preemption is not helpful for scheduling" pod="default/cspod-69"
I0509 14:10:37.644697      12 schedule_one.go:1044] "Unable to schedule pod; no fit; waiting" pod="default/cspod-69" err="0/5 nodes are available: 5 Insufficient cpu. preemption: 0/5 nodes are available: 5 No preemption victims found for incoming pod."
I0509 14:10:37.679045      12 preemption.go:264] "No preemption candidate is found; preemption is not helpful for scheduling" pod="default/cspod-20"
I0509 14:10:37.679161      12 schedule_one.go:1044] "Unable to schedule pod; no fit; waiting" pod="default/cspod-20" err="0/5 nodes are available: 5 Insufficient cpu. preemption: 0/5 nodes are available: 5 No preemption victims found for incoming pod."
I0509 14:10:37.679513      12 preemption.go:264] "No preemption candidate is found; preemption is not helpful for scheduling" pod="default/cspod-21"
I0509 14:10:37.679562      12 schedule_one.go:1044] "Unable to schedule pod; no fit; waiting" pod="default/cspod-21" err="0/5 nodes are available: 5 Insufficient cpu. preemption: 0/5 nodes are available: 5 No preemption victims found for incoming pod."
I0509 14:10:37.684266      12 preemption.go:264] "No preemption candidate is found; preemption is not helpful for scheduling" pod="default/cspod-22"
I0509 14:10:37.684310      12 schedule_one.go:1044] "Unable to schedule pod; no fit; waiting" pod="default/cspod-22" err="0/5 nodes are available: 5 Insufficient cpu. preemption: 0/5 nodes are available: 5 No preemption victims found for incoming pod."
I0509 14:10:37.704347      12 preemption.go:264] "No preemption candidate is found; preemption is not helpful for scheduling" pod="default/cspod-23"
I0509 14:10:37.704410      12 schedule_one.go:1044] "Unable to schedule pod; no fit; waiting" pod="default/cspod-23" err="0/5 nodes are available: 5 Insufficient cpu. preemption: 0/5 nodes are available: 5 No preemption victims found for incoming pod."
I0509 14:10:37.723413      12 preemption.go:264] "No preemption candidate is found; preemption is not helpful for scheduling" pod="default/cspod-24"
I0509 14:10:37.723454      12 schedule_one.go:1044] "Unable to schedule pod; no fit; waiting" pod="default/cspod-24" err="0/5 nodes are available: 5 Insufficient cpu. preemption: 0/5 nodes are available: 5 No preemption victims found for incoming pod."
I0509 14:10:37.743480      12 preemption.go:264] "No preemption candidate is found; preemption is not helpful for scheduling" pod="default/cspod-25"
I0509 14:10:37.743521      12 schedule_one.go:1044] "Unable to schedule pod; no fit; waiting" pod="default/cspod-25" err="0/5 nodes are available: 5 Insufficient cpu. preemption: 0/5 nodes are available: 5 No preemption victims found for incoming pod."
I0509 14:10:37.763692      12 preemption.go:264] "No preemption candidate is found; preemption is not helpful for scheduling" pod="default/cspod-26"
I0509 14:10:37.763733      12 schedule_one.go:1044] "Unable to schedule pod; no fit; waiting" pod="default/cspod-26" err="0/5 nodes are available: 5 Insufficient cpu. preemption: 0/5 nodes are available: 5 No preemption victims found for incoming pod."
I0509 14:10:37.783561      12 preemption.go:264] "No preemption candidate is found; preemption is not helpful for scheduling" pod="default/cspod-27"
I0509 14:10:37.783624      12 schedule_one.go:1044] "Unable to schedule pod; no fit; waiting" pod="default/cspod-27" err="0/5 nodes are available: 5 Insufficient cpu. preemption: 0/5 nodes are available: 5 No preemption victims found for incoming pod."
I0509 14:10:37.803860      12 preemption.go:264] "No preemption candidate is found; preemption is not helpful for scheduling" pod="default/cspod-28"
I0509 14:10:37.803904      12 schedule_one.go:1044] "Unable to schedule pod; no fit; waiting" pod="default/cspod-28" err="0/5 nodes are available: 5 Insufficient cpu. preemption: 0/5 nodes are available: 5 No preemption victims found for incoming pod."
I0509 14:10:37.823979      12 preemption.go:264] "No preemption candidate is found; preemption is not helpful for scheduling" pod="default/cspod-29"
I0509 14:10:37.824012      12 schedule_one.go:1044] "Unable to schedule pod; no fit; waiting" pod="default/cspod-29" err="0/5 nodes are available: 5 Insufficient cpu. preemption: 0/5 nodes are available: 5 No preemption victims found for incoming pod."
I0509 14:10:37.844092      12 preemption.go:264] "No preemption candidate is found; preemption is not helpful for scheduling" pod="default/cspod-30"
I0509 14:10:37.844138      12 schedule_one.go:1044] "Unable to schedule pod; no fit; waiting" pod="default/cspod-30" err="0/5 nodes are available: 5 Insufficient cpu. preemption: 0/5 nodes are available: 5 No preemption victims found for incoming pod."
I0509 14:10:37.864209      12 preemption.go:264] "No preemption candidate is found; preemption is not helpful for scheduling" pod="default/cspod-31"
I0509 14:10:37.864276      12 schedule_one.go:1044] "Unable to schedule pod; no fit; waiting" pod="default/cspod-31" err="0/5 nodes are available: 5 Insufficient cpu. preemption: 0/5 nodes are available: 5 No preemption victims found for incoming pod."
I0509 14:10:37.884543      12 preemption.go:264] "No preemption candidate is found; preemption is not helpful for scheduling" pod="default/cspod-32"
I0509 14:10:37.884593      12 schedule_one.go:1044] "Unable to schedule pod; no fit; waiting" pod="default/cspod-32" err="0/5 nodes are available: 5 Insufficient cpu. preemption: 0/5 nodes are available: 5 No preemption victims found for incoming pod."
I0509 14:10:37.903595      12 preemption.go:264] "No preemption candidate is found; preemption is not helpful for scheduling" pod="default/cspod-33"
I0509 14:10:37.903630      12 schedule_one.go:1044] "Unable to schedule pod; no fit; waiting" pod="default/cspod-33" err="0/5 nodes are available: 5 Insufficient cpu. preemption: 0/5 nodes are available: 5 No preemption victims found for incoming pod."
I0509 14:10:37.923782      12 preemption.go:264] "No preemption candidate is found; preemption is not helpful for scheduling" pod="default/cspod-34"
I0509 14:10:37.923836      12 schedule_one.go:1044] "Unable to schedule pod; no fit; waiting" pod="default/cspod-34" err="0/5 nodes are available: 5 Insufficient cpu. preemption: 0/5 nodes are available: 5 No preemption victims found for incoming pod."
I0509 14:10:37.943992      12 preemption.go:264] "No preemption candidate is found; preemption is not helpful for scheduling" pod="default/cspod-35"
I0509 14:10:37.944063      12 schedule_one.go:1044] "Unable to schedule pod; no fit; waiting" pod="default/cspod-35" err="0/5 nodes are available: 5 Insufficient cpu. preemption: 0/5 nodes are available: 5 No preemption victims found for incoming pod."
I0509 14:10:37.964104      12 preemption.go:264] "No preemption candidate is found; preemption is not helpful for scheduling" pod="default/cspod-36"
I0509 14:10:37.964140      12 schedule_one.go:1044] "Unable to schedule pod; no fit; waiting" pod="default/cspod-36" err="0/5 nodes are available: 5 Insufficient cpu. preemption: 0/5 nodes are available: 5 No preemption victims found for incoming pod."
I0509 14:10:37.984068      12 preemption.go:264] "No preemption candidate is found; preemption is not helpful for scheduling" pod="default/cspod-37"
I0509 14:10:37.984114      12 schedule_one.go:1044] "Unable to schedule pod; no fit; waiting" pod="default/cspod-37" err="0/5 nodes are available: 5 Insufficient cpu. preemption: 0/5 nodes are available: 5 No preemption victims found for incoming pod."
I0509 14:10:38.004043      12 preemption.go:264] "No preemption candidate is found; preemption is not helpful for scheduling" pod="default/cspod-38"
I0509 14:10:38.004088      12 schedule_one.go:1044] "Unable to schedule pod; no fit; waiting" pod="default/cspod-38" err="0/5 nodes are available: 5 Insufficient cpu. preemption: 0/5 nodes are available: 5 No preemption victims found for incoming pod."
I0509 14:10:38.024062      12 preemption.go:264] "No preemption candidate is found; preemption is not helpful for scheduling" pod="default/cspod-39"
I0509 14:10:38.024100      12 schedule_one.go:1044] "Unable to schedule pod; no fit; waiting" pod="default/cspod-39" err="0/5 nodes are available: 5 Insufficient cpu. preemption: 0/5 nodes are available: 5 No preemption victims found for incoming pod."
I0509 14:10:38.044063      12 preemption.go:264] "No preemption candidate is found; preemption is not helpful for scheduling" pod="default/cspod-40"
I0509 14:10:38.044133      12 schedule_one.go:1044] "Unable to schedule pod; no fit; waiting" pod="default/cspod-40" err="0/5 nodes are available: 5 Insufficient cpu. preemption: 0/5 nodes are available: 5 No preemption victims found for incoming pod."
I0509 14:10:38.064146      12 preemption.go:264] "No preemption candidate is found; preemption is not helpful for scheduling" pod="default/cspod-41"
I0509 14:10:38.064201      12 schedule_one.go:1044] "Unable to schedule pod; no fit; waiting" pod="default/cspod-41" err="0/5 nodes are available: 5 Insufficient cpu. preemption: 0/5 nodes are available: 5 No preemption victims found for incoming pod."
I0509 14:10:38.084110      12 preemption.go:264] "No preemption candidate is found; preemption is not helpful for scheduling" pod="default/cspod-42"
I0509 14:10:38.084151      12 schedule_one.go:1044] "Unable to schedule pod; no fit; waiting" pod="default/cspod-42" err="0/5 nodes are available: 5 Insufficient cpu. preemption: 0/5 nodes are available: 5 No preemption victims found for incoming pod."
I0509 14:10:38.104240      12 preemption.go:264] "No preemption candidate is found; preemption is not helpful for scheduling" pod="default/cspod-43"
I0509 14:10:38.104286      12 schedule_one.go:1044] "Unable to schedule pod; no fit; waiting" pod="default/cspod-43" err="0/5 nodes are available: 5 Insufficient cpu. preemption: 0/5 nodes are available: 5 No preemption victims found for incoming pod."
I0509 14:10:38.124387      12 preemption.go:264] "No preemption candidate is found; preemption is not helpful for scheduling" pod="default/cspod-44"
I0509 14:10:38.124429      12 schedule_one.go:1044] "Unable to schedule pod; no fit; waiting" pod="default/cspod-44" err="0/5 nodes are available: 5 Insufficient cpu. preemption: 0/5 nodes are available: 5 No preemption victims found for incoming pod."
I0509 14:10:38.143278      12 preemption.go:264] "No preemption candidate is found; preemption is not helpful for scheduling" pod="default/cspod-45"
I0509 14:10:38.143317      12 schedule_one.go:1044] "Unable to schedule pod; no fit; waiting" pod="default/cspod-45" err="0/5 nodes are available: 5 Insufficient cpu. preemption: 0/5 nodes are available: 5 No preemption victims found for incoming pod."
I0509 14:10:38.164115      12 preemption.go:264] "No preemption candidate is found; preemption is not helpful for scheduling" pod="default/cspod-46"
I0509 14:10:38.164152      12 schedule_one.go:1044] "Unable to schedule pod; no fit; waiting" pod="default/cspod-46" err="0/5 nodes are available: 5 Insufficient cpu. preemption: 0/5 nodes are available: 5 No preemption victims found for incoming pod."
I0509 14:10:38.184387      12 preemption.go:264] "No preemption candidate is found; preemption is not helpful for scheduling" pod="default/cspod-47"
I0509 14:10:38.184431      12 schedule_one.go:1044] "Unable to schedule pod; no fit; waiting" pod="default/cspod-47" err="0/5 nodes are available: 5 Insufficient cpu. preemption: 0/5 nodes are available: 5 No preemption victims found for incoming pod."
I0509 14:10:38.203426      12 preemption.go:264] "No preemption candidate is found; preemption is not helpful for scheduling" pod="default/cspod-48"
I0509 14:10:38.203465      12 schedule_one.go:1044] "Unable to schedule pod; no fit; waiting" pod="default/cspod-48" err="0/5 nodes are available: 5 Insufficient cpu. preemption: 0/5 nodes are available: 5 No preemption victims found for incoming pod."
I0509 14:10:38.223277      12 preemption.go:264] "No preemption candidate is found; preemption is not helpful for scheduling" pod="default/cspod-49"
I0509 14:10:38.223344      12 schedule_one.go:1044] "Unable to schedule pod; no fit; waiting" pod="default/cspod-49" err="0/5 nodes are available: 5 Insufficient cpu. preemption: 0/5 nodes are available: 5 No preemption victims found for incoming pod."
I0509 14:10:38.243464      12 preemption.go:264] "No preemption candidate is found; preemption is not helpful for scheduling" pod="default/cspod-50"
I0509 14:10:38.243508      12 schedule_one.go:1044] "Unable to schedule pod; no fit; waiting" pod="default/cspod-50" err="0/5 nodes are available: 5 Insufficient cpu. preemption: 0/5 nodes are available: 5 No preemption victims found for incoming pod."
I0509 14:10:38.264209      12 preemption.go:264] "No preemption candidate is found; preemption is not helpful for scheduling" pod="default/cspod-51"
I0509 14:10:38.264250      12 schedule_one.go:1044] "Unable to schedule pod; no fit; waiting" pod="default/cspod-51" err="0/5 nodes are available: 5 Insufficient cpu. preemption: 0/5 nodes are available: 5 No preemption victims found for incoming pod."
I0509 14:10:38.284157      12 preemption.go:264] "No preemption candidate is found; preemption is not helpful for scheduling" pod="default/cspod-52"
I0509 14:10:38.284193      12 schedule_one.go:1044] "Unable to schedule pod; no fit; waiting" pod="default/cspod-52" err="0/5 nodes are available: 5 Insufficient cpu. preemption: 0/5 nodes are available: 5 No preemption victims found for incoming pod."
I0509 14:10:38.304189      12 preemption.go:264] "No preemption candidate is found; preemption is not helpful for scheduling" pod="default/cspod-53"
I0509 14:10:38.304232      12 schedule_one.go:1044] "Unable to schedule pod; no fit; waiting" pod="default/cspod-53" err="0/5 nodes are available: 5 Insufficient cpu. preemption: 0/5 nodes are available: 5 No preemption victims found for incoming pod."
I0509 14:10:38.323993      12 preemption.go:264] "No preemption candidate is found; preemption is not helpful for scheduling" pod="default/cspod-54"
I0509 14:10:38.324029      12 schedule_one.go:1044] "Unable to schedule pod; no fit; waiting" pod="default/cspod-54" err="0/5 nodes are available: 5 Insufficient cpu. preemption: 0/5 nodes are available: 5 No preemption victims found for incoming pod."
I0509 14:10:38.344029      12 preemption.go:264] "No preemption candidate is found; preemption is not helpful for scheduling" pod="default/cspod-60"
I0509 14:10:38.344071      12 schedule_one.go:1044] "Unable to schedule pod; no fit; waiting" pod="default/cspod-60" err="0/5 nodes are available: 5 Insufficient cpu. preemption: 0/5 nodes are available: 5 No preemption victims found for incoming pod."
I0509 14:10:38.364699      12 preemption.go:264] "No preemption candidate is found; preemption is not helpful for scheduling" pod="default/cspod-61"
I0509 14:10:38.364739      12 schedule_one.go:1044] "Unable to schedule pod; no fit; waiting" pod="default/cspod-61" err="0/5 nodes are available: 5 Insufficient cpu. preemption: 0/5 nodes are available: 5 No preemption victims found for incoming pod."
I0509 14:10:38.383607      12 preemption.go:264] "No preemption candidate is found; preemption is not helpful for scheduling" pod="default/cspod-62"
I0509 14:10:38.383642      12 schedule_one.go:1044] "Unable to schedule pod; no fit; waiting" pod="default/cspod-62" err="0/5 nodes are available: 5 Insufficient cpu. preemption: 0/5 nodes are available: 5 No preemption victims found for incoming pod."
I0509 14:10:38.403715      12 preemption.go:264] "No preemption candidate is found; preemption is not helpful for scheduling" pod="default/cspod-63"
I0509 14:10:38.403760      12 schedule_one.go:1044] "Unable to schedule pod; no fit; waiting" pod="default/cspod-63" err="0/5 nodes are available: 5 Insufficient cpu. preemption: 0/5 nodes are available: 5 No preemption victims found for incoming pod."
I0509 14:10:38.423959      12 preemption.go:264] "No preemption candidate is found; preemption is not helpful for scheduling" pod="default/cspod-64"
I0509 14:10:38.424013      12 schedule_one.go:1044] "Unable to schedule pod; no fit; waiting" pod="default/cspod-64" err="0/5 nodes are available: 5 Insufficient cpu. preemption: 0/5 nodes are available: 5 No preemption victims found for incoming pod."
I0509 14:10:38.444255      12 preemption.go:264] "No preemption candidate is found; preemption is not helpful for scheduling" pod="default/cspod-65"
I0509 14:10:38.444297      12 schedule_one.go:1044] "Unable to schedule pod; no fit; waiting" pod="default/cspod-65" err="0/5 nodes are available: 5 Insufficient cpu. preemption: 0/5 nodes are available: 5 No preemption victims found for incoming pod."
I0509 14:10:38.464115      12 preemption.go:264] "No preemption candidate is found; preemption is not helpful for scheduling" pod="default/cspod-66"
I0509 14:10:38.464157      12 schedule_one.go:1044] "Unable to schedule pod; no fit; waiting" pod="default/cspod-66" err="0/5 nodes are available: 5 Insufficient cpu. preemption: 0/5 nodes are available: 5 No preemption victims found for incoming pod."
I0509 14:10:38.484061      12 preemption.go:264] "No preemption candidate is found; preemption is not helpful for scheduling" pod="default/cspod-67"
I0509 14:10:38.484097      12 schedule_one.go:1044] "Unable to schedule pod; no fit; waiting" pod="default/cspod-67" err="0/5 nodes are available: 5 Insufficient cpu. preemption: 0/5 nodes are available: 5 No preemption victims found for incoming pod."
I0509 14:10:38.504282      12 preemption.go:264] "No preemption candidate is found; preemption is not helpful for scheduling" pod="default/cspod-68"
I0509 14:10:38.504327      12 schedule_one.go:1044] "Unable to schedule pod; no fit; waiting" pod="default/cspod-68" err="0/5 nodes are available: 5 Insufficient cpu. preemption: 0/5 nodes are available: 5 No preemption victims found for incoming pod."
I0509 14:10:38.523239      12 preemption.go:264] "No preemption candidate is found; preemption is not helpful for scheduling" pod="default/cspod-69"
I0509 14:10:38.523307      12 schedule_one.go:1044] "Unable to schedule pod; no fit; waiting" pod="default/cspod-69" err="0/5 nodes are available: 5 Insufficient cpu. preemption: 0/5 nodes are available: 5 No preemption victims found for incoming pod."
I0509 14:10:41.708305      12 schedule_one.go:314] "Successfully bound pod to node" pod="default/cspod-20" node="csnode-1" evaluatedNodes=5 feasibleNodes=4
I0509 14:10:41.708411      12 schedule_one.go:314] "Successfully bound pod to node" pod="default/cspod-21" node="csnode-2" evaluatedNodes=5 feasibleNodes=5
I0509 14:10:41.708611      12 schedule_one.go:314] "Successfully bound pod to node" pod="default/cspod-22" node="csnode-4" evaluatedNodes=5 feasibleNodes=5
I0509 14:10:41.708707      12 schedule_one.go:314] "Successfully bound pod to node" pod="default/cspod-23" node="csnode-3" evaluatedNodes=5 feasibleNodes=5
I0509 14:10:41.708904      12 schedule_one.go:314] "Successfully bound pod to node" pod="default/cspod-24" node="csnode-0" evaluatedNodes=5 feasibleNodes=5
I0509 14:10:41.709624      12 schedule_one.go:314] "Successfully bound pod to node" pod="default/cspod-25" node="csnode-3" evaluatedNodes=5 feasibleNodes=5
I0509 14:10:41.709742      12 schedule_one.go:314] "Successfully bound pod to node" pod="default/cspod-26" node="csnode-1" evaluatedNodes=5 feasibleNodes=4
I0509 14:10:41.710165      12 schedule_one.go:314] "Successfully bound pod to node" pod="default/cspod-27" node="csnode-4" evaluatedNodes=5 feasibleNodes=3
I0509 14:10:41.710333      12 preemption.go:264] "No preemption candidate is found; preemption is not helpful for scheduling" pod="default/cspod-30"
I0509 14:10:41.710435      12 schedule_one.go:1044] "Unable to schedule pod; no fit; waiting" pod="default/cspod-30" err="0/5 nodes are available: 5 Insufficient cpu. preemption: 0/5 nodes are available: 5 No preemption victims found for incoming pod."
I0509 14:10:41.710868      12 schedule_one.go:314] "Successfully bound pod to node" pod="default/cspod-28" node="csnode-2" evaluatedNodes=5 feasibleNodes=2
I0509 14:10:41.710945      12 schedule_one.go:314] "Successfully bound pod to node" pod="default/cspod-29" node="csnode-0" evaluatedNodes=5 feasibleNodes=1
I0509 14:10:41.711571      12 preemption.go:264] "No preemption candidate is found; preemption is not helpful for scheduling" pod="default/cspod-31"
I0509 14:10:41.711614      12 schedule_one.go:1044] "Unable to schedule pod; no fit; waiting" pod="default/cspod-31" err="0/5 nodes are available: 5 Insufficient cpu. preemption: 0/5 nodes are available: 5 No preemption victims found for incoming pod."
I0509 14:10:41.712220      12 preemption.go:264] "No preemption candidate is found; preemption is not helpful for scheduling" pod="default/cspod-32"
I0509 14:10:41.712257      12 schedule_one.go:1044] "Unable to schedule pod; no fit; waiting" pod="default/cspod-32" err="0/5 nodes are available: 5 Insufficient cpu. preemption: 0/5 nodes are available: 5 No preemption victims found for incoming pod."
I0509 14:10:41.712793      12 preemption.go:264] "No preemption candidate is found; preemption is not helpful for scheduling" pod="default/cspod-33"
I0509 14:10:41.712829      12 schedule_one.go:1044] "Unable to schedule pod; no fit; waiting" pod="default/cspod-33" err="0/5 nodes are available: 5 Insufficient cpu. preemption: 0/5 nodes are available: 5 No preemption victims found for incoming pod."
I0509 14:10:41.713375      12 preemption.go:264] "No preemption candidate is found; preemption is not helpful for scheduling" pod="default/cspod-34"
I0509 14:10:41.713420      12 schedule_one.go:1044] "Unable to schedule pod; no fit; waiting" pod="default/cspod-34" err="0/5 nodes are available: 5 Insufficient cpu. preemption: 0/5 nodes are available: 5 No preemption victims found for incoming pod."
I0509 14:10:41.713943      12 preemption.go:264] "No preemption candidate is found; preemption is not helpful for scheduling" pod="default/cspod-35"
I0509 14:10:41.713984      12 schedule_one.go:1044] "Unable to schedule pod; no fit; waiting" pod="default/cspod-35" err="0/5 nodes are available: 5 Insufficient cpu. preemption: 0/5 nodes are available: 5 No preemption victims found for incoming pod."
I0509 14:10:41.714623      12 preemption.go:264] "No preemption candidate is found; preemption is not helpful for scheduling" pod="default/cspod-36"
I0509 14:10:41.714659      12 schedule_one.go:1044] "Unable to schedule pod; no fit; waiting" pod="default/cspod-36" err="0/5 nodes are available: 5 Insufficient cpu. preemption: 0/5 nodes are available: 5 No preemption victims found for incoming pod."
I0509 14:10:41.715262      12 preemption.go:264] "No preemption candidate is found; preemption is not helpful for scheduling" pod="default/cspod-37"
I0509 14:10:41.715297      12 schedule_one.go:1044] "Unable to schedule pod; no fit; waiting" pod="default/cspod-37" err="0/5 nodes are available: 5 Insufficient cpu. preemption: 0/5 nodes are available: 5 No preemption victims found for incoming pod."
I0509 14:10:41.715936      12 preemption.go:264] "No preemption candidate is found; preemption is not helpful for scheduling" pod="default/cspod-38"
I0509 14:10:41.715972      12 schedule_one.go:1044] "Unable to schedule pod; no fit; waiting" pod="default/cspod-38" err="0/5 nodes are available: 5 Insufficient cpu. preemption: 0/5 nodes are available: 5 No preemption victims found for incoming pod."
I0509 14:10:41.716518      12 preemption.go:264] "No preemption candidate is found; preemption is not helpful for scheduling" pod="default/cspod-39"
I0509 14:10:41.716551      12 schedule_one.go:1044] "Unable to schedule pod; no fit; waiting" pod="default/cspod-39" err="0/5 nodes are available: 5 Insufficient cpu. preemption: 0/5 nodes are available: 5 No preemption victims found for incoming pod."
I0509 14:10:41.717057      12 preemption.go:264] "No preemption candidate is found; preemption is not helpful for scheduling" pod="default/cspod-40"
I0509 14:10:41.717088      12 schedule_one.go:1044] "Unable to schedule pod; no fit; waiting" pod="default/cspod-40" err="0/5 nodes are available: 5 Insufficient cpu. preemption: 0/5 nodes are available: 5 No preemption victims found for incoming pod."
I0509 14:10:41.717540      12 preemption.go:264] "No preemption candidate is found; preemption is not helpful for scheduling" pod="default/cspod-41"
I0509 14:10:41.717571      12 schedule_one.go:1044] "Unable to schedule pod; no fit; waiting" pod="default/cspod-41" err="0/5 nodes are available: 5 Insufficient cpu. preemption: 0/5 nodes are available: 5 No preemption victims found for incoming pod."
I0509 14:10:41.718130      12 preemption.go:264] "No preemption candidate is found; preemption is not helpful for scheduling" pod="default/cspod-42"
I0509 14:10:41.718176      12 schedule_one.go:1044] "Unable to schedule pod; no fit; waiting" pod="default/cspod-42" err="0/5 nodes are available: 5 Insufficient cpu. preemption: 0/5 nodes are available: 5 No preemption victims found for incoming pod."
I0509 14:10:41.718714      12 preemption.go:264] "No preemption candidate is found; preemption is not helpful for scheduling" pod="default/cspod-43"
I0509 14:10:41.718749      12 schedule_one.go:1044] "Unable to schedule pod; no fit; waiting" pod="default/cspod-43" err="0/5 nodes are available: 5 Insufficient cpu. preemption: 0/5 nodes are available: 5 No preemption victims found for incoming pod."
I0509 14:10:41.719307      12 preemption.go:264] "No preemption candidate is found; preemption is not helpful for scheduling" pod="default/cspod-44"
I0509 14:10:41.719340      12 schedule_one.go:1044] "Unable to schedule pod; no fit; waiting" pod="default/cspod-44" err="0/5 nodes are available: 5 Insufficient cpu. preemption: 0/5 nodes are available: 5 No preemption victims found for incoming pod."
I0509 14:10:41.719984      12 preemption.go:264] "No preemption candidate is found; preemption is not helpful for scheduling" pod="default/cspod-45"
I0509 14:10:41.720017      12 schedule_one.go:1044] "Unable to schedule pod; no fit; waiting" pod="default/cspod-45" err="0/5 nodes are available: 5 Insufficient cpu. preemption: 0/5 nodes are available: 5 No preemption victims found for incoming pod."
I0509 14:10:41.720492      12 preemption.go:264] "No preemption candidate is found; preemption is not helpful for scheduling" pod="default/cspod-46"
I0509 14:10:41.720523      12 schedule_one.go:1044] "Unable to schedule pod; no fit; waiting" pod="default/cspod-46" err="0/5 nodes are available: 5 Insufficient cpu. preemption: 0/5 nodes are available: 5 No preemption victims found for incoming pod."
I0509 14:10:41.721012      12 preemption.go:264] "No preemption candidate is found; preemption is not helpful for scheduling" pod="default/cspod-47"
I0509 14:10:41.721079      12 schedule_one.go:1044] "Unable to schedule pod; no fit; waiting" pod="default/cspod-47" err="0/5 nodes are available: 5 Insufficient cpu. preemption: 0/5 nodes are available: 5 No preemption victims found for incoming pod."
I0509 14:10:41.721632      12 preemption.go:264] "No preemption candidate is found; preemption is not helpful for scheduling" pod="default/cspod-48"
I0509 14:10:41.721664      12 schedule_one.go:1044] "Unable to schedule pod; no fit; waiting" pod="default/cspod-48" err="0/5 nodes are available: 5 Insufficient cpu. preemption: 0/5 nodes are available: 5 No preemption victims found for incoming pod."
I0509 14:10:41.722086      12 preemption.go:264] "No preemption candidate is found; preemption is not helpful for scheduling" pod="default/cspod-49"
I0509 14:10:41.722118      12 schedule_one.go:1044] "Unable to schedule pod; no fit; waiting" pod="default/cspod-49" err="0/5 nodes are available: 5 Insufficient cpu. preemption: 0/5 nodes are available: 5 No preemption victims found for incoming pod."
I0509 14:10:41.722616      12 preemption.go:264] "No preemption candidate is found; preemption is not helpful for scheduling" pod="default/cspod-50"
I0509 14:10:41.722648      12 schedule_one.go:1044] "Unable to schedule pod; no fit; waiting" pod="default/cspod-50" err="0/5 nodes are available: 5 Insufficient cpu. preemption: 0/5 nodes are available: 5 No preemption victims found for incoming pod."
I0509 14:10:41.723179      12 preemption.go:264] "No preemption candidate is found; preemption is not helpful for scheduling" pod="default/cspod-51"
I0509 14:10:41.723212      12 schedule_one.go:1044] "Unable to schedule pod; no fit; waiting" pod="default/cspod-51" err="0/5 nodes are available: 5 Insufficient cpu. preemption: 0/5 nodes are available: 5 No preemption victims found for incoming pod."
I0509 14:10:41.723713      12 preemption.go:264] "No preemption candidate is found; preemption is not helpful for scheduling" pod="default/cspod-52"
I0509 14:10:41.723747      12 schedule_one.go:1044] "Unable to schedule pod; no fit; waiting" pod="default/cspod-52" err="0/5 nodes are available: 5 Insufficient cpu. preemption: 0/5 nodes are available: 5 No preemption victims found for incoming pod."
I0509 14:10:41.724225      12 preemption.go:264] "No preemption candidate is found; preemption is not helpful for scheduling" pod="default/cspod-53"
I0509 14:10:41.724258      12 schedule_one.go:1044] "Unable to schedule pod; no fit; waiting" pod="default/cspod-53" err="0/5 nodes are available: 5 Insufficient cpu. preemption: 0/5 nodes are available: 5 No preemption victims found for incoming pod."
I0509 14:10:41.724876      12 preemption.go:264] "No preemption candidate is found; preemption is not helpful for scheduling" pod="default/cspod-54"
I0509 14:10:41.724909      12 schedule_one.go:1044] "Unable to schedule pod; no fit; waiting" pod="default/cspod-54" err="0/5 nodes are available: 5 Insufficient cpu. preemption: 0/5 nodes are available: 5 No preemption victims found for incoming pod."
I0509 14:10:41.725433      12 preemption.go:264] "No preemption candidate is found; preemption is not helpful for scheduling" pod="default/cspod-60"
I0509 14:10:41.725464      12 schedule_one.go:1044] "Unable to schedule pod; no fit; waiting" pod="default/cspod-60" err="0/5 nodes are available: 5 Insufficient cpu. preemption: 0/5 nodes are available: 5 No preemption victims found for incoming pod."
I0509 14:10:41.725994      12 preemption.go:264] "No preemption candidate is found; preemption is not helpful for scheduling" pod="default/cspod-61"
I0509 14:10:41.726031      12 schedule_one.go:1044] "Unable to schedule pod; no fit; waiting" pod="default/cspod-61" err="0/5 nodes are available: 5 Insufficient cpu. preemption: 0/5 nodes are available: 5 No preemption victims found for incoming pod."
I0509 14:10:41.726519      12 preemption.go:264] "No preemption candidate is found; preemption is not helpful for scheduling" pod="default/cspod-62"
I0509 14:10:41.726550      12 schedule_one.go:1044] "Unable to schedule pod; no fit; waiting" pod="default/cspod-62" err="0/5 nodes are available: 5 Insufficient cpu. preemption: 0/5 nodes are available: 5 No preemption victims found for incoming pod."
I0509 14:10:41.727042      12 preemption.go:264] "No preemption candidate is found; preemption is not helpful for scheduling" pod="default/cspod-63"
I0509 14:10:41.727074      12 schedule_one.go:1044] "Unable to schedule pod; no fit; waiting" pod="default/cspod-63" err="0/5 nodes are available: 5 Insufficient cpu. preemption: 0/5 nodes are available: 5 No preemption victims found for incoming pod."
I0509 14:10:41.727523      12 preemption.go:264] "No preemption candidate is found; preemption is not helpful for scheduling" pod="default/cspod-64"
I0509 14:10:41.727555      12 schedule_one.go:1044] "Unable to schedule pod; no fit; waiting" pod="default/cspod-64" err="0/5 nodes are available: 5 Insufficient cpu. preemption: 0/5 nodes are available: 5 No preemption victims found for incoming pod."
I0509 14:10:41.728090      12 preemption.go:264] "No preemption candidate is found; preemption is not helpful for scheduling" pod="default/cspod-65"
I0509 14:10:41.728123      12 schedule_one.go:1044] "Unable to schedule pod; no fit; waiting" pod="default/cspod-65" err="0/5 nodes are available: 5 Insufficient cpu. preemption: 0/5 nodes are available: 5 No preemption victims found for incoming pod."
I0509 14:10:41.728616      12 preemption.go:264] "No preemption candidate is found; preemption is not helpful for scheduling" pod="default/cspod-66"
I0509 14:10:41.728647      12 schedule_one.go:1044] "Unable to schedule pod; no fit; waiting" pod="default/cspod-66" err="0/5 nodes are available: 5 Insufficient cpu. preemption: 0/5 nodes are available: 5 No preemption victims found for incoming pod."
I0509 14:10:41.729157      12 preemption.go:264] "No preemption candidate is found; preemption is not helpful for scheduling" pod="default/cspod-67"
I0509 14:10:41.729188      12 schedule_one.go:1044] "Unable to schedule pod; no fit; waiting" pod="default/cspod-67" err="0/5 nodes are available: 5 Insufficient cpu. preemption: 0/5 nodes are available: 5 No preemption victims found for incoming pod."
I0509 14:10:41.729688      12 preemption.go:264] "No preemption candidate is found; preemption is not helpful for scheduling" pod="default/cspod-68"
I0509 14:10:41.729720      12 schedule_one.go:1044] "Unable to schedule pod; no fit; waiting" pod="default/cspod-68" err="0/5 nodes are available: 5 Insufficient cpu. preemption: 0/5 nodes are available: 5 No preemption victims found for incoming pod."
I0509 14:10:41.730207      12 preemption.go:264] "No preemption candidate is found; preemption is not helpful for scheduling" pod="default/cspod-69"
I0509 14:10:41.730237      12 schedule_one.go:1044] "Unable to schedule pod; no fit; waiting" pod="default/cspod-69" err="0/5 nodes are available: 5 Insufficient cpu. preemption: 0/5 nodes are available: 5 No preemption victims found for incoming pod."
I0509 14:10:41.768122      12 schedule_one.go:314] "Successfully bound pod to node" pod="default/cspod-30" node="csnode-0" evaluatedNodes=5 feasibleNodes=4
I0509 14:10:41.768213      12 schedule_one.go:314] "Successfully bound pod to node" pod="default/cspod-31" node="csnode-1" evaluatedNodes=5 feasibleNodes=5
I0509 14:10:41.768413      12 schedule_one.go:314] "Successfully bound pod to node" pod="default/cspod-33" node="csnode-2" evaluatedNodes=5 feasibleNodes=5
I0509 14:10:41.768413      12 schedule_one.go:314] "Successfully bound pod to node" pod="default/cspod-32" node="csnode-4" evaluatedNodes=5 feasibleNodes=5
I0509 14:10:41.768664      12 schedule_one.go:314] "Successfully bound pod to node" pod="default/cspod-34" node="csnode-3" evaluatedNodes=5 feasibleNodes=5
I0509 14:10:41.768742      12 schedule_one.go:314] "Successfully bound pod to node" pod="default/cspod-35" node="csnode-0" evaluatedNodes=5 feasibleNodes=5
I0509 14:10:41.768881      12 schedule_one.go:314] "Successfully bound pod to node" pod="default/cspod-36" node="csnode-4" evaluatedNodes=5 feasibleNodes=4
I0509 14:10:41.768939      12 schedule_one.go:314] "Successfully bound pod to node" pod="default/cspod-37" node="csnode-2" evaluatedNodes=5 feasibleNodes=3
I0509 14:10:41.768986      12 preemption.go:264] "No preemption candidate is found; preemption is not helpful for scheduling" pod="default/cspod-40"
I0509 14:10:41.769031      12 schedule_one.go:1044] "Unable to schedule pod; no fit; waiting" pod="default/cspod-40" err="0/5 nodes are available: 5 Insufficient cpu. preemption: 0/5 nodes are available: 5 No preemption victims found for incoming pod."
I0509 14:10:41.769131      12 schedule_one.go:314] "Successfully bound pod to node" pod="default/cspod-38" node="csnode-3" evaluatedNodes=5 feasibleNodes=2
I0509 14:10:41.769228      12 schedule_one.go:314] "Successfully bound pod to node" pod="default/cspod-39" node="csnode-1" evaluatedNodes=5 feasibleNodes=1
I0509 14:10:41.769665      12 preemption.go:264] "No preemption candidate is found; preemption is not helpful for scheduling" pod="default/cspod-41"
I0509 14:10:41.769703      12 schedule_one.go:1044] "Unable to schedule pod; no fit; waiting" pod="default/cspod-41" err="0/5 nodes are available: 5 Insufficient cpu. preemption: 0/5 nodes are available: 5 No preemption victims found for incoming pod."
I0509 14:10:41.770238      12 preemption.go:264] "No preemption candidate is found; preemption is not helpful for scheduling" pod="default/cspod-42"
I0509 14:10:41.770271      12 schedule_one.go:1044] "Unable to schedule pod; no fit; waiting" pod="default/cspod-42" err="0/5 nodes are available: 5 Insufficient cpu. preemption: 0/5 nodes are available: 5 No preemption victims found for incoming pod."
I0509 14:10:41.770911      12 preemption.go:264] "No preemption candidate is found; preemption is not helpful for scheduling" pod="default/cspod-43"
I0509 14:10:41.770951      12 schedule_one.go:1044] "Unable to schedule pod; no fit; waiting" pod="default/cspod-43" err="0/5 nodes are available: 5 Insufficient cpu. preemption: 0/5 nodes are available: 5 No preemption victims found for incoming pod."
I0509 14:10:41.771611      12 preemption.go:264] "No preemption candidate is found; preemption is not helpful for scheduling" pod="default/cspod-44"
I0509 14:10:41.771647      12 schedule_one.go:1044] "Unable to schedule pod; no fit; waiting" pod="default/cspod-44" err="0/5 nodes are available: 5 Insufficient cpu. preemption: 0/5 nodes are available: 5 No preemption victims found for incoming pod."
I0509 14:10:41.772207      12 preemption.go:264] "No preemption candidate is found; preemption is not helpful for scheduling" pod="default/cspod-45"
I0509 14:10:41.772243      12 schedule_one.go:1044] "Unable to schedule pod; no fit; waiting" pod="default/cspod-45" err="0/5 nodes are available: 5 Insufficient cpu. preemption: 0/5 nodes are available: 5 No preemption victims found for incoming pod."
I0509 14:10:41.772725      12 preemption.go:264] "No preemption candidate is found; preemption is not helpful for scheduling" pod="default/cspod-46"
I0509 14:10:41.772756      12 schedule_one.go:1044] "Unable to schedule pod; no fit; waiting" pod="default/cspod-46" err="0/5 nodes are available: 5 Insufficient cpu. preemption: 0/5 nodes are available: 5 No preemption victims found for incoming pod."
I0509 14:10:41.773287      12 preemption.go:264] "No preemption candidate is found; preemption is not helpful for scheduling" pod="default/cspod-47"
I0509 14:10:41.773320      12 schedule_one.go:1044] "Unable to schedule pod; no fit; waiting" pod="default/cspod-47" err="0/5 nodes are available: 5 Insufficient cpu. preemption: 0/5 nodes are available: 5 No preemption victims found for incoming pod."
I0509 14:10:41.773851      12 preemption.go:264] "No preemption candidate is found; preemption is not helpful for scheduling" pod="default/cspod-48"
I0509 14:10:41.773884      12 schedule_one.go:1044] "Unable to schedule pod; no fit; waiting" pod="default/cspod-48" err="0/5 nodes are available: 5 Insufficient cpu. preemption: 0/5 nodes are available: 5 No preemption victims found for incoming pod."
I0509 14:10:41.774491      12 preemption.go:264] "No preemption candidate is found; preemption is not helpful for scheduling" pod="default/cspod-49"
I0509 14:10:41.774525      12 schedule_one.go:1044] "Unable to schedule pod; no fit; waiting" pod="default/cspod-49" err="0/5 nodes are available: 5 Insufficient cpu. preemption: 0/5 nodes are available: 5 No preemption victims found for incoming pod."
I0509 14:10:41.775010      12 preemption.go:264] "No preemption candidate is found; preemption is not helpful for scheduling" pod="default/cspod-50"
I0509 14:10:41.775041      12 schedule_one.go:1044] "Unable to schedule pod; no fit; waiting" pod="default/cspod-50" err="0/5 nodes are available: 5 Insufficient cpu. preemption: 0/5 nodes are available: 5 No preemption victims found for incoming pod."
I0509 14:10:41.775509      12 preemption.go:264] "No preemption candidate is found; preemption is not helpful for scheduling" pod="default/cspod-51"
I0509 14:10:41.775550      12 schedule_one.go:1044] "Unable to schedule pod; no fit; waiting" pod="default/cspod-51" err="0/5 nodes are available: 5 Insufficient cpu. preemption: 0/5 nodes are available: 5 No preemption victims found for incoming pod."
I0509 14:10:41.775985      12 preemption.go:264] "No preemption candidate is found; preemption is not helpful for scheduling" pod="default/cspod-52"
I0509 14:10:41.776015      12 schedule_one.go:1044] "Unable to schedule pod; no fit; waiting" pod="default/cspod-52" err="0/5 nodes are available: 5 Insufficient cpu. preemption: 0/5 nodes are available: 5 No preemption victims found for incoming pod."
I0509 14:10:41.776476      12 preemption.go:264] "No preemption candidate is found; preemption is not helpful for scheduling" pod="default/cspod-53"
I0509 14:10:41.776525      12 schedule_one.go:1044] "Unable to schedule pod; no fit; waiting" pod="default/cspod-53" err="0/5 nodes are available: 5 Insufficient cpu. preemption: 0/5 nodes are available: 5 No preemption victims found for incoming pod."
I0509 14:10:41.777043      12 preemption.go:264] "No preemption candidate is found; preemption is not helpful for scheduling" pod="default/cspod-54"
I0509 14:10:41.777075      12 schedule_one.go:1044] "Unable to schedule pod; no fit; waiting" pod="default/cspod-54" err="0/5 nodes are available: 5 Insufficient cpu. preemption: 0/5 nodes are available: 5 No preemption victims found for incoming pod."
I0509 14:10:41.777560      12 preemption.go:264] "No preemption candidate is found; preemption is not helpful for scheduling" pod="default/cspod-60"
I0509 14:10:41.777594      12 schedule_one.go:1044] "Unable to schedule pod; no fit; waiting" pod="default/cspod-60" err="0/5 nodes are available: 5 Insufficient cpu. preemption: 0/5 nodes are available: 5 No preemption victims found for incoming pod."
I0509 14:10:41.778081      12 preemption.go:264] "No preemption candidate is found; preemption is not helpful for scheduling" pod="default/cspod-61"
I0509 14:10:41.778111      12 schedule_one.go:1044] "Unable to schedule pod; no fit; waiting" pod="default/cspod-61" err="0/5 nodes are available: 5 Insufficient cpu. preemption: 0/5 nodes are available: 5 No preemption victims found for incoming pod."
I0509 14:10:41.778597      12 preemption.go:264] "No preemption candidate is found; preemption is not helpful for scheduling" pod="default/cspod-62"
I0509 14:10:41.778626      12 schedule_one.go:1044] "Unable to schedule pod; no fit; waiting" pod="default/cspod-62" err="0/5 nodes are available: 5 Insufficient cpu. preemption: 0/5 nodes are available: 5 No preemption victims found for incoming pod."
I0509 14:10:41.779151      12 preemption.go:264] "No preemption candidate is found; preemption is not helpful for scheduling" pod="default/cspod-63"
I0509 14:10:41.779184      12 schedule_one.go:1044] "Unable to schedule pod; no fit; waiting" pod="default/cspod-63" err="0/5 nodes are available: 5 Insufficient cpu. preemption: 0/5 nodes are available: 5 No preemption victims found for incoming pod."
I0509 14:10:41.779688      12 preemption.go:264] "No preemption candidate is found; preemption is not helpful for scheduling" pod="default/cspod-64"
I0509 14:10:41.779721      12 schedule_one.go:1044] "Unable to schedule pod; no fit; waiting" pod="default/cspod-64" err="0/5 nodes are available: 5 Insufficient cpu. preemption: 0/5 nodes are available: 5 No preemption victims found for incoming pod."
I0509 14:10:41.780157      12 preemption.go:264] "No preemption candidate is found; preemption is not helpful for scheduling" pod="default/cspod-65"
I0509 14:10:41.780188      12 schedule_one.go:1044] "Unable to schedule pod; no fit; waiting" pod="default/cspod-65" err="0/5 nodes are available: 5 Insufficient cpu. preemption: 0/5 nodes are available: 5 No preemption victims found for incoming pod."
I0509 14:10:41.780670      12 preemption.go:264] "No preemption candidate is found; preemption is not helpful for scheduling" pod="default/cspod-66"
I0509 14:10:41.780703      12 schedule_one.go:1044] "Unable to schedule pod; no fit; waiting" pod="default/cspod-66" err="0/5 nodes are available: 5 Insufficient cpu. preemption: 0/5 nodes are available: 5 No preemption victims found for incoming pod."
I0509 14:10:41.781203      12 preemption.go:264] "No preemption candidate is found; preemption is not helpful for scheduling" pod="default/cspod-67"
I0509 14:10:41.781235      12 schedule_one.go:1044] "Unable to schedule pod; no fit; waiting" pod="default/cspod-67" err="0/5 nodes are available: 5 Insufficient cpu. preemption: 0/5 nodes are available: 5 No preemption victims found for incoming pod."
I0509 14:10:41.781721      12 preemption.go:264] "No preemption candidate is found; preemption is not helpful for scheduling" pod="default/cspod-68"
I0509 14:10:41.781759      12 schedule_one.go:1044] "Unable to schedule pod; no fit; waiting" pod="default/cspod-68" err="0/5 nodes are available: 5 Insufficient cpu. preemption: 0/5 nodes are available: 5 No preemption victims found for incoming pod."
I0509 14:10:41.782223      12 preemption.go:264] "No preemption candidate is found; preemption is not helpful for scheduling" pod="default/cspod-69"
I0509 14:10:41.782253      12 schedule_one.go:1044] "Unable to schedule pod; no fit; waiting" pod="default/cspod-69" err="0/5 nodes are available: 5 Insufficient cpu. preemption: 0/5 nodes are available: 5 No preemption victims found for incoming pod."
I0509 14:10:41.802581      12 schedule_one.go:314] "Successfully bound pod to node" pod="default/cspod-40" node="csnode-1" evaluatedNodes=5 feasibleNodes=3
I0509 14:10:41.802623      12 preemption.go:264] "No preemption candidate is found; preemption is not helpful for scheduling" pod="default/cspod-43"
I0509 14:10:41.802630      12 schedule_one.go:1044] "Unable to schedule pod; no fit; waiting" pod="default/cspod-43" err="0/5 nodes are available: 5 Insufficient cpu. preemption: 0/5 nodes are available: 5 No preemption victims found for incoming pod."
I0509 14:10:41.802696      12 schedule_one.go:314] "Successfully bound pod to node" pod="default/cspod-41" node="csnode-2" evaluatedNodes=5 feasibleNodes=2
I0509 14:10:41.803319      12 schedule_one.go:314] "Successfully bound pod to node" pod="default/cspod-42" node="csnode-3" evaluatedNodes=5 feasibleNodes=1
I0509 14:10:41.804029      12 preemption.go:264] "No preemption candidate is found; preemption is not helpful for scheduling" pod="default/cspod-44"
I0509 14:10:41.804068      12 schedule_one.go:1044] "Unable to schedule pod; no fit; waiting" pod="default/cspod-44" err="0/5 nodes are available: 5 Insufficient cpu. preemption: 0/5 nodes are available: 5 No preemption victims found for incoming pod."
I0509 14:10:41.804718      12 preemption.go:264] "No preemption candidate is found; preemption is not helpful for scheduling" pod="default/cspod-45"
I0509 14:10:41.804750      12 schedule_one.go:1044] "Unable to schedule pod; no fit; waiting" pod="default/cspod-45" err="0/5 nodes are available: 5 Insufficient cpu. preemption: 0/5 nodes are available: 5 No preemption victims found for incoming pod."
I0509 14:10:41.805243      12 preemption.go:264] "No preemption candidate is found; preemption is not helpful for scheduling" pod="default/cspod-46"
I0509 14:10:41.805277      12 schedule_one.go:1044] "Unable to schedule pod; no fit; waiting" pod="default/cspod-46" err="0/5 nodes are available: 5 Insufficient cpu. preemption: 0/5 nodes are available: 5 No preemption victims found for incoming pod."
I0509 14:10:41.805770      12 preemption.go:264] "No preemption candidate is found; preemption is not helpful for scheduling" pod="default/cspod-47"
I0509 14:10:41.805810      12 schedule_one.go:1044] "Unable to schedule pod; no fit; waiting" pod="default/cspod-47" err="0/5 nodes are available: 5 Insufficient cpu. preemption: 0/5 nodes are available: 5 No preemption victims found for incoming pod."
I0509 14:10:41.806410      12 preemption.go:264] "No preemption candidate is found; preemption is not helpful for scheduling" pod="default/cspod-48"
I0509 14:10:41.806447      12 schedule_one.go:1044] "Unable to schedule pod; no fit; waiting" pod="default/cspod-48" err="0/5 nodes are available: 5 Insufficient cpu. preemption: 0/5 nodes are available: 5 No preemption victims found for incoming pod."
I0509 14:10:41.806926      12 preemption.go:264] "No preemption candidate is found; preemption is not helpful for scheduling" pod="default/cspod-49"
I0509 14:10:41.806959      12 schedule_one.go:1044] "Unable to schedule pod; no fit; waiting" pod="default/cspod-49" err="0/5 nodes are available: 5 Insufficient cpu. preemption: 0/5 nodes are available: 5 No preemption victims found for incoming pod."
I0509 14:10:41.807451      12 preemption.go:264] "No preemption candidate is found; preemption is not helpful for scheduling" pod="default/cspod-50"
I0509 14:10:41.807486      12 schedule_one.go:1044] "Unable to schedule pod; no fit; waiting" pod="default/cspod-50" err="0/5 nodes are available: 5 Insufficient cpu. preemption: 0/5 nodes are available: 5 No preemption victims found for incoming pod."
I0509 14:10:41.807938      12 preemption.go:264] "No preemption candidate is found; preemption is not helpful for scheduling" pod="default/cspod-51"
I0509 14:10:41.807968      12 schedule_one.go:1044] "Unable to schedule pod; no fit; waiting" pod="default/cspod-51" err="0/5 nodes are available: 5 Insufficient cpu. preemption: 0/5 nodes are available: 5 No preemption victims found for incoming pod."
I0509 14:10:41.808430      12 preemption.go:264] "No preemption candidate is found; preemption is not helpful for scheduling" pod="default/cspod-52"
I0509 14:10:41.808461      12 schedule_one.go:1044] "Unable to schedule pod; no fit; waiting" pod="default/cspod-52" err="0/5 nodes are available: 5 Insufficient cpu. preemption: 0/5 nodes are available: 5 No preemption victims found for incoming pod."
I0509 14:10:41.808936      12 preemption.go:264] "No preemption candidate is found; preemption is not helpful for scheduling" pod="default/cspod-53"
I0509 14:10:41.808968      12 schedule_one.go:1044] "Unable to schedule pod; no fit; waiting" pod="default/cspod-53" err="0/5 nodes are available: 5 Insufficient cpu. preemption: 0/5 nodes are available: 5 No preemption victims found for incoming pod."
I0509 14:10:41.809442      12 preemption.go:264] "No preemption candidate is found; preemption is not helpful for scheduling" pod="default/cspod-54"
I0509 14:10:41.809459      12 schedule_one.go:1044] "Unable to schedule pod; no fit; waiting" pod="default/cspod-54" err="0/5 nodes are available: 5 Insufficient cpu. preemption: 0/5 nodes are available: 5 No preemption victims found for incoming pod."
I0509 14:10:41.809971      12 preemption.go:264] "No preemption candidate is found; preemption is not helpful for scheduling" pod="default/cspod-60"
I0509 14:10:41.810003      12 schedule_one.go:1044] "Unable to schedule pod; no fit; waiting" pod="default/cspod-60" err="0/5 nodes are available: 5 Insufficient cpu. preemption: 0/5 nodes are available: 5 No preemption victims found for incoming pod."
I0509 14:10:41.810432      12 preemption.go:264] "No preemption candidate is found; preemption is not helpful for scheduling" pod="default/cspod-61"
I0509 14:10:41.810463      12 schedule_one.go:1044] "Unable to schedule pod; no fit; waiting" pod="default/cspod-61" err="0/5 nodes are available: 5 Insufficient cpu. preemption: 0/5 nodes are available: 5 No preemption victims found for incoming pod."
I0509 14:10:41.810896      12 preemption.go:264] "No preemption candidate is found; preemption is not helpful for scheduling" pod="default/cspod-62"
I0509 14:10:41.810927      12 schedule_one.go:1044] "Unable to schedule pod; no fit; waiting" pod="default/cspod-62" err="0/5 nodes are available: 5 Insufficient cpu. preemption: 0/5 nodes are available: 5 No preemption victims found for incoming pod."
I0509 14:10:41.811408      12 preemption.go:264] "No preemption candidate is found; preemption is not helpful for scheduling" pod="default/cspod-63"
I0509 14:10:41.811442      12 schedule_one.go:1044] "Unable to schedule pod; no fit; waiting" pod="default/cspod-63" err="0/5 nodes are available: 5 Insufficient cpu. preemption: 0/5 nodes are available: 5 No preemption victims found for incoming pod."
I0509 14:10:41.811954      12 preemption.go:264] "No preemption candidate is found; preemption is not helpful for scheduling" pod="default/cspod-64"
I0509 14:10:41.811988      12 schedule_one.go:1044] "Unable to schedule pod; no fit; waiting" pod="default/cspod-64" err="0/5 nodes are available: 5 Insufficient cpu. preemption: 0/5 nodes are available: 5 No preemption victims found for incoming pod."
I0509 14:10:41.812492      12 preemption.go:264] "No preemption candidate is found; preemption is not helpful for scheduling" pod="default/cspod-65"
I0509 14:10:41.812525      12 schedule_one.go:1044] "Unable to schedule pod; no fit; waiting" pod="default/cspod-65" err="0/5 nodes are available: 5 Insufficient cpu. preemption: 0/5 nodes are available: 5 No preemption victims found for incoming pod."
I0509 14:10:41.813140      12 preemption.go:264] "No preemption candidate is found; preemption is not helpful for scheduling" pod="default/cspod-66"
I0509 14:10:41.813173      12 schedule_one.go:1044] "Unable to schedule pod; no fit; waiting" pod="default/cspod-66" err="0/5 nodes are available: 5 Insufficient cpu. preemption: 0/5 nodes are available: 5 No preemption victims found for incoming pod."
I0509 14:10:41.813604      12 preemption.go:264] "No preemption candidate is found; preemption is not helpful for scheduling" pod="default/cspod-67"
I0509 14:10:41.813637      12 schedule_one.go:1044] "Unable to schedule pod; no fit; waiting" pod="default/cspod-67" err="0/5 nodes are available: 5 Insufficient cpu. preemption: 0/5 nodes are available: 5 No preemption victims found for incoming pod."
I0509 14:10:41.814115      12 preemption.go:264] "No preemption candidate is found; preemption is not helpful for scheduling" pod="default/cspod-68"
I0509 14:10:41.814149      12 schedule_one.go:1044] "Unable to schedule pod; no fit; waiting" pod="default/cspod-68" err="0/5 nodes are available: 5 Insufficient cpu. preemption: 0/5 nodes are available: 5 No preemption victims found for incoming pod."
I0509 14:10:41.814613      12 preemption.go:264] "No preemption candidate is found; preemption is not helpful for scheduling" pod="default/cspod-69"
I0509 14:10:41.814645      12 schedule_one.go:1044] "Unable to schedule pod; no fit; waiting" pod="default/cspod-69" err="0/5 nodes are available: 5 Insufficient cpu. preemption: 0/5 nodes are available: 5 No preemption victims found for incoming pod."
I0509 14:10:41.831611      12 preemption.go:264] "No preemption candidate is found; preemption is not helpful for scheduling" pod="default/cspod-45"
I0509 14:10:41.831652      12 schedule_one.go:1044] "Unable to schedule pod; no fit; waiting" pod="default/cspod-45" err="0/5 nodes are available: 5 Insufficient cpu. preemption: 0/5 nodes are available: 5 No preemption victims found for incoming pod."
I0509 14:10:41.831970      12 schedule_one.go:314] "Successfully bound pod to node" pod="default/cspod-43" node="csnode-0" evaluatedNodes=5 feasibleNodes=2
I0509 14:10:41.848601      12 schedule_one.go:314] "Successfully bound pod to node" pod="default/cspod-44" node="csnode-4" evaluatedNodes=5 feasibleNodes=1
I0509 14:10:41.869767      12 preemption.go:264] "No preemption candidate is found; preemption is not helpful for scheduling" pod="default/cspod-46"
I0509 14:10:41.869820      12 schedule_one.go:1044] "Unable to schedule pod; no fit; waiting" pod="default/cspod-46" err="0/5 nodes are available: 5 Insufficient cpu. preemption: 0/5 nodes are available: 5 No preemption victims found for incoming pod."
I0509 14:10:41.889211      12 preemption.go:264] "No preemption candidate is found; preemption is not helpful for scheduling" pod="default/cspod-47"
I0509 14:10:41.889266      12 schedule_one.go:1044] "Unable to schedule pod; no fit; waiting" pod="default/cspod-47" err="0/5 nodes are available: 5 Insufficient cpu. preemption: 0/5 nodes are available: 5 No preemption victims found for incoming pod."
I0509 14:10:41.909538      12 preemption.go:264] "No preemption candidate is found; preemption is not helpful for scheduling" pod="default/cspod-48"
I0509 14:10:41.909593      12 schedule_one.go:1044] "Unable to schedule pod; no fit; waiting" pod="default/cspod-48" err="0/5 nodes are available: 5 Insufficient cpu. preemption: 0/5 nodes are available: 5 No preemption victims found for incoming pod."
I0509 14:10:41.929689      12 preemption.go:264] "No preemption candidate is found; preemption is not helpful for scheduling" pod="default/cspod-49"
I0509 14:10:41.929732      12 schedule_one.go:1044] "Unable to schedule pod; no fit; waiting" pod="default/cspod-49" err="0/5 nodes are available: 5 Insufficient cpu. preemption: 0/5 nodes are available: 5 No preemption victims found for incoming pod."
I0509 14:10:41.948810      12 preemption.go:264] "No preemption candidate is found; preemption is not helpful for scheduling" pod="default/cspod-50"
I0509 14:10:41.948855      12 schedule_one.go:1044] "Unable to schedule pod; no fit; waiting" pod="default/cspod-50" err="0/5 nodes are available: 5 Insufficient cpu. preemption: 0/5 nodes are available: 5 No preemption victims found for incoming pod."
I0509 14:10:41.969055      12 preemption.go:264] "No preemption candidate is found; preemption is not helpful for scheduling" pod="default/cspod-51"
I0509 14:10:41.969106      12 schedule_one.go:1044] "Unable to schedule pod; no fit; waiting" pod="default/cspod-51" err="0/5 nodes are available: 5 Insufficient cpu. preemption: 0/5 nodes are available: 5 No preemption victims found for incoming pod."
I0509 14:10:41.989272      12 preemption.go:264] "No preemption candidate is found; preemption is not helpful for scheduling" pod="default/cspod-52"
I0509 14:10:41.989346      12 schedule_one.go:1044] "Unable to schedule pod; no fit; waiting" pod="default/cspod-52" err="0/5 nodes are available: 5 Insufficient cpu. preemption: 0/5 nodes are available: 5 No preemption victims found for incoming pod."
E0509 14:10:42.005899      12 event.go:368] "Unable to write event (may retry after sleeping)" err="0-length response with status code: 201 and content type: application/vnd.kubernetes.protobuf" event="&Event{ObjectMeta:{cspod-0.18adeb0599779d03  default    0 0001-01-01 00:00:00 +0000 UTC <nil> <nil> map[] map[] [] [] []},InvolvedObject:ObjectReference{Kind:Pod,Namespace:default,Name:cspod-0,UID:cspod-0-uid,APIVersion:v1,ResourceVersion:6,FieldPath:,},Reason:Scheduled,Message:Successfully assigned default/cspod-0 to csnode-4,Source:EventSource{Component:least-allocated,Host:,},FirstTimestamp:2026-05-09 14:10:37.163330819 +0000 UTC m=+6.856372268,LastTimestamp:2026-05-09 14:10:37.163330819 +0000 UTC m=+6.856372268,Count:1,Type:Normal,EventTime:0001-01-01 00:00:00 +0000 UTC,Series:nil,Action:,Related:nil,ReportingController:least-allocated,ReportingInstance:,}"
I0509 14:10:42.008720      12 preemption.go:264] "No preemption candidate is found; preemption is not helpful for scheduling" pod="default/cspod-53"
I0509 14:10:42.008763      12 schedule_one.go:1044] "Unable to schedule pod; no fit; waiting" pod="default/cspod-53" err="0/5 nodes are available: 5 Insufficient cpu. preemption: 0/5 nodes are available: 5 No preemption victims found for incoming pod."
I0509 14:10:42.028962      12 preemption.go:264] "No preemption candidate is found; preemption is not helpful for scheduling" pod="default/cspod-54"
I0509 14:10:42.029014      12 schedule_one.go:1044] "Unable to schedule pod; no fit; waiting" pod="default/cspod-54" err="0/5 nodes are available: 5 Insufficient cpu. preemption: 0/5 nodes are available: 5 No preemption victims found for incoming pod."
I0509 14:10:42.049129      12 preemption.go:264] "No preemption candidate is found; preemption is not helpful for scheduling" pod="default/cspod-60"
I0509 14:10:42.049202      12 schedule_one.go:1044] "Unable to schedule pod; no fit; waiting" pod="default/cspod-60" err="0/5 nodes are available: 5 Insufficient cpu. preemption: 0/5 nodes are available: 5 No preemption victims found for incoming pod."
I0509 14:10:42.069204      12 preemption.go:264] "No preemption candidate is found; preemption is not helpful for scheduling" pod="default/cspod-61"
I0509 14:10:42.069244      12 schedule_one.go:1044] "Unable to schedule pod; no fit; waiting" pod="default/cspod-61" err="0/5 nodes are available: 5 Insufficient cpu. preemption: 0/5 nodes are available: 5 No preemption victims found for incoming pod."
I0509 14:10:42.089354      12 preemption.go:264] "No preemption candidate is found; preemption is not helpful for scheduling" pod="default/cspod-62"
I0509 14:10:42.089394      12 schedule_one.go:1044] "Unable to schedule pod; no fit; waiting" pod="default/cspod-62" err="0/5 nodes are available: 5 Insufficient cpu. preemption: 0/5 nodes are available: 5 No preemption victims found for incoming pod."
I0509 14:10:42.109619      12 preemption.go:264] "No preemption candidate is found; preemption is not helpful for scheduling" pod="default/cspod-63"
I0509 14:10:42.109664      12 schedule_one.go:1044] "Unable to schedule pod; no fit; waiting" pod="default/cspod-63" err="0/5 nodes are available: 5 Insufficient cpu. preemption: 0/5 nodes are available: 5 No preemption victims found for incoming pod."
I0509 14:10:42.129724      12 preemption.go:264] "No preemption candidate is found; preemption is not helpful for scheduling" pod="default/cspod-64"
I0509 14:10:42.129771      12 schedule_one.go:1044] "Unable to schedule pod; no fit; waiting" pod="default/cspod-64" err="0/5 nodes are available: 5 Insufficient cpu. preemption: 0/5 nodes are available: 5 No preemption victims found for incoming pod."
I0509 14:10:42.148882      12 preemption.go:264] "No preemption candidate is found; preemption is not helpful for scheduling" pod="default/cspod-65"
I0509 14:10:42.148950      12 schedule_one.go:1044] "Unable to schedule pod; no fit; waiting" pod="default/cspod-65" err="0/5 nodes are available: 5 Insufficient cpu. preemption: 0/5 nodes are available: 5 No preemption victims found for incoming pod."
I0509 14:10:42.168965      12 preemption.go:264] "No preemption candidate is found; preemption is not helpful for scheduling" pod="default/cspod-66"
I0509 14:10:42.169039      12 schedule_one.go:1044] "Unable to schedule pod; no fit; waiting" pod="default/cspod-66" err="0/5 nodes are available: 5 Insufficient cpu. preemption: 0/5 nodes are available: 5 No preemption victims found for incoming pod."
I0509 14:10:42.188994      12 preemption.go:264] "No preemption candidate is found; preemption is not helpful for scheduling" pod="default/cspod-67"
I0509 14:10:42.189042      12 schedule_one.go:1044] "Unable to schedule pod; no fit; waiting" pod="default/cspod-67" err="0/5 nodes are available: 5 Insufficient cpu. preemption: 0/5 nodes are available: 5 No preemption victims found for incoming pod."
I0509 14:10:42.209214      12 preemption.go:264] "No preemption candidate is found; preemption is not helpful for scheduling" pod="default/cspod-68"
I0509 14:10:42.209260      12 schedule_one.go:1044] "Unable to schedule pod; no fit; waiting" pod="default/cspod-68" err="0/5 nodes are available: 5 Insufficient cpu. preemption: 0/5 nodes are available: 5 No preemption victims found for incoming pod."
I0509 14:10:42.229191      12 preemption.go:264] "No preemption candidate is found; preemption is not helpful for scheduling" pod="default/cspod-69"
I0509 14:10:42.229228      12 schedule_one.go:1044] "Unable to schedule pod; no fit; waiting" pod="default/cspod-69" err="0/5 nodes are available: 5 Insufficient cpu. preemption: 0/5 nodes are available: 5 No preemption victims found for incoming pod."
I0509 14:10:42.256158      12 preemption.go:264] "No preemption candidate is found; preemption is not helpful for scheduling" pod="default/cspod-46"
I0509 14:10:42.256195      12 schedule_one.go:1044] "Unable to schedule pod; no fit; waiting" pod="default/cspod-46" err="0/5 nodes are available: 5 Insufficient cpu. preemption: 0/5 nodes are available: 5 No preemption victims found for incoming pod."
I0509 14:10:42.268911      12 schedule_one.go:314] "Successfully bound pod to node" pod="default/cspod-45" node="csnode-1" evaluatedNodes=5 feasibleNodes=1
I0509 14:10:42.289108      12 preemption.go:264] "No preemption candidate is found; preemption is not helpful for scheduling" pod="default/cspod-47"
I0509 14:10:42.289185      12 schedule_one.go:1044] "Unable to schedule pod; no fit; waiting" pod="default/cspod-47" err="0/5 nodes are available: 5 Insufficient cpu. preemption: 0/5 nodes are available: 5 No preemption victims found for incoming pod."
I0509 14:10:42.309269      12 preemption.go:264] "No preemption candidate is found; preemption is not helpful for scheduling" pod="default/cspod-48"
I0509 14:10:42.309337      12 schedule_one.go:1044] "Unable to schedule pod; no fit; waiting" pod="default/cspod-48" err="0/5 nodes are available: 5 Insufficient cpu. preemption: 0/5 nodes are available: 5 No preemption victims found for incoming pod."
I0509 14:10:42.329693      12 preemption.go:264] "No preemption candidate is found; preemption is not helpful for scheduling" pod="default/cspod-49"
I0509 14:10:42.329746      12 schedule_one.go:1044] "Unable to schedule pod; no fit; waiting" pod="default/cspod-49" err="0/5 nodes are available: 5 Insufficient cpu. preemption: 0/5 nodes are available: 5 No preemption victims found for incoming pod."
I0509 14:10:42.348633      12 preemption.go:264] "No preemption candidate is found; preemption is not helpful for scheduling" pod="default/cspod-50"
I0509 14:10:42.348707      12 schedule_one.go:1044] "Unable to schedule pod; no fit; waiting" pod="default/cspod-50" err="0/5 nodes are available: 5 Insufficient cpu. preemption: 0/5 nodes are available: 5 No preemption victims found for incoming pod."
I0509 14:10:42.368797      12 preemption.go:264] "No preemption candidate is found; preemption is not helpful for scheduling" pod="default/cspod-51"
I0509 14:10:42.368867      12 schedule_one.go:1044] "Unable to schedule pod; no fit; waiting" pod="default/cspod-51" err="0/5 nodes are available: 5 Insufficient cpu. preemption: 0/5 nodes are available: 5 No preemption victims found for incoming pod."
I0509 14:10:42.388994      12 preemption.go:264] "No preemption candidate is found; preemption is not helpful for scheduling" pod="default/cspod-52"
I0509 14:10:42.389034      12 schedule_one.go:1044] "Unable to schedule pod; no fit; waiting" pod="default/cspod-52" err="0/5 nodes are available: 5 Insufficient cpu. preemption: 0/5 nodes are available: 5 No preemption victims found for incoming pod."
I0509 14:10:42.409139      12 preemption.go:264] "No preemption candidate is found; preemption is not helpful for scheduling" pod="default/cspod-53"
I0509 14:10:42.409175      12 schedule_one.go:1044] "Unable to schedule pod; no fit; waiting" pod="default/cspod-53" err="0/5 nodes are available: 5 Insufficient cpu. preemption: 0/5 nodes are available: 5 No preemption victims found for incoming pod."
I0509 14:10:42.429247      12 preemption.go:264] "No preemption candidate is found; preemption is not helpful for scheduling" pod="default/cspod-54"
I0509 14:10:42.429294      12 schedule_one.go:1044] "Unable to schedule pod; no fit; waiting" pod="default/cspod-54" err="0/5 nodes are available: 5 Insufficient cpu. preemption: 0/5 nodes are available: 5 No preemption victims found for incoming pod."
I0509 14:10:42.449289      12 preemption.go:264] "No preemption candidate is found; preemption is not helpful for scheduling" pod="default/cspod-60"
I0509 14:10:42.449331      12 schedule_one.go:1044] "Unable to schedule pod; no fit; waiting" pod="default/cspod-60" err="0/5 nodes are available: 5 Insufficient cpu. preemption: 0/5 nodes are available: 5 No preemption victims found for incoming pod."
I0509 14:10:42.469407      12 preemption.go:264] "No preemption candidate is found; preemption is not helpful for scheduling" pod="default/cspod-61"
I0509 14:10:42.469455      12 schedule_one.go:1044] "Unable to schedule pod; no fit; waiting" pod="default/cspod-61" err="0/5 nodes are available: 5 Insufficient cpu. preemption: 0/5 nodes are available: 5 No preemption victims found for incoming pod."
I0509 14:10:42.489367      12 preemption.go:264] "No preemption candidate is found; preemption is not helpful for scheduling" pod="default/cspod-62"
I0509 14:10:42.489439      12 schedule_one.go:1044] "Unable to schedule pod; no fit; waiting" pod="default/cspod-62" err="0/5 nodes are available: 5 Insufficient cpu. preemption: 0/5 nodes are available: 5 No preemption victims found for incoming pod."
I0509 14:10:42.509599      12 preemption.go:264] "No preemption candidate is found; preemption is not helpful for scheduling" pod="default/cspod-63"
I0509 14:10:42.509640      12 schedule_one.go:1044] "Unable to schedule pod; no fit; waiting" pod="default/cspod-63" err="0/5 nodes are available: 5 Insufficient cpu. preemption: 0/5 nodes are available: 5 No preemption victims found for incoming pod."
I0509 14:10:42.529778      12 preemption.go:264] "No preemption candidate is found; preemption is not helpful for scheduling" pod="default/cspod-64"
I0509 14:10:42.529829      12 schedule_one.go:1044] "Unable to schedule pod; no fit; waiting" pod="default/cspod-64" err="0/5 nodes are available: 5 Insufficient cpu. preemption: 0/5 nodes are available: 5 No preemption victims found for incoming pod."
I0509 14:10:42.549293      12 preemption.go:264] "No preemption candidate is found; preemption is not helpful for scheduling" pod="default/cspod-65"
I0509 14:10:42.549336      12 schedule_one.go:1044] "Unable to schedule pod; no fit; waiting" pod="default/cspod-65" err="0/5 nodes are available: 5 Insufficient cpu. preemption: 0/5 nodes are available: 5 No preemption victims found for incoming pod."
I0509 14:10:42.569305      12 preemption.go:264] "No preemption candidate is found; preemption is not helpful for scheduling" pod="default/cspod-66"
I0509 14:10:42.569360      12 schedule_one.go:1044] "Unable to schedule pod; no fit; waiting" pod="default/cspod-66" err="0/5 nodes are available: 5 Insufficient cpu. preemption: 0/5 nodes are available: 5 No preemption victims found for incoming pod."
I0509 14:10:42.589562      12 preemption.go:264] "No preemption candidate is found; preemption is not helpful for scheduling" pod="default/cspod-67"
I0509 14:10:42.589628      12 schedule_one.go:1044] "Unable to schedule pod; no fit; waiting" pod="default/cspod-67" err="0/5 nodes are available: 5 Insufficient cpu. preemption: 0/5 nodes are available: 5 No preemption victims found for incoming pod."
I0509 14:10:42.609469      12 preemption.go:264] "No preemption candidate is found; preemption is not helpful for scheduling" pod="default/cspod-68"
I0509 14:10:42.609508      12 schedule_one.go:1044] "Unable to schedule pod; no fit; waiting" pod="default/cspod-68" err="0/5 nodes are available: 5 Insufficient cpu. preemption: 0/5 nodes are available: 5 No preemption victims found for incoming pod."
I0509 14:10:42.629665      12 preemption.go:264] "No preemption candidate is found; preemption is not helpful for scheduling" pod="default/cspod-69"
I0509 14:10:42.629709      12 schedule_one.go:1044] "Unable to schedule pod; no fit; waiting" pod="default/cspod-69" err="0/5 nodes are available: 5 Insufficient cpu. preemption: 0/5 nodes are available: 5 No preemption victims found for incoming pod."
I0509 14:10:42.654115      12 preemption.go:264] "No preemption candidate is found; preemption is not helpful for scheduling" pod="default/cspod-49"
I0509 14:10:42.654157      12 schedule_one.go:1044] "Unable to schedule pod; no fit; waiting" pod="default/cspod-49" err="0/5 nodes are available: 5 Insufficient cpu. preemption: 0/5 nodes are available: 5 No preemption victims found for incoming pod."
I0509 14:10:42.668401      12 schedule_one.go:314] "Successfully bound pod to node" pod="default/cspod-46" node="csnode-3" evaluatedNodes=5 feasibleNodes=3
I0509 14:10:42.688842      12 schedule_one.go:314] "Successfully bound pod to node" pod="default/cspod-47" node="csnode-2" evaluatedNodes=5 feasibleNodes=2
I0509 14:10:42.708643      12 schedule_one.go:314] "Successfully bound pod to node" pod="default/cspod-48" node="csnode-1" evaluatedNodes=5 feasibleNodes=1
I0509 14:10:42.729626      12 preemption.go:264] "No preemption candidate is found; preemption is not helpful for scheduling" pod="default/cspod-50"
I0509 14:10:42.729671      12 schedule_one.go:1044] "Unable to schedule pod; no fit; waiting" pod="default/cspod-50" err="0/5 nodes are available: 5 Insufficient cpu. preemption: 0/5 nodes are available: 5 No preemption victims found for incoming pod."
I0509 14:10:42.749223      12 preemption.go:264] "No preemption candidate is found; preemption is not helpful for scheduling" pod="default/cspod-51"
I0509 14:10:42.749269      12 schedule_one.go:1044] "Unable to schedule pod; no fit; waiting" pod="default/cspod-51" err="0/5 nodes are available: 5 Insufficient cpu. preemption: 0/5 nodes are available: 5 No preemption victims found for incoming pod."
I0509 14:10:42.769097      12 preemption.go:264] "No preemption candidate is found; preemption is not helpful for scheduling" pod="default/cspod-52"
I0509 14:10:42.769163      12 schedule_one.go:1044] "Unable to schedule pod; no fit; waiting" pod="default/cspod-52" err="0/5 nodes are available: 5 Insufficient cpu. preemption: 0/5 nodes are available: 5 No preemption victims found for incoming pod."
I0509 14:10:42.789251      12 preemption.go:264] "No preemption candidate is found; preemption is not helpful for scheduling" pod="default/cspod-53"
I0509 14:10:42.789293      12 schedule_one.go:1044] "Unable to schedule pod; no fit; waiting" pod="default/cspod-53" err="0/5 nodes are available: 5 Insufficient cpu. preemption: 0/5 nodes are available: 5 No preemption victims found for incoming pod."
I0509 14:10:42.809260      12 preemption.go:264] "No preemption candidate is found; preemption is not helpful for scheduling" pod="default/cspod-54"
I0509 14:10:42.809327      12 schedule_one.go:1044] "Unable to schedule pod; no fit; waiting" pod="default/cspod-54" err="0/5 nodes are available: 5 Insufficient cpu. preemption: 0/5 nodes are available: 5 No preemption victims found for incoming pod."
I0509 14:10:42.829446      12 preemption.go:264] "No preemption candidate is found; preemption is not helpful for scheduling" pod="default/cspod-60"
I0509 14:10:42.829519      12 schedule_one.go:1044] "Unable to schedule pod; no fit; waiting" pod="default/cspod-60" err="0/5 nodes are available: 5 Insufficient cpu. preemption: 0/5 nodes are available: 5 No preemption victims found for incoming pod."
I0509 14:10:42.849376      12 preemption.go:264] "No preemption candidate is found; preemption is not helpful for scheduling" pod="default/cspod-61"
I0509 14:10:42.849411      12 schedule_one.go:1044] "Unable to schedule pod; no fit; waiting" pod="default/cspod-61" err="0/5 nodes are available: 5 Insufficient cpu. preemption: 0/5 nodes are available: 5 No preemption victims found for incoming pod."
I0509 14:10:42.869670      12 preemption.go:264] "No preemption candidate is found; preemption is not helpful for scheduling" pod="default/cspod-62"
I0509 14:10:42.869740      12 schedule_one.go:1044] "Unable to schedule pod; no fit; waiting" pod="default/cspod-62" err="0/5 nodes are available: 5 Insufficient cpu. preemption: 0/5 nodes are available: 5 No preemption victims found for incoming pod."
I0509 14:10:42.888937      12 preemption.go:264] "No preemption candidate is found; preemption is not helpful for scheduling" pod="default/cspod-63"
I0509 14:10:42.888982      12 schedule_one.go:1044] "Unable to schedule pod; no fit; waiting" pod="default/cspod-63" err="0/5 nodes are available: 5 Insufficient cpu. preemption: 0/5 nodes are available: 5 No preemption victims found for incoming pod."
I0509 14:10:42.909509      12 preemption.go:264] "No preemption candidate is found; preemption is not helpful for scheduling" pod="default/cspod-64"
I0509 14:10:42.909661      12 schedule_one.go:1044] "Unable to schedule pod; no fit; waiting" pod="default/cspod-64" err="0/5 nodes are available: 5 Insufficient cpu. preemption: 0/5 nodes are available: 5 No preemption victims found for incoming pod."
I0509 14:10:42.928673      12 preemption.go:264] "No preemption candidate is found; preemption is not helpful for scheduling" pod="default/cspod-65"
I0509 14:10:42.928713      12 schedule_one.go:1044] "Unable to schedule pod; no fit; waiting" pod="default/cspod-65" err="0/5 nodes are available: 5 Insufficient cpu. preemption: 0/5 nodes are available: 5 No preemption victims found for incoming pod."
I0509 14:10:42.949681      12 preemption.go:264] "No preemption candidate is found; preemption is not helpful for scheduling" pod="default/cspod-66"
I0509 14:10:42.949728      12 schedule_one.go:1044] "Unable to schedule pod; no fit; waiting" pod="default/cspod-66" err="0/5 nodes are available: 5 Insufficient cpu. preemption: 0/5 nodes are available: 5 No preemption victims found for incoming pod."
I0509 14:10:42.968863      12 preemption.go:264] "No preemption candidate is found; preemption is not helpful for scheduling" pod="default/cspod-67"
I0509 14:10:42.968914      12 schedule_one.go:1044] "Unable to schedule pod; no fit; waiting" pod="default/cspod-67" err="0/5 nodes are available: 5 Insufficient cpu. preemption: 0/5 nodes are available: 5 No preemption victims found for incoming pod."
I0509 14:10:42.988778      12 preemption.go:264] "No preemption candidate is found; preemption is not helpful for scheduling" pod="default/cspod-68"
I0509 14:10:42.988815      12 schedule_one.go:1044] "Unable to schedule pod; no fit; waiting" pod="default/cspod-68" err="0/5 nodes are available: 5 Insufficient cpu. preemption: 0/5 nodes are available: 5 No preemption victims found for incoming pod."
I0509 14:10:43.008739      12 preemption.go:264] "No preemption candidate is found; preemption is not helpful for scheduling" pod="default/cspod-69"
I0509 14:10:43.008816      12 schedule_one.go:1044] "Unable to schedule pod; no fit; waiting" pod="default/cspod-69" err="0/5 nodes are available: 5 Insufficient cpu. preemption: 0/5 nodes are available: 5 No preemption victims found for incoming pod."
I0509 14:10:43.038145      12 preemption.go:264] "No preemption candidate is found; preemption is not helpful for scheduling" pod="default/cspod-53"
I0509 14:10:43.038181      12 schedule_one.go:1044] "Unable to schedule pod; no fit; waiting" pod="default/cspod-53" err="0/5 nodes are available: 5 Insufficient cpu. preemption: 0/5 nodes are available: 5 No preemption victims found for incoming pod."
I0509 14:10:43.048471      12 schedule_one.go:314] "Successfully bound pod to node" pod="default/cspod-49" node="csnode-2" evaluatedNodes=5 feasibleNodes=2
I0509 14:10:43.069121      12 schedule_one.go:314] "Successfully bound pod to node" pod="default/cspod-50" node="csnode-3" evaluatedNodes=5 feasibleNodes=3
I0509 14:10:43.088901      12 schedule_one.go:314] "Successfully bound pod to node" pod="default/cspod-51" node="csnode-4" evaluatedNodes=5 feasibleNodes=2
I0509 14:10:43.108455      12 schedule_one.go:314] "Successfully bound pod to node" pod="default/cspod-52" node="csnode-0" evaluatedNodes=5 feasibleNodes=1
I0509 14:10:43.129626      12 preemption.go:264] "No preemption candidate is found; preemption is not helpful for scheduling" pod="default/cspod-54"
I0509 14:10:43.129671      12 schedule_one.go:1044] "Unable to schedule pod; no fit; waiting" pod="default/cspod-54" err="0/5 nodes are available: 5 Insufficient cpu. preemption: 0/5 nodes are available: 5 No preemption victims found for incoming pod."
I0509 14:10:43.149831      12 preemption.go:264] "No preemption candidate is found; preemption is not helpful for scheduling" pod="default/cspod-60"
I0509 14:10:43.149872      12 schedule_one.go:1044] "Unable to schedule pod; no fit; waiting" pod="default/cspod-60" err="0/5 nodes are available: 5 Insufficient cpu. preemption: 0/5 nodes are available: 5 No preemption victims found for incoming pod."
I0509 14:10:43.168828      12 preemption.go:264] "No preemption candidate is found; preemption is not helpful for scheduling" pod="default/cspod-61"
I0509 14:10:43.168872      12 schedule_one.go:1044] "Unable to schedule pod; no fit; waiting" pod="default/cspod-61" err="0/5 nodes are available: 5 Insufficient cpu. preemption: 0/5 nodes are available: 5 No preemption victims found for incoming pod."
I0509 14:10:43.188637      12 preemption.go:264] "No preemption candidate is found; preemption is not helpful for scheduling" pod="default/cspod-62"
I0509 14:10:43.188674      12 schedule_one.go:1044] "Unable to schedule pod; no fit; waiting" pod="default/cspod-62" err="0/5 nodes are available: 5 Insufficient cpu. preemption: 0/5 nodes are available: 5 No preemption victims found for incoming pod."
I0509 14:10:43.209990      12 preemption.go:264] "No preemption candidate is found; preemption is not helpful for scheduling" pod="default/cspod-63"
I0509 14:10:43.210064      12 schedule_one.go:1044] "Unable to schedule pod; no fit; waiting" pod="default/cspod-63" err="0/5 nodes are available: 5 Insufficient cpu. preemption: 0/5 nodes are available: 5 No preemption victims found for incoming pod."
I0509 14:10:43.228944      12 preemption.go:264] "No preemption candidate is found; preemption is not helpful for scheduling" pod="default/cspod-64"
I0509 14:10:43.228984      12 schedule_one.go:1044] "Unable to schedule pod; no fit; waiting" pod="default/cspod-64" err="0/5 nodes are available: 5 Insufficient cpu. preemption: 0/5 nodes are available: 5 No preemption victims found for incoming pod."
I0509 14:10:43.248923      12 preemption.go:264] "No preemption candidate is found; preemption is not helpful for scheduling" pod="default/cspod-65"
I0509 14:10:43.248958      12 schedule_one.go:1044] "Unable to schedule pod; no fit; waiting" pod="default/cspod-65" err="0/5 nodes are available: 5 Insufficient cpu. preemption: 0/5 nodes are available: 5 No preemption victims found for incoming pod."
I0509 14:10:43.268837      12 preemption.go:264] "No preemption candidate is found; preemption is not helpful for scheduling" pod="default/cspod-66"
I0509 14:10:43.268873      12 schedule_one.go:1044] "Unable to schedule pod; no fit; waiting" pod="default/cspod-66" err="0/5 nodes are available: 5 Insufficient cpu. preemption: 0/5 nodes are available: 5 No preemption victims found for incoming pod."
I0509 14:10:43.288973      12 preemption.go:264] "No preemption candidate is found; preemption is not helpful for scheduling" pod="default/cspod-67"
I0509 14:10:43.289015      12 schedule_one.go:1044] "Unable to schedule pod; no fit; waiting" pod="default/cspod-67" err="0/5 nodes are available: 5 Insufficient cpu. preemption: 0/5 nodes are available: 5 No preemption victims found for incoming pod."
I0509 14:10:43.309072      12 preemption.go:264] "No preemption candidate is found; preemption is not helpful for scheduling" pod="default/cspod-68"
I0509 14:10:43.309111      12 schedule_one.go:1044] "Unable to schedule pod; no fit; waiting" pod="default/cspod-68" err="0/5 nodes are available: 5 Insufficient cpu. preemption: 0/5 nodes are available: 5 No preemption victims found for incoming pod."
I0509 14:10:43.329495      12 preemption.go:264] "No preemption candidate is found; preemption is not helpful for scheduling" pod="default/cspod-69"
I0509 14:10:43.329541      12 schedule_one.go:1044] "Unable to schedule pod; no fit; waiting" pod="default/cspod-69" err="0/5 nodes are available: 5 Insufficient cpu. preemption: 0/5 nodes are available: 5 No preemption victims found for incoming pod."
I0509 14:10:43.355315      12 preemption.go:264] "No preemption candidate is found; preemption is not helpful for scheduling" pod="default/cspod-60"
I0509 14:10:43.355353      12 schedule_one.go:1044] "Unable to schedule pod; no fit; waiting" pod="default/cspod-60" err="0/5 nodes are available: 5 Insufficient cpu. preemption: 0/5 nodes are available: 5 No preemption victims found for incoming pod."
I0509 14:10:43.368961      12 schedule_one.go:314] "Successfully bound pod to node" pod="default/cspod-53" node="csnode-0" evaluatedNodes=5 feasibleNodes=2
I0509 14:10:43.388747      12 schedule_one.go:314] "Successfully bound pod to node" pod="default/cspod-54" node="csnode-4" evaluatedNodes=5 feasibleNodes=1
I0509 14:10:43.409735      12 preemption.go:264] "No preemption candidate is found; preemption is not helpful for scheduling" pod="default/cspod-61"
I0509 14:10:43.409808      12 schedule_one.go:1044] "Unable to schedule pod; no fit; waiting" pod="default/cspod-61" err="0/5 nodes are available: 5 Insufficient cpu. preemption: 0/5 nodes are available: 5 No preemption victims found for incoming pod."
I0509 14:10:43.428818      12 preemption.go:264] "No preemption candidate is found; preemption is not helpful for scheduling" pod="default/cspod-62"
I0509 14:10:43.428887      12 schedule_one.go:1044] "Unable to schedule pod; no fit; waiting" pod="default/cspod-62" err="0/5 nodes are available: 5 Insufficient cpu. preemption: 0/5 nodes are available: 5 No preemption victims found for incoming pod."
I0509 14:10:43.449099      12 preemption.go:264] "No preemption candidate is found; preemption is not helpful for scheduling" pod="default/cspod-63"
I0509 14:10:43.449144      12 schedule_one.go:1044] "Unable to schedule pod; no fit; waiting" pod="default/cspod-63" err="0/5 nodes are available: 5 Insufficient cpu. preemption: 0/5 nodes are available: 5 No preemption victims found for incoming pod."
I0509 14:10:43.469253      12 preemption.go:264] "No preemption candidate is found; preemption is not helpful for scheduling" pod="default/cspod-64"
I0509 14:10:43.469319      12 schedule_one.go:1044] "Unable to schedule pod; no fit; waiting" pod="default/cspod-64" err="0/5 nodes are available: 5 Insufficient cpu. preemption: 0/5 nodes are available: 5 No preemption victims found for incoming pod."
I0509 14:10:43.489216      12 preemption.go:264] "No preemption candidate is found; preemption is not helpful for scheduling" pod="default/cspod-65"
I0509 14:10:43.489252      12 schedule_one.go:1044] "Unable to schedule pod; no fit; waiting" pod="default/cspod-65" err="0/5 nodes are available: 5 Insufficient cpu. preemption: 0/5 nodes are available: 5 No preemption victims found for incoming pod."
I0509 14:10:43.509073      12 preemption.go:264] "No preemption candidate is found; preemption is not helpful for scheduling" pod="default/cspod-66"
I0509 14:10:43.509117      12 schedule_one.go:1044] "Unable to schedule pod; no fit; waiting" pod="default/cspod-66" err="0/5 nodes are available: 5 Insufficient cpu. preemption: 0/5 nodes are available: 5 No preemption victims found for incoming pod."
I0509 14:10:43.529258      12 preemption.go:264] "No preemption candidate is found; preemption is not helpful for scheduling" pod="default/cspod-67"
I0509 14:10:43.529303      12 schedule_one.go:1044] "Unable to schedule pod; no fit; waiting" pod="default/cspod-67" err="0/5 nodes are available: 5 Insufficient cpu. preemption: 0/5 nodes are available: 5 No preemption victims found for incoming pod."
I0509 14:10:43.549421      12 preemption.go:264] "No preemption candidate is found; preemption is not helpful for scheduling" pod="default/cspod-68"
I0509 14:10:43.549478      12 schedule_one.go:1044] "Unable to schedule pod; no fit; waiting" pod="default/cspod-68" err="0/5 nodes are available: 5 Insufficient cpu. preemption: 0/5 nodes are available: 5 No preemption victims found for incoming pod."
I0509 14:10:43.569294      12 preemption.go:264] "No preemption candidate is found; preemption is not helpful for scheduling" pod="default/cspod-69"
I0509 14:10:43.569339      12 schedule_one.go:1044] "Unable to schedule pod; no fit; waiting" pod="default/cspod-69" err="0/5 nodes are available: 5 Insufficient cpu. preemption: 0/5 nodes are available: 5 No preemption victims found for incoming pod."
I0509 14:10:43.596984      12 preemption.go:264] "No preemption candidate is found; preemption is not helpful for scheduling" pod="default/cspod-64"
I0509 14:10:43.597026      12 schedule_one.go:1044] "Unable to schedule pod; no fit; waiting" pod="default/cspod-64" err="0/5 nodes are available: 5 Insufficient cpu. preemption: 0/5 nodes are available: 5 No preemption victims found for incoming pod."
I0509 14:10:43.609568      12 schedule_one.go:314] "Successfully bound pod to node" pod="default/cspod-60" node="csnode-1" evaluatedNodes=5 feasibleNodes=1
I0509 14:10:43.629401      12 schedule_one.go:314] "Successfully bound pod to node" pod="default/cspod-61" node="csnode-3" evaluatedNodes=5 feasibleNodes=3
I0509 14:10:43.649011      12 schedule_one.go:314] "Successfully bound pod to node" pod="default/cspod-62" node="csnode-2" evaluatedNodes=5 feasibleNodes=2
I0509 14:10:43.668570      12 schedule_one.go:314] "Successfully bound pod to node" pod="default/cspod-63" node="csnode-1" evaluatedNodes=5 feasibleNodes=1
I0509 14:10:43.689621      12 preemption.go:264] "No preemption candidate is found; preemption is not helpful for scheduling" pod="default/cspod-65"
I0509 14:10:43.689669      12 schedule_one.go:1044] "Unable to schedule pod; no fit; waiting" pod="default/cspod-65" err="0/5 nodes are available: 5 Insufficient cpu. preemption: 0/5 nodes are available: 5 No preemption victims found for incoming pod."
I0509 14:10:43.708714      12 preemption.go:264] "No preemption candidate is found; preemption is not helpful for scheduling" pod="default/cspod-66"
I0509 14:10:43.708761      12 schedule_one.go:1044] "Unable to schedule pod; no fit; waiting" pod="default/cspod-66" err="0/5 nodes are available: 5 Insufficient cpu. preemption: 0/5 nodes are available: 5 No preemption victims found for incoming pod."
I0509 14:10:43.728514      12 preemption.go:264] "No preemption candidate is found; preemption is not helpful for scheduling" pod="default/cspod-67"
I0509 14:10:43.728549      12 schedule_one.go:1044] "Unable to schedule pod; no fit; waiting" pod="default/cspod-67" err="0/5 nodes are available: 5 Insufficient cpu. preemption: 0/5 nodes are available: 5 No preemption victims found for incoming pod."
I0509 14:10:43.749299      12 preemption.go:264] "No preemption candidate is found; preemption is not helpful for scheduling" pod="default/cspod-68"
I0509 14:10:43.749338      12 schedule_one.go:1044] "Unable to schedule pod; no fit; waiting" pod="default/cspod-68" err="0/5 nodes are available: 5 Insufficient cpu. preemption: 0/5 nodes are available: 5 No preemption victims found for incoming pod."
I0509 14:10:43.769538      12 preemption.go:264] "No preemption candidate is found; preemption is not helpful for scheduling" pod="default/cspod-69"
I0509 14:10:43.769586      12 schedule_one.go:1044] "Unable to schedule pod; no fit; waiting" pod="default/cspod-69" err="0/5 nodes are available: 5 Insufficient cpu. preemption: 0/5 nodes are available: 5 No preemption victims found for incoming pod."
I0509 14:10:43.799632      12 preemption.go:264] "No preemption candidate is found; preemption is not helpful for scheduling" pod="default/cspod-66"
I0509 14:10:43.799673      12 schedule_one.go:1044] "Unable to schedule pod; no fit; waiting" pod="default/cspod-66" err="0/5 nodes are available: 5 Insufficient cpu. preemption: 0/5 nodes are available: 5 No preemption victims found for incoming pod."
I0509 14:10:43.809269      12 schedule_one.go:314] "Successfully bound pod to node" pod="default/cspod-64" node="csnode-3" evaluatedNodes=5 feasibleNodes=2
I0509 14:10:43.828964      12 schedule_one.go:314] "Successfully bound pod to node" pod="default/cspod-65" node="csnode-2" evaluatedNodes=5 feasibleNodes=1
I0509 14:10:43.848918      12 preemption.go:264] "No preemption candidate is found; preemption is not helpful for scheduling" pod="default/cspod-67"
I0509 14:10:43.848964      12 schedule_one.go:1044] "Unable to schedule pod; no fit; waiting" pod="default/cspod-67" err="0/5 nodes are available: 5 Insufficient cpu. preemption: 0/5 nodes are available: 5 No preemption victims found for incoming pod."
I0509 14:10:43.869304      12 preemption.go:264] "No preemption candidate is found; preemption is not helpful for scheduling" pod="default/cspod-68"
I0509 14:10:43.869382      12 schedule_one.go:1044] "Unable to schedule pod; no fit; waiting" pod="default/cspod-68" err="0/5 nodes are available: 5 Insufficient cpu. preemption: 0/5 nodes are available: 5 No preemption victims found for incoming pod."
I0509 14:10:43.889609      12 preemption.go:264] "No preemption candidate is found; preemption is not helpful for scheduling" pod="default/cspod-69"
I0509 14:10:43.889657      12 schedule_one.go:1044] "Unable to schedule pod; no fit; waiting" pod="default/cspod-69" err="0/5 nodes are available: 5 Insufficient cpu. preemption: 0/5 nodes are available: 5 No preemption victims found for incoming pod."
I0509 14:10:43.914903      12 preemption.go:264] "No preemption candidate is found; preemption is not helpful for scheduling" pod="default/cspod-67"
I0509 14:10:43.914946      12 schedule_one.go:1044] "Unable to schedule pod; no fit; waiting" pod="default/cspod-67" err="0/5 nodes are available: 5 Insufficient cpu. preemption: 0/5 nodes are available: 5 No preemption victims found for incoming pod."
I0509 14:10:43.929418      12 schedule_one.go:314] "Successfully bound pod to node" pod="default/cspod-66" node="csnode-4" evaluatedNodes=5 feasibleNodes=1
I0509 14:10:43.949417      12 preemption.go:264] "No preemption candidate is found; preemption is not helpful for scheduling" pod="default/cspod-68"
I0509 14:10:43.949462      12 schedule_one.go:1044] "Unable to schedule pod; no fit; waiting" pod="default/cspod-68" err="0/5 nodes are available: 5 Insufficient cpu. preemption: 0/5 nodes are available: 5 No preemption victims found for incoming pod."
I0509 14:10:43.969450      12 preemption.go:264] "No preemption candidate is found; preemption is not helpful for scheduling" pod="default/cspod-69"
I0509 14:10:43.969523      12 schedule_one.go:1044] "Unable to schedule pod; no fit; waiting" pod="default/cspod-69" err="0/5 nodes are available: 5 Insufficient cpu. preemption: 0/5 nodes are available: 5 No preemption victims found for incoming pod."
I0509 14:10:44.008812      12 schedule_one.go:314] "Successfully bound pod to node" pod="default/cspod-67" node="csnode-0" evaluatedNodes=5 feasibleNodes=1
I0509 14:10:44.029686      12 schedule_one.go:314] "Successfully bound pod to node" pod="default/cspod-68" node="csnode-4" evaluatedNodes=5 feasibleNodes=2
I0509 14:10:44.049296      12 schedule_one.go:314] "Successfully bound pod to node" pod="default/cspod-69" node="csnode-0" evaluatedNodes=5 feasibleNodes=1
I0509 14:10:44.069392      12 node_tree.go:79] "Removed node from NodeTree" node="csnode-4" zone=""
I0509 14:10:44.069427      12 node_tree.go:79] "Removed node from NodeTree" node="csnode-0" zone=""
I0509 14:10:44.069435      12 node_tree.go:79] "Removed node from NodeTree" node="csnode-1" zone=""
I0509 14:10:44.069438      12 node_tree.go:79] "Removed node from NodeTree" node="csnode-2" zone=""
I0509 14:10:44.069442      12 node_tree.go:79] "Removed node from NodeTree" node="csnode-3" zone=""
