2026/05/06 15:10:31 Running command:
Command env: (log-file=, also-stdout=false, redirect-stderr=true)
Run from directory: 
Executable path: /usr/local/bin/kube-scheduler
Args (comma-delimited): kube-scheduler,--config=/etc/kube-scheduler/my-scheduler.yaml,--secure-port=10260,--v=2
2026/05/06 15:10:31 Now listening for interrupts
I0506 15:10:31.624883      12 flags.go:64] FLAG: --allow-metric-labels="[]"
I0506 15:10:31.624930      12 flags.go:64] FLAG: --allow-metric-labels-manifest=""
I0506 15:10:31.624936      12 flags.go:64] FLAG: --authentication-kubeconfig=""
I0506 15:10:31.624938      12 flags.go:64] FLAG: --authentication-skip-lookup="false"
I0506 15:10:31.624940      12 flags.go:64] FLAG: --authentication-token-webhook-cache-ttl="10s"
I0506 15:10:31.624943      12 flags.go:64] FLAG: --authentication-tolerate-lookup-failure="true"
I0506 15:10:31.624944      12 flags.go:64] FLAG: --authorization-always-allow-paths="[/healthz,/readyz,/livez]"
I0506 15:10:31.624954      12 flags.go:64] FLAG: --authorization-kubeconfig=""
I0506 15:10:31.624955      12 flags.go:64] FLAG: --authorization-webhook-cache-authorized-ttl="10s"
I0506 15:10:31.624956      12 flags.go:64] FLAG: --authorization-webhook-cache-unauthorized-ttl="10s"
I0506 15:10:31.624957      12 flags.go:64] FLAG: --bind-address="0.0.0.0"
I0506 15:10:31.624965      12 flags.go:64] FLAG: --cert-dir=""
I0506 15:10:31.624966      12 flags.go:64] FLAG: --client-ca-file=""
I0506 15:10:31.624967      12 flags.go:64] FLAG: --config="/etc/kube-scheduler/my-scheduler.yaml"
I0506 15:10:31.624974      12 flags.go:64] FLAG: --contention-profiling="true"
I0506 15:10:31.624975      12 flags.go:64] FLAG: --disable-http2-serving="false"
I0506 15:10:31.624976      12 flags.go:64] FLAG: --disabled-metrics="[]"
I0506 15:10:31.624979      12 flags.go:64] FLAG: --emulated-version="[]"
I0506 15:10:31.624981      12 flags.go:64] FLAG: --feature-gates=""
I0506 15:10:31.624983      12 flags.go:64] FLAG: --help="false"
I0506 15:10:31.624984      12 flags.go:64] FLAG: --http2-max-streams-per-connection="0"
I0506 15:10:31.624985      12 flags.go:64] FLAG: --kube-api-burst="100"
I0506 15:10:31.624987      12 flags.go:64] FLAG: --kube-api-content-type="application/vnd.kubernetes.protobuf"
I0506 15:10:31.624988      12 flags.go:64] FLAG: --kube-api-qps="50"
I0506 15:10:31.624991      12 flags.go:64] FLAG: --kubeconfig=""
I0506 15:10:31.624992      12 flags.go:64] FLAG: --leader-elect="true"
I0506 15:10:31.624992      12 flags.go:64] FLAG: --leader-elect-lease-duration="15s"
I0506 15:10:31.624993      12 flags.go:64] FLAG: --leader-elect-renew-deadline="10s"
I0506 15:10:31.624994      12 flags.go:64] FLAG: --leader-elect-resource-lock="leases"
I0506 15:10:31.624995      12 flags.go:64] FLAG: --leader-elect-resource-name="kube-scheduler"
I0506 15:10:31.624996      12 flags.go:64] FLAG: --leader-elect-resource-namespace="kube-system"
I0506 15:10:31.624997      12 flags.go:64] FLAG: --leader-elect-retry-period="2s"
I0506 15:10:31.624998      12 flags.go:64] FLAG: --log-flush-frequency="5s"
I0506 15:10:31.624999      12 flags.go:64] FLAG: --log-json-info-buffer-size="0"
I0506 15:10:31.625002      12 flags.go:64] FLAG: --log-json-split-stream="false"
I0506 15:10:31.625003      12 flags.go:64] FLAG: --log-text-info-buffer-size="0"
I0506 15:10:31.625004      12 flags.go:64] FLAG: --log-text-split-stream="false"
I0506 15:10:31.625005      12 flags.go:64] FLAG: --logging-format="text"
I0506 15:10:31.625006      12 flags.go:64] FLAG: --master=""
I0506 15:10:31.625007      12 flags.go:64] FLAG: --permit-address-sharing="false"
I0506 15:10:31.625011      12 flags.go:64] FLAG: --permit-port-sharing="false"
I0506 15:10:31.625012      12 flags.go:64] FLAG: --pod-max-in-unschedulable-pods-duration="5m0s"
I0506 15:10:31.625013      12 flags.go:64] FLAG: --profiling="true"
I0506 15:10:31.625014      12 flags.go:64] FLAG: --requestheader-allowed-names="[]"
I0506 15:10:31.625016      12 flags.go:64] FLAG: --requestheader-client-ca-file=""
I0506 15:10:31.625017      12 flags.go:64] FLAG: --requestheader-extra-headers-prefix="[x-remote-extra-]"
I0506 15:10:31.625024      12 flags.go:64] FLAG: --requestheader-group-headers="[x-remote-group]"
I0506 15:10:31.625027      12 flags.go:64] FLAG: --requestheader-uid-headers="[]"
I0506 15:10:31.625029      12 flags.go:64] FLAG: --requestheader-username-headers="[x-remote-user]"
I0506 15:10:31.625031      12 flags.go:64] FLAG: --secure-port="10260"
I0506 15:10:31.625032      12 flags.go:64] FLAG: --show-hidden-metrics-for-version=""
I0506 15:10:31.625033      12 flags.go:64] FLAG: --tls-cert-file=""
I0506 15:10:31.625034      12 flags.go:64] FLAG: --tls-cipher-suites="[]"
I0506 15:10:31.625036      12 flags.go:64] FLAG: --tls-min-version=""
I0506 15:10:31.625037      12 flags.go:64] FLAG: --tls-private-key-file=""
I0506 15:10:31.625038      12 flags.go:64] FLAG: --tls-sni-cert-key="[]"
I0506 15:10:31.625039      12 flags.go:64] FLAG: --v="2"
I0506 15:10:31.625041      12 flags.go:64] FLAG: --version="false"
I0506 15:10:31.625043      12 flags.go:64] FLAG: --vmodule=""
I0506 15:10:31.625044      12 flags.go:64] FLAG: --write-config-to=""
I0506 15:10:31.799311      12 serving.go:386] Generated self-signed cert in-memory
W0506 15:10:31.921657      12 authentication.go:368] No authentication-kubeconfig provided in order to lookup client-ca-file in configmap/extension-apiserver-authentication in kube-system, so client certificate authentication won't work.
W0506 15:10:31.921696      12 authentication.go:392] No authentication-kubeconfig provided in order to lookup requestheader-client-ca-file in configmap/extension-apiserver-authentication in kube-system, so request-header client certificate authentication won't work.
W0506 15:10:31.921709      12 authorization.go:193] No authorization-kubeconfig provided, so SubjectAccessReview of authorization tokens won't work.
I0506 15:10:31.924233      12 framework.go:399] "the scheduler starts to work with those plugins" Plugins={"PreEnqueue":{"Enabled":[{"Name":"SchedulingGates","Weight":0},{"Name":"DefaultPreemption","Weight":0}],"Disabled":null},"QueueSort":{"Enabled":[{"Name":"PrioritySort","Weight":0}],"Disabled":null},"PreFilter":{"Enabled":[{"Name":"NodeAffinity","Weight":0},{"Name":"NodePorts","Weight":0},{"Name":"NodeResourcesFit","Weight":0},{"Name":"VolumeRestrictions","Weight":0},{"Name":"NodeVolumeLimits","Weight":0},{"Name":"VolumeBinding","Weight":0},{"Name":"VolumeZone","Weight":0},{"Name":"PodTopologySpread","Weight":0},{"Name":"InterPodAffinity","Weight":0}],"Disabled":null},"Filter":{"Enabled":[{"Name":"NodeUnschedulable","Weight":0},{"Name":"NodeName","Weight":0},{"Name":"TaintToleration","Weight":0},{"Name":"NodeAffinity","Weight":0},{"Name":"NodePorts","Weight":0},{"Name":"NodeResourcesFit","Weight":0},{"Name":"VolumeRestrictions","Weight":0},{"Name":"NodeVolumeLimits","Weight":0},{"Name":"VolumeBinding","Weight":0},{"Name":"VolumeZone","Weight":0},{"Name":"PodTopologySpread","Weight":0},{"Name":"InterPodAffinity","Weight":0}],"Disabled":null},"PostFilter":{"Enabled":[{"Name":"DefaultPreemption","Weight":0}],"Disabled":null},"PreScore":{"Enabled":[{"Name":"TaintToleration","Weight":0},{"Name":"NodeAffinity","Weight":0},{"Name":"NodeResourcesFit","Weight":0},{"Name":"VolumeBinding","Weight":0},{"Name":"PodTopologySpread","Weight":0},{"Name":"InterPodAffinity","Weight":0},{"Name":"NodeResourcesBalancedAllocation","Weight":0}],"Disabled":null},"Score":{"Enabled":[{"Name":"NodeResourcesFit","Weight":1}],"Disabled":null},"Reserve":{"Enabled":[{"Name":"VolumeBinding","Weight":0}],"Disabled":null},"Permit":{"Enabled":null,"Disabled":null},"PreBind":{"Enabled":[{"Name":"VolumeBinding","Weight":0}],"Disabled":null},"Bind":{"Enabled":[{"Name":"DefaultBinder","Weight":0}],"Disabled":null},"PostBind":{"Enabled":null,"Disabled":null},"MultiPoint":{"Enabled":null,"Disabled":null}}
I0506 15:10:31.924433      12 framework.go:399] "the scheduler starts to work with those plugins" Plugins={"PreEnqueue":{"Enabled":[{"Name":"SchedulingGates","Weight":0},{"Name":"DefaultPreemption","Weight":0}],"Disabled":null},"QueueSort":{"Enabled":[{"Name":"PrioritySort","Weight":0}],"Disabled":null},"PreFilter":{"Enabled":[{"Name":"NodeAffinity","Weight":0},{"Name":"NodePorts","Weight":0},{"Name":"NodeResourcesFit","Weight":0},{"Name":"VolumeRestrictions","Weight":0},{"Name":"NodeVolumeLimits","Weight":0},{"Name":"VolumeBinding","Weight":0},{"Name":"VolumeZone","Weight":0},{"Name":"PodTopologySpread","Weight":0},{"Name":"InterPodAffinity","Weight":0}],"Disabled":null},"Filter":{"Enabled":[{"Name":"NodeUnschedulable","Weight":0},{"Name":"NodeName","Weight":0},{"Name":"TaintToleration","Weight":0},{"Name":"NodeAffinity","Weight":0},{"Name":"NodePorts","Weight":0},{"Name":"NodeResourcesFit","Weight":0},{"Name":"VolumeRestrictions","Weight":0},{"Name":"NodeVolumeLimits","Weight":0},{"Name":"VolumeBinding","Weight":0},{"Name":"VolumeZone","Weight":0},{"Name":"PodTopologySpread","Weight":0},{"Name":"InterPodAffinity","Weight":0}],"Disabled":null},"PostFilter":{"Enabled":[{"Name":"DefaultPreemption","Weight":0}],"Disabled":null},"PreScore":{"Enabled":[{"Name":"TaintToleration","Weight":0},{"Name":"NodeAffinity","Weight":0},{"Name":"NodeResourcesFit","Weight":0},{"Name":"VolumeBinding","Weight":0},{"Name":"PodTopologySpread","Weight":0},{"Name":"InterPodAffinity","Weight":0},{"Name":"NodeResourcesBalancedAllocation","Weight":0}],"Disabled":null},"Score":{"Enabled":[{"Name":"NodeResourcesFit","Weight":1}],"Disabled":null},"Reserve":{"Enabled":[{"Name":"VolumeBinding","Weight":0}],"Disabled":null},"Permit":{"Enabled":null,"Disabled":null},"PreBind":{"Enabled":[{"Name":"VolumeBinding","Weight":0}],"Disabled":null},"Bind":{"Enabled":[{"Name":"DefaultBinder","Weight":0}],"Disabled":null},"PostBind":{"Enabled":null,"Disabled":null},"MultiPoint":{"Enabled":null,"Disabled":null}}
I0506 15:10:31.927506      12 configfile.go:94] "Using component config" config=<
	apiVersion: kubescheduler.config.k8s.io/v1
	clientConnection:
	  acceptContentTypes: ""
	  burst: 100
	  contentType: application/vnd.kubernetes.protobuf
	  kubeconfig: /etc/kube-scheduler/kubeconfig.yaml
	  qps: 50
	enableContentionProfiling: true
	enableProfiling: true
	kind: KubeSchedulerConfiguration
	leaderElection:
	  leaderElect: false
	  leaseDuration: 15s
	  renewDeadline: 10s
	  resourceLock: leases
	  resourceName: kube-scheduler
	  resourceNamespace: kube-system
	  retryPeriod: 2s
	parallelism: 16
	percentageOfNodesToScore: 0
	podInitialBackoffSeconds: 1
	podMaxBackoffSeconds: 10
	profiles:
	- pluginConfig:
	  - args:
	      apiVersion: kubescheduler.config.k8s.io/v1
	      kind: DefaultPreemptionArgs
	      minCandidateNodesAbsolute: 100
	      minCandidateNodesPercentage: 10
	    name: DefaultPreemption
	  - args:
	      apiVersion: kubescheduler.config.k8s.io/v1
	      hardPodAffinityWeight: 1
	      ignorePreferredTermsOfExistingPods: false
	      kind: InterPodAffinityArgs
	    name: InterPodAffinity
	  - args:
	      apiVersion: kubescheduler.config.k8s.io/v1
	      kind: NodeAffinityArgs
	    name: NodeAffinity
	  - args:
	      apiVersion: kubescheduler.config.k8s.io/v1
	      kind: NodeResourcesBalancedAllocationArgs
	      resources:
	      - name: cpu
	        weight: 1
	      - name: memory
	        weight: 1
	    name: NodeResourcesBalancedAllocation
	  - args:
	      apiVersion: kubescheduler.config.k8s.io/v1
	      kind: NodeResourcesFitArgs
	      scoringStrategy:
	        resources:
	        - name: cpu
	          weight: 1
	        - name: memory
	          weight: 1
	        type: LeastAllocated
	    name: NodeResourcesFit
	  - args:
	      apiVersion: kubescheduler.config.k8s.io/v1
	      defaultingType: System
	      kind: PodTopologySpreadArgs
	    name: PodTopologySpread
	  - args:
	      apiVersion: kubescheduler.config.k8s.io/v1
	      bindTimeoutSeconds: 600
	      kind: VolumeBindingArgs
	    name: VolumeBinding
	  plugins:
	    bind: {}
	    filter: {}
	    multiPoint:
	      enabled:
	      - name: SchedulingGates
	        weight: 0
	      - name: PrioritySort
	        weight: 0
	      - name: NodeUnschedulable
	        weight: 0
	      - name: NodeName
	        weight: 0
	      - name: TaintToleration
	        weight: 3
	      - name: NodeAffinity
	        weight: 2
	      - name: NodePorts
	        weight: 0
	      - name: NodeResourcesFit
	        weight: 1
	      - name: VolumeRestrictions
	        weight: 0
	      - name: NodeVolumeLimits
	        weight: 0
	      - name: VolumeBinding
	        weight: 0
	      - name: VolumeZone
	        weight: 0
	      - name: PodTopologySpread
	        weight: 2
	      - name: InterPodAffinity
	        weight: 2
	      - name: DefaultPreemption
	        weight: 0
	      - name: NodeResourcesBalancedAllocation
	        weight: 1
	      - name: ImageLocality
	        weight: 1
	      - name: DefaultBinder
	        weight: 0
	    permit: {}
	    postBind: {}
	    postFilter: {}
	    preBind: {}
	    preEnqueue: {}
	    preFilter: {}
	    preScore: {}
	    queueSort: {}
	    reserve: {}
	    score:
	      disabled:
	      - name: '*'
	        weight: 0
	      enabled:
	      - name: NodeResourcesFit
	        weight: 0
	  schedulerName: default-scheduler
	- pluginConfig:
	  - args:
	      apiVersion: kubescheduler.config.k8s.io/v1
	      kind: DefaultPreemptionArgs
	      minCandidateNodesAbsolute: 100
	      minCandidateNodesPercentage: 10
	    name: DefaultPreemption
	  - args:
	      apiVersion: kubescheduler.config.k8s.io/v1
	      hardPodAffinityWeight: 1
	      ignorePreferredTermsOfExistingPods: false
	      kind: InterPodAffinityArgs
	    name: InterPodAffinity
	  - args:
	      apiVersion: kubescheduler.config.k8s.io/v1
	      kind: NodeAffinityArgs
	    name: NodeAffinity
	  - args:
	      apiVersion: kubescheduler.config.k8s.io/v1
	      kind: NodeResourcesBalancedAllocationArgs
	      resources:
	      - name: cpu
	        weight: 1
	      - name: memory
	        weight: 1
	    name: NodeResourcesBalancedAllocation
	  - args:
	      apiVersion: kubescheduler.config.k8s.io/v1
	      kind: NodeResourcesFitArgs
	      scoringStrategy:
	        resources:
	        - name: cpu
	          weight: 1
	        - name: memory
	          weight: 1
	        type: MostAllocated
	    name: NodeResourcesFit
	  - args:
	      apiVersion: kubescheduler.config.k8s.io/v1
	      defaultingType: System
	      kind: PodTopologySpreadArgs
	    name: PodTopologySpread
	  - args:
	      apiVersion: kubescheduler.config.k8s.io/v1
	      bindTimeoutSeconds: 600
	      kind: VolumeBindingArgs
	    name: VolumeBinding
	  plugins:
	    bind: {}
	    filter: {}
	    multiPoint:
	      enabled:
	      - name: SchedulingGates
	        weight: 0
	      - name: PrioritySort
	        weight: 0
	      - name: NodeUnschedulable
	        weight: 0
	      - name: NodeName
	        weight: 0
	      - name: TaintToleration
	        weight: 3
	      - name: NodeAffinity
	        weight: 2
	      - name: NodePorts
	        weight: 0
	      - name: NodeResourcesFit
	        weight: 1
	      - name: VolumeRestrictions
	        weight: 0
	      - name: NodeVolumeLimits
	        weight: 0
	      - name: VolumeBinding
	        weight: 0
	      - name: VolumeZone
	        weight: 0
	      - name: PodTopologySpread
	        weight: 2
	      - name: InterPodAffinity
	        weight: 2
	      - name: DefaultPreemption
	        weight: 0
	      - name: NodeResourcesBalancedAllocation
	        weight: 1
	      - name: ImageLocality
	        weight: 1
	      - name: DefaultBinder
	        weight: 0
	    permit: {}
	    postBind: {}
	    postFilter: {}
	    preBind: {}
	    preEnqueue: {}
	    preFilter: {}
	    preScore: {}
	    queueSort: {}
	    reserve: {}
	    score:
	      disabled:
	      - name: '*'
	        weight: 0
	      enabled:
	      - name: NodeResourcesFit
	        weight: 0
	  schedulerName: my-scheduler
 >
I0506 15:10:31.928067      12 server.go:171] "Starting Kubernetes Scheduler" version="v1.33.0"
I0506 15:10:31.928094      12 server.go:173] "Golang settings" GOGC="" GOMAXPROCS="" GOTRACEBACK=""
I0506 15:10:31.929188      12 tlsconfig.go:203] "Loaded serving cert" certName="Generated self signed cert" certDetail="\"localhost@1778080231\" [serving] validServingFor=[127.0.0.1,localhost,localhost] issuer=\"localhost-ca@1778080231\" (2026-05-06 14:10:31 +0000 UTC to 2027-05-06 14:10:31 +0000 UTC (now=2026-05-06 15:10:31.929176398 +0000 UTC))"
I0506 15:10:31.929305      12 named_certificates.go:53] "Loaded SNI cert" index=0 certName="self-signed loopback" certDetail="\"apiserver-loopback-client@1778080231\" [serving] validServingFor=[apiserver-loopback-client] issuer=\"apiserver-loopback-client-ca@1778080231\" (2026-05-06 14:10:31 +0000 UTC to 2029-05-06 14:10:31 +0000 UTC (now=2026-05-06 15:10:31.929294185 +0000 UTC))"
I0506 15:10:31.929366      12 secure_serving.go:211] Serving securely on [::]:10260
I0506 15:10:31.929506      12 tlsconfig.go:243] "Starting DynamicServingCertificateController"
I0506 15:10:31.931710      12 reflector.go:430] "Caches populated" type="*v1.CSINode" reflector="k8s.io/client-go/informers/factory.go:160"
I0506 15:10:31.931849      12 reflector.go:430] "Caches populated" type="*v1.StorageClass" reflector="k8s.io/client-go/informers/factory.go:160"
I0506 15:10:31.931898      12 reflector.go:430] "Caches populated" type="*v1.Node" reflector="k8s.io/client-go/informers/factory.go:160"
I0506 15:10:31.931946      12 reflector.go:430] "Caches populated" type="*v1.CSIDriver" reflector="k8s.io/client-go/informers/factory.go:160"
I0506 15:10:31.931987      12 reflector.go:430] "Caches populated" type="*v1.ReplicaSet" reflector="k8s.io/client-go/informers/factory.go:160"
I0506 15:10:31.932021      12 reflector.go:430] "Caches populated" type="*v1.Namespace" reflector="k8s.io/client-go/informers/factory.go:160"
I0506 15:10:31.933826      12 reflector.go:430] "Caches populated" type="*v1.CSIStorageCapacity" reflector="k8s.io/client-go/informers/factory.go:160"
I0506 15:10:31.933848      12 reflector.go:430] "Caches populated" type="*v1.VolumeAttachment" reflector="k8s.io/client-go/informers/factory.go:160"
I0506 15:10:31.933868      12 reflector.go:430] "Caches populated" type="*v1.PodDisruptionBudget" reflector="k8s.io/client-go/informers/factory.go:160"
I0506 15:10:31.933955      12 reflector.go:430] "Caches populated" type="*v1.PersistentVolumeClaim" reflector="k8s.io/client-go/informers/factory.go:160"
I0506 15:10:31.933981      12 reflector.go:430] "Caches populated" type="*v1.PersistentVolume" reflector="k8s.io/client-go/informers/factory.go:160"
I0506 15:10:31.933831      12 reflector.go:430] "Caches populated" type="*v1.Service" reflector="k8s.io/client-go/informers/factory.go:160"
I0506 15:10:31.934115      12 reflector.go:430] "Caches populated" type="*v1.ReplicationController" reflector="k8s.io/client-go/informers/factory.go:160"
I0506 15:10:31.934236      12 reflector.go:430] "Caches populated" type="*v1.StatefulSet" reflector="k8s.io/client-go/informers/factory.go:160"
I0506 15:10:31.934359      12 reflector.go:430] "Caches populated" type="*v1.Pod" reflector="k8s.io/client-go/informers/factory.go:160"
I0506 15:10:38.877424      12 node_tree.go:65] "Added node to NodeTree" node="csnode-0" zone=""
I0506 15:10:38.877471      12 node_tree.go:65] "Added node to NodeTree" node="csnode-1" zone=""
I0506 15:10:38.877482      12 node_tree.go:65] "Added node to NodeTree" node="csnode-2" zone=""
I0506 15:10:38.877489      12 node_tree.go:65] "Added node to NodeTree" node="csnode-3" zone=""
I0506 15:10:38.877510      12 node_tree.go:65] "Added node to NodeTree" node="csnode-4" zone=""
I0506 15:10:38.906691      12 schedule_one.go:314] "Successfully bound pod to node" pod="default/cspod-1" node="csnode-0" evaluatedNodes=5 feasibleNodes=5
I0506 15:10:38.906735      12 schedule_one.go:314] "Successfully bound pod to node" pod="default/cspod-3" node="csnode-3" evaluatedNodes=5 feasibleNodes=5
I0506 15:10:38.906742      12 schedule_one.go:314] "Successfully bound pod to node" pod="default/cspod-2" node="csnode-2" evaluatedNodes=5 feasibleNodes=5
I0506 15:10:38.906771      12 schedule_one.go:314] "Successfully bound pod to node" pod="default/cspod-0" node="csnode-4" evaluatedNodes=5 feasibleNodes=5
I0506 15:10:38.906830      12 schedule_one.go:314] "Successfully bound pod to node" pod="default/cspod-4" node="csnode-1" evaluatedNodes=5 feasibleNodes=5
I0506 15:10:38.906943      12 schedule_one.go:314] "Successfully bound pod to node" pod="default/cspod-6" node="csnode-4" evaluatedNodes=5 feasibleNodes=5
E0506 15:10:38.906922      12 event.go:368] "Unable to write event (may retry after sleeping)" err="0-length response with status code: 201 and content type: application/vnd.kubernetes.protobuf" event="&Event{ObjectMeta:{cspod-1.18ad028e7e2c5395  default    0 0001-01-01 00:00:00 +0000 UTC <nil> <nil> map[] map[] [] [] []},InvolvedObject:ObjectReference{Kind:Pod,Namespace:default,Name:cspod-1,UID:cspod-1-uid,APIVersion:v1,ResourceVersion:7,FieldPath:,},Reason:Scheduled,Message:Successfully assigned default/cspod-1 to csnode-0,Source:EventSource{Component:default-scheduler,Host:,},FirstTimestamp:2026-05-06 15:10:38.906659733 +0000 UTC m=+7.311898370,LastTimestamp:2026-05-06 15:10:38.906659733 +0000 UTC m=+7.311898370,Count:1,Type:Normal,EventTime:0001-01-01 00:00:00 +0000 UTC,Series:nil,Action:,Related:nil,ReportingController:default-scheduler,ReportingInstance:,}"
I0506 15:10:38.907323      12 schedule_one.go:314] "Successfully bound pod to node" pod="default/cspod-5" node="csnode-4" evaluatedNodes=5 feasibleNodes=5
I0506 15:10:38.907585      12 schedule_one.go:314] "Successfully bound pod to node" pod="default/cspod-7" node="csnode-2" evaluatedNodes=5 feasibleNodes=5
I0506 15:10:38.907625      12 schedule_one.go:314] "Successfully bound pod to node" pod="default/cspod-8" node="csnode-3" evaluatedNodes=5 feasibleNodes=4
I0506 15:10:38.908565      12 schedule_one.go:314] "Successfully bound pod to node" pod="default/cspod-9" node="csnode-1" evaluatedNodes=5 feasibleNodes=3
I0506 15:10:38.908633      12 preemption.go:264] "No preemption candidate is found; preemption is not helpful for scheduling" pod="default/cspod-12"
I0506 15:10:38.908666      12 schedule_one.go:1044] "Unable to schedule pod; no fit; waiting" pod="default/cspod-12" err="0/5 nodes are available: 5 Insufficient cpu. preemption: 0/5 nodes are available: 5 No preemption victims found for incoming pod."
I0506 15:10:38.908856      12 schedule_one.go:314] "Successfully bound pod to node" pod="default/cspod-10" node="csnode-0" evaluatedNodes=5 feasibleNodes=2
I0506 15:10:38.908918      12 schedule_one.go:314] "Successfully bound pod to node" pod="default/cspod-11" node="csnode-4" evaluatedNodes=5 feasibleNodes=1
I0506 15:10:38.909834      12 preemption.go:264] "No preemption candidate is found; preemption is not helpful for scheduling" pod="default/cspod-13"
I0506 15:10:38.909872      12 schedule_one.go:1044] "Unable to schedule pod; no fit; waiting" pod="default/cspod-13" err="0/5 nodes are available: 5 Insufficient cpu. preemption: 0/5 nodes are available: 5 No preemption victims found for incoming pod."
I0506 15:10:38.910386      12 preemption.go:264] "No preemption candidate is found; preemption is not helpful for scheduling" pod="default/cspod-14"
I0506 15:10:38.910419      12 schedule_one.go:1044] "Unable to schedule pod; no fit; waiting" pod="default/cspod-14" err="0/5 nodes are available: 5 Insufficient cpu. preemption: 0/5 nodes are available: 5 No preemption victims found for incoming pod."
I0506 15:10:38.911010      12 preemption.go:264] "No preemption candidate is found; preemption is not helpful for scheduling" pod="default/cspod-15"
I0506 15:10:38.911045      12 schedule_one.go:1044] "Unable to schedule pod; no fit; waiting" pod="default/cspod-15" err="0/5 nodes are available: 5 Insufficient cpu. preemption: 0/5 nodes are available: 5 No preemption victims found for incoming pod."
I0506 15:10:38.911649      12 preemption.go:264] "No preemption candidate is found; preemption is not helpful for scheduling" pod="default/cspod-16"
I0506 15:10:38.911683      12 schedule_one.go:1044] "Unable to schedule pod; no fit; waiting" pod="default/cspod-16" err="0/5 nodes are available: 5 Insufficient cpu. preemption: 0/5 nodes are available: 5 No preemption victims found for incoming pod."
I0506 15:10:38.912187      12 preemption.go:264] "No preemption candidate is found; preemption is not helpful for scheduling" pod="default/cspod-17"
I0506 15:10:38.912220      12 schedule_one.go:1044] "Unable to schedule pod; no fit; waiting" pod="default/cspod-17" err="0/5 nodes are available: 5 Insufficient cpu. preemption: 0/5 nodes are available: 5 No preemption victims found for incoming pod."
I0506 15:10:38.912830      12 preemption.go:264] "No preemption candidate is found; preemption is not helpful for scheduling" pod="default/cspod-18"
I0506 15:10:38.912865      12 schedule_one.go:1044] "Unable to schedule pod; no fit; waiting" pod="default/cspod-18" err="0/5 nodes are available: 5 Insufficient cpu. preemption: 0/5 nodes are available: 5 No preemption victims found for incoming pod."
I0506 15:10:38.913414      12 preemption.go:264] "No preemption candidate is found; preemption is not helpful for scheduling" pod="default/cspod-19"
I0506 15:10:38.913448      12 schedule_one.go:1044] "Unable to schedule pod; no fit; waiting" pod="default/cspod-19" err="0/5 nodes are available: 5 Insufficient cpu. preemption: 0/5 nodes are available: 5 No preemption victims found for incoming pod."
I0506 15:10:38.913957      12 preemption.go:264] "No preemption candidate is found; preemption is not helpful for scheduling" pod="default/cspod-20"
I0506 15:10:38.913991      12 schedule_one.go:1044] "Unable to schedule pod; no fit; waiting" pod="default/cspod-20" err="0/5 nodes are available: 5 Insufficient cpu. preemption: 0/5 nodes are available: 5 No preemption victims found for incoming pod."
I0506 15:10:38.914473      12 preemption.go:264] "No preemption candidate is found; preemption is not helpful for scheduling" pod="default/cspod-21"
I0506 15:10:38.914506      12 schedule_one.go:1044] "Unable to schedule pod; no fit; waiting" pod="default/cspod-21" err="0/5 nodes are available: 5 Insufficient cpu. preemption: 0/5 nodes are available: 5 No preemption victims found for incoming pod."
I0506 15:10:38.915021      12 preemption.go:264] "No preemption candidate is found; preemption is not helpful for scheduling" pod="default/cspod-22"
I0506 15:10:38.915055      12 schedule_one.go:1044] "Unable to schedule pod; no fit; waiting" pod="default/cspod-22" err="0/5 nodes are available: 5 Insufficient cpu. preemption: 0/5 nodes are available: 5 No preemption victims found for incoming pod."
I0506 15:10:38.915522      12 preemption.go:264] "No preemption candidate is found; preemption is not helpful for scheduling" pod="default/cspod-23"
I0506 15:10:38.915561      12 schedule_one.go:1044] "Unable to schedule pod; no fit; waiting" pod="default/cspod-23" err="0/5 nodes are available: 5 Insufficient cpu. preemption: 0/5 nodes are available: 5 No preemption victims found for incoming pod."
I0506 15:10:38.916059      12 preemption.go:264] "No preemption candidate is found; preemption is not helpful for scheduling" pod="default/cspod-24"
I0506 15:10:38.916096      12 schedule_one.go:1044] "Unable to schedule pod; no fit; waiting" pod="default/cspod-24" err="0/5 nodes are available: 5 Insufficient cpu. preemption: 0/5 nodes are available: 5 No preemption victims found for incoming pod."
I0506 15:10:38.916652      12 preemption.go:264] "No preemption candidate is found; preemption is not helpful for scheduling" pod="default/cspod-25"
I0506 15:10:38.916684      12 schedule_one.go:1044] "Unable to schedule pod; no fit; waiting" pod="default/cspod-25" err="0/5 nodes are available: 5 Insufficient cpu. preemption: 0/5 nodes are available: 5 No preemption victims found for incoming pod."
I0506 15:10:38.917299      12 preemption.go:264] "No preemption candidate is found; preemption is not helpful for scheduling" pod="default/cspod-26"
I0506 15:10:38.917334      12 schedule_one.go:1044] "Unable to schedule pod; no fit; waiting" pod="default/cspod-26" err="0/5 nodes are available: 5 Insufficient cpu. preemption: 0/5 nodes are available: 5 No preemption victims found for incoming pod."
I0506 15:10:38.917921      12 preemption.go:264] "No preemption candidate is found; preemption is not helpful for scheduling" pod="default/cspod-27"
I0506 15:10:38.917957      12 schedule_one.go:1044] "Unable to schedule pod; no fit; waiting" pod="default/cspod-27" err="0/5 nodes are available: 5 Insufficient cpu. preemption: 0/5 nodes are available: 5 No preemption victims found for incoming pod."
I0506 15:10:38.918442      12 preemption.go:264] "No preemption candidate is found; preemption is not helpful for scheduling" pod="default/cspod-28"
I0506 15:10:38.918474      12 schedule_one.go:1044] "Unable to schedule pod; no fit; waiting" pod="default/cspod-28" err="0/5 nodes are available: 5 Insufficient cpu. preemption: 0/5 nodes are available: 5 No preemption victims found for incoming pod."
I0506 15:10:38.919050      12 preemption.go:264] "No preemption candidate is found; preemption is not helpful for scheduling" pod="default/cspod-29"
I0506 15:10:38.919085      12 schedule_one.go:1044] "Unable to schedule pod; no fit; waiting" pod="default/cspod-29" err="0/5 nodes are available: 5 Insufficient cpu. preemption: 0/5 nodes are available: 5 No preemption victims found for incoming pod."
I0506 15:10:38.919742      12 preemption.go:264] "No preemption candidate is found; preemption is not helpful for scheduling" pod="default/cspod-30"
I0506 15:10:38.919778      12 schedule_one.go:1044] "Unable to schedule pod; no fit; waiting" pod="default/cspod-30" err="0/5 nodes are available: 5 Insufficient cpu. preemption: 0/5 nodes are available: 5 No preemption victims found for incoming pod."
I0506 15:10:38.920268      12 preemption.go:264] "No preemption candidate is found; preemption is not helpful for scheduling" pod="default/cspod-31"
I0506 15:10:38.920294      12 schedule_one.go:1044] "Unable to schedule pod; no fit; waiting" pod="default/cspod-31" err="0/5 nodes are available: 5 Insufficient cpu. preemption: 0/5 nodes are available: 5 No preemption victims found for incoming pod."
I0506 15:10:38.920821      12 preemption.go:264] "No preemption candidate is found; preemption is not helpful for scheduling" pod="default/cspod-32"
I0506 15:10:38.920856      12 schedule_one.go:1044] "Unable to schedule pod; no fit; waiting" pod="default/cspod-32" err="0/5 nodes are available: 5 Insufficient cpu. preemption: 0/5 nodes are available: 5 No preemption victims found for incoming pod."
I0506 15:10:38.921364      12 preemption.go:264] "No preemption candidate is found; preemption is not helpful for scheduling" pod="default/cspod-33"
I0506 15:10:38.921396      12 schedule_one.go:1044] "Unable to schedule pod; no fit; waiting" pod="default/cspod-33" err="0/5 nodes are available: 5 Insufficient cpu. preemption: 0/5 nodes are available: 5 No preemption victims found for incoming pod."
I0506 15:10:38.921837      12 preemption.go:264] "No preemption candidate is found; preemption is not helpful for scheduling" pod="default/cspod-34"
I0506 15:10:38.921869      12 schedule_one.go:1044] "Unable to schedule pod; no fit; waiting" pod="default/cspod-34" err="0/5 nodes are available: 5 Insufficient cpu. preemption: 0/5 nodes are available: 5 No preemption victims found for incoming pod."
I0506 15:10:38.922365      12 preemption.go:264] "No preemption candidate is found; preemption is not helpful for scheduling" pod="default/cspod-35"
I0506 15:10:38.922401      12 schedule_one.go:1044] "Unable to schedule pod; no fit; waiting" pod="default/cspod-35" err="0/5 nodes are available: 5 Insufficient cpu. preemption: 0/5 nodes are available: 5 No preemption victims found for incoming pod."
I0506 15:10:38.922904      12 preemption.go:264] "No preemption candidate is found; preemption is not helpful for scheduling" pod="default/cspod-36"
I0506 15:10:38.922937      12 schedule_one.go:1044] "Unable to schedule pod; no fit; waiting" pod="default/cspod-36" err="0/5 nodes are available: 5 Insufficient cpu. preemption: 0/5 nodes are available: 5 No preemption victims found for incoming pod."
I0506 15:10:39.020550      12 preemption.go:264] "No preemption candidate is found; preemption is not helpful for scheduling" pod="default/cspod-37"
I0506 15:10:39.020599      12 schedule_one.go:1044] "Unable to schedule pod; no fit; waiting" pod="default/cspod-37" err="0/5 nodes are available: 5 Insufficient cpu. preemption: 0/5 nodes are available: 5 No preemption victims found for incoming pod."
I0506 15:10:39.021293      12 preemption.go:264] "No preemption candidate is found; preemption is not helpful for scheduling" pod="default/cspod-38"
I0506 15:10:39.021346      12 schedule_one.go:1044] "Unable to schedule pod; no fit; waiting" pod="default/cspod-38" err="0/5 nodes are available: 5 Insufficient cpu. preemption: 0/5 nodes are available: 5 No preemption victims found for incoming pod."
I0506 15:10:39.022402      12 preemption.go:264] "No preemption candidate is found; preemption is not helpful for scheduling" pod="default/cspod-39"
I0506 15:10:39.022455      12 schedule_one.go:1044] "Unable to schedule pod; no fit; waiting" pod="default/cspod-39" err="0/5 nodes are available: 5 Insufficient cpu. preemption: 0/5 nodes are available: 5 No preemption victims found for incoming pod."
I0506 15:10:39.023122      12 preemption.go:264] "No preemption candidate is found; preemption is not helpful for scheduling" pod="default/cspod-40"
I0506 15:10:39.023163      12 schedule_one.go:1044] "Unable to schedule pod; no fit; waiting" pod="default/cspod-40" err="0/5 nodes are available: 5 Insufficient cpu. preemption: 0/5 nodes are available: 5 No preemption victims found for incoming pod."
I0506 15:10:39.023841      12 preemption.go:264] "No preemption candidate is found; preemption is not helpful for scheduling" pod="default/cspod-41"
I0506 15:10:39.023880      12 schedule_one.go:1044] "Unable to schedule pod; no fit; waiting" pod="default/cspod-41" err="0/5 nodes are available: 5 Insufficient cpu. preemption: 0/5 nodes are available: 5 No preemption victims found for incoming pod."
I0506 15:10:39.024492      12 preemption.go:264] "No preemption candidate is found; preemption is not helpful for scheduling" pod="default/cspod-42"
I0506 15:10:39.024534      12 schedule_one.go:1044] "Unable to schedule pod; no fit; waiting" pod="default/cspod-42" err="0/5 nodes are available: 5 Insufficient cpu. preemption: 0/5 nodes are available: 5 No preemption victims found for incoming pod."
I0506 15:10:39.025039      12 preemption.go:264] "No preemption candidate is found; preemption is not helpful for scheduling" pod="default/cspod-43"
I0506 15:10:39.025068      12 schedule_one.go:1044] "Unable to schedule pod; no fit; waiting" pod="default/cspod-43" err="0/5 nodes are available: 5 Insufficient cpu. preemption: 0/5 nodes are available: 5 No preemption victims found for incoming pod."
I0506 15:10:39.025533      12 preemption.go:264] "No preemption candidate is found; preemption is not helpful for scheduling" pod="default/cspod-44"
I0506 15:10:39.025566      12 schedule_one.go:1044] "Unable to schedule pod; no fit; waiting" pod="default/cspod-44" err="0/5 nodes are available: 5 Insufficient cpu. preemption: 0/5 nodes are available: 5 No preemption victims found for incoming pod."
I0506 15:10:39.026061      12 preemption.go:264] "No preemption candidate is found; preemption is not helpful for scheduling" pod="default/cspod-45"
I0506 15:10:39.026093      12 schedule_one.go:1044] "Unable to schedule pod; no fit; waiting" pod="default/cspod-45" err="0/5 nodes are available: 5 Insufficient cpu. preemption: 0/5 nodes are available: 5 No preemption victims found for incoming pod."
I0506 15:10:39.026671      12 preemption.go:264] "No preemption candidate is found; preemption is not helpful for scheduling" pod="default/cspod-46"
I0506 15:10:39.026707      12 schedule_one.go:1044] "Unable to schedule pod; no fit; waiting" pod="default/cspod-46" err="0/5 nodes are available: 5 Insufficient cpu. preemption: 0/5 nodes are available: 5 No preemption victims found for incoming pod."
I0506 15:10:39.027390      12 preemption.go:264] "No preemption candidate is found; preemption is not helpful for scheduling" pod="default/cspod-47"
I0506 15:10:39.027426      12 schedule_one.go:1044] "Unable to schedule pod; no fit; waiting" pod="default/cspod-47" err="0/5 nodes are available: 5 Insufficient cpu. preemption: 0/5 nodes are available: 5 No preemption victims found for incoming pod."
I0506 15:10:39.027930      12 preemption.go:264] "No preemption candidate is found; preemption is not helpful for scheduling" pod="default/cspod-48"
I0506 15:10:39.027965      12 schedule_one.go:1044] "Unable to schedule pod; no fit; waiting" pod="default/cspod-48" err="0/5 nodes are available: 5 Insufficient cpu. preemption: 0/5 nodes are available: 5 No preemption victims found for incoming pod."
I0506 15:10:39.028529      12 preemption.go:264] "No preemption candidate is found; preemption is not helpful for scheduling" pod="default/cspod-49"
I0506 15:10:39.028564      12 schedule_one.go:1044] "Unable to schedule pod; no fit; waiting" pod="default/cspod-49" err="0/5 nodes are available: 5 Insufficient cpu. preemption: 0/5 nodes are available: 5 No preemption victims found for incoming pod."
I0506 15:10:39.029060      12 preemption.go:264] "No preemption candidate is found; preemption is not helpful for scheduling" pod="default/cspod-50"
I0506 15:10:39.029093      12 schedule_one.go:1044] "Unable to schedule pod; no fit; waiting" pod="default/cspod-50" err="0/5 nodes are available: 5 Insufficient cpu. preemption: 0/5 nodes are available: 5 No preemption victims found for incoming pod."
I0506 15:10:39.029657      12 preemption.go:264] "No preemption candidate is found; preemption is not helpful for scheduling" pod="default/cspod-51"
I0506 15:10:39.029692      12 schedule_one.go:1044] "Unable to schedule pod; no fit; waiting" pod="default/cspod-51" err="0/5 nodes are available: 5 Insufficient cpu. preemption: 0/5 nodes are available: 5 No preemption victims found for incoming pod."
I0506 15:10:39.030173      12 preemption.go:264] "No preemption candidate is found; preemption is not helpful for scheduling" pod="default/cspod-52"
I0506 15:10:39.030189      12 schedule_one.go:1044] "Unable to schedule pod; no fit; waiting" pod="default/cspod-52" err="0/5 nodes are available: 5 Insufficient cpu. preemption: 0/5 nodes are available: 5 No preemption victims found for incoming pod."
I0506 15:10:39.030667      12 preemption.go:264] "No preemption candidate is found; preemption is not helpful for scheduling" pod="default/cspod-53"
I0506 15:10:39.030700      12 schedule_one.go:1044] "Unable to schedule pod; no fit; waiting" pod="default/cspod-53" err="0/5 nodes are available: 5 Insufficient cpu. preemption: 0/5 nodes are available: 5 No preemption victims found for incoming pod."
I0506 15:10:39.031198      12 preemption.go:264] "No preemption candidate is found; preemption is not helpful for scheduling" pod="default/cspod-54"
I0506 15:10:39.031233      12 schedule_one.go:1044] "Unable to schedule pod; no fit; waiting" pod="default/cspod-54" err="0/5 nodes are available: 5 Insufficient cpu. preemption: 0/5 nodes are available: 5 No preemption victims found for incoming pod."
I0506 15:10:39.054211      12 schedule_one.go:314] "Successfully bound pod to node" pod="default/cspod-12" node="csnode-4" evaluatedNodes=5 feasibleNodes=1
I0506 15:10:39.054356      12 schedule_one.go:314] "Successfully bound pod to node" pod="default/cspod-13" node="csnode-4" evaluatedNodes=5 feasibleNodes=1
I0506 15:10:39.054649      12 preemption.go:264] "No preemption candidate is found; preemption is not helpful for scheduling" pod="default/cspod-16"
I0506 15:10:39.054694      12 schedule_one.go:1044] "Unable to schedule pod; no fit; waiting" pod="default/cspod-16" err="0/5 nodes are available: 5 Insufficient cpu. preemption: 0/5 nodes are available: 5 No preemption victims found for incoming pod."
I0506 15:10:39.054748      12 schedule_one.go:314] "Successfully bound pod to node" pod="default/cspod-14" node="csnode-4" evaluatedNodes=5 feasibleNodes=1
I0506 15:10:39.054763      12 schedule_one.go:314] "Successfully bound pod to node" pod="default/cspod-15" node="csnode-4" evaluatedNodes=5 feasibleNodes=1
I0506 15:10:39.056328      12 preemption.go:264] "No preemption candidate is found; preemption is not helpful for scheduling" pod="default/cspod-17"
I0506 15:10:39.056370      12 schedule_one.go:1044] "Unable to schedule pod; no fit; waiting" pod="default/cspod-17" err="0/5 nodes are available: 5 Insufficient cpu. preemption: 0/5 nodes are available: 5 No preemption victims found for incoming pod."
I0506 15:10:39.057050      12 preemption.go:264] "No preemption candidate is found; preemption is not helpful for scheduling" pod="default/cspod-18"
I0506 15:10:39.057090      12 schedule_one.go:1044] "Unable to schedule pod; no fit; waiting" pod="default/cspod-18" err="0/5 nodes are available: 5 Insufficient cpu. preemption: 0/5 nodes are available: 5 No preemption victims found for incoming pod."
I0506 15:10:39.057633      12 preemption.go:264] "No preemption candidate is found; preemption is not helpful for scheduling" pod="default/cspod-19"
I0506 15:10:39.057669      12 schedule_one.go:1044] "Unable to schedule pod; no fit; waiting" pod="default/cspod-19" err="0/5 nodes are available: 5 Insufficient cpu. preemption: 0/5 nodes are available: 5 No preemption victims found for incoming pod."
I0506 15:10:39.058234      12 preemption.go:264] "No preemption candidate is found; preemption is not helpful for scheduling" pod="default/cspod-20"
I0506 15:10:39.058267      12 schedule_one.go:1044] "Unable to schedule pod; no fit; waiting" pod="default/cspod-20" err="0/5 nodes are available: 5 Insufficient cpu. preemption: 0/5 nodes are available: 5 No preemption victims found for incoming pod."
I0506 15:10:39.058928      12 preemption.go:264] "No preemption candidate is found; preemption is not helpful for scheduling" pod="default/cspod-21"
I0506 15:10:39.058967      12 schedule_one.go:1044] "Unable to schedule pod; no fit; waiting" pod="default/cspod-21" err="0/5 nodes are available: 5 Insufficient cpu. preemption: 0/5 nodes are available: 5 No preemption victims found for incoming pod."
I0506 15:10:39.059539      12 preemption.go:264] "No preemption candidate is found; preemption is not helpful for scheduling" pod="default/cspod-22"
I0506 15:10:39.059572      12 schedule_one.go:1044] "Unable to schedule pod; no fit; waiting" pod="default/cspod-22" err="0/5 nodes are available: 5 Insufficient cpu. preemption: 0/5 nodes are available: 5 No preemption victims found for incoming pod."
I0506 15:10:39.060238      12 preemption.go:264] "No preemption candidate is found; preemption is not helpful for scheduling" pod="default/cspod-23"
I0506 15:10:39.060272      12 schedule_one.go:1044] "Unable to schedule pod; no fit; waiting" pod="default/cspod-23" err="0/5 nodes are available: 5 Insufficient cpu. preemption: 0/5 nodes are available: 5 No preemption victims found for incoming pod."
I0506 15:10:39.060794      12 preemption.go:264] "No preemption candidate is found; preemption is not helpful for scheduling" pod="default/cspod-24"
I0506 15:10:39.060830      12 schedule_one.go:1044] "Unable to schedule pod; no fit; waiting" pod="default/cspod-24" err="0/5 nodes are available: 5 Insufficient cpu. preemption: 0/5 nodes are available: 5 No preemption victims found for incoming pod."
I0506 15:10:39.061429      12 preemption.go:264] "No preemption candidate is found; preemption is not helpful for scheduling" pod="default/cspod-25"
I0506 15:10:39.061467      12 schedule_one.go:1044] "Unable to schedule pod; no fit; waiting" pod="default/cspod-25" err="0/5 nodes are available: 5 Insufficient cpu. preemption: 0/5 nodes are available: 5 No preemption victims found for incoming pod."
I0506 15:10:39.062018      12 preemption.go:264] "No preemption candidate is found; preemption is not helpful for scheduling" pod="default/cspod-26"
I0506 15:10:39.062050      12 schedule_one.go:1044] "Unable to schedule pod; no fit; waiting" pod="default/cspod-26" err="0/5 nodes are available: 5 Insufficient cpu. preemption: 0/5 nodes are available: 5 No preemption victims found for incoming pod."
I0506 15:10:39.062533      12 preemption.go:264] "No preemption candidate is found; preemption is not helpful for scheduling" pod="default/cspod-27"
I0506 15:10:39.062568      12 schedule_one.go:1044] "Unable to schedule pod; no fit; waiting" pod="default/cspod-27" err="0/5 nodes are available: 5 Insufficient cpu. preemption: 0/5 nodes are available: 5 No preemption victims found for incoming pod."
I0506 15:10:39.063265      12 preemption.go:264] "No preemption candidate is found; preemption is not helpful for scheduling" pod="default/cspod-28"
I0506 15:10:39.063301      12 schedule_one.go:1044] "Unable to schedule pod; no fit; waiting" pod="default/cspod-28" err="0/5 nodes are available: 5 Insufficient cpu. preemption: 0/5 nodes are available: 5 No preemption victims found for incoming pod."
I0506 15:10:39.063872      12 preemption.go:264] "No preemption candidate is found; preemption is not helpful for scheduling" pod="default/cspod-29"
I0506 15:10:39.063908      12 schedule_one.go:1044] "Unable to schedule pod; no fit; waiting" pod="default/cspod-29" err="0/5 nodes are available: 5 Insufficient cpu. preemption: 0/5 nodes are available: 5 No preemption victims found for incoming pod."
I0506 15:10:39.064407      12 preemption.go:264] "No preemption candidate is found; preemption is not helpful for scheduling" pod="default/cspod-30"
I0506 15:10:39.064443      12 schedule_one.go:1044] "Unable to schedule pod; no fit; waiting" pod="default/cspod-30" err="0/5 nodes are available: 5 Insufficient cpu. preemption: 0/5 nodes are available: 5 No preemption victims found for incoming pod."
I0506 15:10:39.064950      12 preemption.go:264] "No preemption candidate is found; preemption is not helpful for scheduling" pod="default/cspod-31"
I0506 15:10:39.064982      12 schedule_one.go:1044] "Unable to schedule pod; no fit; waiting" pod="default/cspod-31" err="0/5 nodes are available: 5 Insufficient cpu. preemption: 0/5 nodes are available: 5 No preemption victims found for incoming pod."
I0506 15:10:39.065460      12 preemption.go:264] "No preemption candidate is found; preemption is not helpful for scheduling" pod="default/cspod-32"
I0506 15:10:39.065493      12 schedule_one.go:1044] "Unable to schedule pod; no fit; waiting" pod="default/cspod-32" err="0/5 nodes are available: 5 Insufficient cpu. preemption: 0/5 nodes are available: 5 No preemption victims found for incoming pod."
I0506 15:10:39.066082      12 preemption.go:264] "No preemption candidate is found; preemption is not helpful for scheduling" pod="default/cspod-33"
I0506 15:10:39.066117      12 schedule_one.go:1044] "Unable to schedule pod; no fit; waiting" pod="default/cspod-33" err="0/5 nodes are available: 5 Insufficient cpu. preemption: 0/5 nodes are available: 5 No preemption victims found for incoming pod."
I0506 15:10:39.066590      12 preemption.go:264] "No preemption candidate is found; preemption is not helpful for scheduling" pod="default/cspod-34"
I0506 15:10:39.066624      12 schedule_one.go:1044] "Unable to schedule pod; no fit; waiting" pod="default/cspod-34" err="0/5 nodes are available: 5 Insufficient cpu. preemption: 0/5 nodes are available: 5 No preemption victims found for incoming pod."
I0506 15:10:39.067169      12 preemption.go:264] "No preemption candidate is found; preemption is not helpful for scheduling" pod="default/cspod-35"
I0506 15:10:39.067215      12 schedule_one.go:1044] "Unable to schedule pod; no fit; waiting" pod="default/cspod-35" err="0/5 nodes are available: 5 Insufficient cpu. preemption: 0/5 nodes are available: 5 No preemption victims found for incoming pod."
I0506 15:10:39.067724      12 preemption.go:264] "No preemption candidate is found; preemption is not helpful for scheduling" pod="default/cspod-36"
I0506 15:10:39.067756      12 schedule_one.go:1044] "Unable to schedule pod; no fit; waiting" pod="default/cspod-36" err="0/5 nodes are available: 5 Insufficient cpu. preemption: 0/5 nodes are available: 5 No preemption victims found for incoming pod."
I0506 15:10:39.068259      12 preemption.go:264] "No preemption candidate is found; preemption is not helpful for scheduling" pod="default/cspod-37"
I0506 15:10:39.068297      12 schedule_one.go:1044] "Unable to schedule pod; no fit; waiting" pod="default/cspod-37" err="0/5 nodes are available: 5 Insufficient cpu. preemption: 0/5 nodes are available: 5 No preemption victims found for incoming pod."
I0506 15:10:39.068804      12 preemption.go:264] "No preemption candidate is found; preemption is not helpful for scheduling" pod="default/cspod-38"
I0506 15:10:39.068836      12 schedule_one.go:1044] "Unable to schedule pod; no fit; waiting" pod="default/cspod-38" err="0/5 nodes are available: 5 Insufficient cpu. preemption: 0/5 nodes are available: 5 No preemption victims found for incoming pod."
I0506 15:10:39.069367      12 preemption.go:264] "No preemption candidate is found; preemption is not helpful for scheduling" pod="default/cspod-39"
I0506 15:10:39.069399      12 schedule_one.go:1044] "Unable to schedule pod; no fit; waiting" pod="default/cspod-39" err="0/5 nodes are available: 5 Insufficient cpu. preemption: 0/5 nodes are available: 5 No preemption victims found for incoming pod."
I0506 15:10:39.069881      12 preemption.go:264] "No preemption candidate is found; preemption is not helpful for scheduling" pod="default/cspod-40"
I0506 15:10:39.069913      12 schedule_one.go:1044] "Unable to schedule pod; no fit; waiting" pod="default/cspod-40" err="0/5 nodes are available: 5 Insufficient cpu. preemption: 0/5 nodes are available: 5 No preemption victims found for incoming pod."
I0506 15:10:39.070467      12 preemption.go:264] "No preemption candidate is found; preemption is not helpful for scheduling" pod="default/cspod-41"
I0506 15:10:39.070487      12 schedule_one.go:1044] "Unable to schedule pod; no fit; waiting" pod="default/cspod-41" err="0/5 nodes are available: 5 Insufficient cpu. preemption: 0/5 nodes are available: 5 No preemption victims found for incoming pod."
I0506 15:10:39.071194      12 preemption.go:264] "No preemption candidate is found; preemption is not helpful for scheduling" pod="default/cspod-42"
I0506 15:10:39.071227      12 schedule_one.go:1044] "Unable to schedule pod; no fit; waiting" pod="default/cspod-42" err="0/5 nodes are available: 5 Insufficient cpu. preemption: 0/5 nodes are available: 5 No preemption victims found for incoming pod."
I0506 15:10:39.071780      12 preemption.go:264] "No preemption candidate is found; preemption is not helpful for scheduling" pod="default/cspod-43"
I0506 15:10:39.071814      12 schedule_one.go:1044] "Unable to schedule pod; no fit; waiting" pod="default/cspod-43" err="0/5 nodes are available: 5 Insufficient cpu. preemption: 0/5 nodes are available: 5 No preemption victims found for incoming pod."
I0506 15:10:39.072379      12 preemption.go:264] "No preemption candidate is found; preemption is not helpful for scheduling" pod="default/cspod-44"
I0506 15:10:39.072414      12 schedule_one.go:1044] "Unable to schedule pod; no fit; waiting" pod="default/cspod-44" err="0/5 nodes are available: 5 Insufficient cpu. preemption: 0/5 nodes are available: 5 No preemption victims found for incoming pod."
I0506 15:10:39.072926      12 preemption.go:264] "No preemption candidate is found; preemption is not helpful for scheduling" pod="default/cspod-45"
I0506 15:10:39.072959      12 schedule_one.go:1044] "Unable to schedule pod; no fit; waiting" pod="default/cspod-45" err="0/5 nodes are available: 5 Insufficient cpu. preemption: 0/5 nodes are available: 5 No preemption victims found for incoming pod."
I0506 15:10:39.073771      12 preemption.go:264] "No preemption candidate is found; preemption is not helpful for scheduling" pod="default/cspod-46"
I0506 15:10:39.073805      12 schedule_one.go:1044] "Unable to schedule pod; no fit; waiting" pod="default/cspod-46" err="0/5 nodes are available: 5 Insufficient cpu. preemption: 0/5 nodes are available: 5 No preemption victims found for incoming pod."
I0506 15:10:39.074400      12 preemption.go:264] "No preemption candidate is found; preemption is not helpful for scheduling" pod="default/cspod-47"
I0506 15:10:39.074459      12 schedule_one.go:1044] "Unable to schedule pod; no fit; waiting" pod="default/cspod-47" err="0/5 nodes are available: 5 Insufficient cpu. preemption: 0/5 nodes are available: 5 No preemption victims found for incoming pod."
I0506 15:10:39.075004      12 preemption.go:264] "No preemption candidate is found; preemption is not helpful for scheduling" pod="default/cspod-48"
I0506 15:10:39.075037      12 schedule_one.go:1044] "Unable to schedule pod; no fit; waiting" pod="default/cspod-48" err="0/5 nodes are available: 5 Insufficient cpu. preemption: 0/5 nodes are available: 5 No preemption victims found for incoming pod."
I0506 15:10:39.075575      12 preemption.go:264] "No preemption candidate is found; preemption is not helpful for scheduling" pod="default/cspod-49"
I0506 15:10:39.075609      12 schedule_one.go:1044] "Unable to schedule pod; no fit; waiting" pod="default/cspod-49" err="0/5 nodes are available: 5 Insufficient cpu. preemption: 0/5 nodes are available: 5 No preemption victims found for incoming pod."
I0506 15:10:39.076106      12 preemption.go:264] "No preemption candidate is found; preemption is not helpful for scheduling" pod="default/cspod-50"
I0506 15:10:39.076137      12 schedule_one.go:1044] "Unable to schedule pod; no fit; waiting" pod="default/cspod-50" err="0/5 nodes are available: 5 Insufficient cpu. preemption: 0/5 nodes are available: 5 No preemption victims found for incoming pod."
I0506 15:10:39.076644      12 preemption.go:264] "No preemption candidate is found; preemption is not helpful for scheduling" pod="default/cspod-51"
I0506 15:10:39.076676      12 schedule_one.go:1044] "Unable to schedule pod; no fit; waiting" pod="default/cspod-51" err="0/5 nodes are available: 5 Insufficient cpu. preemption: 0/5 nodes are available: 5 No preemption victims found for incoming pod."
I0506 15:10:39.077162      12 preemption.go:264] "No preemption candidate is found; preemption is not helpful for scheduling" pod="default/cspod-52"
I0506 15:10:39.077196      12 schedule_one.go:1044] "Unable to schedule pod; no fit; waiting" pod="default/cspod-52" err="0/5 nodes are available: 5 Insufficient cpu. preemption: 0/5 nodes are available: 5 No preemption victims found for incoming pod."
I0506 15:10:39.077717      12 preemption.go:264] "No preemption candidate is found; preemption is not helpful for scheduling" pod="default/cspod-53"
I0506 15:10:39.077754      12 schedule_one.go:1044] "Unable to schedule pod; no fit; waiting" pod="default/cspod-53" err="0/5 nodes are available: 5 Insufficient cpu. preemption: 0/5 nodes are available: 5 No preemption victims found for incoming pod."
I0506 15:10:39.078258      12 preemption.go:264] "No preemption candidate is found; preemption is not helpful for scheduling" pod="default/cspod-54"
I0506 15:10:39.078290      12 schedule_one.go:1044] "Unable to schedule pod; no fit; waiting" pod="default/cspod-54" err="0/5 nodes are available: 5 Insufficient cpu. preemption: 0/5 nodes are available: 5 No preemption victims found for incoming pod."
I0506 15:10:39.092649      12 preemption.go:264] "No preemption candidate is found; preemption is not helpful for scheduling" pod="default/cspod-55"
I0506 15:10:39.092688      12 schedule_one.go:1044] "Unable to schedule pod; no fit; waiting" pod="default/cspod-55" err="0/5 nodes are available: 5 Insufficient cpu. preemption: 0/5 nodes are available: 5 No preemption victims found for incoming pod."
I0506 15:10:39.093254      12 preemption.go:264] "No preemption candidate is found; preemption is not helpful for scheduling" pod="default/cspod-56"
I0506 15:10:39.093293      12 schedule_one.go:1044] "Unable to schedule pod; no fit; waiting" pod="default/cspod-56" err="0/5 nodes are available: 5 Insufficient cpu. preemption: 0/5 nodes are available: 5 No preemption victims found for incoming pod."
I0506 15:10:39.093878      12 preemption.go:264] "No preemption candidate is found; preemption is not helpful for scheduling" pod="default/cspod-57"
I0506 15:10:39.093913      12 schedule_one.go:1044] "Unable to schedule pod; no fit; waiting" pod="default/cspod-57" err="0/5 nodes are available: 5 Insufficient cpu. preemption: 0/5 nodes are available: 5 No preemption victims found for incoming pod."
I0506 15:10:39.094455      12 preemption.go:264] "No preemption candidate is found; preemption is not helpful for scheduling" pod="default/cspod-58"
I0506 15:10:39.094491      12 schedule_one.go:1044] "Unable to schedule pod; no fit; waiting" pod="default/cspod-58" err="0/5 nodes are available: 5 Insufficient cpu. preemption: 0/5 nodes are available: 5 No preemption victims found for incoming pod."
I0506 15:10:39.094960      12 preemption.go:264] "No preemption candidate is found; preemption is not helpful for scheduling" pod="default/cspod-59"
I0506 15:10:39.094994      12 schedule_one.go:1044] "Unable to schedule pod; no fit; waiting" pod="default/cspod-59" err="0/5 nodes are available: 5 Insufficient cpu. preemption: 0/5 nodes are available: 5 No preemption victims found for incoming pod."
I0506 15:10:39.095547      12 preemption.go:264] "No preemption candidate is found; preemption is not helpful for scheduling" pod="default/cspod-60"
I0506 15:10:39.095588      12 schedule_one.go:1044] "Unable to schedule pod; no fit; waiting" pod="default/cspod-60" err="0/5 nodes are available: 5 Insufficient cpu. preemption: 0/5 nodes are available: 5 No preemption victims found for incoming pod."
I0506 15:10:39.096108      12 preemption.go:264] "No preemption candidate is found; preemption is not helpful for scheduling" pod="default/cspod-61"
I0506 15:10:39.096142      12 schedule_one.go:1044] "Unable to schedule pod; no fit; waiting" pod="default/cspod-61" err="0/5 nodes are available: 5 Insufficient cpu. preemption: 0/5 nodes are available: 5 No preemption victims found for incoming pod."
I0506 15:10:39.096672      12 preemption.go:264] "No preemption candidate is found; preemption is not helpful for scheduling" pod="default/cspod-62"
I0506 15:10:39.096710      12 schedule_one.go:1044] "Unable to schedule pod; no fit; waiting" pod="default/cspod-62" err="0/5 nodes are available: 5 Insufficient cpu. preemption: 0/5 nodes are available: 5 No preemption victims found for incoming pod."
I0506 15:10:39.097210      12 preemption.go:264] "No preemption candidate is found; preemption is not helpful for scheduling" pod="default/cspod-63"
I0506 15:10:39.097244      12 schedule_one.go:1044] "Unable to schedule pod; no fit; waiting" pod="default/cspod-63" err="0/5 nodes are available: 5 Insufficient cpu. preemption: 0/5 nodes are available: 5 No preemption victims found for incoming pod."
I0506 15:10:39.097795      12 preemption.go:264] "No preemption candidate is found; preemption is not helpful for scheduling" pod="default/cspod-64"
I0506 15:10:39.097833      12 schedule_one.go:1044] "Unable to schedule pod; no fit; waiting" pod="default/cspod-64" err="0/5 nodes are available: 5 Insufficient cpu. preemption: 0/5 nodes are available: 5 No preemption victims found for incoming pod."
I0506 15:10:39.098349      12 preemption.go:264] "No preemption candidate is found; preemption is not helpful for scheduling" pod="default/cspod-65"
I0506 15:10:39.098382      12 schedule_one.go:1044] "Unable to schedule pod; no fit; waiting" pod="default/cspod-65" err="0/5 nodes are available: 5 Insufficient cpu. preemption: 0/5 nodes are available: 5 No preemption victims found for incoming pod."
I0506 15:10:39.098900      12 preemption.go:264] "No preemption candidate is found; preemption is not helpful for scheduling" pod="default/cspod-66"
I0506 15:10:39.098914      12 schedule_one.go:1044] "Unable to schedule pod; no fit; waiting" pod="default/cspod-66" err="0/5 nodes are available: 5 Insufficient cpu. preemption: 0/5 nodes are available: 5 No preemption victims found for incoming pod."
I0506 15:10:39.107086      12 preemption.go:264] "No preemption candidate is found; preemption is not helpful for scheduling" pod="default/cspod-67"
I0506 15:10:39.107155      12 schedule_one.go:1044] "Unable to schedule pod; no fit; waiting" pod="default/cspod-67" err="0/5 nodes are available: 5 Insufficient cpu. preemption: 0/5 nodes are available: 5 No preemption victims found for incoming pod."
I0506 15:10:39.127054      12 preemption.go:264] "No preemption candidate is found; preemption is not helpful for scheduling" pod="default/cspod-68"
I0506 15:10:39.127092      12 schedule_one.go:1044] "Unable to schedule pod; no fit; waiting" pod="default/cspod-68" err="0/5 nodes are available: 5 Insufficient cpu. preemption: 0/5 nodes are available: 5 No preemption victims found for incoming pod."
I0506 15:10:39.147109      12 preemption.go:264] "No preemption candidate is found; preemption is not helpful for scheduling" pod="default/cspod-69"
I0506 15:10:39.147180      12 schedule_one.go:1044] "Unable to schedule pod; no fit; waiting" pod="default/cspod-69" err="0/5 nodes are available: 5 Insufficient cpu. preemption: 0/5 nodes are available: 5 No preemption victims found for incoming pod."
I0506 15:10:39.181643      12 preemption.go:264] "No preemption candidate is found; preemption is not helpful for scheduling" pod="default/cspod-61"
I0506 15:10:39.181690      12 schedule_one.go:1044] "Unable to schedule pod; no fit; waiting" pod="default/cspod-61" err="0/5 nodes are available: 5 Insufficient cpu. preemption: 0/5 nodes are available: 5 No preemption victims found for incoming pod."
I0506 15:10:39.181788      12 preemption.go:264] "No preemption candidate is found; preemption is not helpful for scheduling" pod="default/cspod-62"
I0506 15:10:39.181822      12 schedule_one.go:1044] "Unable to schedule pod; no fit; waiting" pod="default/cspod-62" err="0/5 nodes are available: 5 Insufficient cpu. preemption: 0/5 nodes are available: 5 No preemption victims found for incoming pod."
I0506 15:10:39.187035      12 schedule_one.go:314] "Successfully bound pod to node" pod="default/cspod-55" node="csnode-2" evaluatedNodes=5 feasibleNodes=2
I0506 15:10:39.206783      12 schedule_one.go:314] "Successfully bound pod to node" pod="default/cspod-56" node="csnode-3" evaluatedNodes=5 feasibleNodes=2
I0506 15:10:39.227488      12 schedule_one.go:314] "Successfully bound pod to node" pod="default/cspod-57" node="csnode-3" evaluatedNodes=5 feasibleNodes=2
I0506 15:10:39.247245      12 schedule_one.go:314] "Successfully bound pod to node" pod="default/cspod-58" node="csnode-2" evaluatedNodes=5 feasibleNodes=2
I0506 15:10:39.266863      12 schedule_one.go:314] "Successfully bound pod to node" pod="default/cspod-59" node="csnode-3" evaluatedNodes=5 feasibleNodes=2
I0506 15:10:39.287366      12 schedule_one.go:314] "Successfully bound pod to node" pod="default/cspod-60" node="csnode-2" evaluatedNodes=5 feasibleNodes=1
I0506 15:10:39.307196      12 preemption.go:264] "No preemption candidate is found; preemption is not helpful for scheduling" pod="default/cspod-63"
I0506 15:10:39.307238      12 schedule_one.go:1044] "Unable to schedule pod; no fit; waiting" pod="default/cspod-63" err="0/5 nodes are available: 5 Insufficient cpu. preemption: 0/5 nodes are available: 5 No preemption victims found for incoming pod."
I0506 15:10:39.327833      12 preemption.go:264] "No preemption candidate is found; preemption is not helpful for scheduling" pod="default/cspod-64"
I0506 15:10:39.327882      12 schedule_one.go:1044] "Unable to schedule pod; no fit; waiting" pod="default/cspod-64" err="0/5 nodes are available: 5 Insufficient cpu. preemption: 0/5 nodes are available: 5 No preemption victims found for incoming pod."
I0506 15:10:39.346862      12 preemption.go:264] "No preemption candidate is found; preemption is not helpful for scheduling" pod="default/cspod-65"
I0506 15:10:39.346905      12 schedule_one.go:1044] "Unable to schedule pod; no fit; waiting" pod="default/cspod-65" err="0/5 nodes are available: 5 Insufficient cpu. preemption: 0/5 nodes are available: 5 No preemption victims found for incoming pod."
I0506 15:10:39.366910      12 preemption.go:264] "No preemption candidate is found; preemption is not helpful for scheduling" pod="default/cspod-66"
I0506 15:10:39.366986      12 schedule_one.go:1044] "Unable to schedule pod; no fit; waiting" pod="default/cspod-66" err="0/5 nodes are available: 5 Insufficient cpu. preemption: 0/5 nodes are available: 5 No preemption victims found for incoming pod."
I0506 15:10:39.387043      12 preemption.go:264] "No preemption candidate is found; preemption is not helpful for scheduling" pod="default/cspod-67"
I0506 15:10:39.387092      12 schedule_one.go:1044] "Unable to schedule pod; no fit; waiting" pod="default/cspod-67" err="0/5 nodes are available: 5 Insufficient cpu. preemption: 0/5 nodes are available: 5 No preemption victims found for incoming pod."
I0506 15:10:39.407606      12 preemption.go:264] "No preemption candidate is found; preemption is not helpful for scheduling" pod="default/cspod-68"
I0506 15:10:39.407685      12 schedule_one.go:1044] "Unable to schedule pod; no fit; waiting" pod="default/cspod-68" err="0/5 nodes are available: 5 Insufficient cpu. preemption: 0/5 nodes are available: 5 No preemption victims found for incoming pod."
I0506 15:10:39.426597      12 preemption.go:264] "No preemption candidate is found; preemption is not helpful for scheduling" pod="default/cspod-69"
I0506 15:10:39.426639      12 schedule_one.go:1044] "Unable to schedule pod; no fit; waiting" pod="default/cspod-69" err="0/5 nodes are available: 5 Insufficient cpu. preemption: 0/5 nodes are available: 5 No preemption victims found for incoming pod."
I0506 15:10:39.447652      12 preemption.go:264] "No preemption candidate is found; preemption is not helpful for scheduling" pod="default/cspod-16"
I0506 15:10:39.447693      12 schedule_one.go:1044] "Unable to schedule pod; no fit; waiting" pod="default/cspod-16" err="0/5 nodes are available: 5 Insufficient cpu. preemption: 0/5 nodes are available: 5 No preemption victims found for incoming pod."
I0506 15:10:39.466861      12 preemption.go:264] "No preemption candidate is found; preemption is not helpful for scheduling" pod="default/cspod-17"
I0506 15:10:39.466908      12 schedule_one.go:1044] "Unable to schedule pod; no fit; waiting" pod="default/cspod-17" err="0/5 nodes are available: 5 Insufficient cpu. preemption: 0/5 nodes are available: 5 No preemption victims found for incoming pod."
I0506 15:10:39.486869      12 preemption.go:264] "No preemption candidate is found; preemption is not helpful for scheduling" pod="default/cspod-18"
I0506 15:10:39.486920      12 schedule_one.go:1044] "Unable to schedule pod; no fit; waiting" pod="default/cspod-18" err="0/5 nodes are available: 5 Insufficient cpu. preemption: 0/5 nodes are available: 5 No preemption victims found for incoming pod."
I0506 15:10:39.507785      12 preemption.go:264] "No preemption candidate is found; preemption is not helpful for scheduling" pod="default/cspod-19"
I0506 15:10:39.507834      12 schedule_one.go:1044] "Unable to schedule pod; no fit; waiting" pod="default/cspod-19" err="0/5 nodes are available: 5 Insufficient cpu. preemption: 0/5 nodes are available: 5 No preemption victims found for incoming pod."
I0506 15:10:39.526841      12 preemption.go:264] "No preemption candidate is found; preemption is not helpful for scheduling" pod="default/cspod-20"
I0506 15:10:39.526907      12 schedule_one.go:1044] "Unable to schedule pod; no fit; waiting" pod="default/cspod-20" err="0/5 nodes are available: 5 Insufficient cpu. preemption: 0/5 nodes are available: 5 No preemption victims found for incoming pod."
I0506 15:10:39.547178      12 preemption.go:264] "No preemption candidate is found; preemption is not helpful for scheduling" pod="default/cspod-21"
I0506 15:10:39.547233      12 schedule_one.go:1044] "Unable to schedule pod; no fit; waiting" pod="default/cspod-21" err="0/5 nodes are available: 5 Insufficient cpu. preemption: 0/5 nodes are available: 5 No preemption victims found for incoming pod."
I0506 15:10:39.567143      12 preemption.go:264] "No preemption candidate is found; preemption is not helpful for scheduling" pod="default/cspod-22"
I0506 15:10:39.567220      12 schedule_one.go:1044] "Unable to schedule pod; no fit; waiting" pod="default/cspod-22" err="0/5 nodes are available: 5 Insufficient cpu. preemption: 0/5 nodes are available: 5 No preemption victims found for incoming pod."
I0506 15:10:39.587480      12 preemption.go:264] "No preemption candidate is found; preemption is not helpful for scheduling" pod="default/cspod-23"
I0506 15:10:39.587532      12 schedule_one.go:1044] "Unable to schedule pod; no fit; waiting" pod="default/cspod-23" err="0/5 nodes are available: 5 Insufficient cpu. preemption: 0/5 nodes are available: 5 No preemption victims found for incoming pod."
I0506 15:10:39.607942      12 preemption.go:264] "No preemption candidate is found; preemption is not helpful for scheduling" pod="default/cspod-24"
I0506 15:10:39.607988      12 schedule_one.go:1044] "Unable to schedule pod; no fit; waiting" pod="default/cspod-24" err="0/5 nodes are available: 5 Insufficient cpu. preemption: 0/5 nodes are available: 5 No preemption victims found for incoming pod."
I0506 15:10:39.627463      12 preemption.go:264] "No preemption candidate is found; preemption is not helpful for scheduling" pod="default/cspod-25"
I0506 15:10:39.627510      12 schedule_one.go:1044] "Unable to schedule pod; no fit; waiting" pod="default/cspod-25" err="0/5 nodes are available: 5 Insufficient cpu. preemption: 0/5 nodes are available: 5 No preemption victims found for incoming pod."
I0506 15:10:39.647457      12 preemption.go:264] "No preemption candidate is found; preemption is not helpful for scheduling" pod="default/cspod-26"
I0506 15:10:39.647498      12 schedule_one.go:1044] "Unable to schedule pod; no fit; waiting" pod="default/cspod-26" err="0/5 nodes are available: 5 Insufficient cpu. preemption: 0/5 nodes are available: 5 No preemption victims found for incoming pod."
I0506 15:10:39.667803      12 preemption.go:264] "No preemption candidate is found; preemption is not helpful for scheduling" pod="default/cspod-27"
I0506 15:10:39.667853      12 schedule_one.go:1044] "Unable to schedule pod; no fit; waiting" pod="default/cspod-27" err="0/5 nodes are available: 5 Insufficient cpu. preemption: 0/5 nodes are available: 5 No preemption victims found for incoming pod."
I0506 15:10:39.687229      12 preemption.go:264] "No preemption candidate is found; preemption is not helpful for scheduling" pod="default/cspod-28"
I0506 15:10:39.687271      12 schedule_one.go:1044] "Unable to schedule pod; no fit; waiting" pod="default/cspod-28" err="0/5 nodes are available: 5 Insufficient cpu. preemption: 0/5 nodes are available: 5 No preemption victims found for incoming pod."
I0506 15:10:39.706661      12 preemption.go:264] "No preemption candidate is found; preemption is not helpful for scheduling" pod="default/cspod-29"
I0506 15:10:39.706701      12 schedule_one.go:1044] "Unable to schedule pod; no fit; waiting" pod="default/cspod-29" err="0/5 nodes are available: 5 Insufficient cpu. preemption: 0/5 nodes are available: 5 No preemption victims found for incoming pod."
I0506 15:10:39.727567      12 preemption.go:264] "No preemption candidate is found; preemption is not helpful for scheduling" pod="default/cspod-30"
I0506 15:10:39.727643      12 schedule_one.go:1044] "Unable to schedule pod; no fit; waiting" pod="default/cspod-30" err="0/5 nodes are available: 5 Insufficient cpu. preemption: 0/5 nodes are available: 5 No preemption victims found for incoming pod."
I0506 15:10:39.746676      12 preemption.go:264] "No preemption candidate is found; preemption is not helpful for scheduling" pod="default/cspod-31"
I0506 15:10:39.746727      12 schedule_one.go:1044] "Unable to schedule pod; no fit; waiting" pod="default/cspod-31" err="0/5 nodes are available: 5 Insufficient cpu. preemption: 0/5 nodes are available: 5 No preemption victims found for incoming pod."
I0506 15:10:39.766899      12 preemption.go:264] "No preemption candidate is found; preemption is not helpful for scheduling" pod="default/cspod-32"
I0506 15:10:39.766944      12 schedule_one.go:1044] "Unable to schedule pod; no fit; waiting" pod="default/cspod-32" err="0/5 nodes are available: 5 Insufficient cpu. preemption: 0/5 nodes are available: 5 No preemption victims found for incoming pod."
I0506 15:10:39.787164      12 preemption.go:264] "No preemption candidate is found; preemption is not helpful for scheduling" pod="default/cspod-33"
I0506 15:10:39.787250      12 schedule_one.go:1044] "Unable to schedule pod; no fit; waiting" pod="default/cspod-33" err="0/5 nodes are available: 5 Insufficient cpu. preemption: 0/5 nodes are available: 5 No preemption victims found for incoming pod."
I0506 15:10:39.807087      12 preemption.go:264] "No preemption candidate is found; preemption is not helpful for scheduling" pod="default/cspod-34"
I0506 15:10:39.807130      12 schedule_one.go:1044] "Unable to schedule pod; no fit; waiting" pod="default/cspod-34" err="0/5 nodes are available: 5 Insufficient cpu. preemption: 0/5 nodes are available: 5 No preemption victims found for incoming pod."
I0506 15:10:39.827048      12 preemption.go:264] "No preemption candidate is found; preemption is not helpful for scheduling" pod="default/cspod-35"
I0506 15:10:39.827109      12 schedule_one.go:1044] "Unable to schedule pod; no fit; waiting" pod="default/cspod-35" err="0/5 nodes are available: 5 Insufficient cpu. preemption: 0/5 nodes are available: 5 No preemption victims found for incoming pod."
I0506 15:10:39.847714      12 preemption.go:264] "No preemption candidate is found; preemption is not helpful for scheduling" pod="default/cspod-36"
I0506 15:10:39.847762      12 schedule_one.go:1044] "Unable to schedule pod; no fit; waiting" pod="default/cspod-36" err="0/5 nodes are available: 5 Insufficient cpu. preemption: 0/5 nodes are available: 5 No preemption victims found for incoming pod."
I0506 15:10:39.867430      12 preemption.go:264] "No preemption candidate is found; preemption is not helpful for scheduling" pod="default/cspod-37"
I0506 15:10:39.867478      12 schedule_one.go:1044] "Unable to schedule pod; no fit; waiting" pod="default/cspod-37" err="0/5 nodes are available: 5 Insufficient cpu. preemption: 0/5 nodes are available: 5 No preemption victims found for incoming pod."
I0506 15:10:39.887299      12 preemption.go:264] "No preemption candidate is found; preemption is not helpful for scheduling" pod="default/cspod-38"
I0506 15:10:39.887340      12 schedule_one.go:1044] "Unable to schedule pod; no fit; waiting" pod="default/cspod-38" err="0/5 nodes are available: 5 Insufficient cpu. preemption: 0/5 nodes are available: 5 No preemption victims found for incoming pod."
I0506 15:10:39.907048      12 preemption.go:264] "No preemption candidate is found; preemption is not helpful for scheduling" pod="default/cspod-39"
I0506 15:10:39.907088      12 schedule_one.go:1044] "Unable to schedule pod; no fit; waiting" pod="default/cspod-39" err="0/5 nodes are available: 5 Insufficient cpu. preemption: 0/5 nodes are available: 5 No preemption victims found for incoming pod."
I0506 15:10:39.927301      12 preemption.go:264] "No preemption candidate is found; preemption is not helpful for scheduling" pod="default/cspod-40"
I0506 15:10:39.927352      12 schedule_one.go:1044] "Unable to schedule pod; no fit; waiting" pod="default/cspod-40" err="0/5 nodes are available: 5 Insufficient cpu. preemption: 0/5 nodes are available: 5 No preemption victims found for incoming pod."
I0506 15:10:39.947084      12 preemption.go:264] "No preemption candidate is found; preemption is not helpful for scheduling" pod="default/cspod-41"
I0506 15:10:39.947134      12 schedule_one.go:1044] "Unable to schedule pod; no fit; waiting" pod="default/cspod-41" err="0/5 nodes are available: 5 Insufficient cpu. preemption: 0/5 nodes are available: 5 No preemption victims found for incoming pod."
I0506 15:10:39.966793      12 preemption.go:264] "No preemption candidate is found; preemption is not helpful for scheduling" pod="default/cspod-42"
I0506 15:10:39.966835      12 schedule_one.go:1044] "Unable to schedule pod; no fit; waiting" pod="default/cspod-42" err="0/5 nodes are available: 5 Insufficient cpu. preemption: 0/5 nodes are available: 5 No preemption victims found for incoming pod."
I0506 15:10:39.986750      12 preemption.go:264] "No preemption candidate is found; preemption is not helpful for scheduling" pod="default/cspod-43"
I0506 15:10:39.986794      12 schedule_one.go:1044] "Unable to schedule pod; no fit; waiting" pod="default/cspod-43" err="0/5 nodes are available: 5 Insufficient cpu. preemption: 0/5 nodes are available: 5 No preemption victims found for incoming pod."
I0506 15:10:40.006603      12 preemption.go:264] "No preemption candidate is found; preemption is not helpful for scheduling" pod="default/cspod-44"
I0506 15:10:40.006672      12 schedule_one.go:1044] "Unable to schedule pod; no fit; waiting" pod="default/cspod-44" err="0/5 nodes are available: 5 Insufficient cpu. preemption: 0/5 nodes are available: 5 No preemption victims found for incoming pod."
I0506 15:10:40.026820      12 preemption.go:264] "No preemption candidate is found; preemption is not helpful for scheduling" pod="default/cspod-45"
I0506 15:10:40.026896      12 schedule_one.go:1044] "Unable to schedule pod; no fit; waiting" pod="default/cspod-45" err="0/5 nodes are available: 5 Insufficient cpu. preemption: 0/5 nodes are available: 5 No preemption victims found for incoming pod."
I0506 15:10:40.046973      12 preemption.go:264] "No preemption candidate is found; preemption is not helpful for scheduling" pod="default/cspod-46"
I0506 15:10:40.047021      12 schedule_one.go:1044] "Unable to schedule pod; no fit; waiting" pod="default/cspod-46" err="0/5 nodes are available: 5 Insufficient cpu. preemption: 0/5 nodes are available: 5 No preemption victims found for incoming pod."
I0506 15:10:40.067039      12 preemption.go:264] "No preemption candidate is found; preemption is not helpful for scheduling" pod="default/cspod-47"
I0506 15:10:40.067083      12 schedule_one.go:1044] "Unable to schedule pod; no fit; waiting" pod="default/cspod-47" err="0/5 nodes are available: 5 Insufficient cpu. preemption: 0/5 nodes are available: 5 No preemption victims found for incoming pod."
I0506 15:10:40.087553      12 preemption.go:264] "No preemption candidate is found; preemption is not helpful for scheduling" pod="default/cspod-48"
I0506 15:10:40.087624      12 schedule_one.go:1044] "Unable to schedule pod; no fit; waiting" pod="default/cspod-48" err="0/5 nodes are available: 5 Insufficient cpu. preemption: 0/5 nodes are available: 5 No preemption victims found for incoming pod."
I0506 15:10:40.107850      12 preemption.go:264] "No preemption candidate is found; preemption is not helpful for scheduling" pod="default/cspod-49"
I0506 15:10:40.107895      12 schedule_one.go:1044] "Unable to schedule pod; no fit; waiting" pod="default/cspod-49" err="0/5 nodes are available: 5 Insufficient cpu. preemption: 0/5 nodes are available: 5 No preemption victims found for incoming pod."
I0506 15:10:40.126912      12 preemption.go:264] "No preemption candidate is found; preemption is not helpful for scheduling" pod="default/cspod-50"
I0506 15:10:40.126958      12 schedule_one.go:1044] "Unable to schedule pod; no fit; waiting" pod="default/cspod-50" err="0/5 nodes are available: 5 Insufficient cpu. preemption: 0/5 nodes are available: 5 No preemption victims found for incoming pod."
I0506 15:10:40.146974      12 preemption.go:264] "No preemption candidate is found; preemption is not helpful for scheduling" pod="default/cspod-51"
I0506 15:10:40.147051      12 schedule_one.go:1044] "Unable to schedule pod; no fit; waiting" pod="default/cspod-51" err="0/5 nodes are available: 5 Insufficient cpu. preemption: 0/5 nodes are available: 5 No preemption victims found for incoming pod."
I0506 15:10:40.167248      12 preemption.go:264] "No preemption candidate is found; preemption is not helpful for scheduling" pod="default/cspod-52"
I0506 15:10:40.167308      12 schedule_one.go:1044] "Unable to schedule pod; no fit; waiting" pod="default/cspod-52" err="0/5 nodes are available: 5 Insufficient cpu. preemption: 0/5 nodes are available: 5 No preemption victims found for incoming pod."
I0506 15:10:40.186911      12 preemption.go:264] "No preemption candidate is found; preemption is not helpful for scheduling" pod="default/cspod-53"
I0506 15:10:40.186962      12 schedule_one.go:1044] "Unable to schedule pod; no fit; waiting" pod="default/cspod-53" err="0/5 nodes are available: 5 Insufficient cpu. preemption: 0/5 nodes are available: 5 No preemption victims found for incoming pod."
I0506 15:10:40.207329      12 preemption.go:264] "No preemption candidate is found; preemption is not helpful for scheduling" pod="default/cspod-54"
I0506 15:10:40.207407      12 schedule_one.go:1044] "Unable to schedule pod; no fit; waiting" pod="default/cspod-54" err="0/5 nodes are available: 5 Insufficient cpu. preemption: 0/5 nodes are available: 5 No preemption victims found for incoming pod."
I0506 15:10:41.590696      12 schedule_one.go:314] "Successfully bound pod to node" pod="default/cspod-61" node="csnode-1" evaluatedNodes=5 feasibleNodes=2
I0506 15:10:41.590735      12 schedule_one.go:314] "Successfully bound pod to node" pod="default/cspod-62" node="csnode-0" evaluatedNodes=5 feasibleNodes=2
I0506 15:10:41.590832      12 preemption.go:264] "No preemption candidate is found; preemption is not helpful for scheduling" pod="default/cspod-65"
I0506 15:10:41.590860      12 schedule_one.go:1044] "Unable to schedule pod; no fit; waiting" pod="default/cspod-65" err="0/5 nodes are available: 5 Insufficient cpu. preemption: 0/5 nodes are available: 5 No preemption victims found for incoming pod."
I0506 15:10:41.591045      12 schedule_one.go:314] "Successfully bound pod to node" pod="default/cspod-63" node="csnode-1" evaluatedNodes=5 feasibleNodes=2
I0506 15:10:41.591085      12 preemption.go:264] "No preemption candidate is found; preemption is not helpful for scheduling" pod="default/cspod-66"
I0506 15:10:41.591087      12 schedule_one.go:314] "Successfully bound pod to node" pod="default/cspod-64" node="csnode-0" evaluatedNodes=5 feasibleNodes=1
I0506 15:10:41.591099      12 schedule_one.go:1044] "Unable to schedule pod; no fit; waiting" pod="default/cspod-66" err="0/5 nodes are available: 5 Insufficient cpu. preemption: 0/5 nodes are available: 5 No preemption victims found for incoming pod."
I0506 15:10:41.591340      12 preemption.go:264] "No preemption candidate is found; preemption is not helpful for scheduling" pod="default/cspod-61"
I0506 15:10:41.591375      12 schedule_one.go:1044] "Unable to schedule pod; no fit; waiting" pod="default/cspod-61" err="0/5 nodes are available: 5 Insufficient cpu. preemption: 0/5 nodes are available: 5 No preemption victims found for incoming pod."
I0506 15:10:41.591383      12 schedule_one.go:1059] "Pod has been assigned to node. Abort adding it back to queue." pod="default/cspod-61" node="csnode-1"
I0506 15:10:41.592427      12 preemption.go:264] "No preemption candidate is found; preemption is not helpful for scheduling" pod="default/cspod-67"
I0506 15:10:41.592466      12 schedule_one.go:1044] "Unable to schedule pod; no fit; waiting" pod="default/cspod-67" err="0/5 nodes are available: 5 Insufficient cpu. preemption: 0/5 nodes are available: 5 No preemption victims found for incoming pod."
I0506 15:10:41.593061      12 preemption.go:264] "No preemption candidate is found; preemption is not helpful for scheduling" pod="default/cspod-68"
I0506 15:10:41.593097      12 schedule_one.go:1044] "Unable to schedule pod; no fit; waiting" pod="default/cspod-68" err="0/5 nodes are available: 5 Insufficient cpu. preemption: 0/5 nodes are available: 5 No preemption victims found for incoming pod."
I0506 15:10:41.593709      12 preemption.go:264] "No preemption candidate is found; preemption is not helpful for scheduling" pod="default/cspod-69"
I0506 15:10:41.593741      12 schedule_one.go:1044] "Unable to schedule pod; no fit; waiting" pod="default/cspod-69" err="0/5 nodes are available: 5 Insufficient cpu. preemption: 0/5 nodes are available: 5 No preemption victims found for incoming pod."
I0506 15:10:41.594256      12 preemption.go:264] "No preemption candidate is found; preemption is not helpful for scheduling" pod="default/cspod-16"
I0506 15:10:41.594288      12 schedule_one.go:1044] "Unable to schedule pod; no fit; waiting" pod="default/cspod-16" err="0/5 nodes are available: 5 Insufficient cpu. preemption: 0/5 nodes are available: 5 No preemption victims found for incoming pod."
I0506 15:10:41.594778      12 preemption.go:264] "No preemption candidate is found; preemption is not helpful for scheduling" pod="default/cspod-17"
I0506 15:10:41.594813      12 schedule_one.go:1044] "Unable to schedule pod; no fit; waiting" pod="default/cspod-17" err="0/5 nodes are available: 5 Insufficient cpu. preemption: 0/5 nodes are available: 5 No preemption victims found for incoming pod."
I0506 15:10:41.595350      12 preemption.go:264] "No preemption candidate is found; preemption is not helpful for scheduling" pod="default/cspod-18"
I0506 15:10:41.595387      12 schedule_one.go:1044] "Unable to schedule pod; no fit; waiting" pod="default/cspod-18" err="0/5 nodes are available: 5 Insufficient cpu. preemption: 0/5 nodes are available: 5 No preemption victims found for incoming pod."
I0506 15:10:41.595959      12 preemption.go:264] "No preemption candidate is found; preemption is not helpful for scheduling" pod="default/cspod-19"
I0506 15:10:41.595996      12 schedule_one.go:1044] "Unable to schedule pod; no fit; waiting" pod="default/cspod-19" err="0/5 nodes are available: 5 Insufficient cpu. preemption: 0/5 nodes are available: 5 No preemption victims found for incoming pod."
I0506 15:10:41.596534      12 preemption.go:264] "No preemption candidate is found; preemption is not helpful for scheduling" pod="default/cspod-20"
I0506 15:10:41.596571      12 schedule_one.go:1044] "Unable to schedule pod; no fit; waiting" pod="default/cspod-20" err="0/5 nodes are available: 5 Insufficient cpu. preemption: 0/5 nodes are available: 5 No preemption victims found for incoming pod."
I0506 15:10:41.597180      12 preemption.go:264] "No preemption candidate is found; preemption is not helpful for scheduling" pod="default/cspod-21"
I0506 15:10:41.597216      12 schedule_one.go:1044] "Unable to schedule pod; no fit; waiting" pod="default/cspod-21" err="0/5 nodes are available: 5 Insufficient cpu. preemption: 0/5 nodes are available: 5 No preemption victims found for incoming pod."
I0506 15:10:41.597776      12 preemption.go:264] "No preemption candidate is found; preemption is not helpful for scheduling" pod="default/cspod-22"
I0506 15:10:41.597811      12 schedule_one.go:1044] "Unable to schedule pod; no fit; waiting" pod="default/cspod-22" err="0/5 nodes are available: 5 Insufficient cpu. preemption: 0/5 nodes are available: 5 No preemption victims found for incoming pod."
I0506 15:10:41.598323      12 preemption.go:264] "No preemption candidate is found; preemption is not helpful for scheduling" pod="default/cspod-23"
I0506 15:10:41.598363      12 schedule_one.go:1044] "Unable to schedule pod; no fit; waiting" pod="default/cspod-23" err="0/5 nodes are available: 5 Insufficient cpu. preemption: 0/5 nodes are available: 5 No preemption victims found for incoming pod."
I0506 15:10:41.598929      12 preemption.go:264] "No preemption candidate is found; preemption is not helpful for scheduling" pod="default/cspod-24"
I0506 15:10:41.598962      12 schedule_one.go:1044] "Unable to schedule pod; no fit; waiting" pod="default/cspod-24" err="0/5 nodes are available: 5 Insufficient cpu. preemption: 0/5 nodes are available: 5 No preemption victims found for incoming pod."
I0506 15:10:41.599529      12 preemption.go:264] "No preemption candidate is found; preemption is not helpful for scheduling" pod="default/cspod-25"
I0506 15:10:41.599568      12 schedule_one.go:1044] "Unable to schedule pod; no fit; waiting" pod="default/cspod-25" err="0/5 nodes are available: 5 Insufficient cpu. preemption: 0/5 nodes are available: 5 No preemption victims found for incoming pod."
I0506 15:10:41.600640      12 preemption.go:264] "No preemption candidate is found; preemption is not helpful for scheduling" pod="default/cspod-26"
I0506 15:10:41.600745      12 schedule_one.go:1044] "Unable to schedule pod; no fit; waiting" pod="default/cspod-26" err="0/5 nodes are available: 5 Insufficient cpu. preemption: 0/5 nodes are available: 5 No preemption victims found for incoming pod."
I0506 15:10:41.601508      12 preemption.go:264] "No preemption candidate is found; preemption is not helpful for scheduling" pod="default/cspod-27"
I0506 15:10:41.601548      12 schedule_one.go:1044] "Unable to schedule pod; no fit; waiting" pod="default/cspod-27" err="0/5 nodes are available: 5 Insufficient cpu. preemption: 0/5 nodes are available: 5 No preemption victims found for incoming pod."
I0506 15:10:41.602053      12 preemption.go:264] "No preemption candidate is found; preemption is not helpful for scheduling" pod="default/cspod-28"
I0506 15:10:41.602092      12 schedule_one.go:1044] "Unable to schedule pod; no fit; waiting" pod="default/cspod-28" err="0/5 nodes are available: 5 Insufficient cpu. preemption: 0/5 nodes are available: 5 No preemption victims found for incoming pod."
I0506 15:10:41.602574      12 preemption.go:264] "No preemption candidate is found; preemption is not helpful for scheduling" pod="default/cspod-29"
I0506 15:10:41.602606      12 schedule_one.go:1044] "Unable to schedule pod; no fit; waiting" pod="default/cspod-29" err="0/5 nodes are available: 5 Insufficient cpu. preemption: 0/5 nodes are available: 5 No preemption victims found for incoming pod."
I0506 15:10:41.603051      12 preemption.go:264] "No preemption candidate is found; preemption is not helpful for scheduling" pod="default/cspod-30"
I0506 15:10:41.603085      12 schedule_one.go:1044] "Unable to schedule pod; no fit; waiting" pod="default/cspod-30" err="0/5 nodes are available: 5 Insufficient cpu. preemption: 0/5 nodes are available: 5 No preemption victims found for incoming pod."
I0506 15:10:41.603625      12 preemption.go:264] "No preemption candidate is found; preemption is not helpful for scheduling" pod="default/cspod-31"
I0506 15:10:41.603661      12 schedule_one.go:1044] "Unable to schedule pod; no fit; waiting" pod="default/cspod-31" err="0/5 nodes are available: 5 Insufficient cpu. preemption: 0/5 nodes are available: 5 No preemption victims found for incoming pod."
I0506 15:10:41.604149      12 preemption.go:264] "No preemption candidate is found; preemption is not helpful for scheduling" pod="default/cspod-32"
I0506 15:10:41.604188      12 schedule_one.go:1044] "Unable to schedule pod; no fit; waiting" pod="default/cspod-32" err="0/5 nodes are available: 5 Insufficient cpu. preemption: 0/5 nodes are available: 5 No preemption victims found for incoming pod."
I0506 15:10:41.604719      12 preemption.go:264] "No preemption candidate is found; preemption is not helpful for scheduling" pod="default/cspod-33"
I0506 15:10:41.604756      12 schedule_one.go:1044] "Unable to schedule pod; no fit; waiting" pod="default/cspod-33" err="0/5 nodes are available: 5 Insufficient cpu. preemption: 0/5 nodes are available: 5 No preemption victims found for incoming pod."
I0506 15:10:41.605271      12 preemption.go:264] "No preemption candidate is found; preemption is not helpful for scheduling" pod="default/cspod-34"
I0506 15:10:41.605304      12 schedule_one.go:1044] "Unable to schedule pod; no fit; waiting" pod="default/cspod-34" err="0/5 nodes are available: 5 Insufficient cpu. preemption: 0/5 nodes are available: 5 No preemption victims found for incoming pod."
I0506 15:10:41.605857      12 preemption.go:264] "No preemption candidate is found; preemption is not helpful for scheduling" pod="default/cspod-35"
I0506 15:10:41.605890      12 schedule_one.go:1044] "Unable to schedule pod; no fit; waiting" pod="default/cspod-35" err="0/5 nodes are available: 5 Insufficient cpu. preemption: 0/5 nodes are available: 5 No preemption victims found for incoming pod."
I0506 15:10:41.606411      12 preemption.go:264] "No preemption candidate is found; preemption is not helpful for scheduling" pod="default/cspod-36"
I0506 15:10:41.606446      12 schedule_one.go:1044] "Unable to schedule pod; no fit; waiting" pod="default/cspod-36" err="0/5 nodes are available: 5 Insufficient cpu. preemption: 0/5 nodes are available: 5 No preemption victims found for incoming pod."
I0506 15:10:41.606898      12 preemption.go:264] "No preemption candidate is found; preemption is not helpful for scheduling" pod="default/cspod-37"
I0506 15:10:41.606932      12 schedule_one.go:1044] "Unable to schedule pod; no fit; waiting" pod="default/cspod-37" err="0/5 nodes are available: 5 Insufficient cpu. preemption: 0/5 nodes are available: 5 No preemption victims found for incoming pod."
I0506 15:10:41.607465      12 preemption.go:264] "No preemption candidate is found; preemption is not helpful for scheduling" pod="default/cspod-38"
I0506 15:10:41.607499      12 schedule_one.go:1044] "Unable to schedule pod; no fit; waiting" pod="default/cspod-38" err="0/5 nodes are available: 5 Insufficient cpu. preemption: 0/5 nodes are available: 5 No preemption victims found for incoming pod."
I0506 15:10:41.608026      12 preemption.go:264] "No preemption candidate is found; preemption is not helpful for scheduling" pod="default/cspod-39"
I0506 15:10:41.608059      12 schedule_one.go:1044] "Unable to schedule pod; no fit; waiting" pod="default/cspod-39" err="0/5 nodes are available: 5 Insufficient cpu. preemption: 0/5 nodes are available: 5 No preemption victims found for incoming pod."
I0506 15:10:41.608554      12 preemption.go:264] "No preemption candidate is found; preemption is not helpful for scheduling" pod="default/cspod-40"
I0506 15:10:41.608592      12 schedule_one.go:1044] "Unable to schedule pod; no fit; waiting" pod="default/cspod-40" err="0/5 nodes are available: 5 Insufficient cpu. preemption: 0/5 nodes are available: 5 No preemption victims found for incoming pod."
I0506 15:10:41.609089      12 preemption.go:264] "No preemption candidate is found; preemption is not helpful for scheduling" pod="default/cspod-41"
I0506 15:10:41.609120      12 schedule_one.go:1044] "Unable to schedule pod; no fit; waiting" pod="default/cspod-41" err="0/5 nodes are available: 5 Insufficient cpu. preemption: 0/5 nodes are available: 5 No preemption victims found for incoming pod."
I0506 15:10:41.609582      12 preemption.go:264] "No preemption candidate is found; preemption is not helpful for scheduling" pod="default/cspod-42"
I0506 15:10:41.609616      12 schedule_one.go:1044] "Unable to schedule pod; no fit; waiting" pod="default/cspod-42" err="0/5 nodes are available: 5 Insufficient cpu. preemption: 0/5 nodes are available: 5 No preemption victims found for incoming pod."
I0506 15:10:41.610093      12 preemption.go:264] "No preemption candidate is found; preemption is not helpful for scheduling" pod="default/cspod-43"
I0506 15:10:41.610124      12 schedule_one.go:1044] "Unable to schedule pod; no fit; waiting" pod="default/cspod-43" err="0/5 nodes are available: 5 Insufficient cpu. preemption: 0/5 nodes are available: 5 No preemption victims found for incoming pod."
I0506 15:10:41.610587      12 preemption.go:264] "No preemption candidate is found; preemption is not helpful for scheduling" pod="default/cspod-44"
I0506 15:10:41.610620      12 schedule_one.go:1044] "Unable to schedule pod; no fit; waiting" pod="default/cspod-44" err="0/5 nodes are available: 5 Insufficient cpu. preemption: 0/5 nodes are available: 5 No preemption victims found for incoming pod."
I0506 15:10:41.611084      12 preemption.go:264] "No preemption candidate is found; preemption is not helpful for scheduling" pod="default/cspod-45"
I0506 15:10:41.611121      12 schedule_one.go:1044] "Unable to schedule pod; no fit; waiting" pod="default/cspod-45" err="0/5 nodes are available: 5 Insufficient cpu. preemption: 0/5 nodes are available: 5 No preemption victims found for incoming pod."
I0506 15:10:41.611626      12 preemption.go:264] "No preemption candidate is found; preemption is not helpful for scheduling" pod="default/cspod-46"
I0506 15:10:41.611664      12 schedule_one.go:1044] "Unable to schedule pod; no fit; waiting" pod="default/cspod-46" err="0/5 nodes are available: 5 Insufficient cpu. preemption: 0/5 nodes are available: 5 No preemption victims found for incoming pod."
I0506 15:10:41.612165      12 preemption.go:264] "No preemption candidate is found; preemption is not helpful for scheduling" pod="default/cspod-47"
I0506 15:10:41.612223      12 schedule_one.go:1044] "Unable to schedule pod; no fit; waiting" pod="default/cspod-47" err="0/5 nodes are available: 5 Insufficient cpu. preemption: 0/5 nodes are available: 5 No preemption victims found for incoming pod."
I0506 15:10:41.612778      12 preemption.go:264] "No preemption candidate is found; preemption is not helpful for scheduling" pod="default/cspod-48"
I0506 15:10:41.612812      12 schedule_one.go:1044] "Unable to schedule pod; no fit; waiting" pod="default/cspod-48" err="0/5 nodes are available: 5 Insufficient cpu. preemption: 0/5 nodes are available: 5 No preemption victims found for incoming pod."
I0506 15:10:41.613294      12 preemption.go:264] "No preemption candidate is found; preemption is not helpful for scheduling" pod="default/cspod-49"
I0506 15:10:41.613327      12 schedule_one.go:1044] "Unable to schedule pod; no fit; waiting" pod="default/cspod-49" err="0/5 nodes are available: 5 Insufficient cpu. preemption: 0/5 nodes are available: 5 No preemption victims found for incoming pod."
I0506 15:10:41.613801      12 preemption.go:264] "No preemption candidate is found; preemption is not helpful for scheduling" pod="default/cspod-50"
I0506 15:10:41.613840      12 schedule_one.go:1044] "Unable to schedule pod; no fit; waiting" pod="default/cspod-50" err="0/5 nodes are available: 5 Insufficient cpu. preemption: 0/5 nodes are available: 5 No preemption victims found for incoming pod."
I0506 15:10:41.614395      12 preemption.go:264] "No preemption candidate is found; preemption is not helpful for scheduling" pod="default/cspod-51"
I0506 15:10:41.614427      12 schedule_one.go:1044] "Unable to schedule pod; no fit; waiting" pod="default/cspod-51" err="0/5 nodes are available: 5 Insufficient cpu. preemption: 0/5 nodes are available: 5 No preemption victims found for incoming pod."
I0506 15:10:41.614932      12 preemption.go:264] "No preemption candidate is found; preemption is not helpful for scheduling" pod="default/cspod-52"
I0506 15:10:41.614965      12 schedule_one.go:1044] "Unable to schedule pod; no fit; waiting" pod="default/cspod-52" err="0/5 nodes are available: 5 Insufficient cpu. preemption: 0/5 nodes are available: 5 No preemption victims found for incoming pod."
I0506 15:10:41.615423      12 preemption.go:264] "No preemption candidate is found; preemption is not helpful for scheduling" pod="default/cspod-53"
I0506 15:10:41.615456      12 schedule_one.go:1044] "Unable to schedule pod; no fit; waiting" pod="default/cspod-53" err="0/5 nodes are available: 5 Insufficient cpu. preemption: 0/5 nodes are available: 5 No preemption victims found for incoming pod."
I0506 15:10:41.615934      12 preemption.go:264] "No preemption candidate is found; preemption is not helpful for scheduling" pod="default/cspod-54"
I0506 15:10:41.615964      12 schedule_one.go:1044] "Unable to schedule pod; no fit; waiting" pod="default/cspod-54" err="0/5 nodes are available: 5 Insufficient cpu. preemption: 0/5 nodes are available: 5 No preemption victims found for incoming pod."
I0506 15:10:45.636624      12 schedule_one.go:314] "Successfully bound pod to node" pod="default/cspod-65" node="csnode-4" evaluatedNodes=5 feasibleNodes=1
I0506 15:10:45.636673      12 schedule_one.go:314] "Successfully bound pod to node" pod="default/cspod-66" node="csnode-4" evaluatedNodes=5 feasibleNodes=1
I0506 15:10:45.636698      12 preemption.go:264] "No preemption candidate is found; preemption is not helpful for scheduling" pod="default/cspod-69"
I0506 15:10:45.636710      12 schedule_one.go:1044] "Unable to schedule pod; no fit; waiting" pod="default/cspod-69" err="0/5 nodes are available: 5 Insufficient cpu. preemption: 0/5 nodes are available: 5 No preemption victims found for incoming pod."
I0506 15:10:45.636794      12 preemption.go:264] "No preemption candidate is found; preemption is not helpful for scheduling" pod="default/cspod-16"
I0506 15:10:45.636830      12 schedule_one.go:1044] "Unable to schedule pod; no fit; waiting" pod="default/cspod-16" err="0/5 nodes are available: 5 Insufficient cpu. preemption: 0/5 nodes are available: 5 No preemption victims found for incoming pod."
I0506 15:10:45.636891      12 schedule_one.go:314] "Successfully bound pod to node" pod="default/cspod-67" node="csnode-4" evaluatedNodes=5 feasibleNodes=1
I0506 15:10:45.636967      12 schedule_one.go:314] "Successfully bound pod to node" pod="default/cspod-68" node="csnode-4" evaluatedNodes=5 feasibleNodes=1
I0506 15:10:45.637354      12 preemption.go:264] "No preemption candidate is found; preemption is not helpful for scheduling" pod="default/cspod-17"
I0506 15:10:45.637391      12 schedule_one.go:1044] "Unable to schedule pod; no fit; waiting" pod="default/cspod-17" err="0/5 nodes are available: 5 Insufficient cpu. preemption: 0/5 nodes are available: 5 No preemption victims found for incoming pod."
I0506 15:10:45.637917      12 preemption.go:264] "No preemption candidate is found; preemption is not helpful for scheduling" pod="default/cspod-18"
I0506 15:10:45.637958      12 schedule_one.go:1044] "Unable to schedule pod; no fit; waiting" pod="default/cspod-18" err="0/5 nodes are available: 5 Insufficient cpu. preemption: 0/5 nodes are available: 5 No preemption victims found for incoming pod."
I0506 15:10:45.638555      12 preemption.go:264] "No preemption candidate is found; preemption is not helpful for scheduling" pod="default/cspod-19"
I0506 15:10:45.638588      12 schedule_one.go:1044] "Unable to schedule pod; no fit; waiting" pod="default/cspod-19" err="0/5 nodes are available: 5 Insufficient cpu. preemption: 0/5 nodes are available: 5 No preemption victims found for incoming pod."
I0506 15:10:45.639083      12 preemption.go:264] "No preemption candidate is found; preemption is not helpful for scheduling" pod="default/cspod-20"
I0506 15:10:45.639117      12 schedule_one.go:1044] "Unable to schedule pod; no fit; waiting" pod="default/cspod-20" err="0/5 nodes are available: 5 Insufficient cpu. preemption: 0/5 nodes are available: 5 No preemption victims found for incoming pod."
I0506 15:10:45.639569      12 preemption.go:264] "No preemption candidate is found; preemption is not helpful for scheduling" pod="default/cspod-21"
I0506 15:10:45.639601      12 schedule_one.go:1044] "Unable to schedule pod; no fit; waiting" pod="default/cspod-21" err="0/5 nodes are available: 5 Insufficient cpu. preemption: 0/5 nodes are available: 5 No preemption victims found for incoming pod."
I0506 15:10:45.640310      12 preemption.go:264] "No preemption candidate is found; preemption is not helpful for scheduling" pod="default/cspod-22"
I0506 15:10:45.640348      12 schedule_one.go:1044] "Unable to schedule pod; no fit; waiting" pod="default/cspod-22" err="0/5 nodes are available: 5 Insufficient cpu. preemption: 0/5 nodes are available: 5 No preemption victims found for incoming pod."
I0506 15:10:45.640876      12 preemption.go:264] "No preemption candidate is found; preemption is not helpful for scheduling" pod="default/cspod-23"
I0506 15:10:45.640913      12 schedule_one.go:1044] "Unable to schedule pod; no fit; waiting" pod="default/cspod-23" err="0/5 nodes are available: 5 Insufficient cpu. preemption: 0/5 nodes are available: 5 No preemption victims found for incoming pod."
I0506 15:10:45.641451      12 preemption.go:264] "No preemption candidate is found; preemption is not helpful for scheduling" pod="default/cspod-24"
I0506 15:10:45.641483      12 schedule_one.go:1044] "Unable to schedule pod; no fit; waiting" pod="default/cspod-24" err="0/5 nodes are available: 5 Insufficient cpu. preemption: 0/5 nodes are available: 5 No preemption victims found for incoming pod."
I0506 15:10:45.641965      12 preemption.go:264] "No preemption candidate is found; preemption is not helpful for scheduling" pod="default/cspod-25"
I0506 15:10:45.641998      12 schedule_one.go:1044] "Unable to schedule pod; no fit; waiting" pod="default/cspod-25" err="0/5 nodes are available: 5 Insufficient cpu. preemption: 0/5 nodes are available: 5 No preemption victims found for incoming pod."
I0506 15:10:45.642640      12 preemption.go:264] "No preemption candidate is found; preemption is not helpful for scheduling" pod="default/cspod-26"
I0506 15:10:45.642671      12 schedule_one.go:1044] "Unable to schedule pod; no fit; waiting" pod="default/cspod-26" err="0/5 nodes are available: 5 Insufficient cpu. preemption: 0/5 nodes are available: 5 No preemption victims found for incoming pod."
I0506 15:10:45.643472      12 preemption.go:264] "No preemption candidate is found; preemption is not helpful for scheduling" pod="default/cspod-27"
I0506 15:10:45.643506      12 schedule_one.go:1044] "Unable to schedule pod; no fit; waiting" pod="default/cspod-27" err="0/5 nodes are available: 5 Insufficient cpu. preemption: 0/5 nodes are available: 5 No preemption victims found for incoming pod."
I0506 15:10:45.643979      12 preemption.go:264] "No preemption candidate is found; preemption is not helpful for scheduling" pod="default/cspod-28"
I0506 15:10:45.644011      12 schedule_one.go:1044] "Unable to schedule pod; no fit; waiting" pod="default/cspod-28" err="0/5 nodes are available: 5 Insufficient cpu. preemption: 0/5 nodes are available: 5 No preemption victims found for incoming pod."
I0506 15:10:45.644512      12 preemption.go:264] "No preemption candidate is found; preemption is not helpful for scheduling" pod="default/cspod-29"
I0506 15:10:45.644544      12 schedule_one.go:1044] "Unable to schedule pod; no fit; waiting" pod="default/cspod-29" err="0/5 nodes are available: 5 Insufficient cpu. preemption: 0/5 nodes are available: 5 No preemption victims found for incoming pod."
I0506 15:10:45.645047      12 preemption.go:264] "No preemption candidate is found; preemption is not helpful for scheduling" pod="default/cspod-30"
I0506 15:10:45.645079      12 schedule_one.go:1044] "Unable to schedule pod; no fit; waiting" pod="default/cspod-30" err="0/5 nodes are available: 5 Insufficient cpu. preemption: 0/5 nodes are available: 5 No preemption victims found for incoming pod."
I0506 15:10:45.645543      12 preemption.go:264] "No preemption candidate is found; preemption is not helpful for scheduling" pod="default/cspod-31"
I0506 15:10:45.645577      12 schedule_one.go:1044] "Unable to schedule pod; no fit; waiting" pod="default/cspod-31" err="0/5 nodes are available: 5 Insufficient cpu. preemption: 0/5 nodes are available: 5 No preemption victims found for incoming pod."
I0506 15:10:45.646060      12 preemption.go:264] "No preemption candidate is found; preemption is not helpful for scheduling" pod="default/cspod-32"
I0506 15:10:45.646093      12 schedule_one.go:1044] "Unable to schedule pod; no fit; waiting" pod="default/cspod-32" err="0/5 nodes are available: 5 Insufficient cpu. preemption: 0/5 nodes are available: 5 No preemption victims found for incoming pod."
I0506 15:10:45.646553      12 preemption.go:264] "No preemption candidate is found; preemption is not helpful for scheduling" pod="default/cspod-33"
I0506 15:10:45.646586      12 schedule_one.go:1044] "Unable to schedule pod; no fit; waiting" pod="default/cspod-33" err="0/5 nodes are available: 5 Insufficient cpu. preemption: 0/5 nodes are available: 5 No preemption victims found for incoming pod."
I0506 15:10:45.647041      12 preemption.go:264] "No preemption candidate is found; preemption is not helpful for scheduling" pod="default/cspod-34"
I0506 15:10:45.647075      12 schedule_one.go:1044] "Unable to schedule pod; no fit; waiting" pod="default/cspod-34" err="0/5 nodes are available: 5 Insufficient cpu. preemption: 0/5 nodes are available: 5 No preemption victims found for incoming pod."
I0506 15:10:45.647589      12 preemption.go:264] "No preemption candidate is found; preemption is not helpful for scheduling" pod="default/cspod-35"
I0506 15:10:45.647623      12 schedule_one.go:1044] "Unable to schedule pod; no fit; waiting" pod="default/cspod-35" err="0/5 nodes are available: 5 Insufficient cpu. preemption: 0/5 nodes are available: 5 No preemption victims found for incoming pod."
I0506 15:10:45.648091      12 preemption.go:264] "No preemption candidate is found; preemption is not helpful for scheduling" pod="default/cspod-36"
I0506 15:10:45.648124      12 schedule_one.go:1044] "Unable to schedule pod; no fit; waiting" pod="default/cspod-36" err="0/5 nodes are available: 5 Insufficient cpu. preemption: 0/5 nodes are available: 5 No preemption victims found for incoming pod."
I0506 15:10:45.648623      12 preemption.go:264] "No preemption candidate is found; preemption is not helpful for scheduling" pod="default/cspod-37"
I0506 15:10:45.648658      12 schedule_one.go:1044] "Unable to schedule pod; no fit; waiting" pod="default/cspod-37" err="0/5 nodes are available: 5 Insufficient cpu. preemption: 0/5 nodes are available: 5 No preemption victims found for incoming pod."
I0506 15:10:45.649116      12 preemption.go:264] "No preemption candidate is found; preemption is not helpful for scheduling" pod="default/cspod-38"
I0506 15:10:45.649147      12 schedule_one.go:1044] "Unable to schedule pod; no fit; waiting" pod="default/cspod-38" err="0/5 nodes are available: 5 Insufficient cpu. preemption: 0/5 nodes are available: 5 No preemption victims found for incoming pod."
I0506 15:10:45.649640      12 preemption.go:264] "No preemption candidate is found; preemption is not helpful for scheduling" pod="default/cspod-39"
I0506 15:10:45.649673      12 schedule_one.go:1044] "Unable to schedule pod; no fit; waiting" pod="default/cspod-39" err="0/5 nodes are available: 5 Insufficient cpu. preemption: 0/5 nodes are available: 5 No preemption victims found for incoming pod."
I0506 15:10:45.650134      12 preemption.go:264] "No preemption candidate is found; preemption is not helpful for scheduling" pod="default/cspod-40"
I0506 15:10:45.650166      12 schedule_one.go:1044] "Unable to schedule pod; no fit; waiting" pod="default/cspod-40" err="0/5 nodes are available: 5 Insufficient cpu. preemption: 0/5 nodes are available: 5 No preemption victims found for incoming pod."
I0506 15:10:45.650677      12 preemption.go:264] "No preemption candidate is found; preemption is not helpful for scheduling" pod="default/cspod-41"
I0506 15:10:45.650712      12 schedule_one.go:1044] "Unable to schedule pod; no fit; waiting" pod="default/cspod-41" err="0/5 nodes are available: 5 Insufficient cpu. preemption: 0/5 nodes are available: 5 No preemption victims found for incoming pod."
I0506 15:10:45.651159      12 preemption.go:264] "No preemption candidate is found; preemption is not helpful for scheduling" pod="default/cspod-42"
I0506 15:10:45.651191      12 schedule_one.go:1044] "Unable to schedule pod; no fit; waiting" pod="default/cspod-42" err="0/5 nodes are available: 5 Insufficient cpu. preemption: 0/5 nodes are available: 5 No preemption victims found for incoming pod."
I0506 15:10:45.651679      12 preemption.go:264] "No preemption candidate is found; preemption is not helpful for scheduling" pod="default/cspod-43"
I0506 15:10:45.651711      12 schedule_one.go:1044] "Unable to schedule pod; no fit; waiting" pod="default/cspod-43" err="0/5 nodes are available: 5 Insufficient cpu. preemption: 0/5 nodes are available: 5 No preemption victims found for incoming pod."
I0506 15:10:45.652205      12 preemption.go:264] "No preemption candidate is found; preemption is not helpful for scheduling" pod="default/cspod-44"
I0506 15:10:45.652238      12 schedule_one.go:1044] "Unable to schedule pod; no fit; waiting" pod="default/cspod-44" err="0/5 nodes are available: 5 Insufficient cpu. preemption: 0/5 nodes are available: 5 No preemption victims found for incoming pod."
I0506 15:10:45.652803      12 preemption.go:264] "No preemption candidate is found; preemption is not helpful for scheduling" pod="default/cspod-45"
I0506 15:10:45.652837      12 schedule_one.go:1044] "Unable to schedule pod; no fit; waiting" pod="default/cspod-45" err="0/5 nodes are available: 5 Insufficient cpu. preemption: 0/5 nodes are available: 5 No preemption victims found for incoming pod."
I0506 15:10:45.653358      12 preemption.go:264] "No preemption candidate is found; preemption is not helpful for scheduling" pod="default/cspod-46"
I0506 15:10:45.653395      12 schedule_one.go:1044] "Unable to schedule pod; no fit; waiting" pod="default/cspod-46" err="0/5 nodes are available: 5 Insufficient cpu. preemption: 0/5 nodes are available: 5 No preemption victims found for incoming pod."
I0506 15:10:45.653915      12 preemption.go:264] "No preemption candidate is found; preemption is not helpful for scheduling" pod="default/cspod-47"
I0506 15:10:45.653952      12 schedule_one.go:1044] "Unable to schedule pod; no fit; waiting" pod="default/cspod-47" err="0/5 nodes are available: 5 Insufficient cpu. preemption: 0/5 nodes are available: 5 No preemption victims found for incoming pod."
I0506 15:10:45.654501      12 preemption.go:264] "No preemption candidate is found; preemption is not helpful for scheduling" pod="default/cspod-48"
I0506 15:10:45.654536      12 schedule_one.go:1044] "Unable to schedule pod; no fit; waiting" pod="default/cspod-48" err="0/5 nodes are available: 5 Insufficient cpu. preemption: 0/5 nodes are available: 5 No preemption victims found for incoming pod."
I0506 15:10:45.655007      12 preemption.go:264] "No preemption candidate is found; preemption is not helpful for scheduling" pod="default/cspod-49"
I0506 15:10:45.655039      12 schedule_one.go:1044] "Unable to schedule pod; no fit; waiting" pod="default/cspod-49" err="0/5 nodes are available: 5 Insufficient cpu. preemption: 0/5 nodes are available: 5 No preemption victims found for incoming pod."
I0506 15:10:45.655546      12 preemption.go:264] "No preemption candidate is found; preemption is not helpful for scheduling" pod="default/cspod-50"
I0506 15:10:45.655578      12 schedule_one.go:1044] "Unable to schedule pod; no fit; waiting" pod="default/cspod-50" err="0/5 nodes are available: 5 Insufficient cpu. preemption: 0/5 nodes are available: 5 No preemption victims found for incoming pod."
I0506 15:10:45.656082      12 preemption.go:264] "No preemption candidate is found; preemption is not helpful for scheduling" pod="default/cspod-51"
I0506 15:10:45.656133      12 schedule_one.go:1044] "Unable to schedule pod; no fit; waiting" pod="default/cspod-51" err="0/5 nodes are available: 5 Insufficient cpu. preemption: 0/5 nodes are available: 5 No preemption victims found for incoming pod."
I0506 15:10:45.656673      12 preemption.go:264] "No preemption candidate is found; preemption is not helpful for scheduling" pod="default/cspod-52"
I0506 15:10:45.656709      12 schedule_one.go:1044] "Unable to schedule pod; no fit; waiting" pod="default/cspod-52" err="0/5 nodes are available: 5 Insufficient cpu. preemption: 0/5 nodes are available: 5 No preemption victims found for incoming pod."
I0506 15:10:45.658084      12 preemption.go:264] "No preemption candidate is found; preemption is not helpful for scheduling" pod="default/cspod-53"
I0506 15:10:45.658118      12 schedule_one.go:1044] "Unable to schedule pod; no fit; waiting" pod="default/cspod-53" err="0/5 nodes are available: 5 Insufficient cpu. preemption: 0/5 nodes are available: 5 No preemption victims found for incoming pod."
I0506 15:10:45.658611      12 preemption.go:264] "No preemption candidate is found; preemption is not helpful for scheduling" pod="default/cspod-54"
I0506 15:10:45.658643      12 schedule_one.go:1044] "Unable to schedule pod; no fit; waiting" pod="default/cspod-54" err="0/5 nodes are available: 5 Insufficient cpu. preemption: 0/5 nodes are available: 5 No preemption victims found for incoming pod."
E0506 15:10:45.663645      12 event.go:368] "Unable to write event (may retry after sleeping)" err="0-length response with status code: 201 and content type: application/vnd.kubernetes.protobuf" event="&Event{ObjectMeta:{cspod-1.18ad028e7e2c5395  default    0 0001-01-01 00:00:00 +0000 UTC <nil> <nil> map[] map[] [] [] []},InvolvedObject:ObjectReference{Kind:Pod,Namespace:default,Name:cspod-1,UID:cspod-1-uid,APIVersion:v1,ResourceVersion:7,FieldPath:,},Reason:Scheduled,Message:Successfully assigned default/cspod-1 to csnode-0,Source:EventSource{Component:default-scheduler,Host:,},FirstTimestamp:2026-05-06 15:10:38.906659733 +0000 UTC m=+7.311898370,LastTimestamp:2026-05-06 15:10:38.906659733 +0000 UTC m=+7.311898370,Count:1,Type:Normal,EventTime:0001-01-01 00:00:00 +0000 UTC,Series:nil,Action:,Related:nil,ReportingController:default-scheduler,ReportingInstance:,}"
I0506 15:10:49.662702      12 schedule_one.go:314] "Successfully bound pod to node" pod="default/cspod-69" node="csnode-3" evaluatedNodes=5 feasibleNodes=2
I0506 15:10:49.662809      12 preemption.go:264] "No preemption candidate is found; preemption is not helpful for scheduling" pod="default/cspod-18"
I0506 15:10:49.662851      12 schedule_one.go:1044] "Unable to schedule pod; no fit; waiting" pod="default/cspod-18" err="0/5 nodes are available: 5 Insufficient cpu. preemption: 0/5 nodes are available: 5 No preemption victims found for incoming pod."
I0506 15:10:49.663016      12 schedule_one.go:314] "Successfully bound pod to node" pod="default/cspod-16" node="csnode-3" evaluatedNodes=5 feasibleNodes=2
I0506 15:10:49.663085      12 schedule_one.go:314] "Successfully bound pod to node" pod="default/cspod-17" node="csnode-2" evaluatedNodes=5 feasibleNodes=1
I0506 15:10:49.663435      12 preemption.go:264] "No preemption candidate is found; preemption is not helpful for scheduling" pod="default/cspod-19"
I0506 15:10:49.663473      12 schedule_one.go:1044] "Unable to schedule pod; no fit; waiting" pod="default/cspod-19" err="0/5 nodes are available: 5 Insufficient cpu. preemption: 0/5 nodes are available: 5 No preemption victims found for incoming pod."
I0506 15:10:49.664025      12 preemption.go:264] "No preemption candidate is found; preemption is not helpful for scheduling" pod="default/cspod-20"
I0506 15:10:49.664065      12 schedule_one.go:1044] "Unable to schedule pod; no fit; waiting" pod="default/cspod-20" err="0/5 nodes are available: 5 Insufficient cpu. preemption: 0/5 nodes are available: 5 No preemption victims found for incoming pod."
I0506 15:10:49.664662      12 preemption.go:264] "No preemption candidate is found; preemption is not helpful for scheduling" pod="default/cspod-21"
I0506 15:10:49.664703      12 schedule_one.go:1044] "Unable to schedule pod; no fit; waiting" pod="default/cspod-21" err="0/5 nodes are available: 5 Insufficient cpu. preemption: 0/5 nodes are available: 5 No preemption victims found for incoming pod."
I0506 15:10:49.665318      12 preemption.go:264] "No preemption candidate is found; preemption is not helpful for scheduling" pod="default/cspod-22"
I0506 15:10:49.665358      12 schedule_one.go:1044] "Unable to schedule pod; no fit; waiting" pod="default/cspod-22" err="0/5 nodes are available: 5 Insufficient cpu. preemption: 0/5 nodes are available: 5 No preemption victims found for incoming pod."
I0506 15:10:49.665961      12 preemption.go:264] "No preemption candidate is found; preemption is not helpful for scheduling" pod="default/cspod-23"
I0506 15:10:49.665997      12 schedule_one.go:1044] "Unable to schedule pod; no fit; waiting" pod="default/cspod-23" err="0/5 nodes are available: 5 Insufficient cpu. preemption: 0/5 nodes are available: 5 No preemption victims found for incoming pod."
I0506 15:10:49.666504      12 preemption.go:264] "No preemption candidate is found; preemption is not helpful for scheduling" pod="default/cspod-24"
I0506 15:10:49.666540      12 schedule_one.go:1044] "Unable to schedule pod; no fit; waiting" pod="default/cspod-24" err="0/5 nodes are available: 5 Insufficient cpu. preemption: 0/5 nodes are available: 5 No preemption victims found for incoming pod."
I0506 15:10:49.667229      12 preemption.go:264] "No preemption candidate is found; preemption is not helpful for scheduling" pod="default/cspod-25"
I0506 15:10:49.667266      12 schedule_one.go:1044] "Unable to schedule pod; no fit; waiting" pod="default/cspod-25" err="0/5 nodes are available: 5 Insufficient cpu. preemption: 0/5 nodes are available: 5 No preemption victims found for incoming pod."
I0506 15:10:49.667757      12 preemption.go:264] "No preemption candidate is found; preemption is not helpful for scheduling" pod="default/cspod-26"
I0506 15:10:49.667794      12 schedule_one.go:1044] "Unable to schedule pod; no fit; waiting" pod="default/cspod-26" err="0/5 nodes are available: 5 Insufficient cpu. preemption: 0/5 nodes are available: 5 No preemption victims found for incoming pod."
I0506 15:10:49.668389      12 preemption.go:264] "No preemption candidate is found; preemption is not helpful for scheduling" pod="default/cspod-27"
I0506 15:10:49.668429      12 schedule_one.go:1044] "Unable to schedule pod; no fit; waiting" pod="default/cspod-27" err="0/5 nodes are available: 5 Insufficient cpu. preemption: 0/5 nodes are available: 5 No preemption victims found for incoming pod."
I0506 15:10:49.669023      12 preemption.go:264] "No preemption candidate is found; preemption is not helpful for scheduling" pod="default/cspod-28"
I0506 15:10:49.669066      12 schedule_one.go:1044] "Unable to schedule pod; no fit; waiting" pod="default/cspod-28" err="0/5 nodes are available: 5 Insufficient cpu. preemption: 0/5 nodes are available: 5 No preemption victims found for incoming pod."
I0506 15:10:49.669603      12 preemption.go:264] "No preemption candidate is found; preemption is not helpful for scheduling" pod="default/cspod-29"
I0506 15:10:49.669642      12 schedule_one.go:1044] "Unable to schedule pod; no fit; waiting" pod="default/cspod-29" err="0/5 nodes are available: 5 Insufficient cpu. preemption: 0/5 nodes are available: 5 No preemption victims found for incoming pod."
I0506 15:10:49.670157      12 preemption.go:264] "No preemption candidate is found; preemption is not helpful for scheduling" pod="default/cspod-30"
I0506 15:10:49.670193      12 schedule_one.go:1044] "Unable to schedule pod; no fit; waiting" pod="default/cspod-30" err="0/5 nodes are available: 5 Insufficient cpu. preemption: 0/5 nodes are available: 5 No preemption victims found for incoming pod."
I0506 15:10:49.670725      12 preemption.go:264] "No preemption candidate is found; preemption is not helpful for scheduling" pod="default/cspod-31"
I0506 15:10:49.670761      12 schedule_one.go:1044] "Unable to schedule pod; no fit; waiting" pod="default/cspod-31" err="0/5 nodes are available: 5 Insufficient cpu. preemption: 0/5 nodes are available: 5 No preemption victims found for incoming pod."
I0506 15:10:49.671326      12 preemption.go:264] "No preemption candidate is found; preemption is not helpful for scheduling" pod="default/cspod-32"
I0506 15:10:49.671363      12 schedule_one.go:1044] "Unable to schedule pod; no fit; waiting" pod="default/cspod-32" err="0/5 nodes are available: 5 Insufficient cpu. preemption: 0/5 nodes are available: 5 No preemption victims found for incoming pod."
I0506 15:10:49.671854      12 preemption.go:264] "No preemption candidate is found; preemption is not helpful for scheduling" pod="default/cspod-33"
I0506 15:10:49.671888      12 schedule_one.go:1044] "Unable to schedule pod; no fit; waiting" pod="default/cspod-33" err="0/5 nodes are available: 5 Insufficient cpu. preemption: 0/5 nodes are available: 5 No preemption victims found for incoming pod."
I0506 15:10:49.672387      12 preemption.go:264] "No preemption candidate is found; preemption is not helpful for scheduling" pod="default/cspod-34"
I0506 15:10:49.672421      12 schedule_one.go:1044] "Unable to schedule pod; no fit; waiting" pod="default/cspod-34" err="0/5 nodes are available: 5 Insufficient cpu. preemption: 0/5 nodes are available: 5 No preemption victims found for incoming pod."
I0506 15:10:49.672988      12 preemption.go:264] "No preemption candidate is found; preemption is not helpful for scheduling" pod="default/cspod-35"
I0506 15:10:49.673022      12 schedule_one.go:1044] "Unable to schedule pod; no fit; waiting" pod="default/cspod-35" err="0/5 nodes are available: 5 Insufficient cpu. preemption: 0/5 nodes are available: 5 No preemption victims found for incoming pod."
I0506 15:10:49.673530      12 preemption.go:264] "No preemption candidate is found; preemption is not helpful for scheduling" pod="default/cspod-36"
I0506 15:10:49.673565      12 schedule_one.go:1044] "Unable to schedule pod; no fit; waiting" pod="default/cspod-36" err="0/5 nodes are available: 5 Insufficient cpu. preemption: 0/5 nodes are available: 5 No preemption victims found for incoming pod."
I0506 15:10:49.674091      12 preemption.go:264] "No preemption candidate is found; preemption is not helpful for scheduling" pod="default/cspod-37"
I0506 15:10:49.674124      12 schedule_one.go:1044] "Unable to schedule pod; no fit; waiting" pod="default/cspod-37" err="0/5 nodes are available: 5 Insufficient cpu. preemption: 0/5 nodes are available: 5 No preemption victims found for incoming pod."
I0506 15:10:49.674630      12 preemption.go:264] "No preemption candidate is found; preemption is not helpful for scheduling" pod="default/cspod-38"
I0506 15:10:49.674664      12 schedule_one.go:1044] "Unable to schedule pod; no fit; waiting" pod="default/cspod-38" err="0/5 nodes are available: 5 Insufficient cpu. preemption: 0/5 nodes are available: 5 No preemption victims found for incoming pod."
I0506 15:10:49.675187      12 preemption.go:264] "No preemption candidate is found; preemption is not helpful for scheduling" pod="default/cspod-39"
I0506 15:10:49.675223      12 schedule_one.go:1044] "Unable to schedule pod; no fit; waiting" pod="default/cspod-39" err="0/5 nodes are available: 5 Insufficient cpu. preemption: 0/5 nodes are available: 5 No preemption victims found for incoming pod."
I0506 15:10:49.675778      12 preemption.go:264] "No preemption candidate is found; preemption is not helpful for scheduling" pod="default/cspod-40"
I0506 15:10:49.675815      12 schedule_one.go:1044] "Unable to schedule pod; no fit; waiting" pod="default/cspod-40" err="0/5 nodes are available: 5 Insufficient cpu. preemption: 0/5 nodes are available: 5 No preemption victims found for incoming pod."
I0506 15:10:49.676289      12 preemption.go:264] "No preemption candidate is found; preemption is not helpful for scheduling" pod="default/cspod-41"
I0506 15:10:49.676332      12 schedule_one.go:1044] "Unable to schedule pod; no fit; waiting" pod="default/cspod-41" err="0/5 nodes are available: 5 Insufficient cpu. preemption: 0/5 nodes are available: 5 No preemption victims found for incoming pod."
I0506 15:10:49.676856      12 preemption.go:264] "No preemption candidate is found; preemption is not helpful for scheduling" pod="default/cspod-42"
I0506 15:10:49.676895      12 schedule_one.go:1044] "Unable to schedule pod; no fit; waiting" pod="default/cspod-42" err="0/5 nodes are available: 5 Insufficient cpu. preemption: 0/5 nodes are available: 5 No preemption victims found for incoming pod."
I0506 15:10:49.677450      12 preemption.go:264] "No preemption candidate is found; preemption is not helpful for scheduling" pod="default/cspod-43"
I0506 15:10:49.677485      12 schedule_one.go:1044] "Unable to schedule pod; no fit; waiting" pod="default/cspod-43" err="0/5 nodes are available: 5 Insufficient cpu. preemption: 0/5 nodes are available: 5 No preemption victims found for incoming pod."
I0506 15:10:49.677984      12 preemption.go:264] "No preemption candidate is found; preemption is not helpful for scheduling" pod="default/cspod-44"
I0506 15:10:49.678022      12 schedule_one.go:1044] "Unable to schedule pod; no fit; waiting" pod="default/cspod-44" err="0/5 nodes are available: 5 Insufficient cpu. preemption: 0/5 nodes are available: 5 No preemption victims found for incoming pod."
I0506 15:10:49.678502      12 preemption.go:264] "No preemption candidate is found; preemption is not helpful for scheduling" pod="default/cspod-45"
I0506 15:10:49.678535      12 schedule_one.go:1044] "Unable to schedule pod; no fit; waiting" pod="default/cspod-45" err="0/5 nodes are available: 5 Insufficient cpu. preemption: 0/5 nodes are available: 5 No preemption victims found for incoming pod."
I0506 15:10:49.679039      12 preemption.go:264] "No preemption candidate is found; preemption is not helpful for scheduling" pod="default/cspod-46"
I0506 15:10:49.679073      12 schedule_one.go:1044] "Unable to schedule pod; no fit; waiting" pod="default/cspod-46" err="0/5 nodes are available: 5 Insufficient cpu. preemption: 0/5 nodes are available: 5 No preemption victims found for incoming pod."
I0506 15:10:49.679584      12 preemption.go:264] "No preemption candidate is found; preemption is not helpful for scheduling" pod="default/cspod-47"
I0506 15:10:49.679625      12 schedule_one.go:1044] "Unable to schedule pod; no fit; waiting" pod="default/cspod-47" err="0/5 nodes are available: 5 Insufficient cpu. preemption: 0/5 nodes are available: 5 No preemption victims found for incoming pod."
I0506 15:10:49.680173      12 preemption.go:264] "No preemption candidate is found; preemption is not helpful for scheduling" pod="default/cspod-48"
I0506 15:10:49.680216      12 schedule_one.go:1044] "Unable to schedule pod; no fit; waiting" pod="default/cspod-48" err="0/5 nodes are available: 5 Insufficient cpu. preemption: 0/5 nodes are available: 5 No preemption victims found for incoming pod."
I0506 15:10:49.680915      12 preemption.go:264] "No preemption candidate is found; preemption is not helpful for scheduling" pod="default/cspod-49"
I0506 15:10:49.680948      12 schedule_one.go:1044] "Unable to schedule pod; no fit; waiting" pod="default/cspod-49" err="0/5 nodes are available: 5 Insufficient cpu. preemption: 0/5 nodes are available: 5 No preemption victims found for incoming pod."
I0506 15:10:49.681454      12 preemption.go:264] "No preemption candidate is found; preemption is not helpful for scheduling" pod="default/cspod-50"
I0506 15:10:49.681488      12 schedule_one.go:1044] "Unable to schedule pod; no fit; waiting" pod="default/cspod-50" err="0/5 nodes are available: 5 Insufficient cpu. preemption: 0/5 nodes are available: 5 No preemption victims found for incoming pod."
I0506 15:10:49.681950      12 preemption.go:264] "No preemption candidate is found; preemption is not helpful for scheduling" pod="default/cspod-51"
I0506 15:10:49.681981      12 schedule_one.go:1044] "Unable to schedule pod; no fit; waiting" pod="default/cspod-51" err="0/5 nodes are available: 5 Insufficient cpu. preemption: 0/5 nodes are available: 5 No preemption victims found for incoming pod."
I0506 15:10:49.682512      12 preemption.go:264] "No preemption candidate is found; preemption is not helpful for scheduling" pod="default/cspod-52"
I0506 15:10:49.682547      12 schedule_one.go:1044] "Unable to schedule pod; no fit; waiting" pod="default/cspod-52" err="0/5 nodes are available: 5 Insufficient cpu. preemption: 0/5 nodes are available: 5 No preemption victims found for incoming pod."
I0506 15:10:49.683084      12 preemption.go:264] "No preemption candidate is found; preemption is not helpful for scheduling" pod="default/cspod-53"
I0506 15:10:49.683128      12 schedule_one.go:1044] "Unable to schedule pod; no fit; waiting" pod="default/cspod-53" err="0/5 nodes are available: 5 Insufficient cpu. preemption: 0/5 nodes are available: 5 No preemption victims found for incoming pod."
I0506 15:10:49.683693      12 preemption.go:264] "No preemption candidate is found; preemption is not helpful for scheduling" pod="default/cspod-54"
I0506 15:10:49.683727      12 schedule_one.go:1044] "Unable to schedule pod; no fit; waiting" pod="default/cspod-54" err="0/5 nodes are available: 5 Insufficient cpu. preemption: 0/5 nodes are available: 5 No preemption victims found for incoming pod."
I0506 15:10:49.702763      12 schedule_one.go:314] "Successfully bound pod to node" pod="default/cspod-18" node="csnode-4" evaluatedNodes=5 feasibleNodes=1
I0506 15:10:49.702891      12 preemption.go:264] "No preemption candidate is found; preemption is not helpful for scheduling" pod="default/cspod-22"
I0506 15:10:49.702912      12 schedule_one.go:314] "Successfully bound pod to node" pod="default/cspod-19" node="csnode-4" evaluatedNodes=5 feasibleNodes=1
I0506 15:10:49.702934      12 schedule_one.go:1044] "Unable to schedule pod; no fit; waiting" pod="default/cspod-22" err="0/5 nodes are available: 5 Insufficient cpu. preemption: 0/5 nodes are available: 5 No preemption victims found for incoming pod."
I0506 15:10:49.703063      12 schedule_one.go:314] "Successfully bound pod to node" pod="default/cspod-20" node="csnode-4" evaluatedNodes=5 feasibleNodes=1
I0506 15:10:49.703171      12 schedule_one.go:314] "Successfully bound pod to node" pod="default/cspod-21" node="csnode-4" evaluatedNodes=5 feasibleNodes=1
I0506 15:10:49.703529      12 preemption.go:264] "No preemption candidate is found; preemption is not helpful for scheduling" pod="default/cspod-23"
I0506 15:10:49.703571      12 schedule_one.go:1044] "Unable to schedule pod; no fit; waiting" pod="default/cspod-23" err="0/5 nodes are available: 5 Insufficient cpu. preemption: 0/5 nodes are available: 5 No preemption victims found for incoming pod."
I0506 15:10:49.704144      12 preemption.go:264] "No preemption candidate is found; preemption is not helpful for scheduling" pod="default/cspod-24"
I0506 15:10:49.704180      12 schedule_one.go:1044] "Unable to schedule pod; no fit; waiting" pod="default/cspod-24" err="0/5 nodes are available: 5 Insufficient cpu. preemption: 0/5 nodes are available: 5 No preemption victims found for incoming pod."
I0506 15:10:49.704874      12 preemption.go:264] "No preemption candidate is found; preemption is not helpful for scheduling" pod="default/cspod-25"
I0506 15:10:49.704916      12 schedule_one.go:1044] "Unable to schedule pod; no fit; waiting" pod="default/cspod-25" err="0/5 nodes are available: 5 Insufficient cpu. preemption: 0/5 nodes are available: 5 No preemption victims found for incoming pod."
I0506 15:10:49.705512      12 preemption.go:264] "No preemption candidate is found; preemption is not helpful for scheduling" pod="default/cspod-26"
I0506 15:10:49.705552      12 schedule_one.go:1044] "Unable to schedule pod; no fit; waiting" pod="default/cspod-26" err="0/5 nodes are available: 5 Insufficient cpu. preemption: 0/5 nodes are available: 5 No preemption victims found for incoming pod."
I0506 15:10:49.706197      12 preemption.go:264] "No preemption candidate is found; preemption is not helpful for scheduling" pod="default/cspod-27"
I0506 15:10:49.706234      12 schedule_one.go:1044] "Unable to schedule pod; no fit; waiting" pod="default/cspod-27" err="0/5 nodes are available: 5 Insufficient cpu. preemption: 0/5 nodes are available: 5 No preemption victims found for incoming pod."
I0506 15:10:49.706815      12 preemption.go:264] "No preemption candidate is found; preemption is not helpful for scheduling" pod="default/cspod-28"
I0506 15:10:49.706856      12 schedule_one.go:1044] "Unable to schedule pod; no fit; waiting" pod="default/cspod-28" err="0/5 nodes are available: 5 Insufficient cpu. preemption: 0/5 nodes are available: 5 No preemption victims found for incoming pod."
I0506 15:10:49.707459      12 preemption.go:264] "No preemption candidate is found; preemption is not helpful for scheduling" pod="default/cspod-29"
I0506 15:10:49.707498      12 schedule_one.go:1044] "Unable to schedule pod; no fit; waiting" pod="default/cspod-29" err="0/5 nodes are available: 5 Insufficient cpu. preemption: 0/5 nodes are available: 5 No preemption victims found for incoming pod."
I0506 15:10:49.708104      12 preemption.go:264] "No preemption candidate is found; preemption is not helpful for scheduling" pod="default/cspod-30"
I0506 15:10:49.708148      12 schedule_one.go:1044] "Unable to schedule pod; no fit; waiting" pod="default/cspod-30" err="0/5 nodes are available: 5 Insufficient cpu. preemption: 0/5 nodes are available: 5 No preemption victims found for incoming pod."
I0506 15:10:49.708749      12 preemption.go:264] "No preemption candidate is found; preemption is not helpful for scheduling" pod="default/cspod-31"
I0506 15:10:49.708785      12 schedule_one.go:1044] "Unable to schedule pod; no fit; waiting" pod="default/cspod-31" err="0/5 nodes are available: 5 Insufficient cpu. preemption: 0/5 nodes are available: 5 No preemption victims found for incoming pod."
I0506 15:10:49.709352      12 preemption.go:264] "No preemption candidate is found; preemption is not helpful for scheduling" pod="default/cspod-32"
I0506 15:10:49.709391      12 schedule_one.go:1044] "Unable to schedule pod; no fit; waiting" pod="default/cspod-32" err="0/5 nodes are available: 5 Insufficient cpu. preemption: 0/5 nodes are available: 5 No preemption victims found for incoming pod."
I0506 15:10:49.709922      12 preemption.go:264] "No preemption candidate is found; preemption is not helpful for scheduling" pod="default/cspod-33"
I0506 15:10:49.709957      12 schedule_one.go:1044] "Unable to schedule pod; no fit; waiting" pod="default/cspod-33" err="0/5 nodes are available: 5 Insufficient cpu. preemption: 0/5 nodes are available: 5 No preemption victims found for incoming pod."
I0506 15:10:49.710445      12 preemption.go:264] "No preemption candidate is found; preemption is not helpful for scheduling" pod="default/cspod-34"
I0506 15:10:49.710482      12 schedule_one.go:1044] "Unable to schedule pod; no fit; waiting" pod="default/cspod-34" err="0/5 nodes are available: 5 Insufficient cpu. preemption: 0/5 nodes are available: 5 No preemption victims found for incoming pod."
I0506 15:10:49.711028      12 preemption.go:264] "No preemption candidate is found; preemption is not helpful for scheduling" pod="default/cspod-35"
I0506 15:10:49.711064      12 schedule_one.go:1044] "Unable to schedule pod; no fit; waiting" pod="default/cspod-35" err="0/5 nodes are available: 5 Insufficient cpu. preemption: 0/5 nodes are available: 5 No preemption victims found for incoming pod."
I0506 15:10:49.711583      12 preemption.go:264] "No preemption candidate is found; preemption is not helpful for scheduling" pod="default/cspod-36"
I0506 15:10:49.711618      12 schedule_one.go:1044] "Unable to schedule pod; no fit; waiting" pod="default/cspod-36" err="0/5 nodes are available: 5 Insufficient cpu. preemption: 0/5 nodes are available: 5 No preemption victims found for incoming pod."
I0506 15:10:49.712151      12 preemption.go:264] "No preemption candidate is found; preemption is not helpful for scheduling" pod="default/cspod-37"
I0506 15:10:49.712195      12 schedule_one.go:1044] "Unable to schedule pod; no fit; waiting" pod="default/cspod-37" err="0/5 nodes are available: 5 Insufficient cpu. preemption: 0/5 nodes are available: 5 No preemption victims found for incoming pod."
I0506 15:10:49.712657      12 preemption.go:264] "No preemption candidate is found; preemption is not helpful for scheduling" pod="default/cspod-38"
I0506 15:10:49.712689      12 schedule_one.go:1044] "Unable to schedule pod; no fit; waiting" pod="default/cspod-38" err="0/5 nodes are available: 5 Insufficient cpu. preemption: 0/5 nodes are available: 5 No preemption victims found for incoming pod."
I0506 15:10:49.713274      12 preemption.go:264] "No preemption candidate is found; preemption is not helpful for scheduling" pod="default/cspod-39"
I0506 15:10:49.713309      12 schedule_one.go:1044] "Unable to schedule pod; no fit; waiting" pod="default/cspod-39" err="0/5 nodes are available: 5 Insufficient cpu. preemption: 0/5 nodes are available: 5 No preemption victims found for incoming pod."
I0506 15:10:49.713796      12 preemption.go:264] "No preemption candidate is found; preemption is not helpful for scheduling" pod="default/cspod-40"
I0506 15:10:49.713831      12 schedule_one.go:1044] "Unable to schedule pod; no fit; waiting" pod="default/cspod-40" err="0/5 nodes are available: 5 Insufficient cpu. preemption: 0/5 nodes are available: 5 No preemption victims found for incoming pod."
I0506 15:10:49.714342      12 preemption.go:264] "No preemption candidate is found; preemption is not helpful for scheduling" pod="default/cspod-41"
I0506 15:10:49.714377      12 schedule_one.go:1044] "Unable to schedule pod; no fit; waiting" pod="default/cspod-41" err="0/5 nodes are available: 5 Insufficient cpu. preemption: 0/5 nodes are available: 5 No preemption victims found for incoming pod."
I0506 15:10:49.714971      12 preemption.go:264] "No preemption candidate is found; preemption is not helpful for scheduling" pod="default/cspod-42"
I0506 15:10:49.715005      12 schedule_one.go:1044] "Unable to schedule pod; no fit; waiting" pod="default/cspod-42" err="0/5 nodes are available: 5 Insufficient cpu. preemption: 0/5 nodes are available: 5 No preemption victims found for incoming pod."
I0506 15:10:49.715546      12 preemption.go:264] "No preemption candidate is found; preemption is not helpful for scheduling" pod="default/cspod-43"
I0506 15:10:49.715578      12 schedule_one.go:1044] "Unable to schedule pod; no fit; waiting" pod="default/cspod-43" err="0/5 nodes are available: 5 Insufficient cpu. preemption: 0/5 nodes are available: 5 No preemption victims found for incoming pod."
I0506 15:10:49.716054      12 preemption.go:264] "No preemption candidate is found; preemption is not helpful for scheduling" pod="default/cspod-44"
I0506 15:10:49.716087      12 schedule_one.go:1044] "Unable to schedule pod; no fit; waiting" pod="default/cspod-44" err="0/5 nodes are available: 5 Insufficient cpu. preemption: 0/5 nodes are available: 5 No preemption victims found for incoming pod."
I0506 15:10:49.716601      12 preemption.go:264] "No preemption candidate is found; preemption is not helpful for scheduling" pod="default/cspod-45"
I0506 15:10:49.716636      12 schedule_one.go:1044] "Unable to schedule pod; no fit; waiting" pod="default/cspod-45" err="0/5 nodes are available: 5 Insufficient cpu. preemption: 0/5 nodes are available: 5 No preemption victims found for incoming pod."
I0506 15:10:49.717194      12 preemption.go:264] "No preemption candidate is found; preemption is not helpful for scheduling" pod="default/cspod-46"
I0506 15:10:49.717229      12 schedule_one.go:1044] "Unable to schedule pod; no fit; waiting" pod="default/cspod-46" err="0/5 nodes are available: 5 Insufficient cpu. preemption: 0/5 nodes are available: 5 No preemption victims found for incoming pod."
I0506 15:10:49.717759      12 preemption.go:264] "No preemption candidate is found; preemption is not helpful for scheduling" pod="default/cspod-47"
I0506 15:10:49.717792      12 schedule_one.go:1044] "Unable to schedule pod; no fit; waiting" pod="default/cspod-47" err="0/5 nodes are available: 5 Insufficient cpu. preemption: 0/5 nodes are available: 5 No preemption victims found for incoming pod."
I0506 15:10:49.718406      12 preemption.go:264] "No preemption candidate is found; preemption is not helpful for scheduling" pod="default/cspod-48"
I0506 15:10:49.718453      12 schedule_one.go:1044] "Unable to schedule pod; no fit; waiting" pod="default/cspod-48" err="0/5 nodes are available: 5 Insufficient cpu. preemption: 0/5 nodes are available: 5 No preemption victims found for incoming pod."
I0506 15:10:49.718980      12 preemption.go:264] "No preemption candidate is found; preemption is not helpful for scheduling" pod="default/cspod-49"
I0506 15:10:49.719023      12 schedule_one.go:1044] "Unable to schedule pod; no fit; waiting" pod="default/cspod-49" err="0/5 nodes are available: 5 Insufficient cpu. preemption: 0/5 nodes are available: 5 No preemption victims found for incoming pod."
I0506 15:10:49.719570      12 preemption.go:264] "No preemption candidate is found; preemption is not helpful for scheduling" pod="default/cspod-50"
I0506 15:10:49.719608      12 schedule_one.go:1044] "Unable to schedule pod; no fit; waiting" pod="default/cspod-50" err="0/5 nodes are available: 5 Insufficient cpu. preemption: 0/5 nodes are available: 5 No preemption victims found for incoming pod."
I0506 15:10:49.720256      12 preemption.go:264] "No preemption candidate is found; preemption is not helpful for scheduling" pod="default/cspod-51"
I0506 15:10:49.720293      12 schedule_one.go:1044] "Unable to schedule pod; no fit; waiting" pod="default/cspod-51" err="0/5 nodes are available: 5 Insufficient cpu. preemption: 0/5 nodes are available: 5 No preemption victims found for incoming pod."
I0506 15:10:49.720885      12 preemption.go:264] "No preemption candidate is found; preemption is not helpful for scheduling" pod="default/cspod-52"
I0506 15:10:49.720928      12 schedule_one.go:1044] "Unable to schedule pod; no fit; waiting" pod="default/cspod-52" err="0/5 nodes are available: 5 Insufficient cpu. preemption: 0/5 nodes are available: 5 No preemption victims found for incoming pod."
I0506 15:10:49.721439      12 preemption.go:264] "No preemption candidate is found; preemption is not helpful for scheduling" pod="default/cspod-53"
I0506 15:10:49.721528      12 schedule_one.go:1044] "Unable to schedule pod; no fit; waiting" pod="default/cspod-53" err="0/5 nodes are available: 5 Insufficient cpu. preemption: 0/5 nodes are available: 5 No preemption victims found for incoming pod."
I0506 15:10:49.722108      12 preemption.go:264] "No preemption candidate is found; preemption is not helpful for scheduling" pod="default/cspod-54"
I0506 15:10:49.722149      12 schedule_one.go:1044] "Unable to schedule pod; no fit; waiting" pod="default/cspod-54" err="0/5 nodes are available: 5 Insufficient cpu. preemption: 0/5 nodes are available: 5 No preemption victims found for incoming pod."
I0506 15:10:49.733170      12 preemption.go:264] "No preemption candidate is found; preemption is not helpful for scheduling" pod="default/cspod-23"
I0506 15:10:49.733222      12 schedule_one.go:1044] "Unable to schedule pod; no fit; waiting" pod="default/cspod-23" err="0/5 nodes are available: 5 Insufficient cpu. preemption: 0/5 nodes are available: 5 No preemption victims found for incoming pod."
I0506 15:10:49.733645      12 schedule_one.go:314] "Successfully bound pod to node" pod="default/cspod-22" node="csnode-2" evaluatedNodes=5 feasibleNodes=1
I0506 15:10:49.733773      12 preemption.go:264] "No preemption candidate is found; preemption is not helpful for scheduling" pod="default/cspod-24"
I0506 15:10:49.733793      12 schedule_one.go:1044] "Unable to schedule pod; no fit; waiting" pod="default/cspod-24" err="0/5 nodes are available: 5 Insufficient cpu. preemption: 0/5 nodes are available: 5 No preemption victims found for incoming pod."
I0506 15:10:49.734425      12 preemption.go:264] "No preemption candidate is found; preemption is not helpful for scheduling" pod="default/cspod-25"
I0506 15:10:49.734465      12 schedule_one.go:1044] "Unable to schedule pod; no fit; waiting" pod="default/cspod-25" err="0/5 nodes are available: 5 Insufficient cpu. preemption: 0/5 nodes are available: 5 No preemption victims found for incoming pod."
I0506 15:10:49.735163      12 preemption.go:264] "No preemption candidate is found; preemption is not helpful for scheduling" pod="default/cspod-26"
I0506 15:10:49.735206      12 schedule_one.go:1044] "Unable to schedule pod; no fit; waiting" pod="default/cspod-26" err="0/5 nodes are available: 5 Insufficient cpu. preemption: 0/5 nodes are available: 5 No preemption victims found for incoming pod."
I0506 15:10:49.735798      12 preemption.go:264] "No preemption candidate is found; preemption is not helpful for scheduling" pod="default/cspod-27"
I0506 15:10:49.735836      12 schedule_one.go:1044] "Unable to schedule pod; no fit; waiting" pod="default/cspod-27" err="0/5 nodes are available: 5 Insufficient cpu. preemption: 0/5 nodes are available: 5 No preemption victims found for incoming pod."
I0506 15:10:49.736399      12 preemption.go:264] "No preemption candidate is found; preemption is not helpful for scheduling" pod="default/cspod-28"
I0506 15:10:49.736436      12 schedule_one.go:1044] "Unable to schedule pod; no fit; waiting" pod="default/cspod-28" err="0/5 nodes are available: 5 Insufficient cpu. preemption: 0/5 nodes are available: 5 No preemption victims found for incoming pod."
I0506 15:10:49.737740      12 preemption.go:264] "No preemption candidate is found; preemption is not helpful for scheduling" pod="default/cspod-29"
I0506 15:10:49.737784      12 schedule_one.go:1044] "Unable to schedule pod; no fit; waiting" pod="default/cspod-29" err="0/5 nodes are available: 5 Insufficient cpu. preemption: 0/5 nodes are available: 5 No preemption victims found for incoming pod."
I0506 15:10:49.738357      12 preemption.go:264] "No preemption candidate is found; preemption is not helpful for scheduling" pod="default/cspod-30"
I0506 15:10:49.738394      12 schedule_one.go:1044] "Unable to schedule pod; no fit; waiting" pod="default/cspod-30" err="0/5 nodes are available: 5 Insufficient cpu. preemption: 0/5 nodes are available: 5 No preemption victims found for incoming pod."
I0506 15:10:49.738932      12 preemption.go:264] "No preemption candidate is found; preemption is not helpful for scheduling" pod="default/cspod-31"
I0506 15:10:49.738967      12 schedule_one.go:1044] "Unable to schedule pod; no fit; waiting" pod="default/cspod-31" err="0/5 nodes are available: 5 Insufficient cpu. preemption: 0/5 nodes are available: 5 No preemption victims found for incoming pod."
I0506 15:10:49.739475      12 preemption.go:264] "No preemption candidate is found; preemption is not helpful for scheduling" pod="default/cspod-32"
I0506 15:10:49.739509      12 schedule_one.go:1044] "Unable to schedule pod; no fit; waiting" pod="default/cspod-32" err="0/5 nodes are available: 5 Insufficient cpu. preemption: 0/5 nodes are available: 5 No preemption victims found for incoming pod."
I0506 15:10:49.740015      12 preemption.go:264] "No preemption candidate is found; preemption is not helpful for scheduling" pod="default/cspod-33"
I0506 15:10:49.740048      12 schedule_one.go:1044] "Unable to schedule pod; no fit; waiting" pod="default/cspod-33" err="0/5 nodes are available: 5 Insufficient cpu. preemption: 0/5 nodes are available: 5 No preemption victims found for incoming pod."
I0506 15:10:49.740584      12 preemption.go:264] "No preemption candidate is found; preemption is not helpful for scheduling" pod="default/cspod-34"
I0506 15:10:49.740618      12 schedule_one.go:1044] "Unable to schedule pod; no fit; waiting" pod="default/cspod-34" err="0/5 nodes are available: 5 Insufficient cpu. preemption: 0/5 nodes are available: 5 No preemption victims found for incoming pod."
I0506 15:10:49.741114      12 preemption.go:264] "No preemption candidate is found; preemption is not helpful for scheduling" pod="default/cspod-35"
I0506 15:10:49.741149      12 schedule_one.go:1044] "Unable to schedule pod; no fit; waiting" pod="default/cspod-35" err="0/5 nodes are available: 5 Insufficient cpu. preemption: 0/5 nodes are available: 5 No preemption victims found for incoming pod."
I0506 15:10:49.741681      12 preemption.go:264] "No preemption candidate is found; preemption is not helpful for scheduling" pod="default/cspod-36"
I0506 15:10:49.741714      12 schedule_one.go:1044] "Unable to schedule pod; no fit; waiting" pod="default/cspod-36" err="0/5 nodes are available: 5 Insufficient cpu. preemption: 0/5 nodes are available: 5 No preemption victims found for incoming pod."
I0506 15:10:49.742192      12 preemption.go:264] "No preemption candidate is found; preemption is not helpful for scheduling" pod="default/cspod-37"
I0506 15:10:49.742224      12 schedule_one.go:1044] "Unable to schedule pod; no fit; waiting" pod="default/cspod-37" err="0/5 nodes are available: 5 Insufficient cpu. preemption: 0/5 nodes are available: 5 No preemption victims found for incoming pod."
I0506 15:10:49.743009      12 preemption.go:264] "No preemption candidate is found; preemption is not helpful for scheduling" pod="default/cspod-38"
I0506 15:10:49.743074      12 schedule_one.go:1044] "Unable to schedule pod; no fit; waiting" pod="default/cspod-38" err="0/5 nodes are available: 5 Insufficient cpu. preemption: 0/5 nodes are available: 5 No preemption victims found for incoming pod."
I0506 15:10:49.743674      12 preemption.go:264] "No preemption candidate is found; preemption is not helpful for scheduling" pod="default/cspod-39"
I0506 15:10:49.743709      12 schedule_one.go:1044] "Unable to schedule pod; no fit; waiting" pod="default/cspod-39" err="0/5 nodes are available: 5 Insufficient cpu. preemption: 0/5 nodes are available: 5 No preemption victims found for incoming pod."
I0506 15:10:49.744221      12 preemption.go:264] "No preemption candidate is found; preemption is not helpful for scheduling" pod="default/cspod-40"
I0506 15:10:49.744256      12 schedule_one.go:1044] "Unable to schedule pod; no fit; waiting" pod="default/cspod-40" err="0/5 nodes are available: 5 Insufficient cpu. preemption: 0/5 nodes are available: 5 No preemption victims found for incoming pod."
I0506 15:10:49.744809      12 preemption.go:264] "No preemption candidate is found; preemption is not helpful for scheduling" pod="default/cspod-41"
I0506 15:10:49.744842      12 schedule_one.go:1044] "Unable to schedule pod; no fit; waiting" pod="default/cspod-41" err="0/5 nodes are available: 5 Insufficient cpu. preemption: 0/5 nodes are available: 5 No preemption victims found for incoming pod."
I0506 15:10:49.745363      12 preemption.go:264] "No preemption candidate is found; preemption is not helpful for scheduling" pod="default/cspod-42"
I0506 15:10:49.745397      12 schedule_one.go:1044] "Unable to schedule pod; no fit; waiting" pod="default/cspod-42" err="0/5 nodes are available: 5 Insufficient cpu. preemption: 0/5 nodes are available: 5 No preemption victims found for incoming pod."
I0506 15:10:49.745947      12 preemption.go:264] "No preemption candidate is found; preemption is not helpful for scheduling" pod="default/cspod-43"
I0506 15:10:49.745988      12 schedule_one.go:1044] "Unable to schedule pod; no fit; waiting" pod="default/cspod-43" err="0/5 nodes are available: 5 Insufficient cpu. preemption: 0/5 nodes are available: 5 No preemption victims found for incoming pod."
I0506 15:10:49.746503      12 preemption.go:264] "No preemption candidate is found; preemption is not helpful for scheduling" pod="default/cspod-44"
I0506 15:10:49.746536      12 schedule_one.go:1044] "Unable to schedule pod; no fit; waiting" pod="default/cspod-44" err="0/5 nodes are available: 5 Insufficient cpu. preemption: 0/5 nodes are available: 5 No preemption victims found for incoming pod."
I0506 15:10:49.747044      12 preemption.go:264] "No preemption candidate is found; preemption is not helpful for scheduling" pod="default/cspod-45"
I0506 15:10:49.747078      12 schedule_one.go:1044] "Unable to schedule pod; no fit; waiting" pod="default/cspod-45" err="0/5 nodes are available: 5 Insufficient cpu. preemption: 0/5 nodes are available: 5 No preemption victims found for incoming pod."
I0506 15:10:49.747580      12 preemption.go:264] "No preemption candidate is found; preemption is not helpful for scheduling" pod="default/cspod-46"
I0506 15:10:49.747612      12 schedule_one.go:1044] "Unable to schedule pod; no fit; waiting" pod="default/cspod-46" err="0/5 nodes are available: 5 Insufficient cpu. preemption: 0/5 nodes are available: 5 No preemption victims found for incoming pod."
I0506 15:10:49.748129      12 preemption.go:264] "No preemption candidate is found; preemption is not helpful for scheduling" pod="default/cspod-47"
I0506 15:10:49.748163      12 schedule_one.go:1044] "Unable to schedule pod; no fit; waiting" pod="default/cspod-47" err="0/5 nodes are available: 5 Insufficient cpu. preemption: 0/5 nodes are available: 5 No preemption victims found for incoming pod."
I0506 15:10:49.748706      12 preemption.go:264] "No preemption candidate is found; preemption is not helpful for scheduling" pod="default/cspod-48"
I0506 15:10:49.748741      12 schedule_one.go:1044] "Unable to schedule pod; no fit; waiting" pod="default/cspod-48" err="0/5 nodes are available: 5 Insufficient cpu. preemption: 0/5 nodes are available: 5 No preemption victims found for incoming pod."
I0506 15:10:49.749283      12 preemption.go:264] "No preemption candidate is found; preemption is not helpful for scheduling" pod="default/cspod-49"
I0506 15:10:49.749319      12 schedule_one.go:1044] "Unable to schedule pod; no fit; waiting" pod="default/cspod-49" err="0/5 nodes are available: 5 Insufficient cpu. preemption: 0/5 nodes are available: 5 No preemption victims found for incoming pod."
I0506 15:10:49.764001      12 preemption.go:264] "No preemption candidate is found; preemption is not helpful for scheduling" pod="default/cspod-50"
I0506 15:10:49.764067      12 schedule_one.go:1044] "Unable to schedule pod; no fit; waiting" pod="default/cspod-50" err="0/5 nodes are available: 5 Insufficient cpu. preemption: 0/5 nodes are available: 5 No preemption victims found for incoming pod."
I0506 15:10:49.783238      12 preemption.go:264] "No preemption candidate is found; preemption is not helpful for scheduling" pod="default/cspod-51"
I0506 15:10:49.783284      12 schedule_one.go:1044] "Unable to schedule pod; no fit; waiting" pod="default/cspod-51" err="0/5 nodes are available: 5 Insufficient cpu. preemption: 0/5 nodes are available: 5 No preemption victims found for incoming pod."
I0506 15:10:49.803544      12 preemption.go:264] "No preemption candidate is found; preemption is not helpful for scheduling" pod="default/cspod-52"
I0506 15:10:49.803593      12 schedule_one.go:1044] "Unable to schedule pod; no fit; waiting" pod="default/cspod-52" err="0/5 nodes are available: 5 Insufficient cpu. preemption: 0/5 nodes are available: 5 No preemption victims found for incoming pod."
I0506 15:10:49.824108      12 preemption.go:264] "No preemption candidate is found; preemption is not helpful for scheduling" pod="default/cspod-53"
I0506 15:10:49.824172      12 schedule_one.go:1044] "Unable to schedule pod; no fit; waiting" pod="default/cspod-53" err="0/5 nodes are available: 5 Insufficient cpu. preemption: 0/5 nodes are available: 5 No preemption victims found for incoming pod."
I0506 15:10:49.843591      12 preemption.go:264] "No preemption candidate is found; preemption is not helpful for scheduling" pod="default/cspod-54"
I0506 15:10:49.843657      12 schedule_one.go:1044] "Unable to schedule pod; no fit; waiting" pod="default/cspod-54" err="0/5 nodes are available: 5 Insufficient cpu. preemption: 0/5 nodes are available: 5 No preemption victims found for incoming pod."
I0506 15:10:49.869497      12 preemption.go:264] "No preemption candidate is found; preemption is not helpful for scheduling" pod="default/cspod-25"
I0506 15:10:49.869561      12 schedule_one.go:1044] "Unable to schedule pod; no fit; waiting" pod="default/cspod-25" err="0/5 nodes are available: 5 Insufficient cpu. preemption: 0/5 nodes are available: 5 No preemption victims found for incoming pod."
I0506 15:10:49.883064      12 schedule_one.go:314] "Successfully bound pod to node" pod="default/cspod-23" node="csnode-3" evaluatedNodes=5 feasibleNodes=2
I0506 15:10:49.903777      12 schedule_one.go:314] "Successfully bound pod to node" pod="default/cspod-24" node="csnode-2" evaluatedNodes=5 feasibleNodes=1
I0506 15:10:49.924331      12 preemption.go:264] "No preemption candidate is found; preemption is not helpful for scheduling" pod="default/cspod-26"
I0506 15:10:49.924405      12 schedule_one.go:1044] "Unable to schedule pod; no fit; waiting" pod="default/cspod-26" err="0/5 nodes are available: 5 Insufficient cpu. preemption: 0/5 nodes are available: 5 No preemption victims found for incoming pod."
I0506 15:10:49.944082      12 preemption.go:264] "No preemption candidate is found; preemption is not helpful for scheduling" pod="default/cspod-27"
I0506 15:10:49.944129      12 schedule_one.go:1044] "Unable to schedule pod; no fit; waiting" pod="default/cspod-27" err="0/5 nodes are available: 5 Insufficient cpu. preemption: 0/5 nodes are available: 5 No preemption victims found for incoming pod."
I0506 15:10:49.964018      12 preemption.go:264] "No preemption candidate is found; preemption is not helpful for scheduling" pod="default/cspod-28"
I0506 15:10:49.964061      12 schedule_one.go:1044] "Unable to schedule pod; no fit; waiting" pod="default/cspod-28" err="0/5 nodes are available: 5 Insufficient cpu. preemption: 0/5 nodes are available: 5 No preemption victims found for incoming pod."
I0506 15:10:49.984002      12 preemption.go:264] "No preemption candidate is found; preemption is not helpful for scheduling" pod="default/cspod-29"
I0506 15:10:49.984044      12 schedule_one.go:1044] "Unable to schedule pod; no fit; waiting" pod="default/cspod-29" err="0/5 nodes are available: 5 Insufficient cpu. preemption: 0/5 nodes are available: 5 No preemption victims found for incoming pod."
I0506 15:10:50.004219      12 preemption.go:264] "No preemption candidate is found; preemption is not helpful for scheduling" pod="default/cspod-30"
I0506 15:10:50.004265      12 schedule_one.go:1044] "Unable to schedule pod; no fit; waiting" pod="default/cspod-30" err="0/5 nodes are available: 5 Insufficient cpu. preemption: 0/5 nodes are available: 5 No preemption victims found for incoming pod."
I0506 15:10:50.023937      12 preemption.go:264] "No preemption candidate is found; preemption is not helpful for scheduling" pod="default/cspod-31"
I0506 15:10:50.024008      12 schedule_one.go:1044] "Unable to schedule pod; no fit; waiting" pod="default/cspod-31" err="0/5 nodes are available: 5 Insufficient cpu. preemption: 0/5 nodes are available: 5 No preemption victims found for incoming pod."
I0506 15:10:50.043871      12 preemption.go:264] "No preemption candidate is found; preemption is not helpful for scheduling" pod="default/cspod-32"
I0506 15:10:50.043942      12 schedule_one.go:1044] "Unable to schedule pod; no fit; waiting" pod="default/cspod-32" err="0/5 nodes are available: 5 Insufficient cpu. preemption: 0/5 nodes are available: 5 No preemption victims found for incoming pod."
I0506 15:10:50.064272      12 preemption.go:264] "No preemption candidate is found; preemption is not helpful for scheduling" pod="default/cspod-33"
I0506 15:10:50.064320      12 schedule_one.go:1044] "Unable to schedule pod; no fit; waiting" pod="default/cspod-33" err="0/5 nodes are available: 5 Insufficient cpu. preemption: 0/5 nodes are available: 5 No preemption victims found for incoming pod."
I0506 15:10:50.083439      12 preemption.go:264] "No preemption candidate is found; preemption is not helpful for scheduling" pod="default/cspod-34"
I0506 15:10:50.083483      12 schedule_one.go:1044] "Unable to schedule pod; no fit; waiting" pod="default/cspod-34" err="0/5 nodes are available: 5 Insufficient cpu. preemption: 0/5 nodes are available: 5 No preemption victims found for incoming pod."
I0506 15:10:50.103495      12 preemption.go:264] "No preemption candidate is found; preemption is not helpful for scheduling" pod="default/cspod-35"
I0506 15:10:50.103542      12 schedule_one.go:1044] "Unable to schedule pod; no fit; waiting" pod="default/cspod-35" err="0/5 nodes are available: 5 Insufficient cpu. preemption: 0/5 nodes are available: 5 No preemption victims found for incoming pod."
I0506 15:10:50.123309      12 preemption.go:264] "No preemption candidate is found; preemption is not helpful for scheduling" pod="default/cspod-36"
I0506 15:10:50.123382      12 schedule_one.go:1044] "Unable to schedule pod; no fit; waiting" pod="default/cspod-36" err="0/5 nodes are available: 5 Insufficient cpu. preemption: 0/5 nodes are available: 5 No preemption victims found for incoming pod."
I0506 15:10:50.143453      12 preemption.go:264] "No preemption candidate is found; preemption is not helpful for scheduling" pod="default/cspod-37"
I0506 15:10:50.143494      12 schedule_one.go:1044] "Unable to schedule pod; no fit; waiting" pod="default/cspod-37" err="0/5 nodes are available: 5 Insufficient cpu. preemption: 0/5 nodes are available: 5 No preemption victims found for incoming pod."
I0506 15:10:50.163516      12 preemption.go:264] "No preemption candidate is found; preemption is not helpful for scheduling" pod="default/cspod-38"
I0506 15:10:50.163595      12 schedule_one.go:1044] "Unable to schedule pod; no fit; waiting" pod="default/cspod-38" err="0/5 nodes are available: 5 Insufficient cpu. preemption: 0/5 nodes are available: 5 No preemption victims found for incoming pod."
I0506 15:10:50.183846      12 preemption.go:264] "No preemption candidate is found; preemption is not helpful for scheduling" pod="default/cspod-39"
I0506 15:10:50.183894      12 schedule_one.go:1044] "Unable to schedule pod; no fit; waiting" pod="default/cspod-39" err="0/5 nodes are available: 5 Insufficient cpu. preemption: 0/5 nodes are available: 5 No preemption victims found for incoming pod."
I0506 15:10:50.204223      12 preemption.go:264] "No preemption candidate is found; preemption is not helpful for scheduling" pod="default/cspod-40"
I0506 15:10:50.204272      12 schedule_one.go:1044] "Unable to schedule pod; no fit; waiting" pod="default/cspod-40" err="0/5 nodes are available: 5 Insufficient cpu. preemption: 0/5 nodes are available: 5 No preemption victims found for incoming pod."
I0506 15:10:50.223286      12 preemption.go:264] "No preemption candidate is found; preemption is not helpful for scheduling" pod="default/cspod-41"
I0506 15:10:50.223328      12 schedule_one.go:1044] "Unable to schedule pod; no fit; waiting" pod="default/cspod-41" err="0/5 nodes are available: 5 Insufficient cpu. preemption: 0/5 nodes are available: 5 No preemption victims found for incoming pod."
I0506 15:10:50.243158      12 preemption.go:264] "No preemption candidate is found; preemption is not helpful for scheduling" pod="default/cspod-42"
I0506 15:10:50.243197      12 schedule_one.go:1044] "Unable to schedule pod; no fit; waiting" pod="default/cspod-42" err="0/5 nodes are available: 5 Insufficient cpu. preemption: 0/5 nodes are available: 5 No preemption victims found for incoming pod."
I0506 15:10:50.263356      12 preemption.go:264] "No preemption candidate is found; preemption is not helpful for scheduling" pod="default/cspod-43"
I0506 15:10:50.263404      12 schedule_one.go:1044] "Unable to schedule pod; no fit; waiting" pod="default/cspod-43" err="0/5 nodes are available: 5 Insufficient cpu. preemption: 0/5 nodes are available: 5 No preemption victims found for incoming pod."
I0506 15:10:50.284131      12 preemption.go:264] "No preemption candidate is found; preemption is not helpful for scheduling" pod="default/cspod-44"
I0506 15:10:50.284222      12 schedule_one.go:1044] "Unable to schedule pod; no fit; waiting" pod="default/cspod-44" err="0/5 nodes are available: 5 Insufficient cpu. preemption: 0/5 nodes are available: 5 No preemption victims found for incoming pod."
I0506 15:10:50.303163      12 preemption.go:264] "No preemption candidate is found; preemption is not helpful for scheduling" pod="default/cspod-45"
I0506 15:10:50.303199      12 schedule_one.go:1044] "Unable to schedule pod; no fit; waiting" pod="default/cspod-45" err="0/5 nodes are available: 5 Insufficient cpu. preemption: 0/5 nodes are available: 5 No preemption victims found for incoming pod."
I0506 15:10:50.323259      12 preemption.go:264] "No preemption candidate is found; preemption is not helpful for scheduling" pod="default/cspod-46"
I0506 15:10:50.323307      12 schedule_one.go:1044] "Unable to schedule pod; no fit; waiting" pod="default/cspod-46" err="0/5 nodes are available: 5 Insufficient cpu. preemption: 0/5 nodes are available: 5 No preemption victims found for incoming pod."
I0506 15:10:50.343585      12 preemption.go:264] "No preemption candidate is found; preemption is not helpful for scheduling" pod="default/cspod-47"
I0506 15:10:50.343637      12 schedule_one.go:1044] "Unable to schedule pod; no fit; waiting" pod="default/cspod-47" err="0/5 nodes are available: 5 Insufficient cpu. preemption: 0/5 nodes are available: 5 No preemption victims found for incoming pod."
I0506 15:10:50.363775      12 preemption.go:264] "No preemption candidate is found; preemption is not helpful for scheduling" pod="default/cspod-48"
I0506 15:10:50.363823      12 schedule_one.go:1044] "Unable to schedule pod; no fit; waiting" pod="default/cspod-48" err="0/5 nodes are available: 5 Insufficient cpu. preemption: 0/5 nodes are available: 5 No preemption victims found for incoming pod."
I0506 15:10:50.383650      12 preemption.go:264] "No preemption candidate is found; preemption is not helpful for scheduling" pod="default/cspod-49"
I0506 15:10:50.383700      12 schedule_one.go:1044] "Unable to schedule pod; no fit; waiting" pod="default/cspod-49" err="0/5 nodes are available: 5 Insufficient cpu. preemption: 0/5 nodes are available: 5 No preemption victims found for incoming pod."
I0506 15:10:50.403596      12 preemption.go:264] "No preemption candidate is found; preemption is not helpful for scheduling" pod="default/cspod-50"
I0506 15:10:50.403639      12 schedule_one.go:1044] "Unable to schedule pod; no fit; waiting" pod="default/cspod-50" err="0/5 nodes are available: 5 Insufficient cpu. preemption: 0/5 nodes are available: 5 No preemption victims found for incoming pod."
I0506 15:10:50.423136      12 preemption.go:264] "No preemption candidate is found; preemption is not helpful for scheduling" pod="default/cspod-51"
I0506 15:10:50.423175      12 schedule_one.go:1044] "Unable to schedule pod; no fit; waiting" pod="default/cspod-51" err="0/5 nodes are available: 5 Insufficient cpu. preemption: 0/5 nodes are available: 5 No preemption victims found for incoming pod."
I0506 15:10:50.444594      12 preemption.go:264] "No preemption candidate is found; preemption is not helpful for scheduling" pod="default/cspod-52"
I0506 15:10:50.444641      12 schedule_one.go:1044] "Unable to schedule pod; no fit; waiting" pod="default/cspod-52" err="0/5 nodes are available: 5 Insufficient cpu. preemption: 0/5 nodes are available: 5 No preemption victims found for incoming pod."
I0506 15:10:50.463622      12 preemption.go:264] "No preemption candidate is found; preemption is not helpful for scheduling" pod="default/cspod-53"
I0506 15:10:50.463697      12 schedule_one.go:1044] "Unable to schedule pod; no fit; waiting" pod="default/cspod-53" err="0/5 nodes are available: 5 Insufficient cpu. preemption: 0/5 nodes are available: 5 No preemption victims found for incoming pod."
I0506 15:10:50.483416      12 preemption.go:264] "No preemption candidate is found; preemption is not helpful for scheduling" pod="default/cspod-54"
I0506 15:10:50.483453      12 schedule_one.go:1044] "Unable to schedule pod; no fit; waiting" pod="default/cspod-54" err="0/5 nodes are available: 5 Insufficient cpu. preemption: 0/5 nodes are available: 5 No preemption victims found for incoming pod."
I0506 15:10:50.513882      12 preemption.go:264] "No preemption candidate is found; preemption is not helpful for scheduling" pod="default/cspod-26"
I0506 15:10:50.513933      12 schedule_one.go:1044] "Unable to schedule pod; no fit; waiting" pod="default/cspod-26" err="0/5 nodes are available: 5 Insufficient cpu. preemption: 0/5 nodes are available: 5 No preemption victims found for incoming pod."
E0506 15:10:50.513956      12 schedule_one.go:1067] "Error occurred" err="Pod default/cspod-26 is already present in the active queue" pod="default/cspod-26"
I0506 15:10:50.514084      12 preemption.go:264] "No preemption candidate is found; preemption is not helpful for scheduling" pod="default/cspod-26"
I0506 15:10:50.514123      12 schedule_one.go:1044] "Unable to schedule pod; no fit; waiting" pod="default/cspod-26" err="0/5 nodes are available: 5 Insufficient cpu. preemption: 0/5 nodes are available: 5 No preemption victims found for incoming pod."
I0506 15:10:50.523951      12 schedule_one.go:314] "Successfully bound pod to node" pod="default/cspod-25" node="csnode-3" evaluatedNodes=5 feasibleNodes=1
I0506 15:10:50.543244      12 preemption.go:264] "No preemption candidate is found; preemption is not helpful for scheduling" pod="default/cspod-27"
I0506 15:10:50.543291      12 schedule_one.go:1044] "Unable to schedule pod; no fit; waiting" pod="default/cspod-27" err="0/5 nodes are available: 5 Insufficient cpu. preemption: 0/5 nodes are available: 5 No preemption victims found for incoming pod."
I0506 15:10:50.563461      12 preemption.go:264] "No preemption candidate is found; preemption is not helpful for scheduling" pod="default/cspod-28"
I0506 15:10:50.563508      12 schedule_one.go:1044] "Unable to schedule pod; no fit; waiting" pod="default/cspod-28" err="0/5 nodes are available: 5 Insufficient cpu. preemption: 0/5 nodes are available: 5 No preemption victims found for incoming pod."
I0506 15:10:50.583726      12 preemption.go:264] "No preemption candidate is found; preemption is not helpful for scheduling" pod="default/cspod-29"
I0506 15:10:50.583773      12 schedule_one.go:1044] "Unable to schedule pod; no fit; waiting" pod="default/cspod-29" err="0/5 nodes are available: 5 Insufficient cpu. preemption: 0/5 nodes are available: 5 No preemption victims found for incoming pod."
I0506 15:10:50.603967      12 preemption.go:264] "No preemption candidate is found; preemption is not helpful for scheduling" pod="default/cspod-30"
I0506 15:10:50.604018      12 schedule_one.go:1044] "Unable to schedule pod; no fit; waiting" pod="default/cspod-30" err="0/5 nodes are available: 5 Insufficient cpu. preemption: 0/5 nodes are available: 5 No preemption victims found for incoming pod."
I0506 15:10:50.624249      12 preemption.go:264] "No preemption candidate is found; preemption is not helpful for scheduling" pod="default/cspod-31"
I0506 15:10:50.624301      12 schedule_one.go:1044] "Unable to schedule pod; no fit; waiting" pod="default/cspod-31" err="0/5 nodes are available: 5 Insufficient cpu. preemption: 0/5 nodes are available: 5 No preemption victims found for incoming pod."
I0506 15:10:50.643407      12 preemption.go:264] "No preemption candidate is found; preemption is not helpful for scheduling" pod="default/cspod-32"
I0506 15:10:50.643442      12 schedule_one.go:1044] "Unable to schedule pod; no fit; waiting" pod="default/cspod-32" err="0/5 nodes are available: 5 Insufficient cpu. preemption: 0/5 nodes are available: 5 No preemption victims found for incoming pod."
I0506 15:10:50.663646      12 preemption.go:264] "No preemption candidate is found; preemption is not helpful for scheduling" pod="default/cspod-33"
I0506 15:10:50.663702      12 schedule_one.go:1044] "Unable to schedule pod; no fit; waiting" pod="default/cspod-33" err="0/5 nodes are available: 5 Insufficient cpu. preemption: 0/5 nodes are available: 5 No preemption victims found for incoming pod."
I0506 15:10:50.683830      12 preemption.go:264] "No preemption candidate is found; preemption is not helpful for scheduling" pod="default/cspod-34"
I0506 15:10:50.683905      12 schedule_one.go:1044] "Unable to schedule pod; no fit; waiting" pod="default/cspod-34" err="0/5 nodes are available: 5 Insufficient cpu. preemption: 0/5 nodes are available: 5 No preemption victims found for incoming pod."
I0506 15:10:50.703812      12 preemption.go:264] "No preemption candidate is found; preemption is not helpful for scheduling" pod="default/cspod-35"
I0506 15:10:50.703847      12 schedule_one.go:1044] "Unable to schedule pod; no fit; waiting" pod="default/cspod-35" err="0/5 nodes are available: 5 Insufficient cpu. preemption: 0/5 nodes are available: 5 No preemption victims found for incoming pod."
I0506 15:10:50.723976      12 preemption.go:264] "No preemption candidate is found; preemption is not helpful for scheduling" pod="default/cspod-36"
I0506 15:10:50.724047      12 schedule_one.go:1044] "Unable to schedule pod; no fit; waiting" pod="default/cspod-36" err="0/5 nodes are available: 5 Insufficient cpu. preemption: 0/5 nodes are available: 5 No preemption victims found for incoming pod."
I0506 15:10:50.743406      12 preemption.go:264] "No preemption candidate is found; preemption is not helpful for scheduling" pod="default/cspod-37"
I0506 15:10:50.743456      12 schedule_one.go:1044] "Unable to schedule pod; no fit; waiting" pod="default/cspod-37" err="0/5 nodes are available: 5 Insufficient cpu. preemption: 0/5 nodes are available: 5 No preemption victims found for incoming pod."
I0506 15:10:50.763541      12 preemption.go:264] "No preemption candidate is found; preemption is not helpful for scheduling" pod="default/cspod-38"
I0506 15:10:50.763585      12 schedule_one.go:1044] "Unable to schedule pod; no fit; waiting" pod="default/cspod-38" err="0/5 nodes are available: 5 Insufficient cpu. preemption: 0/5 nodes are available: 5 No preemption victims found for incoming pod."
I0506 15:10:50.783734      12 preemption.go:264] "No preemption candidate is found; preemption is not helpful for scheduling" pod="default/cspod-39"
I0506 15:10:50.783804      12 schedule_one.go:1044] "Unable to schedule pod; no fit; waiting" pod="default/cspod-39" err="0/5 nodes are available: 5 Insufficient cpu. preemption: 0/5 nodes are available: 5 No preemption victims found for incoming pod."
I0506 15:10:50.803966      12 preemption.go:264] "No preemption candidate is found; preemption is not helpful for scheduling" pod="default/cspod-40"
I0506 15:10:50.804031      12 schedule_one.go:1044] "Unable to schedule pod; no fit; waiting" pod="default/cspod-40" err="0/5 nodes are available: 5 Insufficient cpu. preemption: 0/5 nodes are available: 5 No preemption victims found for incoming pod."
I0506 15:10:50.823993      12 preemption.go:264] "No preemption candidate is found; preemption is not helpful for scheduling" pod="default/cspod-41"
I0506 15:10:50.824035      12 schedule_one.go:1044] "Unable to schedule pod; no fit; waiting" pod="default/cspod-41" err="0/5 nodes are available: 5 Insufficient cpu. preemption: 0/5 nodes are available: 5 No preemption victims found for incoming pod."
I0506 15:10:50.844351      12 preemption.go:264] "No preemption candidate is found; preemption is not helpful for scheduling" pod="default/cspod-42"
I0506 15:10:50.844409      12 schedule_one.go:1044] "Unable to schedule pod; no fit; waiting" pod="default/cspod-42" err="0/5 nodes are available: 5 Insufficient cpu. preemption: 0/5 nodes are available: 5 No preemption victims found for incoming pod."
I0506 15:10:50.863562      12 preemption.go:264] "No preemption candidate is found; preemption is not helpful for scheduling" pod="default/cspod-43"
I0506 15:10:50.863617      12 schedule_one.go:1044] "Unable to schedule pod; no fit; waiting" pod="default/cspod-43" err="0/5 nodes are available: 5 Insufficient cpu. preemption: 0/5 nodes are available: 5 No preemption victims found for incoming pod."
I0506 15:10:50.883597      12 preemption.go:264] "No preemption candidate is found; preemption is not helpful for scheduling" pod="default/cspod-44"
I0506 15:10:50.883650      12 schedule_one.go:1044] "Unable to schedule pod; no fit; waiting" pod="default/cspod-44" err="0/5 nodes are available: 5 Insufficient cpu. preemption: 0/5 nodes are available: 5 No preemption victims found for incoming pod."
I0506 15:10:50.903698      12 preemption.go:264] "No preemption candidate is found; preemption is not helpful for scheduling" pod="default/cspod-45"
I0506 15:10:50.903743      12 schedule_one.go:1044] "Unable to schedule pod; no fit; waiting" pod="default/cspod-45" err="0/5 nodes are available: 5 Insufficient cpu. preemption: 0/5 nodes are available: 5 No preemption victims found for incoming pod."
I0506 15:10:50.924105      12 preemption.go:264] "No preemption candidate is found; preemption is not helpful for scheduling" pod="default/cspod-46"
I0506 15:10:50.924152      12 schedule_one.go:1044] "Unable to schedule pod; no fit; waiting" pod="default/cspod-46" err="0/5 nodes are available: 5 Insufficient cpu. preemption: 0/5 nodes are available: 5 No preemption victims found for incoming pod."
I0506 15:10:50.944014      12 preemption.go:264] "No preemption candidate is found; preemption is not helpful for scheduling" pod="default/cspod-47"
I0506 15:10:50.944088      12 schedule_one.go:1044] "Unable to schedule pod; no fit; waiting" pod="default/cspod-47" err="0/5 nodes are available: 5 Insufficient cpu. preemption: 0/5 nodes are available: 5 No preemption victims found for incoming pod."
I0506 15:10:50.962941      12 preemption.go:264] "No preemption candidate is found; preemption is not helpful for scheduling" pod="default/cspod-48"
I0506 15:10:50.962979      12 schedule_one.go:1044] "Unable to schedule pod; no fit; waiting" pod="default/cspod-48" err="0/5 nodes are available: 5 Insufficient cpu. preemption: 0/5 nodes are available: 5 No preemption victims found for incoming pod."
I0506 15:10:50.984212      12 preemption.go:264] "No preemption candidate is found; preemption is not helpful for scheduling" pod="default/cspod-49"
I0506 15:10:50.984261      12 schedule_one.go:1044] "Unable to schedule pod; no fit; waiting" pod="default/cspod-49" err="0/5 nodes are available: 5 Insufficient cpu. preemption: 0/5 nodes are available: 5 No preemption victims found for incoming pod."
I0506 15:10:51.003649      12 preemption.go:264] "No preemption candidate is found; preemption is not helpful for scheduling" pod="default/cspod-50"
I0506 15:10:51.003692      12 schedule_one.go:1044] "Unable to schedule pod; no fit; waiting" pod="default/cspod-50" err="0/5 nodes are available: 5 Insufficient cpu. preemption: 0/5 nodes are available: 5 No preemption victims found for incoming pod."
I0506 15:10:51.023031      12 preemption.go:264] "No preemption candidate is found; preemption is not helpful for scheduling" pod="default/cspod-51"
I0506 15:10:51.023109      12 schedule_one.go:1044] "Unable to schedule pod; no fit; waiting" pod="default/cspod-51" err="0/5 nodes are available: 5 Insufficient cpu. preemption: 0/5 nodes are available: 5 No preemption victims found for incoming pod."
I0506 15:10:51.044698      12 preemption.go:264] "No preemption candidate is found; preemption is not helpful for scheduling" pod="default/cspod-52"
I0506 15:10:51.044773      12 schedule_one.go:1044] "Unable to schedule pod; no fit; waiting" pod="default/cspod-52" err="0/5 nodes are available: 5 Insufficient cpu. preemption: 0/5 nodes are available: 5 No preemption victims found for incoming pod."
I0506 15:10:51.063946      12 preemption.go:264] "No preemption candidate is found; preemption is not helpful for scheduling" pod="default/cspod-53"
I0506 15:10:51.063993      12 schedule_one.go:1044] "Unable to schedule pod; no fit; waiting" pod="default/cspod-53" err="0/5 nodes are available: 5 Insufficient cpu. preemption: 0/5 nodes are available: 5 No preemption victims found for incoming pod."
I0506 15:10:51.083426      12 preemption.go:264] "No preemption candidate is found; preemption is not helpful for scheduling" pod="default/cspod-54"
I0506 15:10:51.083458      12 schedule_one.go:1044] "Unable to schedule pod; no fit; waiting" pod="default/cspod-54" err="0/5 nodes are available: 5 Insufficient cpu. preemption: 0/5 nodes are available: 5 No preemption victims found for incoming pod."
I0506 15:10:51.111558      12 preemption.go:264] "No preemption candidate is found; preemption is not helpful for scheduling" pod="default/cspod-28"
I0506 15:10:51.111600      12 schedule_one.go:1044] "Unable to schedule pod; no fit; waiting" pod="default/cspod-28" err="0/5 nodes are available: 5 Insufficient cpu. preemption: 0/5 nodes are available: 5 No preemption victims found for incoming pod."
I0506 15:10:51.123379      12 schedule_one.go:314] "Successfully bound pod to node" pod="default/cspod-26" node="csnode-4" evaluatedNodes=5 feasibleNodes=1
I0506 15:10:51.144321      12 schedule_one.go:314] "Successfully bound pod to node" pod="default/cspod-27" node="csnode-4" evaluatedNodes=5 feasibleNodes=1
I0506 15:10:51.163378      12 preemption.go:264] "No preemption candidate is found; preemption is not helpful for scheduling" pod="default/cspod-29"
I0506 15:10:51.163448      12 schedule_one.go:1044] "Unable to schedule pod; no fit; waiting" pod="default/cspod-29" err="0/5 nodes are available: 5 Insufficient cpu. preemption: 0/5 nodes are available: 5 No preemption victims found for incoming pod."
I0506 15:10:51.183550      12 preemption.go:264] "No preemption candidate is found; preemption is not helpful for scheduling" pod="default/cspod-30"
I0506 15:10:51.183637      12 schedule_one.go:1044] "Unable to schedule pod; no fit; waiting" pod="default/cspod-30" err="0/5 nodes are available: 5 Insufficient cpu. preemption: 0/5 nodes are available: 5 No preemption victims found for incoming pod."
I0506 15:10:51.203615      12 preemption.go:264] "No preemption candidate is found; preemption is not helpful for scheduling" pod="default/cspod-31"
I0506 15:10:51.203691      12 schedule_one.go:1044] "Unable to schedule pod; no fit; waiting" pod="default/cspod-31" err="0/5 nodes are available: 5 Insufficient cpu. preemption: 0/5 nodes are available: 5 No preemption victims found for incoming pod."
I0506 15:10:51.224264      12 preemption.go:264] "No preemption candidate is found; preemption is not helpful for scheduling" pod="default/cspod-32"
I0506 15:10:51.224303      12 schedule_one.go:1044] "Unable to schedule pod; no fit; waiting" pod="default/cspod-32" err="0/5 nodes are available: 5 Insufficient cpu. preemption: 0/5 nodes are available: 5 No preemption victims found for incoming pod."
I0506 15:10:51.243651      12 preemption.go:264] "No preemption candidate is found; preemption is not helpful for scheduling" pod="default/cspod-33"
I0506 15:10:51.243695      12 schedule_one.go:1044] "Unable to schedule pod; no fit; waiting" pod="default/cspod-33" err="0/5 nodes are available: 5 Insufficient cpu. preemption: 0/5 nodes are available: 5 No preemption victims found for incoming pod."
I0506 15:10:51.263878      12 preemption.go:264] "No preemption candidate is found; preemption is not helpful for scheduling" pod="default/cspod-34"
I0506 15:10:51.263951      12 schedule_one.go:1044] "Unable to schedule pod; no fit; waiting" pod="default/cspod-34" err="0/5 nodes are available: 5 Insufficient cpu. preemption: 0/5 nodes are available: 5 No preemption victims found for incoming pod."
I0506 15:10:51.284240      12 preemption.go:264] "No preemption candidate is found; preemption is not helpful for scheduling" pod="default/cspod-35"
I0506 15:10:51.284281      12 schedule_one.go:1044] "Unable to schedule pod; no fit; waiting" pod="default/cspod-35" err="0/5 nodes are available: 5 Insufficient cpu. preemption: 0/5 nodes are available: 5 No preemption victims found for incoming pod."
I0506 15:10:51.303451      12 preemption.go:264] "No preemption candidate is found; preemption is not helpful for scheduling" pod="default/cspod-36"
I0506 15:10:51.303500      12 schedule_one.go:1044] "Unable to schedule pod; no fit; waiting" pod="default/cspod-36" err="0/5 nodes are available: 5 Insufficient cpu. preemption: 0/5 nodes are available: 5 No preemption victims found for incoming pod."
I0506 15:10:51.323651      12 preemption.go:264] "No preemption candidate is found; preemption is not helpful for scheduling" pod="default/cspod-37"
I0506 15:10:51.323695      12 schedule_one.go:1044] "Unable to schedule pod; no fit; waiting" pod="default/cspod-37" err="0/5 nodes are available: 5 Insufficient cpu. preemption: 0/5 nodes are available: 5 No preemption victims found for incoming pod."
I0506 15:10:51.343624      12 preemption.go:264] "No preemption candidate is found; preemption is not helpful for scheduling" pod="default/cspod-38"
I0506 15:10:51.343664      12 schedule_one.go:1044] "Unable to schedule pod; no fit; waiting" pod="default/cspod-38" err="0/5 nodes are available: 5 Insufficient cpu. preemption: 0/5 nodes are available: 5 No preemption victims found for incoming pod."
I0506 15:10:51.363500      12 preemption.go:264] "No preemption candidate is found; preemption is not helpful for scheduling" pod="default/cspod-39"
I0506 15:10:51.363538      12 schedule_one.go:1044] "Unable to schedule pod; no fit; waiting" pod="default/cspod-39" err="0/5 nodes are available: 5 Insufficient cpu. preemption: 0/5 nodes are available: 5 No preemption victims found for incoming pod."
I0506 15:10:51.384073      12 preemption.go:264] "No preemption candidate is found; preemption is not helpful for scheduling" pod="default/cspod-40"
I0506 15:10:51.384118      12 schedule_one.go:1044] "Unable to schedule pod; no fit; waiting" pod="default/cspod-40" err="0/5 nodes are available: 5 Insufficient cpu. preemption: 0/5 nodes are available: 5 No preemption victims found for incoming pod."
I0506 15:10:51.403692      12 preemption.go:264] "No preemption candidate is found; preemption is not helpful for scheduling" pod="default/cspod-41"
I0506 15:10:51.403756      12 schedule_one.go:1044] "Unable to schedule pod; no fit; waiting" pod="default/cspod-41" err="0/5 nodes are available: 5 Insufficient cpu. preemption: 0/5 nodes are available: 5 No preemption victims found for incoming pod."
I0506 15:10:51.423697      12 preemption.go:264] "No preemption candidate is found; preemption is not helpful for scheduling" pod="default/cspod-42"
I0506 15:10:51.423775      12 schedule_one.go:1044] "Unable to schedule pod; no fit; waiting" pod="default/cspod-42" err="0/5 nodes are available: 5 Insufficient cpu. preemption: 0/5 nodes are available: 5 No preemption victims found for incoming pod."
I0506 15:10:51.444032      12 preemption.go:264] "No preemption candidate is found; preemption is not helpful for scheduling" pod="default/cspod-43"
I0506 15:10:51.444109      12 schedule_one.go:1044] "Unable to schedule pod; no fit; waiting" pod="default/cspod-43" err="0/5 nodes are available: 5 Insufficient cpu. preemption: 0/5 nodes are available: 5 No preemption victims found for incoming pod."
I0506 15:10:51.463464      12 preemption.go:264] "No preemption candidate is found; preemption is not helpful for scheduling" pod="default/cspod-44"
I0506 15:10:51.463503      12 schedule_one.go:1044] "Unable to schedule pod; no fit; waiting" pod="default/cspod-44" err="0/5 nodes are available: 5 Insufficient cpu. preemption: 0/5 nodes are available: 5 No preemption victims found for incoming pod."
I0506 15:10:51.483366      12 preemption.go:264] "No preemption candidate is found; preemption is not helpful for scheduling" pod="default/cspod-45"
I0506 15:10:51.483405      12 schedule_one.go:1044] "Unable to schedule pod; no fit; waiting" pod="default/cspod-45" err="0/5 nodes are available: 5 Insufficient cpu. preemption: 0/5 nodes are available: 5 No preemption victims found for incoming pod."
I0506 15:10:51.503674      12 preemption.go:264] "No preemption candidate is found; preemption is not helpful for scheduling" pod="default/cspod-46"
I0506 15:10:51.503721      12 schedule_one.go:1044] "Unable to schedule pod; no fit; waiting" pod="default/cspod-46" err="0/5 nodes are available: 5 Insufficient cpu. preemption: 0/5 nodes are available: 5 No preemption victims found for incoming pod."
I0506 15:10:51.523997      12 preemption.go:264] "No preemption candidate is found; preemption is not helpful for scheduling" pod="default/cspod-47"
I0506 15:10:51.524046      12 schedule_one.go:1044] "Unable to schedule pod; no fit; waiting" pod="default/cspod-47" err="0/5 nodes are available: 5 Insufficient cpu. preemption: 0/5 nodes are available: 5 No preemption victims found for incoming pod."
I0506 15:10:51.543254      12 preemption.go:264] "No preemption candidate is found; preemption is not helpful for scheduling" pod="default/cspod-48"
I0506 15:10:51.543296      12 schedule_one.go:1044] "Unable to schedule pod; no fit; waiting" pod="default/cspod-48" err="0/5 nodes are available: 5 Insufficient cpu. preemption: 0/5 nodes are available: 5 No preemption victims found for incoming pod."
I0506 15:10:51.563289      12 preemption.go:264] "No preemption candidate is found; preemption is not helpful for scheduling" pod="default/cspod-49"
I0506 15:10:51.563363      12 schedule_one.go:1044] "Unable to schedule pod; no fit; waiting" pod="default/cspod-49" err="0/5 nodes are available: 5 Insufficient cpu. preemption: 0/5 nodes are available: 5 No preemption victims found for incoming pod."
I0506 15:10:51.583772      12 preemption.go:264] "No preemption candidate is found; preemption is not helpful for scheduling" pod="default/cspod-50"
I0506 15:10:51.583841      12 schedule_one.go:1044] "Unable to schedule pod; no fit; waiting" pod="default/cspod-50" err="0/5 nodes are available: 5 Insufficient cpu. preemption: 0/5 nodes are available: 5 No preemption victims found for incoming pod."
I0506 15:10:51.603718      12 preemption.go:264] "No preemption candidate is found; preemption is not helpful for scheduling" pod="default/cspod-51"
I0506 15:10:51.603761      12 schedule_one.go:1044] "Unable to schedule pod; no fit; waiting" pod="default/cspod-51" err="0/5 nodes are available: 5 Insufficient cpu. preemption: 0/5 nodes are available: 5 No preemption victims found for incoming pod."
I0506 15:10:51.623535      12 preemption.go:264] "No preemption candidate is found; preemption is not helpful for scheduling" pod="default/cspod-52"
I0506 15:10:51.623573      12 schedule_one.go:1044] "Unable to schedule pod; no fit; waiting" pod="default/cspod-52" err="0/5 nodes are available: 5 Insufficient cpu. preemption: 0/5 nodes are available: 5 No preemption victims found for incoming pod."
I0506 15:10:51.643675      12 preemption.go:264] "No preemption candidate is found; preemption is not helpful for scheduling" pod="default/cspod-53"
I0506 15:10:51.643753      12 schedule_one.go:1044] "Unable to schedule pod; no fit; waiting" pod="default/cspod-53" err="0/5 nodes are available: 5 Insufficient cpu. preemption: 0/5 nodes are available: 5 No preemption victims found for incoming pod."
I0506 15:10:51.664072      12 preemption.go:264] "No preemption candidate is found; preemption is not helpful for scheduling" pod="default/cspod-54"
I0506 15:10:51.664119      12 schedule_one.go:1044] "Unable to schedule pod; no fit; waiting" pod="default/cspod-54" err="0/5 nodes are available: 5 Insufficient cpu. preemption: 0/5 nodes are available: 5 No preemption victims found for incoming pod."
I0506 15:10:51.692093      12 preemption.go:264] "No preemption candidate is found; preemption is not helpful for scheduling" pod="default/cspod-32"
I0506 15:10:51.692133      12 schedule_one.go:1044] "Unable to schedule pod; no fit; waiting" pod="default/cspod-32" err="0/5 nodes are available: 5 Insufficient cpu. preemption: 0/5 nodes are available: 5 No preemption victims found for incoming pod."
I0506 15:10:51.702965      12 schedule_one.go:314] "Successfully bound pod to node" pod="default/cspod-28" node="csnode-1" evaluatedNodes=5 feasibleNodes=2
I0506 15:10:51.723028      12 schedule_one.go:314] "Successfully bound pod to node" pod="default/cspod-29" node="csnode-0" evaluatedNodes=5 feasibleNodes=2
I0506 15:10:51.743650      12 schedule_one.go:314] "Successfully bound pod to node" pod="default/cspod-30" node="csnode-0" evaluatedNodes=5 feasibleNodes=2
I0506 15:10:51.763498      12 schedule_one.go:314] "Successfully bound pod to node" pod="default/cspod-31" node="csnode-1" evaluatedNodes=5 feasibleNodes=1
I0506 15:10:51.783544      12 preemption.go:264] "No preemption candidate is found; preemption is not helpful for scheduling" pod="default/cspod-33"
I0506 15:10:51.783623      12 schedule_one.go:1044] "Unable to schedule pod; no fit; waiting" pod="default/cspod-33" err="0/5 nodes are available: 5 Insufficient cpu. preemption: 0/5 nodes are available: 5 No preemption victims found for incoming pod."
I0506 15:10:51.803677      12 preemption.go:264] "No preemption candidate is found; preemption is not helpful for scheduling" pod="default/cspod-34"
I0506 15:10:51.803753      12 schedule_one.go:1044] "Unable to schedule pod; no fit; waiting" pod="default/cspod-34" err="0/5 nodes are available: 5 Insufficient cpu. preemption: 0/5 nodes are available: 5 No preemption victims found for incoming pod."
I0506 15:10:51.823867      12 preemption.go:264] "No preemption candidate is found; preemption is not helpful for scheduling" pod="default/cspod-35"
I0506 15:10:51.823911      12 schedule_one.go:1044] "Unable to schedule pod; no fit; waiting" pod="default/cspod-35" err="0/5 nodes are available: 5 Insufficient cpu. preemption: 0/5 nodes are available: 5 No preemption victims found for incoming pod."
I0506 15:10:51.844092      12 preemption.go:264] "No preemption candidate is found; preemption is not helpful for scheduling" pod="default/cspod-36"
I0506 15:10:51.844161      12 schedule_one.go:1044] "Unable to schedule pod; no fit; waiting" pod="default/cspod-36" err="0/5 nodes are available: 5 Insufficient cpu. preemption: 0/5 nodes are available: 5 No preemption victims found for incoming pod."
I0506 15:10:51.863230      12 preemption.go:264] "No preemption candidate is found; preemption is not helpful for scheduling" pod="default/cspod-37"
I0506 15:10:51.863276      12 schedule_one.go:1044] "Unable to schedule pod; no fit; waiting" pod="default/cspod-37" err="0/5 nodes are available: 5 Insufficient cpu. preemption: 0/5 nodes are available: 5 No preemption victims found for incoming pod."
I0506 15:10:51.883333      12 preemption.go:264] "No preemption candidate is found; preemption is not helpful for scheduling" pod="default/cspod-38"
I0506 15:10:51.883409      12 schedule_one.go:1044] "Unable to schedule pod; no fit; waiting" pod="default/cspod-38" err="0/5 nodes are available: 5 Insufficient cpu. preemption: 0/5 nodes are available: 5 No preemption victims found for incoming pod."
I0506 15:10:51.903727      12 preemption.go:264] "No preemption candidate is found; preemption is not helpful for scheduling" pod="default/cspod-39"
I0506 15:10:51.903773      12 schedule_one.go:1044] "Unable to schedule pod; no fit; waiting" pod="default/cspod-39" err="0/5 nodes are available: 5 Insufficient cpu. preemption: 0/5 nodes are available: 5 No preemption victims found for incoming pod."
I0506 15:10:51.923793      12 preemption.go:264] "No preemption candidate is found; preemption is not helpful for scheduling" pod="default/cspod-40"
I0506 15:10:51.923834      12 schedule_one.go:1044] "Unable to schedule pod; no fit; waiting" pod="default/cspod-40" err="0/5 nodes are available: 5 Insufficient cpu. preemption: 0/5 nodes are available: 5 No preemption victims found for incoming pod."
I0506 15:10:51.943897      12 preemption.go:264] "No preemption candidate is found; preemption is not helpful for scheduling" pod="default/cspod-41"
I0506 15:10:51.943941      12 schedule_one.go:1044] "Unable to schedule pod; no fit; waiting" pod="default/cspod-41" err="0/5 nodes are available: 5 Insufficient cpu. preemption: 0/5 nodes are available: 5 No preemption victims found for incoming pod."
I0506 15:10:51.964232      12 preemption.go:264] "No preemption candidate is found; preemption is not helpful for scheduling" pod="default/cspod-42"
I0506 15:10:51.964281      12 schedule_one.go:1044] "Unable to schedule pod; no fit; waiting" pod="default/cspod-42" err="0/5 nodes are available: 5 Insufficient cpu. preemption: 0/5 nodes are available: 5 No preemption victims found for incoming pod."
I0506 15:10:51.983003      12 preemption.go:264] "No preemption candidate is found; preemption is not helpful for scheduling" pod="default/cspod-43"
I0506 15:10:51.983041      12 schedule_one.go:1044] "Unable to schedule pod; no fit; waiting" pod="default/cspod-43" err="0/5 nodes are available: 5 Insufficient cpu. preemption: 0/5 nodes are available: 5 No preemption victims found for incoming pod."
I0506 15:10:52.003952      12 preemption.go:264] "No preemption candidate is found; preemption is not helpful for scheduling" pod="default/cspod-44"
I0506 15:10:52.003994      12 schedule_one.go:1044] "Unable to schedule pod; no fit; waiting" pod="default/cspod-44" err="0/5 nodes are available: 5 Insufficient cpu. preemption: 0/5 nodes are available: 5 No preemption victims found for incoming pod."
I0506 15:10:52.024198      12 preemption.go:264] "No preemption candidate is found; preemption is not helpful for scheduling" pod="default/cspod-45"
I0506 15:10:52.024246      12 schedule_one.go:1044] "Unable to schedule pod; no fit; waiting" pod="default/cspod-45" err="0/5 nodes are available: 5 Insufficient cpu. preemption: 0/5 nodes are available: 5 No preemption victims found for incoming pod."
I0506 15:10:52.043448      12 preemption.go:264] "No preemption candidate is found; preemption is not helpful for scheduling" pod="default/cspod-46"
I0506 15:10:52.043492      12 schedule_one.go:1044] "Unable to schedule pod; no fit; waiting" pod="default/cspod-46" err="0/5 nodes are available: 5 Insufficient cpu. preemption: 0/5 nodes are available: 5 No preemption victims found for incoming pod."
I0506 15:10:52.063334      12 preemption.go:264] "No preemption candidate is found; preemption is not helpful for scheduling" pod="default/cspod-47"
I0506 15:10:52.063407      12 schedule_one.go:1044] "Unable to schedule pod; no fit; waiting" pod="default/cspod-47" err="0/5 nodes are available: 5 Insufficient cpu. preemption: 0/5 nodes are available: 5 No preemption victims found for incoming pod."
I0506 15:10:52.083235      12 preemption.go:264] "No preemption candidate is found; preemption is not helpful for scheduling" pod="default/cspod-48"
I0506 15:10:52.083308      12 schedule_one.go:1044] "Unable to schedule pod; no fit; waiting" pod="default/cspod-48" err="0/5 nodes are available: 5 Insufficient cpu. preemption: 0/5 nodes are available: 5 No preemption victims found for incoming pod."
I0506 15:10:52.103520      12 preemption.go:264] "No preemption candidate is found; preemption is not helpful for scheduling" pod="default/cspod-49"
I0506 15:10:52.103566      12 schedule_one.go:1044] "Unable to schedule pod; no fit; waiting" pod="default/cspod-49" err="0/5 nodes are available: 5 Insufficient cpu. preemption: 0/5 nodes are available: 5 No preemption victims found for incoming pod."
I0506 15:10:52.124004      12 preemption.go:264] "No preemption candidate is found; preemption is not helpful for scheduling" pod="default/cspod-50"
I0506 15:10:52.124082      12 schedule_one.go:1044] "Unable to schedule pod; no fit; waiting" pod="default/cspod-50" err="0/5 nodes are available: 5 Insufficient cpu. preemption: 0/5 nodes are available: 5 No preemption victims found for incoming pod."
I0506 15:10:52.143061      12 preemption.go:264] "No preemption candidate is found; preemption is not helpful for scheduling" pod="default/cspod-51"
I0506 15:10:52.143131      12 schedule_one.go:1044] "Unable to schedule pod; no fit; waiting" pod="default/cspod-51" err="0/5 nodes are available: 5 Insufficient cpu. preemption: 0/5 nodes are available: 5 No preemption victims found for incoming pod."
I0506 15:10:52.163245      12 preemption.go:264] "No preemption candidate is found; preemption is not helpful for scheduling" pod="default/cspod-52"
I0506 15:10:52.163289      12 schedule_one.go:1044] "Unable to schedule pod; no fit; waiting" pod="default/cspod-52" err="0/5 nodes are available: 5 Insufficient cpu. preemption: 0/5 nodes are available: 5 No preemption victims found for incoming pod."
I0506 15:10:52.184402      12 preemption.go:264] "No preemption candidate is found; preemption is not helpful for scheduling" pod="default/cspod-53"
I0506 15:10:52.184449      12 schedule_one.go:1044] "Unable to schedule pod; no fit; waiting" pod="default/cspod-53" err="0/5 nodes are available: 5 Insufficient cpu. preemption: 0/5 nodes are available: 5 No preemption victims found for incoming pod."
I0506 15:10:52.203337      12 preemption.go:264] "No preemption candidate is found; preemption is not helpful for scheduling" pod="default/cspod-54"
I0506 15:10:52.203381      12 schedule_one.go:1044] "Unable to schedule pod; no fit; waiting" pod="default/cspod-54" err="0/5 nodes are available: 5 Insufficient cpu. preemption: 0/5 nodes are available: 5 No preemption victims found for incoming pod."
I0506 15:10:52.231035      12 preemption.go:264] "No preemption candidate is found; preemption is not helpful for scheduling" pod="default/cspod-34"
I0506 15:10:52.231114      12 schedule_one.go:1044] "Unable to schedule pod; no fit; waiting" pod="default/cspod-34" err="0/5 nodes are available: 5 Insufficient cpu. preemption: 0/5 nodes are available: 5 No preemption victims found for incoming pod."
I0506 15:10:52.243380      12 schedule_one.go:314] "Successfully bound pod to node" pod="default/cspod-32" node="csnode-4" evaluatedNodes=5 feasibleNodes=1
I0506 15:10:52.263849      12 schedule_one.go:314] "Successfully bound pod to node" pod="default/cspod-33" node="csnode-4" evaluatedNodes=5 feasibleNodes=1
I0506 15:10:52.283845      12 preemption.go:264] "No preemption candidate is found; preemption is not helpful for scheduling" pod="default/cspod-35"
I0506 15:10:52.283923      12 schedule_one.go:1044] "Unable to schedule pod; no fit; waiting" pod="default/cspod-35" err="0/5 nodes are available: 5 Insufficient cpu. preemption: 0/5 nodes are available: 5 No preemption victims found for incoming pod."
I0506 15:10:52.304138      12 preemption.go:264] "No preemption candidate is found; preemption is not helpful for scheduling" pod="default/cspod-36"
I0506 15:10:52.304226      12 schedule_one.go:1044] "Unable to schedule pod; no fit; waiting" pod="default/cspod-36" err="0/5 nodes are available: 5 Insufficient cpu. preemption: 0/5 nodes are available: 5 No preemption victims found for incoming pod."
I0506 15:10:52.323171      12 preemption.go:264] "No preemption candidate is found; preemption is not helpful for scheduling" pod="default/cspod-37"
I0506 15:10:52.323240      12 schedule_one.go:1044] "Unable to schedule pod; no fit; waiting" pod="default/cspod-37" err="0/5 nodes are available: 5 Insufficient cpu. preemption: 0/5 nodes are available: 5 No preemption victims found for incoming pod."
I0506 15:10:52.343390      12 preemption.go:264] "No preemption candidate is found; preemption is not helpful for scheduling" pod="default/cspod-38"
I0506 15:10:52.343467      12 schedule_one.go:1044] "Unable to schedule pod; no fit; waiting" pod="default/cspod-38" err="0/5 nodes are available: 5 Insufficient cpu. preemption: 0/5 nodes are available: 5 No preemption victims found for incoming pod."
I0506 15:10:52.363687      12 preemption.go:264] "No preemption candidate is found; preemption is not helpful for scheduling" pod="default/cspod-39"
I0506 15:10:52.363763      12 schedule_one.go:1044] "Unable to schedule pod; no fit; waiting" pod="default/cspod-39" err="0/5 nodes are available: 5 Insufficient cpu. preemption: 0/5 nodes are available: 5 No preemption victims found for incoming pod."
I0506 15:10:52.383535      12 preemption.go:264] "No preemption candidate is found; preemption is not helpful for scheduling" pod="default/cspod-40"
I0506 15:10:52.383577      12 schedule_one.go:1044] "Unable to schedule pod; no fit; waiting" pod="default/cspod-40" err="0/5 nodes are available: 5 Insufficient cpu. preemption: 0/5 nodes are available: 5 No preemption victims found for incoming pod."
I0506 15:10:52.403454      12 preemption.go:264] "No preemption candidate is found; preemption is not helpful for scheduling" pod="default/cspod-41"
I0506 15:10:52.403491      12 schedule_one.go:1044] "Unable to schedule pod; no fit; waiting" pod="default/cspod-41" err="0/5 nodes are available: 5 Insufficient cpu. preemption: 0/5 nodes are available: 5 No preemption victims found for incoming pod."
I0506 15:10:52.423512      12 preemption.go:264] "No preemption candidate is found; preemption is not helpful for scheduling" pod="default/cspod-42"
I0506 15:10:52.423590      12 schedule_one.go:1044] "Unable to schedule pod; no fit; waiting" pod="default/cspod-42" err="0/5 nodes are available: 5 Insufficient cpu. preemption: 0/5 nodes are available: 5 No preemption victims found for incoming pod."
I0506 15:10:52.443934      12 preemption.go:264] "No preemption candidate is found; preemption is not helpful for scheduling" pod="default/cspod-43"
I0506 15:10:52.443979      12 schedule_one.go:1044] "Unable to schedule pod; no fit; waiting" pod="default/cspod-43" err="0/5 nodes are available: 5 Insufficient cpu. preemption: 0/5 nodes are available: 5 No preemption victims found for incoming pod."
I0506 15:10:52.464025      12 preemption.go:264] "No preemption candidate is found; preemption is not helpful for scheduling" pod="default/cspod-44"
I0506 15:10:52.464077      12 schedule_one.go:1044] "Unable to schedule pod; no fit; waiting" pod="default/cspod-44" err="0/5 nodes are available: 5 Insufficient cpu. preemption: 0/5 nodes are available: 5 No preemption victims found for incoming pod."
I0506 15:10:52.483918      12 preemption.go:264] "No preemption candidate is found; preemption is not helpful for scheduling" pod="default/cspod-45"
I0506 15:10:52.483955      12 schedule_one.go:1044] "Unable to schedule pod; no fit; waiting" pod="default/cspod-45" err="0/5 nodes are available: 5 Insufficient cpu. preemption: 0/5 nodes are available: 5 No preemption victims found for incoming pod."
I0506 15:10:52.504055      12 preemption.go:264] "No preemption candidate is found; preemption is not helpful for scheduling" pod="default/cspod-46"
I0506 15:10:52.504100      12 schedule_one.go:1044] "Unable to schedule pod; no fit; waiting" pod="default/cspod-46" err="0/5 nodes are available: 5 Insufficient cpu. preemption: 0/5 nodes are available: 5 No preemption victims found for incoming pod."
I0506 15:10:52.523951      12 preemption.go:264] "No preemption candidate is found; preemption is not helpful for scheduling" pod="default/cspod-47"
I0506 15:10:52.523990      12 schedule_one.go:1044] "Unable to schedule pod; no fit; waiting" pod="default/cspod-47" err="0/5 nodes are available: 5 Insufficient cpu. preemption: 0/5 nodes are available: 5 No preemption victims found for incoming pod."
I0506 15:10:52.544363      12 preemption.go:264] "No preemption candidate is found; preemption is not helpful for scheduling" pod="default/cspod-48"
I0506 15:10:52.544429      12 schedule_one.go:1044] "Unable to schedule pod; no fit; waiting" pod="default/cspod-48" err="0/5 nodes are available: 5 Insufficient cpu. preemption: 0/5 nodes are available: 5 No preemption victims found for incoming pod."
I0506 15:10:52.563481      12 preemption.go:264] "No preemption candidate is found; preemption is not helpful for scheduling" pod="default/cspod-49"
I0506 15:10:52.563557      12 schedule_one.go:1044] "Unable to schedule pod; no fit; waiting" pod="default/cspod-49" err="0/5 nodes are available: 5 Insufficient cpu. preemption: 0/5 nodes are available: 5 No preemption victims found for incoming pod."
I0506 15:10:52.583589      12 preemption.go:264] "No preemption candidate is found; preemption is not helpful for scheduling" pod="default/cspod-50"
I0506 15:10:52.583631      12 schedule_one.go:1044] "Unable to schedule pod; no fit; waiting" pod="default/cspod-50" err="0/5 nodes are available: 5 Insufficient cpu. preemption: 0/5 nodes are available: 5 No preemption victims found for incoming pod."
I0506 15:10:52.603777      12 preemption.go:264] "No preemption candidate is found; preemption is not helpful for scheduling" pod="default/cspod-51"
I0506 15:10:52.603847      12 schedule_one.go:1044] "Unable to schedule pod; no fit; waiting" pod="default/cspod-51" err="0/5 nodes are available: 5 Insufficient cpu. preemption: 0/5 nodes are available: 5 No preemption victims found for incoming pod."
I0506 15:10:52.624353      12 preemption.go:264] "No preemption candidate is found; preemption is not helpful for scheduling" pod="default/cspod-52"
I0506 15:10:52.624400      12 schedule_one.go:1044] "Unable to schedule pod; no fit; waiting" pod="default/cspod-52" err="0/5 nodes are available: 5 Insufficient cpu. preemption: 0/5 nodes are available: 5 No preemption victims found for incoming pod."
I0506 15:10:52.644300      12 preemption.go:264] "No preemption candidate is found; preemption is not helpful for scheduling" pod="default/cspod-53"
I0506 15:10:52.644346      12 schedule_one.go:1044] "Unable to schedule pod; no fit; waiting" pod="default/cspod-53" err="0/5 nodes are available: 5 Insufficient cpu. preemption: 0/5 nodes are available: 5 No preemption victims found for incoming pod."
I0506 15:10:52.663417      12 preemption.go:264] "No preemption candidate is found; preemption is not helpful for scheduling" pod="default/cspod-54"
I0506 15:10:52.663453      12 schedule_one.go:1044] "Unable to schedule pod; no fit; waiting" pod="default/cspod-54" err="0/5 nodes are available: 5 Insufficient cpu. preemption: 0/5 nodes are available: 5 No preemption victims found for incoming pod."
I0506 15:10:52.697440      12 preemption.go:264] "No preemption candidate is found; preemption is not helpful for scheduling" pod="default/cspod-36"
I0506 15:10:52.697482      12 schedule_one.go:1044] "Unable to schedule pod; no fit; waiting" pod="default/cspod-36" err="0/5 nodes are available: 5 Insufficient cpu. preemption: 0/5 nodes are available: 5 No preemption victims found for incoming pod."
I0506 15:10:52.703185      12 schedule_one.go:314] "Successfully bound pod to node" pod="default/cspod-34" node="csnode-4" evaluatedNodes=5 feasibleNodes=1
I0506 15:10:52.724003      12 schedule_one.go:314] "Successfully bound pod to node" pod="default/cspod-35" node="csnode-4" evaluatedNodes=5 feasibleNodes=1
I0506 15:10:52.743724      12 preemption.go:264] "No preemption candidate is found; preemption is not helpful for scheduling" pod="default/cspod-37"
I0506 15:10:52.743766      12 schedule_one.go:1044] "Unable to schedule pod; no fit; waiting" pod="default/cspod-37" err="0/5 nodes are available: 5 Insufficient cpu. preemption: 0/5 nodes are available: 5 No preemption victims found for incoming pod."
I0506 15:10:52.764066      12 preemption.go:264] "No preemption candidate is found; preemption is not helpful for scheduling" pod="default/cspod-38"
I0506 15:10:52.764112      12 schedule_one.go:1044] "Unable to schedule pod; no fit; waiting" pod="default/cspod-38" err="0/5 nodes are available: 5 Insufficient cpu. preemption: 0/5 nodes are available: 5 No preemption victims found for incoming pod."
I0506 15:10:52.784136      12 preemption.go:264] "No preemption candidate is found; preemption is not helpful for scheduling" pod="default/cspod-39"
I0506 15:10:52.784242      12 schedule_one.go:1044] "Unable to schedule pod; no fit; waiting" pod="default/cspod-39" err="0/5 nodes are available: 5 Insufficient cpu. preemption: 0/5 nodes are available: 5 No preemption victims found for incoming pod."
I0506 15:10:52.803213      12 preemption.go:264] "No preemption candidate is found; preemption is not helpful for scheduling" pod="default/cspod-40"
I0506 15:10:52.803258      12 schedule_one.go:1044] "Unable to schedule pod; no fit; waiting" pod="default/cspod-40" err="0/5 nodes are available: 5 Insufficient cpu. preemption: 0/5 nodes are available: 5 No preemption victims found for incoming pod."
I0506 15:10:52.823444      12 preemption.go:264] "No preemption candidate is found; preemption is not helpful for scheduling" pod="default/cspod-41"
I0506 15:10:52.823489      12 schedule_one.go:1044] "Unable to schedule pod; no fit; waiting" pod="default/cspod-41" err="0/5 nodes are available: 5 Insufficient cpu. preemption: 0/5 nodes are available: 5 No preemption victims found for incoming pod."
I0506 15:10:52.843637      12 preemption.go:264] "No preemption candidate is found; preemption is not helpful for scheduling" pod="default/cspod-42"
I0506 15:10:52.843710      12 schedule_one.go:1044] "Unable to schedule pod; no fit; waiting" pod="default/cspod-42" err="0/5 nodes are available: 5 Insufficient cpu. preemption: 0/5 nodes are available: 5 No preemption victims found for incoming pod."
I0506 15:10:52.863353      12 preemption.go:264] "No preemption candidate is found; preemption is not helpful for scheduling" pod="default/cspod-43"
I0506 15:10:52.863433      12 schedule_one.go:1044] "Unable to schedule pod; no fit; waiting" pod="default/cspod-43" err="0/5 nodes are available: 5 Insufficient cpu. preemption: 0/5 nodes are available: 5 No preemption victims found for incoming pod."
I0506 15:10:52.883173      12 preemption.go:264] "No preemption candidate is found; preemption is not helpful for scheduling" pod="default/cspod-44"
I0506 15:10:52.883214      12 schedule_one.go:1044] "Unable to schedule pod; no fit; waiting" pod="default/cspod-44" err="0/5 nodes are available: 5 Insufficient cpu. preemption: 0/5 nodes are available: 5 No preemption victims found for incoming pod."
I0506 15:10:52.903303      12 preemption.go:264] "No preemption candidate is found; preemption is not helpful for scheduling" pod="default/cspod-45"
I0506 15:10:52.903348      12 schedule_one.go:1044] "Unable to schedule pod; no fit; waiting" pod="default/cspod-45" err="0/5 nodes are available: 5 Insufficient cpu. preemption: 0/5 nodes are available: 5 No preemption victims found for incoming pod."
I0506 15:10:52.923314      12 preemption.go:264] "No preemption candidate is found; preemption is not helpful for scheduling" pod="default/cspod-46"
I0506 15:10:52.923530      12 schedule_one.go:1044] "Unable to schedule pod; no fit; waiting" pod="default/cspod-46" err="0/5 nodes are available: 5 Insufficient cpu. preemption: 0/5 nodes are available: 5 No preemption victims found for incoming pod."
I0506 15:10:52.943904      12 preemption.go:264] "No preemption candidate is found; preemption is not helpful for scheduling" pod="default/cspod-47"
I0506 15:10:52.943978      12 schedule_one.go:1044] "Unable to schedule pod; no fit; waiting" pod="default/cspod-47" err="0/5 nodes are available: 5 Insufficient cpu. preemption: 0/5 nodes are available: 5 No preemption victims found for incoming pod."
I0506 15:10:52.963702      12 preemption.go:264] "No preemption candidate is found; preemption is not helpful for scheduling" pod="default/cspod-48"
I0506 15:10:52.963776      12 schedule_one.go:1044] "Unable to schedule pod; no fit; waiting" pod="default/cspod-48" err="0/5 nodes are available: 5 Insufficient cpu. preemption: 0/5 nodes are available: 5 No preemption victims found for incoming pod."
I0506 15:10:52.984119      12 preemption.go:264] "No preemption candidate is found; preemption is not helpful for scheduling" pod="default/cspod-49"
I0506 15:10:52.984162      12 schedule_one.go:1044] "Unable to schedule pod; no fit; waiting" pod="default/cspod-49" err="0/5 nodes are available: 5 Insufficient cpu. preemption: 0/5 nodes are available: 5 No preemption victims found for incoming pod."
I0506 15:10:53.003203      12 preemption.go:264] "No preemption candidate is found; preemption is not helpful for scheduling" pod="default/cspod-50"
I0506 15:10:53.003292      12 schedule_one.go:1044] "Unable to schedule pod; no fit; waiting" pod="default/cspod-50" err="0/5 nodes are available: 5 Insufficient cpu. preemption: 0/5 nodes are available: 5 No preemption victims found for incoming pod."
I0506 15:10:53.023538      12 preemption.go:264] "No preemption candidate is found; preemption is not helpful for scheduling" pod="default/cspod-51"
I0506 15:10:53.023583      12 schedule_one.go:1044] "Unable to schedule pod; no fit; waiting" pod="default/cspod-51" err="0/5 nodes are available: 5 Insufficient cpu. preemption: 0/5 nodes are available: 5 No preemption victims found for incoming pod."
I0506 15:10:53.043478      12 preemption.go:264] "No preemption candidate is found; preemption is not helpful for scheduling" pod="default/cspod-52"
I0506 15:10:53.043551      12 schedule_one.go:1044] "Unable to schedule pod; no fit; waiting" pod="default/cspod-52" err="0/5 nodes are available: 5 Insufficient cpu. preemption: 0/5 nodes are available: 5 No preemption victims found for incoming pod."
I0506 15:10:53.063790      12 preemption.go:264] "No preemption candidate is found; preemption is not helpful for scheduling" pod="default/cspod-53"
I0506 15:10:53.063840      12 schedule_one.go:1044] "Unable to schedule pod; no fit; waiting" pod="default/cspod-53" err="0/5 nodes are available: 5 Insufficient cpu. preemption: 0/5 nodes are available: 5 No preemption victims found for incoming pod."
I0506 15:10:53.084011      12 preemption.go:264] "No preemption candidate is found; preemption is not helpful for scheduling" pod="default/cspod-54"
I0506 15:10:53.084061      12 schedule_one.go:1044] "Unable to schedule pod; no fit; waiting" pod="default/cspod-54" err="0/5 nodes are available: 5 Insufficient cpu. preemption: 0/5 nodes are available: 5 No preemption victims found for incoming pod."
I0506 15:10:53.111647      12 preemption.go:264] "No preemption candidate is found; preemption is not helpful for scheduling" pod="default/cspod-37"
I0506 15:10:53.112033      12 schedule_one.go:1044] "Unable to schedule pod; no fit; waiting" pod="default/cspod-37" err="0/5 nodes are available: 5 Insufficient cpu. preemption: 0/5 nodes are available: 5 No preemption victims found for incoming pod."
I0506 15:10:53.123290      12 schedule_one.go:314] "Successfully bound pod to node" pod="default/cspod-36" node="csnode-4" evaluatedNodes=5 feasibleNodes=1
I0506 15:10:53.143251      12 preemption.go:264] "No preemption candidate is found; preemption is not helpful for scheduling" pod="default/cspod-38"
I0506 15:10:53.143326      12 schedule_one.go:1044] "Unable to schedule pod; no fit; waiting" pod="default/cspod-38" err="0/5 nodes are available: 5 Insufficient cpu. preemption: 0/5 nodes are available: 5 No preemption victims found for incoming pod."
I0506 15:10:53.163914      12 preemption.go:264] "No preemption candidate is found; preemption is not helpful for scheduling" pod="default/cspod-39"
I0506 15:10:53.163969      12 schedule_one.go:1044] "Unable to schedule pod; no fit; waiting" pod="default/cspod-39" err="0/5 nodes are available: 5 Insufficient cpu. preemption: 0/5 nodes are available: 5 No preemption victims found for incoming pod."
I0506 15:10:53.183943      12 preemption.go:264] "No preemption candidate is found; preemption is not helpful for scheduling" pod="default/cspod-40"
I0506 15:10:53.184021      12 schedule_one.go:1044] "Unable to schedule pod; no fit; waiting" pod="default/cspod-40" err="0/5 nodes are available: 5 Insufficient cpu. preemption: 0/5 nodes are available: 5 No preemption victims found for incoming pod."
I0506 15:10:53.204195      12 preemption.go:264] "No preemption candidate is found; preemption is not helpful for scheduling" pod="default/cspod-41"
I0506 15:10:53.204232      12 schedule_one.go:1044] "Unable to schedule pod; no fit; waiting" pod="default/cspod-41" err="0/5 nodes are available: 5 Insufficient cpu. preemption: 0/5 nodes are available: 5 No preemption victims found for incoming pod."
I0506 15:10:53.223230      12 preemption.go:264] "No preemption candidate is found; preemption is not helpful for scheduling" pod="default/cspod-42"
I0506 15:10:53.223300      12 schedule_one.go:1044] "Unable to schedule pod; no fit; waiting" pod="default/cspod-42" err="0/5 nodes are available: 5 Insufficient cpu. preemption: 0/5 nodes are available: 5 No preemption victims found for incoming pod."
I0506 15:10:53.243489      12 preemption.go:264] "No preemption candidate is found; preemption is not helpful for scheduling" pod="default/cspod-43"
I0506 15:10:53.243564      12 schedule_one.go:1044] "Unable to schedule pod; no fit; waiting" pod="default/cspod-43" err="0/5 nodes are available: 5 Insufficient cpu. preemption: 0/5 nodes are available: 5 No preemption victims found for incoming pod."
I0506 15:10:53.263666      12 preemption.go:264] "No preemption candidate is found; preemption is not helpful for scheduling" pod="default/cspod-44"
I0506 15:10:53.263709      12 schedule_one.go:1044] "Unable to schedule pod; no fit; waiting" pod="default/cspod-44" err="0/5 nodes are available: 5 Insufficient cpu. preemption: 0/5 nodes are available: 5 No preemption victims found for incoming pod."
I0506 15:10:53.284202      12 preemption.go:264] "No preemption candidate is found; preemption is not helpful for scheduling" pod="default/cspod-45"
I0506 15:10:53.284278      12 schedule_one.go:1044] "Unable to schedule pod; no fit; waiting" pod="default/cspod-45" err="0/5 nodes are available: 5 Insufficient cpu. preemption: 0/5 nodes are available: 5 No preemption victims found for incoming pod."
I0506 15:10:53.303394      12 preemption.go:264] "No preemption candidate is found; preemption is not helpful for scheduling" pod="default/cspod-46"
I0506 15:10:53.303441      12 schedule_one.go:1044] "Unable to schedule pod; no fit; waiting" pod="default/cspod-46" err="0/5 nodes are available: 5 Insufficient cpu. preemption: 0/5 nodes are available: 5 No preemption victims found for incoming pod."
I0506 15:10:53.323872      12 preemption.go:264] "No preemption candidate is found; preemption is not helpful for scheduling" pod="default/cspod-47"
I0506 15:10:53.323917      12 schedule_one.go:1044] "Unable to schedule pod; no fit; waiting" pod="default/cspod-47" err="0/5 nodes are available: 5 Insufficient cpu. preemption: 0/5 nodes are available: 5 No preemption victims found for incoming pod."
I0506 15:10:53.343462      12 preemption.go:264] "No preemption candidate is found; preemption is not helpful for scheduling" pod="default/cspod-48"
I0506 15:10:53.343507      12 schedule_one.go:1044] "Unable to schedule pod; no fit; waiting" pod="default/cspod-48" err="0/5 nodes are available: 5 Insufficient cpu. preemption: 0/5 nodes are available: 5 No preemption victims found for incoming pod."
I0506 15:10:53.363578      12 preemption.go:264] "No preemption candidate is found; preemption is not helpful for scheduling" pod="default/cspod-49"
I0506 15:10:53.363622      12 schedule_one.go:1044] "Unable to schedule pod; no fit; waiting" pod="default/cspod-49" err="0/5 nodes are available: 5 Insufficient cpu. preemption: 0/5 nodes are available: 5 No preemption victims found for incoming pod."
I0506 15:10:53.383376      12 preemption.go:264] "No preemption candidate is found; preemption is not helpful for scheduling" pod="default/cspod-50"
I0506 15:10:53.383448      12 schedule_one.go:1044] "Unable to schedule pod; no fit; waiting" pod="default/cspod-50" err="0/5 nodes are available: 5 Insufficient cpu. preemption: 0/5 nodes are available: 5 No preemption victims found for incoming pod."
I0506 15:10:53.403273      12 preemption.go:264] "No preemption candidate is found; preemption is not helpful for scheduling" pod="default/cspod-51"
I0506 15:10:53.403352      12 schedule_one.go:1044] "Unable to schedule pod; no fit; waiting" pod="default/cspod-51" err="0/5 nodes are available: 5 Insufficient cpu. preemption: 0/5 nodes are available: 5 No preemption victims found for incoming pod."
I0506 15:10:53.423557      12 preemption.go:264] "No preemption candidate is found; preemption is not helpful for scheduling" pod="default/cspod-52"
I0506 15:10:53.423601      12 schedule_one.go:1044] "Unable to schedule pod; no fit; waiting" pod="default/cspod-52" err="0/5 nodes are available: 5 Insufficient cpu. preemption: 0/5 nodes are available: 5 No preemption victims found for incoming pod."
I0506 15:10:53.443779      12 preemption.go:264] "No preemption candidate is found; preemption is not helpful for scheduling" pod="default/cspod-53"
I0506 15:10:53.443827      12 schedule_one.go:1044] "Unable to schedule pod; no fit; waiting" pod="default/cspod-53" err="0/5 nodes are available: 5 Insufficient cpu. preemption: 0/5 nodes are available: 5 No preemption victims found for incoming pod."
I0506 15:10:53.463756      12 preemption.go:264] "No preemption candidate is found; preemption is not helpful for scheduling" pod="default/cspod-54"
I0506 15:10:53.463793      12 schedule_one.go:1044] "Unable to schedule pod; no fit; waiting" pod="default/cspod-54" err="0/5 nodes are available: 5 Insufficient cpu. preemption: 0/5 nodes are available: 5 No preemption victims found for incoming pod."
I0506 15:10:53.489309      12 preemption.go:264] "No preemption candidate is found; preemption is not helpful for scheduling" pod="default/cspod-40"
I0506 15:10:53.489350      12 schedule_one.go:1044] "Unable to schedule pod; no fit; waiting" pod="default/cspod-40" err="0/5 nodes are available: 5 Insufficient cpu. preemption: 0/5 nodes are available: 5 No preemption victims found for incoming pod."
I0506 15:10:53.503851      12 schedule_one.go:314] "Successfully bound pod to node" pod="default/cspod-37" node="csnode-2" evaluatedNodes=5 feasibleNodes=2
I0506 15:10:53.523528      12 schedule_one.go:314] "Successfully bound pod to node" pod="default/cspod-38" node="csnode-3" evaluatedNodes=5 feasibleNodes=2
I0506 15:10:53.543597      12 schedule_one.go:314] "Successfully bound pod to node" pod="default/cspod-39" node="csnode-2" evaluatedNodes=5 feasibleNodes=1
I0506 15:10:53.563595      12 preemption.go:264] "No preemption candidate is found; preemption is not helpful for scheduling" pod="default/cspod-41"
I0506 15:10:53.563636      12 schedule_one.go:1044] "Unable to schedule pod; no fit; waiting" pod="default/cspod-41" err="0/5 nodes are available: 5 Insufficient cpu. preemption: 0/5 nodes are available: 5 No preemption victims found for incoming pod."
I0506 15:10:53.583579      12 preemption.go:264] "No preemption candidate is found; preemption is not helpful for scheduling" pod="default/cspod-42"
I0506 15:10:53.583616      12 schedule_one.go:1044] "Unable to schedule pod; no fit; waiting" pod="default/cspod-42" err="0/5 nodes are available: 5 Insufficient cpu. preemption: 0/5 nodes are available: 5 No preemption victims found for incoming pod."
I0506 15:10:53.603933      12 preemption.go:264] "No preemption candidate is found; preemption is not helpful for scheduling" pod="default/cspod-43"
I0506 15:10:53.603978      12 schedule_one.go:1044] "Unable to schedule pod; no fit; waiting" pod="default/cspod-43" err="0/5 nodes are available: 5 Insufficient cpu. preemption: 0/5 nodes are available: 5 No preemption victims found for incoming pod."
I0506 15:10:53.624223      12 preemption.go:264] "No preemption candidate is found; preemption is not helpful for scheduling" pod="default/cspod-44"
I0506 15:10:53.624267      12 schedule_one.go:1044] "Unable to schedule pod; no fit; waiting" pod="default/cspod-44" err="0/5 nodes are available: 5 Insufficient cpu. preemption: 0/5 nodes are available: 5 No preemption victims found for incoming pod."
I0506 15:10:53.643209      12 preemption.go:264] "No preemption candidate is found; preemption is not helpful for scheduling" pod="default/cspod-45"
I0506 15:10:53.643247      12 schedule_one.go:1044] "Unable to schedule pod; no fit; waiting" pod="default/cspod-45" err="0/5 nodes are available: 5 Insufficient cpu. preemption: 0/5 nodes are available: 5 No preemption victims found for incoming pod."
I0506 15:10:53.663076      12 preemption.go:264] "No preemption candidate is found; preemption is not helpful for scheduling" pod="default/cspod-46"
I0506 15:10:53.663113      12 schedule_one.go:1044] "Unable to schedule pod; no fit; waiting" pod="default/cspod-46" err="0/5 nodes are available: 5 Insufficient cpu. preemption: 0/5 nodes are available: 5 No preemption victims found for incoming pod."
I0506 15:10:53.684584      12 preemption.go:264] "No preemption candidate is found; preemption is not helpful for scheduling" pod="default/cspod-47"
I0506 15:10:53.684635      12 schedule_one.go:1044] "Unable to schedule pod; no fit; waiting" pod="default/cspod-47" err="0/5 nodes are available: 5 Insufficient cpu. preemption: 0/5 nodes are available: 5 No preemption victims found for incoming pod."
I0506 15:10:53.703705      12 preemption.go:264] "No preemption candidate is found; preemption is not helpful for scheduling" pod="default/cspod-48"
I0506 15:10:53.703753      12 schedule_one.go:1044] "Unable to schedule pod; no fit; waiting" pod="default/cspod-48" err="0/5 nodes are available: 5 Insufficient cpu. preemption: 0/5 nodes are available: 5 No preemption victims found for incoming pod."
I0506 15:10:53.723688      12 preemption.go:264] "No preemption candidate is found; preemption is not helpful for scheduling" pod="default/cspod-49"
I0506 15:10:53.723728      12 schedule_one.go:1044] "Unable to schedule pod; no fit; waiting" pod="default/cspod-49" err="0/5 nodes are available: 5 Insufficient cpu. preemption: 0/5 nodes are available: 5 No preemption victims found for incoming pod."
I0506 15:10:53.743905      12 preemption.go:264] "No preemption candidate is found; preemption is not helpful for scheduling" pod="default/cspod-50"
I0506 15:10:53.743951      12 schedule_one.go:1044] "Unable to schedule pod; no fit; waiting" pod="default/cspod-50" err="0/5 nodes are available: 5 Insufficient cpu. preemption: 0/5 nodes are available: 5 No preemption victims found for incoming pod."
I0506 15:10:53.764152      12 preemption.go:264] "No preemption candidate is found; preemption is not helpful for scheduling" pod="default/cspod-51"
I0506 15:10:53.764281      12 schedule_one.go:1044] "Unable to schedule pod; no fit; waiting" pod="default/cspod-51" err="0/5 nodes are available: 5 Insufficient cpu. preemption: 0/5 nodes are available: 5 No preemption victims found for incoming pod."
I0506 15:10:53.783690      12 preemption.go:264] "No preemption candidate is found; preemption is not helpful for scheduling" pod="default/cspod-52"
I0506 15:10:53.783735      12 schedule_one.go:1044] "Unable to schedule pod; no fit; waiting" pod="default/cspod-52" err="0/5 nodes are available: 5 Insufficient cpu. preemption: 0/5 nodes are available: 5 No preemption victims found for incoming pod."
I0506 15:10:53.803606      12 preemption.go:264] "No preemption candidate is found; preemption is not helpful for scheduling" pod="default/cspod-53"
I0506 15:10:53.803646      12 schedule_one.go:1044] "Unable to schedule pod; no fit; waiting" pod="default/cspod-53" err="0/5 nodes are available: 5 Insufficient cpu. preemption: 0/5 nodes are available: 5 No preemption victims found for incoming pod."
I0506 15:10:53.823891      12 preemption.go:264] "No preemption candidate is found; preemption is not helpful for scheduling" pod="default/cspod-54"
I0506 15:10:53.823967      12 schedule_one.go:1044] "Unable to schedule pod; no fit; waiting" pod="default/cspod-54" err="0/5 nodes are available: 5 Insufficient cpu. preemption: 0/5 nodes are available: 5 No preemption victims found for incoming pod."
I0506 15:10:53.851037      12 preemption.go:264] "No preemption candidate is found; preemption is not helpful for scheduling" pod="default/cspod-41"
I0506 15:10:53.851109      12 schedule_one.go:1044] "Unable to schedule pod; no fit; waiting" pod="default/cspod-41" err="0/5 nodes are available: 5 Insufficient cpu. preemption: 0/5 nodes are available: 5 No preemption victims found for incoming pod."
I0506 15:10:53.863429      12 schedule_one.go:314] "Successfully bound pod to node" pod="default/cspod-40" node="csnode-3" evaluatedNodes=5 feasibleNodes=1
I0506 15:10:53.883340      12 preemption.go:264] "No preemption candidate is found; preemption is not helpful for scheduling" pod="default/cspod-42"
I0506 15:10:53.883383      12 schedule_one.go:1044] "Unable to schedule pod; no fit; waiting" pod="default/cspod-42" err="0/5 nodes are available: 5 Insufficient cpu. preemption: 0/5 nodes are available: 5 No preemption victims found for incoming pod."
I0506 15:10:53.903366      12 preemption.go:264] "No preemption candidate is found; preemption is not helpful for scheduling" pod="default/cspod-43"
I0506 15:10:53.903407      12 schedule_one.go:1044] "Unable to schedule pod; no fit; waiting" pod="default/cspod-43" err="0/5 nodes are available: 5 Insufficient cpu. preemption: 0/5 nodes are available: 5 No preemption victims found for incoming pod."
I0506 15:10:53.923404      12 preemption.go:264] "No preemption candidate is found; preemption is not helpful for scheduling" pod="default/cspod-44"
I0506 15:10:53.923440      12 schedule_one.go:1044] "Unable to schedule pod; no fit; waiting" pod="default/cspod-44" err="0/5 nodes are available: 5 Insufficient cpu. preemption: 0/5 nodes are available: 5 No preemption victims found for incoming pod."
I0506 15:10:53.943537      12 preemption.go:264] "No preemption candidate is found; preemption is not helpful for scheduling" pod="default/cspod-45"
I0506 15:10:53.943578      12 schedule_one.go:1044] "Unable to schedule pod; no fit; waiting" pod="default/cspod-45" err="0/5 nodes are available: 5 Insufficient cpu. preemption: 0/5 nodes are available: 5 No preemption victims found for incoming pod."
I0506 15:10:53.963670      12 preemption.go:264] "No preemption candidate is found; preemption is not helpful for scheduling" pod="default/cspod-46"
I0506 15:10:53.963713      12 schedule_one.go:1044] "Unable to schedule pod; no fit; waiting" pod="default/cspod-46" err="0/5 nodes are available: 5 Insufficient cpu. preemption: 0/5 nodes are available: 5 No preemption victims found for incoming pod."
I0506 15:10:53.983768      12 preemption.go:264] "No preemption candidate is found; preemption is not helpful for scheduling" pod="default/cspod-47"
I0506 15:10:53.983807      12 schedule_one.go:1044] "Unable to schedule pod; no fit; waiting" pod="default/cspod-47" err="0/5 nodes are available: 5 Insufficient cpu. preemption: 0/5 nodes are available: 5 No preemption victims found for incoming pod."
I0506 15:10:54.003751      12 preemption.go:264] "No preemption candidate is found; preemption is not helpful for scheduling" pod="default/cspod-48"
I0506 15:10:54.003818      12 schedule_one.go:1044] "Unable to schedule pod; no fit; waiting" pod="default/cspod-48" err="0/5 nodes are available: 5 Insufficient cpu. preemption: 0/5 nodes are available: 5 No preemption victims found for incoming pod."
I0506 15:10:54.024167      12 preemption.go:264] "No preemption candidate is found; preemption is not helpful for scheduling" pod="default/cspod-49"
I0506 15:10:54.024239      12 schedule_one.go:1044] "Unable to schedule pod; no fit; waiting" pod="default/cspod-49" err="0/5 nodes are available: 5 Insufficient cpu. preemption: 0/5 nodes are available: 5 No preemption victims found for incoming pod."
I0506 15:10:54.043443      12 preemption.go:264] "No preemption candidate is found; preemption is not helpful for scheduling" pod="default/cspod-50"
I0506 15:10:54.043489      12 schedule_one.go:1044] "Unable to schedule pod; no fit; waiting" pod="default/cspod-50" err="0/5 nodes are available: 5 Insufficient cpu. preemption: 0/5 nodes are available: 5 No preemption victims found for incoming pod."
I0506 15:10:54.063401      12 preemption.go:264] "No preemption candidate is found; preemption is not helpful for scheduling" pod="default/cspod-51"
I0506 15:10:54.063440      12 schedule_one.go:1044] "Unable to schedule pod; no fit; waiting" pod="default/cspod-51" err="0/5 nodes are available: 5 Insufficient cpu. preemption: 0/5 nodes are available: 5 No preemption victims found for incoming pod."
I0506 15:10:54.083545      12 preemption.go:264] "No preemption candidate is found; preemption is not helpful for scheduling" pod="default/cspod-52"
I0506 15:10:54.083627      12 schedule_one.go:1044] "Unable to schedule pod; no fit; waiting" pod="default/cspod-52" err="0/5 nodes are available: 5 Insufficient cpu. preemption: 0/5 nodes are available: 5 No preemption victims found for incoming pod."
I0506 15:10:54.103664      12 preemption.go:264] "No preemption candidate is found; preemption is not helpful for scheduling" pod="default/cspod-53"
I0506 15:10:54.103733      12 schedule_one.go:1044] "Unable to schedule pod; no fit; waiting" pod="default/cspod-53" err="0/5 nodes are available: 5 Insufficient cpu. preemption: 0/5 nodes are available: 5 No preemption victims found for incoming pod."
I0506 15:10:54.123779      12 preemption.go:264] "No preemption candidate is found; preemption is not helpful for scheduling" pod="default/cspod-54"
I0506 15:10:54.123856      12 schedule_one.go:1044] "Unable to schedule pod; no fit; waiting" pod="default/cspod-54" err="0/5 nodes are available: 5 Insufficient cpu. preemption: 0/5 nodes are available: 5 No preemption victims found for incoming pod."
I0506 15:10:54.151786      12 preemption.go:264] "No preemption candidate is found; preemption is not helpful for scheduling" pod="default/cspod-44"
I0506 15:10:54.151832      12 schedule_one.go:1044] "Unable to schedule pod; no fit; waiting" pod="default/cspod-44" err="0/5 nodes are available: 5 Insufficient cpu. preemption: 0/5 nodes are available: 5 No preemption victims found for incoming pod."
I0506 15:10:54.163868      12 schedule_one.go:314] "Successfully bound pod to node" pod="default/cspod-41" node="csnode-2" evaluatedNodes=5 feasibleNodes=2
I0506 15:10:54.183361      12 schedule_one.go:314] "Successfully bound pod to node" pod="default/cspod-42" node="csnode-2" evaluatedNodes=5 feasibleNodes=2
I0506 15:10:54.202999      12 schedule_one.go:314] "Successfully bound pod to node" pod="default/cspod-43" node="csnode-3" evaluatedNodes=5 feasibleNodes=1
I0506 15:10:54.224294      12 preemption.go:264] "No preemption candidate is found; preemption is not helpful for scheduling" pod="default/cspod-45"
I0506 15:10:54.224342      12 schedule_one.go:1044] "Unable to schedule pod; no fit; waiting" pod="default/cspod-45" err="0/5 nodes are available: 5 Insufficient cpu. preemption: 0/5 nodes are available: 5 No preemption victims found for incoming pod."
I0506 15:10:54.243310      12 preemption.go:264] "No preemption candidate is found; preemption is not helpful for scheduling" pod="default/cspod-46"
I0506 15:10:54.243350      12 schedule_one.go:1044] "Unable to schedule pod; no fit; waiting" pod="default/cspod-46" err="0/5 nodes are available: 5 Insufficient cpu. preemption: 0/5 nodes are available: 5 No preemption victims found for incoming pod."
I0506 15:10:54.263430      12 preemption.go:264] "No preemption candidate is found; preemption is not helpful for scheduling" pod="default/cspod-47"
I0506 15:10:54.263467      12 schedule_one.go:1044] "Unable to schedule pod; no fit; waiting" pod="default/cspod-47" err="0/5 nodes are available: 5 Insufficient cpu. preemption: 0/5 nodes are available: 5 No preemption victims found for incoming pod."
I0506 15:10:54.283819      12 preemption.go:264] "No preemption candidate is found; preemption is not helpful for scheduling" pod="default/cspod-48"
I0506 15:10:54.283861      12 schedule_one.go:1044] "Unable to schedule pod; no fit; waiting" pod="default/cspod-48" err="0/5 nodes are available: 5 Insufficient cpu. preemption: 0/5 nodes are available: 5 No preemption victims found for incoming pod."
I0506 15:10:54.304160      12 preemption.go:264] "No preemption candidate is found; preemption is not helpful for scheduling" pod="default/cspod-49"
I0506 15:10:54.304287      12 schedule_one.go:1044] "Unable to schedule pod; no fit; waiting" pod="default/cspod-49" err="0/5 nodes are available: 5 Insufficient cpu. preemption: 0/5 nodes are available: 5 No preemption victims found for incoming pod."
I0506 15:10:54.323436      12 preemption.go:264] "No preemption candidate is found; preemption is not helpful for scheduling" pod="default/cspod-50"
I0506 15:10:54.323482      12 schedule_one.go:1044] "Unable to schedule pod; no fit; waiting" pod="default/cspod-50" err="0/5 nodes are available: 5 Insufficient cpu. preemption: 0/5 nodes are available: 5 No preemption victims found for incoming pod."
I0506 15:10:54.343605      12 preemption.go:264] "No preemption candidate is found; preemption is not helpful for scheduling" pod="default/cspod-51"
I0506 15:10:54.343653      12 schedule_one.go:1044] "Unable to schedule pod; no fit; waiting" pod="default/cspod-51" err="0/5 nodes are available: 5 Insufficient cpu. preemption: 0/5 nodes are available: 5 No preemption victims found for incoming pod."
I0506 15:10:54.363704      12 preemption.go:264] "No preemption candidate is found; preemption is not helpful for scheduling" pod="default/cspod-52"
I0506 15:10:54.363742      12 schedule_one.go:1044] "Unable to schedule pod; no fit; waiting" pod="default/cspod-52" err="0/5 nodes are available: 5 Insufficient cpu. preemption: 0/5 nodes are available: 5 No preemption victims found for incoming pod."
I0506 15:10:54.383722      12 preemption.go:264] "No preemption candidate is found; preemption is not helpful for scheduling" pod="default/cspod-53"
I0506 15:10:54.383772      12 schedule_one.go:1044] "Unable to schedule pod; no fit; waiting" pod="default/cspod-53" err="0/5 nodes are available: 5 Insufficient cpu. preemption: 0/5 nodes are available: 5 No preemption victims found for incoming pod."
I0506 15:10:54.403826      12 preemption.go:264] "No preemption candidate is found; preemption is not helpful for scheduling" pod="default/cspod-54"
I0506 15:10:54.403876      12 schedule_one.go:1044] "Unable to schedule pod; no fit; waiting" pod="default/cspod-54" err="0/5 nodes are available: 5 Insufficient cpu. preemption: 0/5 nodes are available: 5 No preemption victims found for incoming pod."
I0506 15:10:54.430943      12 preemption.go:264] "No preemption candidate is found; preemption is not helpful for scheduling" pod="default/cspod-46"
I0506 15:10:54.430986      12 schedule_one.go:1044] "Unable to schedule pod; no fit; waiting" pod="default/cspod-46" err="0/5 nodes are available: 5 Insufficient cpu. preemption: 0/5 nodes are available: 5 No preemption victims found for incoming pod."
I0506 15:10:54.443096      12 schedule_one.go:314] "Successfully bound pod to node" pod="default/cspod-44" node="csnode-1" evaluatedNodes=5 feasibleNodes=2
I0506 15:10:54.463782      12 schedule_one.go:314] "Successfully bound pod to node" pod="default/cspod-45" node="csnode-0" evaluatedNodes=5 feasibleNodes=1
I0506 15:10:54.484213      12 preemption.go:264] "No preemption candidate is found; preemption is not helpful for scheduling" pod="default/cspod-47"
I0506 15:10:54.484260      12 schedule_one.go:1044] "Unable to schedule pod; no fit; waiting" pod="default/cspod-47" err="0/5 nodes are available: 5 Insufficient cpu. preemption: 0/5 nodes are available: 5 No preemption victims found for incoming pod."
I0506 15:10:54.503215      12 preemption.go:264] "No preemption candidate is found; preemption is not helpful for scheduling" pod="default/cspod-48"
I0506 15:10:54.503255      12 schedule_one.go:1044] "Unable to schedule pod; no fit; waiting" pod="default/cspod-48" err="0/5 nodes are available: 5 Insufficient cpu. preemption: 0/5 nodes are available: 5 No preemption victims found for incoming pod."
I0506 15:10:54.523134      12 preemption.go:264] "No preemption candidate is found; preemption is not helpful for scheduling" pod="default/cspod-49"
I0506 15:10:54.523174      12 schedule_one.go:1044] "Unable to schedule pod; no fit; waiting" pod="default/cspod-49" err="0/5 nodes are available: 5 Insufficient cpu. preemption: 0/5 nodes are available: 5 No preemption victims found for incoming pod."
I0506 15:10:54.544424      12 preemption.go:264] "No preemption candidate is found; preemption is not helpful for scheduling" pod="default/cspod-50"
I0506 15:10:54.544501      12 schedule_one.go:1044] "Unable to schedule pod; no fit; waiting" pod="default/cspod-50" err="0/5 nodes are available: 5 Insufficient cpu. preemption: 0/5 nodes are available: 5 No preemption victims found for incoming pod."
I0506 15:10:54.563789      12 preemption.go:264] "No preemption candidate is found; preemption is not helpful for scheduling" pod="default/cspod-51"
I0506 15:10:54.563872      12 schedule_one.go:1044] "Unable to schedule pod; no fit; waiting" pod="default/cspod-51" err="0/5 nodes are available: 5 Insufficient cpu. preemption: 0/5 nodes are available: 5 No preemption victims found for incoming pod."
I0506 15:10:54.584334      12 preemption.go:264] "No preemption candidate is found; preemption is not helpful for scheduling" pod="default/cspod-52"
I0506 15:10:54.584385      12 schedule_one.go:1044] "Unable to schedule pod; no fit; waiting" pod="default/cspod-52" err="0/5 nodes are available: 5 Insufficient cpu. preemption: 0/5 nodes are available: 5 No preemption victims found for incoming pod."
I0506 15:10:54.603512      12 preemption.go:264] "No preemption candidate is found; preemption is not helpful for scheduling" pod="default/cspod-53"
I0506 15:10:54.603582      12 schedule_one.go:1044] "Unable to schedule pod; no fit; waiting" pod="default/cspod-53" err="0/5 nodes are available: 5 Insufficient cpu. preemption: 0/5 nodes are available: 5 No preemption victims found for incoming pod."
I0506 15:10:54.623692      12 preemption.go:264] "No preemption candidate is found; preemption is not helpful for scheduling" pod="default/cspod-54"
I0506 15:10:54.623732      12 schedule_one.go:1044] "Unable to schedule pod; no fit; waiting" pod="default/cspod-54" err="0/5 nodes are available: 5 Insufficient cpu. preemption: 0/5 nodes are available: 5 No preemption victims found for incoming pod."
I0506 15:10:54.649795      12 preemption.go:264] "No preemption candidate is found; preemption is not helpful for scheduling" pod="default/cspod-48"
I0506 15:10:54.649844      12 schedule_one.go:1044] "Unable to schedule pod; no fit; waiting" pod="default/cspod-48" err="0/5 nodes are available: 5 Insufficient cpu. preemption: 0/5 nodes are available: 5 No preemption victims found for incoming pod."
I0506 15:10:54.662981      12 schedule_one.go:314] "Successfully bound pod to node" pod="default/cspod-46" node="csnode-1" evaluatedNodes=5 feasibleNodes=2
I0506 15:10:54.683818      12 schedule_one.go:314] "Successfully bound pod to node" pod="default/cspod-47" node="csnode-0" evaluatedNodes=5 feasibleNodes=1
I0506 15:10:54.703801      12 preemption.go:264] "No preemption candidate is found; preemption is not helpful for scheduling" pod="default/cspod-49"
I0506 15:10:54.703843      12 schedule_one.go:1044] "Unable to schedule pod; no fit; waiting" pod="default/cspod-49" err="0/5 nodes are available: 5 Insufficient cpu. preemption: 0/5 nodes are available: 5 No preemption victims found for incoming pod."
I0506 15:10:54.724058      12 preemption.go:264] "No preemption candidate is found; preemption is not helpful for scheduling" pod="default/cspod-50"
I0506 15:10:54.724100      12 schedule_one.go:1044] "Unable to schedule pod; no fit; waiting" pod="default/cspod-50" err="0/5 nodes are available: 5 Insufficient cpu. preemption: 0/5 nodes are available: 5 No preemption victims found for incoming pod."
I0506 15:10:54.743312      12 preemption.go:264] "No preemption candidate is found; preemption is not helpful for scheduling" pod="default/cspod-51"
I0506 15:10:54.743360      12 schedule_one.go:1044] "Unable to schedule pod; no fit; waiting" pod="default/cspod-51" err="0/5 nodes are available: 5 Insufficient cpu. preemption: 0/5 nodes are available: 5 No preemption victims found for incoming pod."
I0506 15:10:54.763782      12 preemption.go:264] "No preemption candidate is found; preemption is not helpful for scheduling" pod="default/cspod-52"
I0506 15:10:54.763859      12 schedule_one.go:1044] "Unable to schedule pod; no fit; waiting" pod="default/cspod-52" err="0/5 nodes are available: 5 Insufficient cpu. preemption: 0/5 nodes are available: 5 No preemption victims found for incoming pod."
I0506 15:10:54.784271      12 preemption.go:264] "No preemption candidate is found; preemption is not helpful for scheduling" pod="default/cspod-53"
I0506 15:10:54.784330      12 schedule_one.go:1044] "Unable to schedule pod; no fit; waiting" pod="default/cspod-53" err="0/5 nodes are available: 5 Insufficient cpu. preemption: 0/5 nodes are available: 5 No preemption victims found for incoming pod."
I0506 15:10:54.803785      12 preemption.go:264] "No preemption candidate is found; preemption is not helpful for scheduling" pod="default/cspod-54"
I0506 15:10:54.803831      12 schedule_one.go:1044] "Unable to schedule pod; no fit; waiting" pod="default/cspod-54" err="0/5 nodes are available: 5 Insufficient cpu. preemption: 0/5 nodes are available: 5 No preemption victims found for incoming pod."
I0506 15:10:54.830266      12 preemption.go:264] "No preemption candidate is found; preemption is not helpful for scheduling" pod="default/cspod-49"
I0506 15:10:54.830305      12 schedule_one.go:1044] "Unable to schedule pod; no fit; waiting" pod="default/cspod-49" err="0/5 nodes are available: 5 Insufficient cpu. preemption: 0/5 nodes are available: 5 No preemption victims found for incoming pod."
I0506 15:10:54.843719      12 schedule_one.go:314] "Successfully bound pod to node" pod="default/cspod-48" node="csnode-3" evaluatedNodes=5 feasibleNodes=1
I0506 15:10:54.863698      12 preemption.go:264] "No preemption candidate is found; preemption is not helpful for scheduling" pod="default/cspod-50"
I0506 15:10:54.863742      12 schedule_one.go:1044] "Unable to schedule pod; no fit; waiting" pod="default/cspod-50" err="0/5 nodes are available: 5 Insufficient cpu. preemption: 0/5 nodes are available: 5 No preemption victims found for incoming pod."
I0506 15:10:54.883448      12 preemption.go:264] "No preemption candidate is found; preemption is not helpful for scheduling" pod="default/cspod-51"
I0506 15:10:54.883518      12 schedule_one.go:1044] "Unable to schedule pod; no fit; waiting" pod="default/cspod-51" err="0/5 nodes are available: 5 Insufficient cpu. preemption: 0/5 nodes are available: 5 No preemption victims found for incoming pod."
I0506 15:10:54.903535      12 preemption.go:264] "No preemption candidate is found; preemption is not helpful for scheduling" pod="default/cspod-52"
I0506 15:10:54.903601      12 schedule_one.go:1044] "Unable to schedule pod; no fit; waiting" pod="default/cspod-52" err="0/5 nodes are available: 5 Insufficient cpu. preemption: 0/5 nodes are available: 5 No preemption victims found for incoming pod."
I0506 15:10:54.923991      12 preemption.go:264] "No preemption candidate is found; preemption is not helpful for scheduling" pod="default/cspod-53"
I0506 15:10:54.924043      12 schedule_one.go:1044] "Unable to schedule pod; no fit; waiting" pod="default/cspod-53" err="0/5 nodes are available: 5 Insufficient cpu. preemption: 0/5 nodes are available: 5 No preemption victims found for incoming pod."
I0506 15:10:54.944155      12 preemption.go:264] "No preemption candidate is found; preemption is not helpful for scheduling" pod="default/cspod-54"
I0506 15:10:54.944228      12 schedule_one.go:1044] "Unable to schedule pod; no fit; waiting" pod="default/cspod-54" err="0/5 nodes are available: 5 Insufficient cpu. preemption: 0/5 nodes are available: 5 No preemption victims found for incoming pod."
I0506 15:10:54.969785      12 preemption.go:264] "No preemption candidate is found; preemption is not helpful for scheduling" pod="default/cspod-53"
I0506 15:10:54.969831      12 schedule_one.go:1044] "Unable to schedule pod; no fit; waiting" pod="default/cspod-53" err="0/5 nodes are available: 5 Insufficient cpu. preemption: 0/5 nodes are available: 5 No preemption victims found for incoming pod."
I0506 15:10:54.983758      12 schedule_one.go:314] "Successfully bound pod to node" pod="default/cspod-50" node="csnode-4" evaluatedNodes=5 feasibleNodes=1
I0506 15:10:55.003540      12 schedule_one.go:314] "Successfully bound pod to node" pod="default/cspod-49" node="csnode-4" evaluatedNodes=5 feasibleNodes=1
I0506 15:10:55.023541      12 schedule_one.go:314] "Successfully bound pod to node" pod="default/cspod-51" node="csnode-4" evaluatedNodes=5 feasibleNodes=1
I0506 15:10:55.043403      12 schedule_one.go:314] "Successfully bound pod to node" pod="default/cspod-52" node="csnode-4" evaluatedNodes=5 feasibleNodes=1
I0506 15:10:55.065042      12 preemption.go:264] "No preemption candidate is found; preemption is not helpful for scheduling" pod="default/cspod-54"
I0506 15:10:55.065188      12 schedule_one.go:1044] "Unable to schedule pod; no fit; waiting" pod="default/cspod-54" err="0/5 nodes are available: 5 Insufficient cpu. preemption: 0/5 nodes are available: 5 No preemption victims found for incoming pod."
I0506 15:10:55.103028      12 schedule_one.go:314] "Successfully bound pod to node" pod="default/cspod-53" node="csnode-2" evaluatedNodes=5 feasibleNodes=2
I0506 15:10:55.123372      12 schedule_one.go:314] "Successfully bound pod to node" pod="default/cspod-54" node="csnode-2" evaluatedNodes=5 feasibleNodes=2
I0506 15:10:55.144611      12 node_tree.go:79] "Removed node from NodeTree" node="csnode-2" zone=""
I0506 15:10:55.144649      12 node_tree.go:79] "Removed node from NodeTree" node="csnode-3" zone=""
I0506 15:10:55.144676      12 node_tree.go:79] "Removed node from NodeTree" node="csnode-4" zone=""
I0506 15:10:55.144693      12 node_tree.go:79] "Removed node from NodeTree" node="csnode-0" zone=""
I0506 15:10:55.144749      12 node_tree.go:79] "Removed node from NodeTree" node="csnode-1" zone=""
E0506 15:10:55.664534      12 event.go:368] "Unable to write event (may retry after sleeping)" err="0-length response with status code: 201 and content type: application/vnd.kubernetes.protobuf" event="&Event{ObjectMeta:{cspod-1.18ad028e7e2c5395  default    0 0001-01-01 00:00:00 +0000 UTC <nil> <nil> map[] map[] [] [] []},InvolvedObject:ObjectReference{Kind:Pod,Namespace:default,Name:cspod-1,UID:cspod-1-uid,APIVersion:v1,ResourceVersion:7,FieldPath:,},Reason:Scheduled,Message:Successfully assigned default/cspod-1 to csnode-0,Source:EventSource{Component:default-scheduler,Host:,},FirstTimestamp:2026-05-06 15:10:38.906659733 +0000 UTC m=+7.311898370,LastTimestamp:2026-05-06 15:10:38.906659733 +0000 UTC m=+7.311898370,Count:1,Type:Normal,EventTime:0001-01-01 00:00:00 +0000 UTC,Series:nil,Action:,Related:nil,ReportingController:default-scheduler,ReportingInstance:,}"
