2026/05/06 16:10:59 Starting K8s Sim Control Plane with Fake API Server on port :8080
Using scheduler: volcano
2026/05/06 16:10:59 Serving HTTP API on :8080
2026/05/06 16:10:59 Fake Kubernetes API server ready for kube-scheduler connections
2026/05/06 16:10:59 Start kube-scheduler with: --master http://localhost:8080 --leader-elect=false
2026/05/06 16:11:00 Scheduling round reset
2026/05/06 16:11:00 {"action":"HandleReset","result":"ok","roundId":"-","ts":"2026-05-06T16:11:00.282410039+01:00"}
2026/05/06 16:11:01 Volcano queue created: default
2026/05/06 16:11:03 Scheduling round reset
2026/05/06 16:11:03 {"action":"HandleReset","result":"ok","roundId":"-","ts":"2026-05-06T16:11:03.462607791+01:00"}
2026/05/06 16:11:03 Scheduling round reset
2026/05/06 16:11:03 {"action":"HandleReset","result":"ok","roundId":"-","ts":"2026-05-06T16:11:03.466632106+01:00"}
2026/05/06 16:11:08 {"action":"HandleNodes","durationMs":0,"nodeCount":5,"result":"ok","roundId":"0","ts":"2026-05-06T16:11:08.36862299+01:00"}
2026/05/06 16:11:08 {"action":"HandleSchedule","completedIds":0,"nodeCount":5,"phase":"start","podCount":37,"roundId":"1","ts":"2026-05-06T16:11:08.393990897+01:00"}
2026/05/06 16:11:08 {"action":"ensureVolcanoQueue","queue":"high-priority","ts":"2026-05-06T16:11:08.394168388+01:00","weight":3}
2026/05/06 16:11:08 {"action":"ensureVolcanoQueue","queue":"batch","ts":"2026-05-06T16:11:08.394215431+01:00","weight":1}
2026/05/06 16:11:08 {"action":"HandleSchedule","phase":"prep_done","podsCreated":37,"prepMs":0,"roundId":"1","staleDeleted":0,"ts":"2026-05-06T16:11:08.394565893+01:00"}
2026/05/06 16:11:08 Scheduling round started: expecting 37 decisions
2026/05/06 16:11:08 Failure: pod=cspod-7 reason="pod group is not ready, 1 Pending, 1 minAvailable; Pending: 1 Unschedulable" (1/37 resolved)
2026/05/06 16:11:08 Failure: pod=cspod-4 reason="pod group is not ready, 1 Pending, 1 minAvailable; Pending: 1 Unschedulable" (2/37 resolved)
2026/05/06 16:11:08 Failure: pod=cspod-9 reason="pod group is not ready, 1 Pending, 1 minAvailable; Pending: 1 Unschedulable" (3/37 resolved)
2026/05/06 16:11:08 Failure: pod=cspod-28 reason="pod group is not ready, 1 Pending, 1 minAvailable; Pending: 1 Unschedulable" (4/37 resolved)
2026/05/06 16:11:08 Failure: pod=cspod-26 reason="pod group is not ready, 1 Pending, 1 minAvailable; Pending: 1 Unschedulable" (5/37 resolved)
2026/05/06 16:11:08 Failure: pod=cspod-17 reason="pod group is not ready, 1 Pending, 1 minAvailable; Pending: 1 Unschedulable" (6/37 resolved)
2026/05/06 16:11:08 Failure: pod=cspod-18 reason="pod group is not ready, 1 Pending, 1 minAvailable; Pending: 1 Unschedulable" (7/37 resolved)
2026/05/06 16:11:08 Failure: pod=cspod-23 reason="pod group is not ready, 1 Pending, 1 minAvailable; Pending: 1 Unschedulable" (8/37 resolved)
2026/05/06 16:11:08 Failure: pod=cspod-8 reason="pod group is not ready, 1 Pending, 1 minAvailable; Pending: 1 Unschedulable" (9/37 resolved)
2026/05/06 16:11:08 Failure: pod=cspod-24 reason="pod group is not ready, 1 Pending, 1 minAvailable; Pending: 1 Unschedulable" (10/37 resolved)
2026/05/06 16:11:08 Failure: pod=cspod-3 reason="pod group is not ready, 1 Pending, 1 minAvailable; Pending: 1 Unschedulable" (11/37 resolved)
2026/05/06 16:11:08 Failure: pod=cspod-33 reason="pod group is not ready, 4 Pending, 4 minAvailable; Pending: 4 Unschedulable" (12/37 resolved)
2026/05/06 16:11:08 Failure: pod=cspod-29 reason="pod group is not ready, 1 Pending, 1 minAvailable; Pending: 1 Unschedulable" (13/37 resolved)
2026/05/06 16:11:08 Failure: pod=cspod-6 reason="pod group is not ready, 1 Pending, 1 minAvailable; Pending: 1 Unschedulable" (14/37 resolved)
2026/05/06 16:11:08 Failure: pod=cspod-25 reason="pod group is not ready, 1 Pending, 1 minAvailable; Pending: 1 Unschedulable" (15/37 resolved)
2026/05/06 16:11:08 Failure: pod=cspod-19 reason="pod group is not ready, 1 Pending, 1 minAvailable; Pending: 1 Unschedulable" (16/37 resolved)
2026/05/06 16:11:08 Failure: pod=cspod-5 reason="pod group is not ready, 1 Pending, 1 minAvailable; Pending: 1 Unschedulable" (17/37 resolved)
2026/05/06 16:11:08 Failure: pod=cspod-30 reason="pod group is not ready, 3 Pending, 3 minAvailable; Pending: 3 Unschedulable" (18/37 resolved)
2026/05/06 16:11:08 Failure: pod=cspod-34 reason="pod group is not ready, 4 Pending, 4 minAvailable; Pending: 4 Unschedulable" (19/37 resolved)
2026/05/06 16:11:08 Failure: pod=cspod-27 reason="pod group is not ready, 1 Pending, 1 minAvailable; Pending: 1 Unschedulable" (20/37 resolved)
2026/05/06 16:11:08 Failure: pod=cspod-2 reason="pod group is not ready, 1 Pending, 1 minAvailable; Pending: 1 Unschedulable" (21/37 resolved)
2026/05/06 16:11:08 Failure: pod=cspod-31 reason="pod group is not ready, 3 Pending, 3 minAvailable; Pending: 3 Unschedulable" (22/37 resolved)
2026/05/06 16:11:08 Failure: pod=cspod-35 reason="pod group is not ready, 4 Pending, 4 minAvailable; Pending: 4 Unschedulable" (23/37 resolved)
2026/05/06 16:11:08 Failure: pod=cspod-32 reason="pod group is not ready, 3 Pending, 3 minAvailable; Pending: 3 Unschedulable" (24/37 resolved)
2026/05/06 16:11:08 Failure: pod=cspod-36 reason="pod group is not ready, 4 Pending, 4 minAvailable; Pending: 4 Unschedulable" (25/37 resolved)
2026/05/06 16:11:08 Binding: pod=cspod-1 -> node=csnode-1 (26/37 resolved)
2026/05/06 16:11:08 Binding: pod=cspod-16 -> node=csnode-4 (27/37 resolved)
2026/05/06 16:11:08 Binding: pod=cspod-22 -> node=csnode-4 (28/37 resolved)
2026/05/06 16:11:08 Binding: pod=cspod-12 -> node=csnode-0 (29/37 resolved)
2026/05/06 16:11:08 Binding: pod=cspod-14 -> node=csnode-4 (30/37 resolved)
2026/05/06 16:11:08 Binding: pod=cspod-21 -> node=csnode-3 (31/37 resolved)
2026/05/06 16:11:08 Binding: pod=cspod-10 -> node=csnode-1 (32/37 resolved)
2026/05/06 16:11:08 Binding: pod=cspod-13 -> node=csnode-0 (33/37 resolved)
2026/05/06 16:11:08 Binding: pod=cspod-15 -> node=csnode-4 (34/37 resolved)
2026/05/06 16:11:08 Binding: pod=cspod-11 -> node=csnode-3 (35/37 resolved)
2026/05/06 16:11:08 Binding: pod=cspod-20 -> node=csnode-2 (36/37 resolved)
2026/05/06 16:11:08 Binding: pod=cspod-0 -> node=csnode-2 (37/37 resolved)
2026/05/06 16:11:08 Round complete: 12 scheduled, 25 failed in 93.77168ms
2026/05/06 16:11:08 {"action":"HandleSchedule","durationMs":94,"podCount":37,"result":"ok","roundId":"1","scheduled":12,"ts":"2026-05-06T16:11:08.488401963+01:00","unschedulable":25}
2026/05/06 16:11:08 {"action":"HandleSchedule","completedIds":0,"nodeCount":5,"phase":"start","podCount":18,"roundId":"2","ts":"2026-05-06T16:11:08.576231717+01:00"}
2026/05/06 16:11:08 {"action":"HandleSchedule","phase":"prep_done","podsCreated":18,"prepMs":0,"roundId":"2","staleDeleted":0,"ts":"2026-05-06T16:11:08.576625661+01:00"}
2026/05/06 16:11:08 Scheduling round started: expecting 18 decisions
2026/05/06 16:11:09 Failure: pod=cspod-39 reason="pod group is not ready, 1 Pending, 1 minAvailable; Pending: 1 Unschedulable" (1/18 resolved)
2026/05/06 16:11:09 Failure: pod=cspod-37 reason="pod group is not ready, 1 Pending, 1 minAvailable; Pending: 1 Unschedulable" (2/18 resolved)
2026/05/06 16:11:09 Failure: pod=cspod-40 reason="pod group is not ready, 1 Pending, 1 minAvailable; Pending: 1 Unschedulable" (3/18 resolved)
2026/05/06 16:11:09 Failure: pod=cspod-38 reason="pod group is not ready, 1 Pending, 1 minAvailable; Pending: 1 Unschedulable" (4/18 resolved)
2026/05/06 16:11:09 Failure: pod=cspod-46 reason="pod group is not ready, 1 Pending, 1 minAvailable; Pending: 1 Unschedulable" (5/18 resolved)
2026/05/06 16:11:09 Failure: pod=cspod-49 reason="pod group is not ready, 1 Pending, 1 minAvailable; Pending: 1 Unschedulable" (6/18 resolved)
2026/05/06 16:11:09 Failure: pod=cspod-45 reason="pod group is not ready, 1 Pending, 1 minAvailable; Pending: 1 Unschedulable" (7/18 resolved)
2026/05/06 16:11:09 Failure: pod=cspod-47 reason="pod group is not ready, 1 Pending, 1 minAvailable; Pending: 1 Unschedulable" (8/18 resolved)
2026/05/06 16:11:09 Failure: pod=cspod-43 reason="pod group is not ready, 1 Pending, 1 minAvailable; Pending: 1 Unschedulable" (9/18 resolved)
2026/05/06 16:11:09 Failure: pod=cspod-42 reason="pod group is not ready, 1 Pending, 1 minAvailable; Pending: 1 Unschedulable" (10/18 resolved)
2026/05/06 16:11:09 Failure: pod=cspod-52 reason="pod group is not ready, 3 Pending, 3 minAvailable; Pending: 3 Unschedulable" (11/18 resolved)
2026/05/06 16:11:09 Failure: pod=cspod-41 reason="pod group is not ready, 1 Pending, 1 minAvailable; Pending: 1 Unschedulable" (12/18 resolved)
2026/05/06 16:11:09 Failure: pod=cspod-53 reason="pod group is not ready, 3 Pending, 3 minAvailable; Pending: 3 Unschedulable" (13/18 resolved)
2026/05/06 16:11:09 Failure: pod=cspod-44 reason="pod group is not ready, 1 Pending, 1 minAvailable; Pending: 1 Unschedulable" (14/18 resolved)
2026/05/06 16:11:09 Failure: pod=cspod-51 reason="pod group is not ready, 1 Pending, 1 minAvailable; Pending: 1 Unschedulable" (15/18 resolved)
2026/05/06 16:11:09 Failure: pod=cspod-48 reason="pod group is not ready, 1 Pending, 1 minAvailable; Pending: 1 Unschedulable" (16/18 resolved)
2026/05/06 16:11:09 Failure: pod=cspod-50 reason="pod group is not ready, 1 Pending, 1 minAvailable; Pending: 1 Unschedulable" (17/18 resolved)
2026/05/06 16:11:09 Failure: pod=cspod-54 reason="pod group is not ready, 3 Pending, 3 minAvailable; Pending: 3 Unschedulable" (18/18 resolved)
2026/05/06 16:11:09 Round complete: 0 scheduled, 18 failed in 910.70209ms
2026/05/06 16:11:09 {"action":"HandleSchedule","durationMs":911,"podCount":18,"result":"ok","roundId":"2","scheduled":0,"ts":"2026-05-06T16:11:09.487453187+01:00","unschedulable":18}
2026/05/06 16:11:09 {"action":"HandleSchedule","completedIds":3,"nodeCount":5,"phase":"start","podCount":43,"roundId":"3","ts":"2026-05-06T16:11:09.505473004+01:00"}
2026/05/06 16:11:09 {"action":"HandleSchedule","phase":"prep_done","podsCreated":43,"prepMs":2,"roundId":"3","staleDeleted":0,"ts":"2026-05-06T16:11:09.507380279+01:00"}
2026/05/06 16:11:09 Scheduling round started: expecting 43 decisions
2026/05/06 16:11:10 Failure: pod=cspod-8 reason="pod group is not ready, 1 Pending, 1 minAvailable; Pending: 1 Unschedulable" (1/43 resolved)
2026/05/06 16:11:10 Failure: pod=cspod-23 reason="pod group is not ready, 1 Pending, 1 minAvailable; Pending: 1 Unschedulable" (2/43 resolved)
2026/05/06 16:11:10 Failure: pod=cspod-7 reason="pod group is not ready, 1 Pending, 1 minAvailable; Pending: 1 Unschedulable" (3/43 resolved)
2026/05/06 16:11:10 Failure: pod=cspod-54 reason="pod group is not ready, 3 Pending, 3 minAvailable; Pending: 3 Unschedulable" (4/43 resolved)
2026/05/06 16:11:10 Failure: pod=cspod-42 reason="pod group is not ready, 1 Pending, 1 minAvailable; Pending: 1 Unschedulable" (5/43 resolved)
2026/05/06 16:11:10 Failure: pod=cspod-6 reason="pod group is not ready, 1 Pending, 1 minAvailable; Pending: 1 Unschedulable" (6/43 resolved)
2026/05/06 16:11:10 Failure: pod=cspod-40 reason="pod group is not ready, 1 Pending, 1 minAvailable; Pending: 1 Unschedulable" (7/43 resolved)
2026/05/06 16:11:10 Failure: pod=cspod-2 reason="pod group is not ready, 1 Pending, 1 minAvailable; Pending: 1 Unschedulable" (8/43 resolved)
2026/05/06 16:11:10 Failure: pod=cspod-47 reason="pod group is not ready, 1 Pending, 1 minAvailable; Pending: 1 Unschedulable" (9/43 resolved)
2026/05/06 16:11:10 Failure: pod=cspod-51 reason="pod group is not ready, 1 Pending, 1 minAvailable; Pending: 1 Unschedulable" (10/43 resolved)
2026/05/06 16:11:10 Failure: pod=cspod-45 reason="pod group is not ready, 1 Pending, 1 minAvailable; Pending: 1 Unschedulable" (11/43 resolved)
2026/05/06 16:11:10 Failure: pod=cspod-37 reason="pod group is not ready, 1 Pending, 1 minAvailable; Pending: 1 Unschedulable" (12/43 resolved)
2026/05/06 16:11:10 Failure: pod=cspod-4 reason="pod group is not ready, 1 Pending, 1 minAvailable; Pending: 1 Unschedulable" (13/43 resolved)
2026/05/06 16:11:10 Failure: pod=cspod-39 reason="pod group is not ready, 1 Pending, 1 minAvailable; Pending: 1 Unschedulable" (14/43 resolved)
2026/05/06 16:11:10 Failure: pod=cspod-33 reason="pod group is not ready, 4 Pending, 4 minAvailable; Pending: 4 Unschedulable" (15/43 resolved)
2026/05/06 16:11:10 Binding: pod=cspod-17 -> node=csnode-4 (16/43 resolved)
2026/05/06 16:11:10 Failure: pod=cspod-29 reason="pod group is not ready, 1 Pending, 1 minAvailable; Pending: 1 Unschedulable" (17/43 resolved)
2026/05/06 16:11:10 Binding: pod=cspod-19 -> node=csnode-4 (18/43 resolved)
2026/05/06 16:11:10 Binding: pod=cspod-18 -> node=csnode-4 (19/43 resolved)
2026/05/06 16:11:10 Failure: pod=cspod-52 reason="pod group is not ready, 3 Pending, 3 minAvailable; Pending: 3 Unschedulable" (20/43 resolved)
2026/05/06 16:11:10 Failure: pod=cspod-46 reason="pod group is not ready, 1 Pending, 1 minAvailable; Pending: 1 Unschedulable" (21/43 resolved)
2026/05/06 16:11:10 Failure: pod=cspod-34 reason="pod group is not ready, 4 Pending, 4 minAvailable; Pending: 4 Unschedulable" (22/43 resolved)
2026/05/06 16:11:10 Failure: pod=cspod-43 reason="pod group is not ready, 1 Pending, 1 minAvailable; Pending: 1 Unschedulable" (23/43 resolved)
2026/05/06 16:11:10 Failure: pod=cspod-27 reason="pod group is not ready, 1 Pending, 1 minAvailable; Pending: 1 Unschedulable" (24/43 resolved)
2026/05/06 16:11:10 Failure: pod=cspod-3 reason="pod group is not ready, 1 Pending, 1 minAvailable; Pending: 1 Unschedulable" (25/43 resolved)
2026/05/06 16:11:10 Failure: pod=cspod-48 reason="pod group is not ready, 1 Pending, 1 minAvailable; Pending: 1 Unschedulable" (26/43 resolved)
2026/05/06 16:11:10 Failure: pod=cspod-26 reason="pod group is not ready, 1 Pending, 1 minAvailable; Pending: 1 Unschedulable" (27/43 resolved)
2026/05/06 16:11:10 Failure: pod=cspod-30 reason="pod group is not ready, 3 Pending, 3 minAvailable; Pending: 3 Unschedulable" (28/43 resolved)
2026/05/06 16:11:10 Failure: pod=cspod-53 reason="pod group is not ready, 3 Pending, 3 minAvailable; Pending: 3 Unschedulable" (29/43 resolved)
2026/05/06 16:11:10 Failure: pod=cspod-24 reason="pod group is not ready, 1 Pending, 1 minAvailable; Pending: 1 Unschedulable" (30/43 resolved)
2026/05/06 16:11:10 Failure: pod=cspod-9 reason="pod group is not ready, 1 Pending, 1 minAvailable; Pending: 1 Unschedulable" (31/43 resolved)
2026/05/06 16:11:10 Failure: pod=cspod-41 reason="pod group is not ready, 1 Pending, 1 minAvailable; Pending: 1 Unschedulable" (32/43 resolved)
2026/05/06 16:11:10 Failure: pod=cspod-44 reason="pod group is not ready, 1 Pending, 1 minAvailable; Pending: 1 Unschedulable" (33/43 resolved)
2026/05/06 16:11:10 Failure: pod=cspod-49 reason="pod group is not ready, 1 Pending, 1 minAvailable; Pending: 1 Unschedulable" (34/43 resolved)
2026/05/06 16:11:10 Failure: pod=cspod-25 reason="pod group is not ready, 1 Pending, 1 minAvailable; Pending: 1 Unschedulable" (35/43 resolved)
2026/05/06 16:11:10 Failure: pod=cspod-38 reason="pod group is not ready, 1 Pending, 1 minAvailable; Pending: 1 Unschedulable" (36/43 resolved)
2026/05/06 16:11:10 Failure: pod=cspod-50 reason="pod group is not ready, 1 Pending, 1 minAvailable; Pending: 1 Unschedulable" (37/43 resolved)
2026/05/06 16:11:10 Failure: pod=cspod-31 reason="pod group is not ready, 3 Pending, 3 minAvailable; Pending: 3 Unschedulable" (38/43 resolved)
2026/05/06 16:11:10 Failure: pod=cspod-35 reason="pod group is not ready, 4 Pending, 4 minAvailable; Pending: 4 Unschedulable" (39/43 resolved)
2026/05/06 16:11:10 Failure: pod=cspod-28 reason="pod group is not ready, 1 Pending, 1 minAvailable; Pending: 1 Unschedulable" (40/43 resolved)
2026/05/06 16:11:10 Failure: pod=cspod-5 reason="pod group is not ready, 1 Pending, 1 minAvailable; Pending: 1 Unschedulable" (41/43 resolved)
2026/05/06 16:11:10 Failure: pod=cspod-36 reason="pod group is not ready, 4 Pending, 4 minAvailable; Pending: 4 Unschedulable" (42/43 resolved)
2026/05/06 16:11:10 Failure: pod=cspod-32 reason="pod group is not ready, 3 Pending, 3 minAvailable; Pending: 3 Unschedulable" (43/43 resolved)
2026/05/06 16:11:10 Round complete: 3 scheduled, 40 failed in 991.706473ms
2026/05/06 16:11:10 {"action":"HandleSchedule","durationMs":993,"podCount":43,"result":"ok","roundId":"3","scheduled":3,"ts":"2026-05-06T16:11:10.499177196+01:00","unschedulable":40}
2026/05/06 16:11:10 {"action":"HandleSchedule","completedIds":0,"nodeCount":5,"phase":"start","podCount":15,"roundId":"4","ts":"2026-05-06T16:11:10.509295861+01:00"}
2026/05/06 16:11:10 {"action":"HandleSchedule","phase":"prep_done","podsCreated":15,"prepMs":0,"roundId":"4","staleDeleted":0,"ts":"2026-05-06T16:11:10.509531266+01:00"}
2026/05/06 16:11:10 Scheduling round started: expecting 15 decisions
2026/05/06 16:11:11 Failure: pod=cspod-55 reason="pod group is not ready, 1 Pending, 1 minAvailable; Pending: 1 Unschedulable" (1/15 resolved)
2026/05/06 16:11:11 Failure: pod=cspod-67 reason="pod group is not ready, 1 Pending, 1 minAvailable; Pending: 1 Unschedulable" (2/15 resolved)
2026/05/06 16:11:11 Failure: pod=cspod-59 reason="pod group is not ready, 1 Pending, 1 minAvailable; Pending: 1 Unschedulable" (3/15 resolved)
2026/05/06 16:11:11 Failure: pod=cspod-69 reason="pod group is not ready, 1 Pending, 1 minAvailable; Pending: 1 Unschedulable" (4/15 resolved)
2026/05/06 16:11:11 Failure: pod=cspod-58 reason="pod group is not ready, 1 Pending, 1 minAvailable; Pending: 1 Unschedulable" (5/15 resolved)
2026/05/06 16:11:11 Failure: pod=cspod-62 reason="pod group is not ready, 1 Pending, 1 minAvailable; Pending: 1 Unschedulable" (6/15 resolved)
2026/05/06 16:11:11 Failure: pod=cspod-60 reason="pod group is not ready, 1 Pending, 1 minAvailable; Pending: 1 Unschedulable" (7/15 resolved)
2026/05/06 16:11:11 Failure: pod=cspod-56 reason="pod group is not ready, 1 Pending, 1 minAvailable; Pending: 1 Unschedulable" (8/15 resolved)
2026/05/06 16:11:11 Failure: pod=cspod-68 reason="pod group is not ready, 1 Pending, 1 minAvailable; Pending: 1 Unschedulable" (9/15 resolved)
2026/05/06 16:11:11 Failure: pod=cspod-61 reason="pod group is not ready, 1 Pending, 1 minAvailable; Pending: 1 Unschedulable" (10/15 resolved)
2026/05/06 16:11:11 Failure: pod=cspod-65 reason="pod group is not ready, 1 Pending, 1 minAvailable; Pending: 1 Unschedulable" (11/15 resolved)
2026/05/06 16:11:11 Failure: pod=cspod-64 reason="pod group is not ready, 1 Pending, 1 minAvailable; Pending: 1 Unschedulable" (12/15 resolved)
2026/05/06 16:11:11 Failure: pod=cspod-57 reason="pod group is not ready, 1 Pending, 1 minAvailable; Pending: 1 Unschedulable" (13/15 resolved)
2026/05/06 16:11:11 Failure: pod=cspod-63 reason="pod group is not ready, 1 Pending, 1 minAvailable; Pending: 1 Unschedulable" (14/15 resolved)
2026/05/06 16:11:11 Failure: pod=cspod-66 reason="pod group is not ready, 1 Pending, 1 minAvailable; Pending: 1 Unschedulable" (15/15 resolved)
2026/05/06 16:11:11 Round complete: 0 scheduled, 15 failed in 996.595358ms
2026/05/06 16:11:11 {"action":"HandleSchedule","durationMs":997,"podCount":15,"result":"ok","roundId":"4","scheduled":0,"ts":"2026-05-06T16:11:11.506220799+01:00","unschedulable":15}
2026/05/06 16:11:11 {"action":"HandleSchedule","completedIds":2,"nodeCount":5,"phase":"start","podCount":55,"roundId":"5","ts":"2026-05-06T16:11:11.518038929+01:00"}
2026/05/06 16:11:11 {"action":"HandleSchedule","phase":"prep_done","podsCreated":55,"prepMs":20,"roundId":"5","staleDeleted":0,"ts":"2026-05-06T16:11:11.538023051+01:00"}
2026/05/06 16:11:11 Scheduling round started: expecting 55 decisions
2026/05/06 16:11:10 Failure: pod=cspod-29 reason="pod group is not ready, 1 Pending, 1 minAvailable; Pending: 1 Unschedulable" (1/55 resolved)
2026/05/06 16:11:10 Failure: pod=cspod-64 reason="pod group is not ready, 1 Pending, 1 minAvailable; Pending: 1 Unschedulable" (2/55 resolved)
2026/05/06 16:11:10 Failure: pod=cspod-45 reason="pod group is not ready, 1 Pending, 1 minAvailable; Pending: 1 Unschedulable" (3/55 resolved)
2026/05/06 16:11:10 Failure: pod=cspod-37 reason="pod group is not ready, 1 Pending, 1 minAvailable; Pending: 1 Unschedulable" (4/55 resolved)
2026/05/06 16:11:10 Failure: pod=cspod-50 reason="pod group is not ready, 1 Pending, 1 minAvailable; Pending: 1 Unschedulable" (5/55 resolved)
2026/05/06 16:11:10 Failure: pod=cspod-59 reason="pod group is not ready, 1 Pending, 1 minAvailable; Pending: 1 Unschedulable" (6/55 resolved)
2026/05/06 16:11:10 Failure: pod=cspod-26 reason="pod group is not ready, 1 Pending, 1 minAvailable; Pending: 1 Unschedulable" (7/55 resolved)
2026/05/06 16:11:10 Failure: pod=cspod-39 reason="pod group is not ready, 1 Pending, 1 minAvailable; Pending: 1 Unschedulable" (8/55 resolved)
2026/05/06 16:11:10 Failure: pod=cspod-44 reason="pod group is not ready, 1 Pending, 1 minAvailable; Pending: 1 Unschedulable" (9/55 resolved)
2026/05/06 16:11:10 Failure: pod=cspod-41 reason="pod group is not ready, 1 Pending, 1 minAvailable; Pending: 1 Unschedulable" (10/55 resolved)
2026/05/06 16:11:10 Failure: pod=cspod-52 reason="pod group is not ready, 3 Pending, 3 minAvailable; Pending: 3 Unschedulable" (11/55 resolved)
2026/05/06 16:11:10 Failure: pod=cspod-57 reason="pod group is not ready, 1 Pending, 1 minAvailable; Pending: 1 Unschedulable" (12/55 resolved)
2026/05/06 16:11:10 Failure: pod=cspod-51 reason="pod group is not ready, 1 Pending, 1 minAvailable; Pending: 1 Unschedulable" (13/55 resolved)
2026/05/06 16:11:10 Failure: pod=cspod-9 reason="pod group is not ready, 1 Pending, 1 minAvailable; Pending: 1 Unschedulable" (14/55 resolved)
2026/05/06 16:11:10 Failure: pod=cspod-27 reason="pod group is not ready, 1 Pending, 1 minAvailable; Pending: 1 Unschedulable" (15/55 resolved)
2026/05/06 16:11:10 Failure: pod=cspod-8 reason="pod group is not ready, 1 Pending, 1 minAvailable; Pending: 1 Unschedulable" (16/55 resolved)
2026/05/06 16:11:10 Failure: pod=cspod-48 reason="pod group is not ready, 1 Pending, 1 minAvailable; Pending: 1 Unschedulable" (17/55 resolved)
2026/05/06 16:11:10 Failure: pod=cspod-28 reason="pod group is not ready, 1 Pending, 1 minAvailable; Pending: 1 Unschedulable" (18/55 resolved)
2026/05/06 16:11:10 Failure: pod=cspod-56 reason="pod group is not ready, 1 Pending, 1 minAvailable; Pending: 1 Unschedulable" (19/55 resolved)
2026/05/06 16:11:10 Failure: pod=cspod-43 reason="pod group is not ready, 1 Pending, 1 minAvailable; Pending: 1 Unschedulable" (20/55 resolved)
2026/05/06 16:11:10 Failure: pod=cspod-6 reason="pod group is not ready, 1 Pending, 1 minAvailable; Pending: 1 Unschedulable" (21/55 resolved)
2026/05/06 16:11:10 Failure: pod=cspod-7 reason="pod group is not ready, 1 Pending, 1 minAvailable; Pending: 1 Unschedulable" (22/55 resolved)
2026/05/06 16:11:10 Failure: pod=cspod-61 reason="pod group is not ready, 1 Pending, 1 minAvailable; Pending: 1 Unschedulable" (23/55 resolved)
2026/05/06 16:11:10 Failure: pod=cspod-53 reason="pod group is not ready, 3 Pending, 3 minAvailable; Pending: 3 Unschedulable" (24/55 resolved)
2026/05/06 16:11:10 Failure: pod=cspod-25 reason="pod group is not ready, 1 Pending, 1 minAvailable; Pending: 1 Unschedulable" (25/55 resolved)
2026/05/06 16:11:10 Failure: pod=cspod-58 reason="pod group is not ready, 1 Pending, 1 minAvailable; Pending: 1 Unschedulable" (26/55 resolved)
2026/05/06 16:11:10 Failure: pod=cspod-68 reason="pod group is not ready, 1 Pending, 1 minAvailable; Pending: 1 Unschedulable" (27/55 resolved)
2026/05/06 16:11:10 Failure: pod=cspod-34 reason="pod group is not ready, 4 Pending, 4 minAvailable; Pending: 4 Unschedulable" (28/55 resolved)
2026/05/06 16:11:10 Failure: pod=cspod-46 reason="pod group is not ready, 1 Pending, 1 minAvailable; Pending: 1 Unschedulable" (29/55 resolved)
2026/05/06 16:11:10 Failure: pod=cspod-54 reason="pod group is not ready, 3 Pending, 3 minAvailable; Pending: 3 Unschedulable" (30/55 resolved)
2026/05/06 16:11:10 Failure: pod=cspod-66 reason="pod group is not ready, 1 Pending, 1 minAvailable; Pending: 1 Unschedulable" (31/55 resolved)
2026/05/06 16:11:10 Failure: pod=cspod-5 reason="pod group is not ready, 1 Pending, 1 minAvailable; Pending: 1 Unschedulable" (32/55 resolved)
2026/05/06 16:11:10 Failure: pod=cspod-23 reason="pod group is not ready, 1 Pending, 1 minAvailable; Pending: 1 Unschedulable" (33/55 resolved)
2026/05/06 16:11:10 Failure: pod=cspod-47 reason="pod group is not ready, 1 Pending, 1 minAvailable; Pending: 1 Unschedulable" (34/55 resolved)
2026/05/06 16:11:10 Failure: pod=cspod-35 reason="pod group is not ready, 4 Pending, 4 minAvailable; Pending: 4 Unschedulable" (35/55 resolved)
2026/05/06 16:11:10 Failure: pod=cspod-63 reason="pod group is not ready, 1 Pending, 1 minAvailable; Pending: 1 Unschedulable" (36/55 resolved)
2026/05/06 16:11:10 Failure: pod=cspod-38 reason="pod group is not ready, 1 Pending, 1 minAvailable; Pending: 1 Unschedulable" (37/55 resolved)
2026/05/06 16:11:10 Failure: pod=cspod-62 reason="pod group is not ready, 1 Pending, 1 minAvailable; Pending: 1 Unschedulable" (38/55 resolved)
2026/05/06 16:11:10 Failure: pod=cspod-60 reason="pod group is not ready, 1 Pending, 1 minAvailable; Pending: 1 Unschedulable" (39/55 resolved)
2026/05/06 16:11:10 Failure: pod=cspod-30 reason="pod group is not ready, 3 Pending, 3 minAvailable; Pending: 3 Unschedulable" (40/55 resolved)
2026/05/06 16:11:10 Failure: pod=cspod-4 reason="pod group is not ready, 1 Pending, 1 minAvailable; Pending: 1 Unschedulable" (41/55 resolved)
2026/05/06 16:11:10 Failure: pod=cspod-65 reason="pod group is not ready, 1 Pending, 1 minAvailable; Pending: 1 Unschedulable" (42/55 resolved)
2026/05/06 16:11:10 Failure: pod=cspod-24 reason="pod group is not ready, 1 Pending, 1 minAvailable; Pending: 1 Unschedulable" (43/55 resolved)
2026/05/06 16:11:10 Failure: pod=cspod-40 reason="pod group is not ready, 1 Pending, 1 minAvailable; Pending: 1 Unschedulable" (44/55 resolved)
2026/05/06 16:11:10 Failure: pod=cspod-67 reason="pod group is not ready, 1 Pending, 1 minAvailable; Pending: 1 Unschedulable" (45/55 resolved)
2026/05/06 16:11:10 Failure: pod=cspod-69 reason="pod group is not ready, 1 Pending, 1 minAvailable; Pending: 1 Unschedulable" (46/55 resolved)
2026/05/06 16:11:10 Failure: pod=cspod-49 reason="pod group is not ready, 1 Pending, 1 minAvailable; Pending: 1 Unschedulable" (47/55 resolved)
2026/05/06 16:11:10 Failure: pod=cspod-36 reason="pod group is not ready, 4 Pending, 4 minAvailable; Pending: 4 Unschedulable" (48/55 resolved)
2026/05/06 16:11:10 Failure: pod=cspod-55 reason="pod group is not ready, 1 Pending, 1 minAvailable; Pending: 1 Unschedulable" (49/55 resolved)
2026/05/06 16:11:10 Failure: pod=cspod-31 reason="pod group is not ready, 3 Pending, 3 minAvailable; Pending: 3 Unschedulable" (50/55 resolved)
2026/05/06 16:11:10 Failure: pod=cspod-42 reason="pod group is not ready, 1 Pending, 1 minAvailable; Pending: 1 Unschedulable" (51/55 resolved)
2026/05/06 16:11:10 Failure: pod=cspod-32 reason="pod group is not ready, 3 Pending, 3 minAvailable; Pending: 3 Unschedulable" (52/55 resolved)
2026/05/06 16:11:10 Failure: pod=cspod-33 reason="pod group is not ready, 4 Pending, 4 minAvailable; Pending: 4 Unschedulable" (53/55 resolved)
2026/05/06 16:11:10 Binding: pod=cspod-3 -> node=csnode-3 (54/55 resolved)
2026/05/06 16:11:10 Binding: pod=cspod-2 -> node=csnode-2 (55/55 resolved)
2026/05/06 16:11:10 Round complete: 2 scheduled, 53 failed in 980.511265ms
2026/05/06 16:11:10 {"action":"HandleSchedule","durationMs":1000,"podCount":55,"result":"ok","roundId":"5","scheduled":2,"ts":"2026-05-06T16:11:10.847435745+01:00","unschedulable":53}
2026/05/06 16:11:10 {"action":"HandleSchedule","completedIds":1,"nodeCount":5,"phase":"start","podCount":53,"roundId":"6","ts":"2026-05-06T16:11:10.857524876+01:00"}
2026/05/06 16:11:10 {"action":"HandleSchedule","phase":"prep_done","podsCreated":53,"prepMs":0,"roundId":"6","staleDeleted":0,"ts":"2026-05-06T16:11:10.858218416+01:00"}
2026/05/06 16:11:10 Scheduling round started: expecting 53 decisions
2026/05/06 16:11:11 Failure: pod=cspod-64 reason="pod group is not ready, 1 Pending, 1 minAvailable; Pending: 1 Unschedulable" (1/53 resolved)
2026/05/06 16:11:11 Failure: pod=cspod-8 reason="pod group is not ready, 1 Pending, 1 minAvailable; Pending: 1 Unschedulable" (2/53 resolved)
2026/05/06 16:11:11 Failure: pod=cspod-26 reason="pod group is not ready, 1 Pending, 1 minAvailable; Pending: 1 Unschedulable" (3/53 resolved)
2026/05/06 16:11:11 Binding: pod=cspod-23 -> node=csnode-4 (4/53 resolved)
2026/05/06 16:11:11 Failure: pod=cspod-4 reason="pod group is not ready, 1 Pending, 1 minAvailable; Pending: 1 Unschedulable" (5/53 resolved)
2026/05/06 16:11:11 Failure: pod=cspod-39 reason="pod group is not ready, 1 Pending, 1 minAvailable; Pending: 1 Unschedulable" (6/53 resolved)
2026/05/06 16:11:11 Failure: pod=cspod-46 reason="pod group is not ready, 1 Pending, 1 minAvailable; Pending: 1 Unschedulable" (7/53 resolved)
2026/05/06 16:11:11 Failure: pod=cspod-49 reason="pod group is not ready, 1 Pending, 1 minAvailable; Pending: 1 Unschedulable" (8/53 resolved)
2026/05/06 16:11:11 Failure: pod=cspod-28 reason="pod group is not ready, 1 Pending, 1 minAvailable; Pending: 1 Unschedulable" (9/53 resolved)
2026/05/06 16:11:11 Failure: pod=cspod-62 reason="pod group is not ready, 1 Pending, 1 minAvailable; Pending: 1 Unschedulable" (10/53 resolved)
2026/05/06 16:11:11 Failure: pod=cspod-48 reason="pod group is not ready, 1 Pending, 1 minAvailable; Pending: 1 Unschedulable" (11/53 resolved)
2026/05/06 16:11:11 Failure: pod=cspod-51 reason="pod group is not ready, 1 Pending, 1 minAvailable; Pending: 1 Unschedulable" (12/53 resolved)
2026/05/06 16:11:11 Failure: pod=cspod-41 reason="pod group is not ready, 1 Pending, 1 minAvailable; Pending: 1 Unschedulable" (13/53 resolved)
2026/05/06 16:11:11 Failure: pod=cspod-6 reason="pod group is not ready, 1 Pending, 1 minAvailable; Pending: 1 Unschedulable" (14/53 resolved)
2026/05/06 16:11:11 Failure: pod=cspod-57 reason="pod group is not ready, 1 Pending, 1 minAvailable; Pending: 1 Unschedulable" (15/53 resolved)
2026/05/06 16:11:11 Failure: pod=cspod-54 reason="pod group is not ready, 3 Pending, 3 minAvailable; Pending: 3 Unschedulable" (16/53 resolved)
2026/05/06 16:11:11 Failure: pod=cspod-63 reason="pod group is not ready, 1 Pending, 1 minAvailable; Pending: 1 Unschedulable" (17/53 resolved)
2026/05/06 16:11:11 Failure: pod=cspod-38 reason="pod group is not ready, 1 Pending, 1 minAvailable; Pending: 1 Unschedulable" (18/53 resolved)
2026/05/06 16:11:11 Failure: pod=cspod-5 reason="pod group is not ready, 1 Pending, 1 minAvailable; Pending: 1 Unschedulable" (19/53 resolved)
2026/05/06 16:11:11 Failure: pod=cspod-47 reason="pod group is not ready, 1 Pending, 1 minAvailable; Pending: 1 Unschedulable" (20/53 resolved)
2026/05/06 16:11:11 Failure: pod=cspod-68 reason="pod group is not ready, 1 Pending, 1 minAvailable; Pending: 1 Unschedulable" (21/53 resolved)
2026/05/06 16:11:11 Failure: pod=cspod-50 reason="pod group is not ready, 1 Pending, 1 minAvailable; Pending: 1 Unschedulable" (22/53 resolved)
2026/05/06 16:11:11 Failure: pod=cspod-29 reason="pod group is not ready, 1 Pending, 1 minAvailable; Pending: 1 Unschedulable" (23/53 resolved)
2026/05/06 16:11:11 Failure: pod=cspod-52 reason="pod group is not ready, 3 Pending, 3 minAvailable; Pending: 3 Unschedulable" (24/53 resolved)
2026/05/06 16:11:11 Failure: pod=cspod-58 reason="pod group is not ready, 1 Pending, 1 minAvailable; Pending: 1 Unschedulable" (25/53 resolved)
2026/05/06 16:11:11 Failure: pod=cspod-65 reason="pod group is not ready, 1 Pending, 1 minAvailable; Pending: 1 Unschedulable" (26/53 resolved)
2026/05/06 16:11:11 Failure: pod=cspod-61 reason="pod group is not ready, 1 Pending, 1 minAvailable; Pending: 1 Unschedulable" (27/53 resolved)
2026/05/06 16:11:11 Failure: pod=cspod-60 reason="pod group is not ready, 1 Pending, 1 minAvailable; Pending: 1 Unschedulable" (28/53 resolved)
2026/05/06 16:11:11 Failure: pod=cspod-59 reason="pod group is not ready, 1 Pending, 1 minAvailable; Pending: 1 Unschedulable" (29/53 resolved)
2026/05/06 16:11:11 Failure: pod=cspod-53 reason="pod group is not ready, 3 Pending, 3 minAvailable; Pending: 3 Unschedulable" (30/53 resolved)
2026/05/06 16:11:11 Failure: pod=cspod-9 reason="pod group is not ready, 1 Pending, 1 minAvailable; Pending: 1 Unschedulable" (31/53 resolved)
2026/05/06 16:11:11 Failure: pod=cspod-55 reason="pod group is not ready, 1 Pending, 1 minAvailable; Pending: 1 Unschedulable" (32/53 resolved)
2026/05/06 16:11:11 Failure: pod=cspod-35 reason="pod group is not ready, 4 Pending, 4 minAvailable; Pending: 4 Unschedulable" (33/53 resolved)
2026/05/06 16:11:11 Failure: pod=cspod-25 reason="pod group is not ready, 1 Pending, 1 minAvailable; Pending: 1 Unschedulable" (34/53 resolved)
2026/05/06 16:11:11 Failure: pod=cspod-69 reason="pod group is not ready, 1 Pending, 1 minAvailable; Pending: 1 Unschedulable" (35/53 resolved)
2026/05/06 16:11:11 Failure: pod=cspod-66 reason="pod group is not ready, 1 Pending, 1 minAvailable; Pending: 1 Unschedulable" (36/53 resolved)
2026/05/06 16:11:11 Failure: pod=cspod-40 reason="pod group is not ready, 1 Pending, 1 minAvailable; Pending: 1 Unschedulable" (37/53 resolved)
2026/05/06 16:11:11 Failure: pod=cspod-56 reason="pod group is not ready, 1 Pending, 1 minAvailable; Pending: 1 Unschedulable" (38/53 resolved)
2026/05/06 16:11:11 Failure: pod=cspod-30 reason="pod group is not ready, 3 Pending, 3 minAvailable; Pending: 3 Unschedulable" (39/53 resolved)
2026/05/06 16:11:11 Failure: pod=cspod-45 reason="pod group is not ready, 1 Pending, 1 minAvailable; Pending: 1 Unschedulable" (40/53 resolved)
2026/05/06 16:11:11 Failure: pod=cspod-27 reason="pod group is not ready, 1 Pending, 1 minAvailable; Pending: 1 Unschedulable" (41/53 resolved)
2026/05/06 16:11:11 Failure: pod=cspod-43 reason="pod group is not ready, 1 Pending, 1 minAvailable; Pending: 1 Unschedulable" (42/53 resolved)
2026/05/06 16:11:11 Failure: pod=cspod-42 reason="pod group is not ready, 1 Pending, 1 minAvailable; Pending: 1 Unschedulable" (43/53 resolved)
2026/05/06 16:11:11 Failure: pod=cspod-67 reason="pod group is not ready, 1 Pending, 1 minAvailable; Pending: 1 Unschedulable" (44/53 resolved)
2026/05/06 16:11:11 Failure: pod=cspod-31 reason="pod group is not ready, 3 Pending, 3 minAvailable; Pending: 3 Unschedulable" (45/53 resolved)
2026/05/06 16:11:11 Failure: pod=cspod-44 reason="pod group is not ready, 1 Pending, 1 minAvailable; Pending: 1 Unschedulable" (46/53 resolved)
2026/05/06 16:11:11 Failure: pod=cspod-24 reason="pod group is not ready, 1 Pending, 1 minAvailable; Pending: 1 Unschedulable" (47/53 resolved)
2026/05/06 16:11:11 Failure: pod=cspod-7 reason="pod group is not ready, 1 Pending, 1 minAvailable; Pending: 1 Unschedulable" (48/53 resolved)
2026/05/06 16:11:11 Failure: pod=cspod-37 reason="pod group is not ready, 1 Pending, 1 minAvailable; Pending: 1 Unschedulable" (49/53 resolved)
2026/05/06 16:11:11 Failure: pod=cspod-32 reason="pod group is not ready, 3 Pending, 3 minAvailable; Pending: 3 Unschedulable" (50/53 resolved)
2026/05/06 16:11:11 Failure: pod=cspod-36 reason="pod group is not ready, 4 Pending, 4 minAvailable; Pending: 4 Unschedulable" (51/53 resolved)
2026/05/06 16:11:11 Failure: pod=cspod-33 reason="pod group is not ready, 4 Pending, 4 minAvailable; Pending: 4 Unschedulable" (52/53 resolved)
2026/05/06 16:11:11 Failure: pod=cspod-34 reason="pod group is not ready, 4 Pending, 4 minAvailable; Pending: 4 Unschedulable" (53/53 resolved)
2026/05/06 16:11:11 Round complete: 1 scheduled, 52 failed in 1.001086166s
2026/05/06 16:11:11 {"action":"HandleSchedule","durationMs":1002,"podCount":53,"result":"ok","roundId":"6","scheduled":1,"ts":"2026-05-06T16:11:11.859424278+01:00","unschedulable":52}
2026/05/06 16:11:11 {"action":"HandleSchedule","completedIds":4,"nodeCount":5,"phase":"start","podCount":52,"roundId":"7","ts":"2026-05-06T16:11:11.870631026+01:00"}
2026/05/06 16:11:11 {"action":"HandleSchedule","phase":"prep_done","podsCreated":52,"prepMs":1,"roundId":"7","staleDeleted":0,"ts":"2026-05-06T16:11:11.872203408+01:00"}
2026/05/06 16:11:11 Scheduling round started: expecting 52 decisions
2026/05/06 16:11:12 Failure: pod=cspod-51 reason="pod group is not ready, 1 Pending, 1 minAvailable; Pending: 1 Unschedulable" (1/52 resolved)
2026/05/06 16:11:12 Failure: pod=cspod-47 reason="pod group is not ready, 1 Pending, 1 minAvailable; Pending: 1 Unschedulable" (2/52 resolved)
2026/05/06 16:11:12 Failure: pod=cspod-9 reason="pod group is not ready, 1 Pending, 1 minAvailable; Pending: 1 Unschedulable" (3/52 resolved)
2026/05/06 16:11:12 Failure: pod=cspod-63 reason="pod group is not ready, 1 Pending, 1 minAvailable; Pending: 1 Unschedulable" (4/52 resolved)
2026/05/06 16:11:12 Failure: pod=cspod-64 reason="pod group is not ready, 1 Pending, 1 minAvailable; Pending: 1 Unschedulable" (5/52 resolved)
2026/05/06 16:11:12 Failure: pod=cspod-26 reason="pod group is not ready, 1 Pending, 1 minAvailable; Pending: 1 Unschedulable" (6/52 resolved)
2026/05/06 16:11:12 Failure: pod=cspod-43 reason="pod group is not ready, 1 Pending, 1 minAvailable; Pending: 1 Unschedulable" (7/52 resolved)
2026/05/06 16:11:12 Failure: pod=cspod-48 reason="pod group is not ready, 1 Pending, 1 minAvailable; Pending: 1 Unschedulable" (8/52 resolved)
2026/05/06 16:11:12 Failure: pod=cspod-50 reason="pod group is not ready, 1 Pending, 1 minAvailable; Pending: 1 Unschedulable" (9/52 resolved)
2026/05/06 16:11:12 Failure: pod=cspod-45 reason="pod group is not ready, 1 Pending, 1 minAvailable; Pending: 1 Unschedulable" (10/52 resolved)
2026/05/06 16:11:12 Failure: pod=cspod-69 reason="pod group is not ready, 1 Pending, 1 minAvailable; Pending: 1 Unschedulable" (11/52 resolved)
2026/05/06 16:11:12 Failure: pod=cspod-8 reason="pod group is not ready, 1 Pending, 1 minAvailable; Pending: 1 Unschedulable" (12/52 resolved)
2026/05/06 16:11:12 Failure: pod=cspod-60 reason="pod group is not ready, 1 Pending, 1 minAvailable; Pending: 1 Unschedulable" (13/52 resolved)
2026/05/06 16:11:12 Failure: pod=cspod-7 reason="pod group is not ready, 1 Pending, 1 minAvailable; Pending: 1 Unschedulable" (14/52 resolved)
2026/05/06 16:11:12 Failure: pod=cspod-6 reason="pod group is not ready, 1 Pending, 1 minAvailable; Pending: 1 Unschedulable" (15/52 resolved)
2026/05/06 16:11:12 Failure: pod=cspod-65 reason="pod group is not ready, 1 Pending, 1 minAvailable; Pending: 1 Unschedulable" (16/52 resolved)
2026/05/06 16:11:12 Failure: pod=cspod-67 reason="pod group is not ready, 1 Pending, 1 minAvailable; Pending: 1 Unschedulable" (17/52 resolved)
2026/05/06 16:11:12 Failure: pod=cspod-52 reason="pod group is not ready, 3 Pending, 3 minAvailable; Pending: 3 Unschedulable" (18/52 resolved)
2026/05/06 16:11:12 Failure: pod=cspod-49 reason="pod group is not ready, 1 Pending, 1 minAvailable; Pending: 1 Unschedulable" (19/52 resolved)
2026/05/06 16:11:12 Failure: pod=cspod-33 reason="pod group is not ready, 4 Pending, 4 minAvailable; Pending: 4 Unschedulable" (20/52 resolved)
2026/05/06 16:11:12 Failure: pod=cspod-24 reason="pod group is not ready, 1 Pending, 1 minAvailable; Pending: 1 Unschedulable" (21/52 resolved)
2026/05/06 16:11:12 Failure: pod=cspod-40 reason="pod group is not ready, 1 Pending, 1 minAvailable; Pending: 1 Unschedulable" (22/52 resolved)
2026/05/06 16:11:12 Failure: pod=cspod-25 reason="pod group is not ready, 1 Pending, 1 minAvailable; Pending: 1 Unschedulable" (23/52 resolved)
2026/05/06 16:11:12 Failure: pod=cspod-29 reason="pod group is not ready, 1 Pending, 1 minAvailable; Pending: 1 Unschedulable" (24/52 resolved)
2026/05/06 16:11:12 Failure: pod=cspod-62 reason="pod group is not ready, 1 Pending, 1 minAvailable; Pending: 1 Unschedulable" (25/52 resolved)
2026/05/06 16:11:12 Failure: pod=cspod-58 reason="pod group is not ready, 1 Pending, 1 minAvailable; Pending: 1 Unschedulable" (26/52 resolved)
2026/05/06 16:11:12 Failure: pod=cspod-56 reason="pod group is not ready, 1 Pending, 1 minAvailable; Pending: 1 Unschedulable" (27/52 resolved)
2026/05/06 16:11:12 Failure: pod=cspod-55 reason="pod group is not ready, 1 Pending, 1 minAvailable; Pending: 1 Unschedulable" (28/52 resolved)
2026/05/06 16:11:12 Failure: pod=cspod-34 reason="pod group is not ready, 4 Pending, 4 minAvailable; Pending: 4 Unschedulable" (29/52 resolved)
2026/05/06 16:11:12 Failure: pod=cspod-30 reason="pod group is not ready, 3 Pending, 3 minAvailable; Pending: 3 Unschedulable" (30/52 resolved)
2026/05/06 16:11:12 Failure: pod=cspod-5 reason="pod group is not ready, 1 Pending, 1 minAvailable; Pending: 1 Unschedulable" (31/52 resolved)
2026/05/06 16:11:12 Failure: pod=cspod-53 reason="pod group is not ready, 3 Pending, 3 minAvailable; Pending: 3 Unschedulable" (32/52 resolved)
2026/05/06 16:11:12 Failure: pod=cspod-57 reason="pod group is not ready, 1 Pending, 1 minAvailable; Pending: 1 Unschedulable" (33/52 resolved)
2026/05/06 16:11:12 Failure: pod=cspod-66 reason="pod group is not ready, 1 Pending, 1 minAvailable; Pending: 1 Unschedulable" (34/52 resolved)
2026/05/06 16:11:12 Failure: pod=cspod-44 reason="pod group is not ready, 1 Pending, 1 minAvailable; Pending: 1 Unschedulable" (35/52 resolved)
2026/05/06 16:11:12 Failure: pod=cspod-42 reason="pod group is not ready, 1 Pending, 1 minAvailable; Pending: 1 Unschedulable" (36/52 resolved)
2026/05/06 16:11:12 Failure: pod=cspod-54 reason="pod group is not ready, 3 Pending, 3 minAvailable; Pending: 3 Unschedulable" (37/52 resolved)
2026/05/06 16:11:12 Failure: pod=cspod-35 reason="pod group is not ready, 4 Pending, 4 minAvailable; Pending: 4 Unschedulable" (38/52 resolved)
2026/05/06 16:11:12 Failure: pod=cspod-41 reason="pod group is not ready, 1 Pending, 1 minAvailable; Pending: 1 Unschedulable" (39/52 resolved)
2026/05/06 16:11:12 Failure: pod=cspod-46 reason="pod group is not ready, 1 Pending, 1 minAvailable; Pending: 1 Unschedulable" (40/52 resolved)
2026/05/06 16:11:12 Failure: pod=cspod-36 reason="pod group is not ready, 4 Pending, 4 minAvailable; Pending: 4 Unschedulable" (41/52 resolved)
2026/05/06 16:11:12 Failure: pod=cspod-27 reason="pod group is not ready, 1 Pending, 1 minAvailable; Pending: 1 Unschedulable" (42/52 resolved)
2026/05/06 16:11:12 Binding: pod=cspod-4 -> node=csnode-0 (43/52 resolved)
2026/05/06 16:11:12 Binding: pod=cspod-37 -> node=csnode-1 (44/52 resolved)
2026/05/06 16:11:12 Binding: pod=cspod-38 -> node=csnode-1 (45/52 resolved)
2026/05/06 16:11:12 Binding: pod=cspod-39 -> node=csnode-0 (46/52 resolved)
2026/05/06 16:11:12 Failure: pod=cspod-68 reason="pod group is not ready, 1 Pending, 1 minAvailable; Pending: 1 Unschedulable" (47/52 resolved)
2026/05/06 16:11:12 Failure: pod=cspod-31 reason="pod group is not ready, 3 Pending, 3 minAvailable; Pending: 3 Unschedulable" (48/52 resolved)
2026/05/06 16:11:12 Failure: pod=cspod-28 reason="pod group is not ready, 1 Pending, 1 minAvailable; Pending: 1 Unschedulable" (49/52 resolved)
2026/05/06 16:11:12 Failure: pod=cspod-59 reason="pod group is not ready, 1 Pending, 1 minAvailable; Pending: 1 Unschedulable" (50/52 resolved)
2026/05/06 16:11:12 Failure: pod=cspod-32 reason="pod group is not ready, 3 Pending, 3 minAvailable; Pending: 3 Unschedulable" (51/52 resolved)
2026/05/06 16:11:12 Failure: pod=cspod-61 reason="pod group is not ready, 1 Pending, 1 minAvailable; Pending: 1 Unschedulable" (52/52 resolved)
2026/05/06 16:11:12 Round complete: 4 scheduled, 48 failed in 1.024488327s
2026/05/06 16:11:12 {"action":"HandleSchedule","durationMs":1026,"podCount":52,"result":"ok","roundId":"7","scheduled":4,"ts":"2026-05-06T16:11:12.896804387+01:00","unschedulable":48}
2026/05/06 16:11:12 {"action":"HandleSchedule","completedIds":3,"nodeCount":5,"phase":"start","podCount":48,"roundId":"8","ts":"2026-05-06T16:11:12.904071436+01:00"}
2026/05/06 16:11:12 {"action":"HandleSchedule","phase":"prep_done","podsCreated":48,"prepMs":0,"roundId":"8","staleDeleted":0,"ts":"2026-05-06T16:11:12.904658652+01:00"}
2026/05/06 16:11:12 Scheduling round started: expecting 48 decisions
2026/05/06 16:11:13 Failure: pod=cspod-67 reason="pod group is not ready, 1 Pending, 1 minAvailable; Pending: 1 Unschedulable" (1/48 resolved)
2026/05/06 16:11:13 Failure: pod=cspod-64 reason="pod group is not ready, 1 Pending, 1 minAvailable; Pending: 1 Unschedulable" (2/48 resolved)
2026/05/06 16:11:13 Failure: pod=cspod-59 reason="pod group is not ready, 1 Pending, 1 minAvailable; Pending: 1 Unschedulable" (3/48 resolved)
2026/05/06 16:11:13 Failure: pod=cspod-62 reason="pod group is not ready, 1 Pending, 1 minAvailable; Pending: 1 Unschedulable" (4/48 resolved)
2026/05/06 16:11:13 Failure: pod=cspod-46 reason="pod group is not ready, 1 Pending, 1 minAvailable; Pending: 1 Unschedulable" (5/48 resolved)
2026/05/06 16:11:13 Failure: pod=cspod-56 reason="pod group is not ready, 1 Pending, 1 minAvailable; Pending: 1 Unschedulable" (6/48 resolved)
2026/05/06 16:11:13 Failure: pod=cspod-8 reason="pod group is not ready, 1 Pending, 1 minAvailable; Pending: 1 Unschedulable" (7/48 resolved)
2026/05/06 16:11:13 Failure: pod=cspod-58 reason="pod group is not ready, 1 Pending, 1 minAvailable; Pending: 1 Unschedulable" (8/48 resolved)
2026/05/06 16:11:13 Failure: pod=cspod-55 reason="pod group is not ready, 1 Pending, 1 minAvailable; Pending: 1 Unschedulable" (9/48 resolved)
2026/05/06 16:11:13 Failure: pod=cspod-25 reason="pod group is not ready, 1 Pending, 1 minAvailable; Pending: 1 Unschedulable" (10/48 resolved)
2026/05/06 16:11:13 Failure: pod=cspod-24 reason="pod group is not ready, 1 Pending, 1 minAvailable; Pending: 1 Unschedulable" (11/48 resolved)
2026/05/06 16:11:13 Failure: pod=cspod-28 reason="pod group is not ready, 1 Pending, 1 minAvailable; Pending: 1 Unschedulable" (12/48 resolved)
2026/05/06 16:11:13 Failure: pod=cspod-68 reason="pod group is not ready, 1 Pending, 1 minAvailable; Pending: 1 Unschedulable" (13/48 resolved)
2026/05/06 16:11:13 Failure: pod=cspod-69 reason="pod group is not ready, 1 Pending, 1 minAvailable; Pending: 1 Unschedulable" (14/48 resolved)
2026/05/06 16:11:13 Failure: pod=cspod-65 reason="pod group is not ready, 1 Pending, 1 minAvailable; Pending: 1 Unschedulable" (15/48 resolved)
2026/05/06 16:11:13 Failure: pod=cspod-52 reason="pod group is not ready, 3 Pending, 3 minAvailable; Pending: 3 Unschedulable" (16/48 resolved)
2026/05/06 16:11:13 Failure: pod=cspod-34 reason="pod group is not ready, 4 Pending, 4 minAvailable; Pending: 4 Unschedulable" (17/48 resolved)
2026/05/06 16:11:13 Failure: pod=cspod-29 reason="pod group is not ready, 1 Pending, 1 minAvailable; Pending: 1 Unschedulable" (18/48 resolved)
2026/05/06 16:11:13 Failure: pod=cspod-9 reason="pod group is not ready, 1 Pending, 1 minAvailable; Pending: 1 Unschedulable" (19/48 resolved)
2026/05/06 16:11:13 Failure: pod=cspod-63 reason="pod group is not ready, 1 Pending, 1 minAvailable; Pending: 1 Unschedulable" (20/48 resolved)
2026/05/06 16:11:13 Failure: pod=cspod-44 reason="pod group is not ready, 1 Pending, 1 minAvailable; Pending: 1 Unschedulable" (21/48 resolved)
2026/05/06 16:11:13 Failure: pod=cspod-51 reason="pod group is not ready, 1 Pending, 1 minAvailable; Pending: 1 Unschedulable" (22/48 resolved)
2026/05/06 16:11:13 Failure: pod=cspod-6 reason="pod group is not ready, 1 Pending, 1 minAvailable; Pending: 1 Unschedulable" (23/48 resolved)
2026/05/06 16:11:13 Failure: pod=cspod-43 reason="pod group is not ready, 1 Pending, 1 minAvailable; Pending: 1 Unschedulable" (24/48 resolved)
2026/05/06 16:11:13 Failure: pod=cspod-50 reason="pod group is not ready, 1 Pending, 1 minAvailable; Pending: 1 Unschedulable" (25/48 resolved)
2026/05/06 16:11:13 Failure: pod=cspod-60 reason="pod group is not ready, 1 Pending, 1 minAvailable; Pending: 1 Unschedulable" (26/48 resolved)
2026/05/06 16:11:13 Failure: pod=cspod-57 reason="pod group is not ready, 1 Pending, 1 minAvailable; Pending: 1 Unschedulable" (27/48 resolved)
2026/05/06 16:11:13 Failure: pod=cspod-35 reason="pod group is not ready, 4 Pending, 4 minAvailable; Pending: 4 Unschedulable" (28/48 resolved)
2026/05/06 16:11:13 Failure: pod=cspod-49 reason="pod group is not ready, 1 Pending, 1 minAvailable; Pending: 1 Unschedulable" (29/48 resolved)
2026/05/06 16:11:13 Failure: pod=cspod-5 reason="pod group is not ready, 1 Pending, 1 minAvailable; Pending: 1 Unschedulable" (30/48 resolved)
2026/05/06 16:11:13 Failure: pod=cspod-66 reason="pod group is not ready, 1 Pending, 1 minAvailable; Pending: 1 Unschedulable" (31/48 resolved)
2026/05/06 16:11:13 Failure: pod=cspod-7 reason="pod group is not ready, 1 Pending, 1 minAvailable; Pending: 1 Unschedulable" (32/48 resolved)
2026/05/06 16:11:13 Failure: pod=cspod-36 reason="pod group is not ready, 4 Pending, 4 minAvailable; Pending: 4 Unschedulable" (33/48 resolved)
2026/05/06 16:11:13 Failure: pod=cspod-61 reason="pod group is not ready, 1 Pending, 1 minAvailable; Pending: 1 Unschedulable" (34/48 resolved)
2026/05/06 16:11:13 Binding: pod=cspod-40 -> node=csnode-4 (35/48 resolved)
2026/05/06 16:11:13 Failure: pod=cspod-53 reason="pod group is not ready, 3 Pending, 3 minAvailable; Pending: 3 Unschedulable" (36/48 resolved)
2026/05/06 16:11:13 Failure: pod=cspod-31 reason="pod group is not ready, 3 Pending, 3 minAvailable; Pending: 3 Unschedulable" (37/48 resolved)
2026/05/06 16:11:13 Binding: pod=cspod-42 -> node=csnode-4 (38/48 resolved)
2026/05/06 16:11:13 Failure: pod=cspod-48 reason="pod group is not ready, 1 Pending, 1 minAvailable; Pending: 1 Unschedulable" (39/48 resolved)
2026/05/06 16:11:13 Failure: pod=cspod-47 reason="pod group is not ready, 1 Pending, 1 minAvailable; Pending: 1 Unschedulable" (40/48 resolved)
2026/05/06 16:11:13 Failure: pod=cspod-45 reason="pod group is not ready, 1 Pending, 1 minAvailable; Pending: 1 Unschedulable" (41/48 resolved)
2026/05/06 16:11:13 Binding: pod=cspod-41 -> node=csnode-4 (42/48 resolved)
2026/05/06 16:11:13 Failure: pod=cspod-27 reason="pod group is not ready, 1 Pending, 1 minAvailable; Pending: 1 Unschedulable" (43/48 resolved)
2026/05/06 16:11:13 Failure: pod=cspod-26 reason="pod group is not ready, 1 Pending, 1 minAvailable; Pending: 1 Unschedulable" (44/48 resolved)
2026/05/06 16:11:13 Failure: pod=cspod-33 reason="pod group is not ready, 4 Pending, 4 minAvailable; Pending: 4 Unschedulable" (45/48 resolved)
2026/05/06 16:11:13 Failure: pod=cspod-32 reason="pod group is not ready, 3 Pending, 3 minAvailable; Pending: 3 Unschedulable" (46/48 resolved)
2026/05/06 16:11:13 Failure: pod=cspod-54 reason="pod group is not ready, 3 Pending, 3 minAvailable; Pending: 3 Unschedulable" (47/48 resolved)
2026/05/06 16:11:13 Failure: pod=cspod-30 reason="pod group is not ready, 3 Pending, 3 minAvailable; Pending: 3 Unschedulable" (48/48 resolved)
2026/05/06 16:11:13 Round complete: 3 scheduled, 45 failed in 1.047778665s
2026/05/06 16:11:13 {"action":"HandleSchedule","durationMs":1048,"podCount":48,"result":"ok","roundId":"8","scheduled":3,"ts":"2026-05-06T16:11:13.952504837+01:00","unschedulable":45}
2026/05/06 16:11:13 {"action":"HandleSchedule","completedIds":2,"nodeCount":5,"phase":"start","podCount":45,"roundId":"9","ts":"2026-05-06T16:11:13.968557234+01:00"}
2026/05/06 16:11:13 {"action":"HandleSchedule","phase":"prep_done","podsCreated":45,"prepMs":0,"roundId":"9","staleDeleted":0,"ts":"2026-05-06T16:11:13.969095781+01:00"}
2026/05/06 16:11:13 Scheduling round started: expecting 45 decisions
2026/05/06 16:11:14 Failure: pod=cspod-7 reason="pod group is not ready, 1 Pending, 1 minAvailable; Pending: 1 Unschedulable" (1/45 resolved)
2026/05/06 16:11:14 Failure: pod=cspod-49 reason="pod group is not ready, 1 Pending, 1 minAvailable; Pending: 1 Unschedulable" (2/45 resolved)
2026/05/06 16:11:14 Failure: pod=cspod-43 reason="pod group is not ready, 1 Pending, 1 minAvailable; Pending: 1 Unschedulable" (3/45 resolved)
2026/05/06 16:11:14 Failure: pod=cspod-26 reason="pod group is not ready, 1 Pending, 1 minAvailable; Pending: 1 Unschedulable" (4/45 resolved)
2026/05/06 16:11:14 Failure: pod=cspod-57 reason="pod group is not ready, 1 Pending, 1 minAvailable; Pending: 1 Unschedulable" (5/45 resolved)
2026/05/06 16:11:14 Failure: pod=cspod-32 reason="pod group is not ready, 3 Pending, 3 minAvailable; Pending: 3 Unschedulable" (6/45 resolved)
2026/05/06 16:11:14 Failure: pod=cspod-47 reason="pod group is not ready, 1 Pending, 1 minAvailable; Pending: 1 Unschedulable" (7/45 resolved)
2026/05/06 16:11:14 Failure: pod=cspod-63 reason="pod group is not ready, 1 Pending, 1 minAvailable; Pending: 1 Unschedulable" (8/45 resolved)
2026/05/06 16:11:14 Failure: pod=cspod-64 reason="pod group is not ready, 1 Pending, 1 minAvailable; Pending: 1 Unschedulable" (9/45 resolved)
2026/05/06 16:11:14 Failure: pod=cspod-66 reason="pod group is not ready, 1 Pending, 1 minAvailable; Pending: 1 Unschedulable" (10/45 resolved)
2026/05/06 16:11:14 Failure: pod=cspod-46 reason="pod group is not ready, 1 Pending, 1 minAvailable; Pending: 1 Unschedulable" (11/45 resolved)
2026/05/06 16:11:14 Failure: pod=cspod-30 reason="pod group is not ready, 3 Pending, 3 minAvailable; Pending: 3 Unschedulable" (12/45 resolved)
2026/05/06 16:11:14 Failure: pod=cspod-67 reason="pod group is not ready, 1 Pending, 1 minAvailable; Pending: 1 Unschedulable" (13/45 resolved)
2026/05/06 16:11:14 Failure: pod=cspod-5 reason="pod group is not ready, 1 Pending, 1 minAvailable; Pending: 1 Unschedulable" (14/45 resolved)
2026/05/06 16:11:14 Failure: pod=cspod-28 reason="pod group is not ready, 1 Pending, 1 minAvailable; Pending: 1 Unschedulable" (15/45 resolved)
2026/05/06 16:11:14 Failure: pod=cspod-50 reason="pod group is not ready, 1 Pending, 1 minAvailable; Pending: 1 Unschedulable" (16/45 resolved)
2026/05/06 16:11:14 Failure: pod=cspod-44 reason="pod group is not ready, 1 Pending, 1 minAvailable; Pending: 1 Unschedulable" (17/45 resolved)
2026/05/06 16:11:14 Failure: pod=cspod-27 reason="pod group is not ready, 1 Pending, 1 minAvailable; Pending: 1 Unschedulable" (18/45 resolved)
2026/05/06 16:11:14 Failure: pod=cspod-45 reason="pod group is not ready, 1 Pending, 1 minAvailable; Pending: 1 Unschedulable" (19/45 resolved)
2026/05/06 16:11:14 Binding: pod=cspod-24 -> node=csnode-3 (20/45 resolved)
2026/05/06 16:11:14 Binding: pod=cspod-25 -> node=csnode-2 (21/45 resolved)
2026/05/06 16:11:14 Failure: pod=cspod-60 reason="pod group is not ready, 1 Pending, 1 minAvailable; Pending: 1 Unschedulable" (22/45 resolved)
2026/05/06 16:11:14 Failure: pod=cspod-48 reason="pod group is not ready, 1 Pending, 1 minAvailable; Pending: 1 Unschedulable" (23/45 resolved)
2026/05/06 16:11:14 Failure: pod=cspod-31 reason="pod group is not ready, 3 Pending, 3 minAvailable; Pending: 3 Unschedulable" (24/45 resolved)
2026/05/06 16:11:14 Failure: pod=cspod-69 reason="pod group is not ready, 1 Pending, 1 minAvailable; Pending: 1 Unschedulable" (25/45 resolved)
2026/05/06 16:11:14 Failure: pod=cspod-36 reason="pod group is not ready, 4 Pending, 4 minAvailable; Pending: 4 Unschedulable" (26/45 resolved)
2026/05/06 16:11:14 Failure: pod=cspod-65 reason="pod group is not ready, 1 Pending, 1 minAvailable; Pending: 1 Unschedulable" (27/45 resolved)
2026/05/06 16:11:14 Failure: pod=cspod-59 reason="pod group is not ready, 1 Pending, 1 minAvailable; Pending: 1 Unschedulable" (28/45 resolved)
2026/05/06 16:11:14 Failure: pod=cspod-68 reason="pod group is not ready, 1 Pending, 1 minAvailable; Pending: 1 Unschedulable" (29/45 resolved)
2026/05/06 16:11:14 Failure: pod=cspod-9 reason="pod group is not ready, 1 Pending, 1 minAvailable; Pending: 1 Unschedulable" (30/45 resolved)
2026/05/06 16:11:14 Failure: pod=cspod-58 reason="pod group is not ready, 1 Pending, 1 minAvailable; Pending: 1 Unschedulable" (31/45 resolved)
2026/05/06 16:11:14 Failure: pod=cspod-62 reason="pod group is not ready, 1 Pending, 1 minAvailable; Pending: 1 Unschedulable" (32/45 resolved)
2026/05/06 16:11:14 Failure: pod=cspod-6 reason="pod group is not ready, 1 Pending, 1 minAvailable; Pending: 1 Unschedulable" (33/45 resolved)
2026/05/06 16:11:14 Failure: pod=cspod-8 reason="pod group is not ready, 1 Pending, 1 minAvailable; Pending: 1 Unschedulable" (34/45 resolved)
2026/05/06 16:11:14 Failure: pod=cspod-51 reason="pod group is not ready, 1 Pending, 1 minAvailable; Pending: 1 Unschedulable" (35/45 resolved)
2026/05/06 16:11:14 Failure: pod=cspod-55 reason="pod group is not ready, 1 Pending, 1 minAvailable; Pending: 1 Unschedulable" (36/45 resolved)
2026/05/06 16:11:14 Failure: pod=cspod-29 reason="pod group is not ready, 1 Pending, 1 minAvailable; Pending: 1 Unschedulable" (37/45 resolved)
2026/05/06 16:11:14 Failure: pod=cspod-61 reason="pod group is not ready, 1 Pending, 1 minAvailable; Pending: 1 Unschedulable" (38/45 resolved)
2026/05/06 16:11:14 Failure: pod=cspod-56 reason="pod group is not ready, 1 Pending, 1 minAvailable; Pending: 1 Unschedulable" (39/45 resolved)
2026/05/06 16:11:14 Failure: pod=cspod-53 reason="pod group is not ready, 3 Pending, 3 minAvailable; Pending: 3 Unschedulable" (40/45 resolved)
2026/05/06 16:11:14 Failure: pod=cspod-33 reason="pod group is not ready, 4 Pending, 4 minAvailable; Pending: 4 Unschedulable" (41/45 resolved)
2026/05/06 16:11:14 Failure: pod=cspod-54 reason="pod group is not ready, 3 Pending, 3 minAvailable; Pending: 3 Unschedulable" (42/45 resolved)
2026/05/06 16:11:14 Failure: pod=cspod-34 reason="pod group is not ready, 4 Pending, 4 minAvailable; Pending: 4 Unschedulable" (43/45 resolved)
2026/05/06 16:11:14 Failure: pod=cspod-35 reason="pod group is not ready, 4 Pending, 4 minAvailable; Pending: 4 Unschedulable" (44/45 resolved)
2026/05/06 16:11:14 Failure: pod=cspod-52 reason="pod group is not ready, 3 Pending, 3 minAvailable; Pending: 3 Unschedulable" (45/45 resolved)
2026/05/06 16:11:14 Round complete: 2 scheduled, 43 failed in 1.009002541s
2026/05/06 16:11:14 {"action":"HandleSchedule","durationMs":1009,"podCount":45,"result":"ok","roundId":"9","scheduled":2,"ts":"2026-05-06T16:11:14.978181112+01:00","unschedulable":43}
2026/05/06 16:11:14 {"action":"HandleSchedule","completedIds":3,"nodeCount":5,"phase":"start","podCount":43,"roundId":"10","ts":"2026-05-06T16:11:14.984209545+01:00"}
2026/05/06 16:11:14 {"action":"HandleSchedule","phase":"prep_done","podsCreated":43,"prepMs":0,"roundId":"10","staleDeleted":0,"ts":"2026-05-06T16:11:14.984722593+01:00"}
2026/05/06 16:11:14 Scheduling round started: expecting 43 decisions
2026/05/06 16:11:15 Failure: pod=cspod-62 reason="pod group is not ready, 1 Pending, 1 minAvailable; Pending: 1 Unschedulable" (1/43 resolved)
2026/05/06 16:11:15 Failure: pod=cspod-49 reason="pod group is not ready, 1 Pending, 1 minAvailable; Pending: 1 Unschedulable" (2/43 resolved)
2026/05/06 16:11:15 Failure: pod=cspod-63 reason="pod group is not ready, 1 Pending, 1 minAvailable; Pending: 1 Unschedulable" (3/43 resolved)
2026/05/06 16:11:15 Failure: pod=cspod-9 reason="pod group is not ready, 1 Pending, 1 minAvailable; Pending: 1 Unschedulable" (4/43 resolved)
2026/05/06 16:11:15 Failure: pod=cspod-55 reason="pod group is not ready, 1 Pending, 1 minAvailable; Pending: 1 Unschedulable" (5/43 resolved)
2026/05/06 16:11:15 Failure: pod=cspod-29 reason="pod group is not ready, 1 Pending, 1 minAvailable; Pending: 1 Unschedulable" (6/43 resolved)
2026/05/06 16:11:15 Failure: pod=cspod-48 reason="pod group is not ready, 1 Pending, 1 minAvailable; Pending: 1 Unschedulable" (7/43 resolved)
2026/05/06 16:11:15 Failure: pod=cspod-51 reason="pod group is not ready, 1 Pending, 1 minAvailable; Pending: 1 Unschedulable" (8/43 resolved)
2026/05/06 16:11:15 Failure: pod=cspod-5 reason="pod group is not ready, 1 Pending, 1 minAvailable; Pending: 1 Unschedulable" (9/43 resolved)
2026/05/06 16:11:15 Failure: pod=cspod-33 reason="pod group is not ready, 4 Pending, 4 minAvailable; Pending: 4 Unschedulable" (10/43 resolved)
2026/05/06 16:11:15 Failure: pod=cspod-50 reason="pod group is not ready, 1 Pending, 1 minAvailable; Pending: 1 Unschedulable" (11/43 resolved)
2026/05/06 16:11:15 Failure: pod=cspod-65 reason="pod group is not ready, 1 Pending, 1 minAvailable; Pending: 1 Unschedulable" (12/43 resolved)
2026/05/06 16:11:15 Failure: pod=cspod-46 reason="pod group is not ready, 1 Pending, 1 minAvailable; Pending: 1 Unschedulable" (13/43 resolved)
2026/05/06 16:11:15 Failure: pod=cspod-8 reason="pod group is not ready, 1 Pending, 1 minAvailable; Pending: 1 Unschedulable" (14/43 resolved)
2026/05/06 16:11:15 Failure: pod=cspod-59 reason="pod group is not ready, 1 Pending, 1 minAvailable; Pending: 1 Unschedulable" (15/43 resolved)
2026/05/06 16:11:15 Failure: pod=cspod-34 reason="pod group is not ready, 4 Pending, 4 minAvailable; Pending: 4 Unschedulable" (16/43 resolved)
2026/05/06 16:11:15 Failure: pod=cspod-60 reason="pod group is not ready, 1 Pending, 1 minAvailable; Pending: 1 Unschedulable" (17/43 resolved)
2026/05/06 16:11:15 Failure: pod=cspod-31 reason="pod group is not ready, 3 Pending, 3 minAvailable; Pending: 3 Unschedulable" (18/43 resolved)
2026/05/06 16:11:15 Failure: pod=cspod-47 reason="pod group is not ready, 1 Pending, 1 minAvailable; Pending: 1 Unschedulable" (19/43 resolved)
2026/05/06 16:11:15 Failure: pod=cspod-56 reason="pod group is not ready, 1 Pending, 1 minAvailable; Pending: 1 Unschedulable" (20/43 resolved)
2026/05/06 16:11:15 Failure: pod=cspod-28 reason="pod group is not ready, 1 Pending, 1 minAvailable; Pending: 1 Unschedulable" (21/43 resolved)
2026/05/06 16:11:15 Failure: pod=cspod-67 reason="pod group is not ready, 1 Pending, 1 minAvailable; Pending: 1 Unschedulable" (22/43 resolved)
2026/05/06 16:11:15 Failure: pod=cspod-6 reason="pod group is not ready, 1 Pending, 1 minAvailable; Pending: 1 Unschedulable" (23/43 resolved)
2026/05/06 16:11:15 Failure: pod=cspod-27 reason="pod group is not ready, 1 Pending, 1 minAvailable; Pending: 1 Unschedulable" (24/43 resolved)
2026/05/06 16:11:15 Failure: pod=cspod-32 reason="pod group is not ready, 3 Pending, 3 minAvailable; Pending: 3 Unschedulable" (25/43 resolved)
2026/05/06 16:11:15 Failure: pod=cspod-52 reason="pod group is not ready, 3 Pending, 3 minAvailable; Pending: 3 Unschedulable" (26/43 resolved)
2026/05/06 16:11:15 Failure: pod=cspod-64 reason="pod group is not ready, 1 Pending, 1 minAvailable; Pending: 1 Unschedulable" (27/43 resolved)
2026/05/06 16:11:15 Failure: pod=cspod-35 reason="pod group is not ready, 4 Pending, 4 minAvailable; Pending: 4 Unschedulable" (28/43 resolved)
2026/05/06 16:11:15 Failure: pod=cspod-68 reason="pod group is not ready, 1 Pending, 1 minAvailable; Pending: 1 Unschedulable" (29/43 resolved)
2026/05/06 16:11:15 Failure: pod=cspod-7 reason="pod group is not ready, 1 Pending, 1 minAvailable; Pending: 1 Unschedulable" (30/43 resolved)
2026/05/06 16:11:15 Failure: pod=cspod-69 reason="pod group is not ready, 1 Pending, 1 minAvailable; Pending: 1 Unschedulable" (31/43 resolved)
2026/05/06 16:11:15 Failure: pod=cspod-58 reason="pod group is not ready, 1 Pending, 1 minAvailable; Pending: 1 Unschedulable" (32/43 resolved)
2026/05/06 16:11:15 Failure: pod=cspod-61 reason="pod group is not ready, 1 Pending, 1 minAvailable; Pending: 1 Unschedulable" (33/43 resolved)
2026/05/06 16:11:15 Failure: pod=cspod-30 reason="pod group is not ready, 3 Pending, 3 minAvailable; Pending: 3 Unschedulable" (34/43 resolved)
2026/05/06 16:11:15 Failure: pod=cspod-53 reason="pod group is not ready, 3 Pending, 3 minAvailable; Pending: 3 Unschedulable" (35/43 resolved)
2026/05/06 16:11:15 Failure: pod=cspod-57 reason="pod group is not ready, 1 Pending, 1 minAvailable; Pending: 1 Unschedulable" (36/43 resolved)
2026/05/06 16:11:15 Failure: pod=cspod-66 reason="pod group is not ready, 1 Pending, 1 minAvailable; Pending: 1 Unschedulable" (37/43 resolved)
2026/05/06 16:11:15 Failure: pod=cspod-26 reason="pod group is not ready, 1 Pending, 1 minAvailable; Pending: 1 Unschedulable" (38/43 resolved)
2026/05/06 16:11:15 Failure: pod=cspod-54 reason="pod group is not ready, 3 Pending, 3 minAvailable; Pending: 3 Unschedulable" (39/43 resolved)
2026/05/06 16:11:15 Failure: pod=cspod-36 reason="pod group is not ready, 4 Pending, 4 minAvailable; Pending: 4 Unschedulable" (40/43 resolved)
2026/05/06 16:11:16 Binding: pod=cspod-43 -> node=csnode-4 (41/43 resolved)
2026/05/06 16:11:16 Binding: pod=cspod-44 -> node=csnode-4 (42/43 resolved)
2026/05/06 16:11:16 Binding: pod=cspod-45 -> node=csnode-4 (43/43 resolved)
2026/05/06 16:11:16 Round complete: 3 scheduled, 40 failed in 1.015861938s
2026/05/06 16:11:16 {"action":"HandleSchedule","durationMs":1016,"podCount":43,"result":"ok","roundId":"10","scheduled":3,"ts":"2026-05-06T16:11:16.000650031+01:00","unschedulable":40}
2026/05/06 16:11:16 {"action":"HandleSchedule","completedIds":2,"nodeCount":5,"phase":"start","podCount":40,"roundId":"11","ts":"2026-05-06T16:11:16.012613346+01:00"}
2026/05/06 16:11:16 {"action":"HandleSchedule","phase":"prep_done","podsCreated":40,"prepMs":0,"roundId":"11","staleDeleted":0,"ts":"2026-05-06T16:11:16.013123261+01:00"}
2026/05/06 16:11:16 Scheduling round started: expecting 40 decisions
2026/05/06 16:11:16 Failure: pod=cspod-58 reason="pod group is not ready, 1 Pending, 1 minAvailable; Pending: 1 Unschedulable" (1/40 resolved)
2026/05/06 16:11:16 Failure: pod=cspod-59 reason="pod group is not ready, 1 Pending, 1 minAvailable; Pending: 1 Unschedulable" (2/40 resolved)
2026/05/06 16:11:16 Failure: pod=cspod-63 reason="pod group is not ready, 1 Pending, 1 minAvailable; Pending: 1 Unschedulable" (3/40 resolved)
2026/05/06 16:11:16 Failure: pod=cspod-55 reason="pod group is not ready, 1 Pending, 1 minAvailable; Pending: 1 Unschedulable" (4/40 resolved)
2026/05/06 16:11:16 Failure: pod=cspod-62 reason="pod group is not ready, 1 Pending, 1 minAvailable; Pending: 1 Unschedulable" (5/40 resolved)
2026/05/06 16:11:16 Failure: pod=cspod-60 reason="pod group is not ready, 1 Pending, 1 minAvailable; Pending: 1 Unschedulable" (6/40 resolved)
2026/05/06 16:11:16 Failure: pod=cspod-5 reason="pod group is not ready, 1 Pending, 1 minAvailable; Pending: 1 Unschedulable" (7/40 resolved)
2026/05/06 16:11:16 Failure: pod=cspod-51 reason="pod group is not ready, 1 Pending, 1 minAvailable; Pending: 1 Unschedulable" (8/40 resolved)
2026/05/06 16:11:16 Failure: pod=cspod-26 reason="pod group is not ready, 1 Pending, 1 minAvailable; Pending: 1 Unschedulable" (9/40 resolved)
2026/05/06 16:11:16 Failure: pod=cspod-7 reason="pod group is not ready, 1 Pending, 1 minAvailable; Pending: 1 Unschedulable" (10/40 resolved)
2026/05/06 16:11:16 Failure: pod=cspod-48 reason="pod group is not ready, 1 Pending, 1 minAvailable; Pending: 1 Unschedulable" (11/40 resolved)
2026/05/06 16:11:16 Failure: pod=cspod-53 reason="pod group is not ready, 3 Pending, 3 minAvailable; Pending: 3 Unschedulable" (12/40 resolved)
2026/05/06 16:11:16 Failure: pod=cspod-49 reason="pod group is not ready, 1 Pending, 1 minAvailable; Pending: 1 Unschedulable" (13/40 resolved)
2026/05/06 16:11:16 Failure: pod=cspod-27 reason="pod group is not ready, 1 Pending, 1 minAvailable; Pending: 1 Unschedulable" (14/40 resolved)
2026/05/06 16:11:16 Failure: pod=cspod-50 reason="pod group is not ready, 1 Pending, 1 minAvailable; Pending: 1 Unschedulable" (15/40 resolved)
2026/05/06 16:11:16 Failure: pod=cspod-65 reason="pod group is not ready, 1 Pending, 1 minAvailable; Pending: 1 Unschedulable" (16/40 resolved)
2026/05/06 16:11:16 Failure: pod=cspod-8 reason="pod group is not ready, 1 Pending, 1 minAvailable; Pending: 1 Unschedulable" (17/40 resolved)
2026/05/06 16:11:16 Failure: pod=cspod-54 reason="pod group is not ready, 3 Pending, 3 minAvailable; Pending: 3 Unschedulable" (18/40 resolved)
2026/05/06 16:11:16 Failure: pod=cspod-9 reason="pod group is not ready, 1 Pending, 1 minAvailable; Pending: 1 Unschedulable" (19/40 resolved)
2026/05/06 16:11:16 Failure: pod=cspod-29 reason="pod group is not ready, 1 Pending, 1 minAvailable; Pending: 1 Unschedulable" (20/40 resolved)
2026/05/06 16:11:16 Failure: pod=cspod-66 reason="pod group is not ready, 1 Pending, 1 minAvailable; Pending: 1 Unschedulable" (21/40 resolved)
2026/05/06 16:11:16 Failure: pod=cspod-68 reason="pod group is not ready, 1 Pending, 1 minAvailable; Pending: 1 Unschedulable" (22/40 resolved)
2026/05/06 16:11:16 Failure: pod=cspod-67 reason="pod group is not ready, 1 Pending, 1 minAvailable; Pending: 1 Unschedulable" (23/40 resolved)
2026/05/06 16:11:16 Failure: pod=cspod-56 reason="pod group is not ready, 1 Pending, 1 minAvailable; Pending: 1 Unschedulable" (24/40 resolved)
2026/05/06 16:11:16 Failure: pod=cspod-57 reason="pod group is not ready, 1 Pending, 1 minAvailable; Pending: 1 Unschedulable" (25/40 resolved)
2026/05/06 16:11:16 Failure: pod=cspod-52 reason="pod group is not ready, 3 Pending, 3 minAvailable; Pending: 3 Unschedulable" (26/40 resolved)
2026/05/06 16:11:16 Failure: pod=cspod-31 reason="pod group is not ready, 3 Pending, 3 minAvailable; Pending: 3 Unschedulable" (27/40 resolved)
2026/05/06 16:11:16 Failure: pod=cspod-6 reason="pod group is not ready, 1 Pending, 1 minAvailable; Pending: 1 Unschedulable" (28/40 resolved)
2026/05/06 16:11:16 Failure: pod=cspod-33 reason="pod group is not ready, 4 Pending, 4 minAvailable; Pending: 4 Unschedulable" (29/40 resolved)
2026/05/06 16:11:16 Failure: pod=cspod-64 reason="pod group is not ready, 1 Pending, 1 minAvailable; Pending: 1 Unschedulable" (30/40 resolved)
2026/05/06 16:11:16 Failure: pod=cspod-61 reason="pod group is not ready, 1 Pending, 1 minAvailable; Pending: 1 Unschedulable" (31/40 resolved)
2026/05/06 16:11:16 Failure: pod=cspod-69 reason="pod group is not ready, 1 Pending, 1 minAvailable; Pending: 1 Unschedulable" (32/40 resolved)
2026/05/06 16:11:16 Failure: pod=cspod-32 reason="pod group is not ready, 3 Pending, 3 minAvailable; Pending: 3 Unschedulable" (33/40 resolved)
2026/05/06 16:11:16 Failure: pod=cspod-34 reason="pod group is not ready, 4 Pending, 4 minAvailable; Pending: 4 Unschedulable" (34/40 resolved)
2026/05/06 16:11:16 Failure: pod=cspod-28 reason="pod group is not ready, 1 Pending, 1 minAvailable; Pending: 1 Unschedulable" (35/40 resolved)
2026/05/06 16:11:16 Failure: pod=cspod-30 reason="pod group is not ready, 3 Pending, 3 minAvailable; Pending: 3 Unschedulable" (36/40 resolved)
2026/05/06 16:11:16 Failure: pod=cspod-35 reason="pod group is not ready, 4 Pending, 4 minAvailable; Pending: 4 Unschedulable" (37/40 resolved)
2026/05/06 16:11:16 Failure: pod=cspod-36 reason="pod group is not ready, 4 Pending, 4 minAvailable; Pending: 4 Unschedulable" (38/40 resolved)
2026/05/06 16:11:17 Binding: pod=cspod-46 -> node=csnode-2 (39/40 resolved)
2026/05/06 16:11:17 Binding: pod=cspod-47 -> node=csnode-3 (40/40 resolved)
2026/05/06 16:11:17 Round complete: 2 scheduled, 38 failed in 996.494994ms
2026/05/06 16:11:17 {"action":"HandleSchedule","durationMs":997,"podCount":40,"result":"ok","roundId":"11","scheduled":2,"ts":"2026-05-06T16:11:17.009721837+01:00","unschedulable":38}
2026/05/06 16:11:17 {"action":"HandleSchedule","completedIds":3,"nodeCount":5,"phase":"start","podCount":38,"roundId":"12","ts":"2026-05-06T16:11:17.015687117+01:00"}
2026/05/06 16:11:17 {"action":"HandleSchedule","phase":"prep_done","podsCreated":38,"prepMs":0,"roundId":"12","staleDeleted":0,"ts":"2026-05-06T16:11:17.016105557+01:00"}
2026/05/06 16:11:17 Scheduling round started: expecting 38 decisions
2026/05/06 16:11:18 Failure: pod=cspod-52 reason="pod group is not ready, 3 Pending, 3 minAvailable; Pending: 3 Unschedulable" (1/38 resolved)
2026/05/06 16:11:18 Failure: pod=cspod-29 reason="pod group is not ready, 1 Pending, 1 minAvailable; Pending: 1 Unschedulable" (2/38 resolved)
2026/05/06 16:11:18 Failure: pod=cspod-68 reason="pod group is not ready, 1 Pending, 1 minAvailable; Pending: 1 Unschedulable" (3/38 resolved)
2026/05/06 16:11:18 Failure: pod=cspod-55 reason="pod group is not ready, 1 Pending, 1 minAvailable; Pending: 1 Unschedulable" (4/38 resolved)
2026/05/06 16:11:18 Failure: pod=cspod-66 reason="pod group is not ready, 1 Pending, 1 minAvailable; Pending: 1 Unschedulable" (5/38 resolved)
2026/05/06 16:11:18 Failure: pod=cspod-58 reason="pod group is not ready, 1 Pending, 1 minAvailable; Pending: 1 Unschedulable" (6/38 resolved)
2026/05/06 16:11:18 Failure: pod=cspod-8 reason="pod group is not ready, 1 Pending, 1 minAvailable; Pending: 1 Unschedulable" (7/38 resolved)
2026/05/06 16:11:18 Failure: pod=cspod-6 reason="pod group is not ready, 1 Pending, 1 minAvailable; Pending: 1 Unschedulable" (8/38 resolved)
2026/05/06 16:11:18 Failure: pod=cspod-31 reason="pod group is not ready, 3 Pending, 3 minAvailable; Pending: 3 Unschedulable" (9/38 resolved)
2026/05/06 16:11:18 Failure: pod=cspod-27 reason="pod group is not ready, 1 Pending, 1 minAvailable; Pending: 1 Unschedulable" (10/38 resolved)
2026/05/06 16:11:18 Failure: pod=cspod-67 reason="pod group is not ready, 1 Pending, 1 minAvailable; Pending: 1 Unschedulable" (11/38 resolved)
2026/05/06 16:11:18 Failure: pod=cspod-35 reason="pod group is not ready, 4 Pending, 4 minAvailable; Pending: 4 Unschedulable" (12/38 resolved)
2026/05/06 16:11:18 Failure: pod=cspod-51 reason="pod group is not ready, 1 Pending, 1 minAvailable; Pending: 1 Unschedulable" (13/38 resolved)
2026/05/06 16:11:18 Failure: pod=cspod-26 reason="pod group is not ready, 1 Pending, 1 minAvailable; Pending: 1 Unschedulable" (14/38 resolved)
2026/05/06 16:11:18 Failure: pod=cspod-61 reason="pod group is not ready, 1 Pending, 1 minAvailable; Pending: 1 Unschedulable" (15/38 resolved)
2026/05/06 16:11:18 Failure: pod=cspod-64 reason="pod group is not ready, 1 Pending, 1 minAvailable; Pending: 1 Unschedulable" (16/38 resolved)
2026/05/06 16:11:18 Failure: pod=cspod-7 reason="pod group is not ready, 1 Pending, 1 minAvailable; Pending: 1 Unschedulable" (17/38 resolved)
2026/05/06 16:11:18 Failure: pod=cspod-9 reason="pod group is not ready, 1 Pending, 1 minAvailable; Pending: 1 Unschedulable" (18/38 resolved)
2026/05/06 16:11:18 Failure: pod=cspod-32 reason="pod group is not ready, 3 Pending, 3 minAvailable; Pending: 3 Unschedulable" (19/38 resolved)
2026/05/06 16:11:18 Failure: pod=cspod-28 reason="pod group is not ready, 1 Pending, 1 minAvailable; Pending: 1 Unschedulable" (20/38 resolved)
2026/05/06 16:11:18 Failure: pod=cspod-53 reason="pod group is not ready, 3 Pending, 3 minAvailable; Pending: 3 Unschedulable" (21/38 resolved)
2026/05/06 16:11:18 Failure: pod=cspod-36 reason="pod group is not ready, 4 Pending, 4 minAvailable; Pending: 4 Unschedulable" (22/38 resolved)
2026/05/06 16:11:18 Failure: pod=cspod-30 reason="pod group is not ready, 3 Pending, 3 minAvailable; Pending: 3 Unschedulable" (23/38 resolved)
2026/05/06 16:11:18 Failure: pod=cspod-33 reason="pod group is not ready, 4 Pending, 4 minAvailable; Pending: 4 Unschedulable" (24/38 resolved)
2026/05/06 16:11:18 Failure: pod=cspod-59 reason="pod group is not ready, 1 Pending, 1 minAvailable; Pending: 1 Unschedulable" (25/38 resolved)
2026/05/06 16:11:18 Failure: pod=cspod-69 reason="pod group is not ready, 1 Pending, 1 minAvailable; Pending: 1 Unschedulable" (26/38 resolved)
2026/05/06 16:11:18 Binding: pod=cspod-48 -> node=csnode-0 (27/38 resolved)
2026/05/06 16:11:18 Failure: pod=cspod-63 reason="pod group is not ready, 1 Pending, 1 minAvailable; Pending: 1 Unschedulable" (28/38 resolved)
2026/05/06 16:11:18 Binding: pod=cspod-49 -> node=csnode-1 (29/38 resolved)
2026/05/06 16:11:18 Failure: pod=cspod-54 reason="pod group is not ready, 3 Pending, 3 minAvailable; Pending: 3 Unschedulable" (30/38 resolved)
2026/05/06 16:11:18 Failure: pod=cspod-34 reason="pod group is not ready, 4 Pending, 4 minAvailable; Pending: 4 Unschedulable" (31/38 resolved)
2026/05/06 16:11:18 Binding: pod=cspod-5 -> node=csnode-1 (32/38 resolved)
2026/05/06 16:11:18 Failure: pod=cspod-60 reason="pod group is not ready, 1 Pending, 1 minAvailable; Pending: 1 Unschedulable" (33/38 resolved)
2026/05/06 16:11:18 Failure: pod=cspod-57 reason="pod group is not ready, 1 Pending, 1 minAvailable; Pending: 1 Unschedulable" (34/38 resolved)
2026/05/06 16:11:18 Failure: pod=cspod-50 reason="pod group is not ready, 1 Pending, 1 minAvailable; Pending: 1 Unschedulable" (35/38 resolved)
2026/05/06 16:11:18 Failure: pod=cspod-62 reason="pod group is not ready, 1 Pending, 1 minAvailable; Pending: 1 Unschedulable" (36/38 resolved)
2026/05/06 16:11:18 Failure: pod=cspod-65 reason="pod group is not ready, 1 Pending, 1 minAvailable; Pending: 1 Unschedulable" (37/38 resolved)
2026/05/06 16:11:18 Failure: pod=cspod-56 reason="pod group is not ready, 1 Pending, 1 minAvailable; Pending: 1 Unschedulable" (38/38 resolved)
2026/05/06 16:11:18 Round complete: 3 scheduled, 35 failed in 993.701733ms
2026/05/06 16:11:18 {"action":"HandleSchedule","durationMs":994,"podCount":38,"result":"ok","roundId":"12","scheduled":3,"ts":"2026-05-06T16:11:18.009891493+01:00","unschedulable":35}
2026/05/06 16:11:18 {"action":"HandleSchedule","completedIds":1,"nodeCount":5,"phase":"start","podCount":35,"roundId":"13","ts":"2026-05-06T16:11:18.01511647+01:00"}
2026/05/06 16:11:18 {"action":"HandleSchedule","phase":"prep_done","podsCreated":35,"prepMs":1,"roundId":"13","staleDeleted":0,"ts":"2026-05-06T16:11:18.016572743+01:00"}
2026/05/06 16:11:18 Scheduling round started: expecting 35 decisions
2026/05/06 16:11:19 Failure: pod=cspod-7 reason="pod group is not ready, 1 Pending, 1 minAvailable; Pending: 1 Unschedulable" (1/35 resolved)
2026/05/06 16:11:19 Failure: pod=cspod-64 reason="pod group is not ready, 1 Pending, 1 minAvailable; Pending: 1 Unschedulable" (2/35 resolved)
2026/05/06 16:11:19 Failure: pod=cspod-67 reason="pod group is not ready, 1 Pending, 1 minAvailable; Pending: 1 Unschedulable" (3/35 resolved)
2026/05/06 16:11:19 Failure: pod=cspod-68 reason="pod group is not ready, 1 Pending, 1 minAvailable; Pending: 1 Unschedulable" (4/35 resolved)
2026/05/06 16:11:19 Failure: pod=cspod-52 reason="pod group is not ready, 3 Pending, 3 minAvailable; Pending: 3 Unschedulable" (5/35 resolved)
2026/05/06 16:11:19 Failure: pod=cspod-30 reason="pod group is not ready, 3 Pending, 3 minAvailable; Pending: 3 Unschedulable" (6/35 resolved)
2026/05/06 16:11:19 Failure: pod=cspod-9 reason="pod group is not ready, 1 Pending, 1 minAvailable; Pending: 1 Unschedulable" (7/35 resolved)
2026/05/06 16:11:19 Failure: pod=cspod-51 reason="pod group is not ready, 1 Pending, 1 minAvailable; Pending: 1 Unschedulable" (8/35 resolved)
2026/05/06 16:11:19 Failure: pod=cspod-27 reason="pod group is not ready, 1 Pending, 1 minAvailable; Pending: 1 Unschedulable" (9/35 resolved)
2026/05/06 16:11:19 Failure: pod=cspod-56 reason="pod group is not ready, 1 Pending, 1 minAvailable; Pending: 1 Unschedulable" (10/35 resolved)
2026/05/06 16:11:19 Failure: pod=cspod-35 reason="pod group is not ready, 4 Pending, 4 minAvailable; Pending: 4 Unschedulable" (11/35 resolved)
2026/05/06 16:11:19 Failure: pod=cspod-28 reason="pod group is not ready, 1 Pending, 1 minAvailable; Pending: 1 Unschedulable" (12/35 resolved)
2026/05/06 16:11:19 Failure: pod=cspod-55 reason="pod group is not ready, 1 Pending, 1 minAvailable; Pending: 1 Unschedulable" (13/35 resolved)
2026/05/06 16:11:19 Failure: pod=cspod-59 reason="pod group is not ready, 1 Pending, 1 minAvailable; Pending: 1 Unschedulable" (14/35 resolved)
2026/05/06 16:11:19 Failure: pod=cspod-66 reason="pod group is not ready, 1 Pending, 1 minAvailable; Pending: 1 Unschedulable" (15/35 resolved)
2026/05/06 16:11:19 Failure: pod=cspod-63 reason="pod group is not ready, 1 Pending, 1 minAvailable; Pending: 1 Unschedulable" (16/35 resolved)
2026/05/06 16:11:19 Failure: pod=cspod-53 reason="pod group is not ready, 3 Pending, 3 minAvailable; Pending: 3 Unschedulable" (17/35 resolved)
2026/05/06 16:11:19 Failure: pod=cspod-54 reason="pod group is not ready, 3 Pending, 3 minAvailable; Pending: 3 Unschedulable" (18/35 resolved)
2026/05/06 16:11:19 Failure: pod=cspod-31 reason="pod group is not ready, 3 Pending, 3 minAvailable; Pending: 3 Unschedulable" (19/35 resolved)
2026/05/06 16:11:19 Failure: pod=cspod-58 reason="pod group is not ready, 1 Pending, 1 minAvailable; Pending: 1 Unschedulable" (20/35 resolved)
2026/05/06 16:11:19 Failure: pod=cspod-65 reason="pod group is not ready, 1 Pending, 1 minAvailable; Pending: 1 Unschedulable" (21/35 resolved)
2026/05/06 16:11:19 Failure: pod=cspod-61 reason="pod group is not ready, 1 Pending, 1 minAvailable; Pending: 1 Unschedulable" (22/35 resolved)
2026/05/06 16:11:19 Failure: pod=cspod-57 reason="pod group is not ready, 1 Pending, 1 minAvailable; Pending: 1 Unschedulable" (23/35 resolved)
2026/05/06 16:11:19 Failure: pod=cspod-29 reason="pod group is not ready, 1 Pending, 1 minAvailable; Pending: 1 Unschedulable" (24/35 resolved)
2026/05/06 16:11:19 Failure: pod=cspod-62 reason="pod group is not ready, 1 Pending, 1 minAvailable; Pending: 1 Unschedulable" (25/35 resolved)
2026/05/06 16:11:19 Failure: pod=cspod-60 reason="pod group is not ready, 1 Pending, 1 minAvailable; Pending: 1 Unschedulable" (26/35 resolved)
2026/05/06 16:11:19 Failure: pod=cspod-36 reason="pod group is not ready, 4 Pending, 4 minAvailable; Pending: 4 Unschedulable" (27/35 resolved)
2026/05/06 16:11:19 Failure: pod=cspod-32 reason="pod group is not ready, 3 Pending, 3 minAvailable; Pending: 3 Unschedulable" (28/35 resolved)
2026/05/06 16:11:19 Failure: pod=cspod-6 reason="pod group is not ready, 1 Pending, 1 minAvailable; Pending: 1 Unschedulable" (29/35 resolved)
2026/05/06 16:11:19 Failure: pod=cspod-50 reason="pod group is not ready, 1 Pending, 1 minAvailable; Pending: 1 Unschedulable" (30/35 resolved)
2026/05/06 16:11:19 Failure: pod=cspod-8 reason="pod group is not ready, 1 Pending, 1 minAvailable; Pending: 1 Unschedulable" (31/35 resolved)
2026/05/06 16:11:19 Failure: pod=cspod-69 reason="pod group is not ready, 1 Pending, 1 minAvailable; Pending: 1 Unschedulable" (32/35 resolved)
2026/05/06 16:11:19 Failure: pod=cspod-33 reason="pod group is not ready, 4 Pending, 4 minAvailable; Pending: 4 Unschedulable" (33/35 resolved)
2026/05/06 16:11:19 Failure: pod=cspod-34 reason="pod group is not ready, 4 Pending, 4 minAvailable; Pending: 4 Unschedulable" (34/35 resolved)
2026/05/06 16:11:19 Binding: pod=cspod-26 -> node=csnode-4 (35/35 resolved)
2026/05/06 16:11:19 Round complete: 1 scheduled, 34 failed in 1.015412967s
2026/05/06 16:11:19 {"action":"HandleSchedule","durationMs":1017,"podCount":35,"result":"ok","roundId":"13","scheduled":1,"ts":"2026-05-06T16:11:19.032068505+01:00","unschedulable":34}
2026/05/06 16:11:19 {"action":"HandleSchedule","completedIds":3,"nodeCount":5,"phase":"start","podCount":34,"roundId":"14","ts":"2026-05-06T16:11:19.036982265+01:00"}
2026/05/06 16:11:19 {"action":"HandleSchedule","phase":"prep_done","podsCreated":34,"prepMs":1,"roundId":"14","staleDeleted":0,"ts":"2026-05-06T16:11:19.038085533+01:00"}
2026/05/06 16:11:19 Scheduling round started: expecting 34 decisions
2026/05/06 16:11:20 Binding: pod=cspod-50 -> node=csnode-4 (1/34 resolved)
2026/05/06 16:11:20 Failure: pod=cspod-65 reason="pod group is not ready, 1 Pending, 1 minAvailable; Pending: 1 Unschedulable" (2/34 resolved)
2026/05/06 16:11:20 Failure: pod=cspod-9 reason="pod group is not ready, 1 Pending, 1 minAvailable; Pending: 1 Unschedulable" (3/34 resolved)
2026/05/06 16:11:20 Failure: pod=cspod-67 reason="pod group is not ready, 1 Pending, 1 minAvailable; Pending: 1 Unschedulable" (4/34 resolved)
2026/05/06 16:11:20 Failure: pod=cspod-8 reason="pod group is not ready, 1 Pending, 1 minAvailable; Pending: 1 Unschedulable" (5/34 resolved)
2026/05/06 16:11:20 Failure: pod=cspod-31 reason="pod group is not ready, 3 Pending, 3 minAvailable; Pending: 3 Unschedulable" (6/34 resolved)
2026/05/06 16:11:20 Failure: pod=cspod-62 reason="pod group is not ready, 1 Pending, 1 minAvailable; Pending: 1 Unschedulable" (7/34 resolved)
2026/05/06 16:11:20 Failure: pod=cspod-60 reason="pod group is not ready, 1 Pending, 1 minAvailable; Pending: 1 Unschedulable" (8/34 resolved)
2026/05/06 16:11:20 Failure: pod=cspod-66 reason="pod group is not ready, 1 Pending, 1 minAvailable; Pending: 1 Unschedulable" (9/34 resolved)
2026/05/06 16:11:20 Failure: pod=cspod-32 reason="pod group is not ready, 3 Pending, 3 minAvailable; Pending: 3 Unschedulable" (10/34 resolved)
2026/05/06 16:11:20 Failure: pod=cspod-33 reason="pod group is not ready, 4 Pending, 4 minAvailable; Pending: 4 Unschedulable" (11/34 resolved)
2026/05/06 16:11:20 Failure: pod=cspod-52 reason="pod group is not ready, 3 Pending, 3 minAvailable; Pending: 3 Unschedulable" (12/34 resolved)
2026/05/06 16:11:20 Failure: pod=cspod-58 reason="pod group is not ready, 1 Pending, 1 minAvailable; Pending: 1 Unschedulable" (13/34 resolved)
2026/05/06 16:11:20 Failure: pod=cspod-69 reason="pod group is not ready, 1 Pending, 1 minAvailable; Pending: 1 Unschedulable" (14/34 resolved)
2026/05/06 16:11:20 Failure: pod=cspod-64 reason="pod group is not ready, 1 Pending, 1 minAvailable; Pending: 1 Unschedulable" (15/34 resolved)
2026/05/06 16:11:20 Failure: pod=cspod-63 reason="pod group is not ready, 1 Pending, 1 minAvailable; Pending: 1 Unschedulable" (16/34 resolved)
2026/05/06 16:11:20 Failure: pod=cspod-57 reason="pod group is not ready, 1 Pending, 1 minAvailable; Pending: 1 Unschedulable" (17/34 resolved)
2026/05/06 16:11:20 Failure: pod=cspod-27 reason="pod group is not ready, 1 Pending, 1 minAvailable; Pending: 1 Unschedulable" (18/34 resolved)
2026/05/06 16:11:20 Failure: pod=cspod-68 reason="pod group is not ready, 1 Pending, 1 minAvailable; Pending: 1 Unschedulable" (19/34 resolved)
2026/05/06 16:11:20 Failure: pod=cspod-34 reason="pod group is not ready, 4 Pending, 4 minAvailable; Pending: 4 Unschedulable" (20/34 resolved)
2026/05/06 16:11:20 Failure: pod=cspod-7 reason="pod group is not ready, 1 Pending, 1 minAvailable; Pending: 1 Unschedulable" (21/34 resolved)
2026/05/06 16:11:20 Failure: pod=cspod-30 reason="pod group is not ready, 3 Pending, 3 minAvailable; Pending: 3 Unschedulable" (22/34 resolved)
2026/05/06 16:11:20 Failure: pod=cspod-53 reason="pod group is not ready, 3 Pending, 3 minAvailable; Pending: 3 Unschedulable" (23/34 resolved)
2026/05/06 16:11:20 Failure: pod=cspod-61 reason="pod group is not ready, 1 Pending, 1 minAvailable; Pending: 1 Unschedulable" (24/34 resolved)
2026/05/06 16:11:20 Failure: pod=cspod-59 reason="pod group is not ready, 1 Pending, 1 minAvailable; Pending: 1 Unschedulable" (25/34 resolved)
2026/05/06 16:11:20 Failure: pod=cspod-29 reason="pod group is not ready, 1 Pending, 1 minAvailable; Pending: 1 Unschedulable" (26/34 resolved)
2026/05/06 16:11:20 Failure: pod=cspod-28 reason="pod group is not ready, 1 Pending, 1 minAvailable; Pending: 1 Unschedulable" (27/34 resolved)
2026/05/06 16:11:20 Failure: pod=cspod-35 reason="pod group is not ready, 4 Pending, 4 minAvailable; Pending: 4 Unschedulable" (28/34 resolved)
2026/05/06 16:11:20 Failure: pod=cspod-6 reason="pod group is not ready, 1 Pending, 1 minAvailable; Pending: 1 Unschedulable" (29/34 resolved)
2026/05/06 16:11:20 Failure: pod=cspod-54 reason="pod group is not ready, 3 Pending, 3 minAvailable; Pending: 3 Unschedulable" (30/34 resolved)
2026/05/06 16:11:20 Failure: pod=cspod-36 reason="pod group is not ready, 4 Pending, 4 minAvailable; Pending: 4 Unschedulable" (31/34 resolved)
2026/05/06 16:11:20 Binding: pod=cspod-55 -> node=csnode-4 (32/34 resolved)
2026/05/06 16:11:20 Binding: pod=cspod-51 -> node=csnode-4 (33/34 resolved)
2026/05/06 16:11:20 Binding: pod=cspod-56 -> node=csnode-4 (34/34 resolved)
2026/05/06 16:11:20 Round complete: 4 scheduled, 30 failed in 1.00350438s
2026/05/06 16:11:20 {"action":"HandleSchedule","durationMs":1004,"podCount":34,"result":"ok","roundId":"14","scheduled":4,"ts":"2026-05-06T16:11:20.041784769+01:00","unschedulable":30}
2026/05/06 16:11:20 {"action":"HandleSchedule","completedIds":2,"nodeCount":5,"phase":"start","podCount":30,"roundId":"15","ts":"2026-05-06T16:11:20.049752414+01:00"}
2026/05/06 16:11:20 {"action":"HandleSchedule","phase":"prep_done","podsCreated":30,"prepMs":1,"roundId":"15","staleDeleted":0,"ts":"2026-05-06T16:11:20.050903804+01:00"}
2026/05/06 16:11:20 Scheduling round started: expecting 30 decisions
2026/05/06 16:11:21 Failure: pod=cspod-30 reason="pod group is not ready, 3 Pending, 3 minAvailable; Pending: 3 Unschedulable" (1/30 resolved)
2026/05/06 16:11:21 Binding: pod=cspod-57 -> node=csnode-4 (2/30 resolved)
2026/05/06 16:11:21 Failure: pod=cspod-7 reason="pod group is not ready, 1 Pending, 1 minAvailable; Pending: 1 Unschedulable" (3/30 resolved)
2026/05/06 16:11:21 Failure: pod=cspod-27 reason="pod group is not ready, 1 Pending, 1 minAvailable; Pending: 1 Unschedulable" (4/30 resolved)
2026/05/06 16:11:21 Failure: pod=cspod-61 reason="pod group is not ready, 1 Pending, 1 minAvailable; Pending: 1 Unschedulable" (5/30 resolved)
2026/05/06 16:11:21 Binding: pod=cspod-58 -> node=csnode-4 (6/30 resolved)
2026/05/06 16:11:21 Failure: pod=cspod-60 reason="pod group is not ready, 1 Pending, 1 minAvailable; Pending: 1 Unschedulable" (7/30 resolved)
2026/05/06 16:11:21 Failure: pod=cspod-8 reason="pod group is not ready, 1 Pending, 1 minAvailable; Pending: 1 Unschedulable" (8/30 resolved)
2026/05/06 16:11:21 Failure: pod=cspod-28 reason="pod group is not ready, 1 Pending, 1 minAvailable; Pending: 1 Unschedulable" (9/30 resolved)
2026/05/06 16:11:21 Failure: pod=cspod-31 reason="pod group is not ready, 3 Pending, 3 minAvailable; Pending: 3 Unschedulable" (10/30 resolved)
2026/05/06 16:11:21 Failure: pod=cspod-6 reason="pod group is not ready, 1 Pending, 1 minAvailable; Pending: 1 Unschedulable" (11/30 resolved)
2026/05/06 16:11:21 Failure: pod=cspod-65 reason="pod group is not ready, 1 Pending, 1 minAvailable; Pending: 1 Unschedulable" (12/30 resolved)
2026/05/06 16:11:21 Failure: pod=cspod-9 reason="pod group is not ready, 1 Pending, 1 minAvailable; Pending: 1 Unschedulable" (13/30 resolved)
2026/05/06 16:11:21 Failure: pod=cspod-62 reason="pod group is not ready, 1 Pending, 1 minAvailable; Pending: 1 Unschedulable" (14/30 resolved)
2026/05/06 16:11:21 Failure: pod=cspod-64 reason="pod group is not ready, 1 Pending, 1 minAvailable; Pending: 1 Unschedulable" (15/30 resolved)
2026/05/06 16:11:21 Failure: pod=cspod-63 reason="pod group is not ready, 1 Pending, 1 minAvailable; Pending: 1 Unschedulable" (16/30 resolved)
2026/05/06 16:11:21 Failure: pod=cspod-66 reason="pod group is not ready, 1 Pending, 1 minAvailable; Pending: 1 Unschedulable" (17/30 resolved)
2026/05/06 16:11:21 Failure: pod=cspod-29 reason="pod group is not ready, 1 Pending, 1 minAvailable; Pending: 1 Unschedulable" (18/30 resolved)
2026/05/06 16:11:21 Failure: pod=cspod-32 reason="pod group is not ready, 3 Pending, 3 minAvailable; Pending: 3 Unschedulable" (19/30 resolved)
2026/05/06 16:11:21 Failure: pod=cspod-69 reason="pod group is not ready, 1 Pending, 1 minAvailable; Pending: 1 Unschedulable" (20/30 resolved)
2026/05/06 16:11:21 Failure: pod=cspod-59 reason="pod group is not ready, 1 Pending, 1 minAvailable; Pending: 1 Unschedulable" (21/30 resolved)
2026/05/06 16:11:21 Failure: pod=cspod-52 reason="pod group is not ready, 3 Pending, 3 minAvailable; Pending: 3 Unschedulable" (22/30 resolved)
2026/05/06 16:11:21 Failure: pod=cspod-68 reason="pod group is not ready, 1 Pending, 1 minAvailable; Pending: 1 Unschedulable" (23/30 resolved)
2026/05/06 16:11:21 Failure: pod=cspod-53 reason="pod group is not ready, 3 Pending, 3 minAvailable; Pending: 3 Unschedulable" (24/30 resolved)
2026/05/06 16:11:21 Failure: pod=cspod-67 reason="pod group is not ready, 1 Pending, 1 minAvailable; Pending: 1 Unschedulable" (25/30 resolved)
2026/05/06 16:11:21 Failure: pod=cspod-54 reason="pod group is not ready, 3 Pending, 3 minAvailable; Pending: 3 Unschedulable" (26/30 resolved)
2026/05/06 16:11:21 Failure: pod=cspod-33 reason="pod group is not ready, 4 Pending, 4 minAvailable; Pending: 4 Unschedulable" (27/30 resolved)
2026/05/06 16:11:21 Failure: pod=cspod-34 reason="pod group is not ready, 4 Pending, 4 minAvailable; Pending: 4 Unschedulable" (28/30 resolved)
2026/05/06 16:11:21 Failure: pod=cspod-35 reason="pod group is not ready, 4 Pending, 4 minAvailable; Pending: 4 Unschedulable" (29/30 resolved)
2026/05/06 16:11:21 Failure: pod=cspod-36 reason="pod group is not ready, 4 Pending, 4 minAvailable; Pending: 4 Unschedulable" (30/30 resolved)
2026/05/06 16:11:21 Round complete: 2 scheduled, 28 failed in 984.028647ms
2026/05/06 16:11:21 {"action":"HandleSchedule","durationMs":985,"podCount":30,"result":"ok","roundId":"15","scheduled":2,"ts":"2026-05-06T16:11:21.035109845+01:00","unschedulable":28}
2026/05/06 16:11:21 {"action":"HandleSchedule","completedIds":1,"nodeCount":5,"phase":"start","podCount":28,"roundId":"16","ts":"2026-05-06T16:11:21.043225305+01:00"}
2026/05/06 16:11:21 {"action":"HandleSchedule","phase":"prep_done","podsCreated":28,"prepMs":0,"roundId":"16","staleDeleted":0,"ts":"2026-05-06T16:11:21.043599968+01:00"}
2026/05/06 16:11:21 Scheduling round started: expecting 28 decisions
2026/05/06 16:11:22 Failure: pod=cspod-7 reason="pod group is not ready, 1 Pending, 1 minAvailable; Pending: 1 Unschedulable" (1/28 resolved)
2026/05/06 16:11:22 Failure: pod=cspod-67 reason="pod group is not ready, 1 Pending, 1 minAvailable; Pending: 1 Unschedulable" (2/28 resolved)
2026/05/06 16:11:22 Failure: pod=cspod-29 reason="pod group is not ready, 1 Pending, 1 minAvailable; Pending: 1 Unschedulable" (3/28 resolved)
2026/05/06 16:11:22 Failure: pod=cspod-61 reason="pod group is not ready, 1 Pending, 1 minAvailable; Pending: 1 Unschedulable" (4/28 resolved)
2026/05/06 16:11:22 Failure: pod=cspod-69 reason="pod group is not ready, 1 Pending, 1 minAvailable; Pending: 1 Unschedulable" (5/28 resolved)
2026/05/06 16:11:22 Failure: pod=cspod-63 reason="pod group is not ready, 1 Pending, 1 minAvailable; Pending: 1 Unschedulable" (6/28 resolved)
2026/05/06 16:11:22 Failure: pod=cspod-27 reason="pod group is not ready, 1 Pending, 1 minAvailable; Pending: 1 Unschedulable" (7/28 resolved)
2026/05/06 16:11:22 Failure: pod=cspod-65 reason="pod group is not ready, 1 Pending, 1 minAvailable; Pending: 1 Unschedulable" (8/28 resolved)
2026/05/06 16:11:22 Failure: pod=cspod-28 reason="pod group is not ready, 1 Pending, 1 minAvailable; Pending: 1 Unschedulable" (9/28 resolved)
2026/05/06 16:11:22 Failure: pod=cspod-52 reason="pod group is not ready, 3 Pending, 3 minAvailable; Pending: 3 Unschedulable" (10/28 resolved)
2026/05/06 16:11:22 Failure: pod=cspod-6 reason="pod group is not ready, 1 Pending, 1 minAvailable; Pending: 1 Unschedulable" (11/28 resolved)
2026/05/06 16:11:22 Failure: pod=cspod-66 reason="pod group is not ready, 1 Pending, 1 minAvailable; Pending: 1 Unschedulable" (12/28 resolved)
2026/05/06 16:11:22 Failure: pod=cspod-64 reason="pod group is not ready, 1 Pending, 1 minAvailable; Pending: 1 Unschedulable" (13/28 resolved)
2026/05/06 16:11:22 Failure: pod=cspod-34 reason="pod group is not ready, 4 Pending, 4 minAvailable; Pending: 4 Unschedulable" (14/28 resolved)
2026/05/06 16:11:22 Failure: pod=cspod-31 reason="pod group is not ready, 3 Pending, 3 minAvailable; Pending: 3 Unschedulable" (15/28 resolved)
2026/05/06 16:11:22 Failure: pod=cspod-62 reason="pod group is not ready, 1 Pending, 1 minAvailable; Pending: 1 Unschedulable" (16/28 resolved)
2026/05/06 16:11:22 Binding: pod=cspod-59 -> node=csnode-0 (17/28 resolved)
2026/05/06 16:11:22 Failure: pod=cspod-8 reason="pod group is not ready, 1 Pending, 1 minAvailable; Pending: 1 Unschedulable" (18/28 resolved)
2026/05/06 16:11:22 Failure: pod=cspod-53 reason="pod group is not ready, 3 Pending, 3 minAvailable; Pending: 3 Unschedulable" (19/28 resolved)
2026/05/06 16:11:22 Failure: pod=cspod-32 reason="pod group is not ready, 3 Pending, 3 minAvailable; Pending: 3 Unschedulable" (20/28 resolved)
2026/05/06 16:11:22 Failure: pod=cspod-60 reason="pod group is not ready, 1 Pending, 1 minAvailable; Pending: 1 Unschedulable" (21/28 resolved)
2026/05/06 16:11:22 Failure: pod=cspod-68 reason="pod group is not ready, 1 Pending, 1 minAvailable; Pending: 1 Unschedulable" (22/28 resolved)
2026/05/06 16:11:22 Failure: pod=cspod-35 reason="pod group is not ready, 4 Pending, 4 minAvailable; Pending: 4 Unschedulable" (23/28 resolved)
2026/05/06 16:11:22 Failure: pod=cspod-30 reason="pod group is not ready, 3 Pending, 3 minAvailable; Pending: 3 Unschedulable" (24/28 resolved)
2026/05/06 16:11:22 Failure: pod=cspod-9 reason="pod group is not ready, 1 Pending, 1 minAvailable; Pending: 1 Unschedulable" (25/28 resolved)
2026/05/06 16:11:22 Failure: pod=cspod-54 reason="pod group is not ready, 3 Pending, 3 minAvailable; Pending: 3 Unschedulable" (26/28 resolved)
2026/05/06 16:11:22 Failure: pod=cspod-36 reason="pod group is not ready, 4 Pending, 4 minAvailable; Pending: 4 Unschedulable" (27/28 resolved)
2026/05/06 16:11:22 Failure: pod=cspod-33 reason="pod group is not ready, 4 Pending, 4 minAvailable; Pending: 4 Unschedulable" (28/28 resolved)
2026/05/06 16:11:22 Round complete: 1 scheduled, 27 failed in 1.003086357s
2026/05/06 16:11:22 {"action":"HandleSchedule","durationMs":1003,"podCount":28,"result":"ok","roundId":"16","scheduled":1,"ts":"2026-05-06T16:11:22.046797875+01:00","unschedulable":27}
2026/05/06 16:11:22 {"action":"HandleSchedule","completedIds":2,"nodeCount":5,"phase":"start","podCount":27,"roundId":"17","ts":"2026-05-06T16:11:22.052908384+01:00"}
2026/05/06 16:11:22 {"action":"HandleSchedule","phase":"prep_done","podsCreated":27,"prepMs":0,"roundId":"17","staleDeleted":0,"ts":"2026-05-06T16:11:22.053308425+01:00"}
2026/05/06 16:11:22 Scheduling round started: expecting 27 decisions
2026/05/06 16:11:23 Failure: pod=cspod-30 reason="pod group is not ready, 3 Pending, 3 minAvailable; Pending: 3 Unschedulable" (1/27 resolved)
2026/05/06 16:11:23 Failure: pod=cspod-60 reason="pod group is not ready, 1 Pending, 1 minAvailable; Pending: 1 Unschedulable" (2/27 resolved)
2026/05/06 16:11:23 Failure: pod=cspod-9 reason="pod group is not ready, 1 Pending, 1 minAvailable; Pending: 1 Unschedulable" (3/27 resolved)
2026/05/06 16:11:23 Failure: pod=cspod-29 reason="pod group is not ready, 1 Pending, 1 minAvailable; Pending: 1 Unschedulable" (4/27 resolved)
2026/05/06 16:11:23 Failure: pod=cspod-36 reason="pod group is not ready, 4 Pending, 4 minAvailable; Pending: 4 Unschedulable" (5/27 resolved)
2026/05/06 16:11:23 Failure: pod=cspod-66 reason="pod group is not ready, 1 Pending, 1 minAvailable; Pending: 1 Unschedulable" (6/27 resolved)
2026/05/06 16:11:23 Failure: pod=cspod-27 reason="pod group is not ready, 1 Pending, 1 minAvailable; Pending: 1 Unschedulable" (7/27 resolved)
2026/05/06 16:11:23 Failure: pod=cspod-68 reason="pod group is not ready, 1 Pending, 1 minAvailable; Pending: 1 Unschedulable" (8/27 resolved)
2026/05/06 16:11:23 Failure: pod=cspod-67 reason="pod group is not ready, 1 Pending, 1 minAvailable; Pending: 1 Unschedulable" (9/27 resolved)
2026/05/06 16:11:23 Failure: pod=cspod-31 reason="pod group is not ready, 3 Pending, 3 minAvailable; Pending: 3 Unschedulable" (10/27 resolved)
2026/05/06 16:11:23 Failure: pod=cspod-69 reason="pod group is not ready, 1 Pending, 1 minAvailable; Pending: 1 Unschedulable" (11/27 resolved)
2026/05/06 16:11:23 Failure: pod=cspod-61 reason="pod group is not ready, 1 Pending, 1 minAvailable; Pending: 1 Unschedulable" (12/27 resolved)
2026/05/06 16:11:23 Failure: pod=cspod-62 reason="pod group is not ready, 1 Pending, 1 minAvailable; Pending: 1 Unschedulable" (13/27 resolved)
2026/05/06 16:11:23 Failure: pod=cspod-8 reason="pod group is not ready, 1 Pending, 1 minAvailable; Pending: 1 Unschedulable" (14/27 resolved)
2026/05/06 16:11:23 Failure: pod=cspod-65 reason="pod group is not ready, 1 Pending, 1 minAvailable; Pending: 1 Unschedulable" (15/27 resolved)
2026/05/06 16:11:23 Failure: pod=cspod-63 reason="pod group is not ready, 1 Pending, 1 minAvailable; Pending: 1 Unschedulable" (16/27 resolved)
2026/05/06 16:11:23 Failure: pod=cspod-33 reason="pod group is not ready, 4 Pending, 4 minAvailable; Pending: 4 Unschedulable" (17/27 resolved)
2026/05/06 16:11:23 Failure: pod=cspod-28 reason="pod group is not ready, 1 Pending, 1 minAvailable; Pending: 1 Unschedulable" (18/27 resolved)
2026/05/06 16:11:23 Failure: pod=cspod-32 reason="pod group is not ready, 3 Pending, 3 minAvailable; Pending: 3 Unschedulable" (19/27 resolved)
2026/05/06 16:11:23 Failure: pod=cspod-52 reason="pod group is not ready, 3 Pending, 3 minAvailable; Pending: 3 Unschedulable" (20/27 resolved)
2026/05/06 16:11:23 Failure: pod=cspod-64 reason="pod group is not ready, 1 Pending, 1 minAvailable; Pending: 1 Unschedulable" (21/27 resolved)
2026/05/06 16:11:23 Failure: pod=cspod-34 reason="pod group is not ready, 4 Pending, 4 minAvailable; Pending: 4 Unschedulable" (22/27 resolved)
2026/05/06 16:11:23 Failure: pod=cspod-53 reason="pod group is not ready, 3 Pending, 3 minAvailable; Pending: 3 Unschedulable" (23/27 resolved)
2026/05/06 16:11:23 Failure: pod=cspod-35 reason="pod group is not ready, 4 Pending, 4 minAvailable; Pending: 4 Unschedulable" (24/27 resolved)
2026/05/06 16:11:23 Failure: pod=cspod-54 reason="pod group is not ready, 3 Pending, 3 minAvailable; Pending: 3 Unschedulable" (25/27 resolved)
2026/05/06 16:11:23 Binding: pod=cspod-7 -> node=csnode-4 (26/27 resolved)
2026/05/06 16:11:23 Binding: pod=cspod-6 -> node=csnode-4 (27/27 resolved)
2026/05/06 16:11:23 Round complete: 2 scheduled, 25 failed in 1.015555771s
2026/05/06 16:11:23 {"action":"HandleSchedule","durationMs":1016,"podCount":27,"result":"ok","roundId":"17","scheduled":2,"ts":"2026-05-06T16:11:23.068901051+01:00","unschedulable":25}
2026/05/06 16:11:23 {"action":"HandleSchedule","completedIds":2,"nodeCount":5,"phase":"start","podCount":25,"roundId":"18","ts":"2026-05-06T16:11:23.074763913+01:00"}
2026/05/06 16:11:23 {"action":"HandleSchedule","phase":"prep_done","podsCreated":25,"prepMs":0,"roundId":"18","staleDeleted":0,"ts":"2026-05-06T16:11:23.075184421+01:00"}
2026/05/06 16:11:23 Scheduling round started: expecting 25 decisions
2026/05/06 16:11:24 Failure: pod=cspod-28 reason="pod group is not ready, 1 Pending, 1 minAvailable; Pending: 1 Unschedulable" (1/25 resolved)
2026/05/06 16:11:24 Failure: pod=cspod-66 reason="pod group is not ready, 1 Pending, 1 minAvailable; Pending: 1 Unschedulable" (2/25 resolved)
2026/05/06 16:11:24 Failure: pod=cspod-65 reason="pod group is not ready, 1 Pending, 1 minAvailable; Pending: 1 Unschedulable" (3/25 resolved)
2026/05/06 16:11:24 Failure: pod=cspod-69 reason="pod group is not ready, 1 Pending, 1 minAvailable; Pending: 1 Unschedulable" (4/25 resolved)
2026/05/06 16:11:24 Failure: pod=cspod-68 reason="pod group is not ready, 1 Pending, 1 minAvailable; Pending: 1 Unschedulable" (5/25 resolved)
2026/05/06 16:11:24 Failure: pod=cspod-27 reason="pod group is not ready, 1 Pending, 1 minAvailable; Pending: 1 Unschedulable" (6/25 resolved)
2026/05/06 16:11:24 Failure: pod=cspod-52 reason="pod group is not ready, 3 Pending, 3 minAvailable; Pending: 3 Unschedulable" (7/25 resolved)
2026/05/06 16:11:24 Failure: pod=cspod-29 reason="pod group is not ready, 1 Pending, 1 minAvailable; Pending: 1 Unschedulable" (8/25 resolved)
2026/05/06 16:11:24 Failure: pod=cspod-9 reason="pod group is not ready, 1 Pending, 1 minAvailable; Pending: 1 Unschedulable" (9/25 resolved)
2026/05/06 16:11:24 Failure: pod=cspod-31 reason="pod group is not ready, 3 Pending, 3 minAvailable; Pending: 3 Unschedulable" (10/25 resolved)
2026/05/06 16:11:24 Failure: pod=cspod-62 reason="pod group is not ready, 1 Pending, 1 minAvailable; Pending: 1 Unschedulable" (11/25 resolved)
2026/05/06 16:11:24 Failure: pod=cspod-67 reason="pod group is not ready, 1 Pending, 1 minAvailable; Pending: 1 Unschedulable" (12/25 resolved)
2026/05/06 16:11:24 Failure: pod=cspod-32 reason="pod group is not ready, 3 Pending, 3 minAvailable; Pending: 3 Unschedulable" (13/25 resolved)
2026/05/06 16:11:24 Failure: pod=cspod-34 reason="pod group is not ready, 4 Pending, 4 minAvailable; Pending: 4 Unschedulable" (14/25 resolved)
2026/05/06 16:11:24 Failure: pod=cspod-61 reason="pod group is not ready, 1 Pending, 1 minAvailable; Pending: 1 Unschedulable" (15/25 resolved)
2026/05/06 16:11:24 Failure: pod=cspod-60 reason="pod group is not ready, 1 Pending, 1 minAvailable; Pending: 1 Unschedulable" (16/25 resolved)
2026/05/06 16:11:24 Failure: pod=cspod-63 reason="pod group is not ready, 1 Pending, 1 minAvailable; Pending: 1 Unschedulable" (17/25 resolved)
2026/05/06 16:11:24 Failure: pod=cspod-64 reason="pod group is not ready, 1 Pending, 1 minAvailable; Pending: 1 Unschedulable" (18/25 resolved)
2026/05/06 16:11:24 Failure: pod=cspod-35 reason="pod group is not ready, 4 Pending, 4 minAvailable; Pending: 4 Unschedulable" (19/25 resolved)
2026/05/06 16:11:24 Failure: pod=cspod-30 reason="pod group is not ready, 3 Pending, 3 minAvailable; Pending: 3 Unschedulable" (20/25 resolved)
2026/05/06 16:11:24 Failure: pod=cspod-53 reason="pod group is not ready, 3 Pending, 3 minAvailable; Pending: 3 Unschedulable" (21/25 resolved)
2026/05/06 16:11:24 Failure: pod=cspod-54 reason="pod group is not ready, 3 Pending, 3 minAvailable; Pending: 3 Unschedulable" (22/25 resolved)
2026/05/06 16:11:24 Failure: pod=cspod-36 reason="pod group is not ready, 4 Pending, 4 minAvailable; Pending: 4 Unschedulable" (23/25 resolved)
2026/05/06 16:11:24 Failure: pod=cspod-33 reason="pod group is not ready, 4 Pending, 4 minAvailable; Pending: 4 Unschedulable" (24/25 resolved)
2026/05/06 16:11:24 Binding: pod=cspod-8 -> node=csnode-4 (25/25 resolved)
2026/05/06 16:11:24 Round complete: 1 scheduled, 24 failed in 992.038432ms
2026/05/06 16:11:24 {"action":"HandleSchedule","durationMs":992,"podCount":25,"result":"ok","roundId":"18","scheduled":1,"ts":"2026-05-06T16:11:24.067313583+01:00","unschedulable":24}
2026/05/06 16:11:24 {"action":"HandleSchedule","completedIds":2,"nodeCount":5,"phase":"start","podCount":24,"roundId":"19","ts":"2026-05-06T16:11:24.073983489+01:00"}
2026/05/06 16:11:24 {"action":"HandleSchedule","phase":"prep_done","podsCreated":24,"prepMs":0,"roundId":"19","staleDeleted":0,"ts":"2026-05-06T16:11:24.07428579+01:00"}
2026/05/06 16:11:24 Scheduling round started: expecting 24 decisions
2026/05/06 16:11:25 Failure: pod=cspod-53 reason="pod group is not ready, 3 Pending, 3 minAvailable; Pending: 1 Schedulable, 2 Unschedulable" (1/24 resolved)
2026/05/06 16:11:25 Failure: pod=cspod-69 reason="pod group is not ready, 1 Pending, 1 minAvailable; Pending: 1 Unschedulable" (2/24 resolved)
2026/05/06 16:11:25 Failure: pod=cspod-28 reason="pod group is not ready, 1 Pending, 1 minAvailable; Pending: 1 Unschedulable" (3/24 resolved)
2026/05/06 16:11:25 Failure: pod=cspod-64 reason="pod group is not ready, 1 Pending, 1 minAvailable; Pending: 1 Unschedulable" (4/24 resolved)
2026/05/06 16:11:25 Failure: pod=cspod-34 reason="pod group is not ready, 4 Pending, 4 minAvailable; Pending: 4 Unschedulable" (5/24 resolved)
2026/05/06 16:11:25 Failure: pod=cspod-63 reason="pod group is not ready, 1 Pending, 1 minAvailable; Pending: 1 Unschedulable" (6/24 resolved)
2026/05/06 16:11:25 Failure: pod=cspod-60 reason="pod group is not ready, 1 Pending, 1 minAvailable; Pending: 1 Unschedulable" (7/24 resolved)
2026/05/06 16:11:25 Failure: pod=cspod-32 reason="pod group is not ready, 3 Pending, 3 minAvailable; Pending: 1 Schedulable, 2 Unschedulable" (8/24 resolved)
2026/05/06 16:11:25 Failure: pod=cspod-54 reason="pod group is not ready, 3 Pending, 3 minAvailable; Pending: 1 Schedulable, 2 Unschedulable" (9/24 resolved)
2026/05/06 16:11:25 Failure: pod=cspod-61 reason="pod group is not ready, 1 Pending, 1 minAvailable; Pending: 1 Unschedulable" (10/24 resolved)
2026/05/06 16:11:25 Failure: pod=cspod-29 reason="pod group is not ready, 1 Pending, 1 minAvailable; Pending: 1 Unschedulable" (11/24 resolved)
2026/05/06 16:11:25 Failure: pod=cspod-27 reason="pod group is not ready, 1 Pending, 1 minAvailable; Pending: 1 Unschedulable" (12/24 resolved)
2026/05/06 16:11:25 Failure: pod=cspod-65 reason="pod group is not ready, 1 Pending, 1 minAvailable; Pending: 1 Unschedulable" (13/24 resolved)
2026/05/06 16:11:25 Failure: pod=cspod-67 reason="pod group is not ready, 1 Pending, 1 minAvailable; Pending: 1 Unschedulable" (14/24 resolved)
2026/05/06 16:11:25 Failure: pod=cspod-62 reason="pod group is not ready, 1 Pending, 1 minAvailable; Pending: 1 Unschedulable" (15/24 resolved)
2026/05/06 16:11:25 Failure: pod=cspod-68 reason="pod group is not ready, 1 Pending, 1 minAvailable; Pending: 1 Unschedulable" (16/24 resolved)
2026/05/06 16:11:25 Failure: pod=cspod-66 reason="pod group is not ready, 1 Pending, 1 minAvailable; Pending: 1 Unschedulable" (17/24 resolved)
2026/05/06 16:11:25 Failure: pod=cspod-35 reason="pod group is not ready, 4 Pending, 4 minAvailable; Pending: 4 Unschedulable" (18/24 resolved)
2026/05/06 16:11:25 Failure: pod=cspod-36 reason="pod group is not ready, 4 Pending, 4 minAvailable; Pending: 4 Unschedulable" (19/24 resolved)
2026/05/06 16:11:25 Failure: pod=cspod-31 reason="pod group is not ready, 3 Pending, 3 minAvailable; Pending: 1 Schedulable, 2 Unschedulable" (20/24 resolved)
2026/05/06 16:11:25 Failure: pod=cspod-33 reason="pod group is not ready, 4 Pending, 4 minAvailable; Pending: 4 Unschedulable" (21/24 resolved)
2026/05/06 16:11:25 Binding: pod=cspod-9 -> node=csnode-3 (22/24 resolved)
2026/05/06 16:11:28 STALL EXIT: no progress for 2s — 1 scheduled, 21 failed, 2 still pending (returning partial)
2026/05/06 16:11:28 {"action":"HandleSchedule","durationMs":4002,"podCount":24,"result":"timeout_partial","roundId":"19","scheduled":1,"ts":"2026-05-06T16:11:28.076379508+01:00","unschedulable":23}
2026/05/06 16:11:28 {"action":"HandleSchedule","durationMs":4002,"podCount":24,"result":"ok","roundId":"19","scheduled":1,"ts":"2026-05-06T16:11:28.076401509+01:00","unschedulable":23}
2026/05/06 16:11:28 {"action":"HandleSchedule","completedIds":2,"nodeCount":5,"phase":"start","podCount":23,"roundId":"20","ts":"2026-05-06T16:11:28.085215806+01:00"}
2026/05/06 16:11:28 {"action":"HandleSchedule","phase":"prep_done","podsCreated":23,"prepMs":1,"roundId":"20","staleDeleted":0,"ts":"2026-05-06T16:11:28.086457562+01:00"}
2026/05/06 16:11:28 Scheduling round started: expecting 23 decisions
2026/05/06 16:11:29 Failure: pod=cspod-35 reason="pod group is not ready, 4 Pending, 4 minAvailable; Pending: 4 Unschedulable" (1/23 resolved)
2026/05/06 16:11:29 Failure: pod=cspod-61 reason="pod group is not ready, 1 Pending, 1 minAvailable; Pending: 1 Unschedulable" (2/23 resolved)
2026/05/06 16:11:29 Failure: pod=cspod-29 reason="pod group is not ready, 1 Pending, 1 minAvailable; Pending: 1 Unschedulable" (3/23 resolved)
2026/05/06 16:11:29 Failure: pod=cspod-28 reason="pod group is not ready, 1 Pending, 1 minAvailable; Pending: 1 Unschedulable" (4/23 resolved)
2026/05/06 16:11:29 Failure: pod=cspod-65 reason="pod group is not ready, 1 Pending, 1 minAvailable; Pending: 1 Unschedulable" (5/23 resolved)
2026/05/06 16:11:29 Failure: pod=cspod-60 reason="pod group is not ready, 1 Pending, 1 minAvailable; Pending: 1 Unschedulable" (6/23 resolved)
2026/05/06 16:11:29 Failure: pod=cspod-67 reason="pod group is not ready, 1 Pending, 1 minAvailable; Pending: 1 Unschedulable" (7/23 resolved)
2026/05/06 16:11:29 Failure: pod=cspod-62 reason="pod group is not ready, 1 Pending, 1 minAvailable; Pending: 1 Unschedulable" (8/23 resolved)
2026/05/06 16:11:29 Failure: pod=cspod-66 reason="pod group is not ready, 1 Pending, 1 minAvailable; Pending: 1 Unschedulable" (9/23 resolved)
2026/05/06 16:11:29 Failure: pod=cspod-27 reason="pod group is not ready, 1 Pending, 1 minAvailable; Pending: 1 Unschedulable" (10/23 resolved)
2026/05/06 16:11:29 Failure: pod=cspod-64 reason="pod group is not ready, 1 Pending, 1 minAvailable; Pending: 1 Unschedulable" (11/23 resolved)
2026/05/06 16:11:29 Failure: pod=cspod-63 reason="pod group is not ready, 1 Pending, 1 minAvailable; Pending: 1 Unschedulable" (12/23 resolved)
2026/05/06 16:11:29 Failure: pod=cspod-36 reason="pod group is not ready, 4 Pending, 4 minAvailable; Pending: 4 Unschedulable" (13/23 resolved)
2026/05/06 16:11:29 Failure: pod=cspod-52 reason="pod group is not ready, 3 Pending, 3 minAvailable; Pending: 3 Unschedulable" (14/23 resolved)
2026/05/06 16:11:29 Failure: pod=cspod-68 reason="pod group is not ready, 1 Pending, 1 minAvailable; Pending: 1 Unschedulable" (15/23 resolved)
2026/05/06 16:11:29 Failure: pod=cspod-69 reason="pod group is not ready, 1 Pending, 1 minAvailable; Pending: 1 Unschedulable" (16/23 resolved)
2026/05/06 16:11:29 Binding: pod=cspod-30 -> node=csnode-2 (17/23 resolved)
2026/05/06 16:11:29 Failure: pod=cspod-53 reason="pod group is not ready, 3 Pending, 3 minAvailable; Pending: 3 Unschedulable" (18/23 resolved)
2026/05/06 16:11:29 Binding: pod=cspod-32 -> node=csnode-0 (19/23 resolved)
2026/05/06 16:11:29 Binding: pod=cspod-31 -> node=csnode-1 (20/23 resolved)
2026/05/06 16:11:29 Failure: pod=cspod-33 reason="pod group is not ready, 4 Pending, 4 minAvailable; Pending: 4 Unschedulable" (21/23 resolved)
2026/05/06 16:11:29 Failure: pod=cspod-54 reason="pod group is not ready, 3 Pending, 3 minAvailable; Pending: 3 Unschedulable" (22/23 resolved)
2026/05/06 16:11:29 Failure: pod=cspod-34 reason="pod group is not ready, 4 Pending, 4 minAvailable; Pending: 4 Unschedulable" (23/23 resolved)
2026/05/06 16:11:29 Round complete: 3 scheduled, 20 failed in 996.04529ms
2026/05/06 16:11:29 {"action":"HandleSchedule","durationMs":997,"podCount":23,"result":"ok","roundId":"20","scheduled":3,"ts":"2026-05-06T16:11:29.082942561+01:00","unschedulable":20}
2026/05/06 16:11:29 {"action":"HandleSchedule","completedIds":1,"nodeCount":5,"phase":"start","podCount":20,"roundId":"21","ts":"2026-05-06T16:11:29.088315623+01:00"}
2026/05/06 16:11:29 {"action":"HandleSchedule","phase":"prep_done","podsCreated":20,"prepMs":0,"roundId":"21","staleDeleted":0,"ts":"2026-05-06T16:11:29.088600919+01:00"}
2026/05/06 16:11:29 Scheduling round started: expecting 20 decisions
2026/05/06 16:11:30 Failure: pod=cspod-67 reason="pod group is not ready, 1 Pending, 1 minAvailable; Pending: 1 Unschedulable" (1/20 resolved)
2026/05/06 16:11:30 Failure: pod=cspod-53 reason="pod group is not ready, 3 Pending, 3 minAvailable; Pending: 1 Schedulable, 2 Unschedulable" (2/20 resolved)
2026/05/06 16:11:30 Failure: pod=cspod-66 reason="pod group is not ready, 1 Pending, 1 minAvailable; Pending: 1 Unschedulable" (3/20 resolved)
2026/05/06 16:11:30 Failure: pod=cspod-61 reason="pod group is not ready, 1 Pending, 1 minAvailable; Pending: 1 Unschedulable" (4/20 resolved)
2026/05/06 16:11:30 Failure: pod=cspod-36 reason="pod group is not ready, 4 Pending, 4 minAvailable; Pending: 4 Unschedulable" (5/20 resolved)
2026/05/06 16:11:30 Failure: pod=cspod-27 reason="pod group is not ready, 1 Pending, 1 minAvailable; Pending: 1 Unschedulable" (6/20 resolved)
2026/05/06 16:11:30 Failure: pod=cspod-33 reason="pod group is not ready, 4 Pending, 4 minAvailable; Pending: 4 Unschedulable" (7/20 resolved)
2026/05/06 16:11:30 Failure: pod=cspod-29 reason="pod group is not ready, 1 Pending, 1 minAvailable; Pending: 1 Unschedulable" (8/20 resolved)
2026/05/06 16:11:30 Failure: pod=cspod-60 reason="pod group is not ready, 1 Pending, 1 minAvailable; Pending: 1 Unschedulable" (9/20 resolved)
2026/05/06 16:11:30 Failure: pod=cspod-68 reason="pod group is not ready, 1 Pending, 1 minAvailable; Pending: 1 Unschedulable" (10/20 resolved)
2026/05/06 16:11:30 Failure: pod=cspod-63 reason="pod group is not ready, 1 Pending, 1 minAvailable; Pending: 1 Unschedulable" (11/20 resolved)
2026/05/06 16:11:30 Failure: pod=cspod-62 reason="pod group is not ready, 1 Pending, 1 minAvailable; Pending: 1 Unschedulable" (12/20 resolved)
2026/05/06 16:11:30 Failure: pod=cspod-64 reason="pod group is not ready, 1 Pending, 1 minAvailable; Pending: 1 Unschedulable" (13/20 resolved)
2026/05/06 16:11:30 Failure: pod=cspod-28 reason="pod group is not ready, 1 Pending, 1 minAvailable; Pending: 1 Unschedulable" (14/20 resolved)
2026/05/06 16:11:30 Failure: pod=cspod-65 reason="pod group is not ready, 1 Pending, 1 minAvailable; Pending: 1 Unschedulable" (15/20 resolved)
2026/05/06 16:11:30 Failure: pod=cspod-69 reason="pod group is not ready, 1 Pending, 1 minAvailable; Pending: 1 Unschedulable" (16/20 resolved)
2026/05/06 16:11:30 Failure: pod=cspod-54 reason="pod group is not ready, 3 Pending, 3 minAvailable; Pending: 1 Schedulable, 2 Unschedulable" (17/20 resolved)
2026/05/06 16:11:30 Failure: pod=cspod-34 reason="pod group is not ready, 4 Pending, 4 minAvailable; Pending: 4 Unschedulable" (18/20 resolved)
2026/05/06 16:11:30 Failure: pod=cspod-35 reason="pod group is not ready, 4 Pending, 4 minAvailable; Pending: 4 Unschedulable" (19/20 resolved)
2026/05/06 16:11:33 STALL EXIT: no progress for 2s — 0 scheduled, 19 failed, 1 still pending (returning partial)
2026/05/06 16:11:33 {"action":"HandleSchedule","durationMs":4013,"podCount":20,"result":"timeout_partial","roundId":"21","scheduled":0,"ts":"2026-05-06T16:11:33.102110011+01:00","unschedulable":20}
2026/05/06 16:11:33 {"action":"HandleSchedule","durationMs":4013,"podCount":20,"result":"ok","roundId":"21","scheduled":0,"ts":"2026-05-06T16:11:33.102136087+01:00","unschedulable":20}
2026/05/06 16:11:33 {"action":"HandleSchedule","completedIds":1,"nodeCount":5,"phase":"start","podCount":20,"roundId":"22","ts":"2026-05-06T16:11:33.107734692+01:00"}
2026/05/06 16:11:33 {"action":"HandleSchedule","phase":"prep_done","podsCreated":20,"prepMs":0,"roundId":"22","staleDeleted":0,"ts":"2026-05-06T16:11:33.108212835+01:00"}
2026/05/06 16:11:33 Scheduling round started: expecting 20 decisions
2026/05/06 16:11:34 Failure: pod=cspod-63 reason="pod group is not ready, 1 Pending, 1 minAvailable; Pending: 1 Unschedulable" (1/20 resolved)
2026/05/06 16:11:34 Failure: pod=cspod-66 reason="pod group is not ready, 1 Pending, 1 minAvailable; Pending: 1 Unschedulable" (2/20 resolved)
2026/05/06 16:11:34 Failure: pod=cspod-69 reason="pod group is not ready, 1 Pending, 1 minAvailable; Pending: 1 Unschedulable" (3/20 resolved)
2026/05/06 16:11:34 Failure: pod=cspod-67 reason="pod group is not ready, 1 Pending, 1 minAvailable; Pending: 1 Unschedulable" (4/20 resolved)
2026/05/06 16:11:34 Failure: pod=cspod-61 reason="pod group is not ready, 1 Pending, 1 minAvailable; Pending: 1 Unschedulable" (5/20 resolved)
2026/05/06 16:11:34 Failure: pod=cspod-64 reason="pod group is not ready, 1 Pending, 1 minAvailable; Pending: 1 Unschedulable" (6/20 resolved)
2026/05/06 16:11:34 Failure: pod=cspod-60 reason="pod group is not ready, 1 Pending, 1 minAvailable; Pending: 1 Unschedulable" (7/20 resolved)
2026/05/06 16:11:34 Failure: pod=cspod-62 reason="pod group is not ready, 1 Pending, 1 minAvailable; Pending: 1 Unschedulable" (8/20 resolved)
2026/05/06 16:11:34 Failure: pod=cspod-28 reason="pod group is not ready, 1 Pending, 1 minAvailable; Pending: 1 Unschedulable" (9/20 resolved)
2026/05/06 16:11:34 Failure: pod=cspod-33 reason="pod group is not ready, 4 Pending, 4 minAvailable; Pending: 4 Unschedulable" (10/20 resolved)
2026/05/06 16:11:34 Failure: pod=cspod-68 reason="pod group is not ready, 1 Pending, 1 minAvailable; Pending: 1 Unschedulable" (11/20 resolved)
2026/05/06 16:11:34 Failure: pod=cspod-29 reason="pod group is not ready, 1 Pending, 1 minAvailable; Pending: 1 Unschedulable" (12/20 resolved)
2026/05/06 16:11:34 Failure: pod=cspod-65 reason="pod group is not ready, 1 Pending, 1 minAvailable; Pending: 1 Unschedulable" (13/20 resolved)
2026/05/06 16:11:34 Failure: pod=cspod-53 reason="pod group is not ready, 3 Pending, 3 minAvailable; Pending: 1 Schedulable, 2 Unschedulable" (14/20 resolved)
2026/05/06 16:11:34 Failure: pod=cspod-34 reason="pod group is not ready, 4 Pending, 4 minAvailable; Pending: 4 Unschedulable" (15/20 resolved)
2026/05/06 16:11:34 Failure: pod=cspod-54 reason="pod group is not ready, 3 Pending, 3 minAvailable; Pending: 1 Schedulable, 2 Unschedulable" (16/20 resolved)
2026/05/06 16:11:34 Failure: pod=cspod-35 reason="pod group is not ready, 4 Pending, 4 minAvailable; Pending: 4 Unschedulable" (17/20 resolved)
2026/05/06 16:11:34 Failure: pod=cspod-36 reason="pod group is not ready, 4 Pending, 4 minAvailable; Pending: 4 Unschedulable" (18/20 resolved)
2026/05/06 16:11:34 Binding: pod=cspod-27 -> node=csnode-4 (19/20 resolved)
2026/05/06 16:11:37 STALL EXIT: no progress for 2s — 1 scheduled, 18 failed, 1 still pending (returning partial)
2026/05/06 16:11:37 {"action":"HandleSchedule","durationMs":4010,"podCount":20,"result":"timeout_partial","roundId":"22","scheduled":1,"ts":"2026-05-06T16:11:37.117786636+01:00","unschedulable":19}
2026/05/06 16:11:37 {"action":"HandleSchedule","durationMs":4010,"podCount":20,"result":"ok","roundId":"22","scheduled":1,"ts":"2026-05-06T16:11:37.117811993+01:00","unschedulable":19}
2026/05/06 16:11:37 {"action":"HandleSchedule","completedIds":2,"nodeCount":5,"phase":"start","podCount":19,"roundId":"23","ts":"2026-05-06T16:11:37.123029349+01:00"}
2026/05/06 16:11:37 {"action":"HandleSchedule","phase":"prep_done","podsCreated":19,"prepMs":0,"roundId":"23","staleDeleted":0,"ts":"2026-05-06T16:11:37.12336045+01:00"}
2026/05/06 16:11:37 Scheduling round started: expecting 19 decisions
2026/05/06 16:11:38 Failure: pod=cspod-29 reason="pod group is not ready, 1 Pending, 1 minAvailable; Pending: 1 Unschedulable" (1/19 resolved)
2026/05/06 16:11:38 Failure: pod=cspod-62 reason="pod group is not ready, 1 Pending, 1 minAvailable; Pending: 1 Unschedulable" (2/19 resolved)
2026/05/06 16:11:38 Failure: pod=cspod-65 reason="pod group is not ready, 1 Pending, 1 minAvailable; Pending: 1 Unschedulable" (3/19 resolved)
2026/05/06 16:11:38 Failure: pod=cspod-69 reason="pod group is not ready, 1 Pending, 1 minAvailable; Pending: 1 Unschedulable" (4/19 resolved)
2026/05/06 16:11:38 Failure: pod=cspod-28 reason="pod group is not ready, 1 Pending, 1 minAvailable; Pending: 1 Unschedulable" (5/19 resolved)
2026/05/06 16:11:38 Failure: pod=cspod-68 reason="pod group is not ready, 1 Pending, 1 minAvailable; Pending: 1 Unschedulable" (6/19 resolved)
2026/05/06 16:11:38 Failure: pod=cspod-67 reason="pod group is not ready, 1 Pending, 1 minAvailable; Pending: 1 Unschedulable" (7/19 resolved)
2026/05/06 16:11:38 Failure: pod=cspod-60 reason="pod group is not ready, 1 Pending, 1 minAvailable; Pending: 1 Unschedulable" (8/19 resolved)
2026/05/06 16:11:38 Failure: pod=cspod-33 reason="pod group is not ready, 4 Pending, 4 minAvailable; Pending: 4 Unschedulable" (9/19 resolved)
2026/05/06 16:11:38 Failure: pod=cspod-61 reason="pod group is not ready, 1 Pending, 1 minAvailable; Pending: 1 Unschedulable" (10/19 resolved)
2026/05/06 16:11:38 Failure: pod=cspod-64 reason="pod group is not ready, 1 Pending, 1 minAvailable; Pending: 1 Unschedulable" (11/19 resolved)
2026/05/06 16:11:38 Failure: pod=cspod-63 reason="pod group is not ready, 1 Pending, 1 minAvailable; Pending: 1 Unschedulable" (12/19 resolved)
2026/05/06 16:11:38 Failure: pod=cspod-66 reason="pod group is not ready, 1 Pending, 1 minAvailable; Pending: 1 Unschedulable" (13/19 resolved)
2026/05/06 16:11:38 Failure: pod=cspod-34 reason="pod group is not ready, 4 Pending, 4 minAvailable; Pending: 4 Unschedulable" (14/19 resolved)
2026/05/06 16:11:38 Failure: pod=cspod-35 reason="pod group is not ready, 4 Pending, 4 minAvailable; Pending: 4 Unschedulable" (15/19 resolved)
2026/05/06 16:11:38 Failure: pod=cspod-36 reason="pod group is not ready, 4 Pending, 4 minAvailable; Pending: 4 Unschedulable" (16/19 resolved)
2026/05/06 16:11:38 Binding: pod=cspod-52 -> node=csnode-0 (17/19 resolved)
2026/05/06 16:11:38 Binding: pod=cspod-53 -> node=csnode-4 (18/19 resolved)
2026/05/06 16:11:38 Binding: pod=cspod-54 -> node=csnode-4 (19/19 resolved)
2026/05/06 16:11:38 Round complete: 3 scheduled, 16 failed in 1.003566332s
2026/05/06 16:11:38 {"action":"HandleSchedule","durationMs":1004,"podCount":19,"result":"ok","roundId":"23","scheduled":3,"ts":"2026-05-06T16:11:38.127012931+01:00","unschedulable":16}
2026/05/06 16:11:38 {"action":"HandleSchedule","completedIds":1,"nodeCount":5,"phase":"start","podCount":16,"roundId":"24","ts":"2026-05-06T16:11:38.131901919+01:00"}
2026/05/06 16:11:38 {"action":"HandleSchedule","phase":"prep_done","podsCreated":16,"prepMs":0,"roundId":"24","staleDeleted":0,"ts":"2026-05-06T16:11:38.13217055+01:00"}
2026/05/06 16:11:38 Scheduling round started: expecting 16 decisions
2026/05/06 16:11:39 Binding: pod=cspod-28 -> node=csnode-4 (1/16 resolved)
2026/05/06 16:11:39 Failure: pod=cspod-69 reason="pod group is not ready, 1 Pending, 1 minAvailable; Pending: 1 Unschedulable" (2/16 resolved)
2026/05/06 16:11:39 Failure: pod=cspod-65 reason="pod group is not ready, 1 Pending, 1 minAvailable; Pending: 1 Unschedulable" (3/16 resolved)
2026/05/06 16:11:39 Failure: pod=cspod-68 reason="pod group is not ready, 1 Pending, 1 minAvailable; Pending: 1 Unschedulable" (4/16 resolved)
2026/05/06 16:11:39 Failure: pod=cspod-64 reason="pod group is not ready, 1 Pending, 1 minAvailable; Pending: 1 Unschedulable" (5/16 resolved)
2026/05/06 16:11:39 Failure: pod=cspod-67 reason="pod group is not ready, 1 Pending, 1 minAvailable; Pending: 1 Unschedulable" (6/16 resolved)
2026/05/06 16:11:39 Failure: pod=cspod-33 reason="pod group is not ready, 4 Pending, 4 minAvailable; Pending: 4 Unschedulable" (7/16 resolved)
2026/05/06 16:11:39 Failure: pod=cspod-29 reason="pod group is not ready, 1 Pending, 1 minAvailable; Pending: 1 Unschedulable" (8/16 resolved)
2026/05/06 16:11:39 Failure: pod=cspod-61 reason="pod group is not ready, 1 Pending, 1 minAvailable; Pending: 1 Unschedulable" (9/16 resolved)
2026/05/06 16:11:39 Failure: pod=cspod-63 reason="pod group is not ready, 1 Pending, 1 minAvailable; Pending: 1 Unschedulable" (10/16 resolved)
2026/05/06 16:11:39 Failure: pod=cspod-66 reason="pod group is not ready, 1 Pending, 1 minAvailable; Pending: 1 Unschedulable" (11/16 resolved)
2026/05/06 16:11:39 Failure: pod=cspod-62 reason="pod group is not ready, 1 Pending, 1 minAvailable; Pending: 1 Unschedulable" (12/16 resolved)
2026/05/06 16:11:39 Failure: pod=cspod-60 reason="pod group is not ready, 1 Pending, 1 minAvailable; Pending: 1 Unschedulable" (13/16 resolved)
2026/05/06 16:11:39 Failure: pod=cspod-34 reason="pod group is not ready, 4 Pending, 4 minAvailable; Pending: 4 Unschedulable" (14/16 resolved)
2026/05/06 16:11:39 Failure: pod=cspod-35 reason="pod group is not ready, 4 Pending, 4 minAvailable; Pending: 4 Unschedulable" (15/16 resolved)
2026/05/06 16:11:39 Failure: pod=cspod-36 reason="pod group is not ready, 4 Pending, 4 minAvailable; Pending: 4 Unschedulable" (16/16 resolved)
2026/05/06 16:11:39 Round complete: 1 scheduled, 15 failed in 989.963225ms
2026/05/06 16:11:39 {"action":"HandleSchedule","durationMs":990,"podCount":16,"result":"ok","roundId":"24","scheduled":1,"ts":"2026-05-06T16:11:39.122252351+01:00","unschedulable":15}
2026/05/06 16:11:39 {"action":"HandleSchedule","completedIds":2,"nodeCount":5,"phase":"start","podCount":15,"roundId":"25","ts":"2026-05-06T16:11:39.127714511+01:00"}
2026/05/06 16:11:39 {"action":"HandleSchedule","phase":"prep_done","podsCreated":15,"prepMs":0,"roundId":"25","staleDeleted":0,"ts":"2026-05-06T16:11:39.127970405+01:00"}
2026/05/06 16:11:39 Scheduling round started: expecting 15 decisions
2026/05/06 16:11:40 Failure: pod=cspod-65 reason="pod group is not ready, 1 Pending, 1 minAvailable; Pending: 1 Unschedulable" (1/15 resolved)
2026/05/06 16:11:40 Failure: pod=cspod-67 reason="pod group is not ready, 1 Pending, 1 minAvailable; Pending: 1 Unschedulable" (2/15 resolved)
2026/05/06 16:11:40 Failure: pod=cspod-33 reason="pod group is not ready, 4 Pending, 4 minAvailable; Pending: 4 Unschedulable" (3/15 resolved)
2026/05/06 16:11:40 Failure: pod=cspod-69 reason="pod group is not ready, 1 Pending, 1 minAvailable; Pending: 1 Unschedulable" (4/15 resolved)
2026/05/06 16:11:40 Failure: pod=cspod-62 reason="pod group is not ready, 1 Pending, 1 minAvailable; Pending: 1 Unschedulable" (5/15 resolved)
2026/05/06 16:11:40 Failure: pod=cspod-61 reason="pod group is not ready, 1 Pending, 1 minAvailable; Pending: 1 Unschedulable" (6/15 resolved)
2026/05/06 16:11:40 Failure: pod=cspod-64 reason="pod group is not ready, 1 Pending, 1 minAvailable; Pending: 1 Unschedulable" (7/15 resolved)
2026/05/06 16:11:40 Failure: pod=cspod-63 reason="pod group is not ready, 1 Pending, 1 minAvailable; Pending: 1 Unschedulable" (8/15 resolved)
2026/05/06 16:11:40 Failure: pod=cspod-34 reason="pod group is not ready, 4 Pending, 4 minAvailable; Pending: 4 Unschedulable" (9/15 resolved)
2026/05/06 16:11:40 Failure: pod=cspod-68 reason="pod group is not ready, 1 Pending, 1 minAvailable; Pending: 1 Unschedulable" (10/15 resolved)
2026/05/06 16:11:40 Failure: pod=cspod-66 reason="pod group is not ready, 1 Pending, 1 minAvailable; Pending: 1 Unschedulable" (11/15 resolved)
2026/05/06 16:11:40 Failure: pod=cspod-35 reason="pod group is not ready, 4 Pending, 4 minAvailable; Pending: 4 Unschedulable" (12/15 resolved)
2026/05/06 16:11:40 Failure: pod=cspod-36 reason="pod group is not ready, 4 Pending, 4 minAvailable; Pending: 4 Unschedulable" (13/15 resolved)
2026/05/06 16:11:40 Binding: pod=cspod-29 -> node=csnode-3 (14/15 resolved)
2026/05/06 16:11:40 Binding: pod=cspod-60 -> node=csnode-2 (15/15 resolved)
2026/05/06 16:11:40 Round complete: 2 scheduled, 13 failed in 1.004676776s
2026/05/06 16:11:40 {"action":"HandleSchedule","durationMs":1005,"podCount":15,"result":"ok","roundId":"25","scheduled":2,"ts":"2026-05-06T16:11:40.132700565+01:00","unschedulable":13}
2026/05/06 16:11:40 {"action":"HandleSchedule","completedIds":1,"nodeCount":5,"phase":"start","podCount":13,"roundId":"26","ts":"2026-05-06T16:11:40.137960575+01:00"}
2026/05/06 16:11:40 {"action":"HandleSchedule","phase":"prep_done","podsCreated":13,"prepMs":0,"roundId":"26","staleDeleted":0,"ts":"2026-05-06T16:11:40.138215393+01:00"}
2026/05/06 16:11:40 Scheduling round started: expecting 13 decisions
2026/05/06 16:11:41 Failure: pod=cspod-62 reason="pod group is not ready, 1 Pending, 1 minAvailable; Pending: 1 Unschedulable" (1/13 resolved)
2026/05/06 16:11:41 Failure: pod=cspod-67 reason="pod group is not ready, 1 Pending, 1 minAvailable; Pending: 1 Unschedulable" (2/13 resolved)
2026/05/06 16:11:41 Failure: pod=cspod-66 reason="pod group is not ready, 1 Pending, 1 minAvailable; Pending: 1 Unschedulable" (3/13 resolved)
2026/05/06 16:11:41 Failure: pod=cspod-69 reason="pod group is not ready, 1 Pending, 1 minAvailable; Pending: 1 Unschedulable" (4/13 resolved)
2026/05/06 16:11:41 Failure: pod=cspod-33 reason="pod group is not ready, 4 Pending, 4 minAvailable; Pending: 4 Unschedulable" (5/13 resolved)
2026/05/06 16:11:41 Failure: pod=cspod-64 reason="pod group is not ready, 1 Pending, 1 minAvailable; Pending: 1 Unschedulable" (6/13 resolved)
2026/05/06 16:11:41 Failure: pod=cspod-63 reason="pod group is not ready, 1 Pending, 1 minAvailable; Pending: 1 Unschedulable" (7/13 resolved)
2026/05/06 16:11:41 Failure: pod=cspod-68 reason="pod group is not ready, 1 Pending, 1 minAvailable; Pending: 1 Unschedulable" (8/13 resolved)
2026/05/06 16:11:41 Failure: pod=cspod-65 reason="pod group is not ready, 1 Pending, 1 minAvailable; Pending: 1 Unschedulable" (9/13 resolved)
2026/05/06 16:11:41 Failure: pod=cspod-34 reason="pod group is not ready, 4 Pending, 4 minAvailable; Pending: 4 Unschedulable" (10/13 resolved)
2026/05/06 16:11:41 Failure: pod=cspod-35 reason="pod group is not ready, 4 Pending, 4 minAvailable; Pending: 4 Unschedulable" (11/13 resolved)
2026/05/06 16:11:41 Binding: pod=cspod-61 -> node=csnode-1 (12/13 resolved)
2026/05/06 16:11:41 Failure: pod=cspod-36 reason="pod group is not ready, 4 Pending, 4 minAvailable; Pending: 4 Unschedulable" (13/13 resolved)
2026/05/06 16:11:41 Round complete: 1 scheduled, 12 failed in 995.302819ms
2026/05/06 16:11:41 {"action":"HandleSchedule","durationMs":995,"podCount":13,"result":"ok","roundId":"26","scheduled":1,"ts":"2026-05-06T16:11:41.133572155+01:00","unschedulable":12}
2026/05/06 16:11:41 {"action":"HandleSchedule","completedIds":1,"nodeCount":5,"phase":"start","podCount":12,"roundId":"27","ts":"2026-05-06T16:11:41.144894636+01:00"}
2026/05/06 16:11:41 {"action":"HandleSchedule","phase":"prep_done","podsCreated":12,"prepMs":0,"roundId":"27","staleDeleted":0,"ts":"2026-05-06T16:11:41.14515491+01:00"}
2026/05/06 16:11:41 Scheduling round started: expecting 12 decisions
2026/05/06 16:11:42 Failure: pod=cspod-67 reason="pod group is not ready, 1 Pending, 1 minAvailable; Pending: 1 Unschedulable" (1/12 resolved)
2026/05/06 16:11:42 Failure: pod=cspod-66 reason="pod group is not ready, 1 Pending, 1 minAvailable; Pending: 1 Unschedulable" (2/12 resolved)
2026/05/06 16:11:42 Failure: pod=cspod-65 reason="pod group is not ready, 1 Pending, 1 minAvailable; Pending: 1 Unschedulable" (3/12 resolved)
2026/05/06 16:11:42 Failure: pod=cspod-68 reason="pod group is not ready, 1 Pending, 1 minAvailable; Pending: 1 Unschedulable" (4/12 resolved)
2026/05/06 16:11:42 Failure: pod=cspod-69 reason="pod group is not ready, 1 Pending, 1 minAvailable; Pending: 1 Unschedulable" (5/12 resolved)
2026/05/06 16:11:42 Failure: pod=cspod-35 reason="pod group is not ready, 4 Pending, 4 minAvailable; Pending: 4 Unschedulable" (6/12 resolved)
2026/05/06 16:11:42 Failure: pod=cspod-63 reason="pod group is not ready, 1 Pending, 1 minAvailable; Pending: 1 Unschedulable" (7/12 resolved)
2026/05/06 16:11:42 Failure: pod=cspod-64 reason="pod group is not ready, 1 Pending, 1 minAvailable; Pending: 1 Unschedulable" (8/12 resolved)
2026/05/06 16:11:42 Failure: pod=cspod-36 reason="pod group is not ready, 4 Pending, 4 minAvailable; Pending: 4 Unschedulable" (9/12 resolved)
2026/05/06 16:11:42 Failure: pod=cspod-33 reason="pod group is not ready, 4 Pending, 4 minAvailable; Pending: 4 Unschedulable" (10/12 resolved)
2026/05/06 16:11:42 Failure: pod=cspod-34 reason="pod group is not ready, 4 Pending, 4 minAvailable; Pending: 4 Unschedulable" (11/12 resolved)
2026/05/06 16:11:42 Binding: pod=cspod-62 -> node=csnode-3 (12/12 resolved)
2026/05/06 16:11:42 Round complete: 1 scheduled, 11 failed in 998.262422ms
2026/05/06 16:11:42 {"action":"HandleSchedule","durationMs":998,"podCount":12,"result":"ok","roundId":"27","scheduled":1,"ts":"2026-05-06T16:11:42.143494754+01:00","unschedulable":11}
2026/05/06 16:11:42 {"action":"HandleSchedule","completedIds":2,"nodeCount":5,"phase":"start","podCount":11,"roundId":"28","ts":"2026-05-06T16:11:42.150831982+01:00"}
2026/05/06 16:11:42 {"action":"HandleSchedule","phase":"prep_done","podsCreated":11,"prepMs":0,"roundId":"28","staleDeleted":0,"ts":"2026-05-06T16:11:42.151039715+01:00"}
2026/05/06 16:11:42 Scheduling round started: expecting 11 decisions
2026/05/06 16:11:41 Failure: pod=cspod-66 reason="pod group is not ready, 1 Pending, 1 minAvailable; Pending: 1 Unschedulable" (1/11 resolved)
2026/05/06 16:11:41 Failure: pod=cspod-36 reason="pod group is not ready, 4 Pending, 4 minAvailable; Pending: 4 Unschedulable" (2/11 resolved)
2026/05/06 16:11:41 Failure: pod=cspod-69 reason="pod group is not ready, 1 Pending, 1 minAvailable; Pending: 1 Unschedulable" (3/11 resolved)
2026/05/06 16:11:41 Failure: pod=cspod-68 reason="pod group is not ready, 1 Pending, 1 minAvailable; Pending: 1 Unschedulable" (4/11 resolved)
2026/05/06 16:11:41 Failure: pod=cspod-65 reason="pod group is not ready, 1 Pending, 1 minAvailable; Pending: 1 Unschedulable" (5/11 resolved)
2026/05/06 16:11:41 Failure: pod=cspod-67 reason="pod group is not ready, 1 Pending, 1 minAvailable; Pending: 1 Unschedulable" (6/11 resolved)
2026/05/06 16:11:41 Failure: pod=cspod-33 reason="pod group is not ready, 4 Pending, 4 minAvailable; Pending: 4 Unschedulable" (7/11 resolved)
2026/05/06 16:11:41 Failure: pod=cspod-34 reason="pod group is not ready, 4 Pending, 4 minAvailable; Pending: 4 Unschedulable" (8/11 resolved)
2026/05/06 16:11:41 Failure: pod=cspod-35 reason="pod group is not ready, 4 Pending, 4 minAvailable; Pending: 4 Unschedulable" (9/11 resolved)
2026/05/06 16:11:41 Binding: pod=cspod-63 -> node=csnode-4 (10/11 resolved)
2026/05/06 16:11:41 Binding: pod=cspod-64 -> node=csnode-4 (11/11 resolved)
2026/05/06 16:11:41 Round complete: 2 scheduled, 9 failed in 1.006542835s
2026/05/06 16:11:41 {"action":"HandleSchedule","durationMs":1007,"podCount":11,"result":"ok","roundId":"28","scheduled":2,"ts":"2026-05-06T16:11:41.538304762+01:00","unschedulable":9}
2026/05/06 16:11:41 {"action":"HandleSchedule","completedIds":1,"nodeCount":5,"phase":"start","podCount":9,"roundId":"29","ts":"2026-05-06T16:11:41.544691386+01:00"}
2026/05/06 16:11:41 {"action":"HandleSchedule","phase":"prep_done","podsCreated":9,"prepMs":0,"roundId":"29","staleDeleted":0,"ts":"2026-05-06T16:11:41.544900039+01:00"}
2026/05/06 16:11:41 Scheduling round started: expecting 9 decisions
2026/05/06 16:11:42 Failure: pod=cspod-66 reason="pod group is not ready, 1 Pending, 1 minAvailable; Pending: 1 Unschedulable" (1/9 resolved)
2026/05/06 16:11:42 Failure: pod=cspod-35 reason="pod group is not ready, 4 Pending, 4 minAvailable; Pending: 4 Unschedulable" (2/9 resolved)
2026/05/06 16:11:42 Failure: pod=cspod-69 reason="pod group is not ready, 1 Pending, 1 minAvailable; Pending: 1 Unschedulable" (3/9 resolved)
2026/05/06 16:11:42 Failure: pod=cspod-67 reason="pod group is not ready, 1 Pending, 1 minAvailable; Pending: 1 Unschedulable" (4/9 resolved)
2026/05/06 16:11:42 Failure: pod=cspod-68 reason="pod group is not ready, 1 Pending, 1 minAvailable; Pending: 1 Unschedulable" (5/9 resolved)
2026/05/06 16:11:42 Failure: pod=cspod-36 reason="pod group is not ready, 4 Pending, 4 minAvailable; Pending: 4 Unschedulable" (6/9 resolved)
2026/05/06 16:11:42 Failure: pod=cspod-33 reason="pod group is not ready, 4 Pending, 4 minAvailable; Pending: 4 Unschedulable" (7/9 resolved)
2026/05/06 16:11:42 Failure: pod=cspod-34 reason="pod group is not ready, 4 Pending, 4 minAvailable; Pending: 4 Unschedulable" (8/9 resolved)
2026/05/06 16:11:42 Binding: pod=cspod-65 -> node=csnode-4 (9/9 resolved)
2026/05/06 16:11:42 Round complete: 1 scheduled, 8 failed in 983.515242ms
2026/05/06 16:11:42 {"action":"HandleSchedule","durationMs":983,"podCount":9,"result":"ok","roundId":"29","scheduled":1,"ts":"2026-05-06T16:11:42.528466347+01:00","unschedulable":8}
2026/05/06 16:11:42 {"action":"HandleSchedule","completedIds":1,"nodeCount":5,"phase":"start","podCount":8,"roundId":"30","ts":"2026-05-06T16:11:42.532936848+01:00"}
2026/05/06 16:11:42 {"action":"HandleSchedule","phase":"prep_done","podsCreated":8,"prepMs":29,"roundId":"30","staleDeleted":0,"ts":"2026-05-06T16:11:42.562184615+01:00"}
2026/05/06 16:11:42 Scheduling round started: expecting 8 decisions
2026/05/06 16:11:43 Failure: pod=cspod-35 reason="pod group is not ready, 4 Pending, 4 minAvailable; Pending: 4 Unschedulable" (1/8 resolved)
2026/05/06 16:11:43 Failure: pod=cspod-67 reason="pod group is not ready, 1 Pending, 1 minAvailable; Pending: 1 Unschedulable" (2/8 resolved)
2026/05/06 16:11:43 Failure: pod=cspod-68 reason="pod group is not ready, 1 Pending, 1 minAvailable; Pending: 1 Unschedulable" (3/8 resolved)
2026/05/06 16:11:43 Failure: pod=cspod-69 reason="pod group is not ready, 1 Pending, 1 minAvailable; Pending: 1 Unschedulable" (4/8 resolved)
2026/05/06 16:11:43 Failure: pod=cspod-36 reason="pod group is not ready, 4 Pending, 4 minAvailable; Pending: 4 Unschedulable" (5/8 resolved)
2026/05/06 16:11:43 Failure: pod=cspod-33 reason="pod group is not ready, 4 Pending, 4 minAvailable; Pending: 4 Unschedulable" (6/8 resolved)
2026/05/06 16:11:43 Failure: pod=cspod-34 reason="pod group is not ready, 4 Pending, 4 minAvailable; Pending: 4 Unschedulable" (7/8 resolved)
2026/05/06 16:11:43 Binding: pod=cspod-66 -> node=csnode-4 (8/8 resolved)
2026/05/06 16:11:43 Round complete: 1 scheduled, 7 failed in 982.310435ms
2026/05/06 16:11:43 {"action":"HandleSchedule","durationMs":1011,"podCount":8,"result":"ok","roundId":"30","scheduled":1,"ts":"2026-05-06T16:11:43.544637326+01:00","unschedulable":7}
2026/05/06 16:11:43 {"action":"HandleSchedule","completedIds":1,"nodeCount":5,"phase":"start","podCount":7,"roundId":"31","ts":"2026-05-06T16:11:43.549132384+01:00"}
2026/05/06 16:11:43 {"action":"HandleSchedule","phase":"prep_done","podsCreated":7,"prepMs":0,"roundId":"31","staleDeleted":0,"ts":"2026-05-06T16:11:43.549338021+01:00"}
2026/05/06 16:11:43 Scheduling round started: expecting 7 decisions
2026/05/06 16:11:44 Failure: pod=cspod-36 reason="pod group is not ready, 4 Pending, 4 minAvailable; Pending: 4 Unschedulable" (1/7 resolved)
2026/05/06 16:11:44 Failure: pod=cspod-69 reason="pod group is not ready, 1 Pending, 1 minAvailable; Pending: 1 Unschedulable" (2/7 resolved)
2026/05/06 16:11:44 Failure: pod=cspod-68 reason="pod group is not ready, 1 Pending, 1 minAvailable; Pending: 1 Unschedulable" (3/7 resolved)
2026/05/06 16:11:44 Failure: pod=cspod-33 reason="pod group is not ready, 4 Pending, 4 minAvailable; Pending: 4 Unschedulable" (4/7 resolved)
2026/05/06 16:11:44 Failure: pod=cspod-34 reason="pod group is not ready, 4 Pending, 4 minAvailable; Pending: 4 Unschedulable" (5/7 resolved)
2026/05/06 16:11:44 Failure: pod=cspod-35 reason="pod group is not ready, 4 Pending, 4 minAvailable; Pending: 4 Unschedulable" (6/7 resolved)
2026/05/06 16:11:44 Binding: pod=cspod-67 -> node=csnode-2 (7/7 resolved)
2026/05/06 16:11:44 Round complete: 1 scheduled, 6 failed in 990.759747ms
2026/05/06 16:11:44 {"action":"HandleSchedule","durationMs":991,"podCount":7,"result":"ok","roundId":"31","scheduled":1,"ts":"2026-05-06T16:11:44.540175048+01:00","unschedulable":6}
2026/05/06 16:11:44 {"action":"HandleSchedule","completedIds":1,"nodeCount":5,"phase":"start","podCount":6,"roundId":"32","ts":"2026-05-06T16:11:44.545435186+01:00"}
2026/05/06 16:11:44 {"action":"HandleSchedule","phase":"prep_done","podsCreated":6,"prepMs":0,"roundId":"32","staleDeleted":0,"ts":"2026-05-06T16:11:44.546297479+01:00"}
2026/05/06 16:11:44 Scheduling round started: expecting 6 decisions
2026/05/06 16:11:45 Failure: pod=cspod-35 reason="pod group is not ready, 4 Pending, 4 minAvailable; Pending: 4 Unschedulable" (1/6 resolved)
2026/05/06 16:11:45 Failure: pod=cspod-69 reason="pod group is not ready, 1 Pending, 1 minAvailable; Pending: 1 Unschedulable" (2/6 resolved)
2026/05/06 16:11:45 Failure: pod=cspod-36 reason="pod group is not ready, 4 Pending, 4 minAvailable; Pending: 4 Unschedulable" (3/6 resolved)
2026/05/06 16:11:45 Failure: pod=cspod-33 reason="pod group is not ready, 4 Pending, 4 minAvailable; Pending: 4 Unschedulable" (4/6 resolved)
2026/05/06 16:11:45 Failure: pod=cspod-34 reason="pod group is not ready, 4 Pending, 4 minAvailable; Pending: 4 Unschedulable" (5/6 resolved)
2026/05/06 16:11:45 Binding: pod=cspod-68 -> node=csnode-0 (6/6 resolved)
2026/05/06 16:11:45 Round complete: 1 scheduled, 5 failed in 1.012243446s
2026/05/06 16:11:45 {"action":"HandleSchedule","durationMs":1013,"podCount":6,"result":"ok","roundId":"32","scheduled":1,"ts":"2026-05-06T16:11:45.55865511+01:00","unschedulable":5}
2026/05/06 16:11:45 {"action":"HandleSchedule","completedIds":1,"nodeCount":5,"phase":"start","podCount":5,"roundId":"33","ts":"2026-05-06T16:11:45.563506711+01:00"}
2026/05/06 16:11:45 {"action":"HandleSchedule","phase":"prep_done","podsCreated":5,"prepMs":0,"roundId":"33","staleDeleted":0,"ts":"2026-05-06T16:11:45.563658434+01:00"}
2026/05/06 16:11:45 Scheduling round started: expecting 5 decisions
2026/05/06 16:11:46 Failure: pod=cspod-34 reason="pod group is not ready, 4 Pending, 4 minAvailable; Pending: 4 Unschedulable" (1/5 resolved)
2026/05/06 16:11:46 Failure: pod=cspod-35 reason="pod group is not ready, 4 Pending, 4 minAvailable; Pending: 4 Unschedulable" (2/5 resolved)
2026/05/06 16:11:46 Failure: pod=cspod-36 reason="pod group is not ready, 4 Pending, 4 minAvailable; Pending: 4 Unschedulable" (3/5 resolved)
2026/05/06 16:11:46 Failure: pod=cspod-33 reason="pod group is not ready, 4 Pending, 4 minAvailable; Pending: 4 Unschedulable" (4/5 resolved)
2026/05/06 16:11:46 Binding: pod=cspod-69 -> node=csnode-1 (5/5 resolved)
2026/05/06 16:11:46 Round complete: 1 scheduled, 4 failed in 989.598035ms
2026/05/06 16:11:46 {"action":"HandleSchedule","durationMs":989,"podCount":5,"result":"ok","roundId":"33","scheduled":1,"ts":"2026-05-06T16:11:46.553348816+01:00","unschedulable":4}
2026/05/06 16:11:46 {"action":"HandleSchedule","completedIds":1,"nodeCount":5,"phase":"start","podCount":4,"roundId":"34","ts":"2026-05-06T16:11:46.557161148+01:00"}
2026/05/06 16:11:46 {"action":"HandleSchedule","phase":"prep_done","podsCreated":4,"prepMs":0,"roundId":"34","staleDeleted":0,"ts":"2026-05-06T16:11:46.557302063+01:00"}
2026/05/06 16:11:46 Scheduling round started: expecting 4 decisions
2026/05/06 16:11:47 Failure: pod=cspod-34 reason="pod group is not ready, 4 Pending, 4 minAvailable; Pending: 1 Schedulable, 3 Unschedulable" (1/4 resolved)
2026/05/06 16:11:47 Failure: pod=cspod-35 reason="pod group is not ready, 4 Pending, 4 minAvailable; Pending: 1 Schedulable, 3 Unschedulable" (2/4 resolved)
2026/05/06 16:11:47 Failure: pod=cspod-36 reason="pod group is not ready, 4 Pending, 4 minAvailable; Pending: 1 Schedulable, 3 Unschedulable" (3/4 resolved)
2026/05/06 16:11:50 STALL EXIT: no progress for 2s — 0 scheduled, 3 failed, 1 still pending (returning partial)
2026/05/06 16:11:50 {"action":"HandleSchedule","durationMs":4001,"podCount":4,"result":"timeout_partial","roundId":"34","scheduled":0,"ts":"2026-05-06T16:11:50.558838335+01:00","unschedulable":4}
2026/05/06 16:11:50 {"action":"HandleSchedule","durationMs":4001,"podCount":4,"result":"ok","roundId":"34","scheduled":0,"ts":"2026-05-06T16:11:50.558865477+01:00","unschedulable":4}
2026/05/06 16:11:50 {"action":"HandleSchedule","completedIds":2,"nodeCount":5,"phase":"start","podCount":4,"roundId":"35","ts":"2026-05-06T16:11:50.562985601+01:00"}
2026/05/06 16:11:50 {"action":"HandleSchedule","phase":"prep_done","podsCreated":4,"prepMs":0,"roundId":"35","staleDeleted":0,"ts":"2026-05-06T16:11:50.563156565+01:00"}
2026/05/06 16:11:50 Scheduling round started: expecting 4 decisions
2026/05/06 16:11:51 Failure: pod=cspod-36 reason="pod group is not ready, 4 Pending, 4 minAvailable; Pending: 1 Unschedulable, 3 Schedulable" (1/4 resolved)
2026/05/06 16:11:54 STALL EXIT: no progress for 2s — 0 scheduled, 1 failed, 3 still pending (returning partial)
2026/05/06 16:11:54 {"action":"HandleSchedule","durationMs":4004,"podCount":4,"result":"timeout_partial","roundId":"35","scheduled":0,"ts":"2026-05-06T16:11:54.567333022+01:00","unschedulable":4}
2026/05/06 16:11:54 {"action":"HandleSchedule","durationMs":4004,"podCount":4,"result":"ok","roundId":"35","scheduled":0,"ts":"2026-05-06T16:11:54.567428807+01:00","unschedulable":4}
2026/05/06 16:11:54 {"action":"HandleSchedule","completedIds":1,"nodeCount":5,"phase":"start","podCount":4,"roundId":"36","ts":"2026-05-06T16:11:54.571671901+01:00"}
2026/05/06 16:11:54 {"action":"HandleSchedule","phase":"prep_done","podsCreated":4,"prepMs":0,"roundId":"36","staleDeleted":0,"ts":"2026-05-06T16:11:54.571865185+01:00"}
2026/05/06 16:11:54 Scheduling round started: expecting 4 decisions
2026/05/06 16:11:55 Binding: pod=cspod-34 -> node=csnode-0 (1/4 resolved)
2026/05/06 16:11:55 Binding: pod=cspod-33 -> node=csnode-2 (2/4 resolved)
2026/05/06 16:11:55 Binding: pod=cspod-36 -> node=csnode-4 (3/4 resolved)
2026/05/06 16:11:55 Binding: pod=cspod-35 -> node=csnode-4 (4/4 resolved)
2026/05/06 16:11:55 Round complete: 4 scheduled, 0 failed in 1.014626616s
2026/05/06 16:11:55 {"action":"HandleSchedule","durationMs":1014,"podCount":4,"result":"ok","roundId":"36","scheduled":4,"ts":"2026-05-06T16:11:55.586534543+01:00","unschedulable":0}
2026/05/06 16:11:55 Scheduling round reset
2026/05/06 16:11:55 {"action":"HandleReset","result":"ok","roundId":"36","ts":"2026-05-06T16:11:55.612354253+01:00"}
