2026/05/06 15:59:24 Running command:
Command env: (log-file=, also-stdout=false, redirect-stderr=true)
Run from directory: 
Executable path: /usr/local/bin/kube-scheduler
Args (comma-delimited): kube-scheduler,--config=/etc/kube-scheduler/my-scheduler.yaml,--secure-port=10260,--v=2
2026/05/06 15:59:24 Now listening for interrupts
I0506 15:59:24.953909      12 flags.go:64] FLAG: --allow-metric-labels="[]"
I0506 15:59:24.953957      12 flags.go:64] FLAG: --allow-metric-labels-manifest=""
I0506 15:59:24.953963      12 flags.go:64] FLAG: --authentication-kubeconfig=""
I0506 15:59:24.953965      12 flags.go:64] FLAG: --authentication-skip-lookup="false"
I0506 15:59:24.953967      12 flags.go:64] FLAG: --authentication-token-webhook-cache-ttl="10s"
I0506 15:59:24.953969      12 flags.go:64] FLAG: --authentication-tolerate-lookup-failure="true"
I0506 15:59:24.953970      12 flags.go:64] FLAG: --authorization-always-allow-paths="[/healthz,/readyz,/livez]"
I0506 15:59:24.953973      12 flags.go:64] FLAG: --authorization-kubeconfig=""
I0506 15:59:24.953974      12 flags.go:64] FLAG: --authorization-webhook-cache-authorized-ttl="10s"
I0506 15:59:24.953975      12 flags.go:64] FLAG: --authorization-webhook-cache-unauthorized-ttl="10s"
I0506 15:59:24.953976      12 flags.go:64] FLAG: --bind-address="0.0.0.0"
I0506 15:59:24.953978      12 flags.go:64] FLAG: --cert-dir=""
I0506 15:59:24.953978      12 flags.go:64] FLAG: --client-ca-file=""
I0506 15:59:24.953980      12 flags.go:64] FLAG: --config="/etc/kube-scheduler/my-scheduler.yaml"
I0506 15:59:24.953981      12 flags.go:64] FLAG: --contention-profiling="true"
I0506 15:59:24.953982      12 flags.go:64] FLAG: --disable-http2-serving="false"
I0506 15:59:24.953983      12 flags.go:64] FLAG: --disabled-metrics="[]"
I0506 15:59:24.953985      12 flags.go:64] FLAG: --emulated-version="[]"
I0506 15:59:24.953986      12 flags.go:64] FLAG: --feature-gates=""
I0506 15:59:24.953988      12 flags.go:64] FLAG: --help="false"
I0506 15:59:24.953989      12 flags.go:64] FLAG: --http2-max-streams-per-connection="0"
I0506 15:59:24.953991      12 flags.go:64] FLAG: --kube-api-burst="100"
I0506 15:59:24.953993      12 flags.go:64] FLAG: --kube-api-content-type="application/vnd.kubernetes.protobuf"
I0506 15:59:24.953994      12 flags.go:64] FLAG: --kube-api-qps="50"
I0506 15:59:24.954004      12 flags.go:64] FLAG: --kubeconfig=""
I0506 15:59:24.954005      12 flags.go:64] FLAG: --leader-elect="true"
I0506 15:59:24.954006      12 flags.go:64] FLAG: --leader-elect-lease-duration="15s"
I0506 15:59:24.954007      12 flags.go:64] FLAG: --leader-elect-renew-deadline="10s"
I0506 15:59:24.954008      12 flags.go:64] FLAG: --leader-elect-resource-lock="leases"
I0506 15:59:24.954008      12 flags.go:64] FLAG: --leader-elect-resource-name="kube-scheduler"
I0506 15:59:24.954009      12 flags.go:64] FLAG: --leader-elect-resource-namespace="kube-system"
I0506 15:59:24.954010      12 flags.go:64] FLAG: --leader-elect-retry-period="2s"
I0506 15:59:24.954011      12 flags.go:64] FLAG: --log-flush-frequency="5s"
I0506 15:59:24.954012      12 flags.go:64] FLAG: --log-json-info-buffer-size="0"
I0506 15:59:24.954015      12 flags.go:64] FLAG: --log-json-split-stream="false"
I0506 15:59:24.954015      12 flags.go:64] FLAG: --log-text-info-buffer-size="0"
I0506 15:59:24.954016      12 flags.go:64] FLAG: --log-text-split-stream="false"
I0506 15:59:24.954017      12 flags.go:64] FLAG: --logging-format="text"
I0506 15:59:24.954018      12 flags.go:64] FLAG: --master=""
I0506 15:59:24.954019      12 flags.go:64] FLAG: --permit-address-sharing="false"
I0506 15:59:24.954020      12 flags.go:64] FLAG: --permit-port-sharing="false"
I0506 15:59:24.954021      12 flags.go:64] FLAG: --pod-max-in-unschedulable-pods-duration="5m0s"
I0506 15:59:24.954022      12 flags.go:64] FLAG: --profiling="true"
I0506 15:59:24.954023      12 flags.go:64] FLAG: --requestheader-allowed-names="[]"
I0506 15:59:24.954025      12 flags.go:64] FLAG: --requestheader-client-ca-file=""
I0506 15:59:24.954026      12 flags.go:64] FLAG: --requestheader-extra-headers-prefix="[x-remote-extra-]"
I0506 15:59:24.954027      12 flags.go:64] FLAG: --requestheader-group-headers="[x-remote-group]"
I0506 15:59:24.954029      12 flags.go:64] FLAG: --requestheader-uid-headers="[]"
I0506 15:59:24.954030      12 flags.go:64] FLAG: --requestheader-username-headers="[x-remote-user]"
I0506 15:59:24.954031      12 flags.go:64] FLAG: --secure-port="10260"
I0506 15:59:24.954033      12 flags.go:64] FLAG: --show-hidden-metrics-for-version=""
I0506 15:59:24.954034      12 flags.go:64] FLAG: --tls-cert-file=""
I0506 15:59:24.954035      12 flags.go:64] FLAG: --tls-cipher-suites="[]"
I0506 15:59:24.954036      12 flags.go:64] FLAG: --tls-min-version=""
I0506 15:59:24.954037      12 flags.go:64] FLAG: --tls-private-key-file=""
I0506 15:59:24.954038      12 flags.go:64] FLAG: --tls-sni-cert-key="[]"
I0506 15:59:24.954040      12 flags.go:64] FLAG: --v="2"
I0506 15:59:24.954041      12 flags.go:64] FLAG: --version="false"
I0506 15:59:24.954045      12 flags.go:64] FLAG: --vmodule=""
I0506 15:59:24.954047      12 flags.go:64] FLAG: --write-config-to=""
I0506 15:59:25.016173      12 serving.go:386] Generated self-signed cert in-memory
W0506 15:59:25.337928      12 authentication.go:368] No authentication-kubeconfig provided in order to lookup client-ca-file in configmap/extension-apiserver-authentication in kube-system, so client certificate authentication won't work.
W0506 15:59:25.337965      12 authentication.go:392] No authentication-kubeconfig provided in order to lookup requestheader-client-ca-file in configmap/extension-apiserver-authentication in kube-system, so request-header client certificate authentication won't work.
W0506 15:59:25.337979      12 authorization.go:193] No authorization-kubeconfig provided, so SubjectAccessReview of authorization tokens won't work.
I0506 15:59:25.342886      12 framework.go:399] "the scheduler starts to work with those plugins" Plugins={"PreEnqueue":{"Enabled":[{"Name":"SchedulingGates","Weight":0},{"Name":"DefaultPreemption","Weight":0}],"Disabled":null},"QueueSort":{"Enabled":[{"Name":"PrioritySort","Weight":0}],"Disabled":null},"PreFilter":{"Enabled":[{"Name":"NodeAffinity","Weight":0},{"Name":"NodePorts","Weight":0},{"Name":"NodeResourcesFit","Weight":0},{"Name":"VolumeRestrictions","Weight":0},{"Name":"NodeVolumeLimits","Weight":0},{"Name":"VolumeBinding","Weight":0},{"Name":"VolumeZone","Weight":0},{"Name":"PodTopologySpread","Weight":0},{"Name":"InterPodAffinity","Weight":0}],"Disabled":null},"Filter":{"Enabled":[{"Name":"NodeUnschedulable","Weight":0},{"Name":"NodeName","Weight":0},{"Name":"TaintToleration","Weight":0},{"Name":"NodeAffinity","Weight":0},{"Name":"NodePorts","Weight":0},{"Name":"NodeResourcesFit","Weight":0},{"Name":"VolumeRestrictions","Weight":0},{"Name":"NodeVolumeLimits","Weight":0},{"Name":"VolumeBinding","Weight":0},{"Name":"VolumeZone","Weight":0},{"Name":"PodTopologySpread","Weight":0},{"Name":"InterPodAffinity","Weight":0}],"Disabled":null},"PostFilter":{"Enabled":[{"Name":"DefaultPreemption","Weight":0}],"Disabled":null},"PreScore":{"Enabled":[{"Name":"TaintToleration","Weight":0},{"Name":"NodeAffinity","Weight":0},{"Name":"NodeResourcesFit","Weight":0},{"Name":"VolumeBinding","Weight":0},{"Name":"PodTopologySpread","Weight":0},{"Name":"InterPodAffinity","Weight":0},{"Name":"NodeResourcesBalancedAllocation","Weight":0}],"Disabled":null},"Score":{"Enabled":[{"Name":"NodeResourcesFit","Weight":1}],"Disabled":null},"Reserve":{"Enabled":[{"Name":"VolumeBinding","Weight":0}],"Disabled":null},"Permit":{"Enabled":null,"Disabled":null},"PreBind":{"Enabled":[{"Name":"VolumeBinding","Weight":0}],"Disabled":null},"Bind":{"Enabled":[{"Name":"DefaultBinder","Weight":0}],"Disabled":null},"PostBind":{"Enabled":null,"Disabled":null},"MultiPoint":{"Enabled":null,"Disabled":null}}
I0506 15:59:25.343094      12 framework.go:399] "the scheduler starts to work with those plugins" Plugins={"PreEnqueue":{"Enabled":[{"Name":"SchedulingGates","Weight":0},{"Name":"DefaultPreemption","Weight":0}],"Disabled":null},"QueueSort":{"Enabled":[{"Name":"PrioritySort","Weight":0}],"Disabled":null},"PreFilter":{"Enabled":[{"Name":"NodeAffinity","Weight":0},{"Name":"NodePorts","Weight":0},{"Name":"NodeResourcesFit","Weight":0},{"Name":"VolumeRestrictions","Weight":0},{"Name":"NodeVolumeLimits","Weight":0},{"Name":"VolumeBinding","Weight":0},{"Name":"VolumeZone","Weight":0},{"Name":"PodTopologySpread","Weight":0},{"Name":"InterPodAffinity","Weight":0}],"Disabled":null},"Filter":{"Enabled":[{"Name":"NodeUnschedulable","Weight":0},{"Name":"NodeName","Weight":0},{"Name":"TaintToleration","Weight":0},{"Name":"NodeAffinity","Weight":0},{"Name":"NodePorts","Weight":0},{"Name":"NodeResourcesFit","Weight":0},{"Name":"VolumeRestrictions","Weight":0},{"Name":"NodeVolumeLimits","Weight":0},{"Name":"VolumeBinding","Weight":0},{"Name":"VolumeZone","Weight":0},{"Name":"PodTopologySpread","Weight":0},{"Name":"InterPodAffinity","Weight":0}],"Disabled":null},"PostFilter":{"Enabled":[{"Name":"DefaultPreemption","Weight":0}],"Disabled":null},"PreScore":{"Enabled":[{"Name":"TaintToleration","Weight":0},{"Name":"NodeAffinity","Weight":0},{"Name":"NodeResourcesFit","Weight":0},{"Name":"VolumeBinding","Weight":0},{"Name":"PodTopologySpread","Weight":0},{"Name":"InterPodAffinity","Weight":0},{"Name":"NodeResourcesBalancedAllocation","Weight":0}],"Disabled":null},"Score":{"Enabled":[{"Name":"NodeResourcesFit","Weight":1}],"Disabled":null},"Reserve":{"Enabled":[{"Name":"VolumeBinding","Weight":0}],"Disabled":null},"Permit":{"Enabled":null,"Disabled":null},"PreBind":{"Enabled":[{"Name":"VolumeBinding","Weight":0}],"Disabled":null},"Bind":{"Enabled":[{"Name":"DefaultBinder","Weight":0}],"Disabled":null},"PostBind":{"Enabled":null,"Disabled":null},"MultiPoint":{"Enabled":null,"Disabled":null}}
I0506 15:59:25.345372      12 configfile.go:94] "Using component config" config=<
	apiVersion: kubescheduler.config.k8s.io/v1
	clientConnection:
	  acceptContentTypes: ""
	  burst: 100
	  contentType: application/vnd.kubernetes.protobuf
	  kubeconfig: /etc/kube-scheduler/kubeconfig.yaml
	  qps: 50
	enableContentionProfiling: true
	enableProfiling: true
	kind: KubeSchedulerConfiguration
	leaderElection:
	  leaderElect: false
	  leaseDuration: 15s
	  renewDeadline: 10s
	  resourceLock: leases
	  resourceName: kube-scheduler
	  resourceNamespace: kube-system
	  retryPeriod: 2s
	parallelism: 16
	percentageOfNodesToScore: 0
	podInitialBackoffSeconds: 1
	podMaxBackoffSeconds: 10
	profiles:
	- pluginConfig:
	  - args:
	      apiVersion: kubescheduler.config.k8s.io/v1
	      kind: DefaultPreemptionArgs
	      minCandidateNodesAbsolute: 100
	      minCandidateNodesPercentage: 10
	    name: DefaultPreemption
	  - args:
	      apiVersion: kubescheduler.config.k8s.io/v1
	      hardPodAffinityWeight: 1
	      ignorePreferredTermsOfExistingPods: false
	      kind: InterPodAffinityArgs
	    name: InterPodAffinity
	  - args:
	      apiVersion: kubescheduler.config.k8s.io/v1
	      kind: NodeAffinityArgs
	    name: NodeAffinity
	  - args:
	      apiVersion: kubescheduler.config.k8s.io/v1
	      kind: NodeResourcesBalancedAllocationArgs
	      resources:
	      - name: cpu
	        weight: 1
	      - name: memory
	        weight: 1
	    name: NodeResourcesBalancedAllocation
	  - args:
	      apiVersion: kubescheduler.config.k8s.io/v1
	      kind: NodeResourcesFitArgs
	      scoringStrategy:
	        resources:
	        - name: cpu
	          weight: 1
	        - name: memory
	          weight: 1
	        type: LeastAllocated
	    name: NodeResourcesFit
	  - args:
	      apiVersion: kubescheduler.config.k8s.io/v1
	      defaultingType: System
	      kind: PodTopologySpreadArgs
	    name: PodTopologySpread
	  - args:
	      apiVersion: kubescheduler.config.k8s.io/v1
	      bindTimeoutSeconds: 600
	      kind: VolumeBindingArgs
	    name: VolumeBinding
	  plugins:
	    bind: {}
	    filter: {}
	    multiPoint:
	      enabled:
	      - name: SchedulingGates
	        weight: 0
	      - name: PrioritySort
	        weight: 0
	      - name: NodeUnschedulable
	        weight: 0
	      - name: NodeName
	        weight: 0
	      - name: TaintToleration
	        weight: 3
	      - name: NodeAffinity
	        weight: 2
	      - name: NodePorts
	        weight: 0
	      - name: NodeResourcesFit
	        weight: 1
	      - name: VolumeRestrictions
	        weight: 0
	      - name: NodeVolumeLimits
	        weight: 0
	      - name: VolumeBinding
	        weight: 0
	      - name: VolumeZone
	        weight: 0
	      - name: PodTopologySpread
	        weight: 2
	      - name: InterPodAffinity
	        weight: 2
	      - name: DefaultPreemption
	        weight: 0
	      - name: NodeResourcesBalancedAllocation
	        weight: 1
	      - name: ImageLocality
	        weight: 1
	      - name: DefaultBinder
	        weight: 0
	    permit: {}
	    postBind: {}
	    postFilter: {}
	    preBind: {}
	    preEnqueue: {}
	    preFilter: {}
	    preScore: {}
	    queueSort: {}
	    reserve: {}
	    score:
	      disabled:
	      - name: '*'
	        weight: 0
	      enabled:
	      - name: NodeResourcesFit
	        weight: 0
	  schedulerName: default-scheduler
	- pluginConfig:
	  - args:
	      apiVersion: kubescheduler.config.k8s.io/v1
	      kind: DefaultPreemptionArgs
	      minCandidateNodesAbsolute: 100
	      minCandidateNodesPercentage: 10
	    name: DefaultPreemption
	  - args:
	      apiVersion: kubescheduler.config.k8s.io/v1
	      hardPodAffinityWeight: 1
	      ignorePreferredTermsOfExistingPods: false
	      kind: InterPodAffinityArgs
	    name: InterPodAffinity
	  - args:
	      apiVersion: kubescheduler.config.k8s.io/v1
	      kind: NodeAffinityArgs
	    name: NodeAffinity
	  - args:
	      apiVersion: kubescheduler.config.k8s.io/v1
	      kind: NodeResourcesBalancedAllocationArgs
	      resources:
	      - name: cpu
	        weight: 1
	      - name: memory
	        weight: 1
	    name: NodeResourcesBalancedAllocation
	  - args:
	      apiVersion: kubescheduler.config.k8s.io/v1
	      kind: NodeResourcesFitArgs
	      scoringStrategy:
	        resources:
	        - name: cpu
	          weight: 1
	        - name: memory
	          weight: 1
	        type: MostAllocated
	    name: NodeResourcesFit
	  - args:
	      apiVersion: kubescheduler.config.k8s.io/v1
	      defaultingType: System
	      kind: PodTopologySpreadArgs
	    name: PodTopologySpread
	  - args:
	      apiVersion: kubescheduler.config.k8s.io/v1
	      bindTimeoutSeconds: 600
	      kind: VolumeBindingArgs
	    name: VolumeBinding
	  plugins:
	    bind: {}
	    filter: {}
	    multiPoint:
	      enabled:
	      - name: SchedulingGates
	        weight: 0
	      - name: PrioritySort
	        weight: 0
	      - name: NodeUnschedulable
	        weight: 0
	      - name: NodeName
	        weight: 0
	      - name: TaintToleration
	        weight: 3
	      - name: NodeAffinity
	        weight: 2
	      - name: NodePorts
	        weight: 0
	      - name: NodeResourcesFit
	        weight: 1
	      - name: VolumeRestrictions
	        weight: 0
	      - name: NodeVolumeLimits
	        weight: 0
	      - name: VolumeBinding
	        weight: 0
	      - name: VolumeZone
	        weight: 0
	      - name: PodTopologySpread
	        weight: 2
	      - name: InterPodAffinity
	        weight: 2
	      - name: DefaultPreemption
	        weight: 0
	      - name: NodeResourcesBalancedAllocation
	        weight: 1
	      - name: ImageLocality
	        weight: 1
	      - name: DefaultBinder
	        weight: 0
	    permit: {}
	    postBind: {}
	    postFilter: {}
	    preBind: {}
	    preEnqueue: {}
	    preFilter: {}
	    preScore: {}
	    queueSort: {}
	    reserve: {}
	    score:
	      disabled:
	      - name: '*'
	        weight: 0
	      enabled:
	      - name: NodeResourcesFit
	        weight: 0
	  schedulerName: my-scheduler
 >
I0506 15:59:25.345917      12 server.go:171] "Starting Kubernetes Scheduler" version="v1.33.0"
I0506 15:59:25.345946      12 server.go:173] "Golang settings" GOGC="" GOMAXPROCS="" GOTRACEBACK=""
I0506 15:59:25.347094      12 tlsconfig.go:203] "Loaded serving cert" certName="Generated self signed cert" certDetail="\"localhost@1778083165\" [serving] validServingFor=[127.0.0.1,localhost,localhost] issuer=\"localhost-ca@1778083164\" (2026-05-06 14:59:24 +0000 UTC to 2027-05-06 14:59:24 +0000 UTC (now=2026-05-06 15:59:25.347081342 +0000 UTC))"
I0506 15:59:25.347210      12 named_certificates.go:53] "Loaded SNI cert" index=0 certName="self-signed loopback" certDetail="\"apiserver-loopback-client@1778083165\" [serving] validServingFor=[apiserver-loopback-client] issuer=\"apiserver-loopback-client-ca@1778083165\" (2026-05-06 14:59:25 +0000 UTC to 2029-05-06 14:59:25 +0000 UTC (now=2026-05-06 15:59:25.347199865 +0000 UTC))"
I0506 15:59:25.347272      12 secure_serving.go:211] Serving securely on [::]:10260
I0506 15:59:25.347330      12 tlsconfig.go:243] "Starting DynamicServingCertificateController"
I0506 15:59:25.348533      12 reflector.go:430] "Caches populated" type="*v1.CSIDriver" reflector="k8s.io/client-go/informers/factory.go:160"
I0506 15:59:25.348628      12 reflector.go:430] "Caches populated" type="*v1.Namespace" reflector="k8s.io/client-go/informers/factory.go:160"
I0506 15:59:25.349211      12 reflector.go:430] "Caches populated" type="*v1.ReplicaSet" reflector="k8s.io/client-go/informers/factory.go:160"
I0506 15:59:25.349273      12 reflector.go:430] "Caches populated" type="*v1.CSINode" reflector="k8s.io/client-go/informers/factory.go:160"
I0506 15:59:25.349376      12 reflector.go:430] "Caches populated" type="*v1.CSIStorageCapacity" reflector="k8s.io/client-go/informers/factory.go:160"
I0506 15:59:25.349394      12 reflector.go:430] "Caches populated" type="*v1.VolumeAttachment" reflector="k8s.io/client-go/informers/factory.go:160"
I0506 15:59:25.348540      12 reflector.go:430] "Caches populated" type="*v1.PodDisruptionBudget" reflector="k8s.io/client-go/informers/factory.go:160"
I0506 15:59:25.349674      12 reflector.go:430] "Caches populated" type="*v1.PersistentVolumeClaim" reflector="k8s.io/client-go/informers/factory.go:160"
I0506 15:59:25.349544      12 reflector.go:430] "Caches populated" type="*v1.StatefulSet" reflector="k8s.io/client-go/informers/factory.go:160"
I0506 15:59:25.350821      12 reflector.go:430] "Caches populated" type="*v1.Node" reflector="k8s.io/client-go/informers/factory.go:160"
I0506 15:59:25.350829      12 reflector.go:430] "Caches populated" type="*v1.Service" reflector="k8s.io/client-go/informers/factory.go:160"
I0506 15:59:25.350839      12 reflector.go:430] "Caches populated" type="*v1.ReplicationController" reflector="k8s.io/client-go/informers/factory.go:160"
I0506 15:59:25.350845      12 reflector.go:430] "Caches populated" type="*v1.PersistentVolume" reflector="k8s.io/client-go/informers/factory.go:160"
I0506 15:59:25.350905      12 reflector.go:430] "Caches populated" type="*v1.StorageClass" reflector="k8s.io/client-go/informers/factory.go:160"
I0506 15:59:25.351196      12 reflector.go:430] "Caches populated" type="*v1.Pod" reflector="k8s.io/client-go/informers/factory.go:160"
I0506 15:59:32.269138      12 node_tree.go:65] "Added node to NodeTree" node="csnode-2" zone=""
I0506 15:59:32.269215      12 node_tree.go:65] "Added node to NodeTree" node="csnode-3" zone=""
I0506 15:59:32.269288      12 node_tree.go:65] "Added node to NodeTree" node="csnode-4" zone=""
I0506 15:59:32.269324      12 node_tree.go:65] "Added node to NodeTree" node="csnode-0" zone=""
I0506 15:59:32.269334      12 node_tree.go:65] "Added node to NodeTree" node="csnode-1" zone=""
I0506 15:59:32.298693      12 schedule_one.go:314] "Successfully bound pod to node" pod="default/cspod-2" node="csnode-3" evaluatedNodes=5 feasibleNodes=4
I0506 15:59:32.298710      12 schedule_one.go:314] "Successfully bound pod to node" pod="default/cspod-0" node="csnode-4" evaluatedNodes=5 feasibleNodes=5
I0506 15:59:32.298822      12 schedule_one.go:314] "Successfully bound pod to node" pod="default/cspod-5" node="csnode-0" evaluatedNodes=5 feasibleNodes=3
I0506 15:59:32.298821      12 schedule_one.go:314] "Successfully bound pod to node" pod="default/cspod-3" node="csnode-3" evaluatedNodes=5 feasibleNodes=4
I0506 15:59:32.299001      12 schedule_one.go:314] "Successfully bound pod to node" pod="default/cspod-6" node="csnode-1" evaluatedNodes=5 feasibleNodes=2
I0506 15:59:32.299042      12 schedule_one.go:314] "Successfully bound pod to node" pod="default/cspod-4" node="csnode-0" evaluatedNodes=5 feasibleNodes=3
I0506 15:59:32.299100      12 schedule_one.go:314] "Successfully bound pod to node" pod="default/cspod-1" node="csnode-4" evaluatedNodes=5 feasibleNodes=5
E0506 15:59:32.299039      12 event.go:368] "Unable to write event (may retry after sleeping)" err="0-length response with status code: 201 and content type: application/vnd.kubernetes.protobuf" event="&Event{ObjectMeta:{cspod-2.18ad053979f62f80  default    0 0001-01-01 00:00:00 +0000 UTC <nil> <nil> map[] map[] [] [] []},InvolvedObject:ObjectReference{Kind:Pod,Namespace:default,Name:cspod-2,UID:cspod-2-uid,APIVersion:v1,ResourceVersion:8,FieldPath:,},Reason:Scheduled,Message:Successfully assigned default/cspod-2 to csnode-3,Source:EventSource{Component:my-scheduler,Host:,},FirstTimestamp:2026-05-06 15:59:32.298665856 +0000 UTC m=+7.376697256,LastTimestamp:2026-05-06 15:59:32.298665856 +0000 UTC m=+7.376697256,Count:1,Type:Normal,EventTime:0001-01-01 00:00:00 +0000 UTC,Series:nil,Action:,Related:nil,ReportingController:my-scheduler,ReportingInstance:,}"
I0506 15:59:32.299260      12 schedule_one.go:314] "Successfully bound pod to node" pod="default/cspod-7" node="csnode-1" evaluatedNodes=5 feasibleNodes=2
I0506 15:59:32.299317      12 schedule_one.go:314] "Successfully bound pod to node" pod="default/cspod-8" node="csnode-2" evaluatedNodes=5 feasibleNodes=1
I0506 15:59:32.299487      12 preemption.go:264] "No preemption candidate is found; preemption is not helpful for scheduling" pod="default/cspod-10"
I0506 15:59:32.299558      12 schedule_one.go:1044] "Unable to schedule pod; no fit; waiting" pod="default/cspod-10" err="0/5 nodes are available: 5 Insufficient cpu. preemption: 0/5 nodes are available: 5 No preemption victims found for incoming pod."
I0506 15:59:32.299590      12 schedule_one.go:314] "Successfully bound pod to node" pod="default/cspod-9" node="csnode-2" evaluatedNodes=5 feasibleNodes=1
I0506 15:59:32.301005      12 preemption.go:264] "No preemption candidate is found; preemption is not helpful for scheduling" pod="default/cspod-11"
I0506 15:59:32.301040      12 schedule_one.go:1044] "Unable to schedule pod; no fit; waiting" pod="default/cspod-11" err="0/5 nodes are available: 5 Insufficient cpu. preemption: 0/5 nodes are available: 5 No preemption victims found for incoming pod."
I0506 15:59:32.301607      12 preemption.go:264] "No preemption candidate is found; preemption is not helpful for scheduling" pod="default/cspod-12"
I0506 15:59:32.301641      12 schedule_one.go:1044] "Unable to schedule pod; no fit; waiting" pod="default/cspod-12" err="0/5 nodes are available: 5 Insufficient cpu. preemption: 0/5 nodes are available: 5 No preemption victims found for incoming pod."
I0506 15:59:32.302135      12 preemption.go:264] "No preemption candidate is found; preemption is not helpful for scheduling" pod="default/cspod-13"
I0506 15:59:32.302168      12 schedule_one.go:1044] "Unable to schedule pod; no fit; waiting" pod="default/cspod-13" err="0/5 nodes are available: 5 Insufficient cpu. preemption: 0/5 nodes are available: 5 No preemption victims found for incoming pod."
I0506 15:59:32.302668      12 preemption.go:264] "No preemption candidate is found; preemption is not helpful for scheduling" pod="default/cspod-14"
I0506 15:59:32.302706      12 schedule_one.go:1044] "Unable to schedule pod; no fit; waiting" pod="default/cspod-14" err="0/5 nodes are available: 5 Insufficient cpu. preemption: 0/5 nodes are available: 5 No preemption victims found for incoming pod."
I0506 15:59:32.303246      12 preemption.go:264] "No preemption candidate is found; preemption is not helpful for scheduling" pod="default/cspod-15"
I0506 15:59:32.303280      12 schedule_one.go:1044] "Unable to schedule pod; no fit; waiting" pod="default/cspod-15" err="0/5 nodes are available: 5 Insufficient cpu. preemption: 0/5 nodes are available: 5 No preemption victims found for incoming pod."
I0506 15:59:32.303816      12 preemption.go:264] "No preemption candidate is found; preemption is not helpful for scheduling" pod="default/cspod-16"
I0506 15:59:32.303850      12 schedule_one.go:1044] "Unable to schedule pod; no fit; waiting" pod="default/cspod-16" err="0/5 nodes are available: 5 Insufficient cpu. preemption: 0/5 nodes are available: 5 No preemption victims found for incoming pod."
I0506 15:59:32.304381      12 preemption.go:264] "No preemption candidate is found; preemption is not helpful for scheduling" pod="default/cspod-17"
I0506 15:59:32.304415      12 schedule_one.go:1044] "Unable to schedule pod; no fit; waiting" pod="default/cspod-17" err="0/5 nodes are available: 5 Insufficient cpu. preemption: 0/5 nodes are available: 5 No preemption victims found for incoming pod."
I0506 15:59:32.304924      12 preemption.go:264] "No preemption candidate is found; preemption is not helpful for scheduling" pod="default/cspod-18"
I0506 15:59:32.304959      12 schedule_one.go:1044] "Unable to schedule pod; no fit; waiting" pod="default/cspod-18" err="0/5 nodes are available: 5 Insufficient cpu. preemption: 0/5 nodes are available: 5 No preemption victims found for incoming pod."
I0506 15:59:32.305495      12 preemption.go:264] "No preemption candidate is found; preemption is not helpful for scheduling" pod="default/cspod-19"
I0506 15:59:32.305528      12 schedule_one.go:1044] "Unable to schedule pod; no fit; waiting" pod="default/cspod-19" err="0/5 nodes are available: 5 Insufficient cpu. preemption: 0/5 nodes are available: 5 No preemption victims found for incoming pod."
I0506 15:59:32.306060      12 preemption.go:264] "No preemption candidate is found; preemption is not helpful for scheduling" pod="default/cspod-20"
I0506 15:59:32.306094      12 schedule_one.go:1044] "Unable to schedule pod; no fit; waiting" pod="default/cspod-20" err="0/5 nodes are available: 5 Insufficient cpu. preemption: 0/5 nodes are available: 5 No preemption victims found for incoming pod."
I0506 15:59:32.306693      12 preemption.go:264] "No preemption candidate is found; preemption is not helpful for scheduling" pod="default/cspod-21"
I0506 15:59:32.306725      12 schedule_one.go:1044] "Unable to schedule pod; no fit; waiting" pod="default/cspod-21" err="0/5 nodes are available: 5 Insufficient cpu. preemption: 0/5 nodes are available: 5 No preemption victims found for incoming pod."
I0506 15:59:32.307232      12 preemption.go:264] "No preemption candidate is found; preemption is not helpful for scheduling" pod="default/cspod-22"
I0506 15:59:32.307272      12 schedule_one.go:1044] "Unable to schedule pod; no fit; waiting" pod="default/cspod-22" err="0/5 nodes are available: 5 Insufficient cpu. preemption: 0/5 nodes are available: 5 No preemption victims found for incoming pod."
I0506 15:59:32.308852      12 preemption.go:264] "No preemption candidate is found; preemption is not helpful for scheduling" pod="default/cspod-23"
I0506 15:59:32.308893      12 schedule_one.go:1044] "Unable to schedule pod; no fit; waiting" pod="default/cspod-23" err="0/5 nodes are available: 5 Insufficient cpu. preemption: 0/5 nodes are available: 5 No preemption victims found for incoming pod."
I0506 15:59:32.309463      12 preemption.go:264] "No preemption candidate is found; preemption is not helpful for scheduling" pod="default/cspod-24"
I0506 15:59:32.309496      12 schedule_one.go:1044] "Unable to schedule pod; no fit; waiting" pod="default/cspod-24" err="0/5 nodes are available: 5 Insufficient cpu. preemption: 0/5 nodes are available: 5 No preemption victims found for incoming pod."
I0506 15:59:32.310093      12 preemption.go:264] "No preemption candidate is found; preemption is not helpful for scheduling" pod="default/cspod-25"
I0506 15:59:32.310142      12 schedule_one.go:1044] "Unable to schedule pod; no fit; waiting" pod="default/cspod-25" err="0/5 nodes are available: 5 Insufficient cpu. preemption: 0/5 nodes are available: 5 No preemption victims found for incoming pod."
I0506 15:59:32.310689      12 preemption.go:264] "No preemption candidate is found; preemption is not helpful for scheduling" pod="default/cspod-26"
I0506 15:59:32.310722      12 schedule_one.go:1044] "Unable to schedule pod; no fit; waiting" pod="default/cspod-26" err="0/5 nodes are available: 5 Insufficient cpu. preemption: 0/5 nodes are available: 5 No preemption victims found for incoming pod."
I0506 15:59:32.311190      12 preemption.go:264] "No preemption candidate is found; preemption is not helpful for scheduling" pod="default/cspod-27"
I0506 15:59:32.311224      12 schedule_one.go:1044] "Unable to schedule pod; no fit; waiting" pod="default/cspod-27" err="0/5 nodes are available: 5 Insufficient cpu. preemption: 0/5 nodes are available: 5 No preemption victims found for incoming pod."
I0506 15:59:32.311736      12 preemption.go:264] "No preemption candidate is found; preemption is not helpful for scheduling" pod="default/cspod-28"
I0506 15:59:32.311769      12 schedule_one.go:1044] "Unable to schedule pod; no fit; waiting" pod="default/cspod-28" err="0/5 nodes are available: 5 Insufficient cpu. preemption: 0/5 nodes are available: 5 No preemption victims found for incoming pod."
I0506 15:59:32.312242      12 preemption.go:264] "No preemption candidate is found; preemption is not helpful for scheduling" pod="default/cspod-29"
I0506 15:59:32.312280      12 schedule_one.go:1044] "Unable to schedule pod; no fit; waiting" pod="default/cspod-29" err="0/5 nodes are available: 5 Insufficient cpu. preemption: 0/5 nodes are available: 5 No preemption victims found for incoming pod."
I0506 15:59:32.312757      12 preemption.go:264] "No preemption candidate is found; preemption is not helpful for scheduling" pod="default/cspod-30"
I0506 15:59:32.312798      12 schedule_one.go:1044] "Unable to schedule pod; no fit; waiting" pod="default/cspod-30" err="0/5 nodes are available: 5 Insufficient cpu. preemption: 0/5 nodes are available: 5 No preemption victims found for incoming pod."
I0506 15:59:32.313386      12 preemption.go:264] "No preemption candidate is found; preemption is not helpful for scheduling" pod="default/cspod-31"
I0506 15:59:32.313418      12 schedule_one.go:1044] "Unable to schedule pod; no fit; waiting" pod="default/cspod-31" err="0/5 nodes are available: 5 Insufficient cpu. preemption: 0/5 nodes are available: 5 No preemption victims found for incoming pod."
I0506 15:59:32.313949      12 preemption.go:264] "No preemption candidate is found; preemption is not helpful for scheduling" pod="default/cspod-32"
I0506 15:59:32.313984      12 schedule_one.go:1044] "Unable to schedule pod; no fit; waiting" pod="default/cspod-32" err="0/5 nodes are available: 5 Insufficient cpu. preemption: 0/5 nodes are available: 5 No preemption victims found for incoming pod."
I0506 15:59:32.314511      12 preemption.go:264] "No preemption candidate is found; preemption is not helpful for scheduling" pod="default/cspod-33"
I0506 15:59:32.314544      12 schedule_one.go:1044] "Unable to schedule pod; no fit; waiting" pod="default/cspod-33" err="0/5 nodes are available: 5 Insufficient cpu. preemption: 0/5 nodes are available: 5 No preemption victims found for incoming pod."
I0506 15:59:32.315032      12 preemption.go:264] "No preemption candidate is found; preemption is not helpful for scheduling" pod="default/cspod-34"
I0506 15:59:32.315067      12 schedule_one.go:1044] "Unable to schedule pod; no fit; waiting" pod="default/cspod-34" err="0/5 nodes are available: 5 Insufficient cpu. preemption: 0/5 nodes are available: 5 No preemption victims found for incoming pod."
I0506 15:59:32.315621      12 preemption.go:264] "No preemption candidate is found; preemption is not helpful for scheduling" pod="default/cspod-35"
I0506 15:59:32.315657      12 schedule_one.go:1044] "Unable to schedule pod; no fit; waiting" pod="default/cspod-35" err="0/5 nodes are available: 5 Insufficient cpu. preemption: 0/5 nodes are available: 5 No preemption victims found for incoming pod."
I0506 15:59:32.316181      12 preemption.go:264] "No preemption candidate is found; preemption is not helpful for scheduling" pod="default/cspod-36"
I0506 15:59:32.316212      12 schedule_one.go:1044] "Unable to schedule pod; no fit; waiting" pod="default/cspod-36" err="0/5 nodes are available: 5 Insufficient cpu. preemption: 0/5 nodes are available: 5 No preemption victims found for incoming pod."
I0506 15:59:32.411661      12 preemption.go:264] "No preemption candidate is found; preemption is not helpful for scheduling" pod="default/cspod-37"
I0506 15:59:32.411711      12 schedule_one.go:1044] "Unable to schedule pod; no fit; waiting" pod="default/cspod-37" err="0/5 nodes are available: 5 Insufficient cpu. preemption: 0/5 nodes are available: 5 No preemption victims found for incoming pod."
I0506 15:59:32.412359      12 preemption.go:264] "No preemption candidate is found; preemption is not helpful for scheduling" pod="default/cspod-38"
I0506 15:59:32.412401      12 schedule_one.go:1044] "Unable to schedule pod; no fit; waiting" pod="default/cspod-38" err="0/5 nodes are available: 5 Insufficient cpu. preemption: 0/5 nodes are available: 5 No preemption victims found for incoming pod."
I0506 15:59:32.413034      12 preemption.go:264] "No preemption candidate is found; preemption is not helpful for scheduling" pod="default/cspod-39"
I0506 15:59:32.413070      12 schedule_one.go:1044] "Unable to schedule pod; no fit; waiting" pod="default/cspod-39" err="0/5 nodes are available: 5 Insufficient cpu. preemption: 0/5 nodes are available: 5 No preemption victims found for incoming pod."
I0506 15:59:32.413622      12 preemption.go:264] "No preemption candidate is found; preemption is not helpful for scheduling" pod="default/cspod-40"
I0506 15:59:32.413655      12 schedule_one.go:1044] "Unable to schedule pod; no fit; waiting" pod="default/cspod-40" err="0/5 nodes are available: 5 Insufficient cpu. preemption: 0/5 nodes are available: 5 No preemption victims found for incoming pod."
I0506 15:59:32.414162      12 preemption.go:264] "No preemption candidate is found; preemption is not helpful for scheduling" pod="default/cspod-41"
I0506 15:59:32.414195      12 schedule_one.go:1044] "Unable to schedule pod; no fit; waiting" pod="default/cspod-41" err="0/5 nodes are available: 5 Insufficient cpu. preemption: 0/5 nodes are available: 5 No preemption victims found for incoming pod."
I0506 15:59:32.414759      12 preemption.go:264] "No preemption candidate is found; preemption is not helpful for scheduling" pod="default/cspod-42"
I0506 15:59:32.414799      12 schedule_one.go:1044] "Unable to schedule pod; no fit; waiting" pod="default/cspod-42" err="0/5 nodes are available: 5 Insufficient cpu. preemption: 0/5 nodes are available: 5 No preemption victims found for incoming pod."
I0506 15:59:32.415390      12 preemption.go:264] "No preemption candidate is found; preemption is not helpful for scheduling" pod="default/cspod-43"
I0506 15:59:32.415423      12 schedule_one.go:1044] "Unable to schedule pod; no fit; waiting" pod="default/cspod-43" err="0/5 nodes are available: 5 Insufficient cpu. preemption: 0/5 nodes are available: 5 No preemption victims found for incoming pod."
I0506 15:59:32.415950      12 preemption.go:264] "No preemption candidate is found; preemption is not helpful for scheduling" pod="default/cspod-44"
I0506 15:59:32.415992      12 schedule_one.go:1044] "Unable to schedule pod; no fit; waiting" pod="default/cspod-44" err="0/5 nodes are available: 5 Insufficient cpu. preemption: 0/5 nodes are available: 5 No preemption victims found for incoming pod."
I0506 15:59:32.416507      12 preemption.go:264] "No preemption candidate is found; preemption is not helpful for scheduling" pod="default/cspod-45"
I0506 15:59:32.416545      12 schedule_one.go:1044] "Unable to schedule pod; no fit; waiting" pod="default/cspod-45" err="0/5 nodes are available: 5 Insufficient cpu. preemption: 0/5 nodes are available: 5 No preemption victims found for incoming pod."
I0506 15:59:32.417111      12 preemption.go:264] "No preemption candidate is found; preemption is not helpful for scheduling" pod="default/cspod-46"
I0506 15:59:32.417145      12 schedule_one.go:1044] "Unable to schedule pod; no fit; waiting" pod="default/cspod-46" err="0/5 nodes are available: 5 Insufficient cpu. preemption: 0/5 nodes are available: 5 No preemption victims found for incoming pod."
I0506 15:59:32.417604      12 preemption.go:264] "No preemption candidate is found; preemption is not helpful for scheduling" pod="default/cspod-47"
I0506 15:59:32.417638      12 schedule_one.go:1044] "Unable to schedule pod; no fit; waiting" pod="default/cspod-47" err="0/5 nodes are available: 5 Insufficient cpu. preemption: 0/5 nodes are available: 5 No preemption victims found for incoming pod."
I0506 15:59:32.418198      12 preemption.go:264] "No preemption candidate is found; preemption is not helpful for scheduling" pod="default/cspod-48"
I0506 15:59:32.418233      12 schedule_one.go:1044] "Unable to schedule pod; no fit; waiting" pod="default/cspod-48" err="0/5 nodes are available: 5 Insufficient cpu. preemption: 0/5 nodes are available: 5 No preemption victims found for incoming pod."
I0506 15:59:32.418965      12 preemption.go:264] "No preemption candidate is found; preemption is not helpful for scheduling" pod="default/cspod-49"
I0506 15:59:32.419001      12 schedule_one.go:1044] "Unable to schedule pod; no fit; waiting" pod="default/cspod-49" err="0/5 nodes are available: 5 Insufficient cpu. preemption: 0/5 nodes are available: 5 No preemption victims found for incoming pod."
I0506 15:59:32.419529      12 preemption.go:264] "No preemption candidate is found; preemption is not helpful for scheduling" pod="default/cspod-50"
I0506 15:59:32.419561      12 schedule_one.go:1044] "Unable to schedule pod; no fit; waiting" pod="default/cspod-50" err="0/5 nodes are available: 5 Insufficient cpu. preemption: 0/5 nodes are available: 5 No preemption victims found for incoming pod."
I0506 15:59:32.420143      12 preemption.go:264] "No preemption candidate is found; preemption is not helpful for scheduling" pod="default/cspod-51"
I0506 15:59:32.420176      12 schedule_one.go:1044] "Unable to schedule pod; no fit; waiting" pod="default/cspod-51" err="0/5 nodes are available: 5 Insufficient cpu. preemption: 0/5 nodes are available: 5 No preemption victims found for incoming pod."
I0506 15:59:32.420733      12 preemption.go:264] "No preemption candidate is found; preemption is not helpful for scheduling" pod="default/cspod-52"
I0506 15:59:32.420770      12 schedule_one.go:1044] "Unable to schedule pod; no fit; waiting" pod="default/cspod-52" err="0/5 nodes are available: 5 Insufficient cpu. preemption: 0/5 nodes are available: 5 No preemption victims found for incoming pod."
I0506 15:59:32.421258      12 preemption.go:264] "No preemption candidate is found; preemption is not helpful for scheduling" pod="default/cspod-53"
I0506 15:59:32.421291      12 schedule_one.go:1044] "Unable to schedule pod; no fit; waiting" pod="default/cspod-53" err="0/5 nodes are available: 5 Insufficient cpu. preemption: 0/5 nodes are available: 5 No preemption victims found for incoming pod."
I0506 15:59:32.421916      12 preemption.go:264] "No preemption candidate is found; preemption is not helpful for scheduling" pod="default/cspod-54"
I0506 15:59:32.421996      12 schedule_one.go:1044] "Unable to schedule pod; no fit; waiting" pod="default/cspod-54" err="0/5 nodes are available: 5 Insufficient cpu. preemption: 0/5 nodes are available: 5 No preemption victims found for incoming pod."
I0506 15:59:32.447571      12 schedule_one.go:314] "Successfully bound pod to node" pod="default/cspod-55" node="csnode-2" evaluatedNodes=5 feasibleNodes=5
I0506 15:59:32.447717      12 schedule_one.go:314] "Successfully bound pod to node" pod="default/cspod-56" node="csnode-4" evaluatedNodes=5 feasibleNodes=4
I0506 15:59:32.447867      12 schedule_one.go:314] "Successfully bound pod to node" pod="default/cspod-57" node="csnode-1" evaluatedNodes=5 feasibleNodes=3
I0506 15:59:32.447972      12 schedule_one.go:314] "Successfully bound pod to node" pod="default/cspod-58" node="csnode-0" evaluatedNodes=5 feasibleNodes=2
I0506 15:59:32.448016      12 preemption.go:264] "No preemption candidate is found; preemption is not helpful for scheduling" pod="default/cspod-60"
I0506 15:59:32.448058      12 schedule_one.go:1044] "Unable to schedule pod; no fit; waiting" pod="default/cspod-60" err="0/5 nodes are available: 5 Insufficient cpu. preemption: 0/5 nodes are available: 5 No preemption victims found for incoming pod."
I0506 15:59:32.448166      12 schedule_one.go:314] "Successfully bound pod to node" pod="default/cspod-59" node="csnode-3" evaluatedNodes=5 feasibleNodes=1
I0506 15:59:32.448894      12 preemption.go:264] "No preemption candidate is found; preemption is not helpful for scheduling" pod="default/cspod-61"
I0506 15:59:32.448930      12 schedule_one.go:1044] "Unable to schedule pod; no fit; waiting" pod="default/cspod-61" err="0/5 nodes are available: 5 Insufficient cpu. preemption: 0/5 nodes are available: 5 No preemption victims found for incoming pod."
I0506 15:59:32.449475      12 preemption.go:264] "No preemption candidate is found; preemption is not helpful for scheduling" pod="default/cspod-62"
I0506 15:59:32.449507      12 schedule_one.go:1044] "Unable to schedule pod; no fit; waiting" pod="default/cspod-62" err="0/5 nodes are available: 5 Insufficient cpu. preemption: 0/5 nodes are available: 5 No preemption victims found for incoming pod."
I0506 15:59:32.450055      12 preemption.go:264] "No preemption candidate is found; preemption is not helpful for scheduling" pod="default/cspod-63"
I0506 15:59:32.450090      12 schedule_one.go:1044] "Unable to schedule pod; no fit; waiting" pod="default/cspod-63" err="0/5 nodes are available: 5 Insufficient cpu. preemption: 0/5 nodes are available: 5 No preemption victims found for incoming pod."
I0506 15:59:32.450786      12 preemption.go:264] "No preemption candidate is found; preemption is not helpful for scheduling" pod="default/cspod-64"
I0506 15:59:32.450819      12 schedule_one.go:1044] "Unable to schedule pod; no fit; waiting" pod="default/cspod-64" err="0/5 nodes are available: 5 Insufficient cpu. preemption: 0/5 nodes are available: 5 No preemption victims found for incoming pod."
I0506 15:59:32.451347      12 preemption.go:264] "No preemption candidate is found; preemption is not helpful for scheduling" pod="default/cspod-65"
I0506 15:59:32.451385      12 schedule_one.go:1044] "Unable to schedule pod; no fit; waiting" pod="default/cspod-65" err="0/5 nodes are available: 5 Insufficient cpu. preemption: 0/5 nodes are available: 5 No preemption victims found for incoming pod."
I0506 15:59:32.451943      12 preemption.go:264] "No preemption candidate is found; preemption is not helpful for scheduling" pod="default/cspod-66"
I0506 15:59:32.451977      12 schedule_one.go:1044] "Unable to schedule pod; no fit; waiting" pod="default/cspod-66" err="0/5 nodes are available: 5 Insufficient cpu. preemption: 0/5 nodes are available: 5 No preemption victims found for incoming pod."
I0506 15:59:32.452491      12 preemption.go:264] "No preemption candidate is found; preemption is not helpful for scheduling" pod="default/cspod-67"
I0506 15:59:32.452524      12 schedule_one.go:1044] "Unable to schedule pod; no fit; waiting" pod="default/cspod-67" err="0/5 nodes are available: 5 Insufficient cpu. preemption: 0/5 nodes are available: 5 No preemption victims found for incoming pod."
I0506 15:59:32.452999      12 preemption.go:264] "No preemption candidate is found; preemption is not helpful for scheduling" pod="default/cspod-68"
I0506 15:59:32.453031      12 schedule_one.go:1044] "Unable to schedule pod; no fit; waiting" pod="default/cspod-68" err="0/5 nodes are available: 5 Insufficient cpu. preemption: 0/5 nodes are available: 5 No preemption victims found for incoming pod."
I0506 15:59:32.453563      12 preemption.go:264] "No preemption candidate is found; preemption is not helpful for scheduling" pod="default/cspod-69"
I0506 15:59:32.453599      12 schedule_one.go:1044] "Unable to schedule pod; no fit; waiting" pod="default/cspod-69" err="0/5 nodes are available: 5 Insufficient cpu. preemption: 0/5 nodes are available: 5 No preemption victims found for incoming pod."
I0506 15:59:32.469610      12 schedule_one.go:314] "Successfully bound pod to node" pod="default/cspod-11" node="csnode-0" evaluatedNodes=5 feasibleNodes=3
I0506 15:59:32.469642      12 schedule_one.go:314] "Successfully bound pod to node" pod="default/cspod-10" node="csnode-0" evaluatedNodes=5 feasibleNodes=1
I0506 15:59:32.469890      12 schedule_one.go:314] "Successfully bound pod to node" pod="default/cspod-13" node="csnode-3" evaluatedNodes=5 feasibleNodes=4
I0506 15:59:32.469982      12 schedule_one.go:314] "Successfully bound pod to node" pod="default/cspod-14" node="csnode-4" evaluatedNodes=5 feasibleNodes=3
I0506 15:59:32.470032      12 schedule_one.go:314] "Successfully bound pod to node" pod="default/cspod-12" node="csnode-3" evaluatedNodes=5 feasibleNodes=4
I0506 15:59:32.470334      12 preemption.go:264] "No preemption candidate is found; preemption is not helpful for scheduling" pod="default/cspod-20"
I0506 15:59:32.470818      12 schedule_one.go:1044] "Unable to schedule pod; no fit; waiting" pod="default/cspod-20" err="0/5 nodes are available: 5 Insufficient cpu. preemption: 0/5 nodes are available: 5 No preemption victims found for incoming pod."
I0506 15:59:32.470957      12 schedule_one.go:314] "Successfully bound pod to node" pod="default/cspod-15" node="csnode-4" evaluatedNodes=5 feasibleNodes=3
I0506 15:59:32.471007      12 schedule_one.go:314] "Successfully bound pod to node" pod="default/cspod-16" node="csnode-1" evaluatedNodes=5 feasibleNodes=2
I0506 15:59:32.471144      12 schedule_one.go:314] "Successfully bound pod to node" pod="default/cspod-17" node="csnode-1" evaluatedNodes=5 feasibleNodes=2
I0506 15:59:32.471476      12 schedule_one.go:314] "Successfully bound pod to node" pod="default/cspod-19" node="csnode-2" evaluatedNodes=5 feasibleNodes=1
I0506 15:59:32.471822      12 schedule_one.go:314] "Successfully bound pod to node" pod="default/cspod-18" node="csnode-2" evaluatedNodes=5 feasibleNodes=1
I0506 15:59:32.471860      12 preemption.go:264] "No preemption candidate is found; preemption is not helpful for scheduling" pod="default/cspod-21"
I0506 15:59:32.471883      12 schedule_one.go:1044] "Unable to schedule pod; no fit; waiting" pod="default/cspod-21" err="0/5 nodes are available: 5 Insufficient cpu. preemption: 0/5 nodes are available: 5 No preemption victims found for incoming pod."
I0506 15:59:32.472937      12 preemption.go:264] "No preemption candidate is found; preemption is not helpful for scheduling" pod="default/cspod-22"
I0506 15:59:32.472982      12 schedule_one.go:1044] "Unable to schedule pod; no fit; waiting" pod="default/cspod-22" err="0/5 nodes are available: 5 Insufficient cpu. preemption: 0/5 nodes are available: 5 No preemption victims found for incoming pod."
I0506 15:59:32.473553      12 preemption.go:264] "No preemption candidate is found; preemption is not helpful for scheduling" pod="default/cspod-23"
I0506 15:59:32.473590      12 schedule_one.go:1044] "Unable to schedule pod; no fit; waiting" pod="default/cspod-23" err="0/5 nodes are available: 5 Insufficient cpu. preemption: 0/5 nodes are available: 5 No preemption victims found for incoming pod."
I0506 15:59:32.474161      12 preemption.go:264] "No preemption candidate is found; preemption is not helpful for scheduling" pod="default/cspod-24"
I0506 15:59:32.474195      12 schedule_one.go:1044] "Unable to schedule pod; no fit; waiting" pod="default/cspod-24" err="0/5 nodes are available: 5 Insufficient cpu. preemption: 0/5 nodes are available: 5 No preemption victims found for incoming pod."
I0506 15:59:32.474695      12 preemption.go:264] "No preemption candidate is found; preemption is not helpful for scheduling" pod="default/cspod-25"
I0506 15:59:32.474737      12 schedule_one.go:1044] "Unable to schedule pod; no fit; waiting" pod="default/cspod-25" err="0/5 nodes are available: 5 Insufficient cpu. preemption: 0/5 nodes are available: 5 No preemption victims found for incoming pod."
I0506 15:59:32.475329      12 preemption.go:264] "No preemption candidate is found; preemption is not helpful for scheduling" pod="default/cspod-26"
I0506 15:59:32.475367      12 schedule_one.go:1044] "Unable to schedule pod; no fit; waiting" pod="default/cspod-26" err="0/5 nodes are available: 5 Insufficient cpu. preemption: 0/5 nodes are available: 5 No preemption victims found for incoming pod."
I0506 15:59:32.476017      12 preemption.go:264] "No preemption candidate is found; preemption is not helpful for scheduling" pod="default/cspod-27"
I0506 15:59:32.476059      12 schedule_one.go:1044] "Unable to schedule pod; no fit; waiting" pod="default/cspod-27" err="0/5 nodes are available: 5 Insufficient cpu. preemption: 0/5 nodes are available: 5 No preemption victims found for incoming pod."
I0506 15:59:32.476647      12 preemption.go:264] "No preemption candidate is found; preemption is not helpful for scheduling" pod="default/cspod-28"
I0506 15:59:32.476681      12 schedule_one.go:1044] "Unable to schedule pod; no fit; waiting" pod="default/cspod-28" err="0/5 nodes are available: 5 Insufficient cpu. preemption: 0/5 nodes are available: 5 No preemption victims found for incoming pod."
I0506 15:59:32.477355      12 preemption.go:264] "No preemption candidate is found; preemption is not helpful for scheduling" pod="default/cspod-29"
I0506 15:59:32.477391      12 schedule_one.go:1044] "Unable to schedule pod; no fit; waiting" pod="default/cspod-29" err="0/5 nodes are available: 5 Insufficient cpu. preemption: 0/5 nodes are available: 5 No preemption victims found for incoming pod."
I0506 15:59:32.477921      12 preemption.go:264] "No preemption candidate is found; preemption is not helpful for scheduling" pod="default/cspod-30"
I0506 15:59:32.477960      12 schedule_one.go:1044] "Unable to schedule pod; no fit; waiting" pod="default/cspod-30" err="0/5 nodes are available: 5 Insufficient cpu. preemption: 0/5 nodes are available: 5 No preemption victims found for incoming pod."
I0506 15:59:32.478524      12 preemption.go:264] "No preemption candidate is found; preemption is not helpful for scheduling" pod="default/cspod-31"
I0506 15:59:32.478557      12 schedule_one.go:1044] "Unable to schedule pod; no fit; waiting" pod="default/cspod-31" err="0/5 nodes are available: 5 Insufficient cpu. preemption: 0/5 nodes are available: 5 No preemption victims found for incoming pod."
I0506 15:59:32.479097      12 preemption.go:264] "No preemption candidate is found; preemption is not helpful for scheduling" pod="default/cspod-32"
I0506 15:59:32.479129      12 schedule_one.go:1044] "Unable to schedule pod; no fit; waiting" pod="default/cspod-32" err="0/5 nodes are available: 5 Insufficient cpu. preemption: 0/5 nodes are available: 5 No preemption victims found for incoming pod."
I0506 15:59:32.479702      12 preemption.go:264] "No preemption candidate is found; preemption is not helpful for scheduling" pod="default/cspod-33"
I0506 15:59:32.479737      12 schedule_one.go:1044] "Unable to schedule pod; no fit; waiting" pod="default/cspod-33" err="0/5 nodes are available: 5 Insufficient cpu. preemption: 0/5 nodes are available: 5 No preemption victims found for incoming pod."
I0506 15:59:32.480329      12 preemption.go:264] "No preemption candidate is found; preemption is not helpful for scheduling" pod="default/cspod-34"
I0506 15:59:32.480366      12 schedule_one.go:1044] "Unable to schedule pod; no fit; waiting" pod="default/cspod-34" err="0/5 nodes are available: 5 Insufficient cpu. preemption: 0/5 nodes are available: 5 No preemption victims found for incoming pod."
I0506 15:59:32.481027      12 preemption.go:264] "No preemption candidate is found; preemption is not helpful for scheduling" pod="default/cspod-35"
I0506 15:59:32.481051      12 schedule_one.go:1044] "Unable to schedule pod; no fit; waiting" pod="default/cspod-35" err="0/5 nodes are available: 5 Insufficient cpu. preemption: 0/5 nodes are available: 5 No preemption victims found for incoming pod."
I0506 15:59:32.481604      12 preemption.go:264] "No preemption candidate is found; preemption is not helpful for scheduling" pod="default/cspod-36"
I0506 15:59:32.481640      12 schedule_one.go:1044] "Unable to schedule pod; no fit; waiting" pod="default/cspod-36" err="0/5 nodes are available: 5 Insufficient cpu. preemption: 0/5 nodes are available: 5 No preemption victims found for incoming pod."
I0506 15:59:32.482187      12 preemption.go:264] "No preemption candidate is found; preemption is not helpful for scheduling" pod="default/cspod-37"
I0506 15:59:32.482223      12 schedule_one.go:1044] "Unable to schedule pod; no fit; waiting" pod="default/cspod-37" err="0/5 nodes are available: 5 Insufficient cpu. preemption: 0/5 nodes are available: 5 No preemption victims found for incoming pod."
I0506 15:59:32.482704      12 preemption.go:264] "No preemption candidate is found; preemption is not helpful for scheduling" pod="default/cspod-38"
I0506 15:59:32.482737      12 schedule_one.go:1044] "Unable to schedule pod; no fit; waiting" pod="default/cspod-38" err="0/5 nodes are available: 5 Insufficient cpu. preemption: 0/5 nodes are available: 5 No preemption victims found for incoming pod."
I0506 15:59:32.483273      12 preemption.go:264] "No preemption candidate is found; preemption is not helpful for scheduling" pod="default/cspod-39"
I0506 15:59:32.483312      12 schedule_one.go:1044] "Unable to schedule pod; no fit; waiting" pod="default/cspod-39" err="0/5 nodes are available: 5 Insufficient cpu. preemption: 0/5 nodes are available: 5 No preemption victims found for incoming pod."
I0506 15:59:32.483904      12 preemption.go:264] "No preemption candidate is found; preemption is not helpful for scheduling" pod="default/cspod-40"
I0506 15:59:32.483945      12 schedule_one.go:1044] "Unable to schedule pod; no fit; waiting" pod="default/cspod-40" err="0/5 nodes are available: 5 Insufficient cpu. preemption: 0/5 nodes are available: 5 No preemption victims found for incoming pod."
I0506 15:59:32.484603      12 preemption.go:264] "No preemption candidate is found; preemption is not helpful for scheduling" pod="default/cspod-41"
I0506 15:59:32.484637      12 schedule_one.go:1044] "Unable to schedule pod; no fit; waiting" pod="default/cspod-41" err="0/5 nodes are available: 5 Insufficient cpu. preemption: 0/5 nodes are available: 5 No preemption victims found for incoming pod."
I0506 15:59:32.485201      12 preemption.go:264] "No preemption candidate is found; preemption is not helpful for scheduling" pod="default/cspod-42"
I0506 15:59:32.485237      12 schedule_one.go:1044] "Unable to schedule pod; no fit; waiting" pod="default/cspod-42" err="0/5 nodes are available: 5 Insufficient cpu. preemption: 0/5 nodes are available: 5 No preemption victims found for incoming pod."
I0506 15:59:32.485762      12 preemption.go:264] "No preemption candidate is found; preemption is not helpful for scheduling" pod="default/cspod-43"
I0506 15:59:32.485795      12 schedule_one.go:1044] "Unable to schedule pod; no fit; waiting" pod="default/cspod-43" err="0/5 nodes are available: 5 Insufficient cpu. preemption: 0/5 nodes are available: 5 No preemption victims found for incoming pod."
I0506 15:59:32.486380      12 preemption.go:264] "No preemption candidate is found; preemption is not helpful for scheduling" pod="default/cspod-44"
I0506 15:59:32.486413      12 schedule_one.go:1044] "Unable to schedule pod; no fit; waiting" pod="default/cspod-44" err="0/5 nodes are available: 5 Insufficient cpu. preemption: 0/5 nodes are available: 5 No preemption victims found for incoming pod."
I0506 15:59:32.487172      12 preemption.go:264] "No preemption candidate is found; preemption is not helpful for scheduling" pod="default/cspod-45"
I0506 15:59:32.487207      12 schedule_one.go:1044] "Unable to schedule pod; no fit; waiting" pod="default/cspod-45" err="0/5 nodes are available: 5 Insufficient cpu. preemption: 0/5 nodes are available: 5 No preemption victims found for incoming pod."
I0506 15:59:32.487795      12 preemption.go:264] "No preemption candidate is found; preemption is not helpful for scheduling" pod="default/cspod-46"
I0506 15:59:32.487832      12 schedule_one.go:1044] "Unable to schedule pod; no fit; waiting" pod="default/cspod-46" err="0/5 nodes are available: 5 Insufficient cpu. preemption: 0/5 nodes are available: 5 No preemption victims found for incoming pod."
I0506 15:59:32.488409      12 preemption.go:264] "No preemption candidate is found; preemption is not helpful for scheduling" pod="default/cspod-47"
I0506 15:59:32.488445      12 schedule_one.go:1044] "Unable to schedule pod; no fit; waiting" pod="default/cspod-47" err="0/5 nodes are available: 5 Insufficient cpu. preemption: 0/5 nodes are available: 5 No preemption victims found for incoming pod."
I0506 15:59:32.488983      12 preemption.go:264] "No preemption candidate is found; preemption is not helpful for scheduling" pod="default/cspod-48"
I0506 15:59:32.489047      12 schedule_one.go:1044] "Unable to schedule pod; no fit; waiting" pod="default/cspod-48" err="0/5 nodes are available: 5 Insufficient cpu. preemption: 0/5 nodes are available: 5 No preemption victims found for incoming pod."
I0506 15:59:32.489611      12 preemption.go:264] "No preemption candidate is found; preemption is not helpful for scheduling" pod="default/cspod-49"
I0506 15:59:32.489652      12 schedule_one.go:1044] "Unable to schedule pod; no fit; waiting" pod="default/cspod-49" err="0/5 nodes are available: 5 Insufficient cpu. preemption: 0/5 nodes are available: 5 No preemption victims found for incoming pod."
I0506 15:59:32.498861      12 preemption.go:264] "No preemption candidate is found; preemption is not helpful for scheduling" pod="default/cspod-50"
I0506 15:59:32.498895      12 schedule_one.go:1044] "Unable to schedule pod; no fit; waiting" pod="default/cspod-50" err="0/5 nodes are available: 5 Insufficient cpu. preemption: 0/5 nodes are available: 5 No preemption victims found for incoming pod."
I0506 15:59:32.519129      12 preemption.go:264] "No preemption candidate is found; preemption is not helpful for scheduling" pod="default/cspod-51"
I0506 15:59:32.519204      12 schedule_one.go:1044] "Unable to schedule pod; no fit; waiting" pod="default/cspod-51" err="0/5 nodes are available: 5 Insufficient cpu. preemption: 0/5 nodes are available: 5 No preemption victims found for incoming pod."
I0506 15:59:32.539451      12 preemption.go:264] "No preemption candidate is found; preemption is not helpful for scheduling" pod="default/cspod-52"
I0506 15:59:32.539495      12 schedule_one.go:1044] "Unable to schedule pod; no fit; waiting" pod="default/cspod-52" err="0/5 nodes are available: 5 Insufficient cpu. preemption: 0/5 nodes are available: 5 No preemption victims found for incoming pod."
I0506 15:59:32.559662      12 preemption.go:264] "No preemption candidate is found; preemption is not helpful for scheduling" pod="default/cspod-53"
I0506 15:59:32.559754      12 schedule_one.go:1044] "Unable to schedule pod; no fit; waiting" pod="default/cspod-53" err="0/5 nodes are available: 5 Insufficient cpu. preemption: 0/5 nodes are available: 5 No preemption victims found for incoming pod."
I0506 15:59:32.579094      12 preemption.go:264] "No preemption candidate is found; preemption is not helpful for scheduling" pod="default/cspod-54"
I0506 15:59:32.579138      12 schedule_one.go:1044] "Unable to schedule pod; no fit; waiting" pod="default/cspod-54" err="0/5 nodes are available: 5 Insufficient cpu. preemption: 0/5 nodes are available: 5 No preemption victims found for incoming pod."
I0506 15:59:32.599140      12 preemption.go:264] "No preemption candidate is found; preemption is not helpful for scheduling" pod="default/cspod-60"
I0506 15:59:32.599182      12 schedule_one.go:1044] "Unable to schedule pod; no fit; waiting" pod="default/cspod-60" err="0/5 nodes are available: 5 Insufficient cpu. preemption: 0/5 nodes are available: 5 No preemption victims found for incoming pod."
I0506 15:59:32.619315      12 preemption.go:264] "No preemption candidate is found; preemption is not helpful for scheduling" pod="default/cspod-61"
I0506 15:59:32.619359      12 schedule_one.go:1044] "Unable to schedule pod; no fit; waiting" pod="default/cspod-61" err="0/5 nodes are available: 5 Insufficient cpu. preemption: 0/5 nodes are available: 5 No preemption victims found for incoming pod."
I0506 15:59:32.639839      12 preemption.go:264] "No preemption candidate is found; preemption is not helpful for scheduling" pod="default/cspod-62"
I0506 15:59:32.639891      12 schedule_one.go:1044] "Unable to schedule pod; no fit; waiting" pod="default/cspod-62" err="0/5 nodes are available: 5 Insufficient cpu. preemption: 0/5 nodes are available: 5 No preemption victims found for incoming pod."
I0506 15:59:32.659250      12 preemption.go:264] "No preemption candidate is found; preemption is not helpful for scheduling" pod="default/cspod-63"
I0506 15:59:32.659343      12 schedule_one.go:1044] "Unable to schedule pod; no fit; waiting" pod="default/cspod-63" err="0/5 nodes are available: 5 Insufficient cpu. preemption: 0/5 nodes are available: 5 No preemption victims found for incoming pod."
I0506 15:59:32.679347      12 preemption.go:264] "No preemption candidate is found; preemption is not helpful for scheduling" pod="default/cspod-64"
I0506 15:59:32.679391      12 schedule_one.go:1044] "Unable to schedule pod; no fit; waiting" pod="default/cspod-64" err="0/5 nodes are available: 5 Insufficient cpu. preemption: 0/5 nodes are available: 5 No preemption victims found for incoming pod."
I0506 15:59:32.699576      12 preemption.go:264] "No preemption candidate is found; preemption is not helpful for scheduling" pod="default/cspod-65"
I0506 15:59:32.699623      12 schedule_one.go:1044] "Unable to schedule pod; no fit; waiting" pod="default/cspod-65" err="0/5 nodes are available: 5 Insufficient cpu. preemption: 0/5 nodes are available: 5 No preemption victims found for incoming pod."
I0506 15:59:32.719779      12 preemption.go:264] "No preemption candidate is found; preemption is not helpful for scheduling" pod="default/cspod-66"
I0506 15:59:32.719836      12 schedule_one.go:1044] "Unable to schedule pod; no fit; waiting" pod="default/cspod-66" err="0/5 nodes are available: 5 Insufficient cpu. preemption: 0/5 nodes are available: 5 No preemption victims found for incoming pod."
I0506 15:59:32.739409      12 preemption.go:264] "No preemption candidate is found; preemption is not helpful for scheduling" pod="default/cspod-67"
I0506 15:59:32.739459      12 schedule_one.go:1044] "Unable to schedule pod; no fit; waiting" pod="default/cspod-67" err="0/5 nodes are available: 5 Insufficient cpu. preemption: 0/5 nodes are available: 5 No preemption victims found for incoming pod."
I0506 15:59:32.759880      12 preemption.go:264] "No preemption candidate is found; preemption is not helpful for scheduling" pod="default/cspod-68"
I0506 15:59:32.759934      12 schedule_one.go:1044] "Unable to schedule pod; no fit; waiting" pod="default/cspod-68" err="0/5 nodes are available: 5 Insufficient cpu. preemption: 0/5 nodes are available: 5 No preemption victims found for incoming pod."
I0506 15:59:32.779296      12 preemption.go:264] "No preemption candidate is found; preemption is not helpful for scheduling" pod="default/cspod-69"
I0506 15:59:32.779351      12 schedule_one.go:1044] "Unable to schedule pod; no fit; waiting" pod="default/cspod-69" err="0/5 nodes are available: 5 Insufficient cpu. preemption: 0/5 nodes are available: 5 No preemption victims found for incoming pod."
I0506 15:59:32.814161      12 preemption.go:264] "No preemption candidate is found; preemption is not helpful for scheduling" pod="default/cspod-20"
I0506 15:59:32.814208      12 schedule_one.go:1044] "Unable to schedule pod; no fit; waiting" pod="default/cspod-20" err="0/5 nodes are available: 5 Insufficient cpu. preemption: 0/5 nodes are available: 5 No preemption victims found for incoming pod."
I0506 15:59:32.814378      12 preemption.go:264] "No preemption candidate is found; preemption is not helpful for scheduling" pod="default/cspod-21"
I0506 15:59:32.814418      12 schedule_one.go:1044] "Unable to schedule pod; no fit; waiting" pod="default/cspod-21" err="0/5 nodes are available: 5 Insufficient cpu. preemption: 0/5 nodes are available: 5 No preemption victims found for incoming pod."
I0506 15:59:32.820172      12 preemption.go:264] "No preemption candidate is found; preemption is not helpful for scheduling" pod="default/cspod-22"
I0506 15:59:32.820218      12 schedule_one.go:1044] "Unable to schedule pod; no fit; waiting" pod="default/cspod-22" err="0/5 nodes are available: 5 Insufficient cpu. preemption: 0/5 nodes are available: 5 No preemption victims found for incoming pod."
I0506 15:59:32.839435      12 preemption.go:264] "No preemption candidate is found; preemption is not helpful for scheduling" pod="default/cspod-23"
I0506 15:59:32.839482      12 schedule_one.go:1044] "Unable to schedule pod; no fit; waiting" pod="default/cspod-23" err="0/5 nodes are available: 5 Insufficient cpu. preemption: 0/5 nodes are available: 5 No preemption victims found for incoming pod."
I0506 15:59:32.859324      12 preemption.go:264] "No preemption candidate is found; preemption is not helpful for scheduling" pod="default/cspod-24"
I0506 15:59:32.859396      12 schedule_one.go:1044] "Unable to schedule pod; no fit; waiting" pod="default/cspod-24" err="0/5 nodes are available: 5 Insufficient cpu. preemption: 0/5 nodes are available: 5 No preemption victims found for incoming pod."
I0506 15:59:32.879399      12 preemption.go:264] "No preemption candidate is found; preemption is not helpful for scheduling" pod="default/cspod-25"
I0506 15:59:32.879441      12 schedule_one.go:1044] "Unable to schedule pod; no fit; waiting" pod="default/cspod-25" err="0/5 nodes are available: 5 Insufficient cpu. preemption: 0/5 nodes are available: 5 No preemption victims found for incoming pod."
I0506 15:59:32.899603      12 preemption.go:264] "No preemption candidate is found; preemption is not helpful for scheduling" pod="default/cspod-26"
I0506 15:59:32.899648      12 schedule_one.go:1044] "Unable to schedule pod; no fit; waiting" pod="default/cspod-26" err="0/5 nodes are available: 5 Insufficient cpu. preemption: 0/5 nodes are available: 5 No preemption victims found for incoming pod."
I0506 15:59:32.919734      12 preemption.go:264] "No preemption candidate is found; preemption is not helpful for scheduling" pod="default/cspod-27"
I0506 15:59:32.919777      12 schedule_one.go:1044] "Unable to schedule pod; no fit; waiting" pod="default/cspod-27" err="0/5 nodes are available: 5 Insufficient cpu. preemption: 0/5 nodes are available: 5 No preemption victims found for incoming pod."
I0506 15:59:32.938681      12 preemption.go:264] "No preemption candidate is found; preemption is not helpful for scheduling" pod="default/cspod-28"
I0506 15:59:32.938723      12 schedule_one.go:1044] "Unable to schedule pod; no fit; waiting" pod="default/cspod-28" err="0/5 nodes are available: 5 Insufficient cpu. preemption: 0/5 nodes are available: 5 No preemption victims found for incoming pod."
I0506 15:59:32.958921      12 preemption.go:264] "No preemption candidate is found; preemption is not helpful for scheduling" pod="default/cspod-29"
I0506 15:59:32.958968      12 schedule_one.go:1044] "Unable to schedule pod; no fit; waiting" pod="default/cspod-29" err="0/5 nodes are available: 5 Insufficient cpu. preemption: 0/5 nodes are available: 5 No preemption victims found for incoming pod."
I0506 15:59:32.979486      12 preemption.go:264] "No preemption candidate is found; preemption is not helpful for scheduling" pod="default/cspod-30"
I0506 15:59:32.979531      12 schedule_one.go:1044] "Unable to schedule pod; no fit; waiting" pod="default/cspod-30" err="0/5 nodes are available: 5 Insufficient cpu. preemption: 0/5 nodes are available: 5 No preemption victims found for incoming pod."
I0506 15:59:32.999789      12 preemption.go:264] "No preemption candidate is found; preemption is not helpful for scheduling" pod="default/cspod-31"
I0506 15:59:32.999838      12 schedule_one.go:1044] "Unable to schedule pod; no fit; waiting" pod="default/cspod-31" err="0/5 nodes are available: 5 Insufficient cpu. preemption: 0/5 nodes are available: 5 No preemption victims found for incoming pod."
I0506 15:59:33.019921      12 preemption.go:264] "No preemption candidate is found; preemption is not helpful for scheduling" pod="default/cspod-32"
I0506 15:59:33.019968      12 schedule_one.go:1044] "Unable to schedule pod; no fit; waiting" pod="default/cspod-32" err="0/5 nodes are available: 5 Insufficient cpu. preemption: 0/5 nodes are available: 5 No preemption victims found for incoming pod."
I0506 15:59:33.038912      12 preemption.go:264] "No preemption candidate is found; preemption is not helpful for scheduling" pod="default/cspod-33"
I0506 15:59:33.038956      12 schedule_one.go:1044] "Unable to schedule pod; no fit; waiting" pod="default/cspod-33" err="0/5 nodes are available: 5 Insufficient cpu. preemption: 0/5 nodes are available: 5 No preemption victims found for incoming pod."
I0506 15:59:33.059196      12 preemption.go:264] "No preemption candidate is found; preemption is not helpful for scheduling" pod="default/cspod-34"
I0506 15:59:33.059237      12 schedule_one.go:1044] "Unable to schedule pod; no fit; waiting" pod="default/cspod-34" err="0/5 nodes are available: 5 Insufficient cpu. preemption: 0/5 nodes are available: 5 No preemption victims found for incoming pod."
I0506 15:59:33.079516      12 preemption.go:264] "No preemption candidate is found; preemption is not helpful for scheduling" pod="default/cspod-35"
I0506 15:59:33.079557      12 schedule_one.go:1044] "Unable to schedule pod; no fit; waiting" pod="default/cspod-35" err="0/5 nodes are available: 5 Insufficient cpu. preemption: 0/5 nodes are available: 5 No preemption victims found for incoming pod."
I0506 15:59:33.099738      12 preemption.go:264] "No preemption candidate is found; preemption is not helpful for scheduling" pod="default/cspod-36"
I0506 15:59:33.099787      12 schedule_one.go:1044] "Unable to schedule pod; no fit; waiting" pod="default/cspod-36" err="0/5 nodes are available: 5 Insufficient cpu. preemption: 0/5 nodes are available: 5 No preemption victims found for incoming pod."
I0506 15:59:33.119212      12 preemption.go:264] "No preemption candidate is found; preemption is not helpful for scheduling" pod="default/cspod-37"
I0506 15:59:33.119274      12 schedule_one.go:1044] "Unable to schedule pod; no fit; waiting" pod="default/cspod-37" err="0/5 nodes are available: 5 Insufficient cpu. preemption: 0/5 nodes are available: 5 No preemption victims found for incoming pod."
I0506 15:59:33.139414      12 preemption.go:264] "No preemption candidate is found; preemption is not helpful for scheduling" pod="default/cspod-38"
I0506 15:59:33.139463      12 schedule_one.go:1044] "Unable to schedule pod; no fit; waiting" pod="default/cspod-38" err="0/5 nodes are available: 5 Insufficient cpu. preemption: 0/5 nodes are available: 5 No preemption victims found for incoming pod."
I0506 15:59:33.159735      12 preemption.go:264] "No preemption candidate is found; preemption is not helpful for scheduling" pod="default/cspod-39"
I0506 15:59:33.159778      12 schedule_one.go:1044] "Unable to schedule pod; no fit; waiting" pod="default/cspod-39" err="0/5 nodes are available: 5 Insufficient cpu. preemption: 0/5 nodes are available: 5 No preemption victims found for incoming pod."
I0506 15:59:33.178815      12 preemption.go:264] "No preemption candidate is found; preemption is not helpful for scheduling" pod="default/cspod-40"
I0506 15:59:33.178864      12 schedule_one.go:1044] "Unable to schedule pod; no fit; waiting" pod="default/cspod-40" err="0/5 nodes are available: 5 Insufficient cpu. preemption: 0/5 nodes are available: 5 No preemption victims found for incoming pod."
I0506 15:59:33.199185      12 preemption.go:264] "No preemption candidate is found; preemption is not helpful for scheduling" pod="default/cspod-41"
I0506 15:59:33.199236      12 schedule_one.go:1044] "Unable to schedule pod; no fit; waiting" pod="default/cspod-41" err="0/5 nodes are available: 5 Insufficient cpu. preemption: 0/5 nodes are available: 5 No preemption victims found for incoming pod."
I0506 15:59:33.219537      12 preemption.go:264] "No preemption candidate is found; preemption is not helpful for scheduling" pod="default/cspod-42"
I0506 15:59:33.219587      12 schedule_one.go:1044] "Unable to schedule pod; no fit; waiting" pod="default/cspod-42" err="0/5 nodes are available: 5 Insufficient cpu. preemption: 0/5 nodes are available: 5 No preemption victims found for incoming pod."
I0506 15:59:33.239657      12 preemption.go:264] "No preemption candidate is found; preemption is not helpful for scheduling" pod="default/cspod-43"
I0506 15:59:33.239732      12 schedule_one.go:1044] "Unable to schedule pod; no fit; waiting" pod="default/cspod-43" err="0/5 nodes are available: 5 Insufficient cpu. preemption: 0/5 nodes are available: 5 No preemption victims found for incoming pod."
I0506 15:59:33.258797      12 preemption.go:264] "No preemption candidate is found; preemption is not helpful for scheduling" pod="default/cspod-44"
I0506 15:59:33.258842      12 schedule_one.go:1044] "Unable to schedule pod; no fit; waiting" pod="default/cspod-44" err="0/5 nodes are available: 5 Insufficient cpu. preemption: 0/5 nodes are available: 5 No preemption victims found for incoming pod."
I0506 15:59:33.279254      12 preemption.go:264] "No preemption candidate is found; preemption is not helpful for scheduling" pod="default/cspod-45"
I0506 15:59:33.279304      12 schedule_one.go:1044] "Unable to schedule pod; no fit; waiting" pod="default/cspod-45" err="0/5 nodes are available: 5 Insufficient cpu. preemption: 0/5 nodes are available: 5 No preemption victims found for incoming pod."
I0506 15:59:33.299555      12 preemption.go:264] "No preemption candidate is found; preemption is not helpful for scheduling" pod="default/cspod-46"
I0506 15:59:33.299606      12 schedule_one.go:1044] "Unable to schedule pod; no fit; waiting" pod="default/cspod-46" err="0/5 nodes are available: 5 Insufficient cpu. preemption: 0/5 nodes are available: 5 No preemption victims found for incoming pod."
I0506 15:59:33.318790      12 preemption.go:264] "No preemption candidate is found; preemption is not helpful for scheduling" pod="default/cspod-47"
I0506 15:59:33.318854      12 schedule_one.go:1044] "Unable to schedule pod; no fit; waiting" pod="default/cspod-47" err="0/5 nodes are available: 5 Insufficient cpu. preemption: 0/5 nodes are available: 5 No preemption victims found for incoming pod."
I0506 15:59:33.339212      12 preemption.go:264] "No preemption candidate is found; preemption is not helpful for scheduling" pod="default/cspod-48"
I0506 15:59:33.339255      12 schedule_one.go:1044] "Unable to schedule pod; no fit; waiting" pod="default/cspod-48" err="0/5 nodes are available: 5 Insufficient cpu. preemption: 0/5 nodes are available: 5 No preemption victims found for incoming pod."
I0506 15:59:33.359140      12 preemption.go:264] "No preemption candidate is found; preemption is not helpful for scheduling" pod="default/cspod-49"
I0506 15:59:33.359191      12 schedule_one.go:1044] "Unable to schedule pod; no fit; waiting" pod="default/cspod-49" err="0/5 nodes are available: 5 Insufficient cpu. preemption: 0/5 nodes are available: 5 No preemption victims found for incoming pod."
I0506 15:59:33.379053      12 preemption.go:264] "No preemption candidate is found; preemption is not helpful for scheduling" pod="default/cspod-50"
I0506 15:59:33.379101      12 schedule_one.go:1044] "Unable to schedule pod; no fit; waiting" pod="default/cspod-50" err="0/5 nodes are available: 5 Insufficient cpu. preemption: 0/5 nodes are available: 5 No preemption victims found for incoming pod."
I0506 15:59:33.399173      12 preemption.go:264] "No preemption candidate is found; preemption is not helpful for scheduling" pod="default/cspod-51"
I0506 15:59:33.399214      12 schedule_one.go:1044] "Unable to schedule pod; no fit; waiting" pod="default/cspod-51" err="0/5 nodes are available: 5 Insufficient cpu. preemption: 0/5 nodes are available: 5 No preemption victims found for incoming pod."
I0506 15:59:33.419506      12 preemption.go:264] "No preemption candidate is found; preemption is not helpful for scheduling" pod="default/cspod-52"
I0506 15:59:33.419559      12 schedule_one.go:1044] "Unable to schedule pod; no fit; waiting" pod="default/cspod-52" err="0/5 nodes are available: 5 Insufficient cpu. preemption: 0/5 nodes are available: 5 No preemption victims found for incoming pod."
I0506 15:59:33.439677      12 preemption.go:264] "No preemption candidate is found; preemption is not helpful for scheduling" pod="default/cspod-53"
I0506 15:59:33.439725      12 schedule_one.go:1044] "Unable to schedule pod; no fit; waiting" pod="default/cspod-53" err="0/5 nodes are available: 5 Insufficient cpu. preemption: 0/5 nodes are available: 5 No preemption victims found for incoming pod."
I0506 15:59:33.458850      12 preemption.go:264] "No preemption candidate is found; preemption is not helpful for scheduling" pod="default/cspod-54"
I0506 15:59:33.458900      12 schedule_one.go:1044] "Unable to schedule pod; no fit; waiting" pod="default/cspod-54" err="0/5 nodes are available: 5 Insufficient cpu. preemption: 0/5 nodes are available: 5 No preemption victims found for incoming pod."
I0506 15:59:33.479100      12 preemption.go:264] "No preemption candidate is found; preemption is not helpful for scheduling" pod="default/cspod-60"
I0506 15:59:33.479148      12 schedule_one.go:1044] "Unable to schedule pod; no fit; waiting" pod="default/cspod-60" err="0/5 nodes are available: 5 Insufficient cpu. preemption: 0/5 nodes are available: 5 No preemption victims found for incoming pod."
I0506 15:59:33.499222      12 preemption.go:264] "No preemption candidate is found; preemption is not helpful for scheduling" pod="default/cspod-61"
I0506 15:59:33.499263      12 schedule_one.go:1044] "Unable to schedule pod; no fit; waiting" pod="default/cspod-61" err="0/5 nodes are available: 5 Insufficient cpu. preemption: 0/5 nodes are available: 5 No preemption victims found for incoming pod."
I0506 15:59:33.519296      12 preemption.go:264] "No preemption candidate is found; preemption is not helpful for scheduling" pod="default/cspod-62"
I0506 15:59:33.519335      12 schedule_one.go:1044] "Unable to schedule pod; no fit; waiting" pod="default/cspod-62" err="0/5 nodes are available: 5 Insufficient cpu. preemption: 0/5 nodes are available: 5 No preemption victims found for incoming pod."
I0506 15:59:33.538808      12 preemption.go:264] "No preemption candidate is found; preemption is not helpful for scheduling" pod="default/cspod-63"
I0506 15:59:33.538859      12 schedule_one.go:1044] "Unable to schedule pod; no fit; waiting" pod="default/cspod-63" err="0/5 nodes are available: 5 Insufficient cpu. preemption: 0/5 nodes are available: 5 No preemption victims found for incoming pod."
I0506 15:59:33.559045      12 preemption.go:264] "No preemption candidate is found; preemption is not helpful for scheduling" pod="default/cspod-64"
I0506 15:59:33.559118      12 schedule_one.go:1044] "Unable to schedule pod; no fit; waiting" pod="default/cspod-64" err="0/5 nodes are available: 5 Insufficient cpu. preemption: 0/5 nodes are available: 5 No preemption victims found for incoming pod."
I0506 15:59:33.579375      12 preemption.go:264] "No preemption candidate is found; preemption is not helpful for scheduling" pod="default/cspod-65"
I0506 15:59:33.579423      12 schedule_one.go:1044] "Unable to schedule pod; no fit; waiting" pod="default/cspod-65" err="0/5 nodes are available: 5 Insufficient cpu. preemption: 0/5 nodes are available: 5 No preemption victims found for incoming pod."
I0506 15:59:33.599101      12 preemption.go:264] "No preemption candidate is found; preemption is not helpful for scheduling" pod="default/cspod-66"
I0506 15:59:33.599146      12 schedule_one.go:1044] "Unable to schedule pod; no fit; waiting" pod="default/cspod-66" err="0/5 nodes are available: 5 Insufficient cpu. preemption: 0/5 nodes are available: 5 No preemption victims found for incoming pod."
I0506 15:59:33.619682      12 preemption.go:264] "No preemption candidate is found; preemption is not helpful for scheduling" pod="default/cspod-67"
I0506 15:59:33.619725      12 schedule_one.go:1044] "Unable to schedule pod; no fit; waiting" pod="default/cspod-67" err="0/5 nodes are available: 5 Insufficient cpu. preemption: 0/5 nodes are available: 5 No preemption victims found for incoming pod."
I0506 15:59:33.638810      12 preemption.go:264] "No preemption candidate is found; preemption is not helpful for scheduling" pod="default/cspod-68"
I0506 15:59:33.638884      12 schedule_one.go:1044] "Unable to schedule pod; no fit; waiting" pod="default/cspod-68" err="0/5 nodes are available: 5 Insufficient cpu. preemption: 0/5 nodes are available: 5 No preemption victims found for incoming pod."
I0506 15:59:33.658944      12 preemption.go:264] "No preemption candidate is found; preemption is not helpful for scheduling" pod="default/cspod-69"
I0506 15:59:33.658983      12 schedule_one.go:1044] "Unable to schedule pod; no fit; waiting" pod="default/cspod-69" err="0/5 nodes are available: 5 Insufficient cpu. preemption: 0/5 nodes are available: 5 No preemption victims found for incoming pod."
I0506 15:59:36.844966      12 schedule_one.go:314] "Successfully bound pod to node" pod="default/cspod-20" node="csnode-1" evaluatedNodes=5 feasibleNodes=2
I0506 15:59:36.845852      12 schedule_one.go:314] "Successfully bound pod to node" pod="default/cspod-21" node="csnode-3" evaluatedNodes=5 feasibleNodes=4
I0506 15:59:36.846869      12 schedule_one.go:314] "Successfully bound pod to node" pod="default/cspod-24" node="csnode-2" evaluatedNodes=5 feasibleNodes=3
I0506 15:59:36.846909      12 schedule_one.go:314] "Successfully bound pod to node" pod="default/cspod-22" node="csnode-3" evaluatedNodes=5 feasibleNodes=5
I0506 15:59:36.847332      12 schedule_one.go:314] "Successfully bound pod to node" pod="default/cspod-23" node="csnode-1" evaluatedNodes=5 feasibleNodes=4
I0506 15:59:36.847899      12 preemption.go:264] "No preemption candidate is found; preemption is not helpful for scheduling" pod="default/cspod-30"
I0506 15:59:36.847948      12 schedule_one.go:1044] "Unable to schedule pod; no fit; waiting" pod="default/cspod-30" err="0/5 nodes are available: 5 Insufficient cpu. preemption: 0/5 nodes are available: 5 No preemption victims found for incoming pod."
I0506 15:59:36.848221      12 schedule_one.go:314] "Successfully bound pod to node" pod="default/cspod-26" node="csnode-4" evaluatedNodes=5 feasibleNodes=2
I0506 15:59:36.848244      12 schedule_one.go:314] "Successfully bound pod to node" pod="default/cspod-25" node="csnode-2" evaluatedNodes=5 feasibleNodes=3
I0506 15:59:36.848263      12 schedule_one.go:314] "Successfully bound pod to node" pod="default/cspod-27" node="csnode-4" evaluatedNodes=5 feasibleNodes=2
I0506 15:59:36.848417      12 schedule_one.go:314] "Successfully bound pod to node" pod="default/cspod-29" node="csnode-0" evaluatedNodes=5 feasibleNodes=1
I0506 15:59:36.848438      12 schedule_one.go:314] "Successfully bound pod to node" pod="default/cspod-28" node="csnode-0" evaluatedNodes=5 feasibleNodes=1
I0506 15:59:36.848607      12 preemption.go:264] "No preemption candidate is found; preemption is not helpful for scheduling" pod="default/cspod-31"
I0506 15:59:36.848646      12 schedule_one.go:1044] "Unable to schedule pod; no fit; waiting" pod="default/cspod-31" err="0/5 nodes are available: 5 Insufficient cpu. preemption: 0/5 nodes are available: 5 No preemption victims found for incoming pod."
I0506 15:59:36.849246      12 preemption.go:264] "No preemption candidate is found; preemption is not helpful for scheduling" pod="default/cspod-32"
I0506 15:59:36.849283      12 schedule_one.go:1044] "Unable to schedule pod; no fit; waiting" pod="default/cspod-32" err="0/5 nodes are available: 5 Insufficient cpu. preemption: 0/5 nodes are available: 5 No preemption victims found for incoming pod."
I0506 15:59:36.849822      12 preemption.go:264] "No preemption candidate is found; preemption is not helpful for scheduling" pod="default/cspod-33"
I0506 15:59:36.849858      12 schedule_one.go:1044] "Unable to schedule pod; no fit; waiting" pod="default/cspod-33" err="0/5 nodes are available: 5 Insufficient cpu. preemption: 0/5 nodes are available: 5 No preemption victims found for incoming pod."
I0506 15:59:36.850420      12 preemption.go:264] "No preemption candidate is found; preemption is not helpful for scheduling" pod="default/cspod-34"
I0506 15:59:36.850461      12 schedule_one.go:1044] "Unable to schedule pod; no fit; waiting" pod="default/cspod-34" err="0/5 nodes are available: 5 Insufficient cpu. preemption: 0/5 nodes are available: 5 No preemption victims found for incoming pod."
I0506 15:59:36.850981      12 preemption.go:264] "No preemption candidate is found; preemption is not helpful for scheduling" pod="default/cspod-35"
I0506 15:59:36.851015      12 schedule_one.go:1044] "Unable to schedule pod; no fit; waiting" pod="default/cspod-35" err="0/5 nodes are available: 5 Insufficient cpu. preemption: 0/5 nodes are available: 5 No preemption victims found for incoming pod."
I0506 15:59:36.851474      12 preemption.go:264] "No preemption candidate is found; preemption is not helpful for scheduling" pod="default/cspod-36"
I0506 15:59:36.851508      12 schedule_one.go:1044] "Unable to schedule pod; no fit; waiting" pod="default/cspod-36" err="0/5 nodes are available: 5 Insufficient cpu. preemption: 0/5 nodes are available: 5 No preemption victims found for incoming pod."
I0506 15:59:36.851988      12 preemption.go:264] "No preemption candidate is found; preemption is not helpful for scheduling" pod="default/cspod-37"
I0506 15:59:36.852021      12 schedule_one.go:1044] "Unable to schedule pod; no fit; waiting" pod="default/cspod-37" err="0/5 nodes are available: 5 Insufficient cpu. preemption: 0/5 nodes are available: 5 No preemption victims found for incoming pod."
I0506 15:59:36.852523      12 preemption.go:264] "No preemption candidate is found; preemption is not helpful for scheduling" pod="default/cspod-38"
I0506 15:59:36.852556      12 schedule_one.go:1044] "Unable to schedule pod; no fit; waiting" pod="default/cspod-38" err="0/5 nodes are available: 5 Insufficient cpu. preemption: 0/5 nodes are available: 5 No preemption victims found for incoming pod."
I0506 15:59:36.853074      12 preemption.go:264] "No preemption candidate is found; preemption is not helpful for scheduling" pod="default/cspod-39"
I0506 15:59:36.853108      12 schedule_one.go:1044] "Unable to schedule pod; no fit; waiting" pod="default/cspod-39" err="0/5 nodes are available: 5 Insufficient cpu. preemption: 0/5 nodes are available: 5 No preemption victims found for incoming pod."
I0506 15:59:36.853616      12 preemption.go:264] "No preemption candidate is found; preemption is not helpful for scheduling" pod="default/cspod-40"
I0506 15:59:36.853648      12 schedule_one.go:1044] "Unable to schedule pod; no fit; waiting" pod="default/cspod-40" err="0/5 nodes are available: 5 Insufficient cpu. preemption: 0/5 nodes are available: 5 No preemption victims found for incoming pod."
I0506 15:59:36.854195      12 preemption.go:264] "No preemption candidate is found; preemption is not helpful for scheduling" pod="default/cspod-41"
I0506 15:59:36.854231      12 schedule_one.go:1044] "Unable to schedule pod; no fit; waiting" pod="default/cspod-41" err="0/5 nodes are available: 5 Insufficient cpu. preemption: 0/5 nodes are available: 5 No preemption victims found for incoming pod."
I0506 15:59:36.854754      12 preemption.go:264] "No preemption candidate is found; preemption is not helpful for scheduling" pod="default/cspod-42"
I0506 15:59:36.854787      12 schedule_one.go:1044] "Unable to schedule pod; no fit; waiting" pod="default/cspod-42" err="0/5 nodes are available: 5 Insufficient cpu. preemption: 0/5 nodes are available: 5 No preemption victims found for incoming pod."
I0506 15:59:36.855320      12 preemption.go:264] "No preemption candidate is found; preemption is not helpful for scheduling" pod="default/cspod-43"
I0506 15:59:36.855353      12 schedule_one.go:1044] "Unable to schedule pod; no fit; waiting" pod="default/cspod-43" err="0/5 nodes are available: 5 Insufficient cpu. preemption: 0/5 nodes are available: 5 No preemption victims found for incoming pod."
I0506 15:59:36.855943      12 preemption.go:264] "No preemption candidate is found; preemption is not helpful for scheduling" pod="default/cspod-44"
I0506 15:59:36.855977      12 schedule_one.go:1044] "Unable to schedule pod; no fit; waiting" pod="default/cspod-44" err="0/5 nodes are available: 5 Insufficient cpu. preemption: 0/5 nodes are available: 5 No preemption victims found for incoming pod."
I0506 15:59:36.856464      12 preemption.go:264] "No preemption candidate is found; preemption is not helpful for scheduling" pod="default/cspod-45"
I0506 15:59:36.856506      12 schedule_one.go:1044] "Unable to schedule pod; no fit; waiting" pod="default/cspod-45" err="0/5 nodes are available: 5 Insufficient cpu. preemption: 0/5 nodes are available: 5 No preemption victims found for incoming pod."
I0506 15:59:36.857044      12 preemption.go:264] "No preemption candidate is found; preemption is not helpful for scheduling" pod="default/cspod-46"
I0506 15:59:36.857080      12 schedule_one.go:1044] "Unable to schedule pod; no fit; waiting" pod="default/cspod-46" err="0/5 nodes are available: 5 Insufficient cpu. preemption: 0/5 nodes are available: 5 No preemption victims found for incoming pod."
I0506 15:59:36.857733      12 preemption.go:264] "No preemption candidate is found; preemption is not helpful for scheduling" pod="default/cspod-47"
I0506 15:59:36.857768      12 schedule_one.go:1044] "Unable to schedule pod; no fit; waiting" pod="default/cspod-47" err="0/5 nodes are available: 5 Insufficient cpu. preemption: 0/5 nodes are available: 5 No preemption victims found for incoming pod."
I0506 15:59:36.858339      12 preemption.go:264] "No preemption candidate is found; preemption is not helpful for scheduling" pod="default/cspod-48"
I0506 15:59:36.858374      12 schedule_one.go:1044] "Unable to schedule pod; no fit; waiting" pod="default/cspod-48" err="0/5 nodes are available: 5 Insufficient cpu. preemption: 0/5 nodes are available: 5 No preemption victims found for incoming pod."
I0506 15:59:36.858875      12 preemption.go:264] "No preemption candidate is found; preemption is not helpful for scheduling" pod="default/cspod-49"
I0506 15:59:36.858912      12 schedule_one.go:1044] "Unable to schedule pod; no fit; waiting" pod="default/cspod-49" err="0/5 nodes are available: 5 Insufficient cpu. preemption: 0/5 nodes are available: 5 No preemption victims found for incoming pod."
I0506 15:59:36.859372      12 preemption.go:264] "No preemption candidate is found; preemption is not helpful for scheduling" pod="default/cspod-50"
I0506 15:59:36.859405      12 schedule_one.go:1044] "Unable to schedule pod; no fit; waiting" pod="default/cspod-50" err="0/5 nodes are available: 5 Insufficient cpu. preemption: 0/5 nodes are available: 5 No preemption victims found for incoming pod."
I0506 15:59:36.859890      12 preemption.go:264] "No preemption candidate is found; preemption is not helpful for scheduling" pod="default/cspod-51"
I0506 15:59:36.859922      12 schedule_one.go:1044] "Unable to schedule pod; no fit; waiting" pod="default/cspod-51" err="0/5 nodes are available: 5 Insufficient cpu. preemption: 0/5 nodes are available: 5 No preemption victims found for incoming pod."
I0506 15:59:36.860449      12 preemption.go:264] "No preemption candidate is found; preemption is not helpful for scheduling" pod="default/cspod-52"
I0506 15:59:36.860482      12 schedule_one.go:1044] "Unable to schedule pod; no fit; waiting" pod="default/cspod-52" err="0/5 nodes are available: 5 Insufficient cpu. preemption: 0/5 nodes are available: 5 No preemption victims found for incoming pod."
I0506 15:59:36.860962      12 preemption.go:264] "No preemption candidate is found; preemption is not helpful for scheduling" pod="default/cspod-53"
I0506 15:59:36.860996      12 schedule_one.go:1044] "Unable to schedule pod; no fit; waiting" pod="default/cspod-53" err="0/5 nodes are available: 5 Insufficient cpu. preemption: 0/5 nodes are available: 5 No preemption victims found for incoming pod."
I0506 15:59:36.861541      12 preemption.go:264] "No preemption candidate is found; preemption is not helpful for scheduling" pod="default/cspod-54"
I0506 15:59:36.861576      12 schedule_one.go:1044] "Unable to schedule pod; no fit; waiting" pod="default/cspod-54" err="0/5 nodes are available: 5 Insufficient cpu. preemption: 0/5 nodes are available: 5 No preemption victims found for incoming pod."
I0506 15:59:36.862141      12 preemption.go:264] "No preemption candidate is found; preemption is not helpful for scheduling" pod="default/cspod-60"
I0506 15:59:36.862179      12 schedule_one.go:1044] "Unable to schedule pod; no fit; waiting" pod="default/cspod-60" err="0/5 nodes are available: 5 Insufficient cpu. preemption: 0/5 nodes are available: 5 No preemption victims found for incoming pod."
I0506 15:59:36.862687      12 preemption.go:264] "No preemption candidate is found; preemption is not helpful for scheduling" pod="default/cspod-61"
I0506 15:59:36.862720      12 schedule_one.go:1044] "Unable to schedule pod; no fit; waiting" pod="default/cspod-61" err="0/5 nodes are available: 5 Insufficient cpu. preemption: 0/5 nodes are available: 5 No preemption victims found for incoming pod."
I0506 15:59:36.863245      12 preemption.go:264] "No preemption candidate is found; preemption is not helpful for scheduling" pod="default/cspod-62"
I0506 15:59:36.863278      12 schedule_one.go:1044] "Unable to schedule pod; no fit; waiting" pod="default/cspod-62" err="0/5 nodes are available: 5 Insufficient cpu. preemption: 0/5 nodes are available: 5 No preemption victims found for incoming pod."
I0506 15:59:36.863787      12 preemption.go:264] "No preemption candidate is found; preemption is not helpful for scheduling" pod="default/cspod-63"
I0506 15:59:36.863821      12 schedule_one.go:1044] "Unable to schedule pod; no fit; waiting" pod="default/cspod-63" err="0/5 nodes are available: 5 Insufficient cpu. preemption: 0/5 nodes are available: 5 No preemption victims found for incoming pod."
I0506 15:59:36.864354      12 preemption.go:264] "No preemption candidate is found; preemption is not helpful for scheduling" pod="default/cspod-64"
I0506 15:59:36.864389      12 schedule_one.go:1044] "Unable to schedule pod; no fit; waiting" pod="default/cspod-64" err="0/5 nodes are available: 5 Insufficient cpu. preemption: 0/5 nodes are available: 5 No preemption victims found for incoming pod."
I0506 15:59:36.864904      12 preemption.go:264] "No preemption candidate is found; preemption is not helpful for scheduling" pod="default/cspod-65"
I0506 15:59:36.864938      12 schedule_one.go:1044] "Unable to schedule pod; no fit; waiting" pod="default/cspod-65" err="0/5 nodes are available: 5 Insufficient cpu. preemption: 0/5 nodes are available: 5 No preemption victims found for incoming pod."
I0506 15:59:36.865514      12 preemption.go:264] "No preemption candidate is found; preemption is not helpful for scheduling" pod="default/cspod-66"
I0506 15:59:36.865550      12 schedule_one.go:1044] "Unable to schedule pod; no fit; waiting" pod="default/cspod-66" err="0/5 nodes are available: 5 Insufficient cpu. preemption: 0/5 nodes are available: 5 No preemption victims found for incoming pod."
I0506 15:59:36.866172      12 preemption.go:264] "No preemption candidate is found; preemption is not helpful for scheduling" pod="default/cspod-67"
I0506 15:59:36.866210      12 schedule_one.go:1044] "Unable to schedule pod; no fit; waiting" pod="default/cspod-67" err="0/5 nodes are available: 5 Insufficient cpu. preemption: 0/5 nodes are available: 5 No preemption victims found for incoming pod."
I0506 15:59:36.866749      12 preemption.go:264] "No preemption candidate is found; preemption is not helpful for scheduling" pod="default/cspod-68"
I0506 15:59:36.866785      12 schedule_one.go:1044] "Unable to schedule pod; no fit; waiting" pod="default/cspod-68" err="0/5 nodes are available: 5 Insufficient cpu. preemption: 0/5 nodes are available: 5 No preemption victims found for incoming pod."
I0506 15:59:36.867339      12 preemption.go:264] "No preemption candidate is found; preemption is not helpful for scheduling" pod="default/cspod-69"
I0506 15:59:36.867373      12 schedule_one.go:1044] "Unable to schedule pod; no fit; waiting" pod="default/cspod-69" err="0/5 nodes are available: 5 Insufficient cpu. preemption: 0/5 nodes are available: 5 No preemption victims found for incoming pod."
I0506 15:59:36.907980      12 schedule_one.go:314] "Successfully bound pod to node" pod="default/cspod-30" node="csnode-1" evaluatedNodes=5 feasibleNodes=5
I0506 15:59:36.908004      12 schedule_one.go:314] "Successfully bound pod to node" pod="default/cspod-31" node="csnode-1" evaluatedNodes=5 feasibleNodes=5
I0506 15:59:36.908297      12 schedule_one.go:314] "Successfully bound pod to node" pod="default/cspod-33" node="csnode-3" evaluatedNodes=5 feasibleNodes=4
I0506 15:59:36.908324      12 schedule_one.go:314] "Successfully bound pod to node" pod="default/cspod-32" node="csnode-3" evaluatedNodes=5 feasibleNodes=4
I0506 15:59:36.908405      12 schedule_one.go:314] "Successfully bound pod to node" pod="default/cspod-35" node="csnode-4" evaluatedNodes=5 feasibleNodes=3
I0506 15:59:36.908477      12 schedule_one.go:314] "Successfully bound pod to node" pod="default/cspod-34" node="csnode-4" evaluatedNodes=5 feasibleNodes=3
I0506 15:59:36.908566      12 preemption.go:264] "No preemption candidate is found; preemption is not helpful for scheduling" pod="default/cspod-40"
I0506 15:59:36.908605      12 schedule_one.go:1044] "Unable to schedule pod; no fit; waiting" pod="default/cspod-40" err="0/5 nodes are available: 5 Insufficient cpu. preemption: 0/5 nodes are available: 5 No preemption victims found for incoming pod."
I0506 15:59:36.908647      12 schedule_one.go:314] "Successfully bound pod to node" pod="default/cspod-36" node="csnode-0" evaluatedNodes=5 feasibleNodes=2
I0506 15:59:36.908779      12 schedule_one.go:314] "Successfully bound pod to node" pod="default/cspod-37" node="csnode-0" evaluatedNodes=5 feasibleNodes=2
I0506 15:59:36.908859      12 schedule_one.go:314] "Successfully bound pod to node" pod="default/cspod-38" node="csnode-2" evaluatedNodes=5 feasibleNodes=1
I0506 15:59:36.909230      12 schedule_one.go:314] "Successfully bound pod to node" pod="default/cspod-39" node="csnode-2" evaluatedNodes=5 feasibleNodes=1
I0506 15:59:36.909370      12 preemption.go:264] "No preemption candidate is found; preemption is not helpful for scheduling" pod="default/cspod-41"
I0506 15:59:36.909406      12 schedule_one.go:1044] "Unable to schedule pod; no fit; waiting" pod="default/cspod-41" err="0/5 nodes are available: 5 Insufficient cpu. preemption: 0/5 nodes are available: 5 No preemption victims found for incoming pod."
I0506 15:59:36.909914      12 preemption.go:264] "No preemption candidate is found; preemption is not helpful for scheduling" pod="default/cspod-42"
I0506 15:59:36.909948      12 schedule_one.go:1044] "Unable to schedule pod; no fit; waiting" pod="default/cspod-42" err="0/5 nodes are available: 5 Insufficient cpu. preemption: 0/5 nodes are available: 5 No preemption victims found for incoming pod."
I0506 15:59:36.910484      12 preemption.go:264] "No preemption candidate is found; preemption is not helpful for scheduling" pod="default/cspod-43"
I0506 15:59:36.910520      12 schedule_one.go:1044] "Unable to schedule pod; no fit; waiting" pod="default/cspod-43" err="0/5 nodes are available: 5 Insufficient cpu. preemption: 0/5 nodes are available: 5 No preemption victims found for incoming pod."
I0506 15:59:36.911070      12 preemption.go:264] "No preemption candidate is found; preemption is not helpful for scheduling" pod="default/cspod-44"
I0506 15:59:36.911107      12 schedule_one.go:1044] "Unable to schedule pod; no fit; waiting" pod="default/cspod-44" err="0/5 nodes are available: 5 Insufficient cpu. preemption: 0/5 nodes are available: 5 No preemption victims found for incoming pod."
I0506 15:59:36.911616      12 preemption.go:264] "No preemption candidate is found; preemption is not helpful for scheduling" pod="default/cspod-45"
I0506 15:59:36.911658      12 schedule_one.go:1044] "Unable to schedule pod; no fit; waiting" pod="default/cspod-45" err="0/5 nodes are available: 5 Insufficient cpu. preemption: 0/5 nodes are available: 5 No preemption victims found for incoming pod."
I0506 15:59:36.912222      12 preemption.go:264] "No preemption candidate is found; preemption is not helpful for scheduling" pod="default/cspod-46"
I0506 15:59:36.912257      12 schedule_one.go:1044] "Unable to schedule pod; no fit; waiting" pod="default/cspod-46" err="0/5 nodes are available: 5 Insufficient cpu. preemption: 0/5 nodes are available: 5 No preemption victims found for incoming pod."
I0506 15:59:36.912778      12 preemption.go:264] "No preemption candidate is found; preemption is not helpful for scheduling" pod="default/cspod-47"
I0506 15:59:36.912819      12 schedule_one.go:1044] "Unable to schedule pod; no fit; waiting" pod="default/cspod-47" err="0/5 nodes are available: 5 Insufficient cpu. preemption: 0/5 nodes are available: 5 No preemption victims found for incoming pod."
I0506 15:59:36.913342      12 preemption.go:264] "No preemption candidate is found; preemption is not helpful for scheduling" pod="default/cspod-48"
I0506 15:59:36.913374      12 schedule_one.go:1044] "Unable to schedule pod; no fit; waiting" pod="default/cspod-48" err="0/5 nodes are available: 5 Insufficient cpu. preemption: 0/5 nodes are available: 5 No preemption victims found for incoming pod."
I0506 15:59:36.913937      12 preemption.go:264] "No preemption candidate is found; preemption is not helpful for scheduling" pod="default/cspod-49"
I0506 15:59:36.913971      12 schedule_one.go:1044] "Unable to schedule pod; no fit; waiting" pod="default/cspod-49" err="0/5 nodes are available: 5 Insufficient cpu. preemption: 0/5 nodes are available: 5 No preemption victims found for incoming pod."
I0506 15:59:36.914462      12 preemption.go:264] "No preemption candidate is found; preemption is not helpful for scheduling" pod="default/cspod-50"
I0506 15:59:36.914496      12 schedule_one.go:1044] "Unable to schedule pod; no fit; waiting" pod="default/cspod-50" err="0/5 nodes are available: 5 Insufficient cpu. preemption: 0/5 nodes are available: 5 No preemption victims found for incoming pod."
I0506 15:59:36.915156      12 preemption.go:264] "No preemption candidate is found; preemption is not helpful for scheduling" pod="default/cspod-51"
I0506 15:59:36.915194      12 schedule_one.go:1044] "Unable to schedule pod; no fit; waiting" pod="default/cspod-51" err="0/5 nodes are available: 5 Insufficient cpu. preemption: 0/5 nodes are available: 5 No preemption victims found for incoming pod."
I0506 15:59:36.915707      12 preemption.go:264] "No preemption candidate is found; preemption is not helpful for scheduling" pod="default/cspod-52"
I0506 15:59:36.915742      12 schedule_one.go:1044] "Unable to schedule pod; no fit; waiting" pod="default/cspod-52" err="0/5 nodes are available: 5 Insufficient cpu. preemption: 0/5 nodes are available: 5 No preemption victims found for incoming pod."
I0506 15:59:36.916249      12 preemption.go:264] "No preemption candidate is found; preemption is not helpful for scheduling" pod="default/cspod-53"
I0506 15:59:36.916283      12 schedule_one.go:1044] "Unable to schedule pod; no fit; waiting" pod="default/cspod-53" err="0/5 nodes are available: 5 Insufficient cpu. preemption: 0/5 nodes are available: 5 No preemption victims found for incoming pod."
I0506 15:59:36.916787      12 preemption.go:264] "No preemption candidate is found; preemption is not helpful for scheduling" pod="default/cspod-54"
I0506 15:59:36.916832      12 schedule_one.go:1044] "Unable to schedule pod; no fit; waiting" pod="default/cspod-54" err="0/5 nodes are available: 5 Insufficient cpu. preemption: 0/5 nodes are available: 5 No preemption victims found for incoming pod."
I0506 15:59:36.917326      12 preemption.go:264] "No preemption candidate is found; preemption is not helpful for scheduling" pod="default/cspod-60"
I0506 15:59:36.917364      12 schedule_one.go:1044] "Unable to schedule pod; no fit; waiting" pod="default/cspod-60" err="0/5 nodes are available: 5 Insufficient cpu. preemption: 0/5 nodes are available: 5 No preemption victims found for incoming pod."
I0506 15:59:36.917902      12 preemption.go:264] "No preemption candidate is found; preemption is not helpful for scheduling" pod="default/cspod-61"
I0506 15:59:36.917935      12 schedule_one.go:1044] "Unable to schedule pod; no fit; waiting" pod="default/cspod-61" err="0/5 nodes are available: 5 Insufficient cpu. preemption: 0/5 nodes are available: 5 No preemption victims found for incoming pod."
I0506 15:59:36.918439      12 preemption.go:264] "No preemption candidate is found; preemption is not helpful for scheduling" pod="default/cspod-62"
I0506 15:59:36.918493      12 schedule_one.go:1044] "Unable to schedule pod; no fit; waiting" pod="default/cspod-62" err="0/5 nodes are available: 5 Insufficient cpu. preemption: 0/5 nodes are available: 5 No preemption victims found for incoming pod."
I0506 15:59:36.919129      12 preemption.go:264] "No preemption candidate is found; preemption is not helpful for scheduling" pod="default/cspod-63"
I0506 15:59:36.919162      12 schedule_one.go:1044] "Unable to schedule pod; no fit; waiting" pod="default/cspod-63" err="0/5 nodes are available: 5 Insufficient cpu. preemption: 0/5 nodes are available: 5 No preemption victims found for incoming pod."
I0506 15:59:36.919698      12 preemption.go:264] "No preemption candidate is found; preemption is not helpful for scheduling" pod="default/cspod-64"
I0506 15:59:36.919732      12 schedule_one.go:1044] "Unable to schedule pod; no fit; waiting" pod="default/cspod-64" err="0/5 nodes are available: 5 Insufficient cpu. preemption: 0/5 nodes are available: 5 No preemption victims found for incoming pod."
I0506 15:59:36.920278      12 preemption.go:264] "No preemption candidate is found; preemption is not helpful for scheduling" pod="default/cspod-65"
I0506 15:59:36.920311      12 schedule_one.go:1044] "Unable to schedule pod; no fit; waiting" pod="default/cspod-65" err="0/5 nodes are available: 5 Insufficient cpu. preemption: 0/5 nodes are available: 5 No preemption victims found for incoming pod."
I0506 15:59:36.920870      12 preemption.go:264] "No preemption candidate is found; preemption is not helpful for scheduling" pod="default/cspod-66"
I0506 15:59:36.920904      12 schedule_one.go:1044] "Unable to schedule pod; no fit; waiting" pod="default/cspod-66" err="0/5 nodes are available: 5 Insufficient cpu. preemption: 0/5 nodes are available: 5 No preemption victims found for incoming pod."
I0506 15:59:36.921705      12 preemption.go:264] "No preemption candidate is found; preemption is not helpful for scheduling" pod="default/cspod-67"
I0506 15:59:36.921739      12 schedule_one.go:1044] "Unable to schedule pod; no fit; waiting" pod="default/cspod-67" err="0/5 nodes are available: 5 Insufficient cpu. preemption: 0/5 nodes are available: 5 No preemption victims found for incoming pod."
I0506 15:59:36.922318      12 preemption.go:264] "No preemption candidate is found; preemption is not helpful for scheduling" pod="default/cspod-68"
I0506 15:59:36.922352      12 schedule_one.go:1044] "Unable to schedule pod; no fit; waiting" pod="default/cspod-68" err="0/5 nodes are available: 5 Insufficient cpu. preemption: 0/5 nodes are available: 5 No preemption victims found for incoming pod."
I0506 15:59:36.923793      12 preemption.go:264] "No preemption candidate is found; preemption is not helpful for scheduling" pod="default/cspod-69"
I0506 15:59:36.923831      12 schedule_one.go:1044] "Unable to schedule pod; no fit; waiting" pod="default/cspod-69" err="0/5 nodes are available: 5 Insufficient cpu. preemption: 0/5 nodes are available: 5 No preemption victims found for incoming pod."
I0506 15:59:36.948905      12 schedule_one.go:314] "Successfully bound pod to node" pod="default/cspod-40" node="csnode-0" evaluatedNodes=5 feasibleNodes=2
I0506 15:59:36.949012      12 preemption.go:264] "No preemption candidate is found; preemption is not helpful for scheduling" pod="default/cspod-43"
I0506 15:59:36.949039      12 schedule_one.go:1044] "Unable to schedule pod; no fit; waiting" pod="default/cspod-43" err="0/5 nodes are available: 5 Insufficient cpu. preemption: 0/5 nodes are available: 5 No preemption victims found for incoming pod."
I0506 15:59:36.949067      12 schedule_one.go:314] "Successfully bound pod to node" pod="default/cspod-41" node="csnode-2" evaluatedNodes=5 feasibleNodes=1
I0506 15:59:36.949430      12 schedule_one.go:314] "Successfully bound pod to node" pod="default/cspod-42" node="csnode-2" evaluatedNodes=5 feasibleNodes=1
I0506 15:59:36.949643      12 preemption.go:264] "No preemption candidate is found; preemption is not helpful for scheduling" pod="default/cspod-44"
I0506 15:59:36.949682      12 schedule_one.go:1044] "Unable to schedule pod; no fit; waiting" pod="default/cspod-44" err="0/5 nodes are available: 5 Insufficient cpu. preemption: 0/5 nodes are available: 5 No preemption victims found for incoming pod."
I0506 15:59:36.950251      12 preemption.go:264] "No preemption candidate is found; preemption is not helpful for scheduling" pod="default/cspod-45"
I0506 15:59:36.950287      12 schedule_one.go:1044] "Unable to schedule pod; no fit; waiting" pod="default/cspod-45" err="0/5 nodes are available: 5 Insufficient cpu. preemption: 0/5 nodes are available: 5 No preemption victims found for incoming pod."
I0506 15:59:36.950840      12 preemption.go:264] "No preemption candidate is found; preemption is not helpful for scheduling" pod="default/cspod-46"
I0506 15:59:36.950875      12 schedule_one.go:1044] "Unable to schedule pod; no fit; waiting" pod="default/cspod-46" err="0/5 nodes are available: 5 Insufficient cpu. preemption: 0/5 nodes are available: 5 No preemption victims found for incoming pod."
I0506 15:59:36.951434      12 preemption.go:264] "No preemption candidate is found; preemption is not helpful for scheduling" pod="default/cspod-47"
I0506 15:59:36.951469      12 schedule_one.go:1044] "Unable to schedule pod; no fit; waiting" pod="default/cspod-47" err="0/5 nodes are available: 5 Insufficient cpu. preemption: 0/5 nodes are available: 5 No preemption victims found for incoming pod."
I0506 15:59:36.952499      12 preemption.go:264] "No preemption candidate is found; preemption is not helpful for scheduling" pod="default/cspod-48"
I0506 15:59:36.952545      12 schedule_one.go:1044] "Unable to schedule pod; no fit; waiting" pod="default/cspod-48" err="0/5 nodes are available: 5 Insufficient cpu. preemption: 0/5 nodes are available: 5 No preemption victims found for incoming pod."
I0506 15:59:36.953055      12 preemption.go:264] "No preemption candidate is found; preemption is not helpful for scheduling" pod="default/cspod-49"
I0506 15:59:36.953092      12 schedule_one.go:1044] "Unable to schedule pod; no fit; waiting" pod="default/cspod-49" err="0/5 nodes are available: 5 Insufficient cpu. preemption: 0/5 nodes are available: 5 No preemption victims found for incoming pod."
I0506 15:59:36.953691      12 preemption.go:264] "No preemption candidate is found; preemption is not helpful for scheduling" pod="default/cspod-50"
I0506 15:59:36.953726      12 schedule_one.go:1044] "Unable to schedule pod; no fit; waiting" pod="default/cspod-50" err="0/5 nodes are available: 5 Insufficient cpu. preemption: 0/5 nodes are available: 5 No preemption victims found for incoming pod."
I0506 15:59:36.954209      12 preemption.go:264] "No preemption candidate is found; preemption is not helpful for scheduling" pod="default/cspod-51"
I0506 15:59:36.954242      12 schedule_one.go:1044] "Unable to schedule pod; no fit; waiting" pod="default/cspod-51" err="0/5 nodes are available: 5 Insufficient cpu. preemption: 0/5 nodes are available: 5 No preemption victims found for incoming pod."
I0506 15:59:36.954746      12 preemption.go:264] "No preemption candidate is found; preemption is not helpful for scheduling" pod="default/cspod-52"
I0506 15:59:36.954780      12 schedule_one.go:1044] "Unable to schedule pod; no fit; waiting" pod="default/cspod-52" err="0/5 nodes are available: 5 Insufficient cpu. preemption: 0/5 nodes are available: 5 No preemption victims found for incoming pod."
I0506 15:59:36.955252      12 preemption.go:264] "No preemption candidate is found; preemption is not helpful for scheduling" pod="default/cspod-53"
I0506 15:59:36.955284      12 schedule_one.go:1044] "Unable to schedule pod; no fit; waiting" pod="default/cspod-53" err="0/5 nodes are available: 5 Insufficient cpu. preemption: 0/5 nodes are available: 5 No preemption victims found for incoming pod."
I0506 15:59:36.955776      12 preemption.go:264] "No preemption candidate is found; preemption is not helpful for scheduling" pod="default/cspod-54"
I0506 15:59:36.955820      12 schedule_one.go:1044] "Unable to schedule pod; no fit; waiting" pod="default/cspod-54" err="0/5 nodes are available: 5 Insufficient cpu. preemption: 0/5 nodes are available: 5 No preemption victims found for incoming pod."
I0506 15:59:36.956335      12 preemption.go:264] "No preemption candidate is found; preemption is not helpful for scheduling" pod="default/cspod-60"
I0506 15:59:36.956371      12 schedule_one.go:1044] "Unable to schedule pod; no fit; waiting" pod="default/cspod-60" err="0/5 nodes are available: 5 Insufficient cpu. preemption: 0/5 nodes are available: 5 No preemption victims found for incoming pod."
I0506 15:59:36.956891      12 preemption.go:264] "No preemption candidate is found; preemption is not helpful for scheduling" pod="default/cspod-61"
I0506 15:59:36.956923      12 schedule_one.go:1044] "Unable to schedule pod; no fit; waiting" pod="default/cspod-61" err="0/5 nodes are available: 5 Insufficient cpu. preemption: 0/5 nodes are available: 5 No preemption victims found for incoming pod."
I0506 15:59:36.957645      12 preemption.go:264] "No preemption candidate is found; preemption is not helpful for scheduling" pod="default/cspod-62"
I0506 15:59:36.957681      12 schedule_one.go:1044] "Unable to schedule pod; no fit; waiting" pod="default/cspod-62" err="0/5 nodes are available: 5 Insufficient cpu. preemption: 0/5 nodes are available: 5 No preemption victims found for incoming pod."
I0506 15:59:36.958201      12 preemption.go:264] "No preemption candidate is found; preemption is not helpful for scheduling" pod="default/cspod-63"
I0506 15:59:36.958236      12 schedule_one.go:1044] "Unable to schedule pod; no fit; waiting" pod="default/cspod-63" err="0/5 nodes are available: 5 Insufficient cpu. preemption: 0/5 nodes are available: 5 No preemption victims found for incoming pod."
I0506 15:59:36.958742      12 preemption.go:264] "No preemption candidate is found; preemption is not helpful for scheduling" pod="default/cspod-64"
I0506 15:59:36.958773      12 schedule_one.go:1044] "Unable to schedule pod; no fit; waiting" pod="default/cspod-64" err="0/5 nodes are available: 5 Insufficient cpu. preemption: 0/5 nodes are available: 5 No preemption victims found for incoming pod."
I0506 15:59:36.959261      12 preemption.go:264] "No preemption candidate is found; preemption is not helpful for scheduling" pod="default/cspod-65"
I0506 15:59:36.959292      12 schedule_one.go:1044] "Unable to schedule pod; no fit; waiting" pod="default/cspod-65" err="0/5 nodes are available: 5 Insufficient cpu. preemption: 0/5 nodes are available: 5 No preemption victims found for incoming pod."
I0506 15:59:36.959826      12 preemption.go:264] "No preemption candidate is found; preemption is not helpful for scheduling" pod="default/cspod-66"
I0506 15:59:36.959859      12 schedule_one.go:1044] "Unable to schedule pod; no fit; waiting" pod="default/cspod-66" err="0/5 nodes are available: 5 Insufficient cpu. preemption: 0/5 nodes are available: 5 No preemption victims found for incoming pod."
I0506 15:59:36.960335      12 preemption.go:264] "No preemption candidate is found; preemption is not helpful for scheduling" pod="default/cspod-67"
I0506 15:59:36.960367      12 schedule_one.go:1044] "Unable to schedule pod; no fit; waiting" pod="default/cspod-67" err="0/5 nodes are available: 5 Insufficient cpu. preemption: 0/5 nodes are available: 5 No preemption victims found for incoming pod."
I0506 15:59:36.960928      12 preemption.go:264] "No preemption candidate is found; preemption is not helpful for scheduling" pod="default/cspod-68"
I0506 15:59:36.960961      12 schedule_one.go:1044] "Unable to schedule pod; no fit; waiting" pod="default/cspod-68" err="0/5 nodes are available: 5 Insufficient cpu. preemption: 0/5 nodes are available: 5 No preemption victims found for incoming pod."
I0506 15:59:36.961470      12 preemption.go:264] "No preemption candidate is found; preemption is not helpful for scheduling" pod="default/cspod-69"
I0506 15:59:36.961506      12 schedule_one.go:1044] "Unable to schedule pod; no fit; waiting" pod="default/cspod-69" err="0/5 nodes are available: 5 Insufficient cpu. preemption: 0/5 nodes are available: 5 No preemption victims found for incoming pod."
I0506 15:59:36.975486      12 preemption.go:264] "No preemption candidate is found; preemption is not helpful for scheduling" pod="default/cspod-46"
I0506 15:59:36.975524      12 schedule_one.go:1044] "Unable to schedule pod; no fit; waiting" pod="default/cspod-46" err="0/5 nodes are available: 5 Insufficient cpu. preemption: 0/5 nodes are available: 5 No preemption victims found for incoming pod."
I0506 15:59:36.975592      12 schedule_one.go:314] "Successfully bound pod to node" pod="default/cspod-43" node="csnode-3" evaluatedNodes=5 feasibleNodes=2
I0506 15:59:36.985817      12 schedule_one.go:314] "Successfully bound pod to node" pod="default/cspod-44" node="csnode-1" evaluatedNodes=5 feasibleNodes=1
I0506 15:59:37.005751      12 schedule_one.go:314] "Successfully bound pod to node" pod="default/cspod-45" node="csnode-1" evaluatedNodes=5 feasibleNodes=1
I0506 15:59:37.025870      12 preemption.go:264] "No preemption candidate is found; preemption is not helpful for scheduling" pod="default/cspod-47"
I0506 15:59:37.025919      12 schedule_one.go:1044] "Unable to schedule pod; no fit; waiting" pod="default/cspod-47" err="0/5 nodes are available: 5 Insufficient cpu. preemption: 0/5 nodes are available: 5 No preemption victims found for incoming pod."
I0506 15:59:37.046096      12 preemption.go:264] "No preemption candidate is found; preemption is not helpful for scheduling" pod="default/cspod-48"
I0506 15:59:37.046144      12 schedule_one.go:1044] "Unable to schedule pod; no fit; waiting" pod="default/cspod-48" err="0/5 nodes are available: 5 Insufficient cpu. preemption: 0/5 nodes are available: 5 No preemption victims found for incoming pod."
I0506 15:59:37.066533      12 preemption.go:264] "No preemption candidate is found; preemption is not helpful for scheduling" pod="default/cspod-49"
I0506 15:59:37.066587      12 schedule_one.go:1044] "Unable to schedule pod; no fit; waiting" pod="default/cspod-49" err="0/5 nodes are available: 5 Insufficient cpu. preemption: 0/5 nodes are available: 5 No preemption victims found for incoming pod."
I0506 15:59:37.085839      12 preemption.go:264] "No preemption candidate is found; preemption is not helpful for scheduling" pod="default/cspod-50"
I0506 15:59:37.085888      12 schedule_one.go:1044] "Unable to schedule pod; no fit; waiting" pod="default/cspod-50" err="0/5 nodes are available: 5 Insufficient cpu. preemption: 0/5 nodes are available: 5 No preemption victims found for incoming pod."
I0506 15:59:37.106423      12 preemption.go:264] "No preemption candidate is found; preemption is not helpful for scheduling" pod="default/cspod-51"
I0506 15:59:37.106475      12 schedule_one.go:1044] "Unable to schedule pod; no fit; waiting" pod="default/cspod-51" err="0/5 nodes are available: 5 Insufficient cpu. preemption: 0/5 nodes are available: 5 No preemption victims found for incoming pod."
I0506 15:59:37.126026      12 preemption.go:264] "No preemption candidate is found; preemption is not helpful for scheduling" pod="default/cspod-52"
I0506 15:59:37.126075      12 schedule_one.go:1044] "Unable to schedule pod; no fit; waiting" pod="default/cspod-52" err="0/5 nodes are available: 5 Insufficient cpu. preemption: 0/5 nodes are available: 5 No preemption victims found for incoming pod."
I0506 15:59:37.146516      12 preemption.go:264] "No preemption candidate is found; preemption is not helpful for scheduling" pod="default/cspod-53"
I0506 15:59:37.146579      12 schedule_one.go:1044] "Unable to schedule pod; no fit; waiting" pod="default/cspod-53" err="0/5 nodes are available: 5 Insufficient cpu. preemption: 0/5 nodes are available: 5 No preemption victims found for incoming pod."
I0506 15:59:37.165895      12 preemption.go:264] "No preemption candidate is found; preemption is not helpful for scheduling" pod="default/cspod-54"
I0506 15:59:37.165951      12 schedule_one.go:1044] "Unable to schedule pod; no fit; waiting" pod="default/cspod-54" err="0/5 nodes are available: 5 Insufficient cpu. preemption: 0/5 nodes are available: 5 No preemption victims found for incoming pod."
I0506 15:59:37.186645      12 preemption.go:264] "No preemption candidate is found; preemption is not helpful for scheduling" pod="default/cspod-60"
I0506 15:59:37.186694      12 schedule_one.go:1044] "Unable to schedule pod; no fit; waiting" pod="default/cspod-60" err="0/5 nodes are available: 5 Insufficient cpu. preemption: 0/5 nodes are available: 5 No preemption victims found for incoming pod."
I0506 15:59:37.206069      12 preemption.go:264] "No preemption candidate is found; preemption is not helpful for scheduling" pod="default/cspod-61"
I0506 15:59:37.206116      12 schedule_one.go:1044] "Unable to schedule pod; no fit; waiting" pod="default/cspod-61" err="0/5 nodes are available: 5 Insufficient cpu. preemption: 0/5 nodes are available: 5 No preemption victims found for incoming pod."
I0506 15:59:37.225974      12 preemption.go:264] "No preemption candidate is found; preemption is not helpful for scheduling" pod="default/cspod-62"
I0506 15:59:37.226018      12 schedule_one.go:1044] "Unable to schedule pod; no fit; waiting" pod="default/cspod-62" err="0/5 nodes are available: 5 Insufficient cpu. preemption: 0/5 nodes are available: 5 No preemption victims found for incoming pod."
I0506 15:59:37.246174      12 preemption.go:264] "No preemption candidate is found; preemption is not helpful for scheduling" pod="default/cspod-63"
I0506 15:59:37.246222      12 schedule_one.go:1044] "Unable to schedule pod; no fit; waiting" pod="default/cspod-63" err="0/5 nodes are available: 5 Insufficient cpu. preemption: 0/5 nodes are available: 5 No preemption victims found for incoming pod."
I0506 15:59:37.266411      12 preemption.go:264] "No preemption candidate is found; preemption is not helpful for scheduling" pod="default/cspod-64"
I0506 15:59:37.266459      12 schedule_one.go:1044] "Unable to schedule pod; no fit; waiting" pod="default/cspod-64" err="0/5 nodes are available: 5 Insufficient cpu. preemption: 0/5 nodes are available: 5 No preemption victims found for incoming pod."
I0506 15:59:37.285530      12 preemption.go:264] "No preemption candidate is found; preemption is not helpful for scheduling" pod="default/cspod-65"
I0506 15:59:37.285573      12 schedule_one.go:1044] "Unable to schedule pod; no fit; waiting" pod="default/cspod-65" err="0/5 nodes are available: 5 Insufficient cpu. preemption: 0/5 nodes are available: 5 No preemption victims found for incoming pod."
I0506 15:59:37.306178      12 preemption.go:264] "No preemption candidate is found; preemption is not helpful for scheduling" pod="default/cspod-66"
I0506 15:59:37.306218      12 schedule_one.go:1044] "Unable to schedule pod; no fit; waiting" pod="default/cspod-66" err="0/5 nodes are available: 5 Insufficient cpu. preemption: 0/5 nodes are available: 5 No preemption victims found for incoming pod."
I0506 15:59:37.326684      12 preemption.go:264] "No preemption candidate is found; preemption is not helpful for scheduling" pod="default/cspod-67"
I0506 15:59:37.326734      12 schedule_one.go:1044] "Unable to schedule pod; no fit; waiting" pod="default/cspod-67" err="0/5 nodes are available: 5 Insufficient cpu. preemption: 0/5 nodes are available: 5 No preemption victims found for incoming pod."
E0506 15:59:37.342257      12 event.go:368] "Unable to write event (may retry after sleeping)" err="0-length response with status code: 201 and content type: application/vnd.kubernetes.protobuf" event="&Event{ObjectMeta:{cspod-2.18ad053979f62f80  default    0 0001-01-01 00:00:00 +0000 UTC <nil> <nil> map[] map[] [] [] []},InvolvedObject:ObjectReference{Kind:Pod,Namespace:default,Name:cspod-2,UID:cspod-2-uid,APIVersion:v1,ResourceVersion:8,FieldPath:,},Reason:Scheduled,Message:Successfully assigned default/cspod-2 to csnode-3,Source:EventSource{Component:my-scheduler,Host:,},FirstTimestamp:2026-05-06 15:59:32.298665856 +0000 UTC m=+7.376697256,LastTimestamp:2026-05-06 15:59:32.298665856 +0000 UTC m=+7.376697256,Count:1,Type:Normal,EventTime:0001-01-01 00:00:00 +0000 UTC,Series:nil,Action:,Related:nil,ReportingController:my-scheduler,ReportingInstance:,}"
I0506 15:59:37.346332      12 preemption.go:264] "No preemption candidate is found; preemption is not helpful for scheduling" pod="default/cspod-68"
I0506 15:59:37.346376      12 schedule_one.go:1044] "Unable to schedule pod; no fit; waiting" pod="default/cspod-68" err="0/5 nodes are available: 5 Insufficient cpu. preemption: 0/5 nodes are available: 5 No preemption victims found for incoming pod."
I0506 15:59:37.366142      12 preemption.go:264] "No preemption candidate is found; preemption is not helpful for scheduling" pod="default/cspod-69"
I0506 15:59:37.366183      12 schedule_one.go:1044] "Unable to schedule pod; no fit; waiting" pod="default/cspod-69" err="0/5 nodes are available: 5 Insufficient cpu. preemption: 0/5 nodes are available: 5 No preemption victims found for incoming pod."
I0506 15:59:37.392484      12 preemption.go:264] "No preemption candidate is found; preemption is not helpful for scheduling" pod="default/cspod-49"
I0506 15:59:37.392530      12 schedule_one.go:1044] "Unable to schedule pod; no fit; waiting" pod="default/cspod-49" err="0/5 nodes are available: 5 Insufficient cpu. preemption: 0/5 nodes are available: 5 No preemption victims found for incoming pod."
I0506 15:59:37.405510      12 schedule_one.go:314] "Successfully bound pod to node" pod="default/cspod-46" node="csnode-0" evaluatedNodes=5 feasibleNodes=1
I0506 15:59:37.425314      12 schedule_one.go:314] "Successfully bound pod to node" pod="default/cspod-47" node="csnode-2" evaluatedNodes=5 feasibleNodes=1
I0506 15:59:37.446014      12 schedule_one.go:314] "Successfully bound pod to node" pod="default/cspod-48" node="csnode-2" evaluatedNodes=5 feasibleNodes=1
I0506 15:59:37.466067      12 preemption.go:264] "No preemption candidate is found; preemption is not helpful for scheduling" pod="default/cspod-50"
I0506 15:59:37.466115      12 schedule_one.go:1044] "Unable to schedule pod; no fit; waiting" pod="default/cspod-50" err="0/5 nodes are available: 5 Insufficient cpu. preemption: 0/5 nodes are available: 5 No preemption victims found for incoming pod."
I0506 15:59:37.486138      12 preemption.go:264] "No preemption candidate is found; preemption is not helpful for scheduling" pod="default/cspod-51"
I0506 15:59:37.486178      12 schedule_one.go:1044] "Unable to schedule pod; no fit; waiting" pod="default/cspod-51" err="0/5 nodes are available: 5 Insufficient cpu. preemption: 0/5 nodes are available: 5 No preemption victims found for incoming pod."
I0506 15:59:37.506430      12 preemption.go:264] "No preemption candidate is found; preemption is not helpful for scheduling" pod="default/cspod-52"
I0506 15:59:37.506506      12 schedule_one.go:1044] "Unable to schedule pod; no fit; waiting" pod="default/cspod-52" err="0/5 nodes are available: 5 Insufficient cpu. preemption: 0/5 nodes are available: 5 No preemption victims found for incoming pod."
I0506 15:59:37.525843      12 preemption.go:264] "No preemption candidate is found; preemption is not helpful for scheduling" pod="default/cspod-53"
I0506 15:59:37.525894      12 schedule_one.go:1044] "Unable to schedule pod; no fit; waiting" pod="default/cspod-53" err="0/5 nodes are available: 5 Insufficient cpu. preemption: 0/5 nodes are available: 5 No preemption victims found for incoming pod."
I0506 15:59:37.546146      12 preemption.go:264] "No preemption candidate is found; preemption is not helpful for scheduling" pod="default/cspod-54"
I0506 15:59:37.546190      12 schedule_one.go:1044] "Unable to schedule pod; no fit; waiting" pod="default/cspod-54" err="0/5 nodes are available: 5 Insufficient cpu. preemption: 0/5 nodes are available: 5 No preemption victims found for incoming pod."
I0506 15:59:37.566267      12 preemption.go:264] "No preemption candidate is found; preemption is not helpful for scheduling" pod="default/cspod-60"
I0506 15:59:37.566307      12 schedule_one.go:1044] "Unable to schedule pod; no fit; waiting" pod="default/cspod-60" err="0/5 nodes are available: 5 Insufficient cpu. preemption: 0/5 nodes are available: 5 No preemption victims found for incoming pod."
I0506 15:59:37.586395      12 preemption.go:264] "No preemption candidate is found; preemption is not helpful for scheduling" pod="default/cspod-61"
I0506 15:59:37.586461      12 schedule_one.go:1044] "Unable to schedule pod; no fit; waiting" pod="default/cspod-61" err="0/5 nodes are available: 5 Insufficient cpu. preemption: 0/5 nodes are available: 5 No preemption victims found for incoming pod."
I0506 15:59:37.605648      12 preemption.go:264] "No preemption candidate is found; preemption is not helpful for scheduling" pod="default/cspod-62"
I0506 15:59:37.605693      12 schedule_one.go:1044] "Unable to schedule pod; no fit; waiting" pod="default/cspod-62" err="0/5 nodes are available: 5 Insufficient cpu. preemption: 0/5 nodes are available: 5 No preemption victims found for incoming pod."
I0506 15:59:37.625681      12 preemption.go:264] "No preemption candidate is found; preemption is not helpful for scheduling" pod="default/cspod-63"
I0506 15:59:37.625721      12 schedule_one.go:1044] "Unable to schedule pod; no fit; waiting" pod="default/cspod-63" err="0/5 nodes are available: 5 Insufficient cpu. preemption: 0/5 nodes are available: 5 No preemption victims found for incoming pod."
I0506 15:59:37.645698      12 preemption.go:264] "No preemption candidate is found; preemption is not helpful for scheduling" pod="default/cspod-64"
I0506 15:59:37.645737      12 schedule_one.go:1044] "Unable to schedule pod; no fit; waiting" pod="default/cspod-64" err="0/5 nodes are available: 5 Insufficient cpu. preemption: 0/5 nodes are available: 5 No preemption victims found for incoming pod."
I0506 15:59:37.665825      12 preemption.go:264] "No preemption candidate is found; preemption is not helpful for scheduling" pod="default/cspod-65"
I0506 15:59:37.665904      12 schedule_one.go:1044] "Unable to schedule pod; no fit; waiting" pod="default/cspod-65" err="0/5 nodes are available: 5 Insufficient cpu. preemption: 0/5 nodes are available: 5 No preemption victims found for incoming pod."
I0506 15:59:37.686144      12 preemption.go:264] "No preemption candidate is found; preemption is not helpful for scheduling" pod="default/cspod-66"
I0506 15:59:37.686190      12 schedule_one.go:1044] "Unable to schedule pod; no fit; waiting" pod="default/cspod-66" err="0/5 nodes are available: 5 Insufficient cpu. preemption: 0/5 nodes are available: 5 No preemption victims found for incoming pod."
I0506 15:59:37.706213      12 preemption.go:264] "No preemption candidate is found; preemption is not helpful for scheduling" pod="default/cspod-67"
I0506 15:59:37.706256      12 schedule_one.go:1044] "Unable to schedule pod; no fit; waiting" pod="default/cspod-67" err="0/5 nodes are available: 5 Insufficient cpu. preemption: 0/5 nodes are available: 5 No preemption victims found for incoming pod."
I0506 15:59:37.726458      12 preemption.go:264] "No preemption candidate is found; preemption is not helpful for scheduling" pod="default/cspod-68"
I0506 15:59:37.726494      12 schedule_one.go:1044] "Unable to schedule pod; no fit; waiting" pod="default/cspod-68" err="0/5 nodes are available: 5 Insufficient cpu. preemption: 0/5 nodes are available: 5 No preemption victims found for incoming pod."
I0506 15:59:37.745515      12 preemption.go:264] "No preemption candidate is found; preemption is not helpful for scheduling" pod="default/cspod-69"
I0506 15:59:37.745564      12 schedule_one.go:1044] "Unable to schedule pod; no fit; waiting" pod="default/cspod-69" err="0/5 nodes are available: 5 Insufficient cpu. preemption: 0/5 nodes are available: 5 No preemption victims found for incoming pod."
I0506 15:59:37.774547      12 preemption.go:264] "No preemption candidate is found; preemption is not helpful for scheduling" pod="default/cspod-51"
I0506 15:59:37.774595      12 schedule_one.go:1044] "Unable to schedule pod; no fit; waiting" pod="default/cspod-51" err="0/5 nodes are available: 5 Insufficient cpu. preemption: 0/5 nodes are available: 5 No preemption victims found for incoming pod."
I0506 15:59:37.786022      12 schedule_one.go:314] "Successfully bound pod to node" pod="default/cspod-49" node="csnode-4" evaluatedNodes=5 feasibleNodes=1
I0506 15:59:37.805774      12 schedule_one.go:314] "Successfully bound pod to node" pod="default/cspod-50" node="csnode-4" evaluatedNodes=5 feasibleNodes=1
I0506 15:59:37.825975      12 preemption.go:264] "No preemption candidate is found; preemption is not helpful for scheduling" pod="default/cspod-52"
I0506 15:59:37.826049      12 schedule_one.go:1044] "Unable to schedule pod; no fit; waiting" pod="default/cspod-52" err="0/5 nodes are available: 5 Insufficient cpu. preemption: 0/5 nodes are available: 5 No preemption victims found for incoming pod."
I0506 15:59:37.846199      12 preemption.go:264] "No preemption candidate is found; preemption is not helpful for scheduling" pod="default/cspod-53"
I0506 15:59:37.846276      12 schedule_one.go:1044] "Unable to schedule pod; no fit; waiting" pod="default/cspod-53" err="0/5 nodes are available: 5 Insufficient cpu. preemption: 0/5 nodes are available: 5 No preemption victims found for incoming pod."
I0506 15:59:37.865551      12 preemption.go:264] "No preemption candidate is found; preemption is not helpful for scheduling" pod="default/cspod-54"
I0506 15:59:37.865602      12 schedule_one.go:1044] "Unable to schedule pod; no fit; waiting" pod="default/cspod-54" err="0/5 nodes are available: 5 Insufficient cpu. preemption: 0/5 nodes are available: 5 No preemption victims found for incoming pod."
I0506 15:59:37.885629      12 preemption.go:264] "No preemption candidate is found; preemption is not helpful for scheduling" pod="default/cspod-60"
I0506 15:59:37.885675      12 schedule_one.go:1044] "Unable to schedule pod; no fit; waiting" pod="default/cspod-60" err="0/5 nodes are available: 5 Insufficient cpu. preemption: 0/5 nodes are available: 5 No preemption victims found for incoming pod."
I0506 15:59:37.905700      12 preemption.go:264] "No preemption candidate is found; preemption is not helpful for scheduling" pod="default/cspod-61"
I0506 15:59:37.905747      12 schedule_one.go:1044] "Unable to schedule pod; no fit; waiting" pod="default/cspod-61" err="0/5 nodes are available: 5 Insufficient cpu. preemption: 0/5 nodes are available: 5 No preemption victims found for incoming pod."
I0506 15:59:37.926060      12 preemption.go:264] "No preemption candidate is found; preemption is not helpful for scheduling" pod="default/cspod-62"
I0506 15:59:37.926109      12 schedule_one.go:1044] "Unable to schedule pod; no fit; waiting" pod="default/cspod-62" err="0/5 nodes are available: 5 Insufficient cpu. preemption: 0/5 nodes are available: 5 No preemption victims found for incoming pod."
I0506 15:59:37.946318      12 preemption.go:264] "No preemption candidate is found; preemption is not helpful for scheduling" pod="default/cspod-63"
I0506 15:59:37.946368      12 schedule_one.go:1044] "Unable to schedule pod; no fit; waiting" pod="default/cspod-63" err="0/5 nodes are available: 5 Insufficient cpu. preemption: 0/5 nodes are available: 5 No preemption victims found for incoming pod."
I0506 15:59:37.966085      12 preemption.go:264] "No preemption candidate is found; preemption is not helpful for scheduling" pod="default/cspod-64"
I0506 15:59:37.966127      12 schedule_one.go:1044] "Unable to schedule pod; no fit; waiting" pod="default/cspod-64" err="0/5 nodes are available: 5 Insufficient cpu. preemption: 0/5 nodes are available: 5 No preemption victims found for incoming pod."
I0506 15:59:37.985982      12 preemption.go:264] "No preemption candidate is found; preemption is not helpful for scheduling" pod="default/cspod-65"
I0506 15:59:37.986024      12 schedule_one.go:1044] "Unable to schedule pod; no fit; waiting" pod="default/cspod-65" err="0/5 nodes are available: 5 Insufficient cpu. preemption: 0/5 nodes are available: 5 No preemption victims found for incoming pod."
I0506 15:59:38.006390      12 preemption.go:264] "No preemption candidate is found; preemption is not helpful for scheduling" pod="default/cspod-66"
I0506 15:59:38.006435      12 schedule_one.go:1044] "Unable to schedule pod; no fit; waiting" pod="default/cspod-66" err="0/5 nodes are available: 5 Insufficient cpu. preemption: 0/5 nodes are available: 5 No preemption victims found for incoming pod."
I0506 15:59:38.026255      12 preemption.go:264] "No preemption candidate is found; preemption is not helpful for scheduling" pod="default/cspod-67"
I0506 15:59:38.026326      12 schedule_one.go:1044] "Unable to schedule pod; no fit; waiting" pod="default/cspod-67" err="0/5 nodes are available: 5 Insufficient cpu. preemption: 0/5 nodes are available: 5 No preemption victims found for incoming pod."
I0506 15:59:38.045523      12 preemption.go:264] "No preemption candidate is found; preemption is not helpful for scheduling" pod="default/cspod-68"
I0506 15:59:38.045571      12 schedule_one.go:1044] "Unable to schedule pod; no fit; waiting" pod="default/cspod-68" err="0/5 nodes are available: 5 Insufficient cpu. preemption: 0/5 nodes are available: 5 No preemption victims found for incoming pod."
I0506 15:59:38.065365      12 preemption.go:264] "No preemption candidate is found; preemption is not helpful for scheduling" pod="default/cspod-69"
I0506 15:59:38.065410      12 schedule_one.go:1044] "Unable to schedule pod; no fit; waiting" pod="default/cspod-69" err="0/5 nodes are available: 5 Insufficient cpu. preemption: 0/5 nodes are available: 5 No preemption victims found for incoming pod."
I0506 15:59:38.091828      12 preemption.go:264] "No preemption candidate is found; preemption is not helpful for scheduling" pod="default/cspod-53"
I0506 15:59:38.091872      12 schedule_one.go:1044] "Unable to schedule pod; no fit; waiting" pod="default/cspod-53" err="0/5 nodes are available: 5 Insufficient cpu. preemption: 0/5 nodes are available: 5 No preemption victims found for incoming pod."
I0506 15:59:38.104917      12 schedule_one.go:314] "Successfully bound pod to node" pod="default/cspod-51" node="csnode-3" evaluatedNodes=5 feasibleNodes=2
I0506 15:59:38.126133      12 schedule_one.go:314] "Successfully bound pod to node" pod="default/cspod-52" node="csnode-0" evaluatedNodes=5 feasibleNodes=1
I0506 15:59:38.146383      12 preemption.go:264] "No preemption candidate is found; preemption is not helpful for scheduling" pod="default/cspod-54"
I0506 15:59:38.146429      12 schedule_one.go:1044] "Unable to schedule pod; no fit; waiting" pod="default/cspod-54" err="0/5 nodes are available: 5 Insufficient cpu. preemption: 0/5 nodes are available: 5 No preemption victims found for incoming pod."
I0506 15:59:38.165635      12 preemption.go:264] "No preemption candidate is found; preemption is not helpful for scheduling" pod="default/cspod-60"
I0506 15:59:38.165671      12 schedule_one.go:1044] "Unable to schedule pod; no fit; waiting" pod="default/cspod-60" err="0/5 nodes are available: 5 Insufficient cpu. preemption: 0/5 nodes are available: 5 No preemption victims found for incoming pod."
I0506 15:59:38.186095      12 preemption.go:264] "No preemption candidate is found; preemption is not helpful for scheduling" pod="default/cspod-61"
I0506 15:59:38.186143      12 schedule_one.go:1044] "Unable to schedule pod; no fit; waiting" pod="default/cspod-61" err="0/5 nodes are available: 5 Insufficient cpu. preemption: 0/5 nodes are available: 5 No preemption victims found for incoming pod."
I0506 15:59:38.205711      12 preemption.go:264] "No preemption candidate is found; preemption is not helpful for scheduling" pod="default/cspod-62"
I0506 15:59:38.205755      12 schedule_one.go:1044] "Unable to schedule pod; no fit; waiting" pod="default/cspod-62" err="0/5 nodes are available: 5 Insufficient cpu. preemption: 0/5 nodes are available: 5 No preemption victims found for incoming pod."
I0506 15:59:38.226102      12 preemption.go:264] "No preemption candidate is found; preemption is not helpful for scheduling" pod="default/cspod-63"
I0506 15:59:38.226146      12 schedule_one.go:1044] "Unable to schedule pod; no fit; waiting" pod="default/cspod-63" err="0/5 nodes are available: 5 Insufficient cpu. preemption: 0/5 nodes are available: 5 No preemption victims found for incoming pod."
I0506 15:59:38.246150      12 preemption.go:264] "No preemption candidate is found; preemption is not helpful for scheduling" pod="default/cspod-64"
I0506 15:59:38.246189      12 schedule_one.go:1044] "Unable to schedule pod; no fit; waiting" pod="default/cspod-64" err="0/5 nodes are available: 5 Insufficient cpu. preemption: 0/5 nodes are available: 5 No preemption victims found for incoming pod."
I0506 15:59:38.266361      12 preemption.go:264] "No preemption candidate is found; preemption is not helpful for scheduling" pod="default/cspod-65"
I0506 15:59:38.266404      12 schedule_one.go:1044] "Unable to schedule pod; no fit; waiting" pod="default/cspod-65" err="0/5 nodes are available: 5 Insufficient cpu. preemption: 0/5 nodes are available: 5 No preemption victims found for incoming pod."
I0506 15:59:38.286723      12 preemption.go:264] "No preemption candidate is found; preemption is not helpful for scheduling" pod="default/cspod-66"
I0506 15:59:38.286775      12 schedule_one.go:1044] "Unable to schedule pod; no fit; waiting" pod="default/cspod-66" err="0/5 nodes are available: 5 Insufficient cpu. preemption: 0/5 nodes are available: 5 No preemption victims found for incoming pod."
I0506 15:59:38.305830      12 preemption.go:264] "No preemption candidate is found; preemption is not helpful for scheduling" pod="default/cspod-67"
I0506 15:59:38.305882      12 schedule_one.go:1044] "Unable to schedule pod; no fit; waiting" pod="default/cspod-67" err="0/5 nodes are available: 5 Insufficient cpu. preemption: 0/5 nodes are available: 5 No preemption victims found for incoming pod."
I0506 15:59:38.326040      12 preemption.go:264] "No preemption candidate is found; preemption is not helpful for scheduling" pod="default/cspod-68"
I0506 15:59:38.326093      12 schedule_one.go:1044] "Unable to schedule pod; no fit; waiting" pod="default/cspod-68" err="0/5 nodes are available: 5 Insufficient cpu. preemption: 0/5 nodes are available: 5 No preemption victims found for incoming pod."
I0506 15:59:38.345767      12 preemption.go:264] "No preemption candidate is found; preemption is not helpful for scheduling" pod="default/cspod-69"
I0506 15:59:38.345808      12 schedule_one.go:1044] "Unable to schedule pod; no fit; waiting" pod="default/cspod-69" err="0/5 nodes are available: 5 Insufficient cpu. preemption: 0/5 nodes are available: 5 No preemption victims found for incoming pod."
I0506 15:59:38.373091      12 preemption.go:264] "No preemption candidate is found; preemption is not helpful for scheduling" pod="default/cspod-61"
I0506 15:59:38.373144      12 schedule_one.go:1044] "Unable to schedule pod; no fit; waiting" pod="default/cspod-61" err="0/5 nodes are available: 5 Insufficient cpu. preemption: 0/5 nodes are available: 5 No preemption victims found for incoming pod."
I0506 15:59:38.386305      12 schedule_one.go:314] "Successfully bound pod to node" pod="default/cspod-53" node="csnode-1" evaluatedNodes=5 feasibleNodes=1
I0506 15:59:38.405631      12 schedule_one.go:314] "Successfully bound pod to node" pod="default/cspod-54" node="csnode-1" evaluatedNodes=5 feasibleNodes=2
I0506 15:59:38.426019      12 schedule_one.go:314] "Successfully bound pod to node" pod="default/cspod-60" node="csnode-3" evaluatedNodes=5 feasibleNodes=1
I0506 15:59:38.445885      12 preemption.go:264] "No preemption candidate is found; preemption is not helpful for scheduling" pod="default/cspod-62"
I0506 15:59:38.445933      12 schedule_one.go:1044] "Unable to schedule pod; no fit; waiting" pod="default/cspod-62" err="0/5 nodes are available: 5 Insufficient cpu. preemption: 0/5 nodes are available: 5 No preemption victims found for incoming pod."
I0506 15:59:38.466161      12 preemption.go:264] "No preemption candidate is found; preemption is not helpful for scheduling" pod="default/cspod-63"
I0506 15:59:38.466209      12 schedule_one.go:1044] "Unable to schedule pod; no fit; waiting" pod="default/cspod-63" err="0/5 nodes are available: 5 Insufficient cpu. preemption: 0/5 nodes are available: 5 No preemption victims found for incoming pod."
I0506 15:59:38.486358      12 preemption.go:264] "No preemption candidate is found; preemption is not helpful for scheduling" pod="default/cspod-64"
I0506 15:59:38.486404      12 schedule_one.go:1044] "Unable to schedule pod; no fit; waiting" pod="default/cspod-64" err="0/5 nodes are available: 5 Insufficient cpu. preemption: 0/5 nodes are available: 5 No preemption victims found for incoming pod."
I0506 15:59:38.506396      12 preemption.go:264] "No preemption candidate is found; preemption is not helpful for scheduling" pod="default/cspod-65"
I0506 15:59:38.506464      12 schedule_one.go:1044] "Unable to schedule pod; no fit; waiting" pod="default/cspod-65" err="0/5 nodes are available: 5 Insufficient cpu. preemption: 0/5 nodes are available: 5 No preemption victims found for incoming pod."
I0506 15:59:38.525759      12 preemption.go:264] "No preemption candidate is found; preemption is not helpful for scheduling" pod="default/cspod-66"
I0506 15:59:38.525807      12 schedule_one.go:1044] "Unable to schedule pod; no fit; waiting" pod="default/cspod-66" err="0/5 nodes are available: 5 Insufficient cpu. preemption: 0/5 nodes are available: 5 No preemption victims found for incoming pod."
I0506 15:59:38.546357      12 preemption.go:264] "No preemption candidate is found; preemption is not helpful for scheduling" pod="default/cspod-67"
I0506 15:59:38.546406      12 schedule_one.go:1044] "Unable to schedule pod; no fit; waiting" pod="default/cspod-67" err="0/5 nodes are available: 5 Insufficient cpu. preemption: 0/5 nodes are available: 5 No preemption victims found for incoming pod."
I0506 15:59:38.565820      12 preemption.go:264] "No preemption candidate is found; preemption is not helpful for scheduling" pod="default/cspod-68"
I0506 15:59:38.565870      12 schedule_one.go:1044] "Unable to schedule pod; no fit; waiting" pod="default/cspod-68" err="0/5 nodes are available: 5 Insufficient cpu. preemption: 0/5 nodes are available: 5 No preemption victims found for incoming pod."
I0506 15:59:38.586270      12 preemption.go:264] "No preemption candidate is found; preemption is not helpful for scheduling" pod="default/cspod-69"
I0506 15:59:38.586337      12 schedule_one.go:1044] "Unable to schedule pod; no fit; waiting" pod="default/cspod-69" err="0/5 nodes are available: 5 Insufficient cpu. preemption: 0/5 nodes are available: 5 No preemption victims found for incoming pod."
I0506 15:59:38.613458      12 preemption.go:264] "No preemption candidate is found; preemption is not helpful for scheduling" pod="default/cspod-64"
I0506 15:59:38.613506      12 schedule_one.go:1044] "Unable to schedule pod; no fit; waiting" pod="default/cspod-64" err="0/5 nodes are available: 5 Insufficient cpu. preemption: 0/5 nodes are available: 5 No preemption victims found for incoming pod."
I0506 15:59:38.625344      12 schedule_one.go:314] "Successfully bound pod to node" pod="default/cspod-61" node="csnode-0" evaluatedNodes=5 feasibleNodes=2
I0506 15:59:38.645788      12 schedule_one.go:314] "Successfully bound pod to node" pod="default/cspod-62" node="csnode-2" evaluatedNodes=5 feasibleNodes=1
I0506 15:59:38.665621      12 schedule_one.go:314] "Successfully bound pod to node" pod="default/cspod-63" node="csnode-2" evaluatedNodes=5 feasibleNodes=1
I0506 15:59:38.685833      12 preemption.go:264] "No preemption candidate is found; preemption is not helpful for scheduling" pod="default/cspod-65"
I0506 15:59:38.685879      12 schedule_one.go:1044] "Unable to schedule pod; no fit; waiting" pod="default/cspod-65" err="0/5 nodes are available: 5 Insufficient cpu. preemption: 0/5 nodes are available: 5 No preemption victims found for incoming pod."
I0506 15:59:38.705757      12 preemption.go:264] "No preemption candidate is found; preemption is not helpful for scheduling" pod="default/cspod-66"
I0506 15:59:38.705811      12 schedule_one.go:1044] "Unable to schedule pod; no fit; waiting" pod="default/cspod-66" err="0/5 nodes are available: 5 Insufficient cpu. preemption: 0/5 nodes are available: 5 No preemption victims found for incoming pod."
I0506 15:59:38.725794      12 preemption.go:264] "No preemption candidate is found; preemption is not helpful for scheduling" pod="default/cspod-67"
I0506 15:59:38.725848      12 schedule_one.go:1044] "Unable to schedule pod; no fit; waiting" pod="default/cspod-67" err="0/5 nodes are available: 5 Insufficient cpu. preemption: 0/5 nodes are available: 5 No preemption victims found for incoming pod."
I0506 15:59:38.745605      12 preemption.go:264] "No preemption candidate is found; preemption is not helpful for scheduling" pod="default/cspod-68"
I0506 15:59:38.745653      12 schedule_one.go:1044] "Unable to schedule pod; no fit; waiting" pod="default/cspod-68" err="0/5 nodes are available: 5 Insufficient cpu. preemption: 0/5 nodes are available: 5 No preemption victims found for incoming pod."
I0506 15:59:38.765227      12 preemption.go:264] "No preemption candidate is found; preemption is not helpful for scheduling" pod="default/cspod-69"
I0506 15:59:38.765300      12 schedule_one.go:1044] "Unable to schedule pod; no fit; waiting" pod="default/cspod-69" err="0/5 nodes are available: 5 Insufficient cpu. preemption: 0/5 nodes are available: 5 No preemption victims found for incoming pod."
I0506 15:59:38.792927      12 preemption.go:264] "No preemption candidate is found; preemption is not helpful for scheduling" pod="default/cspod-66"
I0506 15:59:38.792973      12 schedule_one.go:1044] "Unable to schedule pod; no fit; waiting" pod="default/cspod-66" err="0/5 nodes are available: 5 Insufficient cpu. preemption: 0/5 nodes are available: 5 No preemption victims found for incoming pod."
I0506 15:59:38.805354      12 schedule_one.go:314] "Successfully bound pod to node" pod="default/cspod-64" node="csnode-4" evaluatedNodes=5 feasibleNodes=1
I0506 15:59:38.825305      12 schedule_one.go:314] "Successfully bound pod to node" pod="default/cspod-65" node="csnode-4" evaluatedNodes=5 feasibleNodes=1
I0506 15:59:38.845399      12 preemption.go:264] "No preemption candidate is found; preemption is not helpful for scheduling" pod="default/cspod-67"
I0506 15:59:38.845452      12 schedule_one.go:1044] "Unable to schedule pod; no fit; waiting" pod="default/cspod-67" err="0/5 nodes are available: 5 Insufficient cpu. preemption: 0/5 nodes are available: 5 No preemption victims found for incoming pod."
I0506 15:59:38.866298      12 preemption.go:264] "No preemption candidate is found; preemption is not helpful for scheduling" pod="default/cspod-68"
I0506 15:59:38.866343      12 schedule_one.go:1044] "Unable to schedule pod; no fit; waiting" pod="default/cspod-68" err="0/5 nodes are available: 5 Insufficient cpu. preemption: 0/5 nodes are available: 5 No preemption victims found for incoming pod."
I0506 15:59:38.886032      12 preemption.go:264] "No preemption candidate is found; preemption is not helpful for scheduling" pod="default/cspod-69"
I0506 15:59:38.886076      12 schedule_one.go:1044] "Unable to schedule pod; no fit; waiting" pod="default/cspod-69" err="0/5 nodes are available: 5 Insufficient cpu. preemption: 0/5 nodes are available: 5 No preemption victims found for incoming pod."
I0506 15:59:38.913022      12 preemption.go:264] "No preemption candidate is found; preemption is not helpful for scheduling" pod="default/cspod-67"
I0506 15:59:38.913078      12 schedule_one.go:1044] "Unable to schedule pod; no fit; waiting" pod="default/cspod-67" err="0/5 nodes are available: 5 Insufficient cpu. preemption: 0/5 nodes are available: 5 No preemption victims found for incoming pod."
I0506 15:59:38.925585      12 schedule_one.go:314] "Successfully bound pod to node" pod="default/cspod-66" node="csnode-3" evaluatedNodes=5 feasibleNodes=1
I0506 15:59:38.945411      12 preemption.go:264] "No preemption candidate is found; preemption is not helpful for scheduling" pod="default/cspod-68"
I0506 15:59:38.945448      12 schedule_one.go:1044] "Unable to schedule pod; no fit; waiting" pod="default/cspod-68" err="0/5 nodes are available: 5 Insufficient cpu. preemption: 0/5 nodes are available: 5 No preemption victims found for incoming pod."
I0506 15:59:38.965588      12 preemption.go:264] "No preemption candidate is found; preemption is not helpful for scheduling" pod="default/cspod-69"
I0506 15:59:38.965629      12 schedule_one.go:1044] "Unable to schedule pod; no fit; waiting" pod="default/cspod-69" err="0/5 nodes are available: 5 Insufficient cpu. preemption: 0/5 nodes are available: 5 No preemption victims found for incoming pod."
I0506 15:59:39.005193      12 schedule_one.go:314] "Successfully bound pod to node" pod="default/cspod-67" node="csnode-1" evaluatedNodes=5 feasibleNodes=2
I0506 15:59:39.025811      12 schedule_one.go:314] "Successfully bound pod to node" pod="default/cspod-68" node="csnode-0" evaluatedNodes=5 feasibleNodes=2
I0506 15:59:39.045631      12 schedule_one.go:314] "Successfully bound pod to node" pod="default/cspod-69" node="csnode-1" evaluatedNodes=5 feasibleNodes=1
I0506 15:59:39.063719      12 node_tree.go:79] "Removed node from NodeTree" node="csnode-1" zone=""
I0506 15:59:39.063759      12 node_tree.go:79] "Removed node from NodeTree" node="csnode-2" zone=""
I0506 15:59:39.063768      12 node_tree.go:79] "Removed node from NodeTree" node="csnode-3" zone=""
I0506 15:59:39.063770      12 node_tree.go:79] "Removed node from NodeTree" node="csnode-4" zone=""
I0506 15:59:39.063815      12 node_tree.go:79] "Removed node from NodeTree" node="csnode-0" zone=""
