2026/05/06 15:59:46 Running command:
Command env: (log-file=, also-stdout=false, redirect-stderr=true)
Run from directory: 
Executable path: /usr/local/bin/kube-scheduler
Args (comma-delimited): kube-scheduler,--config=/etc/kube-scheduler/my-scheduler.yaml,--secure-port=10260,--v=2
2026/05/06 15:59:46 Now listening for interrupts
I0506 15:59:46.325094      12 flags.go:64] FLAG: --allow-metric-labels="[]"
I0506 15:59:46.325147      12 flags.go:64] FLAG: --allow-metric-labels-manifest=""
I0506 15:59:46.325153      12 flags.go:64] FLAG: --authentication-kubeconfig=""
I0506 15:59:46.325155      12 flags.go:64] FLAG: --authentication-skip-lookup="false"
I0506 15:59:46.325157      12 flags.go:64] FLAG: --authentication-token-webhook-cache-ttl="10s"
I0506 15:59:46.325159      12 flags.go:64] FLAG: --authentication-tolerate-lookup-failure="true"
I0506 15:59:46.325160      12 flags.go:64] FLAG: --authorization-always-allow-paths="[/healthz,/readyz,/livez]"
I0506 15:59:46.325164      12 flags.go:64] FLAG: --authorization-kubeconfig=""
I0506 15:59:46.325165      12 flags.go:64] FLAG: --authorization-webhook-cache-authorized-ttl="10s"
I0506 15:59:46.325166      12 flags.go:64] FLAG: --authorization-webhook-cache-unauthorized-ttl="10s"
I0506 15:59:46.325167      12 flags.go:64] FLAG: --bind-address="0.0.0.0"
I0506 15:59:46.325170      12 flags.go:64] FLAG: --cert-dir=""
I0506 15:59:46.325171      12 flags.go:64] FLAG: --client-ca-file=""
I0506 15:59:46.325172      12 flags.go:64] FLAG: --config="/etc/kube-scheduler/my-scheduler.yaml"
I0506 15:59:46.325173      12 flags.go:64] FLAG: --contention-profiling="true"
I0506 15:59:46.325174      12 flags.go:64] FLAG: --disable-http2-serving="false"
I0506 15:59:46.325174      12 flags.go:64] FLAG: --disabled-metrics="[]"
I0506 15:59:46.325177      12 flags.go:64] FLAG: --emulated-version="[]"
I0506 15:59:46.325178      12 flags.go:64] FLAG: --feature-gates=""
I0506 15:59:46.325180      12 flags.go:64] FLAG: --help="false"
I0506 15:59:46.325181      12 flags.go:64] FLAG: --http2-max-streams-per-connection="0"
I0506 15:59:46.325182      12 flags.go:64] FLAG: --kube-api-burst="100"
I0506 15:59:46.325184      12 flags.go:64] FLAG: --kube-api-content-type="application/vnd.kubernetes.protobuf"
I0506 15:59:46.325185      12 flags.go:64] FLAG: --kube-api-qps="50"
I0506 15:59:46.325188      12 flags.go:64] FLAG: --kubeconfig=""
I0506 15:59:46.325189      12 flags.go:64] FLAG: --leader-elect="true"
I0506 15:59:46.325191      12 flags.go:64] FLAG: --leader-elect-lease-duration="15s"
I0506 15:59:46.325192      12 flags.go:64] FLAG: --leader-elect-renew-deadline="10s"
I0506 15:59:46.325193      12 flags.go:64] FLAG: --leader-elect-resource-lock="leases"
I0506 15:59:46.325194      12 flags.go:64] FLAG: --leader-elect-resource-name="kube-scheduler"
I0506 15:59:46.325195      12 flags.go:64] FLAG: --leader-elect-resource-namespace="kube-system"
I0506 15:59:46.325196      12 flags.go:64] FLAG: --leader-elect-retry-period="2s"
I0506 15:59:46.325197      12 flags.go:64] FLAG: --log-flush-frequency="5s"
I0506 15:59:46.325198      12 flags.go:64] FLAG: --log-json-info-buffer-size="0"
I0506 15:59:46.325200      12 flags.go:64] FLAG: --log-json-split-stream="false"
I0506 15:59:46.325201      12 flags.go:64] FLAG: --log-text-info-buffer-size="0"
I0506 15:59:46.325202      12 flags.go:64] FLAG: --log-text-split-stream="false"
I0506 15:59:46.325203      12 flags.go:64] FLAG: --logging-format="text"
I0506 15:59:46.325204      12 flags.go:64] FLAG: --master=""
I0506 15:59:46.325204      12 flags.go:64] FLAG: --permit-address-sharing="false"
I0506 15:59:46.325205      12 flags.go:64] FLAG: --permit-port-sharing="false"
I0506 15:59:46.325206      12 flags.go:64] FLAG: --pod-max-in-unschedulable-pods-duration="5m0s"
I0506 15:59:46.325207      12 flags.go:64] FLAG: --profiling="true"
I0506 15:59:46.325208      12 flags.go:64] FLAG: --requestheader-allowed-names="[]"
I0506 15:59:46.325213      12 flags.go:64] FLAG: --requestheader-client-ca-file=""
I0506 15:59:46.325214      12 flags.go:64] FLAG: --requestheader-extra-headers-prefix="[x-remote-extra-]"
I0506 15:59:46.325216      12 flags.go:64] FLAG: --requestheader-group-headers="[x-remote-group]"
I0506 15:59:46.325217      12 flags.go:64] FLAG: --requestheader-uid-headers="[]"
I0506 15:59:46.325219      12 flags.go:64] FLAG: --requestheader-username-headers="[x-remote-user]"
I0506 15:59:46.325220      12 flags.go:64] FLAG: --secure-port="10260"
I0506 15:59:46.325221      12 flags.go:64] FLAG: --show-hidden-metrics-for-version=""
I0506 15:59:46.325222      12 flags.go:64] FLAG: --tls-cert-file=""
I0506 15:59:46.325223      12 flags.go:64] FLAG: --tls-cipher-suites="[]"
I0506 15:59:46.325224      12 flags.go:64] FLAG: --tls-min-version=""
I0506 15:59:46.325225      12 flags.go:64] FLAG: --tls-private-key-file=""
I0506 15:59:46.325226      12 flags.go:64] FLAG: --tls-sni-cert-key="[]"
I0506 15:59:46.325228      12 flags.go:64] FLAG: --v="2"
I0506 15:59:46.325253      12 flags.go:64] FLAG: --version="false"
I0506 15:59:46.325258      12 flags.go:64] FLAG: --vmodule=""
I0506 15:59:46.325260      12 flags.go:64] FLAG: --write-config-to=""
I0506 15:59:46.641094      12 serving.go:386] Generated self-signed cert in-memory
W0506 15:59:46.773837      12 authentication.go:368] No authentication-kubeconfig provided in order to lookup client-ca-file in configmap/extension-apiserver-authentication in kube-system, so client certificate authentication won't work.
W0506 15:59:46.773872      12 authentication.go:392] No authentication-kubeconfig provided in order to lookup requestheader-client-ca-file in configmap/extension-apiserver-authentication in kube-system, so request-header client certificate authentication won't work.
W0506 15:59:46.773889      12 authorization.go:193] No authorization-kubeconfig provided, so SubjectAccessReview of authorization tokens won't work.
I0506 15:59:46.775854      12 framework.go:399] "the scheduler starts to work with those plugins" Plugins={"PreEnqueue":{"Enabled":[{"Name":"SchedulingGates","Weight":0},{"Name":"DefaultPreemption","Weight":0}],"Disabled":null},"QueueSort":{"Enabled":[{"Name":"PrioritySort","Weight":0}],"Disabled":null},"PreFilter":{"Enabled":[{"Name":"NodeAffinity","Weight":0},{"Name":"NodePorts","Weight":0},{"Name":"NodeResourcesFit","Weight":0},{"Name":"VolumeRestrictions","Weight":0},{"Name":"NodeVolumeLimits","Weight":0},{"Name":"VolumeBinding","Weight":0},{"Name":"VolumeZone","Weight":0},{"Name":"PodTopologySpread","Weight":0},{"Name":"InterPodAffinity","Weight":0}],"Disabled":null},"Filter":{"Enabled":[{"Name":"NodeUnschedulable","Weight":0},{"Name":"NodeName","Weight":0},{"Name":"TaintToleration","Weight":0},{"Name":"NodeAffinity","Weight":0},{"Name":"NodePorts","Weight":0},{"Name":"NodeResourcesFit","Weight":0},{"Name":"VolumeRestrictions","Weight":0},{"Name":"NodeVolumeLimits","Weight":0},{"Name":"VolumeBinding","Weight":0},{"Name":"VolumeZone","Weight":0},{"Name":"PodTopologySpread","Weight":0},{"Name":"InterPodAffinity","Weight":0}],"Disabled":null},"PostFilter":{"Enabled":[{"Name":"DefaultPreemption","Weight":0}],"Disabled":null},"PreScore":{"Enabled":[{"Name":"TaintToleration","Weight":0},{"Name":"NodeAffinity","Weight":0},{"Name":"NodeResourcesFit","Weight":0},{"Name":"VolumeBinding","Weight":0},{"Name":"PodTopologySpread","Weight":0},{"Name":"InterPodAffinity","Weight":0},{"Name":"NodeResourcesBalancedAllocation","Weight":0}],"Disabled":null},"Score":{"Enabled":[{"Name":"NodeResourcesFit","Weight":1}],"Disabled":null},"Reserve":{"Enabled":[{"Name":"VolumeBinding","Weight":0}],"Disabled":null},"Permit":{"Enabled":null,"Disabled":null},"PreBind":{"Enabled":[{"Name":"VolumeBinding","Weight":0}],"Disabled":null},"Bind":{"Enabled":[{"Name":"DefaultBinder","Weight":0}],"Disabled":null},"PostBind":{"Enabled":null,"Disabled":null},"MultiPoint":{"Enabled":null,"Disabled":null}}
I0506 15:59:46.776040      12 framework.go:399] "the scheduler starts to work with those plugins" Plugins={"PreEnqueue":{"Enabled":[{"Name":"SchedulingGates","Weight":0},{"Name":"DefaultPreemption","Weight":0}],"Disabled":null},"QueueSort":{"Enabled":[{"Name":"PrioritySort","Weight":0}],"Disabled":null},"PreFilter":{"Enabled":[{"Name":"NodeAffinity","Weight":0},{"Name":"NodePorts","Weight":0},{"Name":"NodeResourcesFit","Weight":0},{"Name":"VolumeRestrictions","Weight":0},{"Name":"NodeVolumeLimits","Weight":0},{"Name":"VolumeBinding","Weight":0},{"Name":"VolumeZone","Weight":0},{"Name":"PodTopologySpread","Weight":0},{"Name":"InterPodAffinity","Weight":0}],"Disabled":null},"Filter":{"Enabled":[{"Name":"NodeUnschedulable","Weight":0},{"Name":"NodeName","Weight":0},{"Name":"TaintToleration","Weight":0},{"Name":"NodeAffinity","Weight":0},{"Name":"NodePorts","Weight":0},{"Name":"NodeResourcesFit","Weight":0},{"Name":"VolumeRestrictions","Weight":0},{"Name":"NodeVolumeLimits","Weight":0},{"Name":"VolumeBinding","Weight":0},{"Name":"VolumeZone","Weight":0},{"Name":"PodTopologySpread","Weight":0},{"Name":"InterPodAffinity","Weight":0}],"Disabled":null},"PostFilter":{"Enabled":[{"Name":"DefaultPreemption","Weight":0}],"Disabled":null},"PreScore":{"Enabled":[{"Name":"TaintToleration","Weight":0},{"Name":"NodeAffinity","Weight":0},{"Name":"NodeResourcesFit","Weight":0},{"Name":"VolumeBinding","Weight":0},{"Name":"PodTopologySpread","Weight":0},{"Name":"InterPodAffinity","Weight":0},{"Name":"NodeResourcesBalancedAllocation","Weight":0}],"Disabled":null},"Score":{"Enabled":[{"Name":"NodeResourcesFit","Weight":1}],"Disabled":null},"Reserve":{"Enabled":[{"Name":"VolumeBinding","Weight":0}],"Disabled":null},"Permit":{"Enabled":null,"Disabled":null},"PreBind":{"Enabled":[{"Name":"VolumeBinding","Weight":0}],"Disabled":null},"Bind":{"Enabled":[{"Name":"DefaultBinder","Weight":0}],"Disabled":null},"PostBind":{"Enabled":null,"Disabled":null},"MultiPoint":{"Enabled":null,"Disabled":null}}
I0506 15:59:46.778274      12 configfile.go:94] "Using component config" config=<
	apiVersion: kubescheduler.config.k8s.io/v1
	clientConnection:
	  acceptContentTypes: ""
	  burst: 100
	  contentType: application/vnd.kubernetes.protobuf
	  kubeconfig: /etc/kube-scheduler/kubeconfig.yaml
	  qps: 50
	enableContentionProfiling: true
	enableProfiling: true
	kind: KubeSchedulerConfiguration
	leaderElection:
	  leaderElect: false
	  leaseDuration: 15s
	  renewDeadline: 10s
	  resourceLock: leases
	  resourceName: kube-scheduler
	  resourceNamespace: kube-system
	  retryPeriod: 2s
	parallelism: 16
	percentageOfNodesToScore: 0
	podInitialBackoffSeconds: 1
	podMaxBackoffSeconds: 10
	profiles:
	- pluginConfig:
	  - args:
	      apiVersion: kubescheduler.config.k8s.io/v1
	      kind: DefaultPreemptionArgs
	      minCandidateNodesAbsolute: 100
	      minCandidateNodesPercentage: 10
	    name: DefaultPreemption
	  - args:
	      apiVersion: kubescheduler.config.k8s.io/v1
	      hardPodAffinityWeight: 1
	      ignorePreferredTermsOfExistingPods: false
	      kind: InterPodAffinityArgs
	    name: InterPodAffinity
	  - args:
	      apiVersion: kubescheduler.config.k8s.io/v1
	      kind: NodeAffinityArgs
	    name: NodeAffinity
	  - args:
	      apiVersion: kubescheduler.config.k8s.io/v1
	      kind: NodeResourcesBalancedAllocationArgs
	      resources:
	      - name: cpu
	        weight: 1
	      - name: memory
	        weight: 1
	    name: NodeResourcesBalancedAllocation
	  - args:
	      apiVersion: kubescheduler.config.k8s.io/v1
	      kind: NodeResourcesFitArgs
	      scoringStrategy:
	        resources:
	        - name: cpu
	          weight: 1
	        - name: memory
	          weight: 1
	        type: LeastAllocated
	    name: NodeResourcesFit
	  - args:
	      apiVersion: kubescheduler.config.k8s.io/v1
	      defaultingType: System
	      kind: PodTopologySpreadArgs
	    name: PodTopologySpread
	  - args:
	      apiVersion: kubescheduler.config.k8s.io/v1
	      bindTimeoutSeconds: 600
	      kind: VolumeBindingArgs
	    name: VolumeBinding
	  plugins:
	    bind: {}
	    filter: {}
	    multiPoint:
	      enabled:
	      - name: SchedulingGates
	        weight: 0
	      - name: PrioritySort
	        weight: 0
	      - name: NodeUnschedulable
	        weight: 0
	      - name: NodeName
	        weight: 0
	      - name: TaintToleration
	        weight: 3
	      - name: NodeAffinity
	        weight: 2
	      - name: NodePorts
	        weight: 0
	      - name: NodeResourcesFit
	        weight: 1
	      - name: VolumeRestrictions
	        weight: 0
	      - name: NodeVolumeLimits
	        weight: 0
	      - name: VolumeBinding
	        weight: 0
	      - name: VolumeZone
	        weight: 0
	      - name: PodTopologySpread
	        weight: 2
	      - name: InterPodAffinity
	        weight: 2
	      - name: DefaultPreemption
	        weight: 0
	      - name: NodeResourcesBalancedAllocation
	        weight: 1
	      - name: ImageLocality
	        weight: 1
	      - name: DefaultBinder
	        weight: 0
	    permit: {}
	    postBind: {}
	    postFilter: {}
	    preBind: {}
	    preEnqueue: {}
	    preFilter: {}
	    preScore: {}
	    queueSort: {}
	    reserve: {}
	    score:
	      disabled:
	      - name: '*'
	        weight: 0
	      enabled:
	      - name: NodeResourcesFit
	        weight: 0
	  schedulerName: default-scheduler
	- pluginConfig:
	  - args:
	      apiVersion: kubescheduler.config.k8s.io/v1
	      kind: DefaultPreemptionArgs
	      minCandidateNodesAbsolute: 100
	      minCandidateNodesPercentage: 10
	    name: DefaultPreemption
	  - args:
	      apiVersion: kubescheduler.config.k8s.io/v1
	      hardPodAffinityWeight: 1
	      ignorePreferredTermsOfExistingPods: false
	      kind: InterPodAffinityArgs
	    name: InterPodAffinity
	  - args:
	      apiVersion: kubescheduler.config.k8s.io/v1
	      kind: NodeAffinityArgs
	    name: NodeAffinity
	  - args:
	      apiVersion: kubescheduler.config.k8s.io/v1
	      kind: NodeResourcesBalancedAllocationArgs
	      resources:
	      - name: cpu
	        weight: 1
	      - name: memory
	        weight: 1
	    name: NodeResourcesBalancedAllocation
	  - args:
	      apiVersion: kubescheduler.config.k8s.io/v1
	      kind: NodeResourcesFitArgs
	      scoringStrategy:
	        resources:
	        - name: cpu
	          weight: 1
	        - name: memory
	          weight: 1
	        type: MostAllocated
	    name: NodeResourcesFit
	  - args:
	      apiVersion: kubescheduler.config.k8s.io/v1
	      defaultingType: System
	      kind: PodTopologySpreadArgs
	    name: PodTopologySpread
	  - args:
	      apiVersion: kubescheduler.config.k8s.io/v1
	      bindTimeoutSeconds: 600
	      kind: VolumeBindingArgs
	    name: VolumeBinding
	  plugins:
	    bind: {}
	    filter: {}
	    multiPoint:
	      enabled:
	      - name: SchedulingGates
	        weight: 0
	      - name: PrioritySort
	        weight: 0
	      - name: NodeUnschedulable
	        weight: 0
	      - name: NodeName
	        weight: 0
	      - name: TaintToleration
	        weight: 3
	      - name: NodeAffinity
	        weight: 2
	      - name: NodePorts
	        weight: 0
	      - name: NodeResourcesFit
	        weight: 1
	      - name: VolumeRestrictions
	        weight: 0
	      - name: NodeVolumeLimits
	        weight: 0
	      - name: VolumeBinding
	        weight: 0
	      - name: VolumeZone
	        weight: 0
	      - name: PodTopologySpread
	        weight: 2
	      - name: InterPodAffinity
	        weight: 2
	      - name: DefaultPreemption
	        weight: 0
	      - name: NodeResourcesBalancedAllocation
	        weight: 1
	      - name: ImageLocality
	        weight: 1
	      - name: DefaultBinder
	        weight: 0
	    permit: {}
	    postBind: {}
	    postFilter: {}
	    preBind: {}
	    preEnqueue: {}
	    preFilter: {}
	    preScore: {}
	    queueSort: {}
	    reserve: {}
	    score:
	      disabled:
	      - name: '*'
	        weight: 0
	      enabled:
	      - name: NodeResourcesFit
	        weight: 0
	  schedulerName: my-scheduler
 >
I0506 15:59:46.778805      12 server.go:171] "Starting Kubernetes Scheduler" version="v1.33.0"
I0506 15:59:46.778835      12 server.go:173] "Golang settings" GOGC="" GOMAXPROCS="" GOTRACEBACK=""
I0506 15:59:46.779853      12 tlsconfig.go:203] "Loaded serving cert" certName="Generated self signed cert" certDetail="\"localhost@1778083186\" [serving] validServingFor=[127.0.0.1,localhost,localhost] issuer=\"localhost-ca@1778083186\" (2026-05-06 14:59:46 +0000 UTC to 2027-05-06 14:59:46 +0000 UTC (now=2026-05-06 15:59:46.779841555 +0000 UTC))"
I0506 15:59:46.779963      12 named_certificates.go:53] "Loaded SNI cert" index=0 certName="self-signed loopback" certDetail="\"apiserver-loopback-client@1778083186\" [serving] validServingFor=[apiserver-loopback-client] issuer=\"apiserver-loopback-client-ca@1778083186\" (2026-05-06 14:59:46 +0000 UTC to 2029-05-06 14:59:46 +0000 UTC (now=2026-05-06 15:59:46.779956589 +0000 UTC))"
I0506 15:59:46.780025      12 secure_serving.go:211] Serving securely on [::]:10260
I0506 15:59:46.780080      12 tlsconfig.go:243] "Starting DynamicServingCertificateController"
I0506 15:59:46.782205      12 reflector.go:430] "Caches populated" type="*v1.PodDisruptionBudget" reflector="k8s.io/client-go/informers/factory.go:160"
I0506 15:59:46.782239      12 reflector.go:430] "Caches populated" type="*v1.PersistentVolumeClaim" reflector="k8s.io/client-go/informers/factory.go:160"
I0506 15:59:46.782260      12 reflector.go:430] "Caches populated" type="*v1.PersistentVolume" reflector="k8s.io/client-go/informers/factory.go:160"
I0506 15:59:46.782206      12 reflector.go:430] "Caches populated" type="*v1.Namespace" reflector="k8s.io/client-go/informers/factory.go:160"
I0506 15:59:46.782372      12 reflector.go:430] "Caches populated" type="*v1.ReplicaSet" reflector="k8s.io/client-go/informers/factory.go:160"
I0506 15:59:46.782587      12 reflector.go:430] "Caches populated" type="*v1.StorageClass" reflector="k8s.io/client-go/informers/factory.go:160"
I0506 15:59:46.782625      12 reflector.go:430] "Caches populated" type="*v1.CSIDriver" reflector="k8s.io/client-go/informers/factory.go:160"
I0506 15:59:46.782799      12 reflector.go:430] "Caches populated" type="*v1.CSIStorageCapacity" reflector="k8s.io/client-go/informers/factory.go:160"
I0506 15:59:46.782881      12 reflector.go:430] "Caches populated" type="*v1.StatefulSet" reflector="k8s.io/client-go/informers/factory.go:160"
I0506 15:59:46.782910      12 reflector.go:430] "Caches populated" type="*v1.Node" reflector="k8s.io/client-go/informers/factory.go:160"
I0506 15:59:46.783000      12 reflector.go:430] "Caches populated" type="*v1.CSINode" reflector="k8s.io/client-go/informers/factory.go:160"
I0506 15:59:46.783060      12 reflector.go:430] "Caches populated" type="*v1.VolumeAttachment" reflector="k8s.io/client-go/informers/factory.go:160"
I0506 15:59:46.783548      12 reflector.go:430] "Caches populated" type="*v1.Service" reflector="k8s.io/client-go/informers/factory.go:160"
I0506 15:59:46.783872      12 reflector.go:430] "Caches populated" type="*v1.ReplicationController" reflector="k8s.io/client-go/informers/factory.go:160"
I0506 15:59:46.784077      12 reflector.go:430] "Caches populated" type="*v1.Pod" reflector="k8s.io/client-go/informers/factory.go:160"
I0506 15:59:51.658026      12 node_tree.go:65] "Added node to NodeTree" node="csnode-0" zone=""
I0506 15:59:51.658091      12 node_tree.go:65] "Added node to NodeTree" node="csnode-1" zone=""
I0506 15:59:51.658104      12 node_tree.go:65] "Added node to NodeTree" node="csnode-2" zone=""
I0506 15:59:51.658108      12 node_tree.go:65] "Added node to NodeTree" node="csnode-3" zone=""
I0506 15:59:51.658113      12 node_tree.go:65] "Added node to NodeTree" node="csnode-4" zone=""
I0506 15:59:51.681256      12 schedule_one.go:314] "Successfully bound pod to node" pod="default/cspod-1" node="csnode-0" evaluatedNodes=5 feasibleNodes=5
I0506 15:59:51.681550      12 preemption.go:264] "No preemption candidate is found; preemption is not helpful for scheduling" pod="default/cspod-10"
I0506 15:59:51.681620      12 schedule_one.go:1044] "Unable to schedule pod; no fit; waiting" pod="default/cspod-10" err="0/5 nodes are available: 5 Insufficient cpu. preemption: 0/5 nodes are available: 5 No preemption victims found for incoming pod."
I0506 15:59:51.805551      12 schedule_one.go:314] "Successfully bound pod to node" pod="default/cspod-5" node="csnode-1" evaluatedNodes=5 feasibleNodes=5
I0506 15:59:51.805547      12 schedule_one.go:314] "Successfully bound pod to node" pod="default/cspod-0" node="csnode-1" evaluatedNodes=5 feasibleNodes=5
I0506 15:59:51.805617      12 schedule_one.go:314] "Successfully bound pod to node" pod="default/cspod-4" node="csnode-3" evaluatedNodes=5 feasibleNodes=5
I0506 15:59:51.805629      12 schedule_one.go:314] "Successfully bound pod to node" pod="default/cspod-7" node="csnode-0" evaluatedNodes=5 feasibleNodes=3
I0506 15:59:51.805638      12 schedule_one.go:314] "Successfully bound pod to node" pod="default/cspod-3" node="csnode-2" evaluatedNodes=5 feasibleNodes=5
I0506 15:59:51.805663      12 schedule_one.go:314] "Successfully bound pod to node" pod="default/cspod-2" node="csnode-4" evaluatedNodes=5 feasibleNodes=5
I0506 15:59:51.805674      12 schedule_one.go:314] "Successfully bound pod to node" pod="default/cspod-6" node="csnode-4" evaluatedNodes=5 feasibleNodes=4
I0506 15:59:51.805702      12 schedule_one.go:314] "Successfully bound pod to node" pod="default/cspod-8" node="csnode-3" evaluatedNodes=5 feasibleNodes=2
E0506 15:59:51.805699      12 event.go:368] "Unable to write event (may retry after sleeping)" err="0-length response with status code: 201 and content type: application/vnd.kubernetes.protobuf" event="&Event{ObjectMeta:{cspod-1.18ad053dfd4083af  default    0 0001-01-01 00:00:00 +0000 UTC <nil> <nil> map[] map[] [] [] []},InvolvedObject:ObjectReference{Kind:Pod,Namespace:default,Name:cspod-1,UID:cspod-1-uid,APIVersion:v1,ResourceVersion:7,FieldPath:,},Reason:Scheduled,Message:Successfully assigned default/cspod-1 to csnode-0,Source:EventSource{Component:default-scheduler,Host:,},FirstTimestamp:2026-05-06 15:59:51.681221551 +0000 UTC m=+7.115148449,LastTimestamp:2026-05-06 15:59:51.681221551 +0000 UTC m=+7.115148449,Count:1,Type:Normal,EventTime:0001-01-01 00:00:00 +0000 UTC,Series:nil,Action:,Related:nil,ReportingController:default-scheduler,ReportingInstance:,}"
I0506 15:59:51.806008      12 schedule_one.go:314] "Successfully bound pod to node" pod="default/cspod-9" node="csnode-2" evaluatedNodes=5 feasibleNodes=1
I0506 15:59:51.806181      12 preemption.go:264] "No preemption candidate is found; preemption is not helpful for scheduling" pod="default/cspod-11"
I0506 15:59:51.806222      12 schedule_one.go:1044] "Unable to schedule pod; no fit; waiting" pod="default/cspod-11" err="0/5 nodes are available: 5 Insufficient cpu. preemption: 0/5 nodes are available: 5 No preemption victims found for incoming pod."
I0506 15:59:51.806896      12 preemption.go:264] "No preemption candidate is found; preemption is not helpful for scheduling" pod="default/cspod-12"
I0506 15:59:51.806947      12 schedule_one.go:1044] "Unable to schedule pod; no fit; waiting" pod="default/cspod-12" err="0/5 nodes are available: 5 Insufficient cpu. preemption: 0/5 nodes are available: 5 No preemption victims found for incoming pod."
I0506 15:59:51.807600      12 preemption.go:264] "No preemption candidate is found; preemption is not helpful for scheduling" pod="default/cspod-13"
I0506 15:59:51.807635      12 schedule_one.go:1044] "Unable to schedule pod; no fit; waiting" pod="default/cspod-13" err="0/5 nodes are available: 5 Insufficient cpu. preemption: 0/5 nodes are available: 5 No preemption victims found for incoming pod."
I0506 15:59:51.808657      12 preemption.go:264] "No preemption candidate is found; preemption is not helpful for scheduling" pod="default/cspod-14"
I0506 15:59:51.808709      12 schedule_one.go:1044] "Unable to schedule pod; no fit; waiting" pod="default/cspod-14" err="0/5 nodes are available: 5 Insufficient cpu. preemption: 0/5 nodes are available: 5 No preemption victims found for incoming pod."
I0506 15:59:51.809669      12 preemption.go:264] "No preemption candidate is found; preemption is not helpful for scheduling" pod="default/cspod-15"
I0506 15:59:51.809703      12 schedule_one.go:1044] "Unable to schedule pod; no fit; waiting" pod="default/cspod-15" err="0/5 nodes are available: 5 Insufficient cpu. preemption: 0/5 nodes are available: 5 No preemption victims found for incoming pod."
I0506 15:59:51.810251      12 preemption.go:264] "No preemption candidate is found; preemption is not helpful for scheduling" pod="default/cspod-16"
I0506 15:59:51.810286      12 schedule_one.go:1044] "Unable to schedule pod; no fit; waiting" pod="default/cspod-16" err="0/5 nodes are available: 5 Insufficient cpu. preemption: 0/5 nodes are available: 5 No preemption victims found for incoming pod."
I0506 15:59:51.810820      12 preemption.go:264] "No preemption candidate is found; preemption is not helpful for scheduling" pod="default/cspod-17"
I0506 15:59:51.810853      12 schedule_one.go:1044] "Unable to schedule pod; no fit; waiting" pod="default/cspod-17" err="0/5 nodes are available: 5 Insufficient cpu. preemption: 0/5 nodes are available: 5 No preemption victims found for incoming pod."
I0506 15:59:51.811381      12 preemption.go:264] "No preemption candidate is found; preemption is not helpful for scheduling" pod="default/cspod-18"
I0506 15:59:51.811413      12 schedule_one.go:1044] "Unable to schedule pod; no fit; waiting" pod="default/cspod-18" err="0/5 nodes are available: 5 Insufficient cpu. preemption: 0/5 nodes are available: 5 No preemption victims found for incoming pod."
I0506 15:59:51.811933      12 preemption.go:264] "No preemption candidate is found; preemption is not helpful for scheduling" pod="default/cspod-19"
I0506 15:59:51.811969      12 schedule_one.go:1044] "Unable to schedule pod; no fit; waiting" pod="default/cspod-19" err="0/5 nodes are available: 5 Insufficient cpu. preemption: 0/5 nodes are available: 5 No preemption victims found for incoming pod."
I0506 15:59:51.812517      12 preemption.go:264] "No preemption candidate is found; preemption is not helpful for scheduling" pod="default/cspod-20"
I0506 15:59:51.812552      12 schedule_one.go:1044] "Unable to schedule pod; no fit; waiting" pod="default/cspod-20" err="0/5 nodes are available: 5 Insufficient cpu. preemption: 0/5 nodes are available: 5 No preemption victims found for incoming pod."
I0506 15:59:51.813084      12 preemption.go:264] "No preemption candidate is found; preemption is not helpful for scheduling" pod="default/cspod-21"
I0506 15:59:51.813118      12 schedule_one.go:1044] "Unable to schedule pod; no fit; waiting" pod="default/cspod-21" err="0/5 nodes are available: 5 Insufficient cpu. preemption: 0/5 nodes are available: 5 No preemption victims found for incoming pod."
I0506 15:59:51.813631      12 preemption.go:264] "No preemption candidate is found; preemption is not helpful for scheduling" pod="default/cspod-22"
I0506 15:59:51.813665      12 schedule_one.go:1044] "Unable to schedule pod; no fit; waiting" pod="default/cspod-22" err="0/5 nodes are available: 5 Insufficient cpu. preemption: 0/5 nodes are available: 5 No preemption victims found for incoming pod."
I0506 15:59:51.814180      12 preemption.go:264] "No preemption candidate is found; preemption is not helpful for scheduling" pod="default/cspod-23"
I0506 15:59:51.814215      12 schedule_one.go:1044] "Unable to schedule pod; no fit; waiting" pod="default/cspod-23" err="0/5 nodes are available: 5 Insufficient cpu. preemption: 0/5 nodes are available: 5 No preemption victims found for incoming pod."
I0506 15:59:51.814890      12 preemption.go:264] "No preemption candidate is found; preemption is not helpful for scheduling" pod="default/cspod-24"
I0506 15:59:51.814938      12 schedule_one.go:1044] "Unable to schedule pod; no fit; waiting" pod="default/cspod-24" err="0/5 nodes are available: 5 Insufficient cpu. preemption: 0/5 nodes are available: 5 No preemption victims found for incoming pod."
I0506 15:59:51.815420      12 preemption.go:264] "No preemption candidate is found; preemption is not helpful for scheduling" pod="default/cspod-25"
I0506 15:59:51.815458      12 schedule_one.go:1044] "Unable to schedule pod; no fit; waiting" pod="default/cspod-25" err="0/5 nodes are available: 5 Insufficient cpu. preemption: 0/5 nodes are available: 5 No preemption victims found for incoming pod."
I0506 15:59:51.815940      12 preemption.go:264] "No preemption candidate is found; preemption is not helpful for scheduling" pod="default/cspod-26"
I0506 15:59:51.815972      12 schedule_one.go:1044] "Unable to schedule pod; no fit; waiting" pod="default/cspod-26" err="0/5 nodes are available: 5 Insufficient cpu. preemption: 0/5 nodes are available: 5 No preemption victims found for incoming pod."
I0506 15:59:51.816513      12 preemption.go:264] "No preemption candidate is found; preemption is not helpful for scheduling" pod="default/cspod-27"
I0506 15:59:51.816548      12 schedule_one.go:1044] "Unable to schedule pod; no fit; waiting" pod="default/cspod-27" err="0/5 nodes are available: 5 Insufficient cpu. preemption: 0/5 nodes are available: 5 No preemption victims found for incoming pod."
I0506 15:59:51.817023      12 preemption.go:264] "No preemption candidate is found; preemption is not helpful for scheduling" pod="default/cspod-28"
I0506 15:59:51.817055      12 schedule_one.go:1044] "Unable to schedule pod; no fit; waiting" pod="default/cspod-28" err="0/5 nodes are available: 5 Insufficient cpu. preemption: 0/5 nodes are available: 5 No preemption victims found for incoming pod."
I0506 15:59:51.817662      12 preemption.go:264] "No preemption candidate is found; preemption is not helpful for scheduling" pod="default/cspod-29"
I0506 15:59:51.817698      12 schedule_one.go:1044] "Unable to schedule pod; no fit; waiting" pod="default/cspod-29" err="0/5 nodes are available: 5 Insufficient cpu. preemption: 0/5 nodes are available: 5 No preemption victims found for incoming pod."
I0506 15:59:51.818239      12 preemption.go:264] "No preemption candidate is found; preemption is not helpful for scheduling" pod="default/cspod-30"
I0506 15:59:51.818274      12 schedule_one.go:1044] "Unable to schedule pod; no fit; waiting" pod="default/cspod-30" err="0/5 nodes are available: 5 Insufficient cpu. preemption: 0/5 nodes are available: 5 No preemption victims found for incoming pod."
I0506 15:59:51.818817      12 preemption.go:264] "No preemption candidate is found; preemption is not helpful for scheduling" pod="default/cspod-31"
I0506 15:59:51.818850      12 schedule_one.go:1044] "Unable to schedule pod; no fit; waiting" pod="default/cspod-31" err="0/5 nodes are available: 5 Insufficient cpu. preemption: 0/5 nodes are available: 5 No preemption victims found for incoming pod."
I0506 15:59:51.819380      12 preemption.go:264] "No preemption candidate is found; preemption is not helpful for scheduling" pod="default/cspod-32"
I0506 15:59:51.819412      12 schedule_one.go:1044] "Unable to schedule pod; no fit; waiting" pod="default/cspod-32" err="0/5 nodes are available: 5 Insufficient cpu. preemption: 0/5 nodes are available: 5 No preemption victims found for incoming pod."
I0506 15:59:51.819957      12 preemption.go:264] "No preemption candidate is found; preemption is not helpful for scheduling" pod="default/cspod-33"
I0506 15:59:51.819991      12 schedule_one.go:1044] "Unable to schedule pod; no fit; waiting" pod="default/cspod-33" err="0/5 nodes are available: 5 Insufficient cpu. preemption: 0/5 nodes are available: 5 No preemption victims found for incoming pod."
I0506 15:59:51.820526      12 preemption.go:264] "No preemption candidate is found; preemption is not helpful for scheduling" pod="default/cspod-34"
I0506 15:59:51.820559      12 schedule_one.go:1044] "Unable to schedule pod; no fit; waiting" pod="default/cspod-34" err="0/5 nodes are available: 5 Insufficient cpu. preemption: 0/5 nodes are available: 5 No preemption victims found for incoming pod."
I0506 15:59:51.821080      12 preemption.go:264] "No preemption candidate is found; preemption is not helpful for scheduling" pod="default/cspod-35"
I0506 15:59:51.821115      12 schedule_one.go:1044] "Unable to schedule pod; no fit; waiting" pod="default/cspod-35" err="0/5 nodes are available: 5 Insufficient cpu. preemption: 0/5 nodes are available: 5 No preemption victims found for incoming pod."
I0506 15:59:51.821617      12 preemption.go:264] "No preemption candidate is found; preemption is not helpful for scheduling" pod="default/cspod-36"
I0506 15:59:51.821649      12 schedule_one.go:1044] "Unable to schedule pod; no fit; waiting" pod="default/cspod-36" err="0/5 nodes are available: 5 Insufficient cpu. preemption: 0/5 nodes are available: 5 No preemption victims found for incoming pod."
I0506 15:59:51.908963      12 preemption.go:264] "No preemption candidate is found; preemption is not helpful for scheduling" pod="default/cspod-37"
I0506 15:59:51.909011      12 schedule_one.go:1044] "Unable to schedule pod; no fit; waiting" pod="default/cspod-37" err="0/5 nodes are available: 5 Insufficient cpu. preemption: 0/5 nodes are available: 5 No preemption victims found for incoming pod."
I0506 15:59:51.909701      12 preemption.go:264] "No preemption candidate is found; preemption is not helpful for scheduling" pod="default/cspod-38"
I0506 15:59:51.909739      12 schedule_one.go:1044] "Unable to schedule pod; no fit; waiting" pod="default/cspod-38" err="0/5 nodes are available: 5 Insufficient cpu. preemption: 0/5 nodes are available: 5 No preemption victims found for incoming pod."
I0506 15:59:51.910540      12 preemption.go:264] "No preemption candidate is found; preemption is not helpful for scheduling" pod="default/cspod-39"
I0506 15:59:51.910576      12 schedule_one.go:1044] "Unable to schedule pod; no fit; waiting" pod="default/cspod-39" err="0/5 nodes are available: 5 Insufficient cpu. preemption: 0/5 nodes are available: 5 No preemption victims found for incoming pod."
I0506 15:59:51.911230      12 preemption.go:264] "No preemption candidate is found; preemption is not helpful for scheduling" pod="default/cspod-40"
I0506 15:59:51.911269      12 schedule_one.go:1044] "Unable to schedule pod; no fit; waiting" pod="default/cspod-40" err="0/5 nodes are available: 5 Insufficient cpu. preemption: 0/5 nodes are available: 5 No preemption victims found for incoming pod."
I0506 15:59:51.911811      12 preemption.go:264] "No preemption candidate is found; preemption is not helpful for scheduling" pod="default/cspod-41"
I0506 15:59:51.911850      12 schedule_one.go:1044] "Unable to schedule pod; no fit; waiting" pod="default/cspod-41" err="0/5 nodes are available: 5 Insufficient cpu. preemption: 0/5 nodes are available: 5 No preemption victims found for incoming pod."
I0506 15:59:51.912388      12 preemption.go:264] "No preemption candidate is found; preemption is not helpful for scheduling" pod="default/cspod-42"
I0506 15:59:51.912421      12 schedule_one.go:1044] "Unable to schedule pod; no fit; waiting" pod="default/cspod-42" err="0/5 nodes are available: 5 Insufficient cpu. preemption: 0/5 nodes are available: 5 No preemption victims found for incoming pod."
I0506 15:59:51.912963      12 preemption.go:264] "No preemption candidate is found; preemption is not helpful for scheduling" pod="default/cspod-43"
I0506 15:59:51.913002      12 schedule_one.go:1044] "Unable to schedule pod; no fit; waiting" pod="default/cspod-43" err="0/5 nodes are available: 5 Insufficient cpu. preemption: 0/5 nodes are available: 5 No preemption victims found for incoming pod."
I0506 15:59:51.913507      12 preemption.go:264] "No preemption candidate is found; preemption is not helpful for scheduling" pod="default/cspod-44"
I0506 15:59:51.913540      12 schedule_one.go:1044] "Unable to schedule pod; no fit; waiting" pod="default/cspod-44" err="0/5 nodes are available: 5 Insufficient cpu. preemption: 0/5 nodes are available: 5 No preemption victims found for incoming pod."
I0506 15:59:51.914041      12 preemption.go:264] "No preemption candidate is found; preemption is not helpful for scheduling" pod="default/cspod-45"
I0506 15:59:51.914076      12 schedule_one.go:1044] "Unable to schedule pod; no fit; waiting" pod="default/cspod-45" err="0/5 nodes are available: 5 Insufficient cpu. preemption: 0/5 nodes are available: 5 No preemption victims found for incoming pod."
I0506 15:59:51.914572      12 preemption.go:264] "No preemption candidate is found; preemption is not helpful for scheduling" pod="default/cspod-46"
I0506 15:59:51.914607      12 schedule_one.go:1044] "Unable to schedule pod; no fit; waiting" pod="default/cspod-46" err="0/5 nodes are available: 5 Insufficient cpu. preemption: 0/5 nodes are available: 5 No preemption victims found for incoming pod."
I0506 15:59:51.915102      12 preemption.go:264] "No preemption candidate is found; preemption is not helpful for scheduling" pod="default/cspod-47"
I0506 15:59:51.915139      12 schedule_one.go:1044] "Unable to schedule pod; no fit; waiting" pod="default/cspod-47" err="0/5 nodes are available: 5 Insufficient cpu. preemption: 0/5 nodes are available: 5 No preemption victims found for incoming pod."
I0506 15:59:51.915676      12 preemption.go:264] "No preemption candidate is found; preemption is not helpful for scheduling" pod="default/cspod-48"
I0506 15:59:51.915708      12 schedule_one.go:1044] "Unable to schedule pod; no fit; waiting" pod="default/cspod-48" err="0/5 nodes are available: 5 Insufficient cpu. preemption: 0/5 nodes are available: 5 No preemption victims found for incoming pod."
I0506 15:59:51.916180      12 preemption.go:264] "No preemption candidate is found; preemption is not helpful for scheduling" pod="default/cspod-49"
I0506 15:59:51.916215      12 schedule_one.go:1044] "Unable to schedule pod; no fit; waiting" pod="default/cspod-49" err="0/5 nodes are available: 5 Insufficient cpu. preemption: 0/5 nodes are available: 5 No preemption victims found for incoming pod."
I0506 15:59:51.916723      12 preemption.go:264] "No preemption candidate is found; preemption is not helpful for scheduling" pod="default/cspod-50"
I0506 15:59:51.916763      12 schedule_one.go:1044] "Unable to schedule pod; no fit; waiting" pod="default/cspod-50" err="0/5 nodes are available: 5 Insufficient cpu. preemption: 0/5 nodes are available: 5 No preemption victims found for incoming pod."
I0506 15:59:51.917238      12 preemption.go:264] "No preemption candidate is found; preemption is not helpful for scheduling" pod="default/cspod-51"
I0506 15:59:51.917277      12 schedule_one.go:1044] "Unable to schedule pod; no fit; waiting" pod="default/cspod-51" err="0/5 nodes are available: 5 Insufficient cpu. preemption: 0/5 nodes are available: 5 No preemption victims found for incoming pod."
I0506 15:59:51.918370      12 preemption.go:264] "No preemption candidate is found; preemption is not helpful for scheduling" pod="default/cspod-52"
I0506 15:59:51.918403      12 schedule_one.go:1044] "Unable to schedule pod; no fit; waiting" pod="default/cspod-52" err="0/5 nodes are available: 5 Insufficient cpu. preemption: 0/5 nodes are available: 5 No preemption victims found for incoming pod."
I0506 15:59:51.918934      12 preemption.go:264] "No preemption candidate is found; preemption is not helpful for scheduling" pod="default/cspod-53"
I0506 15:59:51.918969      12 schedule_one.go:1044] "Unable to schedule pod; no fit; waiting" pod="default/cspod-53" err="0/5 nodes are available: 5 Insufficient cpu. preemption: 0/5 nodes are available: 5 No preemption victims found for incoming pod."
I0506 15:59:51.919501      12 preemption.go:264] "No preemption candidate is found; preemption is not helpful for scheduling" pod="default/cspod-54"
I0506 15:59:51.919534      12 schedule_one.go:1044] "Unable to schedule pod; no fit; waiting" pod="default/cspod-54" err="0/5 nodes are available: 5 Insufficient cpu. preemption: 0/5 nodes are available: 5 No preemption victims found for incoming pod."
I0506 15:59:51.943003      12 schedule_one.go:314] "Successfully bound pod to node" pod="default/cspod-56" node="csnode-0" evaluatedNodes=5 feasibleNodes=4
I0506 15:59:51.943055      12 schedule_one.go:314] "Successfully bound pod to node" pod="default/cspod-55" node="csnode-2" evaluatedNodes=5 feasibleNodes=5
I0506 15:59:51.943321      12 schedule_one.go:314] "Successfully bound pod to node" pod="default/cspod-57" node="csnode-3" evaluatedNodes=5 feasibleNodes=3
I0506 15:59:51.943342      12 preemption.go:264] "No preemption candidate is found; preemption is not helpful for scheduling" pod="default/cspod-60"
I0506 15:59:51.943387      12 schedule_one.go:1044] "Unable to schedule pod; no fit; waiting" pod="default/cspod-60" err="0/5 nodes are available: 5 Insufficient cpu. preemption: 0/5 nodes are available: 5 No preemption victims found for incoming pod."
I0506 15:59:51.943422      12 schedule_one.go:314] "Successfully bound pod to node" pod="default/cspod-58" node="csnode-1" evaluatedNodes=5 feasibleNodes=2
I0506 15:59:51.943629      12 schedule_one.go:314] "Successfully bound pod to node" pod="default/cspod-59" node="csnode-4" evaluatedNodes=5 feasibleNodes=1
I0506 15:59:51.943986      12 preemption.go:264] "No preemption candidate is found; preemption is not helpful for scheduling" pod="default/cspod-61"
I0506 15:59:51.944023      12 schedule_one.go:1044] "Unable to schedule pod; no fit; waiting" pod="default/cspod-61" err="0/5 nodes are available: 5 Insufficient cpu. preemption: 0/5 nodes are available: 5 No preemption victims found for incoming pod."
I0506 15:59:51.944565      12 preemption.go:264] "No preemption candidate is found; preemption is not helpful for scheduling" pod="default/cspod-62"
I0506 15:59:51.944601      12 schedule_one.go:1044] "Unable to schedule pod; no fit; waiting" pod="default/cspod-62" err="0/5 nodes are available: 5 Insufficient cpu. preemption: 0/5 nodes are available: 5 No preemption victims found for incoming pod."
I0506 15:59:51.945124      12 preemption.go:264] "No preemption candidate is found; preemption is not helpful for scheduling" pod="default/cspod-63"
I0506 15:59:51.945159      12 schedule_one.go:1044] "Unable to schedule pod; no fit; waiting" pod="default/cspod-63" err="0/5 nodes are available: 5 Insufficient cpu. preemption: 0/5 nodes are available: 5 No preemption victims found for incoming pod."
I0506 15:59:51.945676      12 preemption.go:264] "No preemption candidate is found; preemption is not helpful for scheduling" pod="default/cspod-64"
I0506 15:59:51.945711      12 schedule_one.go:1044] "Unable to schedule pod; no fit; waiting" pod="default/cspod-64" err="0/5 nodes are available: 5 Insufficient cpu. preemption: 0/5 nodes are available: 5 No preemption victims found for incoming pod."
I0506 15:59:51.946301      12 preemption.go:264] "No preemption candidate is found; preemption is not helpful for scheduling" pod="default/cspod-65"
I0506 15:59:51.946337      12 schedule_one.go:1044] "Unable to schedule pod; no fit; waiting" pod="default/cspod-65" err="0/5 nodes are available: 5 Insufficient cpu. preemption: 0/5 nodes are available: 5 No preemption victims found for incoming pod."
I0506 15:59:51.946875      12 preemption.go:264] "No preemption candidate is found; preemption is not helpful for scheduling" pod="default/cspod-66"
I0506 15:59:51.946909      12 schedule_one.go:1044] "Unable to schedule pod; no fit; waiting" pod="default/cspod-66" err="0/5 nodes are available: 5 Insufficient cpu. preemption: 0/5 nodes are available: 5 No preemption victims found for incoming pod."
I0506 15:59:51.947402      12 preemption.go:264] "No preemption candidate is found; preemption is not helpful for scheduling" pod="default/cspod-67"
I0506 15:59:51.947435      12 schedule_one.go:1044] "Unable to schedule pod; no fit; waiting" pod="default/cspod-67" err="0/5 nodes are available: 5 Insufficient cpu. preemption: 0/5 nodes are available: 5 No preemption victims found for incoming pod."
I0506 15:59:51.947966      12 preemption.go:264] "No preemption candidate is found; preemption is not helpful for scheduling" pod="default/cspod-68"
I0506 15:59:51.948006      12 schedule_one.go:1044] "Unable to schedule pod; no fit; waiting" pod="default/cspod-68" err="0/5 nodes are available: 5 Insufficient cpu. preemption: 0/5 nodes are available: 5 No preemption victims found for incoming pod."
I0506 15:59:51.948533      12 preemption.go:264] "No preemption candidate is found; preemption is not helpful for scheduling" pod="default/cspod-69"
I0506 15:59:51.948568      12 schedule_one.go:1044] "Unable to schedule pod; no fit; waiting" pod="default/cspod-69" err="0/5 nodes are available: 5 Insufficient cpu. preemption: 0/5 nodes are available: 5 No preemption victims found for incoming pod."
I0506 15:59:51.964549      12 schedule_one.go:314] "Successfully bound pod to node" pod="default/cspod-10" node="csnode-0" evaluatedNodes=5 feasibleNodes=3
I0506 15:59:51.965289      12 schedule_one.go:314] "Successfully bound pod to node" pod="default/cspod-11" node="csnode-2" evaluatedNodes=5 feasibleNodes=5
I0506 15:59:51.965350      12 schedule_one.go:314] "Successfully bound pod to node" pod="default/cspod-12" node="csnode-3" evaluatedNodes=5 feasibleNodes=5
I0506 15:59:51.965574      12 schedule_one.go:314] "Successfully bound pod to node" pod="default/cspod-13" node="csnode-1" evaluatedNodes=5 feasibleNodes=5
I0506 15:59:51.965979      12 schedule_one.go:314] "Successfully bound pod to node" pod="default/cspod-14" node="csnode-4" evaluatedNodes=5 feasibleNodes=5
I0506 15:59:51.966059      12 schedule_one.go:314] "Successfully bound pod to node" pod="default/cspod-15" node="csnode-1" evaluatedNodes=5 feasibleNodes=5
I0506 15:59:51.966996      12 schedule_one.go:314] "Successfully bound pod to node" pod="default/cspod-17" node="csnode-4" evaluatedNodes=5 feasibleNodes=3
I0506 15:59:51.967018      12 schedule_one.go:314] "Successfully bound pod to node" pod="default/cspod-16" node="csnode-2" evaluatedNodes=5 feasibleNodes=4
I0506 15:59:51.967304      12 preemption.go:264] "No preemption candidate is found; preemption is not helpful for scheduling" pod="default/cspod-20"
I0506 15:59:51.967357      12 schedule_one.go:1044] "Unable to schedule pod; no fit; waiting" pod="default/cspod-20" err="0/5 nodes are available: 5 Insufficient cpu. preemption: 0/5 nodes are available: 5 No preemption victims found for incoming pod."
I0506 15:59:51.967379      12 schedule_one.go:314] "Successfully bound pod to node" pod="default/cspod-18" node="csnode-3" evaluatedNodes=5 feasibleNodes=2
I0506 15:59:51.967383      12 schedule_one.go:314] "Successfully bound pod to node" pod="default/cspod-19" node="csnode-0" evaluatedNodes=5 feasibleNodes=1
I0506 15:59:51.968000      12 preemption.go:264] "No preemption candidate is found; preemption is not helpful for scheduling" pod="default/cspod-21"
I0506 15:59:51.968052      12 schedule_one.go:1044] "Unable to schedule pod; no fit; waiting" pod="default/cspod-21" err="0/5 nodes are available: 5 Insufficient cpu. preemption: 0/5 nodes are available: 5 No preemption victims found for incoming pod."
I0506 15:59:51.968640      12 preemption.go:264] "No preemption candidate is found; preemption is not helpful for scheduling" pod="default/cspod-22"
I0506 15:59:51.968676      12 schedule_one.go:1044] "Unable to schedule pod; no fit; waiting" pod="default/cspod-22" err="0/5 nodes are available: 5 Insufficient cpu. preemption: 0/5 nodes are available: 5 No preemption victims found for incoming pod."
I0506 15:59:51.969279      12 preemption.go:264] "No preemption candidate is found; preemption is not helpful for scheduling" pod="default/cspod-23"
I0506 15:59:51.969316      12 schedule_one.go:1044] "Unable to schedule pod; no fit; waiting" pod="default/cspod-23" err="0/5 nodes are available: 5 Insufficient cpu. preemption: 0/5 nodes are available: 5 No preemption victims found for incoming pod."
I0506 15:59:51.969961      12 preemption.go:264] "No preemption candidate is found; preemption is not helpful for scheduling" pod="default/cspod-24"
I0506 15:59:51.969998      12 schedule_one.go:1044] "Unable to schedule pod; no fit; waiting" pod="default/cspod-24" err="0/5 nodes are available: 5 Insufficient cpu. preemption: 0/5 nodes are available: 5 No preemption victims found for incoming pod."
I0506 15:59:51.970619      12 preemption.go:264] "No preemption candidate is found; preemption is not helpful for scheduling" pod="default/cspod-25"
I0506 15:59:51.970660      12 schedule_one.go:1044] "Unable to schedule pod; no fit; waiting" pod="default/cspod-25" err="0/5 nodes are available: 5 Insufficient cpu. preemption: 0/5 nodes are available: 5 No preemption victims found for incoming pod."
I0506 15:59:51.971262      12 preemption.go:264] "No preemption candidate is found; preemption is not helpful for scheduling" pod="default/cspod-26"
I0506 15:59:51.971298      12 schedule_one.go:1044] "Unable to schedule pod; no fit; waiting" pod="default/cspod-26" err="0/5 nodes are available: 5 Insufficient cpu. preemption: 0/5 nodes are available: 5 No preemption victims found for incoming pod."
I0506 15:59:51.972011      12 preemption.go:264] "No preemption candidate is found; preemption is not helpful for scheduling" pod="default/cspod-27"
I0506 15:59:51.972084      12 schedule_one.go:1044] "Unable to schedule pod; no fit; waiting" pod="default/cspod-27" err="0/5 nodes are available: 5 Insufficient cpu. preemption: 0/5 nodes are available: 5 No preemption victims found for incoming pod."
I0506 15:59:51.972787      12 preemption.go:264] "No preemption candidate is found; preemption is not helpful for scheduling" pod="default/cspod-28"
I0506 15:59:51.972822      12 schedule_one.go:1044] "Unable to schedule pod; no fit; waiting" pod="default/cspod-28" err="0/5 nodes are available: 5 Insufficient cpu. preemption: 0/5 nodes are available: 5 No preemption victims found for incoming pod."
I0506 15:59:51.973399      12 preemption.go:264] "No preemption candidate is found; preemption is not helpful for scheduling" pod="default/cspod-29"
I0506 15:59:51.973432      12 schedule_one.go:1044] "Unable to schedule pod; no fit; waiting" pod="default/cspod-29" err="0/5 nodes are available: 5 Insufficient cpu. preemption: 0/5 nodes are available: 5 No preemption victims found for incoming pod."
I0506 15:59:51.973926      12 preemption.go:264] "No preemption candidate is found; preemption is not helpful for scheduling" pod="default/cspod-30"
I0506 15:59:51.973959      12 schedule_one.go:1044] "Unable to schedule pod; no fit; waiting" pod="default/cspod-30" err="0/5 nodes are available: 5 Insufficient cpu. preemption: 0/5 nodes are available: 5 No preemption victims found for incoming pod."
I0506 15:59:51.974533      12 preemption.go:264] "No preemption candidate is found; preemption is not helpful for scheduling" pod="default/cspod-31"
I0506 15:59:51.974566      12 schedule_one.go:1044] "Unable to schedule pod; no fit; waiting" pod="default/cspod-31" err="0/5 nodes are available: 5 Insufficient cpu. preemption: 0/5 nodes are available: 5 No preemption victims found for incoming pod."
I0506 15:59:51.975083      12 preemption.go:264] "No preemption candidate is found; preemption is not helpful for scheduling" pod="default/cspod-32"
I0506 15:59:51.975115      12 schedule_one.go:1044] "Unable to schedule pod; no fit; waiting" pod="default/cspod-32" err="0/5 nodes are available: 5 Insufficient cpu. preemption: 0/5 nodes are available: 5 No preemption victims found for incoming pod."
I0506 15:59:51.975631      12 preemption.go:264] "No preemption candidate is found; preemption is not helpful for scheduling" pod="default/cspod-33"
I0506 15:59:51.975663      12 schedule_one.go:1044] "Unable to schedule pod; no fit; waiting" pod="default/cspod-33" err="0/5 nodes are available: 5 Insufficient cpu. preemption: 0/5 nodes are available: 5 No preemption victims found for incoming pod."
I0506 15:59:51.976136      12 preemption.go:264] "No preemption candidate is found; preemption is not helpful for scheduling" pod="default/cspod-34"
I0506 15:59:51.976174      12 schedule_one.go:1044] "Unable to schedule pod; no fit; waiting" pod="default/cspod-34" err="0/5 nodes are available: 5 Insufficient cpu. preemption: 0/5 nodes are available: 5 No preemption victims found for incoming pod."
I0506 15:59:51.976682      12 preemption.go:264] "No preemption candidate is found; preemption is not helpful for scheduling" pod="default/cspod-35"
I0506 15:59:51.976716      12 schedule_one.go:1044] "Unable to schedule pod; no fit; waiting" pod="default/cspod-35" err="0/5 nodes are available: 5 Insufficient cpu. preemption: 0/5 nodes are available: 5 No preemption victims found for incoming pod."
I0506 15:59:51.977202      12 preemption.go:264] "No preemption candidate is found; preemption is not helpful for scheduling" pod="default/cspod-36"
I0506 15:59:51.977236      12 schedule_one.go:1044] "Unable to schedule pod; no fit; waiting" pod="default/cspod-36" err="0/5 nodes are available: 5 Insufficient cpu. preemption: 0/5 nodes are available: 5 No preemption victims found for incoming pod."
I0506 15:59:51.977985      12 preemption.go:264] "No preemption candidate is found; preemption is not helpful for scheduling" pod="default/cspod-37"
I0506 15:59:51.978020      12 schedule_one.go:1044] "Unable to schedule pod; no fit; waiting" pod="default/cspod-37" err="0/5 nodes are available: 5 Insufficient cpu. preemption: 0/5 nodes are available: 5 No preemption victims found for incoming pod."
I0506 15:59:51.978569      12 preemption.go:264] "No preemption candidate is found; preemption is not helpful for scheduling" pod="default/cspod-38"
I0506 15:59:51.978604      12 schedule_one.go:1044] "Unable to schedule pod; no fit; waiting" pod="default/cspod-38" err="0/5 nodes are available: 5 Insufficient cpu. preemption: 0/5 nodes are available: 5 No preemption victims found for incoming pod."
I0506 15:59:51.979275      12 preemption.go:264] "No preemption candidate is found; preemption is not helpful for scheduling" pod="default/cspod-39"
I0506 15:59:51.979310      12 schedule_one.go:1044] "Unable to schedule pod; no fit; waiting" pod="default/cspod-39" err="0/5 nodes are available: 5 Insufficient cpu. preemption: 0/5 nodes are available: 5 No preemption victims found for incoming pod."
I0506 15:59:51.979787      12 preemption.go:264] "No preemption candidate is found; preemption is not helpful for scheduling" pod="default/cspod-40"
I0506 15:59:51.979821      12 schedule_one.go:1044] "Unable to schedule pod; no fit; waiting" pod="default/cspod-40" err="0/5 nodes are available: 5 Insufficient cpu. preemption: 0/5 nodes are available: 5 No preemption victims found for incoming pod."
I0506 15:59:51.980360      12 preemption.go:264] "No preemption candidate is found; preemption is not helpful for scheduling" pod="default/cspod-41"
I0506 15:59:51.980394      12 schedule_one.go:1044] "Unable to schedule pod; no fit; waiting" pod="default/cspod-41" err="0/5 nodes are available: 5 Insufficient cpu. preemption: 0/5 nodes are available: 5 No preemption victims found for incoming pod."
I0506 15:59:51.980937      12 preemption.go:264] "No preemption candidate is found; preemption is not helpful for scheduling" pod="default/cspod-42"
I0506 15:59:51.980972      12 schedule_one.go:1044] "Unable to schedule pod; no fit; waiting" pod="default/cspod-42" err="0/5 nodes are available: 5 Insufficient cpu. preemption: 0/5 nodes are available: 5 No preemption victims found for incoming pod."
I0506 15:59:51.981561      12 preemption.go:264] "No preemption candidate is found; preemption is not helpful for scheduling" pod="default/cspod-43"
I0506 15:59:51.981609      12 schedule_one.go:1044] "Unable to schedule pod; no fit; waiting" pod="default/cspod-43" err="0/5 nodes are available: 5 Insufficient cpu. preemption: 0/5 nodes are available: 5 No preemption victims found for incoming pod."
I0506 15:59:51.982239      12 preemption.go:264] "No preemption candidate is found; preemption is not helpful for scheduling" pod="default/cspod-44"
I0506 15:59:51.982272      12 schedule_one.go:1044] "Unable to schedule pod; no fit; waiting" pod="default/cspod-44" err="0/5 nodes are available: 5 Insufficient cpu. preemption: 0/5 nodes are available: 5 No preemption victims found for incoming pod."
I0506 15:59:51.982803      12 preemption.go:264] "No preemption candidate is found; preemption is not helpful for scheduling" pod="default/cspod-45"
I0506 15:59:51.982845      12 schedule_one.go:1044] "Unable to schedule pod; no fit; waiting" pod="default/cspod-45" err="0/5 nodes are available: 5 Insufficient cpu. preemption: 0/5 nodes are available: 5 No preemption victims found for incoming pod."
I0506 15:59:51.983398      12 preemption.go:264] "No preemption candidate is found; preemption is not helpful for scheduling" pod="default/cspod-46"
I0506 15:59:51.983431      12 schedule_one.go:1044] "Unable to schedule pod; no fit; waiting" pod="default/cspod-46" err="0/5 nodes are available: 5 Insufficient cpu. preemption: 0/5 nodes are available: 5 No preemption victims found for incoming pod."
I0506 15:59:51.983947      12 preemption.go:264] "No preemption candidate is found; preemption is not helpful for scheduling" pod="default/cspod-47"
I0506 15:59:51.983983      12 schedule_one.go:1044] "Unable to schedule pod; no fit; waiting" pod="default/cspod-47" err="0/5 nodes are available: 5 Insufficient cpu. preemption: 0/5 nodes are available: 5 No preemption victims found for incoming pod."
I0506 15:59:51.984513      12 preemption.go:264] "No preemption candidate is found; preemption is not helpful for scheduling" pod="default/cspod-48"
I0506 15:59:51.984547      12 schedule_one.go:1044] "Unable to schedule pod; no fit; waiting" pod="default/cspod-48" err="0/5 nodes are available: 5 Insufficient cpu. preemption: 0/5 nodes are available: 5 No preemption victims found for incoming pod."
I0506 15:59:51.985013      12 preemption.go:264] "No preemption candidate is found; preemption is not helpful for scheduling" pod="default/cspod-49"
I0506 15:59:51.985046      12 schedule_one.go:1044] "Unable to schedule pod; no fit; waiting" pod="default/cspod-49" err="0/5 nodes are available: 5 Insufficient cpu. preemption: 0/5 nodes are available: 5 No preemption victims found for incoming pod."
I0506 15:59:51.985606      12 preemption.go:264] "No preemption candidate is found; preemption is not helpful for scheduling" pod="default/cspod-50"
I0506 15:59:51.985642      12 schedule_one.go:1044] "Unable to schedule pod; no fit; waiting" pod="default/cspod-50" err="0/5 nodes are available: 5 Insufficient cpu. preemption: 0/5 nodes are available: 5 No preemption victims found for incoming pod."
I0506 15:59:51.986321      12 preemption.go:264] "No preemption candidate is found; preemption is not helpful for scheduling" pod="default/cspod-51"
I0506 15:59:51.986358      12 schedule_one.go:1044] "Unable to schedule pod; no fit; waiting" pod="default/cspod-51" err="0/5 nodes are available: 5 Insufficient cpu. preemption: 0/5 nodes are available: 5 No preemption victims found for incoming pod."
I0506 15:59:51.986847      12 preemption.go:264] "No preemption candidate is found; preemption is not helpful for scheduling" pod="default/cspod-52"
I0506 15:59:51.986878      12 schedule_one.go:1044] "Unable to schedule pod; no fit; waiting" pod="default/cspod-52" err="0/5 nodes are available: 5 Insufficient cpu. preemption: 0/5 nodes are available: 5 No preemption victims found for incoming pod."
I0506 15:59:51.987442      12 preemption.go:264] "No preemption candidate is found; preemption is not helpful for scheduling" pod="default/cspod-53"
I0506 15:59:51.987477      12 schedule_one.go:1044] "Unable to schedule pod; no fit; waiting" pod="default/cspod-53" err="0/5 nodes are available: 5 Insufficient cpu. preemption: 0/5 nodes are available: 5 No preemption victims found for incoming pod."
I0506 15:59:51.987952      12 preemption.go:264] "No preemption candidate is found; preemption is not helpful for scheduling" pod="default/cspod-54"
I0506 15:59:51.987985      12 schedule_one.go:1044] "Unable to schedule pod; no fit; waiting" pod="default/cspod-54" err="0/5 nodes are available: 5 Insufficient cpu. preemption: 0/5 nodes are available: 5 No preemption victims found for incoming pod."
I0506 15:59:51.988525      12 preemption.go:264] "No preemption candidate is found; preemption is not helpful for scheduling" pod="default/cspod-60"
I0506 15:59:51.988560      12 schedule_one.go:1044] "Unable to schedule pod; no fit; waiting" pod="default/cspod-60" err="0/5 nodes are available: 5 Insufficient cpu. preemption: 0/5 nodes are available: 5 No preemption victims found for incoming pod."
I0506 15:59:52.001806      12 preemption.go:264] "No preemption candidate is found; preemption is not helpful for scheduling" pod="default/cspod-61"
I0506 15:59:52.001848      12 schedule_one.go:1044] "Unable to schedule pod; no fit; waiting" pod="default/cspod-61" err="0/5 nodes are available: 5 Insufficient cpu. preemption: 0/5 nodes are available: 5 No preemption victims found for incoming pod."
I0506 15:59:52.022339      12 preemption.go:264] "No preemption candidate is found; preemption is not helpful for scheduling" pod="default/cspod-62"
I0506 15:59:52.022379      12 schedule_one.go:1044] "Unable to schedule pod; no fit; waiting" pod="default/cspod-62" err="0/5 nodes are available: 5 Insufficient cpu. preemption: 0/5 nodes are available: 5 No preemption victims found for incoming pod."
I0506 15:59:52.041492      12 preemption.go:264] "No preemption candidate is found; preemption is not helpful for scheduling" pod="default/cspod-63"
I0506 15:59:52.041540      12 schedule_one.go:1044] "Unable to schedule pod; no fit; waiting" pod="default/cspod-63" err="0/5 nodes are available: 5 Insufficient cpu. preemption: 0/5 nodes are available: 5 No preemption victims found for incoming pod."
I0506 15:59:52.062208      12 preemption.go:264] "No preemption candidate is found; preemption is not helpful for scheduling" pod="default/cspod-64"
I0506 15:59:52.062251      12 schedule_one.go:1044] "Unable to schedule pod; no fit; waiting" pod="default/cspod-64" err="0/5 nodes are available: 5 Insufficient cpu. preemption: 0/5 nodes are available: 5 No preemption victims found for incoming pod."
I0506 15:59:52.081334      12 preemption.go:264] "No preemption candidate is found; preemption is not helpful for scheduling" pod="default/cspod-65"
I0506 15:59:52.081375      12 schedule_one.go:1044] "Unable to schedule pod; no fit; waiting" pod="default/cspod-65" err="0/5 nodes are available: 5 Insufficient cpu. preemption: 0/5 nodes are available: 5 No preemption victims found for incoming pod."
I0506 15:59:52.101510      12 preemption.go:264] "No preemption candidate is found; preemption is not helpful for scheduling" pod="default/cspod-66"
I0506 15:59:52.101552      12 schedule_one.go:1044] "Unable to schedule pod; no fit; waiting" pod="default/cspod-66" err="0/5 nodes are available: 5 Insufficient cpu. preemption: 0/5 nodes are available: 5 No preemption victims found for incoming pod."
I0506 15:59:52.121447      12 preemption.go:264] "No preemption candidate is found; preemption is not helpful for scheduling" pod="default/cspod-67"
I0506 15:59:52.121488      12 schedule_one.go:1044] "Unable to schedule pod; no fit; waiting" pod="default/cspod-67" err="0/5 nodes are available: 5 Insufficient cpu. preemption: 0/5 nodes are available: 5 No preemption victims found for incoming pod."
I0506 15:59:52.141476      12 preemption.go:264] "No preemption candidate is found; preemption is not helpful for scheduling" pod="default/cspod-68"
I0506 15:59:52.141529      12 schedule_one.go:1044] "Unable to schedule pod; no fit; waiting" pod="default/cspod-68" err="0/5 nodes are available: 5 Insufficient cpu. preemption: 0/5 nodes are available: 5 No preemption victims found for incoming pod."
I0506 15:59:52.161733      12 preemption.go:264] "No preemption candidate is found; preemption is not helpful for scheduling" pod="default/cspod-69"
I0506 15:59:52.161785      12 schedule_one.go:1044] "Unable to schedule pod; no fit; waiting" pod="default/cspod-69" err="0/5 nodes are available: 5 Insufficient cpu. preemption: 0/5 nodes are available: 5 No preemption victims found for incoming pod."
I0506 15:59:52.196273      12 preemption.go:264] "No preemption candidate is found; preemption is not helpful for scheduling" pod="default/cspod-20"
I0506 15:59:52.196322      12 schedule_one.go:1044] "Unable to schedule pod; no fit; waiting" pod="default/cspod-20" err="0/5 nodes are available: 5 Insufficient cpu. preemption: 0/5 nodes are available: 5 No preemption victims found for incoming pod."
I0506 15:59:52.196414      12 preemption.go:264] "No preemption candidate is found; preemption is not helpful for scheduling" pod="default/cspod-21"
I0506 15:59:52.196444      12 schedule_one.go:1044] "Unable to schedule pod; no fit; waiting" pod="default/cspod-21" err="0/5 nodes are available: 5 Insufficient cpu. preemption: 0/5 nodes are available: 5 No preemption victims found for incoming pod."
I0506 15:59:52.202070      12 preemption.go:264] "No preemption candidate is found; preemption is not helpful for scheduling" pod="default/cspod-22"
I0506 15:59:52.202141      12 schedule_one.go:1044] "Unable to schedule pod; no fit; waiting" pod="default/cspod-22" err="0/5 nodes are available: 5 Insufficient cpu. preemption: 0/5 nodes are available: 5 No preemption victims found for incoming pod."
I0506 15:59:52.221889      12 preemption.go:264] "No preemption candidate is found; preemption is not helpful for scheduling" pod="default/cspod-23"
I0506 15:59:52.221963      12 schedule_one.go:1044] "Unable to schedule pod; no fit; waiting" pod="default/cspod-23" err="0/5 nodes are available: 5 Insufficient cpu. preemption: 0/5 nodes are available: 5 No preemption victims found for incoming pod."
I0506 15:59:52.241860      12 preemption.go:264] "No preemption candidate is found; preemption is not helpful for scheduling" pod="default/cspod-24"
I0506 15:59:52.241936      12 schedule_one.go:1044] "Unable to schedule pod; no fit; waiting" pod="default/cspod-24" err="0/5 nodes are available: 5 Insufficient cpu. preemption: 0/5 nodes are available: 5 No preemption victims found for incoming pod."
I0506 15:59:52.261813      12 preemption.go:264] "No preemption candidate is found; preemption is not helpful for scheduling" pod="default/cspod-25"
I0506 15:59:52.261891      12 schedule_one.go:1044] "Unable to schedule pod; no fit; waiting" pod="default/cspod-25" err="0/5 nodes are available: 5 Insufficient cpu. preemption: 0/5 nodes are available: 5 No preemption victims found for incoming pod."
I0506 15:59:52.281013      12 preemption.go:264] "No preemption candidate is found; preemption is not helpful for scheduling" pod="default/cspod-26"
I0506 15:59:52.281052      12 schedule_one.go:1044] "Unable to schedule pod; no fit; waiting" pod="default/cspod-26" err="0/5 nodes are available: 5 Insufficient cpu. preemption: 0/5 nodes are available: 5 No preemption victims found for incoming pod."
I0506 15:59:52.301660      12 preemption.go:264] "No preemption candidate is found; preemption is not helpful for scheduling" pod="default/cspod-27"
I0506 15:59:52.301732      12 schedule_one.go:1044] "Unable to schedule pod; no fit; waiting" pod="default/cspod-27" err="0/5 nodes are available: 5 Insufficient cpu. preemption: 0/5 nodes are available: 5 No preemption victims found for incoming pod."
I0506 15:59:52.321517      12 preemption.go:264] "No preemption candidate is found; preemption is not helpful for scheduling" pod="default/cspod-28"
I0506 15:59:52.321561      12 schedule_one.go:1044] "Unable to schedule pod; no fit; waiting" pod="default/cspod-28" err="0/5 nodes are available: 5 Insufficient cpu. preemption: 0/5 nodes are available: 5 No preemption victims found for incoming pod."
I0506 15:59:52.342519      12 preemption.go:264] "No preemption candidate is found; preemption is not helpful for scheduling" pod="default/cspod-29"
I0506 15:59:52.342568      12 schedule_one.go:1044] "Unable to schedule pod; no fit; waiting" pod="default/cspod-29" err="0/5 nodes are available: 5 Insufficient cpu. preemption: 0/5 nodes are available: 5 No preemption victims found for incoming pod."
I0506 15:59:52.362393      12 preemption.go:264] "No preemption candidate is found; preemption is not helpful for scheduling" pod="default/cspod-30"
I0506 15:59:52.362440      12 schedule_one.go:1044] "Unable to schedule pod; no fit; waiting" pod="default/cspod-30" err="0/5 nodes are available: 5 Insufficient cpu. preemption: 0/5 nodes are available: 5 No preemption victims found for incoming pod."
I0506 15:59:52.381573      12 preemption.go:264] "No preemption candidate is found; preemption is not helpful for scheduling" pod="default/cspod-31"
I0506 15:59:52.381619      12 schedule_one.go:1044] "Unable to schedule pod; no fit; waiting" pod="default/cspod-31" err="0/5 nodes are available: 5 Insufficient cpu. preemption: 0/5 nodes are available: 5 No preemption victims found for incoming pod."
I0506 15:59:52.401601      12 preemption.go:264] "No preemption candidate is found; preemption is not helpful for scheduling" pod="default/cspod-32"
I0506 15:59:52.401643      12 schedule_one.go:1044] "Unable to schedule pod; no fit; waiting" pod="default/cspod-32" err="0/5 nodes are available: 5 Insufficient cpu. preemption: 0/5 nodes are available: 5 No preemption victims found for incoming pod."
I0506 15:59:52.422079      12 preemption.go:264] "No preemption candidate is found; preemption is not helpful for scheduling" pod="default/cspod-33"
I0506 15:59:52.422157      12 schedule_one.go:1044] "Unable to schedule pod; no fit; waiting" pod="default/cspod-33" err="0/5 nodes are available: 5 Insufficient cpu. preemption: 0/5 nodes are available: 5 No preemption victims found for incoming pod."
I0506 15:59:52.442199      12 preemption.go:264] "No preemption candidate is found; preemption is not helpful for scheduling" pod="default/cspod-34"
I0506 15:59:52.442245      12 schedule_one.go:1044] "Unable to schedule pod; no fit; waiting" pod="default/cspod-34" err="0/5 nodes are available: 5 Insufficient cpu. preemption: 0/5 nodes are available: 5 No preemption victims found for incoming pod."
I0506 15:59:52.461187      12 preemption.go:264] "No preemption candidate is found; preemption is not helpful for scheduling" pod="default/cspod-35"
I0506 15:59:52.461222      12 schedule_one.go:1044] "Unable to schedule pod; no fit; waiting" pod="default/cspod-35" err="0/5 nodes are available: 5 Insufficient cpu. preemption: 0/5 nodes are available: 5 No preemption victims found for incoming pod."
I0506 15:59:52.481660      12 preemption.go:264] "No preemption candidate is found; preemption is not helpful for scheduling" pod="default/cspod-36"
I0506 15:59:52.481733      12 schedule_one.go:1044] "Unable to schedule pod; no fit; waiting" pod="default/cspod-36" err="0/5 nodes are available: 5 Insufficient cpu. preemption: 0/5 nodes are available: 5 No preemption victims found for incoming pod."
I0506 15:59:52.502070      12 preemption.go:264] "No preemption candidate is found; preemption is not helpful for scheduling" pod="default/cspod-37"
I0506 15:59:52.502147      12 schedule_one.go:1044] "Unable to schedule pod; no fit; waiting" pod="default/cspod-37" err="0/5 nodes are available: 5 Insufficient cpu. preemption: 0/5 nodes are available: 5 No preemption victims found for incoming pod."
I0506 15:59:52.521802      12 preemption.go:264] "No preemption candidate is found; preemption is not helpful for scheduling" pod="default/cspod-38"
I0506 15:59:52.521857      12 schedule_one.go:1044] "Unable to schedule pod; no fit; waiting" pod="default/cspod-38" err="0/5 nodes are available: 5 Insufficient cpu. preemption: 0/5 nodes are available: 5 No preemption victims found for incoming pod."
I0506 15:59:52.542061      12 preemption.go:264] "No preemption candidate is found; preemption is not helpful for scheduling" pod="default/cspod-39"
I0506 15:59:52.542131      12 schedule_one.go:1044] "Unable to schedule pod; no fit; waiting" pod="default/cspod-39" err="0/5 nodes are available: 5 Insufficient cpu. preemption: 0/5 nodes are available: 5 No preemption victims found for incoming pod."
I0506 15:59:52.562093      12 preemption.go:264] "No preemption candidate is found; preemption is not helpful for scheduling" pod="default/cspod-40"
I0506 15:59:52.562159      12 schedule_one.go:1044] "Unable to schedule pod; no fit; waiting" pod="default/cspod-40" err="0/5 nodes are available: 5 Insufficient cpu. preemption: 0/5 nodes are available: 5 No preemption victims found for incoming pod."
I0506 15:59:52.582513      12 preemption.go:264] "No preemption candidate is found; preemption is not helpful for scheduling" pod="default/cspod-41"
I0506 15:59:52.582558      12 schedule_one.go:1044] "Unable to schedule pod; no fit; waiting" pod="default/cspod-41" err="0/5 nodes are available: 5 Insufficient cpu. preemption: 0/5 nodes are available: 5 No preemption victims found for incoming pod."
I0506 15:59:52.601579      12 preemption.go:264] "No preemption candidate is found; preemption is not helpful for scheduling" pod="default/cspod-42"
I0506 15:59:52.601623      12 schedule_one.go:1044] "Unable to schedule pod; no fit; waiting" pod="default/cspod-42" err="0/5 nodes are available: 5 Insufficient cpu. preemption: 0/5 nodes are available: 5 No preemption victims found for incoming pod."
I0506 15:59:52.621831      12 preemption.go:264] "No preemption candidate is found; preemption is not helpful for scheduling" pod="default/cspod-43"
I0506 15:59:52.621882      12 schedule_one.go:1044] "Unable to schedule pod; no fit; waiting" pod="default/cspod-43" err="0/5 nodes are available: 5 Insufficient cpu. preemption: 0/5 nodes are available: 5 No preemption victims found for incoming pod."
I0506 15:59:52.642062      12 preemption.go:264] "No preemption candidate is found; preemption is not helpful for scheduling" pod="default/cspod-44"
I0506 15:59:52.642107      12 schedule_one.go:1044] "Unable to schedule pod; no fit; waiting" pod="default/cspod-44" err="0/5 nodes are available: 5 Insufficient cpu. preemption: 0/5 nodes are available: 5 No preemption victims found for incoming pod."
I0506 15:59:52.661268      12 preemption.go:264] "No preemption candidate is found; preemption is not helpful for scheduling" pod="default/cspod-45"
I0506 15:59:52.661309      12 schedule_one.go:1044] "Unable to schedule pod; no fit; waiting" pod="default/cspod-45" err="0/5 nodes are available: 5 Insufficient cpu. preemption: 0/5 nodes are available: 5 No preemption victims found for incoming pod."
I0506 15:59:52.681993      12 preemption.go:264] "No preemption candidate is found; preemption is not helpful for scheduling" pod="default/cspod-46"
I0506 15:59:52.682035      12 schedule_one.go:1044] "Unable to schedule pod; no fit; waiting" pod="default/cspod-46" err="0/5 nodes are available: 5 Insufficient cpu. preemption: 0/5 nodes are available: 5 No preemption victims found for incoming pod."
I0506 15:59:52.702243      12 preemption.go:264] "No preemption candidate is found; preemption is not helpful for scheduling" pod="default/cspod-47"
I0506 15:59:52.702300      12 schedule_one.go:1044] "Unable to schedule pod; no fit; waiting" pod="default/cspod-47" err="0/5 nodes are available: 5 Insufficient cpu. preemption: 0/5 nodes are available: 5 No preemption victims found for incoming pod."
I0506 15:59:52.721286      12 preemption.go:264] "No preemption candidate is found; preemption is not helpful for scheduling" pod="default/cspod-48"
I0506 15:59:52.721333      12 schedule_one.go:1044] "Unable to schedule pod; no fit; waiting" pod="default/cspod-48" err="0/5 nodes are available: 5 Insufficient cpu. preemption: 0/5 nodes are available: 5 No preemption victims found for incoming pod."
I0506 15:59:52.741270      12 preemption.go:264] "No preemption candidate is found; preemption is not helpful for scheduling" pod="default/cspod-49"
I0506 15:59:52.741311      12 schedule_one.go:1044] "Unable to schedule pod; no fit; waiting" pod="default/cspod-49" err="0/5 nodes are available: 5 Insufficient cpu. preemption: 0/5 nodes are available: 5 No preemption victims found for incoming pod."
I0506 15:59:52.761548      12 preemption.go:264] "No preemption candidate is found; preemption is not helpful for scheduling" pod="default/cspod-50"
I0506 15:59:52.761591      12 schedule_one.go:1044] "Unable to schedule pod; no fit; waiting" pod="default/cspod-50" err="0/5 nodes are available: 5 Insufficient cpu. preemption: 0/5 nodes are available: 5 No preemption victims found for incoming pod."
I0506 15:59:52.781792      12 preemption.go:264] "No preemption candidate is found; preemption is not helpful for scheduling" pod="default/cspod-51"
I0506 15:59:52.781838      12 schedule_one.go:1044] "Unable to schedule pod; no fit; waiting" pod="default/cspod-51" err="0/5 nodes are available: 5 Insufficient cpu. preemption: 0/5 nodes are available: 5 No preemption victims found for incoming pod."
I0506 15:59:52.801706      12 preemption.go:264] "No preemption candidate is found; preemption is not helpful for scheduling" pod="default/cspod-52"
I0506 15:59:52.801744      12 schedule_one.go:1044] "Unable to schedule pod; no fit; waiting" pod="default/cspod-52" err="0/5 nodes are available: 5 Insufficient cpu. preemption: 0/5 nodes are available: 5 No preemption victims found for incoming pod."
I0506 15:59:52.821752      12 preemption.go:264] "No preemption candidate is found; preemption is not helpful for scheduling" pod="default/cspod-53"
I0506 15:59:52.821802      12 schedule_one.go:1044] "Unable to schedule pod; no fit; waiting" pod="default/cspod-53" err="0/5 nodes are available: 5 Insufficient cpu. preemption: 0/5 nodes are available: 5 No preemption victims found for incoming pod."
I0506 15:59:52.841999      12 preemption.go:264] "No preemption candidate is found; preemption is not helpful for scheduling" pod="default/cspod-54"
I0506 15:59:52.842043      12 schedule_one.go:1044] "Unable to schedule pod; no fit; waiting" pod="default/cspod-54" err="0/5 nodes are available: 5 Insufficient cpu. preemption: 0/5 nodes are available: 5 No preemption victims found for incoming pod."
I0506 15:59:52.862106      12 preemption.go:264] "No preemption candidate is found; preemption is not helpful for scheduling" pod="default/cspod-60"
I0506 15:59:52.862153      12 schedule_one.go:1044] "Unable to schedule pod; no fit; waiting" pod="default/cspod-60" err="0/5 nodes are available: 5 Insufficient cpu. preemption: 0/5 nodes are available: 5 No preemption victims found for incoming pod."
I0506 15:59:52.882179      12 preemption.go:264] "No preemption candidate is found; preemption is not helpful for scheduling" pod="default/cspod-61"
I0506 15:59:52.882221      12 schedule_one.go:1044] "Unable to schedule pod; no fit; waiting" pod="default/cspod-61" err="0/5 nodes are available: 5 Insufficient cpu. preemption: 0/5 nodes are available: 5 No preemption victims found for incoming pod."
I0506 15:59:52.901412      12 preemption.go:264] "No preemption candidate is found; preemption is not helpful for scheduling" pod="default/cspod-62"
I0506 15:59:52.901458      12 schedule_one.go:1044] "Unable to schedule pod; no fit; waiting" pod="default/cspod-62" err="0/5 nodes are available: 5 Insufficient cpu. preemption: 0/5 nodes are available: 5 No preemption victims found for incoming pod."
I0506 15:59:52.921287      12 preemption.go:264] "No preemption candidate is found; preemption is not helpful for scheduling" pod="default/cspod-63"
I0506 15:59:52.921326      12 schedule_one.go:1044] "Unable to schedule pod; no fit; waiting" pod="default/cspod-63" err="0/5 nodes are available: 5 Insufficient cpu. preemption: 0/5 nodes are available: 5 No preemption victims found for incoming pod."
I0506 15:59:52.941413      12 preemption.go:264] "No preemption candidate is found; preemption is not helpful for scheduling" pod="default/cspod-64"
I0506 15:59:52.941452      12 schedule_one.go:1044] "Unable to schedule pod; no fit; waiting" pod="default/cspod-64" err="0/5 nodes are available: 5 Insufficient cpu. preemption: 0/5 nodes are available: 5 No preemption victims found for incoming pod."
I0506 15:59:52.961653      12 preemption.go:264] "No preemption candidate is found; preemption is not helpful for scheduling" pod="default/cspod-65"
I0506 15:59:52.961703      12 schedule_one.go:1044] "Unable to schedule pod; no fit; waiting" pod="default/cspod-65" err="0/5 nodes are available: 5 Insufficient cpu. preemption: 0/5 nodes are available: 5 No preemption victims found for incoming pod."
I0506 15:59:52.981717      12 preemption.go:264] "No preemption candidate is found; preemption is not helpful for scheduling" pod="default/cspod-66"
I0506 15:59:52.981789      12 schedule_one.go:1044] "Unable to schedule pod; no fit; waiting" pod="default/cspod-66" err="0/5 nodes are available: 5 Insufficient cpu. preemption: 0/5 nodes are available: 5 No preemption victims found for incoming pod."
I0506 15:59:53.001862      12 preemption.go:264] "No preemption candidate is found; preemption is not helpful for scheduling" pod="default/cspod-67"
I0506 15:59:53.001963      12 schedule_one.go:1044] "Unable to schedule pod; no fit; waiting" pod="default/cspod-67" err="0/5 nodes are available: 5 Insufficient cpu. preemption: 0/5 nodes are available: 5 No preemption victims found for incoming pod."
I0506 15:59:53.022043      12 preemption.go:264] "No preemption candidate is found; preemption is not helpful for scheduling" pod="default/cspod-68"
I0506 15:59:53.022118      12 schedule_one.go:1044] "Unable to schedule pod; no fit; waiting" pod="default/cspod-68" err="0/5 nodes are available: 5 Insufficient cpu. preemption: 0/5 nodes are available: 5 No preemption victims found for incoming pod."
I0506 15:59:53.042322      12 preemption.go:264] "No preemption candidate is found; preemption is not helpful for scheduling" pod="default/cspod-69"
I0506 15:59:53.042367      12 schedule_one.go:1044] "Unable to schedule pod; no fit; waiting" pod="default/cspod-69" err="0/5 nodes are available: 5 Insufficient cpu. preemption: 0/5 nodes are available: 5 No preemption victims found for incoming pod."
E0506 15:59:54.616074      12 event.go:368] "Unable to write event (may retry after sleeping)" err="0-length response with status code: 201 and content type: application/vnd.kubernetes.protobuf" event="&Event{ObjectMeta:{cspod-1.18ad053dfd4083af  default    0 0001-01-01 00:00:00 +0000 UTC <nil> <nil> map[] map[] [] [] []},InvolvedObject:ObjectReference{Kind:Pod,Namespace:default,Name:cspod-1,UID:cspod-1-uid,APIVersion:v1,ResourceVersion:7,FieldPath:,},Reason:Scheduled,Message:Successfully assigned default/cspod-1 to csnode-0,Source:EventSource{Component:default-scheduler,Host:,},FirstTimestamp:2026-05-06 15:59:51.681221551 +0000 UTC m=+7.115148449,LastTimestamp:2026-05-06 15:59:51.681221551 +0000 UTC m=+7.115148449,Count:1,Type:Normal,EventTime:0001-01-01 00:00:00 +0000 UTC,Series:nil,Action:,Related:nil,ReportingController:default-scheduler,ReportingInstance:,}"
I0506 15:59:56.239110      12 schedule_one.go:314] "Successfully bound pod to node" pod="default/cspod-20" node="csnode-3" evaluatedNodes=5 feasibleNodes=5
I0506 15:59:56.239209      12 schedule_one.go:314] "Successfully bound pod to node" pod="default/cspod-21" node="csnode-0" evaluatedNodes=5 feasibleNodes=5
I0506 15:59:56.239467      12 schedule_one.go:314] "Successfully bound pod to node" pod="default/cspod-23" node="csnode-2" evaluatedNodes=5 feasibleNodes=5
I0506 15:59:56.239529      12 schedule_one.go:314] "Successfully bound pod to node" pod="default/cspod-24" node="csnode-4" evaluatedNodes=5 feasibleNodes=5
I0506 15:59:56.239655      12 schedule_one.go:314] "Successfully bound pod to node" pod="default/cspod-22" node="csnode-1" evaluatedNodes=5 feasibleNodes=5
I0506 15:59:56.239704      12 schedule_one.go:314] "Successfully bound pod to node" pod="default/cspod-25" node="csnode-0" evaluatedNodes=5 feasibleNodes=5
I0506 15:59:56.239764      12 schedule_one.go:314] "Successfully bound pod to node" pod="default/cspod-26" node="csnode-3" evaluatedNodes=5 feasibleNodes=4
I0506 15:59:56.239990      12 schedule_one.go:314] "Successfully bound pod to node" pod="default/cspod-27" node="csnode-4" evaluatedNodes=5 feasibleNodes=3
I0506 15:59:56.240088      12 preemption.go:264] "No preemption candidate is found; preemption is not helpful for scheduling" pod="default/cspod-30"
I0506 15:59:56.240109      12 schedule_one.go:1044] "Unable to schedule pod; no fit; waiting" pod="default/cspod-30" err="0/5 nodes are available: 5 Insufficient cpu. preemption: 0/5 nodes are available: 5 No preemption victims found for incoming pod."
I0506 15:59:56.240320      12 schedule_one.go:314] "Successfully bound pod to node" pod="default/cspod-28" node="csnode-2" evaluatedNodes=5 feasibleNodes=2
I0506 15:59:56.240367      12 schedule_one.go:314] "Successfully bound pod to node" pod="default/cspod-29" node="csnode-1" evaluatedNodes=5 feasibleNodes=1
I0506 15:59:56.240982      12 preemption.go:264] "No preemption candidate is found; preemption is not helpful for scheduling" pod="default/cspod-31"
I0506 15:59:56.241026      12 schedule_one.go:1044] "Unable to schedule pod; no fit; waiting" pod="default/cspod-31" err="0/5 nodes are available: 5 Insufficient cpu. preemption: 0/5 nodes are available: 5 No preemption victims found for incoming pod."
I0506 15:59:56.241574      12 preemption.go:264] "No preemption candidate is found; preemption is not helpful for scheduling" pod="default/cspod-32"
I0506 15:59:56.241618      12 schedule_one.go:1044] "Unable to schedule pod; no fit; waiting" pod="default/cspod-32" err="0/5 nodes are available: 5 Insufficient cpu. preemption: 0/5 nodes are available: 5 No preemption victims found for incoming pod."
I0506 15:59:56.242231      12 preemption.go:264] "No preemption candidate is found; preemption is not helpful for scheduling" pod="default/cspod-33"
I0506 15:59:56.242272      12 schedule_one.go:1044] "Unable to schedule pod; no fit; waiting" pod="default/cspod-33" err="0/5 nodes are available: 5 Insufficient cpu. preemption: 0/5 nodes are available: 5 No preemption victims found for incoming pod."
I0506 15:59:56.242873      12 preemption.go:264] "No preemption candidate is found; preemption is not helpful for scheduling" pod="default/cspod-34"
I0506 15:59:56.242912      12 schedule_one.go:1044] "Unable to schedule pod; no fit; waiting" pod="default/cspod-34" err="0/5 nodes are available: 5 Insufficient cpu. preemption: 0/5 nodes are available: 5 No preemption victims found for incoming pod."
I0506 15:59:56.243508      12 preemption.go:264] "No preemption candidate is found; preemption is not helpful for scheduling" pod="default/cspod-35"
I0506 15:59:56.243543      12 schedule_one.go:1044] "Unable to schedule pod; no fit; waiting" pod="default/cspod-35" err="0/5 nodes are available: 5 Insufficient cpu. preemption: 0/5 nodes are available: 5 No preemption victims found for incoming pod."
I0506 15:59:56.244153      12 preemption.go:264] "No preemption candidate is found; preemption is not helpful for scheduling" pod="default/cspod-36"
I0506 15:59:56.244191      12 schedule_one.go:1044] "Unable to schedule pod; no fit; waiting" pod="default/cspod-36" err="0/5 nodes are available: 5 Insufficient cpu. preemption: 0/5 nodes are available: 5 No preemption victims found for incoming pod."
I0506 15:59:56.244747      12 preemption.go:264] "No preemption candidate is found; preemption is not helpful for scheduling" pod="default/cspod-37"
I0506 15:59:56.244784      12 schedule_one.go:1044] "Unable to schedule pod; no fit; waiting" pod="default/cspod-37" err="0/5 nodes are available: 5 Insufficient cpu. preemption: 0/5 nodes are available: 5 No preemption victims found for incoming pod."
I0506 15:59:56.245395      12 preemption.go:264] "No preemption candidate is found; preemption is not helpful for scheduling" pod="default/cspod-38"
I0506 15:59:56.245434      12 schedule_one.go:1044] "Unable to schedule pod; no fit; waiting" pod="default/cspod-38" err="0/5 nodes are available: 5 Insufficient cpu. preemption: 0/5 nodes are available: 5 No preemption victims found for incoming pod."
I0506 15:59:56.246066      12 preemption.go:264] "No preemption candidate is found; preemption is not helpful for scheduling" pod="default/cspod-39"
I0506 15:59:56.246101      12 schedule_one.go:1044] "Unable to schedule pod; no fit; waiting" pod="default/cspod-39" err="0/5 nodes are available: 5 Insufficient cpu. preemption: 0/5 nodes are available: 5 No preemption victims found for incoming pod."
I0506 15:59:56.246709      12 preemption.go:264] "No preemption candidate is found; preemption is not helpful for scheduling" pod="default/cspod-40"
I0506 15:59:56.246748      12 schedule_one.go:1044] "Unable to schedule pod; no fit; waiting" pod="default/cspod-40" err="0/5 nodes are available: 5 Insufficient cpu. preemption: 0/5 nodes are available: 5 No preemption victims found for incoming pod."
I0506 15:59:56.247327      12 preemption.go:264] "No preemption candidate is found; preemption is not helpful for scheduling" pod="default/cspod-41"
I0506 15:59:56.247365      12 schedule_one.go:1044] "Unable to schedule pod; no fit; waiting" pod="default/cspod-41" err="0/5 nodes are available: 5 Insufficient cpu. preemption: 0/5 nodes are available: 5 No preemption victims found for incoming pod."
I0506 15:59:56.247923      12 preemption.go:264] "No preemption candidate is found; preemption is not helpful for scheduling" pod="default/cspod-42"
I0506 15:59:56.247961      12 schedule_one.go:1044] "Unable to schedule pod; no fit; waiting" pod="default/cspod-42" err="0/5 nodes are available: 5 Insufficient cpu. preemption: 0/5 nodes are available: 5 No preemption victims found for incoming pod."
I0506 15:59:56.248560      12 preemption.go:264] "No preemption candidate is found; preemption is not helpful for scheduling" pod="default/cspod-43"
I0506 15:59:56.248600      12 schedule_one.go:1044] "Unable to schedule pod; no fit; waiting" pod="default/cspod-43" err="0/5 nodes are available: 5 Insufficient cpu. preemption: 0/5 nodes are available: 5 No preemption victims found for incoming pod."
I0506 15:59:56.249183      12 preemption.go:264] "No preemption candidate is found; preemption is not helpful for scheduling" pod="default/cspod-44"
I0506 15:59:56.249216      12 schedule_one.go:1044] "Unable to schedule pod; no fit; waiting" pod="default/cspod-44" err="0/5 nodes are available: 5 Insufficient cpu. preemption: 0/5 nodes are available: 5 No preemption victims found for incoming pod."
I0506 15:59:56.249794      12 preemption.go:264] "No preemption candidate is found; preemption is not helpful for scheduling" pod="default/cspod-45"
I0506 15:59:56.249829      12 schedule_one.go:1044] "Unable to schedule pod; no fit; waiting" pod="default/cspod-45" err="0/5 nodes are available: 5 Insufficient cpu. preemption: 0/5 nodes are available: 5 No preemption victims found for incoming pod."
I0506 15:59:56.250489      12 preemption.go:264] "No preemption candidate is found; preemption is not helpful for scheduling" pod="default/cspod-46"
I0506 15:59:56.250525      12 schedule_one.go:1044] "Unable to schedule pod; no fit; waiting" pod="default/cspod-46" err="0/5 nodes are available: 5 Insufficient cpu. preemption: 0/5 nodes are available: 5 No preemption victims found for incoming pod."
I0506 15:59:56.251027      12 preemption.go:264] "No preemption candidate is found; preemption is not helpful for scheduling" pod="default/cspod-47"
I0506 15:59:56.251060      12 schedule_one.go:1044] "Unable to schedule pod; no fit; waiting" pod="default/cspod-47" err="0/5 nodes are available: 5 Insufficient cpu. preemption: 0/5 nodes are available: 5 No preemption victims found for incoming pod."
I0506 15:59:56.251581      12 preemption.go:264] "No preemption candidate is found; preemption is not helpful for scheduling" pod="default/cspod-48"
I0506 15:59:56.251615      12 schedule_one.go:1044] "Unable to schedule pod; no fit; waiting" pod="default/cspod-48" err="0/5 nodes are available: 5 Insufficient cpu. preemption: 0/5 nodes are available: 5 No preemption victims found for incoming pod."
I0506 15:59:56.252168      12 preemption.go:264] "No preemption candidate is found; preemption is not helpful for scheduling" pod="default/cspod-49"
I0506 15:59:56.252202      12 schedule_one.go:1044] "Unable to schedule pod; no fit; waiting" pod="default/cspod-49" err="0/5 nodes are available: 5 Insufficient cpu. preemption: 0/5 nodes are available: 5 No preemption victims found for incoming pod."
I0506 15:59:56.252682      12 preemption.go:264] "No preemption candidate is found; preemption is not helpful for scheduling" pod="default/cspod-50"
I0506 15:59:56.252715      12 schedule_one.go:1044] "Unable to schedule pod; no fit; waiting" pod="default/cspod-50" err="0/5 nodes are available: 5 Insufficient cpu. preemption: 0/5 nodes are available: 5 No preemption victims found for incoming pod."
I0506 15:59:56.253180      12 preemption.go:264] "No preemption candidate is found; preemption is not helpful for scheduling" pod="default/cspod-51"
I0506 15:59:56.253211      12 schedule_one.go:1044] "Unable to schedule pod; no fit; waiting" pod="default/cspod-51" err="0/5 nodes are available: 5 Insufficient cpu. preemption: 0/5 nodes are available: 5 No preemption victims found for incoming pod."
I0506 15:59:56.253733      12 preemption.go:264] "No preemption candidate is found; preemption is not helpful for scheduling" pod="default/cspod-52"
I0506 15:59:56.254005      12 schedule_one.go:1044] "Unable to schedule pod; no fit; waiting" pod="default/cspod-52" err="0/5 nodes are available: 5 Insufficient cpu. preemption: 0/5 nodes are available: 5 No preemption victims found for incoming pod."
I0506 15:59:56.255266      12 preemption.go:264] "No preemption candidate is found; preemption is not helpful for scheduling" pod="default/cspod-53"
I0506 15:59:56.255303      12 schedule_one.go:1044] "Unable to schedule pod; no fit; waiting" pod="default/cspod-53" err="0/5 nodes are available: 5 Insufficient cpu. preemption: 0/5 nodes are available: 5 No preemption victims found for incoming pod."
I0506 15:59:56.255877      12 preemption.go:264] "No preemption candidate is found; preemption is not helpful for scheduling" pod="default/cspod-54"
I0506 15:59:56.255911      12 schedule_one.go:1044] "Unable to schedule pod; no fit; waiting" pod="default/cspod-54" err="0/5 nodes are available: 5 Insufficient cpu. preemption: 0/5 nodes are available: 5 No preemption victims found for incoming pod."
I0506 15:59:56.256364      12 preemption.go:264] "No preemption candidate is found; preemption is not helpful for scheduling" pod="default/cspod-60"
I0506 15:59:56.256396      12 schedule_one.go:1044] "Unable to schedule pod; no fit; waiting" pod="default/cspod-60" err="0/5 nodes are available: 5 Insufficient cpu. preemption: 0/5 nodes are available: 5 No preemption victims found for incoming pod."
I0506 15:59:56.256948      12 preemption.go:264] "No preemption candidate is found; preemption is not helpful for scheduling" pod="default/cspod-61"
I0506 15:59:56.256983      12 schedule_one.go:1044] "Unable to schedule pod; no fit; waiting" pod="default/cspod-61" err="0/5 nodes are available: 5 Insufficient cpu. preemption: 0/5 nodes are available: 5 No preemption victims found for incoming pod."
I0506 15:59:56.257468      12 preemption.go:264] "No preemption candidate is found; preemption is not helpful for scheduling" pod="default/cspod-62"
I0506 15:59:56.257505      12 schedule_one.go:1044] "Unable to schedule pod; no fit; waiting" pod="default/cspod-62" err="0/5 nodes are available: 5 Insufficient cpu. preemption: 0/5 nodes are available: 5 No preemption victims found for incoming pod."
I0506 15:59:56.258017      12 preemption.go:264] "No preemption candidate is found; preemption is not helpful for scheduling" pod="default/cspod-63"
I0506 15:59:56.258053      12 schedule_one.go:1044] "Unable to schedule pod; no fit; waiting" pod="default/cspod-63" err="0/5 nodes are available: 5 Insufficient cpu. preemption: 0/5 nodes are available: 5 No preemption victims found for incoming pod."
I0506 15:59:56.258575      12 preemption.go:264] "No preemption candidate is found; preemption is not helpful for scheduling" pod="default/cspod-64"
I0506 15:59:56.258609      12 schedule_one.go:1044] "Unable to schedule pod; no fit; waiting" pod="default/cspod-64" err="0/5 nodes are available: 5 Insufficient cpu. preemption: 0/5 nodes are available: 5 No preemption victims found for incoming pod."
I0506 15:59:56.259089      12 preemption.go:264] "No preemption candidate is found; preemption is not helpful for scheduling" pod="default/cspod-65"
I0506 15:59:56.259122      12 schedule_one.go:1044] "Unable to schedule pod; no fit; waiting" pod="default/cspod-65" err="0/5 nodes are available: 5 Insufficient cpu. preemption: 0/5 nodes are available: 5 No preemption victims found for incoming pod."
I0506 15:59:56.259641      12 preemption.go:264] "No preemption candidate is found; preemption is not helpful for scheduling" pod="default/cspod-66"
I0506 15:59:56.259674      12 schedule_one.go:1044] "Unable to schedule pod; no fit; waiting" pod="default/cspod-66" err="0/5 nodes are available: 5 Insufficient cpu. preemption: 0/5 nodes are available: 5 No preemption victims found for incoming pod."
I0506 15:59:56.260182      12 preemption.go:264] "No preemption candidate is found; preemption is not helpful for scheduling" pod="default/cspod-67"
I0506 15:59:56.260216      12 schedule_one.go:1044] "Unable to schedule pod; no fit; waiting" pod="default/cspod-67" err="0/5 nodes are available: 5 Insufficient cpu. preemption: 0/5 nodes are available: 5 No preemption victims found for incoming pod."
I0506 15:59:56.260701      12 preemption.go:264] "No preemption candidate is found; preemption is not helpful for scheduling" pod="default/cspod-68"
I0506 15:59:56.260734      12 schedule_one.go:1044] "Unable to schedule pod; no fit; waiting" pod="default/cspod-68" err="0/5 nodes are available: 5 Insufficient cpu. preemption: 0/5 nodes are available: 5 No preemption victims found for incoming pod."
I0506 15:59:56.261187      12 preemption.go:264] "No preemption candidate is found; preemption is not helpful for scheduling" pod="default/cspod-69"
I0506 15:59:56.261221      12 schedule_one.go:1044] "Unable to schedule pod; no fit; waiting" pod="default/cspod-69" err="0/5 nodes are available: 5 Insufficient cpu. preemption: 0/5 nodes are available: 5 No preemption victims found for incoming pod."
I0506 15:59:56.287457      12 schedule_one.go:314] "Successfully bound pod to node" pod="default/cspod-31" node="csnode-0" evaluatedNodes=5 feasibleNodes=5
I0506 15:59:56.287514      12 schedule_one.go:314] "Successfully bound pod to node" pod="default/cspod-30" node="csnode-3" evaluatedNodes=5 feasibleNodes=4
I0506 15:59:56.287848      12 schedule_one.go:314] "Successfully bound pod to node" pod="default/cspod-33" node="csnode-1" evaluatedNodes=5 feasibleNodes=5
I0506 15:59:56.287978      12 schedule_one.go:314] "Successfully bound pod to node" pod="default/cspod-35" node="csnode-2" evaluatedNodes=5 feasibleNodes=5
I0506 15:59:56.288000      12 schedule_one.go:314] "Successfully bound pod to node" pod="default/cspod-32" node="csnode-4" evaluatedNodes=5 feasibleNodes=5
I0506 15:59:56.288042      12 schedule_one.go:314] "Successfully bound pod to node" pod="default/cspod-34" node="csnode-2" evaluatedNodes=5 feasibleNodes=5
I0506 15:59:56.288046      12 schedule_one.go:314] "Successfully bound pod to node" pod="default/cspod-36" node="csnode-3" evaluatedNodes=5 feasibleNodes=4
I0506 15:59:56.288110      12 preemption.go:264] "No preemption candidate is found; preemption is not helpful for scheduling" pod="default/cspod-40"
I0506 15:59:56.288124      12 schedule_one.go:1044] "Unable to schedule pod; no fit; waiting" pod="default/cspod-40" err="0/5 nodes are available: 5 Insufficient cpu. preemption: 0/5 nodes are available: 5 No preemption victims found for incoming pod."
I0506 15:59:56.288170      12 schedule_one.go:314] "Successfully bound pod to node" pod="default/cspod-37" node="csnode-4" evaluatedNodes=5 feasibleNodes=3
I0506 15:59:56.288237      12 schedule_one.go:314] "Successfully bound pod to node" pod="default/cspod-38" node="csnode-0" evaluatedNodes=5 feasibleNodes=2
I0506 15:59:56.288396      12 schedule_one.go:314] "Successfully bound pod to node" pod="default/cspod-39" node="csnode-1" evaluatedNodes=5 feasibleNodes=1
I0506 15:59:56.288721      12 preemption.go:264] "No preemption candidate is found; preemption is not helpful for scheduling" pod="default/cspod-41"
I0506 15:59:56.288757      12 schedule_one.go:1044] "Unable to schedule pod; no fit; waiting" pod="default/cspod-41" err="0/5 nodes are available: 5 Insufficient cpu. preemption: 0/5 nodes are available: 5 No preemption victims found for incoming pod."
I0506 15:59:56.289308      12 preemption.go:264] "No preemption candidate is found; preemption is not helpful for scheduling" pod="default/cspod-42"
I0506 15:59:56.289340      12 schedule_one.go:1044] "Unable to schedule pod; no fit; waiting" pod="default/cspod-42" err="0/5 nodes are available: 5 Insufficient cpu. preemption: 0/5 nodes are available: 5 No preemption victims found for incoming pod."
I0506 15:59:56.289910      12 preemption.go:264] "No preemption candidate is found; preemption is not helpful for scheduling" pod="default/cspod-43"
I0506 15:59:56.289956      12 schedule_one.go:1044] "Unable to schedule pod; no fit; waiting" pod="default/cspod-43" err="0/5 nodes are available: 5 Insufficient cpu. preemption: 0/5 nodes are available: 5 No preemption victims found for incoming pod."
I0506 15:59:56.290561      12 preemption.go:264] "No preemption candidate is found; preemption is not helpful for scheduling" pod="default/cspod-44"
I0506 15:59:56.290604      12 schedule_one.go:1044] "Unable to schedule pod; no fit; waiting" pod="default/cspod-44" err="0/5 nodes are available: 5 Insufficient cpu. preemption: 0/5 nodes are available: 5 No preemption victims found for incoming pod."
I0506 15:59:56.291190      12 preemption.go:264] "No preemption candidate is found; preemption is not helpful for scheduling" pod="default/cspod-45"
I0506 15:59:56.291224      12 schedule_one.go:1044] "Unable to schedule pod; no fit; waiting" pod="default/cspod-45" err="0/5 nodes are available: 5 Insufficient cpu. preemption: 0/5 nodes are available: 5 No preemption victims found for incoming pod."
I0506 15:59:56.291836      12 preemption.go:264] "No preemption candidate is found; preemption is not helpful for scheduling" pod="default/cspod-46"
I0506 15:59:56.291877      12 schedule_one.go:1044] "Unable to schedule pod; no fit; waiting" pod="default/cspod-46" err="0/5 nodes are available: 5 Insufficient cpu. preemption: 0/5 nodes are available: 5 No preemption victims found for incoming pod."
I0506 15:59:56.292490      12 preemption.go:264] "No preemption candidate is found; preemption is not helpful for scheduling" pod="default/cspod-47"
I0506 15:59:56.292526      12 schedule_one.go:1044] "Unable to schedule pod; no fit; waiting" pod="default/cspod-47" err="0/5 nodes are available: 5 Insufficient cpu. preemption: 0/5 nodes are available: 5 No preemption victims found for incoming pod."
I0506 15:59:56.293114      12 preemption.go:264] "No preemption candidate is found; preemption is not helpful for scheduling" pod="default/cspod-48"
I0506 15:59:56.293150      12 schedule_one.go:1044] "Unable to schedule pod; no fit; waiting" pod="default/cspod-48" err="0/5 nodes are available: 5 Insufficient cpu. preemption: 0/5 nodes are available: 5 No preemption victims found for incoming pod."
I0506 15:59:56.293662      12 preemption.go:264] "No preemption candidate is found; preemption is not helpful for scheduling" pod="default/cspod-49"
I0506 15:59:56.293698      12 schedule_one.go:1044] "Unable to schedule pod; no fit; waiting" pod="default/cspod-49" err="0/5 nodes are available: 5 Insufficient cpu. preemption: 0/5 nodes are available: 5 No preemption victims found for incoming pod."
I0506 15:59:56.294229      12 preemption.go:264] "No preemption candidate is found; preemption is not helpful for scheduling" pod="default/cspod-50"
I0506 15:59:56.294257      12 schedule_one.go:1044] "Unable to schedule pod; no fit; waiting" pod="default/cspod-50" err="0/5 nodes are available: 5 Insufficient cpu. preemption: 0/5 nodes are available: 5 No preemption victims found for incoming pod."
I0506 15:59:56.294769      12 preemption.go:264] "No preemption candidate is found; preemption is not helpful for scheduling" pod="default/cspod-51"
I0506 15:59:56.294805      12 schedule_one.go:1044] "Unable to schedule pod; no fit; waiting" pod="default/cspod-51" err="0/5 nodes are available: 5 Insufficient cpu. preemption: 0/5 nodes are available: 5 No preemption victims found for incoming pod."
I0506 15:59:56.295333      12 preemption.go:264] "No preemption candidate is found; preemption is not helpful for scheduling" pod="default/cspod-52"
I0506 15:59:56.295372      12 schedule_one.go:1044] "Unable to schedule pod; no fit; waiting" pod="default/cspod-52" err="0/5 nodes are available: 5 Insufficient cpu. preemption: 0/5 nodes are available: 5 No preemption victims found for incoming pod."
I0506 15:59:56.295894      12 preemption.go:264] "No preemption candidate is found; preemption is not helpful for scheduling" pod="default/cspod-53"
I0506 15:59:56.295929      12 schedule_one.go:1044] "Unable to schedule pod; no fit; waiting" pod="default/cspod-53" err="0/5 nodes are available: 5 Insufficient cpu. preemption: 0/5 nodes are available: 5 No preemption victims found for incoming pod."
I0506 15:59:56.296472      12 preemption.go:264] "No preemption candidate is found; preemption is not helpful for scheduling" pod="default/cspod-54"
I0506 15:59:56.296506      12 schedule_one.go:1044] "Unable to schedule pod; no fit; waiting" pod="default/cspod-54" err="0/5 nodes are available: 5 Insufficient cpu. preemption: 0/5 nodes are available: 5 No preemption victims found for incoming pod."
I0506 15:59:56.297048      12 preemption.go:264] "No preemption candidate is found; preemption is not helpful for scheduling" pod="default/cspod-60"
I0506 15:59:56.297083      12 schedule_one.go:1044] "Unable to schedule pod; no fit; waiting" pod="default/cspod-60" err="0/5 nodes are available: 5 Insufficient cpu. preemption: 0/5 nodes are available: 5 No preemption victims found for incoming pod."
I0506 15:59:56.297633      12 preemption.go:264] "No preemption candidate is found; preemption is not helpful for scheduling" pod="default/cspod-61"
I0506 15:59:56.297669      12 schedule_one.go:1044] "Unable to schedule pod; no fit; waiting" pod="default/cspod-61" err="0/5 nodes are available: 5 Insufficient cpu. preemption: 0/5 nodes are available: 5 No preemption victims found for incoming pod."
I0506 15:59:56.298298      12 preemption.go:264] "No preemption candidate is found; preemption is not helpful for scheduling" pod="default/cspod-62"
I0506 15:59:56.298334      12 schedule_one.go:1044] "Unable to schedule pod; no fit; waiting" pod="default/cspod-62" err="0/5 nodes are available: 5 Insufficient cpu. preemption: 0/5 nodes are available: 5 No preemption victims found for incoming pod."
I0506 15:59:56.298916      12 preemption.go:264] "No preemption candidate is found; preemption is not helpful for scheduling" pod="default/cspod-63"
I0506 15:59:56.298953      12 schedule_one.go:1044] "Unable to schedule pod; no fit; waiting" pod="default/cspod-63" err="0/5 nodes are available: 5 Insufficient cpu. preemption: 0/5 nodes are available: 5 No preemption victims found for incoming pod."
I0506 15:59:56.299525      12 preemption.go:264] "No preemption candidate is found; preemption is not helpful for scheduling" pod="default/cspod-64"
I0506 15:59:56.299560      12 schedule_one.go:1044] "Unable to schedule pod; no fit; waiting" pod="default/cspod-64" err="0/5 nodes are available: 5 Insufficient cpu. preemption: 0/5 nodes are available: 5 No preemption victims found for incoming pod."
I0506 15:59:56.300080      12 preemption.go:264] "No preemption candidate is found; preemption is not helpful for scheduling" pod="default/cspod-65"
I0506 15:59:56.300120      12 schedule_one.go:1044] "Unable to schedule pod; no fit; waiting" pod="default/cspod-65" err="0/5 nodes are available: 5 Insufficient cpu. preemption: 0/5 nodes are available: 5 No preemption victims found for incoming pod."
I0506 15:59:56.300648      12 preemption.go:264] "No preemption candidate is found; preemption is not helpful for scheduling" pod="default/cspod-66"
I0506 15:59:56.300682      12 schedule_one.go:1044] "Unable to schedule pod; no fit; waiting" pod="default/cspod-66" err="0/5 nodes are available: 5 Insufficient cpu. preemption: 0/5 nodes are available: 5 No preemption victims found for incoming pod."
I0506 15:59:56.301253      12 preemption.go:264] "No preemption candidate is found; preemption is not helpful for scheduling" pod="default/cspod-67"
I0506 15:59:56.301288      12 schedule_one.go:1044] "Unable to schedule pod; no fit; waiting" pod="default/cspod-67" err="0/5 nodes are available: 5 Insufficient cpu. preemption: 0/5 nodes are available: 5 No preemption victims found for incoming pod."
I0506 15:59:56.301772      12 preemption.go:264] "No preemption candidate is found; preemption is not helpful for scheduling" pod="default/cspod-68"
I0506 15:59:56.301804      12 schedule_one.go:1044] "Unable to schedule pod; no fit; waiting" pod="default/cspod-68" err="0/5 nodes are available: 5 Insufficient cpu. preemption: 0/5 nodes are available: 5 No preemption victims found for incoming pod."
I0506 15:59:56.302324      12 preemption.go:264] "No preemption candidate is found; preemption is not helpful for scheduling" pod="default/cspod-69"
I0506 15:59:56.302357      12 schedule_one.go:1044] "Unable to schedule pod; no fit; waiting" pod="default/cspod-69" err="0/5 nodes are available: 5 Insufficient cpu. preemption: 0/5 nodes are available: 5 No preemption victims found for incoming pod."
I0506 15:59:56.321182      12 preemption.go:264] "No preemption candidate is found; preemption is not helpful for scheduling" pod="default/cspod-43"
I0506 15:59:56.321230      12 schedule_one.go:1044] "Unable to schedule pod; no fit; waiting" pod="default/cspod-43" err="0/5 nodes are available: 5 Insufficient cpu. preemption: 0/5 nodes are available: 5 No preemption victims found for incoming pod."
I0506 15:59:56.321307      12 schedule_one.go:314] "Successfully bound pod to node" pod="default/cspod-40" node="csnode-1" evaluatedNodes=5 feasibleNodes=3
I0506 15:59:56.321374      12 schedule_one.go:314] "Successfully bound pod to node" pod="default/cspod-41" node="csnode-0" evaluatedNodes=5 feasibleNodes=2
I0506 15:59:56.321691      12 schedule_one.go:314] "Successfully bound pod to node" pod="default/cspod-42" node="csnode-4" evaluatedNodes=5 feasibleNodes=1
I0506 15:59:56.321892      12 preemption.go:264] "No preemption candidate is found; preemption is not helpful for scheduling" pod="default/cspod-44"
I0506 15:59:56.321927      12 schedule_one.go:1044] "Unable to schedule pod; no fit; waiting" pod="default/cspod-44" err="0/5 nodes are available: 5 Insufficient cpu. preemption: 0/5 nodes are available: 5 No preemption victims found for incoming pod."
I0506 15:59:56.322483      12 preemption.go:264] "No preemption candidate is found; preemption is not helpful for scheduling" pod="default/cspod-45"
I0506 15:59:56.322517      12 schedule_one.go:1044] "Unable to schedule pod; no fit; waiting" pod="default/cspod-45" err="0/5 nodes are available: 5 Insufficient cpu. preemption: 0/5 nodes are available: 5 No preemption victims found for incoming pod."
I0506 15:59:56.323064      12 preemption.go:264] "No preemption candidate is found; preemption is not helpful for scheduling" pod="default/cspod-46"
I0506 15:59:56.323099      12 schedule_one.go:1044] "Unable to schedule pod; no fit; waiting" pod="default/cspod-46" err="0/5 nodes are available: 5 Insufficient cpu. preemption: 0/5 nodes are available: 5 No preemption victims found for incoming pod."
I0506 15:59:56.323652      12 preemption.go:264] "No preemption candidate is found; preemption is not helpful for scheduling" pod="default/cspod-47"
I0506 15:59:56.323687      12 schedule_one.go:1044] "Unable to schedule pod; no fit; waiting" pod="default/cspod-47" err="0/5 nodes are available: 5 Insufficient cpu. preemption: 0/5 nodes are available: 5 No preemption victims found for incoming pod."
I0506 15:59:56.324781      12 preemption.go:264] "No preemption candidate is found; preemption is not helpful for scheduling" pod="default/cspod-48"
I0506 15:59:56.324871      12 schedule_one.go:1044] "Unable to schedule pod; no fit; waiting" pod="default/cspod-48" err="0/5 nodes are available: 5 Insufficient cpu. preemption: 0/5 nodes are available: 5 No preemption victims found for incoming pod."
I0506 15:59:56.325660      12 preemption.go:264] "No preemption candidate is found; preemption is not helpful for scheduling" pod="default/cspod-49"
I0506 15:59:56.325700      12 schedule_one.go:1044] "Unable to schedule pod; no fit; waiting" pod="default/cspod-49" err="0/5 nodes are available: 5 Insufficient cpu. preemption: 0/5 nodes are available: 5 No preemption victims found for incoming pod."
I0506 15:59:56.326317      12 preemption.go:264] "No preemption candidate is found; preemption is not helpful for scheduling" pod="default/cspod-50"
I0506 15:59:56.326362      12 schedule_one.go:1044] "Unable to schedule pod; no fit; waiting" pod="default/cspod-50" err="0/5 nodes are available: 5 Insufficient cpu. preemption: 0/5 nodes are available: 5 No preemption victims found for incoming pod."
I0506 15:59:56.326888      12 preemption.go:264] "No preemption candidate is found; preemption is not helpful for scheduling" pod="default/cspod-51"
I0506 15:59:56.326924      12 schedule_one.go:1044] "Unable to schedule pod; no fit; waiting" pod="default/cspod-51" err="0/5 nodes are available: 5 Insufficient cpu. preemption: 0/5 nodes are available: 5 No preemption victims found for incoming pod."
I0506 15:59:56.327445      12 preemption.go:264] "No preemption candidate is found; preemption is not helpful for scheduling" pod="default/cspod-52"
I0506 15:59:56.327478      12 schedule_one.go:1044] "Unable to schedule pod; no fit; waiting" pod="default/cspod-52" err="0/5 nodes are available: 5 Insufficient cpu. preemption: 0/5 nodes are available: 5 No preemption victims found for incoming pod."
I0506 15:59:56.327954      12 preemption.go:264] "No preemption candidate is found; preemption is not helpful for scheduling" pod="default/cspod-53"
I0506 15:59:56.327987      12 schedule_one.go:1044] "Unable to schedule pod; no fit; waiting" pod="default/cspod-53" err="0/5 nodes are available: 5 Insufficient cpu. preemption: 0/5 nodes are available: 5 No preemption victims found for incoming pod."
I0506 15:59:56.328484      12 preemption.go:264] "No preemption candidate is found; preemption is not helpful for scheduling" pod="default/cspod-54"
I0506 15:59:56.328517      12 schedule_one.go:1044] "Unable to schedule pod; no fit; waiting" pod="default/cspod-54" err="0/5 nodes are available: 5 Insufficient cpu. preemption: 0/5 nodes are available: 5 No preemption victims found for incoming pod."
I0506 15:59:56.329017      12 preemption.go:264] "No preemption candidate is found; preemption is not helpful for scheduling" pod="default/cspod-60"
I0506 15:59:56.329050      12 schedule_one.go:1044] "Unable to schedule pod; no fit; waiting" pod="default/cspod-60" err="0/5 nodes are available: 5 Insufficient cpu. preemption: 0/5 nodes are available: 5 No preemption victims found for incoming pod."
I0506 15:59:56.329578      12 preemption.go:264] "No preemption candidate is found; preemption is not helpful for scheduling" pod="default/cspod-61"
I0506 15:59:56.329612      12 schedule_one.go:1044] "Unable to schedule pod; no fit; waiting" pod="default/cspod-61" err="0/5 nodes are available: 5 Insufficient cpu. preemption: 0/5 nodes are available: 5 No preemption victims found for incoming pod."
I0506 15:59:56.330226      12 preemption.go:264] "No preemption candidate is found; preemption is not helpful for scheduling" pod="default/cspod-62"
I0506 15:59:56.330261      12 schedule_one.go:1044] "Unable to schedule pod; no fit; waiting" pod="default/cspod-62" err="0/5 nodes are available: 5 Insufficient cpu. preemption: 0/5 nodes are available: 5 No preemption victims found for incoming pod."
I0506 15:59:56.330788      12 preemption.go:264] "No preemption candidate is found; preemption is not helpful for scheduling" pod="default/cspod-63"
I0506 15:59:56.330832      12 schedule_one.go:1044] "Unable to schedule pod; no fit; waiting" pod="default/cspod-63" err="0/5 nodes are available: 5 Insufficient cpu. preemption: 0/5 nodes are available: 5 No preemption victims found for incoming pod."
I0506 15:59:56.331378      12 preemption.go:264] "No preemption candidate is found; preemption is not helpful for scheduling" pod="default/cspod-64"
I0506 15:59:56.331409      12 schedule_one.go:1044] "Unable to schedule pod; no fit; waiting" pod="default/cspod-64" err="0/5 nodes are available: 5 Insufficient cpu. preemption: 0/5 nodes are available: 5 No preemption victims found for incoming pod."
I0506 15:59:56.331952      12 preemption.go:264] "No preemption candidate is found; preemption is not helpful for scheduling" pod="default/cspod-65"
I0506 15:59:56.331986      12 schedule_one.go:1044] "Unable to schedule pod; no fit; waiting" pod="default/cspod-65" err="0/5 nodes are available: 5 Insufficient cpu. preemption: 0/5 nodes are available: 5 No preemption victims found for incoming pod."
I0506 15:59:56.332477      12 preemption.go:264] "No preemption candidate is found; preemption is not helpful for scheduling" pod="default/cspod-66"
I0506 15:59:56.332510      12 schedule_one.go:1044] "Unable to schedule pod; no fit; waiting" pod="default/cspod-66" err="0/5 nodes are available: 5 Insufficient cpu. preemption: 0/5 nodes are available: 5 No preemption victims found for incoming pod."
I0506 15:59:56.333012      12 preemption.go:264] "No preemption candidate is found; preemption is not helpful for scheduling" pod="default/cspod-67"
I0506 15:59:56.333046      12 schedule_one.go:1044] "Unable to schedule pod; no fit; waiting" pod="default/cspod-67" err="0/5 nodes are available: 5 Insufficient cpu. preemption: 0/5 nodes are available: 5 No preemption victims found for incoming pod."
I0506 15:59:56.333510      12 preemption.go:264] "No preemption candidate is found; preemption is not helpful for scheduling" pod="default/cspod-68"
I0506 15:59:56.333543      12 schedule_one.go:1044] "Unable to schedule pod; no fit; waiting" pod="default/cspod-68" err="0/5 nodes are available: 5 Insufficient cpu. preemption: 0/5 nodes are available: 5 No preemption victims found for incoming pod."
I0506 15:59:56.334034      12 preemption.go:264] "No preemption candidate is found; preemption is not helpful for scheduling" pod="default/cspod-69"
I0506 15:59:56.334067      12 schedule_one.go:1044] "Unable to schedule pod; no fit; waiting" pod="default/cspod-69" err="0/5 nodes are available: 5 Insufficient cpu. preemption: 0/5 nodes are available: 5 No preemption victims found for incoming pod."
I0506 15:59:56.351956      12 preemption.go:264] "No preemption candidate is found; preemption is not helpful for scheduling" pod="default/cspod-44"
I0506 15:59:56.352002      12 schedule_one.go:1044] "Unable to schedule pod; no fit; waiting" pod="default/cspod-44" err="0/5 nodes are available: 5 Insufficient cpu. preemption: 0/5 nodes are available: 5 No preemption victims found for incoming pod."
I0506 15:59:56.360381      12 schedule_one.go:314] "Successfully bound pod to node" pod="default/cspod-43" node="csnode-3" evaluatedNodes=5 feasibleNodes=1
I0506 15:59:56.379937      12 preemption.go:264] "No preemption candidate is found; preemption is not helpful for scheduling" pod="default/cspod-45"
I0506 15:59:56.379988      12 schedule_one.go:1044] "Unable to schedule pod; no fit; waiting" pod="default/cspod-45" err="0/5 nodes are available: 5 Insufficient cpu. preemption: 0/5 nodes are available: 5 No preemption victims found for incoming pod."
I0506 15:59:56.399793      12 preemption.go:264] "No preemption candidate is found; preemption is not helpful for scheduling" pod="default/cspod-46"
I0506 15:59:56.399847      12 schedule_one.go:1044] "Unable to schedule pod; no fit; waiting" pod="default/cspod-46" err="0/5 nodes are available: 5 Insufficient cpu. preemption: 0/5 nodes are available: 5 No preemption victims found for incoming pod."
I0506 15:59:56.420720      12 preemption.go:264] "No preemption candidate is found; preemption is not helpful for scheduling" pod="default/cspod-47"
I0506 15:59:56.420769      12 schedule_one.go:1044] "Unable to schedule pod; no fit; waiting" pod="default/cspod-47" err="0/5 nodes are available: 5 Insufficient cpu. preemption: 0/5 nodes are available: 5 No preemption victims found for incoming pod."
I0506 15:59:56.439820      12 preemption.go:264] "No preemption candidate is found; preemption is not helpful for scheduling" pod="default/cspod-48"
I0506 15:59:56.439862      12 schedule_one.go:1044] "Unable to schedule pod; no fit; waiting" pod="default/cspod-48" err="0/5 nodes are available: 5 Insufficient cpu. preemption: 0/5 nodes are available: 5 No preemption victims found for incoming pod."
I0506 15:59:56.460309      12 preemption.go:264] "No preemption candidate is found; preemption is not helpful for scheduling" pod="default/cspod-49"
I0506 15:59:56.460360      12 schedule_one.go:1044] "Unable to schedule pod; no fit; waiting" pod="default/cspod-49" err="0/5 nodes are available: 5 Insufficient cpu. preemption: 0/5 nodes are available: 5 No preemption victims found for incoming pod."
I0506 15:59:56.480787      12 preemption.go:264] "No preemption candidate is found; preemption is not helpful for scheduling" pod="default/cspod-50"
I0506 15:59:56.480837      12 schedule_one.go:1044] "Unable to schedule pod; no fit; waiting" pod="default/cspod-50" err="0/5 nodes are available: 5 Insufficient cpu. preemption: 0/5 nodes are available: 5 No preemption victims found for incoming pod."
I0506 15:59:56.500134      12 preemption.go:264] "No preemption candidate is found; preemption is not helpful for scheduling" pod="default/cspod-51"
I0506 15:59:56.500180      12 schedule_one.go:1044] "Unable to schedule pod; no fit; waiting" pod="default/cspod-51" err="0/5 nodes are available: 5 Insufficient cpu. preemption: 0/5 nodes are available: 5 No preemption victims found for incoming pod."
I0506 15:59:56.520356      12 preemption.go:264] "No preemption candidate is found; preemption is not helpful for scheduling" pod="default/cspod-52"
I0506 15:59:56.520400      12 schedule_one.go:1044] "Unable to schedule pod; no fit; waiting" pod="default/cspod-52" err="0/5 nodes are available: 5 Insufficient cpu. preemption: 0/5 nodes are available: 5 No preemption victims found for incoming pod."
I0506 15:59:56.540829      12 preemption.go:264] "No preemption candidate is found; preemption is not helpful for scheduling" pod="default/cspod-53"
I0506 15:59:56.540875      12 schedule_one.go:1044] "Unable to schedule pod; no fit; waiting" pod="default/cspod-53" err="0/5 nodes are available: 5 Insufficient cpu. preemption: 0/5 nodes are available: 5 No preemption victims found for incoming pod."
I0506 15:59:56.563476      12 preemption.go:264] "No preemption candidate is found; preemption is not helpful for scheduling" pod="default/cspod-54"
I0506 15:59:56.563523      12 schedule_one.go:1044] "Unable to schedule pod; no fit; waiting" pod="default/cspod-54" err="0/5 nodes are available: 5 Insufficient cpu. preemption: 0/5 nodes are available: 5 No preemption victims found for incoming pod."
I0506 15:59:56.580344      12 preemption.go:264] "No preemption candidate is found; preemption is not helpful for scheduling" pod="default/cspod-60"
I0506 15:59:56.580386      12 schedule_one.go:1044] "Unable to schedule pod; no fit; waiting" pod="default/cspod-60" err="0/5 nodes are available: 5 Insufficient cpu. preemption: 0/5 nodes are available: 5 No preemption victims found for incoming pod."
I0506 15:59:56.600436      12 preemption.go:264] "No preemption candidate is found; preemption is not helpful for scheduling" pod="default/cspod-61"
I0506 15:59:56.600510      12 schedule_one.go:1044] "Unable to schedule pod; no fit; waiting" pod="default/cspod-61" err="0/5 nodes are available: 5 Insufficient cpu. preemption: 0/5 nodes are available: 5 No preemption victims found for incoming pod."
I0506 15:59:56.620702      12 preemption.go:264] "No preemption candidate is found; preemption is not helpful for scheduling" pod="default/cspod-62"
I0506 15:59:56.620744      12 schedule_one.go:1044] "Unable to schedule pod; no fit; waiting" pod="default/cspod-62" err="0/5 nodes are available: 5 Insufficient cpu. preemption: 0/5 nodes are available: 5 No preemption victims found for incoming pod."
I0506 15:59:56.640015      12 preemption.go:264] "No preemption candidate is found; preemption is not helpful for scheduling" pod="default/cspod-63"
I0506 15:59:56.640063      12 schedule_one.go:1044] "Unable to schedule pod; no fit; waiting" pod="default/cspod-63" err="0/5 nodes are available: 5 Insufficient cpu. preemption: 0/5 nodes are available: 5 No preemption victims found for incoming pod."
I0506 15:59:56.660360      12 preemption.go:264] "No preemption candidate is found; preemption is not helpful for scheduling" pod="default/cspod-64"
I0506 15:59:56.660408      12 schedule_one.go:1044] "Unable to schedule pod; no fit; waiting" pod="default/cspod-64" err="0/5 nodes are available: 5 Insufficient cpu. preemption: 0/5 nodes are available: 5 No preemption victims found for incoming pod."
I0506 15:59:56.680674      12 preemption.go:264] "No preemption candidate is found; preemption is not helpful for scheduling" pod="default/cspod-65"
I0506 15:59:56.680717      12 schedule_one.go:1044] "Unable to schedule pod; no fit; waiting" pod="default/cspod-65" err="0/5 nodes are available: 5 Insufficient cpu. preemption: 0/5 nodes are available: 5 No preemption victims found for incoming pod."
I0506 15:59:56.699952      12 preemption.go:264] "No preemption candidate is found; preemption is not helpful for scheduling" pod="default/cspod-66"
I0506 15:59:56.699994      12 schedule_one.go:1044] "Unable to schedule pod; no fit; waiting" pod="default/cspod-66" err="0/5 nodes are available: 5 Insufficient cpu. preemption: 0/5 nodes are available: 5 No preemption victims found for incoming pod."
I0506 15:59:56.719607      12 preemption.go:264] "No preemption candidate is found; preemption is not helpful for scheduling" pod="default/cspod-67"
I0506 15:59:56.719653      12 schedule_one.go:1044] "Unable to schedule pod; no fit; waiting" pod="default/cspod-67" err="0/5 nodes are available: 5 Insufficient cpu. preemption: 0/5 nodes are available: 5 No preemption victims found for incoming pod."
I0506 15:59:56.739777      12 preemption.go:264] "No preemption candidate is found; preemption is not helpful for scheduling" pod="default/cspod-68"
I0506 15:59:56.739823      12 schedule_one.go:1044] "Unable to schedule pod; no fit; waiting" pod="default/cspod-68" err="0/5 nodes are available: 5 Insufficient cpu. preemption: 0/5 nodes are available: 5 No preemption victims found for incoming pod."
I0506 15:59:56.759845      12 preemption.go:264] "No preemption candidate is found; preemption is not helpful for scheduling" pod="default/cspod-69"
I0506 15:59:56.759888      12 schedule_one.go:1044] "Unable to schedule pod; no fit; waiting" pod="default/cspod-69" err="0/5 nodes are available: 5 Insufficient cpu. preemption: 0/5 nodes are available: 5 No preemption victims found for incoming pod."
I0506 15:59:56.786447      12 preemption.go:264] "No preemption candidate is found; preemption is not helpful for scheduling" pod="default/cspod-46"
I0506 15:59:56.786495      12 schedule_one.go:1044] "Unable to schedule pod; no fit; waiting" pod="default/cspod-46" err="0/5 nodes are available: 5 Insufficient cpu. preemption: 0/5 nodes are available: 5 No preemption victims found for incoming pod."
I0506 15:59:56.800216      12 schedule_one.go:314] "Successfully bound pod to node" pod="default/cspod-44" node="csnode-4" evaluatedNodes=5 feasibleNodes=2
I0506 15:59:56.820158      12 schedule_one.go:314] "Successfully bound pod to node" pod="default/cspod-45" node="csnode-0" evaluatedNodes=5 feasibleNodes=1
I0506 15:59:56.840155      12 preemption.go:264] "No preemption candidate is found; preemption is not helpful for scheduling" pod="default/cspod-47"
I0506 15:59:56.840201      12 schedule_one.go:1044] "Unable to schedule pod; no fit; waiting" pod="default/cspod-47" err="0/5 nodes are available: 5 Insufficient cpu. preemption: 0/5 nodes are available: 5 No preemption victims found for incoming pod."
I0506 15:59:56.860343      12 preemption.go:264] "No preemption candidate is found; preemption is not helpful for scheduling" pod="default/cspod-48"
I0506 15:59:56.860390      12 schedule_one.go:1044] "Unable to schedule pod; no fit; waiting" pod="default/cspod-48" err="0/5 nodes are available: 5 Insufficient cpu. preemption: 0/5 nodes are available: 5 No preemption victims found for incoming pod."
I0506 15:59:56.880745      12 preemption.go:264] "No preemption candidate is found; preemption is not helpful for scheduling" pod="default/cspod-49"
I0506 15:59:56.880795      12 schedule_one.go:1044] "Unable to schedule pod; no fit; waiting" pod="default/cspod-49" err="0/5 nodes are available: 5 Insufficient cpu. preemption: 0/5 nodes are available: 5 No preemption victims found for incoming pod."
I0506 15:59:56.900644      12 preemption.go:264] "No preemption candidate is found; preemption is not helpful for scheduling" pod="default/cspod-50"
I0506 15:59:56.900688      12 schedule_one.go:1044] "Unable to schedule pod; no fit; waiting" pod="default/cspod-50" err="0/5 nodes are available: 5 Insufficient cpu. preemption: 0/5 nodes are available: 5 No preemption victims found for incoming pod."
I0506 15:59:56.920661      12 preemption.go:264] "No preemption candidate is found; preemption is not helpful for scheduling" pod="default/cspod-51"
I0506 15:59:56.920736      12 schedule_one.go:1044] "Unable to schedule pod; no fit; waiting" pod="default/cspod-51" err="0/5 nodes are available: 5 Insufficient cpu. preemption: 0/5 nodes are available: 5 No preemption victims found for incoming pod."
I0506 15:59:56.940654      12 preemption.go:264] "No preemption candidate is found; preemption is not helpful for scheduling" pod="default/cspod-52"
I0506 15:59:56.940698      12 schedule_one.go:1044] "Unable to schedule pod; no fit; waiting" pod="default/cspod-52" err="0/5 nodes are available: 5 Insufficient cpu. preemption: 0/5 nodes are available: 5 No preemption victims found for incoming pod."
I0506 15:59:56.959671      12 preemption.go:264] "No preemption candidate is found; preemption is not helpful for scheduling" pod="default/cspod-53"
I0506 15:59:56.959710      12 schedule_one.go:1044] "Unable to schedule pod; no fit; waiting" pod="default/cspod-53" err="0/5 nodes are available: 5 Insufficient cpu. preemption: 0/5 nodes are available: 5 No preemption victims found for incoming pod."
I0506 15:59:56.979725      12 preemption.go:264] "No preemption candidate is found; preemption is not helpful for scheduling" pod="default/cspod-54"
I0506 15:59:56.979799      12 schedule_one.go:1044] "Unable to schedule pod; no fit; waiting" pod="default/cspod-54" err="0/5 nodes are available: 5 Insufficient cpu. preemption: 0/5 nodes are available: 5 No preemption victims found for incoming pod."
I0506 15:59:56.999995      12 preemption.go:264] "No preemption candidate is found; preemption is not helpful for scheduling" pod="default/cspod-60"
I0506 15:59:57.000042      12 schedule_one.go:1044] "Unable to schedule pod; no fit; waiting" pod="default/cspod-60" err="0/5 nodes are available: 5 Insufficient cpu. preemption: 0/5 nodes are available: 5 No preemption victims found for incoming pod."
I0506 15:59:57.020250      12 preemption.go:264] "No preemption candidate is found; preemption is not helpful for scheduling" pod="default/cspod-61"
I0506 15:59:57.020292      12 schedule_one.go:1044] "Unable to schedule pod; no fit; waiting" pod="default/cspod-61" err="0/5 nodes are available: 5 Insufficient cpu. preemption: 0/5 nodes are available: 5 No preemption victims found for incoming pod."
I0506 15:59:57.040190      12 preemption.go:264] "No preemption candidate is found; preemption is not helpful for scheduling" pod="default/cspod-62"
I0506 15:59:57.040234      12 schedule_one.go:1044] "Unable to schedule pod; no fit; waiting" pod="default/cspod-62" err="0/5 nodes are available: 5 Insufficient cpu. preemption: 0/5 nodes are available: 5 No preemption victims found for incoming pod."
I0506 15:59:57.060203      12 preemption.go:264] "No preemption candidate is found; preemption is not helpful for scheduling" pod="default/cspod-63"
I0506 15:59:57.060277      12 schedule_one.go:1044] "Unable to schedule pod; no fit; waiting" pod="default/cspod-63" err="0/5 nodes are available: 5 Insufficient cpu. preemption: 0/5 nodes are available: 5 No preemption victims found for incoming pod."
I0506 15:59:57.080468      12 preemption.go:264] "No preemption candidate is found; preemption is not helpful for scheduling" pod="default/cspod-64"
I0506 15:59:57.080542      12 schedule_one.go:1044] "Unable to schedule pod; no fit; waiting" pod="default/cspod-64" err="0/5 nodes are available: 5 Insufficient cpu. preemption: 0/5 nodes are available: 5 No preemption victims found for incoming pod."
I0506 15:59:57.100170      12 preemption.go:264] "No preemption candidate is found; preemption is not helpful for scheduling" pod="default/cspod-65"
I0506 15:59:57.100231      12 schedule_one.go:1044] "Unable to schedule pod; no fit; waiting" pod="default/cspod-65" err="0/5 nodes are available: 5 Insufficient cpu. preemption: 0/5 nodes are available: 5 No preemption victims found for incoming pod."
I0506 15:59:57.120369      12 preemption.go:264] "No preemption candidate is found; preemption is not helpful for scheduling" pod="default/cspod-66"
I0506 15:59:57.120410      12 schedule_one.go:1044] "Unable to schedule pod; no fit; waiting" pod="default/cspod-66" err="0/5 nodes are available: 5 Insufficient cpu. preemption: 0/5 nodes are available: 5 No preemption victims found for incoming pod."
I0506 15:59:57.140599      12 preemption.go:264] "No preemption candidate is found; preemption is not helpful for scheduling" pod="default/cspod-67"
I0506 15:59:57.140650      12 schedule_one.go:1044] "Unable to schedule pod; no fit; waiting" pod="default/cspod-67" err="0/5 nodes are available: 5 Insufficient cpu. preemption: 0/5 nodes are available: 5 No preemption victims found for incoming pod."
I0506 15:59:57.159558      12 preemption.go:264] "No preemption candidate is found; preemption is not helpful for scheduling" pod="default/cspod-68"
I0506 15:59:57.159599      12 schedule_one.go:1044] "Unable to schedule pod; no fit; waiting" pod="default/cspod-68" err="0/5 nodes are available: 5 Insufficient cpu. preemption: 0/5 nodes are available: 5 No preemption victims found for incoming pod."
I0506 15:59:57.179620      12 preemption.go:264] "No preemption candidate is found; preemption is not helpful for scheduling" pod="default/cspod-69"
I0506 15:59:57.179663      12 schedule_one.go:1044] "Unable to schedule pod; no fit; waiting" pod="default/cspod-69" err="0/5 nodes are available: 5 Insufficient cpu. preemption: 0/5 nodes are available: 5 No preemption victims found for incoming pod."
I0506 15:59:57.205327      12 preemption.go:264] "No preemption candidate is found; preemption is not helpful for scheduling" pod="default/cspod-49"
I0506 15:59:57.205370      12 schedule_one.go:1044] "Unable to schedule pod; no fit; waiting" pod="default/cspod-49" err="0/5 nodes are available: 5 Insufficient cpu. preemption: 0/5 nodes are available: 5 No preemption victims found for incoming pod."
I0506 15:59:57.219692      12 schedule_one.go:314] "Successfully bound pod to node" pod="default/cspod-46" node="csnode-0" evaluatedNodes=5 feasibleNodes=2
I0506 15:59:57.240361      12 schedule_one.go:314] "Successfully bound pod to node" pod="default/cspod-47" node="csnode-4" evaluatedNodes=5 feasibleNodes=2
I0506 15:59:57.259885      12 schedule_one.go:314] "Successfully bound pod to node" pod="default/cspod-48" node="csnode-1" evaluatedNodes=5 feasibleNodes=1
I0506 15:59:57.279946      12 preemption.go:264] "No preemption candidate is found; preemption is not helpful for scheduling" pod="default/cspod-50"
I0506 15:59:57.280025      12 schedule_one.go:1044] "Unable to schedule pod; no fit; waiting" pod="default/cspod-50" err="0/5 nodes are available: 5 Insufficient cpu. preemption: 0/5 nodes are available: 5 No preemption victims found for incoming pod."
I0506 15:59:57.300084      12 preemption.go:264] "No preemption candidate is found; preemption is not helpful for scheduling" pod="default/cspod-51"
I0506 15:59:57.300141      12 schedule_one.go:1044] "Unable to schedule pod; no fit; waiting" pod="default/cspod-51" err="0/5 nodes are available: 5 Insufficient cpu. preemption: 0/5 nodes are available: 5 No preemption victims found for incoming pod."
I0506 15:59:57.320251      12 preemption.go:264] "No preemption candidate is found; preemption is not helpful for scheduling" pod="default/cspod-52"
I0506 15:59:57.320325      12 schedule_one.go:1044] "Unable to schedule pod; no fit; waiting" pod="default/cspod-52" err="0/5 nodes are available: 5 Insufficient cpu. preemption: 0/5 nodes are available: 5 No preemption victims found for incoming pod."
I0506 15:59:57.340442      12 preemption.go:264] "No preemption candidate is found; preemption is not helpful for scheduling" pod="default/cspod-53"
I0506 15:59:57.340486      12 schedule_one.go:1044] "Unable to schedule pod; no fit; waiting" pod="default/cspod-53" err="0/5 nodes are available: 5 Insufficient cpu. preemption: 0/5 nodes are available: 5 No preemption victims found for incoming pod."
I0506 15:59:57.360380      12 preemption.go:264] "No preemption candidate is found; preemption is not helpful for scheduling" pod="default/cspod-54"
I0506 15:59:57.360424      12 schedule_one.go:1044] "Unable to schedule pod; no fit; waiting" pod="default/cspod-54" err="0/5 nodes are available: 5 Insufficient cpu. preemption: 0/5 nodes are available: 5 No preemption victims found for incoming pod."
I0506 15:59:57.379560      12 preemption.go:264] "No preemption candidate is found; preemption is not helpful for scheduling" pod="default/cspod-60"
I0506 15:59:57.379630      12 schedule_one.go:1044] "Unable to schedule pod; no fit; waiting" pod="default/cspod-60" err="0/5 nodes are available: 5 Insufficient cpu. preemption: 0/5 nodes are available: 5 No preemption victims found for incoming pod."
I0506 15:59:57.400220      12 preemption.go:264] "No preemption candidate is found; preemption is not helpful for scheduling" pod="default/cspod-61"
I0506 15:59:57.400267      12 schedule_one.go:1044] "Unable to schedule pod; no fit; waiting" pod="default/cspod-61" err="0/5 nodes are available: 5 Insufficient cpu. preemption: 0/5 nodes are available: 5 No preemption victims found for incoming pod."
I0506 15:59:57.419469      12 preemption.go:264] "No preemption candidate is found; preemption is not helpful for scheduling" pod="default/cspod-62"
I0506 15:59:57.419506      12 schedule_one.go:1044] "Unable to schedule pod; no fit; waiting" pod="default/cspod-62" err="0/5 nodes are available: 5 Insufficient cpu. preemption: 0/5 nodes are available: 5 No preemption victims found for incoming pod."
I0506 15:59:57.439942      12 preemption.go:264] "No preemption candidate is found; preemption is not helpful for scheduling" pod="default/cspod-63"
I0506 15:59:57.439988      12 schedule_one.go:1044] "Unable to schedule pod; no fit; waiting" pod="default/cspod-63" err="0/5 nodes are available: 5 Insufficient cpu. preemption: 0/5 nodes are available: 5 No preemption victims found for incoming pod."
I0506 15:59:57.459958      12 preemption.go:264] "No preemption candidate is found; preemption is not helpful for scheduling" pod="default/cspod-64"
I0506 15:59:57.459998      12 schedule_one.go:1044] "Unable to schedule pod; no fit; waiting" pod="default/cspod-64" err="0/5 nodes are available: 5 Insufficient cpu. preemption: 0/5 nodes are available: 5 No preemption victims found for incoming pod."
I0506 15:59:57.479919      12 preemption.go:264] "No preemption candidate is found; preemption is not helpful for scheduling" pod="default/cspod-65"
I0506 15:59:57.479963      12 schedule_one.go:1044] "Unable to schedule pod; no fit; waiting" pod="default/cspod-65" err="0/5 nodes are available: 5 Insufficient cpu. preemption: 0/5 nodes are available: 5 No preemption victims found for incoming pod."
I0506 15:59:57.499983      12 preemption.go:264] "No preemption candidate is found; preemption is not helpful for scheduling" pod="default/cspod-66"
I0506 15:59:57.500051      12 schedule_one.go:1044] "Unable to schedule pod; no fit; waiting" pod="default/cspod-66" err="0/5 nodes are available: 5 Insufficient cpu. preemption: 0/5 nodes are available: 5 No preemption victims found for incoming pod."
I0506 15:59:57.519905      12 preemption.go:264] "No preemption candidate is found; preemption is not helpful for scheduling" pod="default/cspod-67"
I0506 15:59:57.519957      12 schedule_one.go:1044] "Unable to schedule pod; no fit; waiting" pod="default/cspod-67" err="0/5 nodes are available: 5 Insufficient cpu. preemption: 0/5 nodes are available: 5 No preemption victims found for incoming pod."
I0506 15:59:57.540222      12 preemption.go:264] "No preemption candidate is found; preemption is not helpful for scheduling" pod="default/cspod-68"
I0506 15:59:57.540285      12 schedule_one.go:1044] "Unable to schedule pod; no fit; waiting" pod="default/cspod-68" err="0/5 nodes are available: 5 Insufficient cpu. preemption: 0/5 nodes are available: 5 No preemption victims found for incoming pod."
I0506 15:59:57.560055      12 preemption.go:264] "No preemption candidate is found; preemption is not helpful for scheduling" pod="default/cspod-69"
I0506 15:59:57.560124      12 schedule_one.go:1044] "Unable to schedule pod; no fit; waiting" pod="default/cspod-69" err="0/5 nodes are available: 5 Insufficient cpu. preemption: 0/5 nodes are available: 5 No preemption victims found for incoming pod."
I0506 15:59:57.589701      12 preemption.go:264] "No preemption candidate is found; preemption is not helpful for scheduling" pod="default/cspod-51"
I0506 15:59:57.589784      12 schedule_one.go:1044] "Unable to schedule pod; no fit; waiting" pod="default/cspod-51" err="0/5 nodes are available: 5 Insufficient cpu. preemption: 0/5 nodes are available: 5 No preemption victims found for incoming pod."
I0506 15:59:57.599993      12 schedule_one.go:314] "Successfully bound pod to node" pod="default/cspod-49" node="csnode-2" evaluatedNodes=5 feasibleNodes=1
I0506 15:59:57.620297      12 schedule_one.go:314] "Successfully bound pod to node" pod="default/cspod-50" node="csnode-2" evaluatedNodes=5 feasibleNodes=1
I0506 15:59:57.640501      12 preemption.go:264] "No preemption candidate is found; preemption is not helpful for scheduling" pod="default/cspod-52"
I0506 15:59:57.640545      12 schedule_one.go:1044] "Unable to schedule pod; no fit; waiting" pod="default/cspod-52" err="0/5 nodes are available: 5 Insufficient cpu. preemption: 0/5 nodes are available: 5 No preemption victims found for incoming pod."
I0506 15:59:57.660688      12 preemption.go:264] "No preemption candidate is found; preemption is not helpful for scheduling" pod="default/cspod-53"
I0506 15:59:57.660734      12 schedule_one.go:1044] "Unable to schedule pod; no fit; waiting" pod="default/cspod-53" err="0/5 nodes are available: 5 Insufficient cpu. preemption: 0/5 nodes are available: 5 No preemption victims found for incoming pod."
I0506 15:59:57.679758      12 preemption.go:264] "No preemption candidate is found; preemption is not helpful for scheduling" pod="default/cspod-54"
I0506 15:59:57.679802      12 schedule_one.go:1044] "Unable to schedule pod; no fit; waiting" pod="default/cspod-54" err="0/5 nodes are available: 5 Insufficient cpu. preemption: 0/5 nodes are available: 5 No preemption victims found for incoming pod."
I0506 15:59:57.699645      12 preemption.go:264] "No preemption candidate is found; preemption is not helpful for scheduling" pod="default/cspod-60"
I0506 15:59:57.699684      12 schedule_one.go:1044] "Unable to schedule pod; no fit; waiting" pod="default/cspod-60" err="0/5 nodes are available: 5 Insufficient cpu. preemption: 0/5 nodes are available: 5 No preemption victims found for incoming pod."
I0506 15:59:57.719908      12 preemption.go:264] "No preemption candidate is found; preemption is not helpful for scheduling" pod="default/cspod-61"
I0506 15:59:57.719987      12 schedule_one.go:1044] "Unable to schedule pod; no fit; waiting" pod="default/cspod-61" err="0/5 nodes are available: 5 Insufficient cpu. preemption: 0/5 nodes are available: 5 No preemption victims found for incoming pod."
I0506 15:59:57.740224      12 preemption.go:264] "No preemption candidate is found; preemption is not helpful for scheduling" pod="default/cspod-62"
I0506 15:59:57.740271      12 schedule_one.go:1044] "Unable to schedule pod; no fit; waiting" pod="default/cspod-62" err="0/5 nodes are available: 5 Insufficient cpu. preemption: 0/5 nodes are available: 5 No preemption victims found for incoming pod."
I0506 15:59:57.760318      12 preemption.go:264] "No preemption candidate is found; preemption is not helpful for scheduling" pod="default/cspod-63"
I0506 15:59:57.760367      12 schedule_one.go:1044] "Unable to schedule pod; no fit; waiting" pod="default/cspod-63" err="0/5 nodes are available: 5 Insufficient cpu. preemption: 0/5 nodes are available: 5 No preemption victims found for incoming pod."
I0506 15:59:57.780328      12 preemption.go:264] "No preemption candidate is found; preemption is not helpful for scheduling" pod="default/cspod-64"
I0506 15:59:57.780393      12 schedule_one.go:1044] "Unable to schedule pod; no fit; waiting" pod="default/cspod-64" err="0/5 nodes are available: 5 Insufficient cpu. preemption: 0/5 nodes are available: 5 No preemption victims found for incoming pod."
I0506 15:59:57.800886      12 preemption.go:264] "No preemption candidate is found; preemption is not helpful for scheduling" pod="default/cspod-65"
I0506 15:59:57.800937      12 schedule_one.go:1044] "Unable to schedule pod; no fit; waiting" pod="default/cspod-65" err="0/5 nodes are available: 5 Insufficient cpu. preemption: 0/5 nodes are available: 5 No preemption victims found for incoming pod."
I0506 15:59:57.820358      12 preemption.go:264] "No preemption candidate is found; preemption is not helpful for scheduling" pod="default/cspod-66"
I0506 15:59:57.820433      12 schedule_one.go:1044] "Unable to schedule pod; no fit; waiting" pod="default/cspod-66" err="0/5 nodes are available: 5 Insufficient cpu. preemption: 0/5 nodes are available: 5 No preemption victims found for incoming pod."
I0506 15:59:57.840657      12 preemption.go:264] "No preemption candidate is found; preemption is not helpful for scheduling" pod="default/cspod-67"
I0506 15:59:57.840717      12 schedule_one.go:1044] "Unable to schedule pod; no fit; waiting" pod="default/cspod-67" err="0/5 nodes are available: 5 Insufficient cpu. preemption: 0/5 nodes are available: 5 No preemption victims found for incoming pod."
I0506 15:59:57.859631      12 preemption.go:264] "No preemption candidate is found; preemption is not helpful for scheduling" pod="default/cspod-68"
I0506 15:59:57.859676      12 schedule_one.go:1044] "Unable to schedule pod; no fit; waiting" pod="default/cspod-68" err="0/5 nodes are available: 5 Insufficient cpu. preemption: 0/5 nodes are available: 5 No preemption victims found for incoming pod."
I0506 15:59:57.879901      12 preemption.go:264] "No preemption candidate is found; preemption is not helpful for scheduling" pod="default/cspod-69"
I0506 15:59:57.879953      12 schedule_one.go:1044] "Unable to schedule pod; no fit; waiting" pod="default/cspod-69" err="0/5 nodes are available: 5 Insufficient cpu. preemption: 0/5 nodes are available: 5 No preemption victims found for incoming pod."
I0506 15:59:57.905108      12 preemption.go:264] "No preemption candidate is found; preemption is not helpful for scheduling" pod="default/cspod-53"
I0506 15:59:57.905151      12 schedule_one.go:1044] "Unable to schedule pod; no fit; waiting" pod="default/cspod-53" err="0/5 nodes are available: 5 Insufficient cpu. preemption: 0/5 nodes are available: 5 No preemption victims found for incoming pod."
I0506 15:59:57.920071      12 schedule_one.go:314] "Successfully bound pod to node" pod="default/cspod-51" node="csnode-3" evaluatedNodes=5 feasibleNodes=2
I0506 15:59:57.939772      12 schedule_one.go:314] "Successfully bound pod to node" pod="default/cspod-52" node="csnode-1" evaluatedNodes=5 feasibleNodes=1
I0506 15:59:57.959874      12 preemption.go:264] "No preemption candidate is found; preemption is not helpful for scheduling" pod="default/cspod-54"
I0506 15:59:57.959917      12 schedule_one.go:1044] "Unable to schedule pod; no fit; waiting" pod="default/cspod-54" err="0/5 nodes are available: 5 Insufficient cpu. preemption: 0/5 nodes are available: 5 No preemption victims found for incoming pod."
I0506 15:59:57.980094      12 preemption.go:264] "No preemption candidate is found; preemption is not helpful for scheduling" pod="default/cspod-60"
I0506 15:59:57.980141      12 schedule_one.go:1044] "Unable to schedule pod; no fit; waiting" pod="default/cspod-60" err="0/5 nodes are available: 5 Insufficient cpu. preemption: 0/5 nodes are available: 5 No preemption victims found for incoming pod."
I0506 15:59:58.000338      12 preemption.go:264] "No preemption candidate is found; preemption is not helpful for scheduling" pod="default/cspod-61"
I0506 15:59:58.000406      12 schedule_one.go:1044] "Unable to schedule pod; no fit; waiting" pod="default/cspod-61" err="0/5 nodes are available: 5 Insufficient cpu. preemption: 0/5 nodes are available: 5 No preemption victims found for incoming pod."
I0506 15:59:58.020456      12 preemption.go:264] "No preemption candidate is found; preemption is not helpful for scheduling" pod="default/cspod-62"
I0506 15:59:58.020494      12 schedule_one.go:1044] "Unable to schedule pod; no fit; waiting" pod="default/cspod-62" err="0/5 nodes are available: 5 Insufficient cpu. preemption: 0/5 nodes are available: 5 No preemption victims found for incoming pod."
I0506 15:59:58.040285      12 preemption.go:264] "No preemption candidate is found; preemption is not helpful for scheduling" pod="default/cspod-63"
I0506 15:59:58.040321      12 schedule_one.go:1044] "Unable to schedule pod; no fit; waiting" pod="default/cspod-63" err="0/5 nodes are available: 5 Insufficient cpu. preemption: 0/5 nodes are available: 5 No preemption victims found for incoming pod."
I0506 15:59:58.061156      12 preemption.go:264] "No preemption candidate is found; preemption is not helpful for scheduling" pod="default/cspod-64"
I0506 15:59:58.061207      12 schedule_one.go:1044] "Unable to schedule pod; no fit; waiting" pod="default/cspod-64" err="0/5 nodes are available: 5 Insufficient cpu. preemption: 0/5 nodes are available: 5 No preemption victims found for incoming pod."
I0506 15:59:58.080257      12 preemption.go:264] "No preemption candidate is found; preemption is not helpful for scheduling" pod="default/cspod-65"
I0506 15:59:58.080302      12 schedule_one.go:1044] "Unable to schedule pod; no fit; waiting" pod="default/cspod-65" err="0/5 nodes are available: 5 Insufficient cpu. preemption: 0/5 nodes are available: 5 No preemption victims found for incoming pod."
I0506 15:59:58.100033      12 preemption.go:264] "No preemption candidate is found; preemption is not helpful for scheduling" pod="default/cspod-66"
I0506 15:59:58.100070      12 schedule_one.go:1044] "Unable to schedule pod; no fit; waiting" pod="default/cspod-66" err="0/5 nodes are available: 5 Insufficient cpu. preemption: 0/5 nodes are available: 5 No preemption victims found for incoming pod."
I0506 15:59:58.120002      12 preemption.go:264] "No preemption candidate is found; preemption is not helpful for scheduling" pod="default/cspod-67"
I0506 15:59:58.120039      12 schedule_one.go:1044] "Unable to schedule pod; no fit; waiting" pod="default/cspod-67" err="0/5 nodes are available: 5 Insufficient cpu. preemption: 0/5 nodes are available: 5 No preemption victims found for incoming pod."
I0506 15:59:58.140283      12 preemption.go:264] "No preemption candidate is found; preemption is not helpful for scheduling" pod="default/cspod-68"
I0506 15:59:58.140332      12 schedule_one.go:1044] "Unable to schedule pod; no fit; waiting" pod="default/cspod-68" err="0/5 nodes are available: 5 Insufficient cpu. preemption: 0/5 nodes are available: 5 No preemption victims found for incoming pod."
I0506 15:59:58.160767      12 preemption.go:264] "No preemption candidate is found; preemption is not helpful for scheduling" pod="default/cspod-69"
I0506 15:59:58.160814      12 schedule_one.go:1044] "Unable to schedule pod; no fit; waiting" pod="default/cspod-69" err="0/5 nodes are available: 5 Insufficient cpu. preemption: 0/5 nodes are available: 5 No preemption victims found for incoming pod."
I0506 15:59:58.185138      12 preemption.go:264] "No preemption candidate is found; preemption is not helpful for scheduling" pod="default/cspod-54"
I0506 15:59:58.185179      12 schedule_one.go:1044] "Unable to schedule pod; no fit; waiting" pod="default/cspod-54" err="0/5 nodes are available: 5 Insufficient cpu. preemption: 0/5 nodes are available: 5 No preemption victims found for incoming pod."
I0506 15:59:58.199533      12 schedule_one.go:314] "Successfully bound pod to node" pod="default/cspod-53" node="csnode-3" evaluatedNodes=5 feasibleNodes=1
I0506 15:59:58.220492      12 preemption.go:264] "No preemption candidate is found; preemption is not helpful for scheduling" pod="default/cspod-60"
I0506 15:59:58.220535      12 schedule_one.go:1044] "Unable to schedule pod; no fit; waiting" pod="default/cspod-60" err="0/5 nodes are available: 5 Insufficient cpu. preemption: 0/5 nodes are available: 5 No preemption victims found for incoming pod."
I0506 15:59:58.240864      12 preemption.go:264] "No preemption candidate is found; preemption is not helpful for scheduling" pod="default/cspod-61"
I0506 15:59:58.240940      12 schedule_one.go:1044] "Unable to schedule pod; no fit; waiting" pod="default/cspod-61" err="0/5 nodes are available: 5 Insufficient cpu. preemption: 0/5 nodes are available: 5 No preemption victims found for incoming pod."
I0506 15:59:58.260133      12 preemption.go:264] "No preemption candidate is found; preemption is not helpful for scheduling" pod="default/cspod-62"
I0506 15:59:58.260177      12 schedule_one.go:1044] "Unable to schedule pod; no fit; waiting" pod="default/cspod-62" err="0/5 nodes are available: 5 Insufficient cpu. preemption: 0/5 nodes are available: 5 No preemption victims found for incoming pod."
I0506 15:59:58.279925      12 preemption.go:264] "No preemption candidate is found; preemption is not helpful for scheduling" pod="default/cspod-63"
I0506 15:59:58.279970      12 schedule_one.go:1044] "Unable to schedule pod; no fit; waiting" pod="default/cspod-63" err="0/5 nodes are available: 5 Insufficient cpu. preemption: 0/5 nodes are available: 5 No preemption victims found for incoming pod."
I0506 15:59:58.299799      12 preemption.go:264] "No preemption candidate is found; preemption is not helpful for scheduling" pod="default/cspod-64"
I0506 15:59:58.299841      12 schedule_one.go:1044] "Unable to schedule pod; no fit; waiting" pod="default/cspod-64" err="0/5 nodes are available: 5 Insufficient cpu. preemption: 0/5 nodes are available: 5 No preemption victims found for incoming pod."
I0506 15:59:58.320025      12 preemption.go:264] "No preemption candidate is found; preemption is not helpful for scheduling" pod="default/cspod-65"
I0506 15:59:58.320074      12 schedule_one.go:1044] "Unable to schedule pod; no fit; waiting" pod="default/cspod-65" err="0/5 nodes are available: 5 Insufficient cpu. preemption: 0/5 nodes are available: 5 No preemption victims found for incoming pod."
I0506 15:59:58.340281      12 preemption.go:264] "No preemption candidate is found; preemption is not helpful for scheduling" pod="default/cspod-66"
I0506 15:59:58.340328      12 schedule_one.go:1044] "Unable to schedule pod; no fit; waiting" pod="default/cspod-66" err="0/5 nodes are available: 5 Insufficient cpu. preemption: 0/5 nodes are available: 5 No preemption victims found for incoming pod."
I0506 15:59:58.360170      12 preemption.go:264] "No preemption candidate is found; preemption is not helpful for scheduling" pod="default/cspod-67"
I0506 15:59:58.360208      12 schedule_one.go:1044] "Unable to schedule pod; no fit; waiting" pod="default/cspod-67" err="0/5 nodes are available: 5 Insufficient cpu. preemption: 0/5 nodes are available: 5 No preemption victims found for incoming pod."
I0506 15:59:58.380169      12 preemption.go:264] "No preemption candidate is found; preemption is not helpful for scheduling" pod="default/cspod-68"
I0506 15:59:58.380207      12 schedule_one.go:1044] "Unable to schedule pod; no fit; waiting" pod="default/cspod-68" err="0/5 nodes are available: 5 Insufficient cpu. preemption: 0/5 nodes are available: 5 No preemption victims found for incoming pod."
I0506 15:59:58.400439      12 preemption.go:264] "No preemption candidate is found; preemption is not helpful for scheduling" pod="default/cspod-69"
I0506 15:59:58.400481      12 schedule_one.go:1044] "Unable to schedule pod; no fit; waiting" pod="default/cspod-69" err="0/5 nodes are available: 5 Insufficient cpu. preemption: 0/5 nodes are available: 5 No preemption victims found for incoming pod."
I0506 15:59:58.425464      12 preemption.go:264] "No preemption candidate is found; preemption is not helpful for scheduling" pod="default/cspod-64"
I0506 15:59:58.425509      12 schedule_one.go:1044] "Unable to schedule pod; no fit; waiting" pod="default/cspod-64" err="0/5 nodes are available: 5 Insufficient cpu. preemption: 0/5 nodes are available: 5 No preemption victims found for incoming pod."
I0506 15:59:58.439446      12 schedule_one.go:314] "Successfully bound pod to node" pod="default/cspod-54" node="csnode-0" evaluatedNodes=5 feasibleNodes=3
I0506 15:59:58.460155      12 schedule_one.go:314] "Successfully bound pod to node" pod="default/cspod-60" node="csnode-4" evaluatedNodes=5 feasibleNodes=3
I0506 15:59:58.479778      12 schedule_one.go:314] "Successfully bound pod to node" pod="default/cspod-61" node="csnode-0" evaluatedNodes=5 feasibleNodes=3
I0506 15:59:58.499735      12 schedule_one.go:314] "Successfully bound pod to node" pod="default/cspod-62" node="csnode-1" evaluatedNodes=5 feasibleNodes=2
I0506 15:59:58.520322      12 schedule_one.go:314] "Successfully bound pod to node" pod="default/cspod-63" node="csnode-4" evaluatedNodes=5 feasibleNodes=1
I0506 15:59:58.540374      12 preemption.go:264] "No preemption candidate is found; preemption is not helpful for scheduling" pod="default/cspod-65"
I0506 15:59:58.540426      12 schedule_one.go:1044] "Unable to schedule pod; no fit; waiting" pod="default/cspod-65" err="0/5 nodes are available: 5 Insufficient cpu. preemption: 0/5 nodes are available: 5 No preemption victims found for incoming pod."
I0506 15:59:58.560262      12 preemption.go:264] "No preemption candidate is found; preemption is not helpful for scheduling" pod="default/cspod-66"
I0506 15:59:58.560301      12 schedule_one.go:1044] "Unable to schedule pod; no fit; waiting" pod="default/cspod-66" err="0/5 nodes are available: 5 Insufficient cpu. preemption: 0/5 nodes are available: 5 No preemption victims found for incoming pod."
I0506 15:59:58.580462      12 preemption.go:264] "No preemption candidate is found; preemption is not helpful for scheduling" pod="default/cspod-67"
I0506 15:59:58.580507      12 schedule_one.go:1044] "Unable to schedule pod; no fit; waiting" pod="default/cspod-67" err="0/5 nodes are available: 5 Insufficient cpu. preemption: 0/5 nodes are available: 5 No preemption victims found for incoming pod."
I0506 15:59:58.600641      12 preemption.go:264] "No preemption candidate is found; preemption is not helpful for scheduling" pod="default/cspod-68"
I0506 15:59:58.600690      12 schedule_one.go:1044] "Unable to schedule pod; no fit; waiting" pod="default/cspod-68" err="0/5 nodes are available: 5 Insufficient cpu. preemption: 0/5 nodes are available: 5 No preemption victims found for incoming pod."
I0506 15:59:58.619729      12 preemption.go:264] "No preemption candidate is found; preemption is not helpful for scheduling" pod="default/cspod-69"
I0506 15:59:58.619766      12 schedule_one.go:1044] "Unable to schedule pod; no fit; waiting" pod="default/cspod-69" err="0/5 nodes are available: 5 Insufficient cpu. preemption: 0/5 nodes are available: 5 No preemption victims found for incoming pod."
I0506 15:59:58.648223      12 preemption.go:264] "No preemption candidate is found; preemption is not helpful for scheduling" pod="default/cspod-66"
I0506 15:59:58.648263      12 schedule_one.go:1044] "Unable to schedule pod; no fit; waiting" pod="default/cspod-66" err="0/5 nodes are available: 5 Insufficient cpu. preemption: 0/5 nodes are available: 5 No preemption victims found for incoming pod."
I0506 15:59:58.659689      12 schedule_one.go:314] "Successfully bound pod to node" pod="default/cspod-64" node="csnode-2" evaluatedNodes=5 feasibleNodes=1
I0506 15:59:58.680512      12 schedule_one.go:314] "Successfully bound pod to node" pod="default/cspod-65" node="csnode-2" evaluatedNodes=5 feasibleNodes=1
I0506 15:59:58.700273      12 preemption.go:264] "No preemption candidate is found; preemption is not helpful for scheduling" pod="default/cspod-67"
I0506 15:59:58.700313      12 schedule_one.go:1044] "Unable to schedule pod; no fit; waiting" pod="default/cspod-67" err="0/5 nodes are available: 5 Insufficient cpu. preemption: 0/5 nodes are available: 5 No preemption victims found for incoming pod."
I0506 15:59:58.720673      12 preemption.go:264] "No preemption candidate is found; preemption is not helpful for scheduling" pod="default/cspod-68"
I0506 15:59:58.720748      12 schedule_one.go:1044] "Unable to schedule pod; no fit; waiting" pod="default/cspod-68" err="0/5 nodes are available: 5 Insufficient cpu. preemption: 0/5 nodes are available: 5 No preemption victims found for incoming pod."
I0506 15:59:58.739876      12 preemption.go:264] "No preemption candidate is found; preemption is not helpful for scheduling" pod="default/cspod-69"
I0506 15:59:58.739919      12 schedule_one.go:1044] "Unable to schedule pod; no fit; waiting" pod="default/cspod-69" err="0/5 nodes are available: 5 Insufficient cpu. preemption: 0/5 nodes are available: 5 No preemption victims found for incoming pod."
I0506 15:59:58.765716      12 preemption.go:264] "No preemption candidate is found; preemption is not helpful for scheduling" pod="default/cspod-67"
I0506 15:59:58.765761      12 schedule_one.go:1044] "Unable to schedule pod; no fit; waiting" pod="default/cspod-67" err="0/5 nodes are available: 5 Insufficient cpu. preemption: 0/5 nodes are available: 5 No preemption victims found for incoming pod."
I0506 15:59:58.780015      12 schedule_one.go:314] "Successfully bound pod to node" pod="default/cspod-66" node="csnode-3" evaluatedNodes=5 feasibleNodes=1
I0506 15:59:58.800106      12 preemption.go:264] "No preemption candidate is found; preemption is not helpful for scheduling" pod="default/cspod-68"
I0506 15:59:58.800184      12 schedule_one.go:1044] "Unable to schedule pod; no fit; waiting" pod="default/cspod-68" err="0/5 nodes are available: 5 Insufficient cpu. preemption: 0/5 nodes are available: 5 No preemption victims found for incoming pod."
I0506 15:59:58.820372      12 preemption.go:264] "No preemption candidate is found; preemption is not helpful for scheduling" pod="default/cspod-69"
I0506 15:59:58.820410      12 schedule_one.go:1044] "Unable to schedule pod; no fit; waiting" pod="default/cspod-69" err="0/5 nodes are available: 5 Insufficient cpu. preemption: 0/5 nodes are available: 5 No preemption victims found for incoming pod."
I0506 15:59:58.859642      12 schedule_one.go:314] "Successfully bound pod to node" pod="default/cspod-67" node="csnode-1" evaluatedNodes=5 feasibleNodes=3
I0506 15:59:58.880308      12 schedule_one.go:314] "Successfully bound pod to node" pod="default/cspod-68" node="csnode-0" evaluatedNodes=5 feasibleNodes=2
I0506 15:59:58.900010      12 schedule_one.go:314] "Successfully bound pod to node" pod="default/cspod-69" node="csnode-3" evaluatedNodes=5 feasibleNodes=1
I0506 15:59:58.916020      12 node_tree.go:79] "Removed node from NodeTree" node="csnode-0" zone=""
I0506 15:59:58.916061      12 node_tree.go:79] "Removed node from NodeTree" node="csnode-1" zone=""
I0506 15:59:58.916078      12 node_tree.go:79] "Removed node from NodeTree" node="csnode-2" zone=""
I0506 15:59:58.916081      12 node_tree.go:79] "Removed node from NodeTree" node="csnode-3" zone=""
I0506 15:59:58.916116      12 node_tree.go:79] "Removed node from NodeTree" node="csnode-4" zone=""
