2026/05/06 17:00:03 Starting K8s Sim Control Plane with Fake API Server on port :8080
Using scheduler: volcano
2026/05/06 17:00:03 Serving HTTP API on :8080
2026/05/06 17:00:03 Fake Kubernetes API server ready for kube-scheduler connections
2026/05/06 17:00:03 Start kube-scheduler with: --master http://localhost:8080 --leader-elect=false
2026/05/06 17:00:04 Scheduling round reset
2026/05/06 17:00:04 {"action":"HandleReset","result":"ok","roundId":"-","ts":"2026-05-06T17:00:04.845832375+01:00"}
2026/05/06 17:00:05 Volcano queue created: default
2026/05/06 17:00:08 Scheduling round reset
2026/05/06 17:00:08 {"action":"HandleReset","result":"ok","roundId":"-","ts":"2026-05-06T17:00:08.026753611+01:00"}
2026/05/06 17:00:08 Scheduling round reset
2026/05/06 17:00:08 {"action":"HandleReset","result":"ok","roundId":"-","ts":"2026-05-06T17:00:08.030374097+01:00"}
2026/05/06 17:00:12 {"action":"HandleNodes","durationMs":0,"nodeCount":5,"result":"ok","roundId":"0","ts":"2026-05-06T17:00:12.969958233+01:00"}
2026/05/06 17:00:12 {"action":"HandleSchedule","completedIds":0,"nodeCount":5,"phase":"start","podCount":37,"roundId":"1","ts":"2026-05-06T17:00:12.994136469+01:00"}
2026/05/06 17:00:12 {"action":"ensureVolcanoQueue","queue":"high-priority","ts":"2026-05-06T17:00:12.994281499+01:00","weight":3}
2026/05/06 17:00:12 {"action":"ensureVolcanoQueue","queue":"batch","ts":"2026-05-06T17:00:12.994326597+01:00","weight":1}
2026/05/06 17:00:12 podgroup watch encode error: write tcp 127.0.0.1:8080->127.0.0.1:34796: write: broken pipe
2026/05/06 17:00:12 {"action":"HandleSchedule","phase":"prep_done","podsCreated":37,"prepMs":0,"roundId":"1","staleDeleted":0,"ts":"2026-05-06T17:00:12.994683556+01:00"}
2026/05/06 17:00:12 Scheduling round started: expecting 37 decisions
2026/05/06 17:00:13 Binding: pod=cspod-20 -> node=csnode-0 (1/37 resolved)
2026/05/06 17:00:13 Binding: pod=cspod-1 -> node=csnode-3 (2/37 resolved)
2026/05/06 17:00:13 Binding: pod=cspod-14 -> node=csnode-2 (3/37 resolved)
2026/05/06 17:00:13 Binding: pod=cspod-21 -> node=csnode-4 (4/37 resolved)
2026/05/06 17:00:13 Binding: pod=cspod-13 -> node=csnode-1 (5/37 resolved)
2026/05/06 17:00:13 Binding: pod=cspod-12 -> node=csnode-1 (6/37 resolved)
2026/05/06 17:00:13 Binding: pod=cspod-11 -> node=csnode-4 (7/37 resolved)
2026/05/06 17:00:13 Binding: pod=cspod-10 -> node=csnode-3 (8/37 resolved)
2026/05/06 17:00:13 Binding: pod=cspod-0 -> node=csnode-0 (9/37 resolved)
2026/05/06 17:00:13 Binding: pod=cspod-22 -> node=csnode-2 (10/37 resolved)
2026/05/06 17:00:13 Failure: pod=cspod-7 reason="0/5 nodes are unavailable: 5 Insufficient cpu." (11/37 resolved)
2026/05/06 17:00:13 Failure: pod=cspod-30 reason="0/5 nodes are unavailable: 5 Insufficient cpu." (12/37 resolved)
2026/05/06 17:00:13 Failure: pod=cspod-24 reason="pod group is not ready, 1 Pending, 1 minAvailable; Pending: 1 Unschedulable" (13/37 resolved)
2026/05/06 17:00:13 Failure: pod=cspod-15 reason="0/5 nodes are unavailable: 5 Insufficient cpu." (14/37 resolved)
2026/05/06 17:00:13 Failure: pod=cspod-23 reason="pod group is not ready, 1 Pending, 1 minAvailable; Pending: 1 Unschedulable" (15/37 resolved)
2026/05/06 17:00:13 Failure: pod=cspod-35 reason="pod group is not ready, 4 Pending, 4 minAvailable; Pending: 4 Unschedulable" (16/37 resolved)
2026/05/06 17:00:13 Failure: pod=cspod-16 reason="0/5 nodes are unavailable: 5 Insufficient cpu." (17/37 resolved)
2026/05/06 17:00:13 Failure: pod=cspod-25 reason="pod group is not ready, 1 Pending, 1 minAvailable; Pending: 1 Unschedulable" (18/37 resolved)
2026/05/06 17:00:13 Failure: pod=cspod-17 reason="0/5 nodes are unavailable: 5 Insufficient cpu." (19/37 resolved)
2026/05/06 17:00:13 Failure: pod=cspod-27 reason="pod group is not ready, 1 Pending, 1 minAvailable; Pending: 1 Unschedulable" (20/37 resolved)
2026/05/06 17:00:13 Failure: pod=cspod-31 reason="pod group is not ready, 3 Pending, 3 minAvailable; Pending: 3 Unschedulable. Origin reason is cspod-30: 0/5 nodes are unavailable: 5 Insufficient cpu." (21/37 resolved)
2026/05/06 17:00:13 Failure: pod=cspod-29 reason="pod group is not ready, 1 Pending, 1 minAvailable; Pending: 1 Unschedulable" (22/37 resolved)
2026/05/06 17:00:13 Failure: pod=cspod-3 reason="0/5 nodes are unavailable: 5 Insufficient cpu." (23/37 resolved)
2026/05/06 17:00:13 Failure: pod=cspod-28 reason="pod group is not ready, 1 Pending, 1 minAvailable; Pending: 1 Unschedulable" (24/37 resolved)
2026/05/06 17:00:13 Failure: pod=cspod-36 reason="pod group is not ready, 4 Pending, 4 minAvailable; Pending: 4 Unschedulable" (25/37 resolved)
2026/05/06 17:00:13 Failure: pod=cspod-9 reason="0/5 nodes are unavailable: 5 Insufficient cpu." (26/37 resolved)
2026/05/06 17:00:13 Failure: pod=cspod-8 reason="0/5 nodes are unavailable: 5 Insufficient cpu." (27/37 resolved)
2026/05/06 17:00:13 Failure: pod=cspod-18 reason="0/5 nodes are unavailable: 5 Insufficient cpu." (28/37 resolved)
2026/05/06 17:00:13 Failure: pod=cspod-5 reason="0/5 nodes are unavailable: 5 Insufficient cpu." (29/37 resolved)
2026/05/06 17:00:13 Failure: pod=cspod-26 reason="pod group is not ready, 1 Pending, 1 minAvailable; Pending: 1 Unschedulable" (30/37 resolved)
2026/05/06 17:00:13 Failure: pod=cspod-19 reason="0/5 nodes are unavailable: 5 Insufficient cpu." (31/37 resolved)
2026/05/06 17:00:13 Failure: pod=cspod-2 reason="0/5 nodes are unavailable: 5 Insufficient cpu." (32/37 resolved)
2026/05/06 17:00:13 Failure: pod=cspod-6 reason="0/5 nodes are unavailable: 5 Insufficient cpu." (33/37 resolved)
2026/05/06 17:00:13 Failure: pod=cspod-4 reason="0/5 nodes are unavailable: 5 Insufficient cpu." (34/37 resolved)
2026/05/06 17:00:13 Failure: pod=cspod-33 reason="pod group is not ready, 4 Pending, 4 minAvailable; Pending: 4 Unschedulable" (35/37 resolved)
2026/05/06 17:00:13 Failure: pod=cspod-32 reason="pod group is not ready, 3 Pending, 3 minAvailable; Pending: 3 Unschedulable. Origin reason is cspod-30: 0/5 nodes are unavailable: 5 Insufficient cpu." (36/37 resolved)
2026/05/06 17:00:13 Failure: pod=cspod-34 reason="pod group is not ready, 4 Pending, 4 minAvailable; Pending: 4 Unschedulable" (37/37 resolved)
2026/05/06 17:00:13 Round complete: 10 scheduled, 27 failed in 54.618759ms
2026/05/06 17:00:13 {"action":"HandleSchedule","durationMs":55,"podCount":37,"result":"ok","roundId":"1","scheduled":10,"ts":"2026-05-06T17:00:13.049433421+01:00","unschedulable":27}
2026/05/06 17:00:13 {"action":"HandleSchedule","completedIds":0,"nodeCount":5,"phase":"start","podCount":18,"roundId":"2","ts":"2026-05-06T17:00:13.142173202+01:00"}
2026/05/06 17:00:13 {"action":"HandleSchedule","phase":"prep_done","podsCreated":18,"prepMs":0,"roundId":"2","staleDeleted":0,"ts":"2026-05-06T17:00:13.142525983+01:00"}
2026/05/06 17:00:13 Scheduling round started: expecting 18 decisions
2026/05/06 17:00:14 Failure: pod=cspod-47 reason="0/5 nodes are unavailable: 5 Insufficient cpu." (1/18 resolved)
2026/05/06 17:00:14 Failure: pod=cspod-42 reason="0/5 nodes are unavailable: 5 Insufficient cpu." (2/18 resolved)
2026/05/06 17:00:14 Failure: pod=cspod-53 reason="pod group is not ready, 3 Pending, 3 minAvailable; Pending: 3 Unschedulable. Origin reason is cspod-52: 0/5 nodes are unavailable: 5 Insufficient cpu." (3/18 resolved)
2026/05/06 17:00:14 Failure: pod=cspod-41 reason="0/5 nodes are unavailable: 5 Insufficient cpu." (4/18 resolved)
2026/05/06 17:00:14 Failure: pod=cspod-44 reason="0/5 nodes are unavailable: 5 Insufficient cpu." (5/18 resolved)
2026/05/06 17:00:14 Failure: pod=cspod-46 reason="0/5 nodes are unavailable: 5 Insufficient cpu." (6/18 resolved)
2026/05/06 17:00:14 Failure: pod=cspod-39 reason="0/5 nodes are unavailable: 5 Insufficient cpu." (7/18 resolved)
2026/05/06 17:00:14 Failure: pod=cspod-54 reason="pod group is not ready, 3 Pending, 3 minAvailable; Pending: 3 Unschedulable. Origin reason is cspod-52: 0/5 nodes are unavailable: 5 Insufficient cpu." (8/18 resolved)
2026/05/06 17:00:14 Failure: pod=cspod-37 reason="0/5 nodes are unavailable: 5 Insufficient cpu." (9/18 resolved)
2026/05/06 17:00:14 Failure: pod=cspod-50 reason="0/5 nodes are unavailable: 5 Insufficient cpu." (10/18 resolved)
2026/05/06 17:00:14 Failure: pod=cspod-51 reason="0/5 nodes are unavailable: 5 Insufficient cpu." (11/18 resolved)
2026/05/06 17:00:14 Failure: pod=cspod-45 reason="0/5 nodes are unavailable: 5 Insufficient cpu." (12/18 resolved)
2026/05/06 17:00:14 Failure: pod=cspod-43 reason="0/5 nodes are unavailable: 5 Insufficient cpu." (13/18 resolved)
2026/05/06 17:00:14 Failure: pod=cspod-49 reason="0/5 nodes are unavailable: 5 Insufficient cpu." (14/18 resolved)
2026/05/06 17:00:14 Failure: pod=cspod-38 reason="0/5 nodes are unavailable: 5 Insufficient cpu." (15/18 resolved)
2026/05/06 17:00:14 Failure: pod=cspod-40 reason="0/5 nodes are unavailable: 5 Insufficient cpu." (16/18 resolved)
2026/05/06 17:00:14 Failure: pod=cspod-48 reason="0/5 nodes are unavailable: 5 Insufficient cpu." (17/18 resolved)
2026/05/06 17:00:14 Failure: pod=cspod-52 reason="0/5 nodes are unavailable: 5 Insufficient cpu." (18/18 resolved)
2026/05/06 17:00:14 Round complete: 0 scheduled, 18 failed in 916.907849ms
2026/05/06 17:00:14 {"action":"HandleSchedule","durationMs":917,"podCount":18,"result":"ok","roundId":"2","scheduled":0,"ts":"2026-05-06T17:00:14.059522735+01:00","unschedulable":18}
2026/05/06 17:00:14 {"action":"HandleSchedule","completedIds":0,"nodeCount":5,"phase":"start","podCount":15,"roundId":"3","ts":"2026-05-06T17:00:14.078065158+01:00"}
2026/05/06 17:00:14 {"action":"HandleSchedule","phase":"prep_done","podsCreated":15,"prepMs":0,"roundId":"3","staleDeleted":0,"ts":"2026-05-06T17:00:14.078389415+01:00"}
2026/05/06 17:00:14 Scheduling round started: expecting 15 decisions
2026/05/06 17:00:15 Failure: pod=cspod-65 reason="pod group is not ready, 1 Pending, 1 minAvailable; Pending: 1 Unschedulable" (1/15 resolved)
2026/05/06 17:00:15 Failure: pod=cspod-67 reason="pod group is not ready, 1 Pending, 1 minAvailable; Pending: 1 Unschedulable" (2/15 resolved)
2026/05/06 17:00:15 Failure: pod=cspod-8 reason="pod group is not ready, 1 Pending, 1 minAvailable; Pending: 1 Unschedulable" (3/15 resolved)
2026/05/06 17:00:15 Failure: pod=cspod-30 reason="pod group is not ready, 3 Pending, 3 minAvailable; Pending: 3 Unschedulable" (4/15 resolved)
2026/05/06 17:00:15 Failure: pod=cspod-9 reason="pod group is not ready, 1 Pending, 1 minAvailable; Pending: 1 Unschedulable" (5/15 resolved)
2026/05/06 17:00:15 Failure: pod=cspod-69 reason="pod group is not ready, 1 Pending, 1 minAvailable; Pending: 1 Unschedulable" (6/15 resolved)
2026/05/06 17:00:15 Failure: pod=cspod-60 reason="pod group is not ready, 1 Pending, 1 minAvailable; Pending: 1 Unschedulable" (7/15 resolved)
2026/05/06 17:00:15 Failure: pod=cspod-59 reason="pod group is not ready, 1 Pending, 1 minAvailable; Pending: 1 Unschedulable" (8/15 resolved)
2026/05/06 17:00:15 Failure: pod=cspod-6 reason="pod group is not ready, 1 Pending, 1 minAvailable; Pending: 1 Unschedulable" (9/15 resolved)
2026/05/06 17:00:15 Failure: pod=cspod-7 reason="pod group is not ready, 1 Pending, 1 minAvailable; Pending: 1 Unschedulable" (10/15 resolved)
2026/05/06 17:00:15 Failure: pod=cspod-64 reason="pod group is not ready, 1 Pending, 1 minAvailable; Pending: 1 Unschedulable" (11/15 resolved)
2026/05/06 17:00:15 Failure: pod=cspod-52 reason="pod group is not ready, 3 Pending, 3 minAvailable; Pending: 3 Unschedulable" (12/15 resolved)
2026/05/06 17:00:15 Failure: pod=cspod-61 reason="pod group is not ready, 1 Pending, 1 minAvailable; Pending: 1 Unschedulable" (13/15 resolved)
2026/05/06 17:00:15 Failure: pod=cspod-68 reason="pod group is not ready, 1 Pending, 1 minAvailable; Pending: 1 Unschedulable" (14/15 resolved)
2026/05/06 17:00:15 Failure: pod=cspod-31 reason="pod group is not ready, 3 Pending, 3 minAvailable; Pending: 3 Unschedulable" (15/15 resolved)
2026/05/06 17:00:15 Round complete: 0 scheduled, 15 failed in 987.900263ms
2026/05/06 17:00:15 {"action":"HandleSchedule","durationMs":988,"podCount":15,"result":"ok","roundId":"3","scheduled":0,"ts":"2026-05-06T17:00:15.066349453+01:00","unschedulable":15}
2026/05/06 17:00:15 WARNING: Late binding (round inactive): pod=cspod-55 -> node=csnode-2 — scheduler bound a pod after the round closed
2026/05/06 17:00:15 WARNING: Late binding (round inactive): pod=cspod-58 -> node=csnode-3 — scheduler bound a pod after the round closed
2026/05/06 17:00:15 WARNING: Late binding (round inactive): pod=cspod-56 -> node=csnode-0 — scheduler bound a pod after the round closed
2026/05/06 17:00:15 WARNING: Late binding (round inactive): pod=cspod-57 -> node=csnode-1 — scheduler bound a pod after the round closed
2026/05/06 17:00:15 {"action":"HandleSchedule","completedIds":7,"nodeCount":5,"phase":"start","podCount":60,"roundId":"4","ts":"2026-05-06T17:00:15.079295797+01:00"}
2026/05/06 17:00:15 {"action":"HandleSchedule","count":4,"phase":"late_bindings","roundId":"4","ts":"2026-05-06T17:00:15.079479849+01:00","warning":"scheduler bound pods after previous round closed — these will be merged into this round's decision"}
2026/05/06 17:00:15 {"action":"HandleSchedule","phase":"prep_done","podsCreated":56,"prepMs":1,"roundId":"4","staleDeleted":0,"ts":"2026-05-06T17:00:15.080215132+01:00"}
2026/05/06 17:00:15 Scheduling round started: expecting 56 decisions
2026/05/06 17:00:16 Failure: pod=cspod-59 reason="pod group is not ready, 1 Pending, 1 minAvailable; Pending: 1 Unschedulable" (1/56 resolved)
2026/05/06 17:00:16 Failure: pod=cspod-52 reason="pod group is not ready, 3 Pending, 3 minAvailable; Pending: 3 Unschedulable" (2/56 resolved)
2026/05/06 17:00:16 Failure: pod=cspod-28 reason="pod group is not ready, 1 Pending, 1 minAvailable; Pending: 1 Unschedulable" (3/56 resolved)
2026/05/06 17:00:16 Failure: pod=cspod-23 reason="pod group is not ready, 1 Pending, 1 minAvailable; Pending: 1 Unschedulable" (4/56 resolved)
2026/05/06 17:00:16 Failure: pod=cspod-33 reason="pod group is not ready, 4 Pending, 4 minAvailable; Pending: 4 Unschedulable" (5/56 resolved)
2026/05/06 17:00:16 Binding: pod=cspod-18 -> node=csnode-1 (6/56 resolved)
2026/05/06 17:00:16 Binding: pod=cspod-2 -> node=csnode-3 (7/56 resolved)
2026/05/06 17:00:16 Binding: pod=cspod-3 -> node=csnode-3 (8/56 resolved)
2026/05/06 17:00:16 Failure: pod=cspod-49 reason="pod group is not ready, 1 Pending, 1 minAvailable; Pending: 1 Unschedulable" (9/56 resolved)
2026/05/06 17:00:16 Failure: pod=cspod-50 reason="pod group is not ready, 1 Pending, 1 minAvailable; Pending: 1 Unschedulable" (10/56 resolved)
2026/05/06 17:00:16 Binding: pod=cspod-17 -> node=csnode-4 (11/56 resolved)
2026/05/06 17:00:16 Binding: pod=cspod-15 -> node=csnode-0 (12/56 resolved)
2026/05/06 17:00:16 Binding: pod=cspod-19 -> node=csnode-1 (13/56 resolved)
2026/05/06 17:00:16 Binding: pod=cspod-16 -> node=csnode-2 (14/56 resolved)
2026/05/06 17:00:16 Failure: pod=cspod-9 reason="pod group is not ready, 1 Pending, 1 minAvailable; Pending: 1 Unschedulable" (15/56 resolved)
2026/05/06 17:00:16 Failure: pod=cspod-47 reason="pod group is not ready, 1 Pending, 1 minAvailable; Pending: 1 Unschedulable" (16/56 resolved)
2026/05/06 17:00:16 Failure: pod=cspod-53 reason="pod group is not ready, 3 Pending, 3 minAvailable; Pending: 3 Unschedulable" (17/56 resolved)
2026/05/06 17:00:16 Failure: pod=cspod-24 reason="pod group is not ready, 1 Pending, 1 minAvailable; Pending: 1 Unschedulable" (18/56 resolved)
2026/05/06 17:00:16 Failure: pod=cspod-42 reason="pod group is not ready, 1 Pending, 1 minAvailable; Pending: 1 Unschedulable" (19/56 resolved)
2026/05/06 17:00:16 Failure: pod=cspod-25 reason="pod group is not ready, 1 Pending, 1 minAvailable; Pending: 1 Unschedulable" (20/56 resolved)
2026/05/06 17:00:16 Failure: pod=cspod-7 reason="pod group is not ready, 1 Pending, 1 minAvailable; Pending: 1 Unschedulable" (21/56 resolved)
2026/05/06 17:00:16 Failure: pod=cspod-26 reason="pod group is not ready, 1 Pending, 1 minAvailable; Pending: 1 Unschedulable" (22/56 resolved)
2026/05/06 17:00:16 Failure: pod=cspod-37 reason="pod group is not ready, 1 Pending, 1 minAvailable; Pending: 1 Unschedulable" (23/56 resolved)
2026/05/06 17:00:16 Failure: pod=cspod-68 reason="pod group is not ready, 1 Pending, 1 minAvailable; Pending: 1 Unschedulable" (24/56 resolved)
2026/05/06 17:00:16 Failure: pod=cspod-4 reason="pod group is not ready, 1 Pending, 1 minAvailable; Pending: 1 Unschedulable" (25/56 resolved)
2026/05/06 17:00:16 Failure: pod=cspod-6 reason="pod group is not ready, 1 Pending, 1 minAvailable; Pending: 1 Unschedulable" (26/56 resolved)
2026/05/06 17:00:16 Failure: pod=cspod-54 reason="pod group is not ready, 3 Pending, 3 minAvailable; Pending: 3 Unschedulable" (27/56 resolved)
2026/05/06 17:00:16 Failure: pod=cspod-62 reason="pod group is not ready, 1 Pending, 1 minAvailable; Pending: 1 Unschedulable" (28/56 resolved)
2026/05/06 17:00:16 Failure: pod=cspod-34 reason="pod group is not ready, 4 Pending, 4 minAvailable; Pending: 4 Unschedulable" (29/56 resolved)
2026/05/06 17:00:16 Failure: pod=cspod-69 reason="pod group is not ready, 1 Pending, 1 minAvailable; Pending: 1 Unschedulable" (30/56 resolved)
2026/05/06 17:00:16 Failure: pod=cspod-44 reason="pod group is not ready, 1 Pending, 1 minAvailable; Pending: 1 Unschedulable" (31/56 resolved)
2026/05/06 17:00:16 Failure: pod=cspod-65 reason="pod group is not ready, 1 Pending, 1 minAvailable; Pending: 1 Unschedulable" (32/56 resolved)
2026/05/06 17:00:16 Failure: pod=cspod-46 reason="pod group is not ready, 1 Pending, 1 minAvailable; Pending: 1 Unschedulable" (33/56 resolved)
2026/05/06 17:00:16 Failure: pod=cspod-27 reason="pod group is not ready, 1 Pending, 1 minAvailable; Pending: 1 Unschedulable" (34/56 resolved)
2026/05/06 17:00:16 Failure: pod=cspod-39 reason="pod group is not ready, 1 Pending, 1 minAvailable; Pending: 1 Unschedulable" (35/56 resolved)
2026/05/06 17:00:16 Failure: pod=cspod-8 reason="pod group is not ready, 1 Pending, 1 minAvailable; Pending: 1 Unschedulable" (36/56 resolved)
2026/05/06 17:00:16 Failure: pod=cspod-60 reason="pod group is not ready, 1 Pending, 1 minAvailable; Pending: 1 Unschedulable" (37/56 resolved)
2026/05/06 17:00:16 Failure: pod=cspod-41 reason="pod group is not ready, 1 Pending, 1 minAvailable; Pending: 1 Unschedulable" (38/56 resolved)
2026/05/06 17:00:16 Failure: pod=cspod-48 reason="pod group is not ready, 1 Pending, 1 minAvailable; Pending: 1 Unschedulable" (39/56 resolved)
2026/05/06 17:00:16 Failure: pod=cspod-35 reason="pod group is not ready, 4 Pending, 4 minAvailable; Pending: 4 Unschedulable" (40/56 resolved)
2026/05/06 17:00:16 Failure: pod=cspod-45 reason="pod group is not ready, 1 Pending, 1 minAvailable; Pending: 1 Unschedulable" (41/56 resolved)
2026/05/06 17:00:16 Failure: pod=cspod-36 reason="pod group is not ready, 4 Pending, 4 minAvailable; Pending: 4 Unschedulable" (42/56 resolved)
2026/05/06 17:00:16 Failure: pod=cspod-51 reason="pod group is not ready, 1 Pending, 1 minAvailable; Pending: 1 Unschedulable" (43/56 resolved)
2026/05/06 17:00:16 Failure: pod=cspod-66 reason="pod group is not ready, 1 Pending, 1 minAvailable; Pending: 1 Unschedulable" (44/56 resolved)
2026/05/06 17:00:16 Failure: pod=cspod-5 reason="pod group is not ready, 1 Pending, 1 minAvailable; Pending: 1 Unschedulable" (45/56 resolved)
2026/05/06 17:00:16 Failure: pod=cspod-43 reason="pod group is not ready, 1 Pending, 1 minAvailable; Pending: 1 Unschedulable" (46/56 resolved)
2026/05/06 17:00:16 Failure: pod=cspod-40 reason="pod group is not ready, 1 Pending, 1 minAvailable; Pending: 1 Unschedulable" (47/56 resolved)
2026/05/06 17:00:16 Failure: pod=cspod-30 reason="pod group is not ready, 3 Pending, 3 minAvailable; Pending: 3 Unschedulable" (48/56 resolved)
2026/05/06 17:00:16 Failure: pod=cspod-61 reason="pod group is not ready, 1 Pending, 1 minAvailable; Pending: 1 Unschedulable" (49/56 resolved)
2026/05/06 17:00:16 Failure: pod=cspod-63 reason="pod group is not ready, 1 Pending, 1 minAvailable; Pending: 1 Unschedulable" (50/56 resolved)
2026/05/06 17:00:16 Failure: pod=cspod-64 reason="pod group is not ready, 1 Pending, 1 minAvailable; Pending: 1 Unschedulable" (51/56 resolved)
2026/05/06 17:00:16 Failure: pod=cspod-67 reason="pod group is not ready, 1 Pending, 1 minAvailable; Pending: 1 Unschedulable" (52/56 resolved)
2026/05/06 17:00:16 Failure: pod=cspod-29 reason="pod group is not ready, 1 Pending, 1 minAvailable; Pending: 1 Unschedulable" (53/56 resolved)
2026/05/06 17:00:16 Failure: pod=cspod-38 reason="pod group is not ready, 1 Pending, 1 minAvailable; Pending: 1 Unschedulable" (54/56 resolved)
2026/05/06 17:00:16 Failure: pod=cspod-31 reason="pod group is not ready, 3 Pending, 3 minAvailable; Pending: 3 Unschedulable" (55/56 resolved)
2026/05/06 17:00:16 Failure: pod=cspod-32 reason="pod group is not ready, 3 Pending, 3 minAvailable; Pending: 3 Unschedulable" (56/56 resolved)
2026/05/06 17:00:16 Round complete: 7 scheduled, 49 failed in 1.000583593s
2026/05/06 17:00:16 {"action":"HandleSchedule","durationMs":1001,"podCount":56,"result":"ok","roundId":"4","scheduled":11,"ts":"2026-05-06T17:00:16.080897412+01:00","unschedulable":49}
2026/05/06 17:00:16 {"action":"HandleSchedule","completedIds":4,"nodeCount":5,"phase":"start","podCount":49,"roundId":"5","ts":"2026-05-06T17:00:16.101184641+01:00"}
2026/05/06 17:00:16 {"action":"HandleSchedule","phase":"prep_done","podsCreated":49,"prepMs":0,"roundId":"5","staleDeleted":0,"ts":"2026-05-06T17:00:16.101850292+01:00"}
2026/05/06 17:00:16 Scheduling round started: expecting 49 decisions
2026/05/06 17:00:17 Failure: pod=cspod-25 reason="pod group is not ready, 1 Pending, 1 minAvailable; Pending: 1 Unschedulable" (1/49 resolved)
2026/05/06 17:00:17 Failure: pod=cspod-54 reason="pod group is not ready, 3 Pending, 3 minAvailable; Pending: 3 Unschedulable. Origin reason is cspod-52: 0/5 nodes are unavailable: 5 Insufficient cpu." (2/49 resolved)
2026/05/06 17:00:17 Failure: pod=cspod-51 reason="0/5 nodes are unavailable: 5 Insufficient cpu." (3/49 resolved)
2026/05/06 17:00:17 Failure: pod=cspod-60 reason="pod group is not ready, 1 Pending, 1 minAvailable; Pending: 1 Unschedulable" (4/49 resolved)
2026/05/06 17:00:17 Failure: pod=cspod-63 reason="pod group is not ready, 1 Pending, 1 minAvailable; Pending: 1 Unschedulable" (5/49 resolved)
2026/05/06 17:00:17 Failure: pod=cspod-33 reason="pod group is not ready, 4 Pending, 4 minAvailable; Pending: 4 Unschedulable" (6/49 resolved)
2026/05/06 17:00:17 Failure: pod=cspod-23 reason="pod group is not ready, 1 Pending, 1 minAvailable; Pending: 1 Unschedulable" (7/49 resolved)
2026/05/06 17:00:17 Failure: pod=cspod-4 reason="0/5 nodes are unavailable: 5 Insufficient cpu." (8/49 resolved)
2026/05/06 17:00:17 Failure: pod=cspod-52 reason="0/5 nodes are unavailable: 5 Insufficient cpu." (9/49 resolved)
2026/05/06 17:00:17 Failure: pod=cspod-38 reason="0/5 nodes are unavailable: 5 Insufficient cpu." (10/49 resolved)
2026/05/06 17:00:17 Failure: pod=cspod-64 reason="pod group is not ready, 1 Pending, 1 minAvailable; Pending: 1 Unschedulable" (11/49 resolved)
2026/05/06 17:00:17 Binding: pod=cspod-59 -> node=csnode-0 (12/49 resolved)
2026/05/06 17:00:17 Failure: pod=cspod-50 reason="0/5 nodes are unavailable: 5 Insufficient cpu." (13/49 resolved)
2026/05/06 17:00:17 Failure: pod=cspod-53 reason="pod group is not ready, 3 Pending, 3 minAvailable; Pending: 3 Unschedulable. Origin reason is cspod-52: 0/5 nodes are unavailable: 5 Insufficient cpu." (14/49 resolved)
2026/05/06 17:00:17 Failure: pod=cspod-9 reason="0/5 nodes are unavailable: 5 Insufficient cpu." (15/49 resolved)
2026/05/06 17:00:17 Failure: pod=cspod-62 reason="pod group is not ready, 1 Pending, 1 minAvailable; Pending: 1 Unschedulable" (16/49 resolved)
2026/05/06 17:00:17 Failure: pod=cspod-46 reason="0/5 nodes are unavailable: 5 Insufficient cpu." (17/49 resolved)
2026/05/06 17:00:17 Failure: pod=cspod-66 reason="pod group is not ready, 1 Pending, 1 minAvailable; Pending: 1 Unschedulable" (18/49 resolved)
2026/05/06 17:00:17 Failure: pod=cspod-34 reason="pod group is not ready, 4 Pending, 4 minAvailable; Pending: 4 Unschedulable" (19/49 resolved)
2026/05/06 17:00:17 Failure: pod=cspod-42 reason="0/5 nodes are unavailable: 5 Insufficient cpu." (20/49 resolved)
2026/05/06 17:00:17 Failure: pod=cspod-35 reason="pod group is not ready, 4 Pending, 4 minAvailable; Pending: 4 Unschedulable" (21/49 resolved)
2026/05/06 17:00:17 Failure: pod=cspod-43 reason="0/5 nodes are unavailable: 5 Insufficient cpu." (22/49 resolved)
2026/05/06 17:00:17 Failure: pod=cspod-7 reason="0/5 nodes are unavailable: 5 Insufficient cpu." (23/49 resolved)
2026/05/06 17:00:17 Failure: pod=cspod-27 reason="pod group is not ready, 1 Pending, 1 minAvailable; Pending: 1 Unschedulable" (24/49 resolved)
2026/05/06 17:00:17 Failure: pod=cspod-40 reason="0/5 nodes are unavailable: 5 Insufficient cpu." (25/49 resolved)
2026/05/06 17:00:17 Failure: pod=cspod-44 reason="0/5 nodes are unavailable: 5 Insufficient cpu." (26/49 resolved)
2026/05/06 17:00:17 Failure: pod=cspod-26 reason="pod group is not ready, 1 Pending, 1 minAvailable; Pending: 1 Unschedulable" (27/49 resolved)
2026/05/06 17:00:17 Failure: pod=cspod-8 reason="0/5 nodes are unavailable: 5 Insufficient cpu." (28/49 resolved)
2026/05/06 17:00:17 Failure: pod=cspod-47 reason="0/5 nodes are unavailable: 5 Insufficient cpu." (29/49 resolved)
2026/05/06 17:00:17 Failure: pod=cspod-36 reason="pod group is not ready, 4 Pending, 4 minAvailable; Pending: 4 Unschedulable" (30/49 resolved)
2026/05/06 17:00:17 Failure: pod=cspod-48 reason="0/5 nodes are unavailable: 5 Insufficient cpu." (31/49 resolved)
2026/05/06 17:00:17 Failure: pod=cspod-28 reason="pod group is not ready, 1 Pending, 1 minAvailable; Pending: 1 Unschedulable" (32/49 resolved)
2026/05/06 17:00:17 Failure: pod=cspod-5 reason="0/5 nodes are unavailable: 5 Insufficient cpu." (33/49 resolved)
2026/05/06 17:00:17 Failure: pod=cspod-29 reason="pod group is not ready, 1 Pending, 1 minAvailable; Pending: 1 Unschedulable" (34/49 resolved)
2026/05/06 17:00:17 Failure: pod=cspod-24 reason="pod group is not ready, 1 Pending, 1 minAvailable; Pending: 1 Unschedulable" (35/49 resolved)
2026/05/06 17:00:17 Failure: pod=cspod-61 reason="pod group is not ready, 1 Pending, 1 minAvailable; Pending: 1 Unschedulable" (36/49 resolved)
2026/05/06 17:00:17 Failure: pod=cspod-41 reason="0/5 nodes are unavailable: 5 Insufficient cpu." (37/49 resolved)
2026/05/06 17:00:17 Failure: pod=cspod-30 reason="0/5 nodes are unavailable: 5 Insufficient cpu." (38/49 resolved)
2026/05/06 17:00:17 Failure: pod=cspod-45 reason="0/5 nodes are unavailable: 5 Insufficient cpu." (39/49 resolved)
2026/05/06 17:00:17 Failure: pod=cspod-67 reason="pod group is not ready, 1 Pending, 1 minAvailable; Pending: 1 Unschedulable" (40/49 resolved)
2026/05/06 17:00:17 Failure: pod=cspod-37 reason="0/5 nodes are unavailable: 5 Insufficient cpu." (41/49 resolved)
2026/05/06 17:00:17 Failure: pod=cspod-69 reason="pod group is not ready, 1 Pending, 1 minAvailable; Pending: 1 Unschedulable" (42/49 resolved)
2026/05/06 17:00:17 Failure: pod=cspod-39 reason="0/5 nodes are unavailable: 5 Insufficient cpu." (43/49 resolved)
2026/05/06 17:00:17 Failure: pod=cspod-31 reason="pod group is not ready, 3 Pending, 3 minAvailable; Pending: 3 Unschedulable. Origin reason is cspod-30: 0/5 nodes are unavailable: 5 Insufficient cpu." (44/49 resolved)
2026/05/06 17:00:17 Failure: pod=cspod-6 reason="0/5 nodes are unavailable: 5 Insufficient cpu." (45/49 resolved)
2026/05/06 17:00:17 Failure: pod=cspod-65 reason="pod group is not ready, 1 Pending, 1 minAvailable; Pending: 1 Unschedulable" (46/49 resolved)
2026/05/06 17:00:17 Failure: pod=cspod-49 reason="0/5 nodes are unavailable: 5 Insufficient cpu." (47/49 resolved)
2026/05/06 17:00:17 Failure: pod=cspod-32 reason="pod group is not ready, 3 Pending, 3 minAvailable; Pending: 3 Unschedulable. Origin reason is cspod-30: 0/5 nodes are unavailable: 5 Insufficient cpu." (48/49 resolved)
2026/05/06 17:00:17 Failure: pod=cspod-68 reason="pod group is not ready, 1 Pending, 1 minAvailable; Pending: 1 Unschedulable" (49/49 resolved)
2026/05/06 17:00:17 Round complete: 1 scheduled, 48 failed in 989.554648ms
2026/05/06 17:00:17 {"action":"HandleSchedule","durationMs":990,"podCount":49,"result":"ok","roundId":"5","scheduled":1,"ts":"2026-05-06T17:00:17.091495572+01:00","unschedulable":48}
2026/05/06 17:00:17 {"action":"HandleSchedule","completedIds":3,"nodeCount":5,"phase":"start","podCount":48,"roundId":"6","ts":"2026-05-06T17:00:17.10485028+01:00"}
2026/05/06 17:00:17 {"action":"HandleSchedule","phase":"prep_done","podsCreated":48,"prepMs":0,"roundId":"6","staleDeleted":0,"ts":"2026-05-06T17:00:17.105542367+01:00"}
2026/05/06 17:00:17 Scheduling round started: expecting 48 decisions
2026/05/06 17:00:18 Failure: pod=cspod-34 reason="pod group is not ready, 4 Pending, 4 minAvailable; Pending: 4 Unschedulable" (1/48 resolved)
2026/05/06 17:00:18 Failure: pod=cspod-63 reason="pod group is not ready, 1 Pending, 1 minAvailable; Pending: 1 Unschedulable" (2/48 resolved)
2026/05/06 17:00:18 Failure: pod=cspod-64 reason="pod group is not ready, 1 Pending, 1 minAvailable; Pending: 1 Unschedulable" (3/48 resolved)
2026/05/06 17:00:18 Failure: pod=cspod-29 reason="pod group is not ready, 1 Pending, 1 minAvailable; Pending: 1 Unschedulable" (4/48 resolved)
2026/05/06 17:00:18 Failure: pod=cspod-43 reason="0/5 nodes are unavailable: 5 Insufficient cpu." (5/48 resolved)
2026/05/06 17:00:18 Failure: pod=cspod-38 reason="0/5 nodes are unavailable: 5 Insufficient cpu." (6/48 resolved)
2026/05/06 17:00:18 Failure: pod=cspod-7 reason="0/5 nodes are unavailable: 5 Insufficient cpu." (7/48 resolved)
2026/05/06 17:00:18 Failure: pod=cspod-66 reason="pod group is not ready, 1 Pending, 1 minAvailable; Pending: 1 Unschedulable" (8/48 resolved)
2026/05/06 17:00:18 Failure: pod=cspod-48 reason="0/5 nodes are unavailable: 5 Insufficient cpu." (9/48 resolved)
2026/05/06 17:00:18 Failure: pod=cspod-35 reason="pod group is not ready, 4 Pending, 4 minAvailable; Pending: 4 Unschedulable" (10/48 resolved)
2026/05/06 17:00:18 Failure: pod=cspod-46 reason="0/5 nodes are unavailable: 5 Insufficient cpu." (11/48 resolved)
2026/05/06 17:00:18 Failure: pod=cspod-8 reason="0/5 nodes are unavailable: 5 Insufficient cpu." (12/48 resolved)
2026/05/06 17:00:18 Failure: pod=cspod-44 reason="0/5 nodes are unavailable: 5 Insufficient cpu." (13/48 resolved)
2026/05/06 17:00:18 Failure: pod=cspod-9 reason="0/5 nodes are unavailable: 5 Insufficient cpu." (14/48 resolved)
2026/05/06 17:00:18 Failure: pod=cspod-39 reason="0/5 nodes are unavailable: 5 Insufficient cpu." (15/48 resolved)
2026/05/06 17:00:18 Failure: pod=cspod-41 reason="0/5 nodes are unavailable: 5 Insufficient cpu." (16/48 resolved)
2026/05/06 17:00:18 Failure: pod=cspod-37 reason="0/5 nodes are unavailable: 5 Insufficient cpu." (17/48 resolved)
2026/05/06 17:00:18 Failure: pod=cspod-28 reason="pod group is not ready, 1 Pending, 1 minAvailable; Pending: 1 Unschedulable" (18/48 resolved)
2026/05/06 17:00:18 Failure: pod=cspod-60 reason="pod group is not ready, 1 Pending, 1 minAvailable; Pending: 1 Unschedulable" (19/48 resolved)
2026/05/06 17:00:18 Failure: pod=cspod-6 reason="0/5 nodes are unavailable: 5 Insufficient cpu." (20/48 resolved)
2026/05/06 17:00:18 Failure: pod=cspod-5 reason="0/5 nodes are unavailable: 5 Insufficient cpu." (21/48 resolved)
2026/05/06 17:00:18 Failure: pod=cspod-51 reason="0/5 nodes are unavailable: 5 Insufficient cpu." (22/48 resolved)
2026/05/06 17:00:18 Binding: pod=cspod-24 -> node=csnode-4 (23/48 resolved)
2026/05/06 17:00:18 Failure: pod=cspod-36 reason="pod group is not ready, 4 Pending, 4 minAvailable; Pending: 4 Unschedulable" (24/48 resolved)
2026/05/06 17:00:18 Binding: pod=cspod-23 -> node=csnode-0 (25/48 resolved)
2026/05/06 17:00:18 Binding: pod=cspod-25 -> node=csnode-2 (26/48 resolved)
2026/05/06 17:00:18 Failure: pod=cspod-42 reason="0/5 nodes are unavailable: 5 Insufficient cpu." (27/48 resolved)
2026/05/06 17:00:18 Failure: pod=cspod-69 reason="pod group is not ready, 1 Pending, 1 minAvailable; Pending: 1 Unschedulable" (28/48 resolved)
2026/05/06 17:00:18 Failure: pod=cspod-49 reason="0/5 nodes are unavailable: 5 Insufficient cpu." (29/48 resolved)
2026/05/06 17:00:18 Failure: pod=cspod-45 reason="0/5 nodes are unavailable: 5 Insufficient cpu." (30/48 resolved)
2026/05/06 17:00:18 Failure: pod=cspod-33 reason="pod group is not ready, 4 Pending, 4 minAvailable; Pending: 4 Unschedulable" (31/48 resolved)
2026/05/06 17:00:18 Failure: pod=cspod-52 reason="0/5 nodes are unavailable: 5 Insufficient cpu." (32/48 resolved)
2026/05/06 17:00:18 Failure: pod=cspod-47 reason="0/5 nodes are unavailable: 5 Insufficient cpu." (33/48 resolved)
2026/05/06 17:00:18 Failure: pod=cspod-67 reason="pod group is not ready, 1 Pending, 1 minAvailable; Pending: 1 Unschedulable" (34/48 resolved)
2026/05/06 17:00:18 Failure: pod=cspod-26 reason="pod group is not ready, 1 Pending, 1 minAvailable; Pending: 1 Unschedulable" (35/48 resolved)
2026/05/06 17:00:18 Failure: pod=cspod-32 reason="pod group is not ready, 3 Pending, 3 minAvailable; Pending: 3 Unschedulable. Origin reason is cspod-30: 0/5 nodes are unavailable: 5 Insufficient cpu." (36/48 resolved)
2026/05/06 17:00:18 Failure: pod=cspod-62 reason="pod group is not ready, 1 Pending, 1 minAvailable; Pending: 1 Unschedulable" (37/48 resolved)
2026/05/06 17:00:18 Failure: pod=cspod-4 reason="0/5 nodes are unavailable: 5 Insufficient cpu." (38/48 resolved)
2026/05/06 17:00:18 Failure: pod=cspod-68 reason="pod group is not ready, 1 Pending, 1 minAvailable; Pending: 1 Unschedulable" (39/48 resolved)
2026/05/06 17:00:18 Failure: pod=cspod-40 reason="0/5 nodes are unavailable: 5 Insufficient cpu." (40/48 resolved)
2026/05/06 17:00:18 Failure: pod=cspod-27 reason="pod group is not ready, 1 Pending, 1 minAvailable; Pending: 1 Unschedulable" (41/48 resolved)
2026/05/06 17:00:18 Failure: pod=cspod-50 reason="0/5 nodes are unavailable: 5 Insufficient cpu." (42/48 resolved)
2026/05/06 17:00:18 Failure: pod=cspod-61 reason="pod group is not ready, 1 Pending, 1 minAvailable; Pending: 1 Unschedulable" (43/48 resolved)
2026/05/06 17:00:18 Failure: pod=cspod-30 reason="0/5 nodes are unavailable: 5 Insufficient cpu." (44/48 resolved)
2026/05/06 17:00:18 Failure: pod=cspod-53 reason="pod group is not ready, 3 Pending, 3 minAvailable; Pending: 3 Unschedulable. Origin reason is cspod-52: 0/5 nodes are unavailable: 5 Insufficient cpu." (45/48 resolved)
2026/05/06 17:00:18 Failure: pod=cspod-65 reason="pod group is not ready, 1 Pending, 1 minAvailable; Pending: 1 Unschedulable" (46/48 resolved)
2026/05/06 17:00:18 Failure: pod=cspod-31 reason="pod group is not ready, 3 Pending, 3 minAvailable; Pending: 3 Unschedulable. Origin reason is cspod-30: 0/5 nodes are unavailable: 5 Insufficient cpu." (47/48 resolved)
2026/05/06 17:00:18 Failure: pod=cspod-54 reason="pod group is not ready, 3 Pending, 3 minAvailable; Pending: 3 Unschedulable. Origin reason is cspod-52: 0/5 nodes are unavailable: 5 Insufficient cpu." (48/48 resolved)
2026/05/06 17:00:18 Round complete: 3 scheduled, 45 failed in 997.699921ms
2026/05/06 17:00:18 {"action":"HandleSchedule","durationMs":998,"podCount":48,"result":"ok","roundId":"6","scheduled":3,"ts":"2026-05-06T17:00:18.103358298+01:00","unschedulable":45}
2026/05/06 17:00:18 {"action":"HandleSchedule","completedIds":1,"nodeCount":5,"phase":"start","podCount":45,"roundId":"7","ts":"2026-05-06T17:00:18.110991949+01:00"}
2026/05/06 17:00:18 {"action":"HandleSchedule","phase":"prep_done","podsCreated":45,"prepMs":0,"roundId":"7","staleDeleted":0,"ts":"2026-05-06T17:00:18.111506027+01:00"}
2026/05/06 17:00:18 Scheduling round started: expecting 45 decisions
2026/05/06 17:00:19 Failure: pod=cspod-42 reason="0/5 nodes are unavailable: 5 Insufficient cpu." (1/45 resolved)
2026/05/06 17:00:19 Failure: pod=cspod-9 reason="0/5 nodes are unavailable: 5 Insufficient cpu." (2/45 resolved)
2026/05/06 17:00:19 Failure: pod=cspod-4 reason="0/5 nodes are unavailable: 5 Insufficient cpu." (3/45 resolved)
2026/05/06 17:00:19 Failure: pod=cspod-37 reason="0/5 nodes are unavailable: 5 Insufficient cpu." (4/45 resolved)
2026/05/06 17:00:19 Failure: pod=cspod-41 reason="0/5 nodes are unavailable: 5 Insufficient cpu." (5/45 resolved)
2026/05/06 17:00:19 Failure: pod=cspod-45 reason="0/5 nodes are unavailable: 5 Insufficient cpu." (6/45 resolved)
2026/05/06 17:00:19 Failure: pod=cspod-39 reason="0/5 nodes are unavailable: 5 Insufficient cpu." (7/45 resolved)
2026/05/06 17:00:19 Failure: pod=cspod-68 reason="pod group is not ready, 1 Pending, 1 minAvailable; Pending: 1 Unschedulable" (8/45 resolved)
2026/05/06 17:00:19 Failure: pod=cspod-27 reason="pod group is not ready, 1 Pending, 1 minAvailable; Pending: 1 Unschedulable" (9/45 resolved)
2026/05/06 17:00:19 Failure: pod=cspod-29 reason="pod group is not ready, 1 Pending, 1 minAvailable; Pending: 1 Unschedulable" (10/45 resolved)
2026/05/06 17:00:19 Failure: pod=cspod-32 reason="pod group is not ready, 3 Pending, 3 minAvailable; Pending: 3 Unschedulable. Origin reason is cspod-30: 0/5 nodes are unavailable: 5 Insufficient cpu." (11/45 resolved)
2026/05/06 17:00:19 Failure: pod=cspod-33 reason="pod group is not ready, 4 Pending, 4 minAvailable; Pending: 4 Unschedulable" (12/45 resolved)
2026/05/06 17:00:19 Failure: pod=cspod-26 reason="pod group is not ready, 1 Pending, 1 minAvailable; Pending: 1 Unschedulable" (13/45 resolved)
2026/05/06 17:00:19 Failure: pod=cspod-6 reason="0/5 nodes are unavailable: 5 Insufficient cpu." (14/45 resolved)
2026/05/06 17:00:19 Failure: pod=cspod-60 reason="pod group is not ready, 1 Pending, 1 minAvailable; Pending: 1 Unschedulable" (15/45 resolved)
2026/05/06 17:00:19 Failure: pod=cspod-30 reason="0/5 nodes are unavailable: 5 Insufficient cpu." (16/45 resolved)
2026/05/06 17:00:19 Failure: pod=cspod-51 reason="0/5 nodes are unavailable: 5 Insufficient cpu." (17/45 resolved)
2026/05/06 17:00:19 Failure: pod=cspod-49 reason="0/5 nodes are unavailable: 5 Insufficient cpu." (18/45 resolved)
2026/05/06 17:00:19 Failure: pod=cspod-31 reason="pod group is not ready, 3 Pending, 3 minAvailable; Pending: 3 Unschedulable. Origin reason is cspod-30: 0/5 nodes are unavailable: 5 Insufficient cpu." (19/45 resolved)
2026/05/06 17:00:19 Failure: pod=cspod-66 reason="pod group is not ready, 1 Pending, 1 minAvailable; Pending: 1 Unschedulable" (20/45 resolved)
2026/05/06 17:00:19 Failure: pod=cspod-8 reason="0/5 nodes are unavailable: 5 Insufficient cpu." (21/45 resolved)
2026/05/06 17:00:19 Failure: pod=cspod-34 reason="pod group is not ready, 4 Pending, 4 minAvailable; Pending: 4 Unschedulable" (22/45 resolved)
2026/05/06 17:00:19 Failure: pod=cspod-28 reason="pod group is not ready, 1 Pending, 1 minAvailable; Pending: 1 Unschedulable" (23/45 resolved)
2026/05/06 17:00:19 Failure: pod=cspod-5 reason="0/5 nodes are unavailable: 5 Insufficient cpu." (24/45 resolved)
2026/05/06 17:00:19 Failure: pod=cspod-64 reason="pod group is not ready, 1 Pending, 1 minAvailable; Pending: 1 Unschedulable" (25/45 resolved)
2026/05/06 17:00:19 Failure: pod=cspod-50 reason="0/5 nodes are unavailable: 5 Insufficient cpu." (26/45 resolved)
2026/05/06 17:00:19 Failure: pod=cspod-62 reason="pod group is not ready, 1 Pending, 1 minAvailable; Pending: 1 Unschedulable" (27/45 resolved)
2026/05/06 17:00:19 Failure: pod=cspod-65 reason="pod group is not ready, 1 Pending, 1 minAvailable; Pending: 1 Unschedulable" (28/45 resolved)
2026/05/06 17:00:19 Failure: pod=cspod-63 reason="pod group is not ready, 1 Pending, 1 minAvailable; Pending: 1 Unschedulable" (29/45 resolved)
2026/05/06 17:00:19 Failure: pod=cspod-67 reason="pod group is not ready, 1 Pending, 1 minAvailable; Pending: 1 Unschedulable" (30/45 resolved)
2026/05/06 17:00:19 Failure: pod=cspod-54 reason="pod group is not ready, 3 Pending, 3 minAvailable; Pending: 3 Unschedulable. Origin reason is cspod-52: 0/5 nodes are unavailable: 5 Insufficient cpu." (31/45 resolved)
2026/05/06 17:00:19 Failure: pod=cspod-46 reason="0/5 nodes are unavailable: 5 Insufficient cpu." (32/45 resolved)
2026/05/06 17:00:19 Failure: pod=cspod-38 reason="0/5 nodes are unavailable: 5 Insufficient cpu." (33/45 resolved)
2026/05/06 17:00:19 Failure: pod=cspod-35 reason="pod group is not ready, 4 Pending, 4 minAvailable; Pending: 4 Unschedulable" (34/45 resolved)
2026/05/06 17:00:19 Failure: pod=cspod-47 reason="0/5 nodes are unavailable: 5 Insufficient cpu." (35/45 resolved)
2026/05/06 17:00:19 Failure: pod=cspod-69 reason="pod group is not ready, 1 Pending, 1 minAvailable; Pending: 1 Unschedulable" (36/45 resolved)
2026/05/06 17:00:19 Failure: pod=cspod-44 reason="0/5 nodes are unavailable: 5 Insufficient cpu." (37/45 resolved)
2026/05/06 17:00:19 Failure: pod=cspod-61 reason="pod group is not ready, 1 Pending, 1 minAvailable; Pending: 1 Unschedulable" (38/45 resolved)
2026/05/06 17:00:19 Failure: pod=cspod-43 reason="0/5 nodes are unavailable: 5 Insufficient cpu." (39/45 resolved)
2026/05/06 17:00:19 Failure: pod=cspod-36 reason="pod group is not ready, 4 Pending, 4 minAvailable; Pending: 4 Unschedulable" (40/45 resolved)
2026/05/06 17:00:19 Failure: pod=cspod-52 reason="0/5 nodes are unavailable: 5 Insufficient cpu." (41/45 resolved)
2026/05/06 17:00:19 Failure: pod=cspod-40 reason="0/5 nodes are unavailable: 5 Insufficient cpu." (42/45 resolved)
2026/05/06 17:00:19 Failure: pod=cspod-48 reason="0/5 nodes are unavailable: 5 Insufficient cpu." (43/45 resolved)
2026/05/06 17:00:19 Failure: pod=cspod-53 reason="pod group is not ready, 3 Pending, 3 minAvailable; Pending: 3 Unschedulable. Origin reason is cspod-52: 0/5 nodes are unavailable: 5 Insufficient cpu." (44/45 resolved)
2026/05/06 17:00:19 Failure: pod=cspod-7 reason="0/5 nodes are unavailable: 5 Insufficient cpu." (45/45 resolved)
2026/05/06 17:00:19 Round complete: 0 scheduled, 45 failed in 1.003972655s
2026/05/06 17:00:19 {"action":"HandleSchedule","durationMs":1005,"podCount":45,"result":"ok","roundId":"7","scheduled":0,"ts":"2026-05-06T17:00:19.115586105+01:00","unschedulable":45}
2026/05/06 17:00:19 {"action":"HandleSchedule","completedIds":5,"nodeCount":5,"phase":"start","podCount":45,"roundId":"8","ts":"2026-05-06T17:00:19.127776386+01:00"}
2026/05/06 17:00:19 {"action":"HandleSchedule","phase":"prep_done","podsCreated":45,"prepMs":0,"roundId":"8","staleDeleted":0,"ts":"2026-05-06T17:00:19.128344334+01:00"}
2026/05/06 17:00:19 Scheduling round started: expecting 45 decisions
2026/05/06 17:00:20 Failure: pod=cspod-67 reason="pod group is not ready, 1 Pending, 1 minAvailable; Pending: 1 Unschedulable" (1/45 resolved)
2026/05/06 17:00:20 Failure: pod=cspod-9 reason="0/5 nodes are unavailable: 5 Insufficient cpu." (2/45 resolved)
2026/05/06 17:00:20 Failure: pod=cspod-68 reason="pod group is not ready, 1 Pending, 1 minAvailable; Pending: 1 Unschedulable" (3/45 resolved)
2026/05/06 17:00:20 Failure: pod=cspod-42 reason="0/5 nodes are unavailable: 5 Insufficient cpu." (4/45 resolved)
2026/05/06 17:00:20 Failure: pod=cspod-29 reason="pod group is not ready, 1 Pending, 1 minAvailable; Pending: 1 Unschedulable" (5/45 resolved)
2026/05/06 17:00:20 Failure: pod=cspod-45 reason="0/5 nodes are unavailable: 5 Insufficient cpu." (6/45 resolved)
2026/05/06 17:00:20 Failure: pod=cspod-60 reason="pod group is not ready, 1 Pending, 1 minAvailable; Pending: 1 Unschedulable" (7/45 resolved)
2026/05/06 17:00:20 Failure: pod=cspod-64 reason="pod group is not ready, 1 Pending, 1 minAvailable; Pending: 1 Unschedulable" (8/45 resolved)
2026/05/06 17:00:20 Failure: pod=cspod-69 reason="pod group is not ready, 1 Pending, 1 minAvailable; Pending: 1 Unschedulable" (9/45 resolved)
2026/05/06 17:00:20 Failure: pod=cspod-44 reason="0/5 nodes are unavailable: 5 Insufficient cpu." (10/45 resolved)
2026/05/06 17:00:20 Failure: pod=cspod-8 reason="0/5 nodes are unavailable: 5 Insufficient cpu." (11/45 resolved)
2026/05/06 17:00:20 Failure: pod=cspod-47 reason="0/5 nodes are unavailable: 5 Insufficient cpu." (12/45 resolved)
2026/05/06 17:00:20 Failure: pod=cspod-48 reason="0/5 nodes are unavailable: 5 Insufficient cpu." (13/45 resolved)
2026/05/06 17:00:20 Failure: pod=cspod-52 reason="0/5 nodes are unavailable: 5 Insufficient cpu." (14/45 resolved)
2026/05/06 17:00:20 Failure: pod=cspod-63 reason="pod group is not ready, 1 Pending, 1 minAvailable; Pending: 1 Unschedulable" (15/45 resolved)
2026/05/06 17:00:20 Failure: pod=cspod-26 reason="pod group is not ready, 1 Pending, 1 minAvailable; Pending: 1 Unschedulable" (16/45 resolved)
2026/05/06 17:00:20 Failure: pod=cspod-33 reason="pod group is not ready, 4 Pending, 4 minAvailable; Pending: 4 Unschedulable" (17/45 resolved)
2026/05/06 17:00:20 Failure: pod=cspod-51 reason="0/5 nodes are unavailable: 5 Insufficient cpu." (18/45 resolved)
2026/05/06 17:00:20 Failure: pod=cspod-46 reason="0/5 nodes are unavailable: 5 Insufficient cpu." (19/45 resolved)
2026/05/06 17:00:20 Failure: pod=cspod-27 reason="pod group is not ready, 1 Pending, 1 minAvailable; Pending: 1 Unschedulable" (20/45 resolved)
2026/05/06 17:00:20 Failure: pod=cspod-7 reason="0/5 nodes are unavailable: 5 Insufficient cpu." (21/45 resolved)
2026/05/06 17:00:20 Failure: pod=cspod-65 reason="pod group is not ready, 1 Pending, 1 minAvailable; Pending: 1 Unschedulable" (22/45 resolved)
2026/05/06 17:00:20 Failure: pod=cspod-49 reason="0/5 nodes are unavailable: 5 Insufficient cpu." (23/45 resolved)
2026/05/06 17:00:20 Failure: pod=cspod-28 reason="pod group is not ready, 1 Pending, 1 minAvailable; Pending: 1 Unschedulable" (24/45 resolved)
2026/05/06 17:00:20 Failure: pod=cspod-5 reason="0/5 nodes are unavailable: 5 Insufficient cpu." (25/45 resolved)
2026/05/06 17:00:20 Failure: pod=cspod-6 reason="0/5 nodes are unavailable: 5 Insufficient cpu." (26/45 resolved)
2026/05/06 17:00:20 Failure: pod=cspod-50 reason="0/5 nodes are unavailable: 5 Insufficient cpu." (27/45 resolved)
2026/05/06 17:00:20 Binding: pod=cspod-4 -> node=csnode-1 (28/45 resolved)
2026/05/06 17:00:20 Binding: pod=cspod-40 -> node=csnode-1 (29/45 resolved)
2026/05/06 17:00:20 Binding: pod=cspod-37 -> node=csnode-4 (30/45 resolved)
2026/05/06 17:00:20 Failure: pod=cspod-53 reason="pod group is not ready, 3 Pending, 3 minAvailable; Pending: 3 Unschedulable. Origin reason is cspod-52: 0/5 nodes are unavailable: 5 Insufficient cpu." (31/45 resolved)
2026/05/06 17:00:20 Binding: pod=cspod-38 -> node=csnode-3 (32/45 resolved)
2026/05/06 17:00:20 Binding: pod=cspod-39 -> node=csnode-3 (33/45 resolved)
2026/05/06 17:00:20 Failure: pod=cspod-32 reason="pod group is not ready, 3 Pending, 3 minAvailable; Pending: 3 Unschedulable. Origin reason is cspod-30: 0/5 nodes are unavailable: 5 Insufficient cpu." (34/45 resolved)
2026/05/06 17:00:20 Failure: pod=cspod-62 reason="pod group is not ready, 1 Pending, 1 minAvailable; Pending: 1 Unschedulable" (35/45 resolved)
2026/05/06 17:00:20 Failure: pod=cspod-43 reason="0/5 nodes are unavailable: 5 Insufficient cpu." (36/45 resolved)
2026/05/06 17:00:20 Failure: pod=cspod-34 reason="pod group is not ready, 4 Pending, 4 minAvailable; Pending: 4 Unschedulable" (37/45 resolved)
2026/05/06 17:00:20 Failure: pod=cspod-35 reason="pod group is not ready, 4 Pending, 4 minAvailable; Pending: 4 Unschedulable" (38/45 resolved)
2026/05/06 17:00:20 Failure: pod=cspod-66 reason="pod group is not ready, 1 Pending, 1 minAvailable; Pending: 1 Unschedulable" (39/45 resolved)
2026/05/06 17:00:20 Failure: pod=cspod-30 reason="0/5 nodes are unavailable: 5 Insufficient cpu." (40/45 resolved)
2026/05/06 17:00:20 Failure: pod=cspod-61 reason="pod group is not ready, 1 Pending, 1 minAvailable; Pending: 1 Unschedulable" (41/45 resolved)
2026/05/06 17:00:20 Failure: pod=cspod-36 reason="pod group is not ready, 4 Pending, 4 minAvailable; Pending: 4 Unschedulable" (42/45 resolved)
2026/05/06 17:00:20 Failure: pod=cspod-31 reason="pod group is not ready, 3 Pending, 3 minAvailable; Pending: 3 Unschedulable. Origin reason is cspod-30: 0/5 nodes are unavailable: 5 Insufficient cpu." (43/45 resolved)
2026/05/06 17:00:20 Failure: pod=cspod-41 reason="0/5 nodes are unavailable: 5 Insufficient cpu." (44/45 resolved)
2026/05/06 17:00:20 Failure: pod=cspod-54 reason="pod group is not ready, 3 Pending, 3 minAvailable; Pending: 3 Unschedulable. Origin reason is cspod-52: 0/5 nodes are unavailable: 5 Insufficient cpu." (45/45 resolved)
2026/05/06 17:00:20 Round complete: 5 scheduled, 40 failed in 1.004209682s
2026/05/06 17:00:20 {"action":"HandleSchedule","durationMs":1005,"podCount":45,"result":"ok","roundId":"8","scheduled":5,"ts":"2026-05-06T17:00:20.132605831+01:00","unschedulable":40}
2026/05/06 17:00:20 {"action":"HandleSchedule","completedIds":2,"nodeCount":5,"phase":"start","podCount":40,"roundId":"9","ts":"2026-05-06T17:00:20.138858042+01:00"}
2026/05/06 17:00:20 {"action":"HandleSchedule","phase":"prep_done","podsCreated":40,"prepMs":0,"roundId":"9","staleDeleted":0,"ts":"2026-05-06T17:00:20.139320942+01:00"}
2026/05/06 17:00:20 Scheduling round started: expecting 40 decisions
2026/05/06 17:00:19 Failure: pod=cspod-69 reason="pod group is not ready, 1 Pending, 1 minAvailable; Pending: 1 Unschedulable" (1/40 resolved)
2026/05/06 17:00:19 Failure: pod=cspod-44 reason="0/5 nodes are unavailable: 5 Insufficient cpu." (2/40 resolved)
2026/05/06 17:00:19 Failure: pod=cspod-9 reason="0/5 nodes are unavailable: 5 Insufficient cpu." (3/40 resolved)
2026/05/06 17:00:19 Failure: pod=cspod-65 reason="pod group is not ready, 1 Pending, 1 minAvailable; Pending: 1 Unschedulable" (4/40 resolved)
2026/05/06 17:00:19 Failure: pod=cspod-36 reason="pod group is not ready, 4 Pending, 4 minAvailable; Pending: 4 Unschedulable" (5/40 resolved)
2026/05/06 17:00:19 Failure: pod=cspod-61 reason="pod group is not ready, 1 Pending, 1 minAvailable; Pending: 1 Unschedulable" (6/40 resolved)
2026/05/06 17:00:19 Failure: pod=cspod-46 reason="0/5 nodes are unavailable: 5 Insufficient cpu." (7/40 resolved)
2026/05/06 17:00:19 Failure: pod=cspod-60 reason="pod group is not ready, 1 Pending, 1 minAvailable; Pending: 1 Unschedulable" (8/40 resolved)
2026/05/06 17:00:19 Failure: pod=cspod-63 reason="pod group is not ready, 1 Pending, 1 minAvailable; Pending: 1 Unschedulable" (9/40 resolved)
2026/05/06 17:00:19 Failure: pod=cspod-29 reason="pod group is not ready, 1 Pending, 1 minAvailable; Pending: 1 Unschedulable" (10/40 resolved)
2026/05/06 17:00:19 Failure: pod=cspod-47 reason="0/5 nodes are unavailable: 5 Insufficient cpu." (11/40 resolved)
2026/05/06 17:00:19 Failure: pod=cspod-8 reason="0/5 nodes are unavailable: 5 Insufficient cpu." (12/40 resolved)
2026/05/06 17:00:19 Failure: pod=cspod-5 reason="0/5 nodes are unavailable: 5 Insufficient cpu." (13/40 resolved)
2026/05/06 17:00:19 Failure: pod=cspod-68 reason="pod group is not ready, 1 Pending, 1 minAvailable; Pending: 1 Unschedulable" (14/40 resolved)
2026/05/06 17:00:19 Failure: pod=cspod-6 reason="0/5 nodes are unavailable: 5 Insufficient cpu." (15/40 resolved)
2026/05/06 17:00:19 Binding: pod=cspod-41 -> node=csnode-2 (16/40 resolved)
2026/05/06 17:00:19 Failure: pod=cspod-33 reason="pod group is not ready, 4 Pending, 4 minAvailable; Pending: 4 Unschedulable" (17/40 resolved)
2026/05/06 17:00:19 Binding: pod=cspod-42 -> node=csnode-0 (18/40 resolved)
2026/05/06 17:00:19 Failure: pod=cspod-26 reason="pod group is not ready, 1 Pending, 1 minAvailable; Pending: 1 Unschedulable" (19/40 resolved)
2026/05/06 17:00:19 Failure: pod=cspod-52 reason="0/5 nodes are unavailable: 5 Insufficient cpu." (20/40 resolved)
2026/05/06 17:00:19 Failure: pod=cspod-62 reason="pod group is not ready, 1 Pending, 1 minAvailable; Pending: 1 Unschedulable" (21/40 resolved)
2026/05/06 17:00:19 Failure: pod=cspod-34 reason="pod group is not ready, 4 Pending, 4 minAvailable; Pending: 4 Unschedulable" (22/40 resolved)
2026/05/06 17:00:19 Failure: pod=cspod-48 reason="0/5 nodes are unavailable: 5 Insufficient cpu." (23/40 resolved)
2026/05/06 17:00:19 Failure: pod=cspod-27 reason="pod group is not ready, 1 Pending, 1 minAvailable; Pending: 1 Unschedulable" (24/40 resolved)
2026/05/06 17:00:19 Failure: pod=cspod-28 reason="pod group is not ready, 1 Pending, 1 minAvailable; Pending: 1 Unschedulable" (25/40 resolved)
2026/05/06 17:00:19 Failure: pod=cspod-43 reason="0/5 nodes are unavailable: 5 Insufficient cpu." (26/40 resolved)
2026/05/06 17:00:19 Failure: pod=cspod-67 reason="pod group is not ready, 1 Pending, 1 minAvailable; Pending: 1 Unschedulable" (27/40 resolved)
2026/05/06 17:00:19 Failure: pod=cspod-7 reason="0/5 nodes are unavailable: 5 Insufficient cpu." (28/40 resolved)
2026/05/06 17:00:19 Failure: pod=cspod-51 reason="0/5 nodes are unavailable: 5 Insufficient cpu." (29/40 resolved)
2026/05/06 17:00:19 Failure: pod=cspod-64 reason="pod group is not ready, 1 Pending, 1 minAvailable; Pending: 1 Unschedulable" (30/40 resolved)
2026/05/06 17:00:19 Failure: pod=cspod-50 reason="0/5 nodes are unavailable: 5 Insufficient cpu." (31/40 resolved)
2026/05/06 17:00:19 Failure: pod=cspod-35 reason="pod group is not ready, 4 Pending, 4 minAvailable; Pending: 4 Unschedulable" (32/40 resolved)
2026/05/06 17:00:19 Failure: pod=cspod-53 reason="pod group is not ready, 3 Pending, 3 minAvailable; Pending: 3 Unschedulable. Origin reason is cspod-52: 0/5 nodes are unavailable: 5 Insufficient cpu." (33/40 resolved)
2026/05/06 17:00:19 Failure: pod=cspod-30 reason="0/5 nodes are unavailable: 5 Insufficient cpu." (34/40 resolved)
2026/05/06 17:00:19 Failure: pod=cspod-45 reason="0/5 nodes are unavailable: 5 Insufficient cpu." (35/40 resolved)
2026/05/06 17:00:19 Failure: pod=cspod-66 reason="pod group is not ready, 1 Pending, 1 minAvailable; Pending: 1 Unschedulable" (36/40 resolved)
2026/05/06 17:00:19 Failure: pod=cspod-54 reason="pod group is not ready, 3 Pending, 3 minAvailable; Pending: 3 Unschedulable. Origin reason is cspod-52: 0/5 nodes are unavailable: 5 Insufficient cpu." (37/40 resolved)
2026/05/06 17:00:19 Failure: pod=cspod-31 reason="pod group is not ready, 3 Pending, 3 minAvailable; Pending: 3 Unschedulable. Origin reason is cspod-30: 0/5 nodes are unavailable: 5 Insufficient cpu." (38/40 resolved)
2026/05/06 17:00:19 Failure: pod=cspod-49 reason="0/5 nodes are unavailable: 5 Insufficient cpu." (39/40 resolved)
2026/05/06 17:00:19 Failure: pod=cspod-32 reason="pod group is not ready, 3 Pending, 3 minAvailable; Pending: 3 Unschedulable. Origin reason is cspod-30: 0/5 nodes are unavailable: 5 Insufficient cpu." (40/40 resolved)
2026/05/06 17:00:19 Round complete: 2 scheduled, 38 failed in 1.024198221s
2026/05/06 17:00:19 {"action":"HandleSchedule","durationMs":1024,"podCount":40,"result":"ok","roundId":"9","scheduled":2,"ts":"2026-05-06T17:00:19.405351571+01:00","unschedulable":38}
2026/05/06 17:00:19 {"action":"HandleSchedule","completedIds":4,"nodeCount":5,"phase":"start","podCount":38,"roundId":"10","ts":"2026-05-06T17:00:19.419096638+01:00"}
2026/05/06 17:00:19 {"action":"HandleSchedule","phase":"prep_done","podsCreated":38,"prepMs":1,"roundId":"10","staleDeleted":0,"ts":"2026-05-06T17:00:19.420720721+01:00"}
2026/05/06 17:00:19 Scheduling round started: expecting 38 decisions
2026/05/06 17:00:20 Failure: pod=cspod-69 reason="pod group is not ready, 1 Pending, 1 minAvailable; Pending: 1 Unschedulable" (1/38 resolved)
2026/05/06 17:00:20 Failure: pod=cspod-61 reason="pod group is not ready, 1 Pending, 1 minAvailable; Pending: 1 Unschedulable" (2/38 resolved)
2026/05/06 17:00:20 Failure: pod=cspod-27 reason="pod group is not ready, 1 Pending, 1 minAvailable; Pending: 1 Unschedulable" (3/38 resolved)
2026/05/06 17:00:20 Failure: pod=cspod-65 reason="pod group is not ready, 1 Pending, 1 minAvailable; Pending: 1 Unschedulable" (4/38 resolved)
2026/05/06 17:00:20 Failure: pod=cspod-28 reason="pod group is not ready, 1 Pending, 1 minAvailable; Pending: 1 Unschedulable" (5/38 resolved)
2026/05/06 17:00:20 Failure: pod=cspod-7 reason="0/5 nodes are unavailable: 5 Insufficient cpu." (6/38 resolved)
2026/05/06 17:00:20 Failure: pod=cspod-51 reason="0/5 nodes are unavailable: 5 Insufficient cpu." (7/38 resolved)
2026/05/06 17:00:20 Failure: pod=cspod-48 reason="0/5 nodes are unavailable: 5 Insufficient cpu." (8/38 resolved)
2026/05/06 17:00:20 Failure: pod=cspod-9 reason="0/5 nodes are unavailable: 5 Insufficient cpu." (9/38 resolved)
2026/05/06 17:00:20 Failure: pod=cspod-33 reason="pod group is not ready, 4 Pending, 4 minAvailable; Pending: 4 Unschedulable" (10/38 resolved)
2026/05/06 17:00:20 Failure: pod=cspod-50 reason="0/5 nodes are unavailable: 5 Insufficient cpu." (11/38 resolved)
2026/05/06 17:00:20 Failure: pod=cspod-47 reason="0/5 nodes are unavailable: 5 Insufficient cpu." (12/38 resolved)
2026/05/06 17:00:20 Failure: pod=cspod-66 reason="pod group is not ready, 1 Pending, 1 minAvailable; Pending: 1 Unschedulable" (13/38 resolved)
2026/05/06 17:00:20 Failure: pod=cspod-52 reason="0/5 nodes are unavailable: 5 Insufficient cpu." (14/38 resolved)
2026/05/06 17:00:20 Failure: pod=cspod-60 reason="pod group is not ready, 1 Pending, 1 minAvailable; Pending: 1 Unschedulable" (15/38 resolved)
2026/05/06 17:00:20 Failure: pod=cspod-5 reason="0/5 nodes are unavailable: 5 Insufficient cpu." (16/38 resolved)
2026/05/06 17:00:20 Failure: pod=cspod-26 reason="pod group is not ready, 1 Pending, 1 minAvailable; Pending: 1 Unschedulable" (17/38 resolved)
2026/05/06 17:00:20 Failure: pod=cspod-62 reason="pod group is not ready, 1 Pending, 1 minAvailable; Pending: 1 Unschedulable" (18/38 resolved)
2026/05/06 17:00:20 Failure: pod=cspod-34 reason="pod group is not ready, 4 Pending, 4 minAvailable; Pending: 4 Unschedulable" (19/38 resolved)
2026/05/06 17:00:20 Failure: pod=cspod-8 reason="0/5 nodes are unavailable: 5 Insufficient cpu." (20/38 resolved)
2026/05/06 17:00:20 Failure: pod=cspod-49 reason="0/5 nodes are unavailable: 5 Insufficient cpu." (21/38 resolved)
2026/05/06 17:00:20 Failure: pod=cspod-64 reason="pod group is not ready, 1 Pending, 1 minAvailable; Pending: 1 Unschedulable" (22/38 resolved)
2026/05/06 17:00:20 Failure: pod=cspod-67 reason="pod group is not ready, 1 Pending, 1 minAvailable; Pending: 1 Unschedulable" (23/38 resolved)
2026/05/06 17:00:20 Failure: pod=cspod-68 reason="pod group is not ready, 1 Pending, 1 minAvailable; Pending: 1 Unschedulable" (24/38 resolved)
2026/05/06 17:00:20 Failure: pod=cspod-53 reason="pod group is not ready, 3 Pending, 3 minAvailable; Pending: 3 Unschedulable. Origin reason is cspod-52: 0/5 nodes are unavailable: 5 Insufficient cpu." (25/38 resolved)
2026/05/06 17:00:20 Failure: pod=cspod-29 reason="pod group is not ready, 1 Pending, 1 minAvailable; Pending: 1 Unschedulable" (26/38 resolved)
2026/05/06 17:00:20 Failure: pod=cspod-32 reason="pod group is not ready, 3 Pending, 3 minAvailable; Pending: 3 Unschedulable. Origin reason is cspod-30: 0/5 nodes are unavailable: 5 Insufficient cpu." (27/38 resolved)
2026/05/06 17:00:20 Failure: pod=cspod-6 reason="0/5 nodes are unavailable: 5 Insufficient cpu." (28/38 resolved)
2026/05/06 17:00:20 Failure: pod=cspod-54 reason="pod group is not ready, 3 Pending, 3 minAvailable; Pending: 3 Unschedulable. Origin reason is cspod-52: 0/5 nodes are unavailable: 5 Insufficient cpu." (29/38 resolved)
2026/05/06 17:00:20 Failure: pod=cspod-30 reason="0/5 nodes are unavailable: 5 Insufficient cpu." (30/38 resolved)
2026/05/06 17:00:20 Failure: pod=cspod-63 reason="pod group is not ready, 1 Pending, 1 minAvailable; Pending: 1 Unschedulable" (31/38 resolved)
2026/05/06 17:00:20 Failure: pod=cspod-35 reason="pod group is not ready, 4 Pending, 4 minAvailable; Pending: 4 Unschedulable" (32/38 resolved)
2026/05/06 17:00:20 Failure: pod=cspod-31 reason="pod group is not ready, 3 Pending, 3 minAvailable; Pending: 3 Unschedulable. Origin reason is cspod-30: 0/5 nodes are unavailable: 5 Insufficient cpu." (33/38 resolved)
2026/05/06 17:00:20 Failure: pod=cspod-36 reason="pod group is not ready, 4 Pending, 4 minAvailable; Pending: 4 Unschedulable" (34/38 resolved)
2026/05/06 17:00:20 Binding: pod=cspod-44 -> node=csnode-1 (35/38 resolved)
2026/05/06 17:00:20 Binding: pod=cspod-46 -> node=csnode-3 (36/38 resolved)
2026/05/06 17:00:20 Binding: pod=cspod-45 -> node=csnode-3 (37/38 resolved)
2026/05/06 17:00:20 Binding: pod=cspod-43 -> node=csnode-4 (38/38 resolved)
2026/05/06 17:00:20 Round complete: 4 scheduled, 34 failed in 1.000402708s
2026/05/06 17:00:20 {"action":"HandleSchedule","durationMs":1002,"podCount":38,"result":"ok","roundId":"10","scheduled":4,"ts":"2026-05-06T17:00:20.421190517+01:00","unschedulable":34}
2026/05/06 17:00:20 {"action":"HandleSchedule","completedIds":2,"nodeCount":5,"phase":"start","podCount":34,"roundId":"11","ts":"2026-05-06T17:00:20.426087377+01:00"}
2026/05/06 17:00:20 {"action":"HandleSchedule","phase":"prep_done","podsCreated":34,"prepMs":1,"roundId":"11","staleDeleted":0,"ts":"2026-05-06T17:00:20.427876961+01:00"}
2026/05/06 17:00:20 Scheduling round started: expecting 34 decisions
2026/05/06 17:00:21 Failure: pod=cspod-26 reason="pod group is not ready, 1 Pending, 1 minAvailable; Pending: 1 Unschedulable" (1/34 resolved)
2026/05/06 17:00:21 Failure: pod=cspod-69 reason="pod group is not ready, 1 Pending, 1 minAvailable; Pending: 1 Unschedulable" (2/34 resolved)
2026/05/06 17:00:21 Failure: pod=cspod-68 reason="pod group is not ready, 1 Pending, 1 minAvailable; Pending: 1 Unschedulable" (3/34 resolved)
2026/05/06 17:00:21 Failure: pod=cspod-62 reason="pod group is not ready, 1 Pending, 1 minAvailable; Pending: 1 Unschedulable" (4/34 resolved)
2026/05/06 17:00:21 Failure: pod=cspod-5 reason="0/5 nodes are unavailable: 5 Insufficient cpu." (5/34 resolved)
2026/05/06 17:00:21 Failure: pod=cspod-64 reason="pod group is not ready, 1 Pending, 1 minAvailable; Pending: 1 Unschedulable" (6/34 resolved)
2026/05/06 17:00:21 Failure: pod=cspod-51 reason="0/5 nodes are unavailable: 5 Insufficient cpu." (7/34 resolved)
2026/05/06 17:00:21 Failure: pod=cspod-30 reason="0/5 nodes are unavailable: 5 Insufficient cpu." (8/34 resolved)
2026/05/06 17:00:21 Failure: pod=cspod-6 reason="0/5 nodes are unavailable: 5 Insufficient cpu." (9/34 resolved)
2026/05/06 17:00:21 Failure: pod=cspod-29 reason="pod group is not ready, 1 Pending, 1 minAvailable; Pending: 1 Unschedulable" (10/34 resolved)
2026/05/06 17:00:21 Failure: pod=cspod-33 reason="pod group is not ready, 4 Pending, 4 minAvailable; Pending: 4 Unschedulable" (11/34 resolved)
2026/05/06 17:00:21 Failure: pod=cspod-50 reason="0/5 nodes are unavailable: 5 Insufficient cpu." (12/34 resolved)
2026/05/06 17:00:21 Failure: pod=cspod-31 reason="pod group is not ready, 3 Pending, 3 minAvailable; Pending: 3 Unschedulable. Origin reason is cspod-30: 0/5 nodes are unavailable: 5 Insufficient cpu." (13/34 resolved)
2026/05/06 17:00:21 Failure: pod=cspod-65 reason="pod group is not ready, 1 Pending, 1 minAvailable; Pending: 1 Unschedulable" (14/34 resolved)
2026/05/06 17:00:21 Failure: pod=cspod-63 reason="pod group is not ready, 1 Pending, 1 minAvailable; Pending: 1 Unschedulable" (15/34 resolved)
2026/05/06 17:00:21 Failure: pod=cspod-8 reason="0/5 nodes are unavailable: 5 Insufficient cpu." (16/34 resolved)
2026/05/06 17:00:21 Failure: pod=cspod-52 reason="0/5 nodes are unavailable: 5 Insufficient cpu." (17/34 resolved)
2026/05/06 17:00:21 Failure: pod=cspod-34 reason="pod group is not ready, 4 Pending, 4 minAvailable; Pending: 4 Unschedulable" (18/34 resolved)
2026/05/06 17:00:21 Failure: pod=cspod-27 reason="pod group is not ready, 1 Pending, 1 minAvailable; Pending: 1 Unschedulable" (19/34 resolved)
2026/05/06 17:00:21 Failure: pod=cspod-7 reason="0/5 nodes are unavailable: 5 Insufficient cpu." (20/34 resolved)
2026/05/06 17:00:21 Failure: pod=cspod-32 reason="pod group is not ready, 3 Pending, 3 minAvailable; Pending: 3 Unschedulable. Origin reason is cspod-30: 0/5 nodes are unavailable: 5 Insufficient cpu." (21/34 resolved)
2026/05/06 17:00:21 Failure: pod=cspod-28 reason="pod group is not ready, 1 Pending, 1 minAvailable; Pending: 1 Unschedulable" (22/34 resolved)
2026/05/06 17:00:21 Failure: pod=cspod-60 reason="pod group is not ready, 1 Pending, 1 minAvailable; Pending: 1 Unschedulable" (23/34 resolved)
2026/05/06 17:00:21 Failure: pod=cspod-49 reason="0/5 nodes are unavailable: 5 Insufficient cpu." (24/34 resolved)
2026/05/06 17:00:21 Failure: pod=cspod-66 reason="pod group is not ready, 1 Pending, 1 minAvailable; Pending: 1 Unschedulable" (25/34 resolved)
2026/05/06 17:00:21 Failure: pod=cspod-9 reason="0/5 nodes are unavailable: 5 Insufficient cpu." (26/34 resolved)
2026/05/06 17:00:21 Failure: pod=cspod-53 reason="pod group is not ready, 3 Pending, 3 minAvailable; Pending: 3 Unschedulable. Origin reason is cspod-52: 0/5 nodes are unavailable: 5 Insufficient cpu." (27/34 resolved)
2026/05/06 17:00:21 Failure: pod=cspod-67 reason="pod group is not ready, 1 Pending, 1 minAvailable; Pending: 1 Unschedulable" (28/34 resolved)
2026/05/06 17:00:21 Failure: pod=cspod-61 reason="pod group is not ready, 1 Pending, 1 minAvailable; Pending: 1 Unschedulable" (29/34 resolved)
2026/05/06 17:00:21 Failure: pod=cspod-35 reason="pod group is not ready, 4 Pending, 4 minAvailable; Pending: 4 Unschedulable" (30/34 resolved)
2026/05/06 17:00:21 Failure: pod=cspod-54 reason="pod group is not ready, 3 Pending, 3 minAvailable; Pending: 3 Unschedulable. Origin reason is cspod-52: 0/5 nodes are unavailable: 5 Insufficient cpu." (31/34 resolved)
2026/05/06 17:00:21 Failure: pod=cspod-36 reason="pod group is not ready, 4 Pending, 4 minAvailable; Pending: 4 Unschedulable" (32/34 resolved)
2026/05/06 17:00:21 Binding: pod=cspod-48 -> node=csnode-0 (33/34 resolved)
2026/05/06 17:00:21 Binding: pod=cspod-47 -> node=csnode-2 (34/34 resolved)
2026/05/06 17:00:21 Round complete: 2 scheduled, 32 failed in 1.007300459s
2026/05/06 17:00:21 {"action":"HandleSchedule","durationMs":1009,"podCount":34,"result":"ok","roundId":"11","scheduled":2,"ts":"2026-05-06T17:00:21.435226457+01:00","unschedulable":32}
2026/05/06 17:00:21 {"action":"HandleSchedule","completedIds":1,"nodeCount":5,"phase":"start","podCount":32,"roundId":"12","ts":"2026-05-06T17:00:21.443595088+01:00"}
2026/05/06 17:00:21 {"action":"HandleSchedule","phase":"prep_done","podsCreated":32,"prepMs":1,"roundId":"12","staleDeleted":0,"ts":"2026-05-06T17:00:21.445106565+01:00"}
2026/05/06 17:00:21 Scheduling round started: expecting 32 decisions
2026/05/06 17:00:22 Failure: pod=cspod-67 reason="pod group is not ready, 1 Pending, 1 minAvailable; Pending: 1 Unschedulable" (1/32 resolved)
2026/05/06 17:00:22 Failure: pod=cspod-62 reason="pod group is not ready, 1 Pending, 1 minAvailable; Pending: 1 Unschedulable" (2/32 resolved)
2026/05/06 17:00:22 Failure: pod=cspod-60 reason="pod group is not ready, 1 Pending, 1 minAvailable; Pending: 1 Unschedulable" (3/32 resolved)
2026/05/06 17:00:22 Failure: pod=cspod-66 reason="pod group is not ready, 1 Pending, 1 minAvailable; Pending: 1 Unschedulable" (4/32 resolved)
2026/05/06 17:00:22 Failure: pod=cspod-65 reason="pod group is not ready, 1 Pending, 1 minAvailable; Pending: 1 Unschedulable" (5/32 resolved)
2026/05/06 17:00:22 Failure: pod=cspod-30 reason="0/5 nodes are unavailable: 5 Insufficient cpu." (6/32 resolved)
2026/05/06 17:00:22 Failure: pod=cspod-64 reason="pod group is not ready, 1 Pending, 1 minAvailable; Pending: 1 Unschedulable" (7/32 resolved)
2026/05/06 17:00:22 Failure: pod=cspod-9 reason="0/5 nodes are unavailable: 5 Insufficient cpu." (8/32 resolved)
2026/05/06 17:00:22 Failure: pod=cspod-53 reason="pod group is not ready, 3 Pending, 3 minAvailable; Pending: 3 Unschedulable. Origin reason is cspod-52: 0/5 nodes are unavailable: 5 Insufficient cpu." (9/32 resolved)
2026/05/06 17:00:22 Failure: pod=cspod-51 reason="0/5 nodes are unavailable: 5 Insufficient cpu." (10/32 resolved)
2026/05/06 17:00:22 Failure: pod=cspod-28 reason="pod group is not ready, 1 Pending, 1 minAvailable; Pending: 1 Unschedulable" (11/32 resolved)
2026/05/06 17:00:22 Failure: pod=cspod-50 reason="0/5 nodes are unavailable: 5 Insufficient cpu." (12/32 resolved)
2026/05/06 17:00:22 Failure: pod=cspod-8 reason="0/5 nodes are unavailable: 5 Insufficient cpu." (13/32 resolved)
2026/05/06 17:00:22 Failure: pod=cspod-7 reason="0/5 nodes are unavailable: 5 Insufficient cpu." (14/32 resolved)
2026/05/06 17:00:22 Failure: pod=cspod-61 reason="pod group is not ready, 1 Pending, 1 minAvailable; Pending: 1 Unschedulable" (15/32 resolved)
2026/05/06 17:00:22 Failure: pod=cspod-69 reason="pod group is not ready, 1 Pending, 1 minAvailable; Pending: 1 Unschedulable" (16/32 resolved)
2026/05/06 17:00:22 Failure: pod=cspod-31 reason="pod group is not ready, 3 Pending, 3 minAvailable; Pending: 3 Unschedulable. Origin reason is cspod-30: 0/5 nodes are unavailable: 5 Insufficient cpu." (17/32 resolved)
2026/05/06 17:00:22 Failure: pod=cspod-32 reason="pod group is not ready, 3 Pending, 3 minAvailable; Pending: 3 Unschedulable. Origin reason is cspod-30: 0/5 nodes are unavailable: 5 Insufficient cpu." (18/32 resolved)
2026/05/06 17:00:22 Failure: pod=cspod-35 reason="pod group is not ready, 4 Pending, 4 minAvailable; Pending: 4 Unschedulable" (19/32 resolved)
2026/05/06 17:00:22 Failure: pod=cspod-6 reason="0/5 nodes are unavailable: 5 Insufficient cpu." (20/32 resolved)
2026/05/06 17:00:22 Failure: pod=cspod-26 reason="pod group is not ready, 1 Pending, 1 minAvailable; Pending: 1 Unschedulable" (21/32 resolved)
2026/05/06 17:00:22 Failure: pod=cspod-5 reason="0/5 nodes are unavailable: 5 Insufficient cpu." (22/32 resolved)
2026/05/06 17:00:22 Failure: pod=cspod-27 reason="pod group is not ready, 1 Pending, 1 minAvailable; Pending: 1 Unschedulable" (23/32 resolved)
2026/05/06 17:00:22 Failure: pod=cspod-29 reason="pod group is not ready, 1 Pending, 1 minAvailable; Pending: 1 Unschedulable" (24/32 resolved)
2026/05/06 17:00:22 Failure: pod=cspod-54 reason="pod group is not ready, 3 Pending, 3 minAvailable; Pending: 3 Unschedulable. Origin reason is cspod-52: 0/5 nodes are unavailable: 5 Insufficient cpu." (25/32 resolved)
2026/05/06 17:00:22 Failure: pod=cspod-68 reason="pod group is not ready, 1 Pending, 1 minAvailable; Pending: 1 Unschedulable" (26/32 resolved)
2026/05/06 17:00:22 Failure: pod=cspod-63 reason="pod group is not ready, 1 Pending, 1 minAvailable; Pending: 1 Unschedulable" (27/32 resolved)
2026/05/06 17:00:22 Failure: pod=cspod-36 reason="pod group is not ready, 4 Pending, 4 minAvailable; Pending: 4 Unschedulable" (28/32 resolved)
2026/05/06 17:00:22 Failure: pod=cspod-52 reason="0/5 nodes are unavailable: 5 Insufficient cpu." (29/32 resolved)
2026/05/06 17:00:22 Failure: pod=cspod-33 reason="pod group is not ready, 4 Pending, 4 minAvailable; Pending: 4 Unschedulable" (30/32 resolved)
2026/05/06 17:00:22 Failure: pod=cspod-34 reason="pod group is not ready, 4 Pending, 4 minAvailable; Pending: 4 Unschedulable" (31/32 resolved)
2026/05/06 17:00:22 Binding: pod=cspod-49 -> node=csnode-1 (32/32 resolved)
2026/05/06 17:00:22 Round complete: 1 scheduled, 31 failed in 990.115994ms
2026/05/06 17:00:22 {"action":"HandleSchedule","durationMs":991,"podCount":32,"result":"ok","roundId":"12","scheduled":1,"ts":"2026-05-06T17:00:22.435292351+01:00","unschedulable":31}
2026/05/06 17:00:22 {"action":"HandleSchedule","completedIds":3,"nodeCount":5,"phase":"start","podCount":31,"roundId":"13","ts":"2026-05-06T17:00:22.444172226+01:00"}
2026/05/06 17:00:22 {"action":"HandleSchedule","phase":"prep_done","podsCreated":31,"prepMs":0,"roundId":"13","staleDeleted":0,"ts":"2026-05-06T17:00:22.444585856+01:00"}
2026/05/06 17:00:22 Scheduling round started: expecting 31 decisions
2026/05/06 17:00:23 Failure: pod=cspod-8 reason="0/5 nodes are unavailable: 5 Insufficient cpu." (1/31 resolved)
2026/05/06 17:00:23 Failure: pod=cspod-68 reason="pod group is not ready, 1 Pending, 1 minAvailable; Pending: 1 Unschedulable" (2/31 resolved)
2026/05/06 17:00:23 Failure: pod=cspod-61 reason="pod group is not ready, 1 Pending, 1 minAvailable; Pending: 1 Unschedulable" (3/31 resolved)
2026/05/06 17:00:23 Failure: pod=cspod-9 reason="0/5 nodes are unavailable: 5 Insufficient cpu." (4/31 resolved)
2026/05/06 17:00:23 Failure: pod=cspod-69 reason="pod group is not ready, 1 Pending, 1 minAvailable; Pending: 1 Unschedulable" (5/31 resolved)
2026/05/06 17:00:23 Failure: pod=cspod-6 reason="0/5 nodes are unavailable: 5 Insufficient cpu." (6/31 resolved)
2026/05/06 17:00:23 Failure: pod=cspod-63 reason="pod group is not ready, 1 Pending, 1 minAvailable; Pending: 1 Unschedulable" (7/31 resolved)
2026/05/06 17:00:23 Failure: pod=cspod-52 reason="0/5 nodes are unavailable: 5 Insufficient cpu." (8/31 resolved)
2026/05/06 17:00:23 Failure: pod=cspod-5 reason="0/5 nodes are unavailable: 5 Insufficient cpu." (9/31 resolved)
2026/05/06 17:00:23 Failure: pod=cspod-35 reason="pod group is not ready, 4 Pending, 4 minAvailable; Pending: 4 Unschedulable" (10/31 resolved)
2026/05/06 17:00:23 Failure: pod=cspod-62 reason="pod group is not ready, 1 Pending, 1 minAvailable; Pending: 1 Unschedulable" (11/31 resolved)
2026/05/06 17:00:23 Failure: pod=cspod-51 reason="0/5 nodes are unavailable: 5 Insufficient cpu." (12/31 resolved)
2026/05/06 17:00:23 Failure: pod=cspod-30 reason="0/5 nodes are unavailable: 5 Insufficient cpu." (13/31 resolved)
2026/05/06 17:00:23 Failure: pod=cspod-66 reason="pod group is not ready, 1 Pending, 1 minAvailable; Pending: 1 Unschedulable" (14/31 resolved)
2026/05/06 17:00:23 Failure: pod=cspod-31 reason="pod group is not ready, 3 Pending, 3 minAvailable; Pending: 3 Unschedulable. Origin reason is cspod-30: 0/5 nodes are unavailable: 5 Insufficient cpu." (15/31 resolved)
2026/05/06 17:00:23 Failure: pod=cspod-50 reason="0/5 nodes are unavailable: 5 Insufficient cpu." (16/31 resolved)
2026/05/06 17:00:23 Failure: pod=cspod-67 reason="pod group is not ready, 1 Pending, 1 minAvailable; Pending: 1 Unschedulable" (17/31 resolved)
2026/05/06 17:00:23 Failure: pod=cspod-64 reason="pod group is not ready, 1 Pending, 1 minAvailable; Pending: 1 Unschedulable" (18/31 resolved)
2026/05/06 17:00:23 Failure: pod=cspod-36 reason="pod group is not ready, 4 Pending, 4 minAvailable; Pending: 4 Unschedulable" (19/31 resolved)
2026/05/06 17:00:23 Failure: pod=cspod-53 reason="pod group is not ready, 3 Pending, 3 minAvailable; Pending: 3 Unschedulable. Origin reason is cspod-52: 0/5 nodes are unavailable: 5 Insufficient cpu." (20/31 resolved)
2026/05/06 17:00:23 Failure: pod=cspod-7 reason="0/5 nodes are unavailable: 5 Insufficient cpu." (21/31 resolved)
2026/05/06 17:00:23 Failure: pod=cspod-32 reason="pod group is not ready, 3 Pending, 3 minAvailable; Pending: 3 Unschedulable. Origin reason is cspod-30: 0/5 nodes are unavailable: 5 Insufficient cpu." (22/31 resolved)
2026/05/06 17:00:23 Failure: pod=cspod-60 reason="pod group is not ready, 1 Pending, 1 minAvailable; Pending: 1 Unschedulable" (23/31 resolved)
2026/05/06 17:00:23 Failure: pod=cspod-33 reason="pod group is not ready, 4 Pending, 4 minAvailable; Pending: 4 Unschedulable" (24/31 resolved)
2026/05/06 17:00:23 Failure: pod=cspod-29 reason="pod group is not ready, 1 Pending, 1 minAvailable; Pending: 1 Unschedulable" (25/31 resolved)
2026/05/06 17:00:23 Failure: pod=cspod-65 reason="pod group is not ready, 1 Pending, 1 minAvailable; Pending: 1 Unschedulable" (26/31 resolved)
2026/05/06 17:00:23 Failure: pod=cspod-54 reason="pod group is not ready, 3 Pending, 3 minAvailable; Pending: 3 Unschedulable. Origin reason is cspod-52: 0/5 nodes are unavailable: 5 Insufficient cpu." (27/31 resolved)
2026/05/06 17:00:23 Failure: pod=cspod-34 reason="pod group is not ready, 4 Pending, 4 minAvailable; Pending: 4 Unschedulable" (28/31 resolved)
2026/05/06 17:00:23 Binding: pod=cspod-28 -> node=csnode-4 (29/31 resolved)
2026/05/06 17:00:23 Binding: pod=cspod-26 -> node=csnode-2 (30/31 resolved)
2026/05/06 17:00:23 Binding: pod=cspod-27 -> node=csnode-0 (31/31 resolved)
2026/05/06 17:00:23 Round complete: 3 scheduled, 28 failed in 1.003726251s
2026/05/06 17:00:23 {"action":"HandleSchedule","durationMs":1004,"podCount":31,"result":"ok","roundId":"13","scheduled":3,"ts":"2026-05-06T17:00:23.448446155+01:00","unschedulable":28}
2026/05/06 17:00:23 {"action":"HandleSchedule","completedIds":4,"nodeCount":5,"phase":"start","podCount":28,"roundId":"14","ts":"2026-05-06T17:00:23.453531122+01:00"}
2026/05/06 17:00:23 {"action":"HandleSchedule","phase":"prep_done","podsCreated":28,"prepMs":0,"roundId":"14","staleDeleted":0,"ts":"2026-05-06T17:00:23.45398244+01:00"}
2026/05/06 17:00:23 Scheduling round started: expecting 28 decisions
2026/05/06 17:00:24 Failure: pod=cspod-7 reason="0/5 nodes are unavailable: 5 Insufficient cpu." (1/28 resolved)
2026/05/06 17:00:24 Failure: pod=cspod-9 reason="0/5 nodes are unavailable: 5 Insufficient cpu." (2/28 resolved)
2026/05/06 17:00:24 Failure: pod=cspod-34 reason="pod group is not ready, 4 Pending, 4 minAvailable; Pending: 4 Unschedulable" (3/28 resolved)
2026/05/06 17:00:24 Failure: pod=cspod-31 reason="pod group is not ready, 3 Pending, 3 minAvailable; Pending: 3 Unschedulable. Origin reason is cspod-30: 0/5 nodes are unavailable: 5 Insufficient cpu." (4/28 resolved)
2026/05/06 17:00:24 Failure: pod=cspod-60 reason="pod group is not ready, 1 Pending, 1 minAvailable; Pending: 1 Unschedulable" (5/28 resolved)
2026/05/06 17:00:24 Failure: pod=cspod-66 reason="pod group is not ready, 1 Pending, 1 minAvailable; Pending: 1 Unschedulable" (6/28 resolved)
2026/05/06 17:00:24 Failure: pod=cspod-63 reason="pod group is not ready, 1 Pending, 1 minAvailable; Pending: 1 Unschedulable" (7/28 resolved)
2026/05/06 17:00:24 Failure: pod=cspod-68 reason="pod group is not ready, 1 Pending, 1 minAvailable; Pending: 1 Unschedulable" (8/28 resolved)
2026/05/06 17:00:24 Failure: pod=cspod-69 reason="pod group is not ready, 1 Pending, 1 minAvailable; Pending: 1 Unschedulable" (9/28 resolved)
2026/05/06 17:00:24 Failure: pod=cspod-65 reason="pod group is not ready, 1 Pending, 1 minAvailable; Pending: 1 Unschedulable" (10/28 resolved)
2026/05/06 17:00:24 Failure: pod=cspod-67 reason="pod group is not ready, 1 Pending, 1 minAvailable; Pending: 1 Unschedulable" (11/28 resolved)
2026/05/06 17:00:24 Failure: pod=cspod-29 reason="pod group is not ready, 1 Pending, 1 minAvailable; Pending: 1 Unschedulable" (12/28 resolved)
2026/05/06 17:00:24 Failure: pod=cspod-61 reason="pod group is not ready, 1 Pending, 1 minAvailable; Pending: 1 Unschedulable" (13/28 resolved)
2026/05/06 17:00:24 Failure: pod=cspod-8 reason="0/5 nodes are unavailable: 5 Insufficient cpu." (14/28 resolved)
2026/05/06 17:00:24 Failure: pod=cspod-62 reason="pod group is not ready, 1 Pending, 1 minAvailable; Pending: 1 Unschedulable" (15/28 resolved)
2026/05/06 17:00:24 Failure: pod=cspod-32 reason="pod group is not ready, 3 Pending, 3 minAvailable; Pending: 3 Unschedulable. Origin reason is cspod-30: 0/5 nodes are unavailable: 5 Insufficient cpu." (16/28 resolved)
2026/05/06 17:00:24 Failure: pod=cspod-35 reason="pod group is not ready, 4 Pending, 4 minAvailable; Pending: 4 Unschedulable" (17/28 resolved)
2026/05/06 17:00:24 Failure: pod=cspod-64 reason="pod group is not ready, 1 Pending, 1 minAvailable; Pending: 1 Unschedulable" (18/28 resolved)
2026/05/06 17:00:24 Failure: pod=cspod-54 reason="pod group is not ready, 3 Pending, 3 minAvailable; Pending: 3 Unschedulable. Origin reason is cspod-52: 0/5 nodes are unavailable: 5 Insufficient cpu." (19/28 resolved)
2026/05/06 17:00:24 Failure: pod=cspod-30 reason="0/5 nodes are unavailable: 5 Insufficient cpu." (20/28 resolved)
2026/05/06 17:00:24 Failure: pod=cspod-52 reason="0/5 nodes are unavailable: 5 Insufficient cpu." (21/28 resolved)
2026/05/06 17:00:24 Failure: pod=cspod-36 reason="pod group is not ready, 4 Pending, 4 minAvailable; Pending: 4 Unschedulable" (22/28 resolved)
2026/05/06 17:00:24 Failure: pod=cspod-53 reason="pod group is not ready, 3 Pending, 3 minAvailable; Pending: 3 Unschedulable. Origin reason is cspod-52: 0/5 nodes are unavailable: 5 Insufficient cpu." (23/28 resolved)
2026/05/06 17:00:24 Failure: pod=cspod-33 reason="pod group is not ready, 4 Pending, 4 minAvailable; Pending: 4 Unschedulable" (24/28 resolved)
2026/05/06 17:00:24 Binding: pod=cspod-6 -> node=csnode-3 (25/28 resolved)
2026/05/06 17:00:24 Binding: pod=cspod-50 -> node=csnode-4 (26/28 resolved)
2026/05/06 17:00:24 Binding: pod=cspod-5 -> node=csnode-1 (27/28 resolved)
2026/05/06 17:00:24 Binding: pod=cspod-51 -> node=csnode-3 (28/28 resolved)
2026/05/06 17:00:24 Round complete: 4 scheduled, 24 failed in 1.011319771s
2026/05/06 17:00:24 {"action":"HandleSchedule","durationMs":1012,"podCount":28,"result":"ok","roundId":"14","scheduled":4,"ts":"2026-05-06T17:00:24.465355052+01:00","unschedulable":24}
2026/05/06 17:00:24 {"action":"HandleSchedule","completedIds":2,"nodeCount":5,"phase":"start","podCount":24,"roundId":"15","ts":"2026-05-06T17:00:24.469837903+01:00"}
2026/05/06 17:00:24 {"action":"HandleSchedule","phase":"prep_done","podsCreated":24,"prepMs":0,"roundId":"15","staleDeleted":0,"ts":"2026-05-06T17:00:24.470197937+01:00"}
2026/05/06 17:00:24 Scheduling round started: expecting 24 decisions
2026/05/06 17:00:25 Failure: pod=cspod-65 reason="pod group is not ready, 1 Pending, 1 minAvailable; Pending: 1 Unschedulable" (1/24 resolved)
2026/05/06 17:00:25 Failure: pod=cspod-64 reason="pod group is not ready, 1 Pending, 1 minAvailable; Pending: 1 Unschedulable" (2/24 resolved)
2026/05/06 17:00:25 Failure: pod=cspod-35 reason="pod group is not ready, 4 Pending, 4 minAvailable; Pending: 4 Unschedulable" (3/24 resolved)
2026/05/06 17:00:25 Binding: pod=cspod-8 -> node=csnode-2 (4/24 resolved)
2026/05/06 17:00:25 Failure: pod=cspod-61 reason="pod group is not ready, 1 Pending, 1 minAvailable; Pending: 1 Unschedulable" (5/24 resolved)
2026/05/06 17:00:25 Failure: pod=cspod-66 reason="pod group is not ready, 1 Pending, 1 minAvailable; Pending: 1 Unschedulable" (6/24 resolved)
2026/05/06 17:00:25 Binding: pod=cspod-7 -> node=csnode-0 (7/24 resolved)
2026/05/06 17:00:25 Failure: pod=cspod-29 reason="pod group is not ready, 1 Pending, 1 minAvailable; Pending: 1 Unschedulable" (8/24 resolved)
2026/05/06 17:00:25 Failure: pod=cspod-62 reason="pod group is not ready, 1 Pending, 1 minAvailable; Pending: 1 Unschedulable" (9/24 resolved)
2026/05/06 17:00:25 Failure: pod=cspod-67 reason="pod group is not ready, 1 Pending, 1 minAvailable; Pending: 1 Unschedulable" (10/24 resolved)
2026/05/06 17:00:25 Failure: pod=cspod-30 reason="0/5 nodes are unavailable: 5 Insufficient cpu." (11/24 resolved)
2026/05/06 17:00:25 Failure: pod=cspod-36 reason="pod group is not ready, 4 Pending, 4 minAvailable; Pending: 4 Unschedulable" (12/24 resolved)
2026/05/06 17:00:25 Failure: pod=cspod-54 reason="pod group is not ready, 3 Pending, 3 minAvailable; Pending: 3 Unschedulable. Origin reason is cspod-52: 0/5 nodes are unavailable: 5 Insufficient cpu." (13/24 resolved)
2026/05/06 17:00:25 Failure: pod=cspod-68 reason="pod group is not ready, 1 Pending, 1 minAvailable; Pending: 1 Unschedulable" (14/24 resolved)
2026/05/06 17:00:25 Failure: pod=cspod-9 reason="0/5 nodes are unavailable: 5 Insufficient cpu." (15/24 resolved)
2026/05/06 17:00:25 Failure: pod=cspod-63 reason="pod group is not ready, 1 Pending, 1 minAvailable; Pending: 1 Unschedulable" (16/24 resolved)
2026/05/06 17:00:25 Failure: pod=cspod-60 reason="pod group is not ready, 1 Pending, 1 minAvailable; Pending: 1 Unschedulable" (17/24 resolved)
2026/05/06 17:00:25 Failure: pod=cspod-31 reason="pod group is not ready, 3 Pending, 3 minAvailable; Pending: 3 Unschedulable. Origin reason is cspod-30: 0/5 nodes are unavailable: 5 Insufficient cpu." (18/24 resolved)
2026/05/06 17:00:25 Failure: pod=cspod-33 reason="pod group is not ready, 4 Pending, 4 minAvailable; Pending: 4 Unschedulable" (19/24 resolved)
2026/05/06 17:00:25 Failure: pod=cspod-52 reason="0/5 nodes are unavailable: 5 Insufficient cpu." (20/24 resolved)
2026/05/06 17:00:25 Failure: pod=cspod-69 reason="pod group is not ready, 1 Pending, 1 minAvailable; Pending: 1 Unschedulable" (21/24 resolved)
2026/05/06 17:00:25 Failure: pod=cspod-34 reason="pod group is not ready, 4 Pending, 4 minAvailable; Pending: 4 Unschedulable" (22/24 resolved)
2026/05/06 17:00:25 Failure: pod=cspod-32 reason="pod group is not ready, 3 Pending, 3 minAvailable; Pending: 3 Unschedulable. Origin reason is cspod-30: 0/5 nodes are unavailable: 5 Insufficient cpu." (23/24 resolved)
2026/05/06 17:00:25 Failure: pod=cspod-53 reason="pod group is not ready, 3 Pending, 3 minAvailable; Pending: 3 Unschedulable. Origin reason is cspod-52: 0/5 nodes are unavailable: 5 Insufficient cpu." (24/24 resolved)
2026/05/06 17:00:25 Round complete: 2 scheduled, 22 failed in 1.003330392s
2026/05/06 17:00:25 {"action":"HandleSchedule","durationMs":1003,"podCount":24,"result":"ok","roundId":"15","scheduled":2,"ts":"2026-05-06T17:00:25.47357985+01:00","unschedulable":22}
2026/05/06 17:00:25 {"action":"HandleSchedule","completedIds":1,"nodeCount":5,"phase":"start","podCount":22,"roundId":"16","ts":"2026-05-06T17:00:25.479944755+01:00"}
2026/05/06 17:00:25 {"action":"HandleSchedule","phase":"prep_done","podsCreated":22,"prepMs":0,"roundId":"16","staleDeleted":0,"ts":"2026-05-06T17:00:25.480242407+01:00"}
2026/05/06 17:00:25 Scheduling round started: expecting 22 decisions
2026/05/06 17:00:26 Failure: pod=cspod-61 reason="pod group is not ready, 1 Pending, 1 minAvailable; Pending: 1 Unschedulable" (1/22 resolved)
2026/05/06 17:00:26 Failure: pod=cspod-60 reason="pod group is not ready, 1 Pending, 1 minAvailable; Pending: 1 Unschedulable" (2/22 resolved)
2026/05/06 17:00:26 Failure: pod=cspod-67 reason="pod group is not ready, 1 Pending, 1 minAvailable; Pending: 1 Unschedulable" (3/22 resolved)
2026/05/06 17:00:26 Failure: pod=cspod-66 reason="pod group is not ready, 1 Pending, 1 minAvailable; Pending: 1 Unschedulable" (4/22 resolved)
2026/05/06 17:00:26 Failure: pod=cspod-62 reason="pod group is not ready, 1 Pending, 1 minAvailable; Pending: 1 Unschedulable" (5/22 resolved)
2026/05/06 17:00:26 Failure: pod=cspod-64 reason="pod group is not ready, 1 Pending, 1 minAvailable; Pending: 1 Unschedulable" (6/22 resolved)
2026/05/06 17:00:26 Failure: pod=cspod-69 reason="pod group is not ready, 1 Pending, 1 minAvailable; Pending: 1 Unschedulable" (7/22 resolved)
2026/05/06 17:00:26 Failure: pod=cspod-52 reason="0/5 nodes are unavailable: 5 Insufficient cpu." (8/22 resolved)
2026/05/06 17:00:26 Failure: pod=cspod-68 reason="pod group is not ready, 1 Pending, 1 minAvailable; Pending: 1 Unschedulable" (9/22 resolved)
2026/05/06 17:00:26 Failure: pod=cspod-63 reason="pod group is not ready, 1 Pending, 1 minAvailable; Pending: 1 Unschedulable" (10/22 resolved)
2026/05/06 17:00:26 Failure: pod=cspod-29 reason="pod group is not ready, 1 Pending, 1 minAvailable; Pending: 1 Unschedulable" (11/22 resolved)
2026/05/06 17:00:26 Failure: pod=cspod-65 reason="pod group is not ready, 1 Pending, 1 minAvailable; Pending: 1 Unschedulable" (12/22 resolved)
2026/05/06 17:00:26 Failure: pod=cspod-35 reason="pod group is not ready, 4 Pending, 4 minAvailable; Pending: 4 Unschedulable" (13/22 resolved)
2026/05/06 17:00:26 Failure: pod=cspod-31 reason="pod group is not ready, 3 Pending, 3 minAvailable; Pending: 3 Unschedulable. Origin reason is cspod-30: 0/5 nodes are unavailable: 5 Insufficient cpu." (14/22 resolved)
2026/05/06 17:00:26 Failure: pod=cspod-53 reason="pod group is not ready, 3 Pending, 3 minAvailable; Pending: 3 Unschedulable. Origin reason is cspod-52: 0/5 nodes are unavailable: 5 Insufficient cpu." (15/22 resolved)
2026/05/06 17:00:26 Failure: pod=cspod-36 reason="pod group is not ready, 4 Pending, 4 minAvailable; Pending: 4 Unschedulable" (16/22 resolved)
2026/05/06 17:00:26 Failure: pod=cspod-54 reason="pod group is not ready, 3 Pending, 3 minAvailable; Pending: 3 Unschedulable. Origin reason is cspod-52: 0/5 nodes are unavailable: 5 Insufficient cpu." (17/22 resolved)
2026/05/06 17:00:26 Failure: pod=cspod-32 reason="pod group is not ready, 3 Pending, 3 minAvailable; Pending: 3 Unschedulable. Origin reason is cspod-30: 0/5 nodes are unavailable: 5 Insufficient cpu." (18/22 resolved)
2026/05/06 17:00:26 Failure: pod=cspod-33 reason="pod group is not ready, 4 Pending, 4 minAvailable; Pending: 4 Unschedulable" (19/22 resolved)
2026/05/06 17:00:26 Failure: pod=cspod-30 reason="0/5 nodes are unavailable: 5 Insufficient cpu." (20/22 resolved)
2026/05/06 17:00:26 Failure: pod=cspod-34 reason="pod group is not ready, 4 Pending, 4 minAvailable; Pending: 4 Unschedulable" (21/22 resolved)
2026/05/06 17:00:26 Binding: pod=cspod-9 -> node=csnode-1 (22/22 resolved)
2026/05/06 17:00:26 Round complete: 1 scheduled, 21 failed in 1.014183866s
2026/05/06 17:00:26 {"action":"HandleSchedule","durationMs":1014,"podCount":22,"result":"ok","roundId":"16","scheduled":1,"ts":"2026-05-06T17:00:26.494511556+01:00","unschedulable":21}
2026/05/06 17:00:26 {"action":"HandleSchedule","completedIds":2,"nodeCount":5,"phase":"start","podCount":21,"roundId":"17","ts":"2026-05-06T17:00:26.50114661+01:00"}
2026/05/06 17:00:26 {"action":"HandleSchedule","phase":"prep_done","podsCreated":21,"prepMs":0,"roundId":"17","staleDeleted":0,"ts":"2026-05-06T17:00:26.501498683+01:00"}
2026/05/06 17:00:26 Scheduling round started: expecting 21 decisions
2026/05/06 17:00:27 Failure: pod=cspod-61 reason="pod group is not ready, 1 Pending, 1 minAvailable; Pending: 1 Unschedulable" (1/21 resolved)
2026/05/06 17:00:27 Failure: pod=cspod-65 reason="pod group is not ready, 1 Pending, 1 minAvailable; Pending: 1 Unschedulable" (2/21 resolved)
2026/05/06 17:00:27 Failure: pod=cspod-66 reason="pod group is not ready, 1 Pending, 1 minAvailable; Pending: 1 Unschedulable" (3/21 resolved)
2026/05/06 17:00:27 Failure: pod=cspod-67 reason="pod group is not ready, 1 Pending, 1 minAvailable; Pending: 1 Unschedulable" (4/21 resolved)
2026/05/06 17:00:27 Failure: pod=cspod-62 reason="pod group is not ready, 1 Pending, 1 minAvailable; Pending: 1 Unschedulable" (5/21 resolved)
2026/05/06 17:00:27 Failure: pod=cspod-34 reason="pod group is not ready, 4 Pending, 4 minAvailable; Pending: 4 Unschedulable" (6/21 resolved)
2026/05/06 17:00:27 Failure: pod=cspod-68 reason="pod group is not ready, 1 Pending, 1 minAvailable; Pending: 1 Unschedulable" (7/21 resolved)
2026/05/06 17:00:27 Failure: pod=cspod-64 reason="pod group is not ready, 1 Pending, 1 minAvailable; Pending: 1 Unschedulable" (8/21 resolved)
2026/05/06 17:00:27 Failure: pod=cspod-69 reason="pod group is not ready, 1 Pending, 1 minAvailable; Pending: 1 Unschedulable" (9/21 resolved)
2026/05/06 17:00:27 Failure: pod=cspod-29 reason="pod group is not ready, 1 Pending, 1 minAvailable; Pending: 1 Unschedulable" (10/21 resolved)
2026/05/06 17:00:27 Failure: pod=cspod-60 reason="pod group is not ready, 1 Pending, 1 minAvailable; Pending: 1 Unschedulable" (11/21 resolved)
2026/05/06 17:00:27 Failure: pod=cspod-63 reason="pod group is not ready, 1 Pending, 1 minAvailable; Pending: 1 Unschedulable" (12/21 resolved)
2026/05/06 17:00:27 Failure: pod=cspod-35 reason="pod group is not ready, 4 Pending, 4 minAvailable; Pending: 4 Unschedulable" (13/21 resolved)
2026/05/06 17:00:27 Failure: pod=cspod-36 reason="pod group is not ready, 4 Pending, 4 minAvailable; Pending: 4 Unschedulable" (14/21 resolved)
2026/05/06 17:00:27 Failure: pod=cspod-54 reason="0/5 nodes are unavailable: 5 Insufficient cpu." (15/21 resolved)
2026/05/06 17:00:27 Failure: pod=cspod-33 reason="pod group is not ready, 4 Pending, 4 minAvailable; Pending: 4 Unschedulable" (16/21 resolved)
2026/05/06 17:00:27 Failure: pod=cspod-32 reason="0/5 nodes are unavailable: 5 Insufficient cpu." (17/21 resolved)
2026/05/06 17:00:30 STALL EXIT: no progress for 2s — 0 scheduled, 17 failed, 4 still pending (returning partial)
2026/05/06 17:00:30 {"action":"HandleSchedule","durationMs":4009,"podCount":21,"result":"timeout_partial","roundId":"17","scheduled":0,"ts":"2026-05-06T17:00:30.510963802+01:00","unschedulable":21}
2026/05/06 17:00:30 {"action":"HandleSchedule","durationMs":4009,"podCount":21,"result":"ok","roundId":"17","scheduled":0,"ts":"2026-05-06T17:00:30.510989385+01:00","unschedulable":21}
2026/05/06 17:00:30 {"action":"HandleSchedule","completedIds":2,"nodeCount":5,"phase":"start","podCount":21,"roundId":"18","ts":"2026-05-06T17:00:30.522068529+01:00"}
2026/05/06 17:00:30 {"action":"HandleSchedule","phase":"prep_done","podsCreated":21,"prepMs":0,"roundId":"18","staleDeleted":0,"ts":"2026-05-06T17:00:30.522422447+01:00"}
2026/05/06 17:00:30 Scheduling round started: expecting 21 decisions
2026/05/06 17:00:31 Failure: pod=cspod-29 reason="pod group is not ready, 1 Pending, 1 minAvailable; Pending: 1 Unschedulable" (1/21 resolved)
2026/05/06 17:00:31 Failure: pod=cspod-64 reason="pod group is not ready, 1 Pending, 1 minAvailable; Pending: 1 Unschedulable" (2/21 resolved)
2026/05/06 17:00:31 Failure: pod=cspod-61 reason="pod group is not ready, 1 Pending, 1 minAvailable; Pending: 1 Unschedulable" (3/21 resolved)
2026/05/06 17:00:31 Failure: pod=cspod-36 reason="pod group is not ready, 4 Pending, 4 minAvailable; Pending: 4 Unschedulable" (4/21 resolved)
2026/05/06 17:00:31 Failure: pod=cspod-68 reason="pod group is not ready, 1 Pending, 1 minAvailable; Pending: 1 Unschedulable" (5/21 resolved)
2026/05/06 17:00:31 Failure: pod=cspod-67 reason="pod group is not ready, 1 Pending, 1 minAvailable; Pending: 1 Unschedulable" (6/21 resolved)
2026/05/06 17:00:31 Failure: pod=cspod-65 reason="pod group is not ready, 1 Pending, 1 minAvailable; Pending: 1 Unschedulable" (7/21 resolved)
2026/05/06 17:00:31 Failure: pod=cspod-63 reason="pod group is not ready, 1 Pending, 1 minAvailable; Pending: 1 Unschedulable" (8/21 resolved)
2026/05/06 17:00:31 Failure: pod=cspod-69 reason="pod group is not ready, 1 Pending, 1 minAvailable; Pending: 1 Unschedulable" (9/21 resolved)
2026/05/06 17:00:31 Failure: pod=cspod-60 reason="pod group is not ready, 1 Pending, 1 minAvailable; Pending: 1 Unschedulable" (10/21 resolved)
2026/05/06 17:00:31 Failure: pod=cspod-33 reason="pod group is not ready, 4 Pending, 4 minAvailable; Pending: 4 Unschedulable" (11/21 resolved)
2026/05/06 17:00:31 Failure: pod=cspod-62 reason="pod group is not ready, 1 Pending, 1 minAvailable; Pending: 1 Unschedulable" (12/21 resolved)
2026/05/06 17:00:31 Failure: pod=cspod-66 reason="pod group is not ready, 1 Pending, 1 minAvailable; Pending: 1 Unschedulable" (13/21 resolved)
2026/05/06 17:00:31 Failure: pod=cspod-53 reason="0/5 nodes are unavailable: 5 Insufficient cpu." (14/21 resolved)
2026/05/06 17:00:31 Failure: pod=cspod-34 reason="pod group is not ready, 4 Pending, 4 minAvailable; Pending: 4 Unschedulable" (15/21 resolved)
2026/05/06 17:00:31 Failure: pod=cspod-35 reason="pod group is not ready, 4 Pending, 4 minAvailable; Pending: 4 Unschedulable" (16/21 resolved)
2026/05/06 17:00:31 Failure: pod=cspod-54 reason="pod group is not ready, 3 Pending, 3 minAvailable; Pending: 1 Schedulable, 2 Unschedulable. Origin reason is cspod-53: 0/5 nodes are unavailable: 5 Insufficient cpu." (17/21 resolved)
2026/05/06 17:00:31 Binding: pod=cspod-32 -> node=csnode-3 (18/21 resolved)
2026/05/06 17:00:31 Binding: pod=cspod-30 -> node=csnode-4 (19/21 resolved)
2026/05/06 17:00:31 Binding: pod=cspod-31 -> node=csnode-1 (20/21 resolved)
2026/05/06 17:00:34 STALL EXIT: no progress for 2s — 3 scheduled, 17 failed, 1 still pending (returning partial)
2026/05/06 17:00:34 {"action":"HandleSchedule","durationMs":4042,"podCount":21,"result":"timeout_partial","roundId":"18","scheduled":3,"ts":"2026-05-06T17:00:34.564363784+01:00","unschedulable":18}
2026/05/06 17:00:34 {"action":"HandleSchedule","durationMs":4042,"podCount":21,"result":"ok","roundId":"18","scheduled":3,"ts":"2026-05-06T17:00:34.564388219+01:00","unschedulable":18}
2026/05/06 17:00:34 {"action":"HandleSchedule","completedIds":2,"nodeCount":5,"phase":"start","podCount":18,"roundId":"19","ts":"2026-05-06T17:00:34.569414676+01:00"}
2026/05/06 17:00:34 {"action":"HandleSchedule","phase":"prep_done","podsCreated":18,"prepMs":1,"roundId":"19","staleDeleted":0,"ts":"2026-05-06T17:00:34.570526604+01:00"}
2026/05/06 17:00:34 Scheduling round started: expecting 18 decisions
2026/05/06 17:00:35 Failure: pod=cspod-69 reason="pod group is not ready, 1 Pending, 1 minAvailable; Pending: 1 Unschedulable" (1/18 resolved)
2026/05/06 17:00:35 Failure: pod=cspod-61 reason="pod group is not ready, 1 Pending, 1 minAvailable; Pending: 1 Unschedulable" (2/18 resolved)
2026/05/06 17:00:35 Failure: pod=cspod-64 reason="pod group is not ready, 1 Pending, 1 minAvailable; Pending: 1 Unschedulable" (3/18 resolved)
2026/05/06 17:00:35 Failure: pod=cspod-65 reason="pod group is not ready, 1 Pending, 1 minAvailable; Pending: 1 Unschedulable" (4/18 resolved)
2026/05/06 17:00:35 Failure: pod=cspod-68 reason="pod group is not ready, 1 Pending, 1 minAvailable; Pending: 1 Unschedulable" (5/18 resolved)
2026/05/06 17:00:35 Failure: pod=cspod-34 reason="pod group is not ready, 4 Pending, 4 minAvailable; Pending: 4 Unschedulable" (6/18 resolved)
2026/05/06 17:00:35 Failure: pod=cspod-62 reason="pod group is not ready, 1 Pending, 1 minAvailable; Pending: 1 Unschedulable" (7/18 resolved)
2026/05/06 17:00:35 Failure: pod=cspod-67 reason="pod group is not ready, 1 Pending, 1 minAvailable; Pending: 1 Unschedulable" (8/18 resolved)
2026/05/06 17:00:35 Failure: pod=cspod-66 reason="pod group is not ready, 1 Pending, 1 minAvailable; Pending: 1 Unschedulable" (9/18 resolved)
2026/05/06 17:00:35 Failure: pod=cspod-63 reason="pod group is not ready, 1 Pending, 1 minAvailable; Pending: 1 Unschedulable" (10/18 resolved)
2026/05/06 17:00:35 Failure: pod=cspod-35 reason="pod group is not ready, 4 Pending, 4 minAvailable; Pending: 4 Unschedulable" (11/18 resolved)
2026/05/06 17:00:35 Failure: pod=cspod-36 reason="pod group is not ready, 4 Pending, 4 minAvailable; Pending: 4 Unschedulable" (12/18 resolved)
2026/05/06 17:00:35 Failure: pod=cspod-54 reason="0/5 nodes are unavailable: 5 Insufficient cpu." (13/18 resolved)
2026/05/06 17:00:35 Failure: pod=cspod-33 reason="pod group is not ready, 4 Pending, 4 minAvailable; Pending: 4 Unschedulable" (14/18 resolved)
2026/05/06 17:00:35 Binding: pod=cspod-60 -> node=csnode-3 (15/18 resolved)
2026/05/06 17:00:35 Binding: pod=cspod-29 -> node=csnode-2 (16/18 resolved)
2026/05/06 17:00:36 Failure: pod=cspod-54 reason="pod group is not ready, 3 Pending, 3 minAvailable; Pending: 1 Schedulable, 2 Unschedulable. Origin reason is cspod-53: 0/5 nodes are unavailable: 5 Insufficient cpu." (17/18 resolved)
2026/05/06 17:00:36 Failure: pod=cspod-53 reason="0/5 nodes are unavailable: 5 Insufficient cpu." (18/18 resolved)
2026/05/06 17:00:36 Round complete: 2 scheduled, 16 failed in 1.945516215s
2026/05/06 17:00:36 {"action":"HandleSchedule","durationMs":1946,"podCount":18,"result":"ok","roundId":"19","scheduled":2,"ts":"2026-05-06T17:00:36.51612332+01:00","unschedulable":16}
2026/05/06 17:00:36 {"action":"HandleSchedule","completedIds":1,"nodeCount":5,"phase":"start","podCount":16,"roundId":"20","ts":"2026-05-06T17:00:36.522808173+01:00"}
2026/05/06 17:00:36 {"action":"HandleSchedule","phase":"prep_done","podsCreated":16,"prepMs":0,"roundId":"20","staleDeleted":0,"ts":"2026-05-06T17:00:36.523092826+01:00"}
2026/05/06 17:00:36 Scheduling round started: expecting 16 decisions
2026/05/06 17:00:37 Failure: pod=cspod-65 reason="pod group is not ready, 1 Pending, 1 minAvailable; Pending: 1 Unschedulable" (1/16 resolved)
2026/05/06 17:00:37 Failure: pod=cspod-63 reason="pod group is not ready, 1 Pending, 1 minAvailable; Pending: 1 Unschedulable" (2/16 resolved)
2026/05/06 17:00:37 Failure: pod=cspod-62 reason="pod group is not ready, 1 Pending, 1 minAvailable; Pending: 1 Unschedulable" (3/16 resolved)
2026/05/06 17:00:37 Failure: pod=cspod-66 reason="pod group is not ready, 1 Pending, 1 minAvailable; Pending: 1 Unschedulable" (4/16 resolved)
2026/05/06 17:00:37 Failure: pod=cspod-69 reason="pod group is not ready, 1 Pending, 1 minAvailable; Pending: 1 Unschedulable" (5/16 resolved)
2026/05/06 17:00:37 Failure: pod=cspod-67 reason="pod group is not ready, 1 Pending, 1 minAvailable; Pending: 1 Unschedulable" (6/16 resolved)
2026/05/06 17:00:37 Failure: pod=cspod-68 reason="pod group is not ready, 1 Pending, 1 minAvailable; Pending: 1 Unschedulable" (7/16 resolved)
2026/05/06 17:00:37 Failure: pod=cspod-33 reason="pod group is not ready, 4 Pending, 4 minAvailable; Pending: 4 Unschedulable" (8/16 resolved)
2026/05/06 17:00:37 Failure: pod=cspod-64 reason="pod group is not ready, 1 Pending, 1 minAvailable; Pending: 1 Unschedulable" (9/16 resolved)
2026/05/06 17:00:37 Failure: pod=cspod-54 reason="0/5 nodes are unavailable: 5 Insufficient cpu." (10/16 resolved)
2026/05/06 17:00:37 Failure: pod=cspod-34 reason="pod group is not ready, 4 Pending, 4 minAvailable; Pending: 4 Unschedulable" (11/16 resolved)
2026/05/06 17:00:37 Failure: pod=cspod-35 reason="pod group is not ready, 4 Pending, 4 minAvailable; Pending: 4 Unschedulable" (12/16 resolved)
2026/05/06 17:00:37 Failure: pod=cspod-36 reason="pod group is not ready, 4 Pending, 4 minAvailable; Pending: 4 Unschedulable" (13/16 resolved)
2026/05/06 17:00:37 Binding: pod=cspod-61 -> node=csnode-1 (14/16 resolved)
2026/05/06 17:00:38 Failure: pod=cspod-53 reason="0/5 nodes are unavailable: 5 Insufficient cpu." (15/16 resolved)
2026/05/06 17:00:38 Failure: pod=cspod-54 reason="pod group is not ready, 3 Pending, 3 minAvailable; Pending: 1 Schedulable, 2 Unschedulable. Origin reason is cspod-53: 0/5 nodes are unavailable: 5 Insufficient cpu." (16/16 resolved)
2026/05/06 17:00:38 Round complete: 1 scheduled, 15 failed in 2.002852312s
2026/05/06 17:00:38 {"action":"HandleSchedule","durationMs":2003,"podCount":16,"result":"ok","roundId":"20","scheduled":1,"ts":"2026-05-06T17:00:38.526083883+01:00","unschedulable":15}
2026/05/06 17:00:38 {"action":"HandleSchedule","completedIds":1,"nodeCount":5,"phase":"start","podCount":15,"roundId":"21","ts":"2026-05-06T17:00:38.531259358+01:00"}
2026/05/06 17:00:38 {"action":"HandleSchedule","phase":"prep_done","podsCreated":15,"prepMs":0,"roundId":"21","staleDeleted":0,"ts":"2026-05-06T17:00:38.531510257+01:00"}
2026/05/06 17:00:38 Scheduling round started: expecting 15 decisions
2026/05/06 17:00:39 Failure: pod=cspod-66 reason="pod group is not ready, 1 Pending, 1 minAvailable; Pending: 1 Unschedulable" (1/15 resolved)
2026/05/06 17:00:39 Failure: pod=cspod-36 reason="pod group is not ready, 4 Pending, 4 minAvailable; Pending: 4 Unschedulable" (2/15 resolved)
2026/05/06 17:00:39 Failure: pod=cspod-67 reason="pod group is not ready, 1 Pending, 1 minAvailable; Pending: 1 Unschedulable" (3/15 resolved)
2026/05/06 17:00:39 Failure: pod=cspod-65 reason="pod group is not ready, 1 Pending, 1 minAvailable; Pending: 1 Unschedulable" (4/15 resolved)
2026/05/06 17:00:39 Failure: pod=cspod-63 reason="pod group is not ready, 1 Pending, 1 minAvailable; Pending: 1 Unschedulable" (5/15 resolved)
2026/05/06 17:00:39 Failure: pod=cspod-69 reason="pod group is not ready, 1 Pending, 1 minAvailable; Pending: 1 Unschedulable" (6/15 resolved)
2026/05/06 17:00:39 Failure: pod=cspod-68 reason="pod group is not ready, 1 Pending, 1 minAvailable; Pending: 1 Unschedulable" (7/15 resolved)
2026/05/06 17:00:39 Failure: pod=cspod-64 reason="pod group is not ready, 1 Pending, 1 minAvailable; Pending: 1 Unschedulable" (8/15 resolved)
2026/05/06 17:00:39 Failure: pod=cspod-33 reason="pod group is not ready, 4 Pending, 4 minAvailable; Pending: 4 Unschedulable" (9/15 resolved)
2026/05/06 17:00:39 Failure: pod=cspod-54 reason="0/5 nodes are unavailable: 5 Insufficient cpu." (10/15 resolved)
2026/05/06 17:00:39 Failure: pod=cspod-34 reason="pod group is not ready, 4 Pending, 4 minAvailable; Pending: 4 Unschedulable" (11/15 resolved)
2026/05/06 17:00:39 Failure: pod=cspod-35 reason="pod group is not ready, 4 Pending, 4 minAvailable; Pending: 4 Unschedulable" (12/15 resolved)
2026/05/06 17:00:39 Binding: pod=cspod-62 -> node=csnode-0 (13/15 resolved)
2026/05/06 17:00:40 Failure: pod=cspod-53 reason="0/5 nodes are unavailable: 5 Insufficient cpu." (14/15 resolved)
2026/05/06 17:00:40 Failure: pod=cspod-54 reason="pod group is not ready, 3 Pending, 3 minAvailable; Pending: 1 Schedulable, 2 Unschedulable. Origin reason is cspod-53: 0/5 nodes are unavailable: 5 Insufficient cpu." (15/15 resolved)
2026/05/06 17:00:40 Round complete: 1 scheduled, 14 failed in 2.003790426s
2026/05/06 17:00:40 {"action":"HandleSchedule","durationMs":2004,"podCount":15,"result":"ok","roundId":"21","scheduled":1,"ts":"2026-05-06T17:00:40.535408888+01:00","unschedulable":14}
2026/05/06 17:00:40 {"action":"HandleSchedule","completedIds":2,"nodeCount":5,"phase":"start","podCount":14,"roundId":"22","ts":"2026-05-06T17:00:40.539261368+01:00"}
2026/05/06 17:00:40 {"action":"HandleSchedule","phase":"prep_done","podsCreated":14,"prepMs":0,"roundId":"22","staleDeleted":0,"ts":"2026-05-06T17:00:40.53948833+01:00"}
2026/05/06 17:00:40 Scheduling round started: expecting 14 decisions
2026/05/06 17:00:41 Binding: pod=cspod-54 -> node=csnode-4 (1/14 resolved)
2026/05/06 17:00:41 Binding: pod=cspod-52 -> node=csnode-2 (2/14 resolved)
2026/05/06 17:00:41 Binding: pod=cspod-53 -> node=csnode-0 (3/14 resolved)
2026/05/06 17:00:41 Failure: pod=cspod-65 reason="0/5 nodes are unavailable: 5 Insufficient cpu." (4/14 resolved)
2026/05/06 17:00:41 Failure: pod=cspod-67 reason="0/5 nodes are unavailable: 5 Insufficient cpu." (5/14 resolved)
2026/05/06 17:00:41 Failure: pod=cspod-35 reason="pod group is not ready, 4 Pending, 4 minAvailable; Pending: 4 Unschedulable. Origin reason is cspod-33: 0/5 nodes are unavailable: 5 Insufficient cpu." (6/14 resolved)
2026/05/06 17:00:41 Failure: pod=cspod-69 reason="0/5 nodes are unavailable: 5 Insufficient cpu." (7/14 resolved)
2026/05/06 17:00:41 Failure: pod=cspod-68 reason="0/5 nodes are unavailable: 5 Insufficient cpu." (8/14 resolved)
2026/05/06 17:00:41 Failure: pod=cspod-36 reason="pod group is not ready, 4 Pending, 4 minAvailable; Pending: 4 Unschedulable. Origin reason is cspod-33: 0/5 nodes are unavailable: 5 Insufficient cpu." (9/14 resolved)
2026/05/06 17:00:41 Failure: pod=cspod-63 reason="0/5 nodes are unavailable: 5 Insufficient cpu." (10/14 resolved)
2026/05/06 17:00:41 Failure: pod=cspod-66 reason="0/5 nodes are unavailable: 5 Insufficient cpu." (11/14 resolved)
2026/05/06 17:00:41 Failure: pod=cspod-64 reason="0/5 nodes are unavailable: 5 Insufficient cpu." (12/14 resolved)
2026/05/06 17:00:41 Failure: pod=cspod-33 reason="0/5 nodes are unavailable: 5 Insufficient cpu." (13/14 resolved)
2026/05/06 17:00:41 Failure: pod=cspod-34 reason="pod group is not ready, 4 Pending, 4 minAvailable; Pending: 4 Unschedulable. Origin reason is cspod-33: 0/5 nodes are unavailable: 5 Insufficient cpu." (14/14 resolved)
2026/05/06 17:00:41 Round complete: 3 scheduled, 11 failed in 1.001472099s
2026/05/06 17:00:41 {"action":"HandleSchedule","durationMs":1001,"podCount":14,"result":"ok","roundId":"22","scheduled":3,"ts":"2026-05-06T17:00:41.54107816+01:00","unschedulable":11}
2026/05/06 17:00:41 {"action":"HandleSchedule","completedIds":2,"nodeCount":5,"phase":"start","podCount":11,"roundId":"23","ts":"2026-05-06T17:00:41.548232364+01:00"}
2026/05/06 17:00:41 {"action":"HandleSchedule","phase":"prep_done","podsCreated":11,"prepMs":0,"roundId":"23","staleDeleted":0,"ts":"2026-05-06T17:00:41.548500066+01:00"}
2026/05/06 17:00:41 Scheduling round started: expecting 11 decisions
2026/05/06 17:00:42 Failure: pod=cspod-66 reason="0/5 nodes are unavailable: 5 Insufficient cpu." (1/11 resolved)
2026/05/06 17:00:42 Failure: pod=cspod-67 reason="0/5 nodes are unavailable: 5 Insufficient cpu." (2/11 resolved)
2026/05/06 17:00:42 Failure: pod=cspod-65 reason="0/5 nodes are unavailable: 5 Insufficient cpu." (3/11 resolved)
2026/05/06 17:00:42 Failure: pod=cspod-34 reason="pod group is not ready, 4 Pending, 4 minAvailable; Pending: 4 Unschedulable. Origin reason is cspod-33: 0/5 nodes are unavailable: 5 Insufficient cpu." (4/11 resolved)
2026/05/06 17:00:42 Failure: pod=cspod-69 reason="0/5 nodes are unavailable: 5 Insufficient cpu." (5/11 resolved)
2026/05/06 17:00:42 Failure: pod=cspod-68 reason="0/5 nodes are unavailable: 5 Insufficient cpu." (6/11 resolved)
2026/05/06 17:00:42 Failure: pod=cspod-35 reason="pod group is not ready, 4 Pending, 4 minAvailable; Pending: 4 Unschedulable. Origin reason is cspod-33: 0/5 nodes are unavailable: 5 Insufficient cpu." (7/11 resolved)
2026/05/06 17:00:42 Failure: pod=cspod-36 reason="pod group is not ready, 4 Pending, 4 minAvailable; Pending: 4 Unschedulable. Origin reason is cspod-33: 0/5 nodes are unavailable: 5 Insufficient cpu." (8/11 resolved)
2026/05/06 17:00:42 Failure: pod=cspod-33 reason="0/5 nodes are unavailable: 5 Insufficient cpu." (9/11 resolved)
2026/05/06 17:00:42 Binding: pod=cspod-64 -> node=csnode-1 (10/11 resolved)
2026/05/06 17:00:42 Binding: pod=cspod-63 -> node=csnode-4 (11/11 resolved)
2026/05/06 17:00:42 Round complete: 2 scheduled, 9 failed in 1.009956514s
2026/05/06 17:00:42 {"action":"HandleSchedule","durationMs":1010,"podCount":11,"result":"ok","roundId":"23","scheduled":2,"ts":"2026-05-06T17:00:42.558503866+01:00","unschedulable":9}
2026/05/06 17:00:42 {"action":"HandleSchedule","completedIds":2,"nodeCount":5,"phase":"start","podCount":9,"roundId":"24","ts":"2026-05-06T17:00:42.563089524+01:00"}
2026/05/06 17:00:42 {"action":"HandleSchedule","phase":"prep_done","podsCreated":9,"prepMs":0,"roundId":"24","staleDeleted":0,"ts":"2026-05-06T17:00:42.563295045+01:00"}
2026/05/06 17:00:42 Scheduling round started: expecting 9 decisions
2026/05/06 17:00:43 Failure: pod=cspod-67 reason="0/5 nodes are unavailable: 5 Insufficient cpu." (1/9 resolved)
2026/05/06 17:00:43 Failure: pod=cspod-36 reason="pod group is not ready, 4 Pending, 4 minAvailable; Pending: 4 Unschedulable. Origin reason is cspod-33: 0/5 nodes are unavailable: 5 Insufficient cpu." (2/9 resolved)
2026/05/06 17:00:43 Failure: pod=cspod-69 reason="0/5 nodes are unavailable: 5 Insufficient cpu." (3/9 resolved)
2026/05/06 17:00:43 Failure: pod=cspod-68 reason="0/5 nodes are unavailable: 5 Insufficient cpu." (4/9 resolved)
2026/05/06 17:00:43 Failure: pod=cspod-33 reason="0/5 nodes are unavailable: 5 Insufficient cpu." (5/9 resolved)
2026/05/06 17:00:43 Failure: pod=cspod-34 reason="pod group is not ready, 4 Pending, 4 minAvailable; Pending: 4 Unschedulable. Origin reason is cspod-33: 0/5 nodes are unavailable: 5 Insufficient cpu." (6/9 resolved)
2026/05/06 17:00:43 Failure: pod=cspod-35 reason="pod group is not ready, 4 Pending, 4 minAvailable; Pending: 4 Unschedulable. Origin reason is cspod-33: 0/5 nodes are unavailable: 5 Insufficient cpu." (7/9 resolved)
2026/05/06 17:00:43 Binding: pod=cspod-65 -> node=csnode-3 (8/9 resolved)
2026/05/06 17:00:43 Binding: pod=cspod-66 -> node=csnode-3 (9/9 resolved)
2026/05/06 17:00:43 Round complete: 2 scheduled, 7 failed in 996.730432ms
2026/05/06 17:00:43 {"action":"HandleSchedule","durationMs":997,"podCount":9,"result":"ok","roundId":"24","scheduled":2,"ts":"2026-05-06T17:00:43.560102086+01:00","unschedulable":7}
2026/05/06 17:00:43 {"action":"HandleSchedule","completedIds":3,"nodeCount":5,"phase":"start","podCount":7,"roundId":"25","ts":"2026-05-06T17:00:43.566938822+01:00"}
2026/05/06 17:00:43 {"action":"HandleSchedule","phase":"prep_done","podsCreated":7,"prepMs":0,"roundId":"25","staleDeleted":0,"ts":"2026-05-06T17:00:43.567117215+01:00"}
2026/05/06 17:00:43 Scheduling round started: expecting 7 decisions
2026/05/06 17:00:44 Binding: pod=cspod-67 -> node=csnode-4 (1/7 resolved)
2026/05/06 17:00:44 Binding: pod=cspod-68 -> node=csnode-0 (2/7 resolved)
2026/05/06 17:00:44 Binding: pod=cspod-69 -> node=csnode-2 (3/7 resolved)
2026/05/06 17:00:44 Failure: pod=cspod-35 reason="pod group is not ready, 4 Pending, 4 minAvailable; Pending: 4 Unschedulable. Origin reason is cspod-33: 0/5 nodes are unavailable: 5 Insufficient cpu." (4/7 resolved)
2026/05/06 17:00:44 Failure: pod=cspod-36 reason="pod group is not ready, 4 Pending, 4 minAvailable; Pending: 4 Unschedulable. Origin reason is cspod-33: 0/5 nodes are unavailable: 5 Insufficient cpu." (5/7 resolved)
2026/05/06 17:00:44 Failure: pod=cspod-33 reason="0/5 nodes are unavailable: 5 Insufficient cpu." (6/7 resolved)
2026/05/06 17:00:44 Failure: pod=cspod-34 reason="pod group is not ready, 4 Pending, 4 minAvailable; Pending: 4 Unschedulable. Origin reason is cspod-33: 0/5 nodes are unavailable: 5 Insufficient cpu." (7/7 resolved)
2026/05/06 17:00:44 Round complete: 3 scheduled, 4 failed in 1.007172401s
2026/05/06 17:00:44 {"action":"HandleSchedule","durationMs":1007,"podCount":7,"result":"ok","roundId":"25","scheduled":3,"ts":"2026-05-06T17:00:44.574374161+01:00","unschedulable":4}
2026/05/06 17:00:44 {"action":"HandleSchedule","completedIds":1,"nodeCount":5,"phase":"start","podCount":4,"roundId":"26","ts":"2026-05-06T17:00:44.579897502+01:00"}
2026/05/06 17:00:44 {"action":"HandleSchedule","phase":"prep_done","podsCreated":4,"prepMs":0,"roundId":"26","staleDeleted":0,"ts":"2026-05-06T17:00:44.580056576+01:00"}
2026/05/06 17:00:44 Scheduling round started: expecting 4 decisions
2026/05/06 17:00:45 Failure: pod=cspod-34 reason="0/5 nodes are unavailable: 5 Insufficient cpu." (1/4 resolved)
2026/05/06 17:00:45 Failure: pod=cspod-35 reason="pod group is not ready, 4 Pending, 4 minAvailable; Pending: 1 Schedulable, 3 Unschedulable. Origin reason is cspod-34: 0/5 nodes are unavailable: 5 Insufficient cpu." (2/4 resolved)
2026/05/06 17:00:45 Failure: pod=cspod-36 reason="pod group is not ready, 4 Pending, 4 minAvailable; Pending: 1 Schedulable, 3 Unschedulable. Origin reason is cspod-34: 0/5 nodes are unavailable: 5 Insufficient cpu." (3/4 resolved)
2026/05/06 17:00:48 STALL EXIT: no progress for 2s — 0 scheduled, 3 failed, 1 still pending (returning partial)
2026/05/06 17:00:48 {"action":"HandleSchedule","durationMs":4018,"podCount":4,"result":"timeout_partial","roundId":"26","scheduled":0,"ts":"2026-05-06T17:00:48.5987199+01:00","unschedulable":4}
2026/05/06 17:00:48 {"action":"HandleSchedule","durationMs":4019,"podCount":4,"result":"ok","roundId":"26","scheduled":0,"ts":"2026-05-06T17:00:48.598760369+01:00","unschedulable":4}
2026/05/06 17:00:48 {"action":"HandleSchedule","completedIds":1,"nodeCount":5,"phase":"start","podCount":4,"roundId":"27","ts":"2026-05-06T17:00:48.603165246+01:00"}
2026/05/06 17:00:48 {"action":"HandleSchedule","phase":"prep_done","podsCreated":4,"prepMs":0,"roundId":"27","staleDeleted":0,"ts":"2026-05-06T17:00:48.603350701+01:00"}
2026/05/06 17:00:48 Scheduling round started: expecting 4 decisions
2026/05/06 17:00:49 Failure: pod=cspod-36 reason="pod group is not ready, 4 Pending, 4 minAvailable; Pending: 2 Schedulable, 2 Unschedulable. Origin reason is cspod-35: 0/5 nodes are unavailable: 5 Insufficient cpu." (1/4 resolved)
2026/05/06 17:00:49 Failure: pod=cspod-35 reason="0/5 nodes are unavailable: 5 Insufficient cpu." (2/4 resolved)
2026/05/06 17:00:50 STALL EXIT: no progress for 2s — 0 scheduled, 2 failed, 2 still pending (returning partial)
2026/05/06 17:00:50 {"action":"HandleSchedule","durationMs":4030,"podCount":4,"result":"timeout_partial","roundId":"27","scheduled":0,"ts":"2026-05-06T17:00:50.847112797+01:00","unschedulable":4}
2026/05/06 17:00:50 {"action":"HandleSchedule","durationMs":4031,"podCount":4,"result":"ok","roundId":"27","scheduled":0,"ts":"2026-05-06T17:00:50.847142865+01:00","unschedulable":4}
2026/05/06 17:00:50 {"action":"HandleSchedule","completedIds":1,"nodeCount":5,"phase":"start","podCount":4,"roundId":"28","ts":"2026-05-06T17:00:50.852278364+01:00"}
2026/05/06 17:00:50 {"action":"HandleSchedule","phase":"prep_done","podsCreated":4,"prepMs":0,"roundId":"28","staleDeleted":0,"ts":"2026-05-06T17:00:50.852493558+01:00"}
2026/05/06 17:00:50 Scheduling round started: expecting 4 decisions
2026/05/06 17:00:51 Failure: pod=cspod-36 reason="0/5 nodes are unavailable: 5 Insufficient cpu." (1/4 resolved)
2026/05/06 17:00:54 STALL EXIT: no progress for 2s — 0 scheduled, 1 failed, 3 still pending (returning partial)
2026/05/06 17:00:54 {"action":"HandleSchedule","durationMs":4001,"podCount":4,"result":"timeout_partial","roundId":"28","scheduled":0,"ts":"2026-05-06T17:00:54.853939035+01:00","unschedulable":4}
2026/05/06 17:00:54 {"action":"HandleSchedule","durationMs":4001,"podCount":4,"result":"ok","roundId":"28","scheduled":0,"ts":"2026-05-06T17:00:54.853958182+01:00","unschedulable":4}
2026/05/06 17:00:54 {"action":"HandleSchedule","completedIds":2,"nodeCount":5,"phase":"start","podCount":4,"roundId":"29","ts":"2026-05-06T17:00:54.85968436+01:00"}
2026/05/06 17:00:54 {"action":"HandleSchedule","phase":"prep_done","podsCreated":4,"prepMs":0,"roundId":"29","staleDeleted":0,"ts":"2026-05-06T17:00:54.86004207+01:00"}
2026/05/06 17:00:54 Scheduling round started: expecting 4 decisions
2026/05/06 17:00:55 Binding: pod=cspod-33 -> node=csnode-4 (1/4 resolved)
2026/05/06 17:00:55 Binding: pod=cspod-36 -> node=csnode-1 (2/4 resolved)
2026/05/06 17:00:55 Binding: pod=cspod-35 -> node=csnode-2 (3/4 resolved)
2026/05/06 17:00:55 Binding: pod=cspod-34 -> node=csnode-0 (4/4 resolved)
2026/05/06 17:00:55 Round complete: 4 scheduled, 0 failed in 980.454516ms
2026/05/06 17:00:55 {"action":"HandleSchedule","durationMs":980,"podCount":4,"result":"ok","roundId":"29","scheduled":4,"ts":"2026-05-06T17:00:55.840610248+01:00","unschedulable":0}
2026/05/06 17:00:55 Scheduling round reset
2026/05/06 17:00:55 {"action":"HandleReset","result":"ok","roundId":"29","ts":"2026-05-06T17:00:55.85763631+01:00"}
